Workbook
Name RiskAutoStopPercChange: 1.5
Name RiskCollectDistributionSamples: 2
Name RiskExcelReportsGoInNewWorkbook: TRUE
Name RiskExcelReportsToGenerate: 0
Name RiskFixedSeed: 1
Name RiskGenerateExcelReportsAtEndOfSimulation: FALSE
Name RiskHasSettings: TRUE
Name RiskMinimizeOnStart: FALSE
Name RiskMonitorConvergence: FALSE
Name RiskNumIterations: 1000
Name RiskNumSimulations: 1
Name RiskPauseOnError: FALSE
Name RiskRealTimeResults: FALSE
Name RiskReportGraphFormat: 0
Name RiskResultsUpdateFreq: 100
Name RiskRunAfterRecalcMacro: FALSE
Name RiskRunAfterSimMacro: FALSE
Name RiskRunBeforeRecalcMacro: FALSE
Name RiskRunBeforeSimMacro: FALSE
Name RiskSamplingType: 3
Name RiskShowRiskWindowAtEndOfSimulation: TRUE
Name RiskStandardRecalc: 1
Name RiskTemplateSheetName: "myTemplate"
Name RiskUpdateDisplay: FALSE
Name RiskUseDifferentSeedForEachSim: FALSE
Name RiskUseFixedSeed: FALSE
Name RiskUseMultipleCPUs: FALSE

Sheet __FDSCACHE__
B1: This sheet contains FactSet XML data for use with this workbook's =FDS codes. Modifying the worksheet's contents may damage the workbook's =FDS functionality.

Sheet JEF DISCLAIMER
B1: This material was prepared by personnel who are associated with Jefferies (Jefferies International Limited, Jefferies Hong Kong Limited, Jefferies Singapore Limited, Jefferies (Japan) Limited, Tokyo Branch, Jefferies India Private Limited, Jefferies (Australia) Pty Ltd); or by personnel who are associated with both Jefferies LLC and Jefferies Research Services LLC (“JRS”). Jefferies LLC is a US registered broker-dealer and is affiliated with JRS, which is a US registered investment adviser. JRS does not create tailored or personalized research and all research provided by JRS is impersonal. If you are paying separately for this research, it is being provided to you by JRS. Otherwise, it is being provided by Jefferies LLC. Jefferies LLC, JRS, and their affiliates are collectively referred to below as “Jefferies”. The information upon which this material is based was obtained from sources believed to be reliable, but has not been independently verified, therefore, we do not guarantee its accuracy. Additional and supporting information is available upon request. This is not an offer or solicitation of an offer to buy or sell any security or investment. Any opinion or estimates constitute our best judgment as of this date, and are subject to change without notice. Members of Jefferies and their respective directors, officers and employees may buy or sell securities mentioned herein as agent or principal for their own account. Upon request members of Jefferies may provide specialized research products or services to certain customers focusing on the prospects for individual covered stocks as compared to other covered stocks over varying time horizons or under differing market conditions. While the views expressed in these situations may not always be directionally consistent with the long-term views expressed in the analyst's published research, the analyst has a reasonable basis and any inconsistencies can be reasonably explained. In Australia, this report may contain general advice. Where this report refers to a particular financial product, you should obtain a copy of the relevant product disclosure statement or offer document before making any decision in relation to the product. This report may contain forward looking statements that may be affected by inaccurate assumptions or by known or unknown risks, uncertainties and other important factors. As a result, the actual results, events, performance or achievements of the financial product may be materially different from those expressed or implied in such statements. Past performance is not indicative of future performance. This report/model may contain information obtained from third parties, including ratings from credit ratings agencies such as Standard & Poor’s. Reproduction and distribution of third party content in any form is prohibited except with the prior written permission of the applicable third party. Third party content providers do not guarantee the accuracy, completeness, timeliness or availability of any information, including ratings, and are not responsible for any errors or omissions (negligent or otherwise), regardless of the cause, or for the results obtained from the use of such content. Third party content providers do not provide any express or implied warranties, including, but not limited to, any warranties of merchantability or fitness for a particular purpose or use. Third party content providers are not liable for any direct, indirect, incidental, exemplary, compensatory, punitive, special or consequential damages, costs, expenses, legal fees, or losses (including lost income or profits and opportunity costs) in connection with any use of their content, including ratings. Credit ratings are statements of opinions and are not statements of fact or recommendations to purchase, hold or sell securities. Such credit ratings do not address the suitability of securities or the suitability of securities for investment purposes, and should not be relied on as investment advice. This report/model or any portion hereof may not be reprinted, sold or redistributed without the written consent of Jefferies or its affiliates. Neither Jefferies or its affiliates nor any officer nor employee of Jefferies or its affiliates accepts any liability whatsoever for any direct, indirect or consequential damages or losses of any kind arising from any use of this report/model or its contents. For Important Disclosure information, please visit our website at https://javatar.bluematrix.com/sellside/Disclosures.action or call 1.888.JEFFERIES.

Sheet IS
A3: Valvoline Inc. (VVV)
A4: FYE: Sept.
A5: Earnings Model
A6: ($M's, except per share)
B7: 1Q16 | C7: 2Q16 | D7: 3Q16 | E7: 4Q16 | F7: FY16 | G7: 1Q17 | H7: 2Q17 | I7: 3Q17 | J7: 4Q17 | K7: FY17 | L7: 1Q18 | M7: 2Q18 | N7: 3Q18 | O7: 4Q18 | P7: FY18 | Q7: 1Q19 | R7: 2Q19 | S7: 3Q19 | T7: 4Q19 | U7: FY19 | V7: 1Q20 | W7: 2Q20 | X7: 3Q20 | Y7: 4Q20 | Z7: FY20 | AA7: 1Q21 | AB7: 2Q21 | AC7: 3Q21 | AD7: 4Q21 | AE7: FY21 | AF7: 1Q22 | AG7: 2Q22 | AH7: 3Q22 | AI7: 4Q22 | AJ7: FY22 | AK7: 1Q23 | AL7: 2Q23 | AM7: 3Q23 | AN7: 4Q23 | AO7: FY23 | AP7: 1Q24 | AQ7: 2Q24 | AR7: 3Q24 | AS7: 4Q24 | AT7: FY24 | AU7: 1Q25 | AV7: 2Q25 | AW7: 3Q25 | AX7: 4Q25 | AY7: FY25 | AZ7: 1Q26 | BA7: 2Q26E | BB7: 3Q26E | BC7: 4Q26E | BD7: FY26E | BE7: 1Q27E | BF7: 2Q27E | BG7: 3Q27E | BH7: 4Q27E | BI7: FY27E
A9: Global Products
A11: Sales Analysis: | B11: =SUM(B12:B13) -> 356 | C11: =SUM(C12:C13) -> 367 | D11: =SUM(D12:D13) -> 380 | E11: =SUM(E12:E13) -> 369 | F11: =SUM(B11:E11) -> 1472 | G11: =SUM(G12:G13) -> 362 | H11: =SUM(H12:H13) -> 386 | I11: =SUM(I12:I13) -> 395 | J11: =SUM(J12:J13) -> 400 | K11: =SUM(G11:J11) -> 1543 | L11: =SUM(L12:L13) -> 391 | M11: =SUM(M12:M13) -> 411 | N11: =SUM(N12:N13) -> 410 | O11: =SUM(O12:O13) -> 413 | P11: =SUM(L11:O11) -> 1625 | Q11: =SUM(Q12:Q13) -> 368 | R11: =SUM(R12:R13) -> 391 | S11: =SUM(S12:S13) -> 402 | T11: =SUM(T12:T13) -> 407 | U11: =SUM(Q11:T11) -> 1568 | V11: =SUM(V12:V13) -> 389 | W11: =SUM(W12:W13) -> 366 | X11: =SUM(X12:X13) -> 317 | Y11: =SUM(Y12:Y13) -> 398 | Z11: =SUM(V11:Y11) -> 1470 | AA11: =SUM(AA12:AA13) -> 399 | AB11: =SUM(AB12:AB13) -> 416 | AC11: 462 | AD11: 483 | AE11: =SUM(AA11:AD11) -> 1760 | AF11: 512 | AG11: 536 | AH11: 573 | AJ11: =SUM(AF11:AI11) -> 1621
A12: Core NA | B12: 241 | C12: 248 | D12: 251 | E12: 239 | F12: =SUM(B12:E12) -> 979 | G12: 237 | H12: 253 | I12: 258 | J12: 256 | K12: =SUM(G12:J12) -> 1004 | L12: 251 | M12: 258 | N12: 264 | O12: 262 | P12: =SUM(L12:O12) -> 1035 | Q12: 232 | R12: 243 | S12: 260 | T12: 259 | U12: =SUM(Q12:T12) -> 994 | V12: 248 | W12: 238 | X12: 207 | Y12: 252 | Z12: =SUM(V12:Y12) -> 945 | AA12: 235 | AB12: 242 | AE12: =SUM(AA12:AD12) -> 477
A13: International | B13: 115 | C13: 119 | D13: 129 | E13: 130 | F13: =SUM(B13:E13) -> 493 | G13: 125 | H13: 133 | I13: 137 | J13: 144 | K13: =SUM(G13:J13) -> 539 | L13: 140 | M13: 153 | N13: 146 | O13: 151 | P13: =SUM(L13:O13) -> 590 | Q13: 136 | R13: 148 | S13: 142 | T13: 148 | U13: =SUM(Q13:T13) -> 574 | V13: 141 | W13: 128 | X13: 110 | Y13: 146 | Z13: =SUM(V13:Y13) -> 525 | AA13: 164 | AB13: 174 | AE13: =SUM(AA13:AD13) -> 338
A15: Y/Y % growth
A16: Core NA | G16: =G12/B12-1 -> -0.01659751 | H16: =H12/C12-1 -> 0.02016129 | I16: =I12/D12-1 -> 0.027888446 | J16: =J12/E12-1 -> 0.071129707 | K16: =K12/F12-1 -> 0.025536261 | L16: =L12/G12-1 -> 0.05907173 | M16: =M12/H12-1 -> 0.019762846 | N16: =N12/I12-1 -> 0.023255814 | ... AB16: =AB12/W12-1 -> 0.016806723
A17: International | G17: =G13/B13-1 -> 0.086956522 | H17: =H13/C13-1 -> 0.11764706 | I17: =I13/D13-1 -> 0.062015504 | J17: =J13/E13-1 -> 0.10769231 | K17: =K13/F13-1 -> 0.093306288 | L17: =L13/G13-1 -> 0.12 | M17: =M13/H13-1 -> 0.15037594 | N17: =N13/I13-1 -> 0.065693431 | ... AB17: =AB13/W13-1 -> 0.359375
A18: Global Products Total | G18: =G11/B11-1 -> 0.016853933 | H18: =H11/C11-1 -> 0.051771117 | I18: =I11/D11-1 -> 0.039473684 | J18: =J11/E11-1 -> 0.08401084 | K18: =K11/F11-1 -> 0.048233696 | L18: =L11/G11-1 -> 0.080110497 | M18: =M11/H11-1 -> 0.064766839 | N18: =N11/I11-1 -> 0.037974684 | ... AH18: =AH11/AC11-1 -> 0.24025974 | AJ18: =AJ11/AE11-1 -> -0.078977273
A20: Operating Margin Analysis: | E20: =SUM(E21:E22) -> 63 | F20: =SUM(F21:F22) -> 286 | G20: =SUM(G21:G22) -> 71 | H20: =SUM(H21:H22) -> 75 | I20: =SUM(I21:I22) -> 66 | J20: =SUM(J21:J22) -> 63 | K20: =SUM(G20:J20) -> 275 | L20: =SUM(L21:L22) -> 62 | M20: =SUM(M21:M22) -> 70 | N20: =SUM(N21:N22) -> 61 | O20: =SUM(O21:O22) -> 63 | P20: =SUM(L20:O20) -> 256 | Q20: =SUM(Q21:Q22) -> 49 | R20: =SUM(R21:R22) -> 63 | S20: =SUM(S21:S22) -> 58 | T20: =SUM(T21:T22) -> 67 | U20: =SUM(Q20:T20) -> 237 | V20: =SUM(V21:V22) -> 66 | W20: =SUM(W21:W22) -> 65 | X20: =SUM(X21:X22) -> 63 | Y20: =SUM(Y21:Y22) -> 81 | Z20: =SUM(V20:Y20) -> 275 | AA20: =SUM(AA21:AA22) -> 81 | AB20: =SUM(AB21:AB22) -> 66 | AC20: 72 | AD20: 65 | AE20: =SUM(AA20:AD20) -> 284 | AF20: 70 | AG20: 74 | AH20: 80
A21: Core NA | E21: 42 | F21: 212 | G21: 51 | H21: 57 | I21: 48 | J21: 43 | K21: =SUM(G21:J21) -> 199 | L21: 43 | M21: 46 | N21: 41 | O21: 42 | P21: =SUM(L21:O21) -> 172 | Q21: 31 | R21: 40 | S21: 38 | T21: 43 | U21: =SUM(Q21:T21) -> 152 | V21: 46 | W21: 47 | X21: 51 | Y21: 58 | Z21: =SUM(V21:Y21) -> 202 | AA21: 47 | AB21: 38
A22: International | E22: 21 | F22: 74 | G22: 20 | H22: 18 | I22: 18 | J22: 20 | K22: =SUM(G22:J22) -> 76 | L22: 19 | M22: 24 | N22: 20 | O22: 21 | P22: =SUM(L22:O22) -> 84 | Q22: 18 | R22: 23 | S22: 20 | T22: 24 | U22: =SUM(Q22:T22) -> 85 | V22: 20 | W22: 18 | X22: 12 | Y22: 23 | Z22: =SUM(V22:Y22) -> 73 | AA22: 34 | AB22: 28
A24: Operating Margin % | E24: =E20/E11 -> 0.17073171 | F24: =F20/F11 -> 0.19429348 | G24: =G20/G11 -> 0.1961326 | H24: =H20/H11 -> 0.19430052 | I24: =I20/I11 -> 0.16708861 | J24: =J20/J11 -> 0.1575 | K24: =K20/K11 -> 0.17822424 | L24: =L20/L11 -> 0.15856777 | ... AH24: =AH20/AH11 -> 0.13961606 | AJ24: =AJ20/AJ11 -> 0
A26: Depreciation and Amortization | E26: =4+5 -> 9 | F26: 21 | G26: 4 | H26: 4 | I26: 6 | J26: 6 | K26: =SUM(G26:J26) -> 20 | L26: 5 | M26: 6 | N26: 7 | O26: 6 | P26: =SUM(L26:O26) -> 24 | Q26: 6 | R26: 5 | S26: 6 | T26: 8 | U26: =SUM(Q26:T26) -> 25 | V26: 6 | W26: 5 | X26: 6 | Y26: 6 | Z26: =SUM(V26:Y26) -> 23 | AA26: 6 | AB26: 7 | AC26: 9 | AD26: 7 | AF26: 7 | AG26: 7 | AH26: 7
A27: Other Ajustments | E27: 0 | F27: 0 | G27: 0 | H27: 0 | I27: 0 | J27: 0 | K27: =SUM(G27:J27) -> 0 | L27: 0 | M27: 0 | N27: 0 | O27: 0 | P27: =SUM(L27:O27) -> 0 | Q27: 0 | R27: 0 | S27: 0 | T27: 0 | U27: =SUM(Q27:T27) -> 0 | V27: 0 | W27: 0 | X27: 0 | Y27: 0 | Z27: =SUM(V27:Y27) -> 0 | AA27: 0 | AB27: 0 | AC27: 0 | AD27: 0 | AF27: 0 | AG27: 0 | AH27: 0
A29: EBITDA Analysis:
A30: EBITDA | E30: =E20+SUM(E26:E27) -> 72 | F30: =F20+SUM(F26:F27) -> 307 | G30: =G20+SUM(G26:G27) -> 75 | H30: =H20+SUM(H26:H27) -> 79 | I30: =I20+SUM(I26:I27) -> 72 | J30: =J20+SUM(J26:J27) -> 69 | K30: =SUM(G30:J30) -> 295 | L30: =L20+SUM(L26:L27) -> 67 | M30: =M20+SUM(M26:M27) -> 76 | N30: =N20+SUM(N26:N27) -> 68 | O30: =O20+SUM(O26:O27) -> 69 | P30: =SUM(L30:O30) -> 280 | Q30: =Q20+SUM(Q26:Q27) -> 55 | R30: =R20+SUM(R26:R27) -> 68 | S30: =S20+SUM(S26:S27) -> 64 | T30: =T20+SUM(T26:T27) -> 75 | U30: =SUM(Q30:T30) -> 262 | V30: =V20+SUM(V26:V27) -> 72 | W30: =W20+SUM(W26:W27) -> 70 | X30: =X20+SUM(X26:X27) -> 69 | Y30: =Y20+SUM(Y26:Y27) -> 87 | Z30: =SUM(V30:Y30) -> 298 | AA30: =AA20+SUM(AA26:AA27) -> 87 | AB30: =AB20+SUM(AB26:AB27) -> 73 | AC30: =AC20+SUM(AC26:AC27) -> 81 | AD30: =AD20+SUM(AD26:AD27) -> 72 | AE30: =SUM(AA30:AD30) -> 313 | AF30: =AF20+SUM(AF26:AF27) -> 77 | AG30: =AG20+SUM(AG26:AG27) -> 81 | AH30: =AH20+SUM(AH26:AH27) -> 87 | AJ30: =SUM(AF30:AI30) -> 245
A31: EBITDA Margin | E31: =E30/E11 -> 0.19512195 | F31: =F30/F11 -> 0.20855978 | G31: =G30/G11 -> 0.20718232 | H31: =H30/H11 -> 0.20466321 | I31: =I30/I11 -> 0.18227848 | J31: =J30/J11 -> 0.1725 | K31: =K30/K11 -> 0.191186 | L31: =L30/L11 -> 0.1713555 | ... AH31: =AH30/AH11 -> 0.15183246 | AJ31: =AJ30/AJ11 -> 0.15114127
A35: Retail Services
A37: Retail Stores
A38: Company Operated
A39: Opened | C39: 1 | D39: 0 | E39: 2 | F39: =SUM(B39:E39) -> 3 | G39: 0 | H39: 0 | I39: 1 | J39: 2 | K39: =SUM(G39:J39) -> 3 | L39: 2 | M39: 0 | N39: 4 | O39: 11 | P39: =SUM(L39:O39) -> 17 | Q39: 5 | R39: 7 | S39: 4 | T39: 12 | U39: =SUM(Q39:T39) -> 28 | V39: 2 | W39: 7 | X39: 5 | Y39: 22 | Z39: =SUM(V39:Y39) -> 36 | AA39: 18 | AB39: 11 | AC39: 17 | AD39: 21 | AE39: =SUM(AA39:AD39) -> 67 | AF39: 7 | AG39: 10 | AH39: 5 | AI39: 12 | AJ39: =SUM(AF39:AI39) -> 34 | AK39: 17 | AL39: 13 | AM39: 12 | AN39: 14 | AO39: =SUM(AK39:AN39) -> 56 | AP39: 14 | AQ39: 14 | AR39: 12 | AS39: 26 | AT39: =SUM(AP39:AS39) -> 66 | AU39: 15 | AV39: 12 | AW39: 19 | AX39: 26 | AY39: =SUM(AU39:AX39) -> 72 | AZ39: 26 | BA39: 23 | BB39: 23 | BC39: 28 | BD39: =SUM(AZ39:BC39) -> 100 | BE39: 20 | BF39: 20 | BG39: 23 | BH39: 28 | BI39: =SUM(BE39:BH39) -> 91
A40: Acquired | C40: 47 | D40: 1 | E40: 0 | F40: =SUM(B40:E40) -> 48 | G40: 0 | H40: 28 | I40: 0 | J40: 1 | K40: =SUM(G40:J40) -> 29 | L40: 0 | M40: 2 | N40: 1 | O40: 0 | P40: =SUM(L40:O40) -> 3 | Q40: 0 | R40: 5 | S40: 13 | T40: 6 | U40: =SUM(Q40:T40) -> 24 | V40: 7 | W40: 1 | X40: 2 | Y40: 2 | Z40: =SUM(V40:Y40) -> 12 | AA40: 54 | AB40: 0 | AC40: 5 | AD40: 3 | AE40: =SUM(AA40:AD40) -> 62 | AF40: 12 | AG40: 9 | AH40: 9 | AI40: 3 | AJ40: =SUM(AF40:AI40) -> 33 | AK40: 5 | AL40: 6 | AM40: 8 | AN40: 8 | AO40: =SUM(AK40:AN40) -> 27 | AP40: 5 | AQ40: 10 | AR40: 6 | AS40: 10 | AT40: =SUM(AP40:AS40) -> 31 | AU40: 6 | AV40: 6 | AW40: 8 | AX40: 8 | AY40: =SUM(AU40:AX40) -> 28 | AZ40: 210 | BA40: 0 | BB40: 0 | BC40: 0 | BD40: =SUM(AZ40:BC40) -> 210 | BE40: 0 | BF40: 0 | BG40: 0 | BH40: 0 | BI40: =SUM(BE40:BH40) -> 0
A41: Net Conversions | C41: 1 | D41: 1 | E41: 7 | F41: =SUM(B41:E41) -> 9 | G41: 5 | H41: 0 | I41: 9 | J41: 0 | K41: =SUM(G41:J41) -> 14 | L41: 56 | M41: 1 | N41: 1 | O41: 0 | P41: =SUM(L41:O41) -> 58 | Q41: 4 | R41: 0 | S41: 1 | T41: 0 | U41: =SUM(Q41:T41) -> 5 | V41: -4 | W41: 4 | X41: 5 | Y41: 12 | Z41: =SUM(V41:Y41) -> 17 | AA41: 7 | AB41: 0 | AC41: 3 | AD41: 0 | AE41: =SUM(AA41:AD41) -> 10 | AF41: 0 | AG41: 0 | AH41: 1 | AI41: 3 | AJ41: =SUM(AF41:AI41) -> 4 | AK41: 2 | AL41: 0 | AM41: 2 | AN41: 0 | AO41: =SUM(AK41:AN41) -> 4 | AP41: 0 | AQ41: 0 | AR41: 0 | AS41: -23 | AT41: =SUM(AP41:AS41) -> -23 | AU41: -39 | AV41: 0 | AW41: 6 | AX41: 0 | AY41: =SUM(AU41:AX41) -> -33 | AZ41: -10 | BA41: 0 | BB41: 0 | BC41: 0 | BD41: =SUM(AZ41:BC41) -> -10 | BE41: 0 | BF41: 0 | BG41: 0 | BH41: 0 | BI41: =SUM(BE41:BH41) -> 0
A42: Closed | C42: 0 | D42: 0 | E42: 0 | F42: =SUM(B42:E42) -> 0 | G42: 0 | H42: -1 | I42: -1 | J42: -2 | K42: =SUM(G42:J42) -> -4 | L42: 0 | M42: 0 | N42: 0 | O42: 0 | P42: =SUM(L42:O42) -> 0 | Q42: 0 | R42: 0 | S42: 0 | T42: 0 | U42: =SUM(Q42:T42) -> 0 | V42: 0 | W42: 0 | X42: 0 | Y42: 0 | Z42: =SUM(V42:Y42) -> 0 | AA42: 0 | AB42: -1 | AC42: 0 | AD42: -3 | AE42: =SUM(AA42:AD42) -> -4 | AF42: 0 | AG42: 0 | AH42: 0 | AI42: 0 | AJ42: =SUM(AF42:AI42) -> 0 | AK42: -1 | AL42: 0 | AM42: 0 | AN42: 0 | AO42: =SUM(AK42:AN42) -> -1 | AP42: 0 | AQ42: 0 | AR42: 0 | AS42: 0 | AT42: =SUM(AP42:AS42) -> 0 | AU42: 0 | AV42: 0 | AW42: 0 | AX42: -1 | AY42: =SUM(AU42:AX42) -> -1 | AZ42: =-45-1 -> -46 | BA42: 0 | BB42: 0 | BC42: 0 | BD42: =SUM(AZ42:BC42) -> -46 | BE42: 0 | BF42: 0 | BG42: 0 | BH42: 0 | BI42: =SUM(BE42:BH42) -> 0
A43: End of Period | B43: 282 | C43: =B43+SUM(C39:C42) -> 331 | D43: =C43+SUM(D39:D42) -> 333 | E43: =D43+SUM(E39:E42) -> 342 | F43: =E43 -> 342 | G43: =F43+SUM(G39:G42) -> 347 | H43: =G43+SUM(H39:H42) -> 374 | I43: =H43+SUM(I39:I42) -> 383 | J43: =I43+SUM(J39:J42) -> 384 | K43: =J43 -> 384 | L43: =K43+SUM(L39:L42) -> 442 | M43: =L43+SUM(M39:M42) -> 445 | N43: =M43+SUM(N39:N42) -> 451 | O43: =N43+SUM(O39:O42) -> 462 | P43: =O43 -> 462 | Q43: =P43+SUM(Q39:Q42) -> 471 | R43: =Q43+SUM(R39:R42) -> 483 | S43: =R43+SUM(S39:S42) -> 501 | T43: =S43+SUM(T39:T42) -> 519 | U43: =T43 -> 519 | V43: =U43+SUM(V39:V42) -> 524 | W43: =V43+SUM(W39:W42) -> 536 | X43: =W43+SUM(X39:X42) -> 548 | Y43: =X43+SUM(Y39:Y42) -> 584 | Z43: =Y43 -> 584 | AA43: =Z43+SUM(AA39:AA42) -> 663 | AB43: =AA43+SUM(AB39:AB42) -> 673 | AC43: =AB43+SUM(AC39:AC42) -> 698 | AD43: =AC43+SUM(AD39:AD42) -> 719 | AE43: =AD43 -> 719 | AF43: 738 | AG43: =AF43+AG39+AG40+AG41+AG42 -> 757 | AH43: =AG43+AH39+AH40+AH41+AH42 -> 772 | AI43: =AH43+AI39+AI40+AI41+AI42 -> 790 | AJ43: =AI43 -> 790 | AK43: =AJ43+AK39+AK40+AK41+AK42 -> 813 | AL43: =AK43+AL39+AL40+AL41+AL42 -> 832 | AM43: =AL43+AM39+AM40+AM41+AM42 -> 854 | AN43: =AM43+AN39+AN40+AN41+AN42 -> 876 | AO43: =AN43 -> 876 | AP43: =AO43+AP39+AP40+AP41+AP42 -> 895 | AQ43: =AP43+AQ39+AQ40+AQ41+AQ42 -> 919 | AR43: =AQ43+AR39+AR40+AR41+AR42 -> 937 | AS43: =AR43+AS39+AS40+AS41+AS42 -> 950 | AT43: =AS43 -> 950 | AU43: =AT43+AU39+AU40+AU41+AU42 -> 932 | AV43: =AU43+AV39+AV40+AV41+AV42 -> 950 | AW43: =AV43+AW39+AW40+AW41+AW42 -> 983 | AX43: =AW43+AX39+AX40+AX41+AX42 -> 1016 | AY43: =AX43 -> 1016 | AZ43: =AY43+AZ39+AZ40+AZ41+AZ42 -> 1196 | BA43: =AZ43+BA39+BA40+BA41+BA42 -> 1219 | BB43: =BA43+BB39+BB40+BB41+BB42 -> 1242 | BC43: =BB43+BC39+BC40+BC41+BC42 -> 1270 | BD43: =BC43 -> 1270 | BE43: =BD43+BE39+BE40+BE41+BE42 -> 1290 | BF43: =BE43+BF39+BF40+BF41+BF42 -> 1310 | BG43: =BF43+BG39+BG40+BG41+BG42 -> 1333 | BH43: =BG43+BH39+BH40+BH41+BH42 -> 1361 | BI43: =BH43 -> 1361
A45: Franchised
A46: Opened | C46: 6 | D46: 4 | E46: 12 | F46: =SUM(B46:E46) -> 22 | G46: 10 | H46: 7 | I46: 6 | J46: 15 | K46: =SUM(G46:J46) -> 38 | L46: 11 | M46: 2 | N46: 10 | O46: 5 | P46: =SUM(L46:O46) -> 28 | Q46: 24 | R46: 15 | S46: 11 | T46: 15 | U46: =SUM(Q46:T46) -> 65 | V46: 13 | W46: 8 | X46: 8 | Y46: 7 | Z46: =SUM(V46:Y46) -> 36 | AA46: 0 | AB46: 2 | AC46: 0 | AD46: 0 | AE46: =SUM(AA46:AD46) -> 2 | AF46: 25 | AG46: 9 | AH46: 16 | AI46: 10 | AJ46: =SUM(AF46:AI46) -> 60 | AK46: 11 | AL46: 16 | AM46: 3 | AN46: 26 | AO46: =SUM(AK46:AN46) -> 56 | AP46: 19 | AQ46: 15 | AR46: 15 | AS46: 13 | AT46: =SUM(AP46:AS46) -> 62 | AU46: 14 | AV46: 17 | AW46: 19 | AX46: 24 | AY46: =SUM(AU46:AX46) -> 74 | AZ46: 13 | BA46: 20 | BB46: 24 | BC46: 30 | BD46: =SUM(AZ46:BC46) -> 87 | BE46: 25 | BF46: 25 | BG46: 30 | BH46: 30 | BI46: =SUM(BE46:BH46) -> 110
A47: Acquired | C47: 42 | D47: 0 | E47: 0 | F47: =SUM(B47:E47) -> 42 | G47: 0 | H47: 0 | I47: 0 | J47: 0 | K47: =SUM(G47:J47) -> 0 | L47: 0 | M47: 0 | N47: 0 | O47: 73 | P47: =SUM(L47:O47) -> 73 | Q47: 31 | R47: 0 | S47: 0 | T47: 0 | U47: =SUM(Q47:T47) -> 31 | V47: 4 | W47: 0 | X47: 0 | Y47: 0 | Z47: =SUM(V47:Y47) -> 4 | AA47: 0 | AB47: 3 | AC47: 0 | AD47: 4 | AE47: =SUM(AA47:AD47) -> 7 | AF47: 0 | AG47: 0 | AH47: 0 | AI47: 0 | AJ47: =SUM(AF47:AI47) -> 0 | AK47: 0 | AL47: 0 | AM47: 0 | AN47: 0 | AO47: =SUM(AK47:AN47) -> 0 | AP47: 0 | AQ47: 0 | AR47: 0 | AS47: 0 | AT47: =SUM(AP47:AS47) -> 0 | AU47: 0 | AV47: 0 | AW47: 0 | AX47: 0 | AY47: =SUM(AU47:AX47) -> 0 | AZ47: 0 | BA47: 0 | BB47: 0 | BC47: 0 | BD47: =SUM(AZ47:BC47) -> 0 | BE47: 0 | BF47: 0 | BG47: 0 | BH47: 0 | BI47: =SUM(BE47:BH47) -> 0
A48: Net Conversions | C48: -1 | D48: -1 | E48: -7 | F48: =SUM(B48:E48) -> -9 | G48: -5 | I48: -9 | K48: =SUM(G48:J48) -> -14 | L48: -56 | M48: -1 | N48: -1 | O48: 0 | P48: =SUM(L48:O48) -> -58 | Q48: -4 | R48: 0 | S48: -1 | T48: 0 | U48: =SUM(Q48:T48) -> -5 | V48: 0 | W48: -4 | X48: -5 | Y48: -12 | Z48: =SUM(V48:Y48) -> -21 | AA48: -7 | AB48: 0 | AC48: -3 | AD48: 0 | AE48: =SUM(AA48:AD48) -> -10 | AF48: 0 | AG48: 0 | AH48: -1 | AI48: -3 | AJ48: =SUM(AF48:AI48) -> -4 | AK48: -2 | AL48: 0 | AM48: -2 | AN48: 0 | AO48: =SUM(AK48:AN48) -> -4 | AP48: 0 | AQ48: 0 | AR48: 0 | AS48: 23 | AT48: =SUM(AP48:AS48) -> 23 | AU48: 39 | AV48: 0 | AW48: -6 | AX48: 0 | AY48: =SUM(AU48:AX48) -> 33 | AZ48: 10 | BA48: 0 | BB48: 0 | BC48: 0 | BD48: =SUM(AZ48:BC48) -> 10 | BE48: 0 | BF48: 0 | BG48: 0 | BH48: 0 | BI48: =SUM(BE48:BH48) -> 0
A49: Closed | C49: 0 | D49: -2 | E49: -1 | F49: =SUM(B49:E49) -> -3 | G49: -2 | H49: -2 | I49: -1 | J49: -2 | K49: =SUM(G49:J49) -> -7 | L49: -1 | M49: -2 | N49: -2 | O49: -1 | P49: =SUM(L49:O49) -> -6 | Q49: -1 | R49: -1 | S49: -3 | T49: 0 | U49: =SUM(Q49:T49) -> -5 | V49: 0 | W49: -4 | X49: -2 | Y49: -1 | Z49: =SUM(V49:Y49) -> -7 | AA49: -1 | AB49: 0 | AC49: -1 | AD49: 0 | AE49: =SUM(AA49:AD49) -> -2 | AF49: -3 | AG49: -2 | AH49: -1 | AI49: 0 | AJ49: =SUM(AF49:AI49) -> -6 | AK49: -1 | AL49: 0 | AM49: 0 | AN49: 0 | AO49: =SUM(AK49:AN49) -> -1 | AP49: 0 | AQ49: -1 | AR49: 0 | AS49: 0 | AT49: =SUM(AP49:AS49) -> -1 | AU49: 0 | AV49: -2 | AW49: 0 | AX49: -1 | AY49: =SUM(AU49:AX49) -> -3 | AZ49: -3 | BA49: 0 | BB49: 0 | BC49: 0 | BD49: =SUM(AZ49:BC49) -> -3 | BE49: 0 | BF49: 0 | BG49: 0 | BH49: 0 | BI49: =SUM(BE49:BH49) -> 0
A50: End of Period | B50: 674 | C50: =B50+SUM(C46:C49) -> 721 | D50: =C50+SUM(D46:D49) -> 722 | E50: =D50+SUM(E46:E49) -> 726 | F50: =E50 -> 726 | G50: =F50+SUM(G46:G49) -> 729 | H50: =G50+SUM(H46:H49) -> 734 | I50: =H50+SUM(I46:I49) -> 730 | J50: =I50+SUM(J46:J49) -> 743 | K50: =J50 -> 743 | L50: =K50+SUM(L46:L49) -> 697 | M50: =L50+SUM(M46:M49) -> 696 | N50: =M50+SUM(N46:N49) -> 703 | O50: =N50+SUM(O46:O49) -> 780 | P50: =O50 -> 780 | Q50: =P50+SUM(Q46:Q49) -> 830 | R50: =Q50+SUM(R46:R49) -> 844 | S50: =R50+SUM(S46:S49) -> 851 | T50: =S50+SUM(T46:T49) -> 866 | U50: =T50 -> 866 | V50: =U50+SUM(V46:V49) -> 883 | W50: =V50+SUM(W46:W49) -> 883 | X50: =W50+SUM(X46:X49) -> 884 | Y50: =X50+SUM(Y46:Y49) -> 878 | Z50: =Y50 -> 878 | AA50: =Z50+SUM(AA46:AA49) -> 870 | AB50: =AA50+SUM(AB46:AB49) -> 875 | AC50: =AB50+SUM(AC46:AC49) -> 871 | AD50: =AC50+SUM(AD46:AD49) -> 875 | AE50: =AD50 -> 875 | AF50: 897 | AG50: =AF50+AG46+AG47+AG48+AG49 -> 904 | AH50: =AG50+AH46+AH47+AH48+AH49 -> 918 | AI50: =AH50+AI46+AI47+AI48+AI49 -> 925 | AJ50: =AI50 -> 925 | AK50: =AJ50+AK46+AK47+AK48+AK49 -> 933 | AL50: =AK50+AL46+AL47+AL48+AL49 -> 949 | AM50: =AL50+AM46+AM47+AM48+AM49 -> 950 | AN50: =AM50+AN46+AN47+AN48+AN49 -> 976 | AO50: =AN50 -> 976 | AP50: =AO50+AP46+AP47+AP48+AP49 -> 995 | AQ50: =AP50+AQ46+AQ47+AQ48+AQ49 -> 1009 | AR50: =AQ50+AR46+AR47+AR48+AR49 -> 1024 | AS50: =AR50+AS46+AS47+AS48+AS49 -> 1060 | AT50: =AS50 -> 1060 | AU50: =AT50+AU46+AU47+AU48+AU49 -> 1113 | AV50: =AU50+AV46+AV47+AV48+AV49 -> 1128 | AW50: =AV50+AW46+AW47+AW48+AW49 -> 1141 | AX50: =AW50+AX46+AX47+AX48+AX49 -> 1164 | AY50: =AX50 -> 1164 | AZ50: =AY50+AZ46+AZ47+AZ48+AZ49 -> 1184 | BA50: =AZ50+BA46+BA47+BA48+BA49 -> 1204 | BB50: =BA50+BB46+BB47+BB48+BB49 -> 1228 | BC50: =BB50+BC46+BC47+BC48+BC49 -> 1258 | BD50: =BC50 -> 1258 | BE50: =BD50+BE46+BE47+BE48+BE49 -> 1283 | BF50: =BE50+BF46+BF47+BF48+BF49 -> 1308 | BG50: =BF50+BG46+BG47+BG48+BG49 -> 1338 | BH50: =BG50+BH46+BH47+BH48+BH49 -> 1368 | BI50: =BH50 -> 1368
A52: System-Wide Stores | B52: =B43+B50 -> 956 | C52: =C43+C50 -> 1052 | D52: =D43+D50 -> 1055 | E52: =E43+E50 -> 1068 | F52: =F50+F43 -> 1068 | G52: =G43+G50 -> 1076 | H52: =H43+H50 -> 1108 | I52: =I43+I50 -> 1113 | J52: =J43+J50 -> 1127 | K52: =K50+K43 -> 1127 | L52: =L43+L50 -> 1139 | M52: =M43+M50 -> 1141 | N52: =N43+N50 -> 1154 | O52: =O43+O50 -> 1242 | P52: =P50+P43 -> 1242 | Q52: =Q43+Q50 -> 1301 | R52: =R43+R50 -> 1327 | S52: =S43+S50 -> 1352 | T52: =T43+T50 -> 1385 | U52: =U50+U43 -> 1385 | V52: =V43+V50 -> 1407 | W52: =W43+W50 -> 1419 | X52: =X43+X50 -> 1432 | Y52: =Y43+Y50 -> 1462 | Z52: =Z50+Z43 -> 1462 | AA52: =AA43+AA50 -> 1533 | AB52: =AB43+AB50 -> 1548 | AC52: =AC43+AC50 -> 1569 | AD52: =AD43+AD50 -> 1594 | AE52: =AE50+AE43 -> 1594 | AF52: =AF50+AF43 -> 1635 | AG52: =AG50+AG43 -> 1661 | AH52: =AH50+AH43 -> 1690 | AI52: =AI50+AI43 -> 1715 | AJ52: =AJ50+AJ43 -> 1715 | AK52: =AK50+AK43 -> 1746 | AL52: =AL50+AL43 -> 1781 | ... BI52: =BI50+BI43 -> 2729
A54: Sales Analysis:
A55: SSS Contribution | AF55: =AA59*(1+(AF83/100)) -> 524.987 | AG55: =AB59*(1+(AG83/100)) -> 529.308 | AH55: =AC59*(1+(AH83/100)) -> 578.074 | AI55: =AD59*(1+(AI83/100)) -> 605.7324 | AK55: =AF59*(1+(AK83/100)) -> 616.4571 | AL55: =AG59*(1+(AL83/100)) -> 632.195 | AM55: =AH59*(1+(AM83/100)) -> 686.7 | AN55: =AI59*(1+(AN83/100)) -> 706.09 | AP55: =AK59*(1+(AP83/100)) -> 689.724 | AQ55: =AL59*(1+(AQ83/100)) -> 710.7123 | AR55: =AM59*(1+(AR83/100)) -> 766.374 | AS55: =AN59*(1+(AS83/100)) -> 778.1682 | AU55: =AP59*(1+(AU83/100)) -> 780.60403 | AV55: =AQ59*(1+(AV83/100)) -> 789.20289 | AW55: =AR59*(1+(AW83/100)) -> 847.84258 | AX55: =AS59*(1+(AX83/100)) -> 876.30332 | AZ55: =AU59*(1+(AZ83/100)) -> 867.8774 | BA55: =AV59*(1+(BA83/100)) -> 869.66681 | BB55: =AW59*(1+(BB83/100)) -> 940.76461 | BC55: =AX59*(1+(BC83/100)) -> 964.7901 | BE55: =AZ59*(1+(BE83/100)) -> 956.39408 | BF55: =BA59*(1+(BF83/100)) -> 986.49364 | BG55: =BB59*(1+(BG83/100)) -> 1056.2241 | BH55: =BC59*(1+(BH83/100)) -> 1095.8242
A56: Net New Store Contribution | AF56: =AF59-AF55 -> 25.913 | AG56: =AG59-AG55 -> 27.692 | AH56: =AH59-AH55 -> 32.326 | AI56: =AI59-AI55 -> 36.1676 | AK56: =AK59-AK55 -> 27.5429 | AL56: =AL59-AL55 -> 27.705 | AM56: =AM59-AM55 -> 32.9 | AN56: =AN59-AN55 -> 32.21 | AP56: =AP59-AP55 -> 33.176 | AQ56: =AQ59-AQ55 -> 35.3877 | AR56: =AR59-AR55 -> 42.126 | AS56: =AS59-AS55 -> 48.6318 | AU56: =AU59-AU55 -> 39.695966 | AV56: =AV59-AV55 -> 36.297106 | AW56: =AW59-AW55 -> 41.757416 | AX56: =AX59-AX55 -> 42.096677 | AZ56: =AZ59-AZ55 -> 55.7226 | BA56: =(BA57*(BA39+BA40+BA41+BA46+BA47+AZ39+AZ40+AZ41+AZ46+AZ47+AX39+AX40+AX41+AX46+AX47+AW39+AW40+AW41+AW46+AW47))+(BA57*(BA42+AZ42+AX42+AW42+BA49+AZ49+AX49+AW49)) -> 78.43 | BB56: =(BB57*(BB39+BB40+BB41+BB46+BB47+BA39+BA40+BA41+BA46+BA47+AZ39+AZ40+AZ41+AZ46+AZ47+AX39+AX40+AX41+AX46+AX47))+(BB57*(BB42+BA42+AZ42+AX42+BB49+BA49+AZ49+AX49)) -> 77.28 | BC56: =(BC57*(BC39+BC40+BC41+BC46+BC47+BB39+BB40+BB41+BB46+BB47+BA39+BA40+BA41+BA46+BA47+AZ39+AZ40+AZ41+AZ46+AZ47))+(BC57*(BC42+BB42+BA42+AZ42+BC49+BB49+BA49+AZ49)) -> 87.88 | BE56: =(BE57*(BE39+BE40+BE41+BE46+BE47+BC39+BC40+BC41+BC46+BC47+BB39+BB40+BB41+BB46+BB47+BA39+BA40+BA41+BA46+BA47))+(BE57*(BE42+BC42+BB42+BA42+BE49+BC49+BB49+BA49)) -> 46.32 | BF56: =(BF57*(BF39+BF40+BF41+BF46+BF47+BE39+BE40+BE41+BE46+BE47+BC39+BC40+BC41+BC46+BC47+BB39+BB40+BB41+BB46+BB47))+(BF57*(BF42+BE42+BC42+BB42+BF49+BE49+BC49+BB49)) -> 48.75 | BG56: =(BG57*(BG39+BG40+BG41+BG46+BG47+BF39+BF40+BF41+BF46+BF47+BE39+BE40+BE41+BE46+BE47+BC39+BC40+BC41+BC46+BC47))+(BG57*(BG42+BF42+BE42+BC42+BG49+BF49+BE49+BC49)) -> 56.28 | BH56: =(BH57*(BH39+BH40+BH41+BH46+BH47+BG39+BG40+BG41+BG46+BG47+BF39+BF40+BF41+BF46+BF47+BE39+BE40+BE41+BE46+BE47))+(BH57*(BH42+BG42+BF42+BE42+BH49+BG49+BF49+BE49)) -> 44.22
...

Sheet BS
A5: Valvoline Inc. (VVV)
A6: Consolidated Balance Sheet
A7: ($M's, except per share) | B7: =IS!B7 -> 1Q16 | C7: =IS!C7 -> 2Q16 | D7: =IS!D7 -> 3Q16 | E7: =IS!E7 -> 4Q16 | F7: =IS!F7 -> FY16 | G7: =IS!G7 -> 1Q17 | H7: =IS!H7 -> 2Q17 | I7: =IS!I7 -> 3Q17 | ... BI7: =IS!BI7 -> FY27E
A9: Assets
A10: Current assets:
A11: Cash and equivalents | E11: 172 | F11: =E11 -> 172 | G11: 236 | H11: 135 | I11: 132 | J11: 201 | K11: =J11 -> 201 | L11: 115 | M11: 127 | N11: 107 | O11: 96 | P11: =O11 -> 96 | Q11: 99 | R11: 114 | S11: 126 | T11: 159 | U11: =T11 -> 159 | V11: 162 | W11: 774 | X11: 751 | Y11: 760 | Z11: =Y11 -> 760 | AA11: 527 | AB11: 247 | AC11: 226 | AD11: 230 | AE11: =AD11 -> 230 | AF11: 152 | AG11: 118 | AH11: 98 | AI11: 23.4 | AJ11: =AI11 -> 23.4 | AK11: 21 | AL11: 2334.5 | AM11: 526.7 | AN11: 409.1 | AO11: =AN11 -> 409.1 | AP11: 420.7 | AQ11: 494.5 | AR11: 65.7 | AS11: 68.3 | AT11: =AS11 -> 68.3 | AU11: 60 | AV11: 61.9 | AW11: 68.3 | AX11: 51.6 | AY11: =AX11 -> 51.6 | AZ11: 69.9 | BA11: =CF!BA42 -> 71.058486 | BB11: =CF!BB42 -> 74.260016 | BC11: =CF!BC42 -> 76.878199 | BD11: =BC11 -> 76.878199 | BE11: =CF!BE42 -> 79.015504 | BF11: =CF!BF42 -> 81.348377 | BG11: =CF!BG42 -> 84.509122 | BH11: =CF!BH42 -> 88.150574 | BI11: =BH11 -> 88.150574
A12: Receivables | E12: 363 | F12: =E12 -> 363 | G12: 353 | H12: 405 | I12: 403 | J12: 385 | K12: =J12 -> 385 | L12: 418 | M12: 435 | N12: 461 | O12: 409 | P12: =O12 -> 409 | Q12: 331 | R12: 368 | S12: 423 | T12: 401 | U12: =T12 -> 401 | V12: 395 | W12: 352 | X12: 396 | Y12: 433 | Z12: =Y12 -> 433 | AA12: 430 | AB12: 448 | AC12: 490 | AD12: 496 | AE12: =AD12 -> 496 | AF12: 530 | AG12: 563 | AH12: 583 | AI12: 66.1 | AJ12: =AI12 -> 66.1 | AK12: 56.9 | AL12: 61.1 | AM12: 71.9 | AN12: 81.3 | AO12: =AN12 -> 81.3 | AP12: 83.5 | AQ12: 109.6 | AR12: 97.5 | AS12: 86.4 | AT12: =AS12 -> 86.4 | AU12: 84.7 | AV12: 86.1 | AW12: 89.8 | AX12: 89.6 | AY12: =AX12 -> 89.6 | AZ12: 98.5 | BA12: =2*(BA70/BA79)-AZ12 -> 99.821968 | BB12: =2*(BB70/BB79)-BA12 -> 104.23436 | BC12: =2*(BC70/BC79)-BB12 -> 107.1859 | BD12: =BC12 -> 107.1859 | BE12: =2*(BE70/BE79)-BD12 -> 111.27148 | BF12: =2*(BF70/BF79)-BE12 -> 116.20769 | BG12: =2*(BG70/BG79)-BF12 -> 121.36048 | BH12: =2*(BH70/BH79)-BG12 -> 126.9202 | BI12: =BH12 -> 126.9202
A13: Inventories | E13: 139 | F13: =E13 -> 139 | G13: 141 | H13: 156 | I13: 181 | J13: 175 | K13: =J13 -> 175 | L13: 170 | M13: 194 | N13: 196 | O13: 176 | P13: =O13 -> 176 | Q13: 200 | R13: 192 | S13: 200 | T13: 194 | U13: =T13 -> 194 | V13: 194 | W13: 209 | X13: 189 | Y13: 199 | Z13: =Y13 -> 199 | AA13: 213 | AB13: 218 | AC13: 247 | AD13: 258 | AE13: =AD13 -> 258 | AF13: 264 | AG13: 276 | AH13: 306 | AI13: 29.4 | AJ13: =AI13 -> 29.4 | AK13: 31.2 | AL13: 33.5 | AM13: 34.1 | AN13: 33.3 | AO13: =AN13 -> 33.3 | AP13: 31.5 | AQ13: 37.5 | AR13: 40.2 | AS13: 39.7 | AT13: =AS13 -> 39.7 | AU13: 38 | AV13: 41.5 | AW13: 41.3 | AX13: 42.6 | AY13: =AX13 -> 42.6 | AZ13: 48.5 | BA13: =2*(BA71/BA78)-AZ13 -> 48.66322 | BB13: =2*(BB71/BB78)-BA13 -> 50.60637 | BC13: =2*(BC71/BC78)-BB13 -> 52.456515 | BD13: =BC13 -> 52.456515 | BE13: =2*(BE71/BE78)-BD13 -> 54.311853 | BF13: =2*(BF71/BF78)-BE13 -> 55.590687 | BG13: =2*(BG71/BG78)-BF13 -> 57.593763 | BH13: =2*(BH71/BH78)-BG13 -> 60.363968 | BI13: =BH13 -> 60.363968
A14: Prepaid expenses and other current assets | E14: 56 | F14: =E14 -> 56 | G14: 29 | H14: 36 | I14: 32 | J14: 29 | K14: =J14 -> 29 | L14: 32 | M14: 39 | N14: 26 | O14: 44 | P14: =O14 -> 44 | Q14: 38 | R14: 59 | S14: 52 | T14: 43 | U14: =T14 -> 43 | V14: 43 | W14: 49 | X14: 43 | Y14: 46 | Z14: =Y14 -> 46 | AA14: 44 | AB14: 55 | AC14: 53 | AD14: 53 | AE14: =AD14 -> 53 | AF14: 55 | AG14: 59 | AH14: 64 | AI14: 38 | AJ14: =AI14 -> 38 | AK14: 38.7 | AL14: 29 | AM14: =30.3+424.1 -> 454.4 | AN14: =65.5+347.5 -> 413 | AO14: =AN14 -> 413 | AP14: =55.2+119.7 -> 174.9 | AQ14: 59.8 | AR14: 53 | AS14: 61 | AT14: =AS14 -> 61 | AU14: 30 | AV14: 40.5 | AW14: 39.6 | AX14: 59.9 | AY14: =AX14 -> 59.9 | AZ14: 38.3 | BA14: =AZ14 -> 38.3 | BB14: =BA14 -> 38.3 | BC14: =BB14 -> 38.3 | BD14: =BC14 -> 38.3 | BE14: =BD14 -> 38.3 | BF14: =BE14 -> 38.3 | BG14: =BF14 -> 38.3 | BH14: =BG14 -> 38.3 | BI14: =BH14 -> 38.3
A15: Current assets of discontinued operations | E15: 0 | F15: =E15 -> 0 | G15: 0 | H15: 0 | I15: 0 | J15: 0 | K15: =J15 -> 0 | L15: 0 | M15: 0 | N15: 0 | O15: 0 | P15: =O15 -> 0 | Q15: 0 | R15: 0 | S15: 0 | T15: 0 | U15: =T15 -> 0 | V15: 0 | W15: 0 | X15: 0 | Y15: 0 | Z15: =Y15 -> 0 | AA15: 0 | AB15: 0 | AC15: 0 | AD15: 0 | AE15: =AD15 -> 0 | AF15: 0 | AG15: 0 | AH15: 0 | AI15: 1464.2 | AJ15: =AI15 -> 1464.2 | AK15: 1553.6 | AL15: 0 | AM15: =AL15 -> 0 | AN15: =AM15 -> 0 | AO15: =AN15 -> 0 | AP15: =AO15 -> 0 | AQ15: =AP15 -> 0 | AR15: 0 | AS15: =AR15 -> 0 | AT15: =AS15 -> 0 | AU15: =AT15 -> 0 | AV15: =AU15 -> 0 | AW15: =AV15 -> 0 | AX15: =AW15 -> 0 | AY15: =AX15 -> 0 | AZ15: =AY15 -> 0 | ... BI15: =BH15 -> 0
A16: Total current assets | E16: =SUM(E11:E15) -> 730 | F16: =SUM(F11:F15) -> 730 | G16: =SUM(G11:G15) -> 759 | H16: =SUM(H11:H15) -> 732 | I16: =SUM(I11:I15) -> 748 | J16: =SUM(J11:J15) -> 790 | K16: =SUM(K11:K15) -> 790 | L16: =SUM(L11:L15) -> 735 | ... BI16: =SUM(BI11:BI15) -> 313.73474
A18: Property, Plant and Equipment | E18: 324 | F18: =E18 -> 324 | G18: 331 | H18: 349 | I18: 369 | J18: 391 | K18: =J18 -> 391 | L18: 384 | M18: 390 | N18: 399 | O18: 420 | P18: =O18 -> 420 | Q18: 428 | R18: 441 | S18: 455 | T18: 498 | U18: =T18 -> 498 | V18: 479 | W18: 509 | X18: 559 | Y18: 613 | Z18: =Y18 -> 613 | AA18: 713 | AB18: 741 | AC18: 773 | AD18: 817 | AE18: =AD18 -> 817 | AF18: 824 | AG18: 843 | AH18: 874 | AI18: 668.6 | AJ18: =AI18 -> 668.6 | AK18: 693.3 | AL18: 722.5 | AM18: 761.6 | AN18: 818.3 | AO18: =AN18 -> 818.3 | AP18: 841.5 | AQ18: 877.9 | AR18: 927.2 | AS18: 958.7 | AT18: =AS18 -> 958.7 | AU18: 934.14 | AV18: 995.5 | AW18: 1050.5 | AX18: 1134.6 | AY18: =AX18 -> 1134.6 | AZ18: 1217.3 | BA18: =AZ18 -> 1217.3 | BB18: =BA18 -> 1217.3 | BC18: =BB18 -> 1217.3 | BD18: =BC18 -> 1217.3 | BE18: =BD18 -> 1217.3 | BF18: =BE18 -> 1217.3 | BG18: =BF18 -> 1217.3 | BH18: =BG18 -> 1217.3 | BI18: =BH18 -> 1217.3
A19: Operating lease assets | E19: 0 | F19: =E19 -> 0 | G19: 0 | H19: 0 | I19: 0 | J19: 0 | K19: =J19 -> 0 | L19: 0 | M19: 0 | N19: 0 | O19: 0 | P19: =O19 -> 0 | Q19: 0 | R19: 0 | S19: 0 | T19: 0 | U19: =T19 -> 0 | V19: 253 | W19: 254 | X19: 261 | Y19: 261 | Z19: =Y19 -> 261 | AA19: 293 | AB19: 299 | AC19: 311 | AD19: 307 | AE19: =AD19 -> 307 | AF19: 309 | AG19: 313 | AH19: 321 | AI19: 248.1 | AJ19: =AI19 -> 248.1 | AK19: 253.5 | AL19: 258.7 | AM19: 264.3 | AN19: 266.5 | AO19: =AN19 -> 266.5 | AP19: 273.1 | AQ19: 288.1 | AR19: 289.3 | AS19: 298.6 | AT19: =AS19 -> 298.6 | AU19: 290.7 | AV19: 313.2 | AW19: 329.3 | AX19: 331.8 | AY19: =AX19 -> 331.8 | AZ19: 403.3 | BA19: =AZ19 -> 403.3 | BB19: =BA19 -> 403.3 | BC19: =BB19 -> 403.3 | BD19: =BC19 -> 403.3 | BE19: =BD19 -> 403.3 | BF19: =BE19 -> 403.3 | BG19: =BF19 -> 403.3 | BH19: =BG19 -> 403.3 | BI19: =BH19 -> 403.3
A20: Goodwill and Intangibles | E20: 267 | F20: =E20 -> 267 | G20: 270 | H20: 317 | I20: 334 | J20: 335 | K20: =J20 -> 335 | L20: 393 | M20: 396 | N20: 398 | O20: 448 | P20: =O20 -> 448 | Q20: 473 | R20: 478 | S20: 490 | T20: 504 | U20: =T20 -> 504 | V20: 507 | W20: 503 | X20: 510 | Y20: 529 | Z20: =Y20 -> 529 | AA20: 739 | AB20: 732 | AC20: 773 | AD20: 775 | AE20: =AD20 -> 775 | AF20: 782 | AG20: 788 | AH20: 804 | AI20: 663.1 | AJ20: =AI20 -> 663.1 | AK20: 668.2 | AL20: 673.1 | AM20: 678 | AN20: 680.6 | AO20: =AN20 -> 680.6 | AP20: 685.6 | AQ20: 692.3 | AR20: 693.7 | AS20: 705.6 | AT20: =AS20 -> 705.6 | AU20: 689.5 | AV20: 690.8 | AW20: 713.1 | AX20: 740.5 | AY20: =AX20 -> 740.5 | AZ20: 1304.9 | BA20: =AZ20 -> 1304.9 | BB20: =BA20 -> 1304.9 | BC20: =BB20 -> 1304.9 | BD20: =BC20 -> 1304.9 | BE20: =BD20 -> 1304.9 | BF20: =BE20 -> 1304.9 | BG20: =BF20 -> 1304.9 | BH20: =BG20 -> 1304.9 | BI20: =BH20 -> 1304.9
A21: Deferred Tax Assets | E21: 389 | F21: =E21 -> 389 | G21: 386 | H21: 393 | I21: 394 | J21: 281 | K21: =J21 -> 281 | L21: 196 | M21: 171 | N21: 147 | O21: 138 | P21: =O21 -> 138 | Q21: 134 | R21: 125 | S21: 113 | T21: 123 | U21: =T21 -> 123 | V21: 116 | W21: 99 | X21: 82 | Y21: 34 | Z21: =Y21 -> 34 | AA21: 28 | AB21: 19 | AC21: 10 | AD21: 14 | AE21: =AD21 -> 14 | AF21: 13 | AG21: 13 | AH21: 0 | AI21: 61.6 | AJ21: =AI21 -> 61.6 | AK21: 82.2 | AL21: 0 | AM21: =AL21 -> 0 | AN21: =AM21 -> 0 | AO21: =AN21 -> 0 | AP21: =AO21 -> 0 | AQ21: 0 | AR21: 0 | AS21: =AR21 -> 0 | AT21: =AS21 -> 0 | AU21: =AT21 -> 0 | AV21: =AU21 -> 0 | AW21: =AV21 -> 0 | AX21: =AW21 -> 0 | AY21: =AX21 -> 0 | AZ21: =AY21 -> 0 | ... BI21: =BH21 -> 0
A22: Other assets | E22: =26+89 -> 115 | F22: =E22 -> 115 | G22: 89 | H22: =86+30 -> 116 | I22: =86+29 -> 115 | J22: =88+30 -> 118 | K22: =J22 -> 118 | L22: =33+86 -> 119 | M22: =34+83 -> 117 | N22: =33+82 -> 115 | O22: =92+31 -> 123 | P22: =O22 -> 123 | Q22: =97+32 -> 129 | R22: =103+34 -> 137 | S22: =106+35 -> 141 | T22: =108+34 -> 142 | U22: =T22 -> 142 | V22: =109+39 -> 148 | W22: =131+37 -> 168 | X22: =133+39 -> 172 | Y22: =132+44 -> 176 | Z22: =Y22 -> 176 | AA22: =123+46 -> 169 | AB22: =117+45 -> 162 | AC22: =119+47 -> 166 | AD22: =194+47 -> 241 | AE22: =AD22 -> 241 | AF22: =204+50 -> 254 | AG22: =222+53 -> 275 | AH22: =250+48 -> 298 | AI22: 154.3 | AJ22: =AI22 -> 154.3 | AK22: 152.9 | AL22: 168 | AM22: 194.5 | AN22: 187.8 | AO22: =AN22 -> 187.8 | AP22: 198.5 | AQ22: 203.3 | AR22: 209 | AS22: 220.4 | AT22: =AS22 -> 220.4 | AU22: 222.8 | AV22: 223.1 | AW22: 229.7 | AX22: 219.8 | AY22: =AX22 -> 219.8 | AZ22: 221.4 | BA22: =AZ22 -> 221.4 | BB22: =BA22 -> 221.4 | BC22: =BB22 -> 221.4 | BD22: =BC22 -> 221.4 | BE22: =BD22 -> 221.4 | BF22: =BE22 -> 221.4 | BG22: =BF22 -> 221.4 | BH22: =BG22 -> 221.4 | BI22: =BH22 -> 221.4
A23: Total assets | E23: =E16+SUM(E18:E22) -> 1825 | F23: =E23 -> 1825 | G23: =G16+SUM(G18:G22) -> 1835 | H23: =H16+SUM(H18:H22) -> 1907 | I23: =I16+SUM(I18:I22) -> 1960 | J23: =J16+SUM(J18:J22) -> 1915 | K23: =J23 -> 1915 | L23: =L16+SUM(L18:L22) -> 1827 | M23: =M16+SUM(M18:M22) -> 1869 | N23: =N16+SUM(N18:N22) -> 1849 | O23: =O16+SUM(O18:O22) -> 1854 | P23: =O23 -> 1854 | Q23: =Q16+SUM(Q18:Q22) -> 1832 | R23: =R16+SUM(R18:R22) -> 1914 | S23: =S16+SUM(S18:S22) -> 2000 | T23: =T16+SUM(T18:T22) -> 2064 | U23: =T23 -> 2064 | V23: =V16+SUM(V18:V22) -> 2297 | W23: =W16+SUM(W18:W22) -> 2917 | X23: =X16+SUM(X18:X22) -> 2963 | Y23: =Y16+SUM(Y18:Y22) -> 3051 | Z23: =Y23 -> 3051 | AA23: =AA16+SUM(AA18:AA22) -> 3156 | AB23: =AB16+SUM(AB18:AB22) -> 2921 | AC23: =AC16+SUM(AC18:AC22) -> 3049 | AD23: =AD16+SUM(AD18:AD22) -> 3191 | AE23: =AD23 -> 3191 | AF23: =AF16+SUM(AF18:AF22) -> 3183 | AG23: =AG16+SUM(AG18:AG22) -> 3248 | AH23: =AH16+SUM(AH18:AH22) -> 3348 | AI23: =AI16+SUM(AI18:AI22) -> 3416.8 | AJ23: =AI23 -> 3416.8 | AK23: =AK16+SUM(AK18:AK22) -> 3551.5 | AL23: =AL16+SUM(AL18:AL22) -> 4280.4 | AM23: =AM16+SUM(AM18:AM22) -> 2985.5 | AN23: =AN16+SUM(AN18:AN22) -> 2889.9 | AO23: =AN23 -> 2889.9 | AP23: =AP16+SUM(AP18:AP22) -> 2709.3 | AQ23: =AQ16+SUM(AQ18:AQ22) -> 2763 | AR23: =AR16+SUM(AR18:AR22) -> 2375.6 | AS23: =AS16+SUM(AS18:AS22) -> 2438.7 | AT23: =AS23 -> 2438.7 | AU23: =AU16+SUM(AU18:AU22) -> 2349.84 | AV23: =AV16+SUM(AV18:AV22) -> 2452.6 | AW23: =AW16+SUM(AW18:AW22) -> 2561.6 | AX23: =AX16+SUM(AX18:AX22) -> 2670.4 | AY23: =AX23 -> 2670.4 | AZ23: =AZ16+SUM(AZ18:AZ22) -> 3402.1 | BA23: =BA16+SUM(BA18:BA22) -> 3404.7437 | BB23: =BB16+SUM(BB18:BB22) -> 3414.3007 | BC23: =BC16+SUM(BC18:BC22) -> 3421.7206 | BD23: =BC23 -> 3421.7206 | BE23: =BE16+SUM(BE18:BE22) -> 3429.7988 | BF23: =BF16+SUM(BF18:BF22) -> 3438.3468 | BG23: =BG16+SUM(BG18:BG22) -> 3448.6634 | BH23: =BH16+SUM(BH18:BH22) -> 3460.6347 | BI23: =BH23 -> 3460.6347
A25: Liabilities and Shareholders' Equity
A26: Current liabilities:
A27: Current portion of LT debt | E27: 19 | F27: =E27 -> 19 | G27: =15+75 -> 90 | H27: =75+16 -> 91 | I27: =75+15 -> 90 | J27: 90 | K27: =J27 -> 90 | L27: 19 | M27: 23 | N27: 26 | O27: 30 | P27: =O27 -> 30 | Q27: 30 | R27: 30 | S27: 7 | T27: 15 | U27: =T27 -> 15 | V27: 32 | W27: 0 | X27: 0 | Y27: 0 | Z27: =Y27 -> 0 | AA27: 88 | AB27: 1 | AC27: 2 | AD27: 17 | AE27: =AD27 -> 17 | AF27: 32 | AG27: 47 | AH27: 61 | AI27: 162.5 | AJ27: =AI27 -> 162.5 | AK27: 224.5 | AL27: 23.8 | AM27: 23.7 | AN27: 23.8 | AO27: =AN27 -> 23.8 | AP27: 23.8 | AQ27: 623.8 | AR27: 23.8 | AS27: 23.8 | AT27: =AS27 -> 23.8 | AU27: 23.8 | AV27: 23.8 | AW27: 23.8 | AX27: 23.8 | AY27: =AX27 -> 23.8 | AZ27: 31.2 | BA27: =AZ27 -> 31.2 | BB27: =BA27 -> 31.2 | BC27: =BB27 -> 31.2 | BD27: =BC27 -> 31.2 | BE27: =BD27 -> 31.2 | BF27: =BE27 -> 31.2 | BG27: =BF27 -> 31.2 | BH27: =BG27 -> 31.2 | BI27: =BH27 -> 31.2
A28: Trade accounts payable | E28: 177 | F28: =E28 -> 177 | G28: 146 | H28: 170 | I28: 196 | J28: 192 | K28: =J28 -> 192 | L28: 141 | M28: 194 | N28: 176 | O28: 178 | P28: =O28 -> 178 | Q28: 152 | R28: 154 | S28: 163 | T28: 171 | U28: =T28 -> 171 | V28: 218 | W28: 186 | X28: 178 | Y28: 189 | Z28: =Y28 -> 189 | AA28: 158 | AB28: 180 | AC28: 216 | AD28: 246 | AE28: =AD28 -> 246 | AF28: 218 | AG28: 238 | AH28: 265 | AI28: 45 | AJ28: =AI28 -> 45 | AK28: 46.6 | AL28: 85.8 | AM28: 96.4 | AN28: 118.7 | AO28: =AN28 -> 118.7 | AP28: 77.2 | AQ28: 118.8 | AR28: 107.7 | AS28: 117.4 | AT28: =AS28 -> 117.4 | AU28: 88.3 | AV28: 102.5 | AW28: 100.8 | AX28: 118.9 | AY28: =AX28 -> 118.9 | AZ28: 113.4 | BA28: =2*(BA71/BA80)-AZ28 -> 115.88538 | BB28: =2*(BB71/BB80)-BA28 -> 116.56796 | BC28: =2*(BC71/BC80)-BB28 -> 117.34609 | BD28: =BC28 -> 117.34609 | BE28: =2*(BE71/BE80)-BD28 -> 122.02783 | BF28: =2*(BF71/BF80)-BE28 -> 125.05522 | BG28: =2*(BG71/BG80)-BF28 -> 125.48118 | BH28: =2*(BH71/BH80)-BG28 -> 129.47308 | BI28: =BH28 -> 129.47308
A29: Federal and state income taxes payable | E29: 0 | F29: =E29 -> 0 | G29: 0 | H29: 0 | I29: 0 | J29: 0 | K29: =J29 -> 0 | L29: 0 | M29: 0 | N29: 0 | O29: 0 | P29: =O29 -> 0 | Q29: 0 | R29: 0 | S29: 0 | T29: 0 | U29: =T29 -> 0 | V29: 0 | W29: 0 | X29: 0 | Y29: 0 | Z29: =Y29 -> 0 | AA29: 0 | AB29: 0 | AC29: 0 | AD29: 0 | AE29: =AD29 -> 0 | AF29: 0 | AG29: 0 | AH29: 0 | AI29: 0 | AJ29: =AI29 -> 0 | AK29: 0 | AL29: 0 | AM29: =AL29 -> 0 | AN29: =AM29 -> 0 | AO29: =AN29 -> 0 | AP29: =AO29 -> 0 | AQ29: 0 | AR29: 0 | AS29: =AR29 -> 0 | AT29: =AS29 -> 0 | AU29: =AT29 -> 0 | AV29: =AU29 -> 0 | AW29: =AV29 -> 0 | AX29: =AW29 -> 0 | AY29: =AX29 -> 0 | AZ29: =AY29 -> 0 | ... BI29: =BH29 -> 0
A30: Current liabilities held for sale | E30: 0 | F30: =E30 -> 0 | G30: 0 | H30: 0 | I30: 0 | J30: 0 | K30: =J30 -> 0 | L30: 0 | M30: 0 | N30: 0 | O30: 0 | P30: =O30 -> 0 | Q30: 0 | R30: 0 | S30: 0 | T30: 0 | U30: =T30 -> 0 | V30: 0 | W30: 0 | X30: 0 | Y30: 0 | Z30: =Y30 -> 0 | AA30: 0 | AB30: 0 | AC30: 0 | AD30: 0 | AE30: =AD30 -> 0 | AF30: 0 | AG30: 0 | AH30: 0 | AI30: 539.3 | AJ30: =AI30 -> 539.3 | AK30: 478.1 | AL30: 0 | AM30: =AL30 -> 0 | AN30: =AM30 -> 0 | AO30: =AN30 -> 0 | AP30: =AO30 -> 0 | AQ30: 0 | AR30: 0 | AS30: =AR30 -> 0 | AT30: =AS30 -> 0 | AU30: =AT30 -> 0 | AV30: =AU30 -> 0 | AW30: =AV30 -> 0 | AX30: =AW30 -> 0 | AY30: =AX30 -> 0 | AZ30: =AY30 -> 0 | ... BI30: =BH30 -> 0
A31: Accrued expenses and other liabilities | E31: 204 | F31: =E31 -> 204 | G31: 257 | H31: 210 | I31: 235 | J31: 196 | K31: =J31 -> 196 | L31: 208 | M31: 198 | N31: 223 | O31: 203 | P31: =O31 -> 203 | Q31: 198 | R31: 206 | S31: 242 | T31: 237 | U31: =T31 -> 237 | V31: 291 | W31: 215 | X31: 254 | Y31: 255 | Z31: =Y31 -> 255 | AA31: 260 | AB31: 267 | AC31: 289 | AD31: 306 | AE31: =AD31 -> 306 | AF31: 291 | AG31: 300 | AH31: 315 | AI31: 172.6 | AJ31: =AI31 -> 172.6 | AK31: 175.2 | AL31: 512 | AM31: 285.8 | AN31: =215.9+3.9 -> 219.8 | AO31: =AN31 -> 219.8 | AP31: 216.4 | AQ31: 221.1 | AR31: 219.9 | AS31: 212.7 | AT31: =AS31 -> 212.7 | AU31: 191.5 | AV31: 189.3 | AW31: 202.9 | AX31: 204.7 | AY31: =AX31 -> 204.7 | AZ31: 219.2 | BA31: =AZ31 -> 219.2 | BB31: =BA31 -> 219.2 | BC31: =BB31 -> 219.2 | BD31: =BC31 -> 219.2 | BE31: =BD31 -> 219.2 | BF31: =BE31 -> 219.2 | BG31: =BF31 -> 219.2 | BH31: =BG31 -> 219.2 | BI31: =BH31 -> 219.2
A32: Total current liabilities | E32: =SUM(E27:E31) -> 400 | F32: =E32 -> 400 | G32: =SUM(G27:G31) -> 493 | H32: =SUM(H27:H31) -> 471 | I32: =SUM(I27:I31) -> 521 | J32: =SUM(J27:J31) -> 478 | K32: =J32 -> 478 | L32: =SUM(L27:L31) -> 368 | M32: =SUM(M27:M31) -> 415 | N32: =SUM(N27:N31) -> 425 | O32: =SUM(O27:O31) -> 411 | P32: =O32 -> 411 | Q32: =SUM(Q27:Q31) -> 380 | R32: =SUM(R27:R31) -> 390 | S32: =SUM(S27:S31) -> 412 | T32: =SUM(T27:T31) -> 423 | U32: =T32 -> 423 | V32: =SUM(V27:V31) -> 541 | W32: =SUM(W27:W31) -> 401 | X32: =SUM(X27:X31) -> 432 | Y32: =SUM(Y27:Y31) -> 444 | Z32: =Y32 -> 444 | AA32: =SUM(AA27:AA31) -> 506 | AB32: =SUM(AB27:AB31) -> 448 | AC32: =SUM(AC27:AC31) -> 507 | AD32: =SUM(AD27:AD31) -> 569 | AE32: =AD32 -> 569 | AF32: =SUM(AF27:AF31) -> 541 | AG32: =SUM(AG27:AG31) -> 585 | AH32: =SUM(AH27:AH31) -> 641 | AI32: =SUM(AI27:AI31) -> 919.4 | AJ32: =AI32 -> 919.4 | AK32: =SUM(AK27:AK31) -> 924.4 | AL32: =SUM(AL27:AL31) -> 621.6 | AM32: =SUM(AM27:AM31) -> 405.9 | AN32: =SUM(AN27:AN31) -> 362.3 | AO32: =AN32 -> 362.3 | AP32: =SUM(AP27:AP31) -> 317.4 | AQ32: =SUM(AQ27:AQ31) -> 963.7 | AR32: =SUM(AR27:AR31) -> 351.4 | AS32: =SUM(AS27:AS31) -> 353.9 | AT32: =AS32 -> 353.9 | AU32: =SUM(AU27:AU31) -> 303.6 | AV32: =SUM(AV27:AV31) -> 315.6 | AW32: =SUM(AW27:AW31) -> 327.5 | AX32: =SUM(AX27:AX31) -> 347.4 | AY32: =AX32 -> 347.4 | AZ32: =SUM(AZ27:AZ31) -> 363.8 | BA32: =SUM(BA27:BA31) -> 366.28538 | BB32: =SUM(BB27:BB31) -> 366.96796 | BC32: =SUM(BC27:BC31) -> 367.74609 | BD32: =BC32 -> 367.74609 | BE32: =SUM(BE27:BE31) -> 372.42783 | BF32: =SUM(BF27:BF31) -> 375.45522 | BG32: =SUM(BG27:BG31) -> 375.88118 | BH32: =SUM(BH27:BH31) -> 379.87308 | BI32: =BH32 -> 379.87308
A34: Long term debt | E34: 724 | F34: =E34 -> 724 | G34: 650 | H34: 646 | I34: 643 | J34: 1034 | K34: =J34 -> 1034 | L34: 1147 | M34: 1183 | N34: 1231 | O34: 1292 | P34: =O34 -> 1292 | Q34: 1291 | R34: 1318 | S34: 1334 | T34: 1327 | U34: =T34 -> 1327 | V34: 1320 | W34: 2003 | X34: 1953 | Y34: 1962 | Z34: =Y34 -> 1962 | AA34: 1887 | AB34: 1719 | AC34: 1691 | AD34: 1677 | AE34: =AD34 -> 1677 | AF34: 1662 | AG34: 1648 | AH34: 1639 | AI34: 1525.1 | AJ34: =AI34 -> 1525.1 | AK34: 1656.1 | AL34: 1573.4 | AM34: 1567.8 | AN34: 1562.3 | AO34: =AN34 -> 1562.3 | AP34: 1556.8 | AQ34: 951.3 | AR34: 1125.7 | AS34: 1070 | AT34: =AS34 -> 1070 | AU34: 1009.3 | AV34: 1051.9 | AW34: 1055.9 | AX34: 1050.2 | AY34: =AX34 -> 1050.2 | AZ34: 1633.6 | BA34: =AZ34+CF!BA30+CF!BA29 -> 1623.6 | BB34: =BA34+CF!BB30+CF!BB29 -> 1613.6 | BC34: =BB34+CF!BC30+CF!BC29 -> 1603.6 | BD34: =BC34 -> 1603.6 | BE34: =BD34+CF!BE30+CF!BE29 -> 1588.6 | BF34: =BE34+CF!BF30+CF!BF29 -> 1573.6 | BG34: =BF34+CF!BG30+CF!BG29 -> 1558.6 | BH34: =BG34+CF!BH30+CF!BH29 -> 1543.6 | BI34: =BH34 -> 1543.6
A35: Employee benefit obligations | E35: 886 | F35: =E35 -> 886 | G35: 854 | H35: 833 | I35: 811 | J35: 342 | K35: =J35 -> 342 | L35: 331 | M35: 316 | N35: 303 | O35: 333 | P35: =O35 -> 333 | Q35: 330 | R35: 325 | S35: 322 | T35: 387 | U35: =T35 -> 387 | V35: 376 | W35: 361 | X35: 350 | Y35: 317 | Z35: =Y35 -> 317 | AA35: 303 | AB35: 286 | AC35: 272 | AD35: 258 | AE35: =AD35 -> 258 | AF35: 248 | AG35: 237 | AH35: 229 | AI35: 199.4 | AJ35: =AI35 -> 199.4 | AK35: 200.5 | AL35: 201 | AM35: 202.1 | AN35: 168 | AO35: =AN35 -> 168 | AP35: 169.9 | AQ35: 170.2 | AR35: 167.8 | AS35: 176.2 | AT35: =AS35 -> 176.2 | AU35: 174.5 | AV35: 171.5 | AW35: 170.4 | AX35: 187.5 | AY35: =AX35 -> 187.5 | AZ35: 186.1 | BA35: =AZ35 -> 186.1 | BB35: =BA35 -> 186.1 | BC35: =BB35 -> 186.1 | BD35: =BC35 -> 186.1 | BE35: =BD35 -> 186.1 | BF35: =BE35 -> 186.1 | BG35: =BF35 -> 186.1 | BH35: =BG35 -> 186.1 | BI35: =BH35 -> 186.1
A36: Operating lease liabilities | E36: 0 | F36: =E36 -> 0 | G36: 0 | H36: 0 | I36: 0 | J36: 0 | K36: =J36 -> 0 | L36: 0 | M36: 0 | N36: 0 | O36: 0 | P36: =O36 -> 0 | Q36: 0 | R36: 0 | S36: 0 | T36: 0 | U36: =T36 -> 0 | V36: 224 | W36: 226 | X36: 231 | Y36: 231 | Z36: =Y36 -> 231 | AA36: 260 | AB36: 286 | AC36: 276 | AD36: 274 | AE36: =AD36 -> 274 | AF36: 276 | AG36: 280 | AH36: 288 | AI36: 229.4 | AJ36: =AI36 -> 229.4 | AK36: 234.5 | AL36: 239.6 | AM36: 245 | AN36: 247.3 | AO36: =AN36 -> 247.3 | AP36: 253.9 | AQ36: 269 | AR36: 270.3 | AS36: 279.7 | AT36: =AS36 -> 279.7 | AU36: 273.1 | AV36: 295.2 | AW36: 312.2 | AX36: 315.3 | AY36: =AX36 -> 315.3 | AZ36: 376 | BA36: =AZ36 -> 376 | BB36: =BA36 -> 376 | BC36: =BB36 -> 376 | BD36: =BC36 -> 376 | BE36: =BD36 -> 376 | BF36: =BE36 -> 376 | BG36: =BF36 -> 376 | BH36: =BG36 -> 376 | BI36: =BH36 -> 376
A37: Other long-term liabilities | E37: =143+2 -> 145 | F37: =E37 -> 145 | G37: 154 | H37: =2+173 -> 175 | I37: =2+186 -> 188 | J37: 178 | K37: =J37 -> 178 | L37: 175 | M37: 181 | N37: 178 | O37: 176 | P37: =O37 -> 176 | Q37: 174 | R37: 179 | S37: 184 | T37: 185 | U37: =T37 -> 185 | V37: 152 | W37: 163 | X37: 185 | Y37: 173 | Z37: =Y37 -> 173 | AA37: 255 | AB37: 259 | AC37: 280 | AD37: =252+26 -> 278 | AE37: =AD37 -> 278 | AF37: =255+34 -> 289 | AG37: =256+42 -> 298 | AH37: =267+58 -> 325 | AI37: 237.1 | AJ37: =AI37 -> 237.1 | AK37: 246.7 | AL37: 272.4 | AM37: 279.3 | AN37: 346.8 | AO37: =AN37 -> 346.8 | AP37: 346.5 | AQ37: 348.7 | AR37: 353.9 | AS37: 373.3 | AT37: =AS37 -> 373.3 | AU37: 359.5 | AV37: 369.7 | AW37: 382 | AX37: 431.5 | AY37: =AX37 -> 431.5 | AZ37: 535 | BA37: =AZ37 -> 535 | BB37: =BA37 -> 535 | BC37: =BB37 -> 535 | BD37: =BC37 -> 535 | BE37: =BD37 -> 535 | BF37: =BE37 -> 535 | BG37: =BF37 -> 535 | BH37: =BG37 -> 535 | BI37: =BH37 -> 535
A38: Total liabilities | E38: =SUM(E34:E37)+E32 -> 2155 | F38: =E38 -> 2155 | G38: =SUM(G34:G37)+G32 -> 2151 | H38: =SUM(H34:H37)+H32 -> 2125 | I38: =SUM(I34:I37)+I32 -> 2163 | J38: =SUM(J34:J37)+J32 -> 2032 | K38: =J38 -> 2032 | L38: =SUM(L34:L37)+L32 -> 2021 | M38: =SUM(M34:M37)+M32 -> 2095 | N38: =SUM(N34:N37)+N32 -> 2137 | O38: =SUM(O34:O37)+O32 -> 2212 | P38: =O38 -> 2212 | Q38: =SUM(Q34:Q37)+Q32 -> 2175 | R38: =SUM(R34:R37)+R32 -> 2212 | S38: =SUM(S34:S37)+S32 -> 2252 | T38: =SUM(T34:T37)+T32 -> 2322 | U38: =T38 -> 2322 | V38: =SUM(V34:V37)+V32 -> 2613 | W38: =SUM(W34:W37)+W32 -> 3154 | X38: =SUM(X34:X37)+X32 -> 3151 | Y38: =SUM(Y34:Y37)+Y32 -> 3127 | Z38: =Y38 -> 3127 | AA38: =SUM(AA34:AA37)+AA32 -> 3211 | AB38: =SUM(AB34:AB37)+AB32 -> 2998 | AC38: =SUM(AC34:AC37)+AC32 -> 3026 | AD38: =SUM(AD34:AD37)+AD32 -> 3056 | AE38: =AD38 -> 3056 | AF38: =SUM(AF34:AF37)+AF32 -> 3016 | AG38: =SUM(AG34:AG37)+AG32 -> 3048 | AH38: =SUM(AH34:AH37)+AH32 -> 3122 | AI38: =SUM(AI34:AI37)+AI32 -> 3110.4 | AJ38: =AI38 -> 3110.4 | AK38: =SUM(AK34:AK37)+AK32 -> 3262.2 | AL38: =SUM(AL34:AL37)+AL32 -> 2908 | AM38: =SUM(AM34:AM37)+AM32 -> 2700.1 | AN38: =SUM(AN34:AN37)+AN32 -> 2686.7 | AO38: =AN38 -> 2686.7 | AP38: =SUM(AP34:AP37)+AP32 -> 2644.5 | AQ38: =SUM(AQ34:AQ37)+AQ32 -> 2702.9 | AR38: =SUM(AR34:AR37)+AR32 -> 2269.1 | AS38: =SUM(AS34:AS37)+AS32 -> 2253.1 | AT38: =AS38 -> 2253.1 | AU38: =SUM(AU34:AU37)+AU32 -> 2120 | AV38: =SUM(AV34:AV37)+AV32 -> 2203.9 | AW38: =SUM(AW34:AW37)+AW32 -> 2248 | AX38: =SUM(AX34:AX37)+AX32 -> 2331.9 | AY38: =AX38 -> 2331.9 | AZ38: =SUM(AZ34:AZ37)+AZ32 -> 3094.5 | BA38: =SUM(BA34:BA37)+BA32 -> 3086.9854 | BB38: =SUM(BB34:BB37)+BB32 -> 3077.668 | BC38: =SUM(BC34:BC37)+BC32 -> 3068.4461 | BD38: =BC38 -> 3068.4461 | BE38: =SUM(BE34:BE37)+BE32 -> 3058.1278 | BF38: =SUM(BF34:BF37)+BF32 -> 3046.1552 | BG38: =SUM(BG34:BG37)+BG32 -> 3031.5812 | BH38: =SUM(BH34:BH37)+BH32 -> 3020.5731 | BI38: =BH38 -> 3020.5731
A40: Shareholders' equity
A41: Preferred stock, no par value | Q41: 0 | R41: 0 | S41: 0 | T41: 0 | U41: =T41 -> 0 | V41: 0 | W41: 0 | X41: 0 | Y41: 0 | Z41: =Y41 -> 0 | AA41: 0 | AB41: 0 | AC41: 0 | AD41: 0 | AE41: =AD41 -> 0 | AF41: 0 | AG41: 0 | AH41: 0 | AI41: 0 | AJ41: =AI41 -> 0 | AK41: 0 | AL41: 0 | AM41: 0 | AN41: 0 | AO41: =AN41 -> 0 | AT41: =AS41 -> 0
A42: Common Stock | Q42: 2 | R42: 2 | S42: 2 | T42: 2 | U42: =T42 -> 2 | V42: 2 | W42: 2 | X42: 2 | Y42: 2 | Z42: =Y42 -> 2 | AA42: 2 | AB42: 2 | AC42: 2 | AD42: 2 | AE42: =AD42 -> 2 | AF42: 2 | AG42: 2 | AH42: 2 | AI42: 1.8 | AJ42: =AI42 -> 1.8 | AK42: 1.7 | AL42: 1.7 | AM42: 1.4 | AN42: 1.3 | AO42: =AN42 -> 1.3 | AP42: 1.3 | AQ42: 1.3 | AR42: 1.3 | AS42: 1.3 | AT42: =AS42 -> 1.3 | AU42: 1.3 | AV42: 1.3 | AW42: 1.3
A43: Paid-in capital | Q43: 8 | R43: 10 | S43: 13 | T43: 13 | U43: =T43 -> 13 | V43: 16 | W43: 16 | X43: 20 | Y43: 24 | Z43: =Y43 -> 24 | AA43: 25 | AB43: 29 | AC43: 32 | AD43: 35 | AE43: =AD43 -> 35 | AF43: 33 | AG43: 36 | AH43: 41 | AI43: 44.1 | AJ43: =AI43 -> 44.1 | AK43: 40.8 | AL43: 42.6 | AM43: 44.8 | AN43: 48 | AO43: =AN43 -> 48 | AP43: 46.3 | AQ43: 45.3 | AR43: 48.9 | AS43: 51.2 | AT43: =AS43 -> 51.2 | AU43: 50.3 | AV43: 52.8 | AW43: 55.5
A44: Retained earnings | Q44: -379 | R44: -336 | S44: -291 | T44: -284 | U44: =T44 -> -284 | V44: -231 | W44: -249 | X44: -211 | Y44: -110 | Z44: =Y44 -> -110 | AA44: -106 | AB44: -103 | AC44: -29 | AD44: 90 | AE44: =AD44 -> 90 | AF44: 123 | AG44: 147 | AH44: 186 | AI44: 282 | AJ44: =AI44 -> 282 | AK44: 254.6 | AL44: 1310.2 | AM44: 222.2 | AN44: 140.7 | AO44: =AN44 -> 140.7 | AP44: -0.2 | AQ44: 0.4 | AR44: 46.3 | AS44: 123.2 | AT44: =AS44 -> 123.2 | AU44: 175.2 | AV44: 192.1 | AW44: 248.6
A45: Accumulated other comprehensive loss | Q45: 26 | R45: 26 | S45: 24 | T45: 11 | U45: =T45 -> 11 | V45: 17 | W45: -6 | X45: 1 | Y45: 8 | Z45: =Y45 -> 8 | AA45: 24 | AB45: 16 | AC45: 18 | AD45: 8 | AE45: =AD45 -> 8 | AF45: 9 | AG45: 15 | AH45: -3 | AI45: -21.3 | AJ45: =AI45 -> -21.3 | AK45: -7.8 | AL45: 17.9 | AM45: 17 | AN45: 13.2 | AO45: =AN45 -> 13.2 | AP45: 17.4 | AQ45: 13.1 | AR45: 10 | AS45: 9.9 | AT45: =AS45 -> 9.9 | AU45: 3 | AV45: 2.5 | AW45: 8.2
A46: Total shareholders' equity | E46: =E23-E38 -> -330 | F46: =F23-F38 -> -330 | G46: -286 | H46: -218 | I46: -203 | J46: =J23-J38 -> -117 | K46: =K23-K38 -> -117 | L46: =L23-L38 -> -194 | M46: =M23-M38 -> -226 | N46: =N23-N38 -> -288 | O46: =O23-O38 -> -358 | P46: =P23-P38 -> -358 | Q46: =SUM(Q41:Q45) -> -343 | R46: =SUM(R41:R45) -> -298 | S46: =SUM(S41:S45) -> -252 | T46: =SUM(T41:T45) -> -258 | U46: =T46 -> -258 | V46: =SUM(V41:V45) -> -196 | W46: =SUM(W41:W45) -> -237 | X46: =SUM(X41:X45) -> -188 | Y46: =SUM(Y41:Y45) -> -76 | Z46: =Y46 -> -76 | AA46: =SUM(AA41:AA45) -> -55 | AB46: =SUM(AB41:AB45) -> -56 | AC46: =SUM(AC41:AC45) -> 23 | AD46: =SUM(AD41:AD45) -> 135 | AE46: =AD46 -> 135 | AF46: =SUM(AF41:AF45) -> 167 | AG46: =SUM(AG41:AG45) -> 200 | AH46: =SUM(AH41:AH45) -> 226 | AI46: =SUM(AI41:AI45) -> 306.6 | AJ46: =AI46 -> 306.6 | AK46: =SUM(AK41:AK45) -> 289.3 | AL46: =SUM(AL41:AL45) -> 1372.4 | AM46: =SUM(AM41:AM45) -> 285.4 | AN46: =SUM(AN41:AN45) -> 203.2 | AO46: =AN46 -> 203.2 | AP46: =SUM(AP42:AP45) -> 64.8 | AQ46: =SUM(AQ42:AQ45) -> 60.1 | AR46: =SUM(AR42:AR45) -> 106.5 | AS46: =SUM(AS42:AS45) -> 185.6 | AT46: =AS46 -> 185.6 | AU46: =SUM(AU42:AU45) -> 229.8 | AV46: =SUM(AV42:AV45) -> 248.7 | AW46: =SUM(AW42:AW45) -> 313.6 | AX46: =AX23-AX38 -> 338.5 | AY46: =AX46 -> 338.5 | AZ46: 307.6 | BA46: =BA23-BA38 -> 317.75829 | BB46: =BB23-BB38 -> 336.63278 | BC46: =BC23-BC38 -> 353.27452 | BD46: =BC46 -> 353.27452 | BE46: =BE23-BE38 -> 371.67101 | BF46: =BF23-BF38 -> 392.19153 | BG46: =BG23-BG38 -> 417.08219 | BH46: =BH23-BH38 -> 440.06167 | BI46: =BH46 -> 440.06167
A47: Total liabilities and shareholders' equity | E47: =E46+E38 -> 1825 | F47: =F46+F38 -> 1825 | G47: =G46+G38 -> 1865 | H47: =H46+H38 -> 1907 | I47: =I46+I38 -> 1960 | J47: =J46+J38 -> 1915 | K47: =K46+K38 -> 1915 | L47: =L46+L38 -> 1827 | ... O47: =O46+O38 -> 1854 | Q47: =Q46+Q38 -> 1832 | R47: =R46+R38 -> 1914 | S47: =S46+S38 -> 2000 | T47: =T46+T38 -> 2064 | U47: =U46+U38 -> 2064 | V47: =V46+V38 -> 2417 | W47: =W46+W38 -> 2917 | X47: =X46+X38 -> 2963 | ... BI47: =BI46+BI38 -> 3460.6347
AD48: =AD47-AD23 -> 0
A49: BALANCE SHEET ANALYSIS
...

Sheet CF
A3: Valvoline Inc. (VVV)
A4: Cash Flow Statement
A5: ($M's, except per share) | B5: =IS!B7 -> 1Q16 | C5: =IS!C7 -> 2Q16 | D5: =IS!D7 -> 3Q16 | E5: =IS!E7 -> 4Q16 | F5: =IS!F7 -> FY16 | G5: =IS!G7 -> 1Q17 | H5: =IS!H7 -> 2Q17 | I5: =IS!I7 -> 3Q17 | ... BI5: =IS!BI7 -> FY27E
A8: Net income | E8: 65 | F8: 273 | G8: 72 | H8: =143-G8 -> 71 | I8: =199-SUM(G8:H8) -> 56 | J8: =K8-SUM(G8:I8) -> 105 | K8: 304 | L8: -10 | M8: 67 | N8: =121-SUM(L8:M8) -> 64 | O8: =P8-SUM(L8:N8) -> 45 | P8: 166 | Q8: 53 | R8: 63 | S8: 65 | T8: =U8-SUM(Q8:S8) -> 27 | U8: 208 | V8: 73 | W8: =136-V8 -> 63 | X8: =195-SUM(V8:W8) -> 59 | Y8: =Z8-SUM(V8:X8) -> 122 | Z8: 317 | AA8: 87 | AB8: =155-AA8 -> 68 | AC8: =252-SUM(AA8:AB8) -> 97 | AD8: =AE8-SUM(AA8:AC8) -> 168 | AE8: 420 | AF8: 87 | AG8: =168.4-AF8 -> 81.4 | AH8: =267-SUM(AF8:AG8) -> 98.6 | AI8: =AJ8-SUM(AF8:AH8) -> 157.3 | AJ8: 424.3 | AK8: 81.9 | AL8: =1309.2-AK8 -> 1227.3 | AM8: =1370.8-SUM(AK8:AL8) -> 61.6 | AN8: =AO8-SUM(AK8:AM8) -> 48.9 | AO8: 1419.7 | AP8: 31.9 | AQ8: =73.3-AP8 -> 41.4 | AR8: =119.2-SUM(AP8:AQ8) -> 45.9 | AS8: =+AT8-SUM(AP8:AR8) -> 92.3 | AT8: 211.5 | AU8: 91.6 | AV8: =129.2-AU8 -> 37.6 | AW8: =185.7-SUM(AU8:AV8) -> 56.5 | AX8: =+AY8-SUM(AU8:AW8) -> 25 | AY8: 210.7 | AZ8: -32.8 | BA8: =IS!BA96 -> 40.435838 | BB8: =IS!BB96 -> 57.622197 | BC8: =IS!BC96 -> 58.769405 | BD8: =SUM(AZ8:BC8) -> 124.02744 | BE8: =IS!BE96 -> 42.996489 | BF8: =IS!BF96 -> 48.720523 | BG8: =IS!BG96 -> 71.390662 | BH8: =IS!BH96 -> 72.794342 | BI8: =SUM(BE8:BH8) -> 235.90202
A9: Depreciation and amortization | E9: 10 | F9: 38 | G9: 9 | H9: =18-G9 -> 9 | I9: =30-SUM(G9:H9) -> 12 | J9: =K9-SUM(G9:I9) -> 12 | K9: 42 | L9: 11 | M9: 14 | N9: 14 | O9: =P9-SUM(L9:N9) -> 15 | P9: 54 | Q9: 14 | R9: 14 | S9: 15 | T9: =U9-SUM(Q9:S9) -> 18 | U9: 61 | V9: 16 | W9: =31-V9 -> 15 | X9: =48-SUM(V9:W9) -> 17 | Y9: =Z9-SUM(V9:X9) -> 18 | Z9: 66 | AA9: 21 | AB9: =44-AA9 -> 23 | AC9: =68-SUM(AA9:AB9) -> 24 | AD9: =AE9-SUM(AA9:AC9) -> 24 | AE9: 92 | AF9: 16.9 | AG9: =34.5-AF9 -> 17.6 | AH9: 17.6 | AI9: =AJ9-SUM(AF9:AH9) -> 19.3 | AJ9: 71.4 | AK9: 18.5 | AL9: =39.1-AK9 -> 20.6 | AM9: =60.7-SUM(AK9:AL9) -> 21.6 | AN9: =AO9-SUM(AK9:AM9) -> 28.1 | AO9: 88.8 | AP9: 24.6 | AQ9: =50.2-AP9 -> 25.6 | AR9: =77.1-AQ9-AP9 -> 26.9 | AS9: =+AT9-SUM(AP9:AR9) -> 28.8 | AT9: 105.9 | AU9: 28 | AV9: 28.4 | AW9: 30.2 | AX9: =+AY9-SUM(AU9:AW9) -> 32.8 | AY9: 119.4 | AZ9: 33.5 | BA9: =+BA58*IS!BA86 -> 36.722451 | BB9: =+BB58*IS!BB86 -> 38.252294 | BC9: =+BC58*IS!BC86 -> 39.872331 | BD9: =SUM(AZ9:BC9) -> 148.34708 | BE9: =+BE58*IS!BE86 -> 41.4 | BF9: =+BF58*IS!BF86 -> 42.8 | BG9: =+BG58*IS!BG86 -> 44.5 | BH9: =+BH58*IS!BH86 -> 46.185134 | BI9: =SUM(BE9:BH9) -> 174.88513
A10: Stock-based compensation expense | E10: 0 | G10: 1 | H10: =3-G10 -> 2 | I10: =6-SUM(G10:H10) -> 3 | J10: =K10-SUM(G10:I10) -> 3 | K10: 9 | L10: 4 | M10: 3 | N10: 3 | O10: =P10-SUM(L10:N10) -> 2 | P10: 12 | Q10: 3 | R10: 2 | S10: -5 | T10: =U10-SUM(Q10:S10) -> 9 | U10: 9 | V10: 4 | W10: =3-V10 -> -1 | X10: =8-SUM(V10:W10) -> 5 | Y10: =Z10-SUM(V10:X10) -> 4 | Z10: 12 | AA10: 3 | AB10: =6-AA10 -> 3 | AC10: =10-SUM(AA10:AB10) -> 4 | AD10: =AE10-SUM(AA10:AC10) -> 4 | AE10: 14 | AF10: 3.2 | AG10: =7.2-AF10 -> 4 | AH10: =11-SUM(AF10:AG10) -> 3.8 | AI10: =AJ10-SUM(AF10:AH10) -> 3.4 | AJ10: 14.4 | AK10: 2.9 | AL10: =5.4-AK10 -> 2.5 | AM10: =8.8-SUM(AK10:AL10) -> 3.4 | AN10: =AO10-SUM(AK10:AM10) -> 3.4 | AO10: 12.2 | AP10: 2.4 | AQ10: =4.9-AP10 -> 2.5 | AR10: =9.4-SUM(AP10:AQ10) -> 4.5 | AS10: =+AT10-SUM(AP10:AR10) -> 2.6 | AT10: 12 | AU10: 2 | AV10: =4.6-AU10 -> 2.6 | AW10: =7.4-SUM(AU10:AV10) -> 2.8 | AX10: =+AY10-SUM(AU10:AW10) -> 3.1 | AY10: 10.5 | AZ10: 2.4 | BA10: 3 | BB10: 3 | BC10: 3 | BD10: =SUM(AZ10:BC10) -> 11.4 | BE10: 4 | BF10: 4 | BG10: 4 | BH10: 4 | BI10: =SUM(BE10:BH10) -> 16
