Workbook
Name blank: #REF!
Name Current_Q: #REF!
Name export: #REF!
Name FY_92: #REF!
Name FY_93: #REF!
Name FY_94: #REF!
Name N_A: #REF!
Name N_M: #REF!
Name Next_Actual_Period_Range: '[1]Income Statement'!$D$3:$BE$6
Name NM_T: #REF!
Name Prior_Q: #REF!
Name Same_Q_Last_Yr: #REF!
Name source: #REF!
Name WIZARD_3YRATCF: #REF!
Name WIZARD_3YREBITDA: #REF!
Name WIZARD_3YRSECGROWTH: #REF!
Name WIZARD_AVGTRADINGVOLUME: #REF!
Name WIZARD_BKVALSHR: #REF!
Name WIZARD_BURNRATE: #REF!
Name WIZARD_CASH: #REF!
Name WIZARD_DIVYIELD: #REF!
Name WIZARD_EARNINGS: #REF!
Name WIZARD_EBITDABYSHROO: #REF!
Name WIZARD_EVBYEBITDAOO: #REF!
Name WIZARD_EVINVCAP: #REF!
Name WIZARD_LTDEBT: #REF!
Name WIZARD_MARKETCAP: #REF!
Name WIZARD_NETDEBTCAP: #REF!
Name WIZARD_OPERMARGIN: #REF!
Name WIZARD_PRICEESTNAV: #REF!
Name WIZARD_REVENUES: #REF!
Name WIZARD_ROAA: #REF!
Name WIZARD_ROAE: #REF!
Name WIZARD_ROE: #REF!
Name WIZARD_ROIC: #REF!
Name WIZARD_SHARESOUT: #REF!
Name WIZARD_STATIONREV: #REF!
Name WIZARD_TICKER: #REF!
Name WIZARD_TOTDEBTCAP: #REF!
Name WIZARD_Y1CAPREVR: [2]AMAT_FC!#REF!
Name WIZARD_Y1CAPREVS2: #REF!
Name WIZARD_Y1CASHCYEPSS1: #REF!
Name WIZARD_Y1CASHCYPES1: #REF!
Name WIZARD_Y1CYE: [2]AMAT_FC!#REF!
Name WIZARD_Y1CYPEE: [2]AMAT_FC!#REF!
Name WIZARD_Y1CYPES1: #REF!
Name WIZARD_Y1CYREVS2: #REF!
Name WIZARD_Y1CYS1: #REF!
Name WIZARD_Y1E: [2]AMAT_FC!#REF!
Name WIZARD_Y1EBITDAYRS2: #REF!
Name WIZARD_Y1EMVBYREV: #REF!
Name WIZARD_Y1EVEBITDAS2: #REF!
Name WIZARD_Y1PEE: [2]AMAT_FC!#REF!
Name WIZARD_Y1PES1: #REF!
Name WIZARD_Y1Q1E: [2]AMAT_FC!#REF!
Name WIZARD_Y1Q1R: [2]AMAT_FC!#REF!
Name WIZARD_Y1Q1S1: #REF!
Name WIZARD_Y1Q1S2: #REF!
Name WIZARD_Y1Q2E: [2]AMAT_FC!#REF!
Name WIZARD_Y1Q2R: [2]AMAT_FC!#REF!

Sheet Comparison
B2: Tempus Labs
D3: Y/Y Change | G3: Q/Q Change | J3: Estimate vs Actual
B4: Variance Analysis | D4: 4Q24 | E4: =K4 -> 4Q25 | F4: % Change | G4: 3Q25 | H4: =K4 -> 4Q25 | I4: % Change | J4: 4Q25E | K4: 4Q25 | L4: % Change
B5: Total Revenues | D5: =IS!AF15 -> 200.68 | E5: =K5 -> 367.211 | F5: =E5/D5-1 -> 0.82983357 | G5: 334.206 | H5: =K5 -> 367.211 | I5: =H5/G5-1 -> 0.098756456 | J5: 360.44908 | K5: =IS!AK15 -> 367.211 | L5: =K5/J5-1 -> 0.018759708
B6: Genomics Revenue | D6: =IS!AF9 -> 120.434 | E6: =K6 -> 266.856 | F6: =E6/D6-1 -> 1.2157862 | G6: 252.878 | H6: =K6 -> 266.856 | I6: =H6/G6-1 -> 0.055275667 | J6: 258.65224 | K6: =IS!AK9 -> 266.856 | L6: =K6/J6-1 -> 0.03171734
B7: Data & Other Revenue | D7: =IS!AF12 -> 80.246 | E7: =K7 -> 100.355 | F7: =E7/D7-1 -> 0.25059193 | G7: 81.328 | H7: =K7 -> 100.355 | I7: =H7/G7-1 -> 0.23395387 | J7: 101.79684 | K7: =IS!AK12 -> 100.355 | L7: =K7/J7-1 -> -0.014163911
B9: Cost of revenue | D9: =IS!AF23 -> 76.521 | E9: =K9 -> 126.384 | F9: =E9/D9-1 -> 0.65162504 | G9: 121.641 | H9: =K9 -> 126.384 | I9: =H9/G9-1 -> 0.038991787 | J9: 128.65 | K9: =IS!AK23 -> 126.384 | L9: =K9/J9-1 -> -0.017613648
B10: Non-GAAP Gross Profit | D10: =IS!AF25 -> 124.159 | E10: =K10 -> 240.827 | F10: =E10/D10-1 -> 0.93966607 | G10: 212.565 | H10: =K10 -> 240.827 | I10: =H10/G10-1 -> 0.13295698 | J10: 231.79908 | K10: =IS!AK25 -> 240.827 | L10: =K10/J10-1 -> 0.038947157
C11: Gross Margin | D11: =IS!AF26 -> 0.61869145 | E11: =K11 -> 0.6558273 | F11: =E11/D11-1 -> 0.060023223 | G11: 0.63602987 | H11: =K11 -> 0.6558273 | I11: =H11/G11-1 -> 0.031126572 | J11: 0.64308413 | K11: =IS!AK26 -> 0.6558273 | L11: =K11/J11-1 -> 0.019815712
B13: Operating Expenses
B14: Technology | D14: =IS!AF29 -> 26.448 | E14: =H14 -> 32.966 | F14: =E14/D14-1 -> 0.24644586 | G14: 32.346 | H14: =K14 -> 32.966 | I14: =H14/G14-1 -> 0.019167749 | J14: 32.260193 | K14: =IS!AK29 -> 32.966 | L14: =K14/J14-1 -> 0.021878583
B15: Research & Development | D15: =IS!AF31 -> 26.005 | E15: =K15 -> 45.302 | F15: =E15/D15-1 -> 0.74204961 | G15: 41.537 | H15: =K15 -> 45.302 | I15: =H15/G15-1 -> 0.090642078 | J15: 41.451644 | K15: =IS!AK31 -> 45.302 | L15: =K15/J15-1 -> 0.092887889
B16: General & Administrative | D16: =IS!AF33 -> 90.039 | E16: =K16 -> 158.278 | F16: =E16/D16-1 -> 0.7578827 | G16: 147.344 | H16: =K16 -> 158.278 | I16: =H16/G16-1 -> 0.074207297 | J16: 147.42367 | K16: =IS!AK33 -> 158.278 | L16: =K16/J16-1 -> 0.073626751
B17: Total Operating Expense | D17: =IS!AF35 -> 142.492 | E17: =K17 -> 236.546 | F17: =E17/D17-1 -> 0.66006513 | G17: 221.227 | H17: =K17 -> 236.546 | I17: =H17/G17-1 -> 0.069245616 | J17: 221.13551 | K17: =IS!AK35 -> 236.546 | L17: =K17/J17-1 -> 0.069687989 | M17: =K17-J17 -> 15.410489
B19: Non-GAAP Operating Income | D19: =IS!AF37 -> -18.333 | E19: =K19 -> 4.281 | F19: =E19/D19-1 -> -1.2335133 | G19: -8.662 | H19: =K19 -> 4.281 | I19: =H19/G19-1 -> -1.4942277 | J19: 10.663574 | K19: =IS!AK37 -> 4.281 | L19: =K19/J19-1 -> -0.59853984
C20: Operating Margins | D20: =IS!AF38 -> -0.091354395 | E20: =K20 -> 0.011658147 | F20: =E20/D20-1 -> -1.1276145 | G20: -0.025918146 | H20: =K20 -> 0.011658147 | I20: =H20/G20-1 -> -1.4498064 | J20: 0.029584134 | K20: =IS!AK38 -> 0.011658147 | L20: =K20/J20-1 -> -0.60593244
B22: GAAP & Non-Cash Charges | D22: =IS!AF53 -> 34.903 | E22: =K22 -> 65.326 | F22: =E22/D22-1 -> 0.87164427 | G22: 52.334 | H22: =K22 -> 65.326 | I22: =H22/G22-1 -> 0.24825161 | J22: 52.5 | K22: =IS!AK53 -> 65.326 | L22: =K22/J22-1 -> 0.24430476
B24: GAAP Operating Income | D24: =IS!AF55 -> -53.236 | E24: =K24 -> -61.045 | F24: =E24/D24-1 -> 0.14668645 | G24: -60.996 | H24: =K24 -> -61.045 | I24: =H24/G24-1 -> 0.00080333137 | J24: -41.836426 | K24: =IS!AK55 -> -61.045 | L24: =K24/J24-1 -> 0.45913515
C25: Operating Margins | D25: =IS!AF56 -> -0.26527805 | E25: =K25 -> -0.16623957 | F25: =E25/D25-1 -> -0.37333839 | G25: -0.18251019 | H25: =K25 -> -0.16623957 | I25: =H25/G25-1 -> -0.089149077 | J25: -0.11606751 | K25: =IS!AK56 -> -0.16623957 | L25: =K25/J25-1 -> 0.43226625
B27: Adjusted EBITDA | D27: =IS!AF63 -> -7.7515803 | E27: =K27 -> 12.893 | F27: =E27/D27-1 -> -2.6632738 | G27: 1.476 | H27: =K27 -> 12.893 | I27: =H27/G27-1 -> 7.7350949 | J27: 20.038574 | K27: =IS!AK63 -> 12.893 | L27: =K27/J27-1 -> -0.35659094
C28: Adjusted EBITDA Margin | D28: =IS!AF64 -> -0.038626571 | E28: =K28 -> 0.035110604 | F28: =E28/D28-1 -> -1.9089754 | G28: 0.0044164378 | H28: =K28 -> 0.035110604 | I28: =H28/G28-1 -> 6.9499827 | J28: 0.055593355 | K28: =IS!AK64 -> 0.035110604 | L28: =K28/J28-1 -> -0.36843884
B30: Other income (expense) | D30: =IS!AF61 -> 40.34442 | E30: =K30 -> 4.404 | F30: =E30/D30-1 -> -0.89083992 | G30: -20.228 | H30: =K30 -> 4.404 | I30: =H30/G30-1 -> -1.217718 | J30: -11.4 | K30: =IS!AK61 -> 4.404 | L30: =K30/J30-1 -> -1.3863158
B32: Non-GAAP Income Before Taxes | D32: =IS!AF66 -> -29.576 | E32: =K32 -> 8.685 | F32: =E32/D32-1 -> -1.2936503 | G32: -28.89 | H32: =K32 -> 8.685 | I32: =H32/G32-1 -> -1.3006231 | J32: -0.73642619 | K32: =IS!AK66 -> 8.685 | L32: =K32/J32-1 -> -12.793443
B33: Non-GAAP Income Tax | D33: =IS!AF67 -> -0.122 | E33: =K33 -> 5.992 | F33: =E33/D33-1 -> -50.114754 | G33: -0.276 | H33: =K33 -> 5.992 | I33: =H33/G33-1 -> -22.710145 | J33: 0 | K33: =IS!AK67 -> 5.992 | L33: =K33/J33-1 -> #DIV/0!
B34: Non-GAAP Net Income | D34: =IS!AF74 -> -13.01358 | E34: =K34 -> -54.166 | F34: =E34/D34-1 -> 3.1622673 | G34: -79.982 | H34: =K34 -> -54.166 | I34: =H34/G34-1 -> -0.32277262 | J34: -53.236426 | K34: =IS!AK74 -> -54.166 | L34: =K34/J34-1 -> 0.017461236
B36: GAAP Income Before Taxes | D36: =IS!AF71 -> -12.89158 | E36: =K36 -> -56.641 | F36: =E36/D36-1 -> 3.3936429 | G36: -81.224 | H36: =K36 -> -56.641 | I36: =H36/G36-1 -> -0.30265685 | J36: -53.236426 | K36: =IS!AK71 -> -56.641 | L36: =K36/J36-1 -> 0.06395196
B37: GAAP Income Tax | D37: =IS!AF72 -> -0.122 | E37: =K37 -> 5.992 | F37: =IFERROR(E37/D37-1, 0) -> -50.114754 | G37: -0.276 | H37: =K37 -> 5.992 | I37: =H37/G37-1 -> -22.710145 | J37: 0 | K37: =IS!AK72 -> 5.992 | L37: =K37/J37-1 -> #DIV/0!
B38: GAAP Net Income | D38: =IS!AF74 -> -13.01358 | E38: =K38 -> -54.166 | F38: =E38/D38-1 -> 3.1622673 | G38: -79.982 | H38: =K38 -> -54.166 | I38: =H38/G38-1 -> -0.32277262 | J38: -53.236426 | K38: =IS!AK74 -> -54.166 | L38: =K38/J38-1 -> 0.017461236
B40: GAAP EPS | D40: =IS!AF82 -> -0.18715117 | E40: =K40 -> -0.30414446 | F40: =IFERROR(E40/D40-1, 0) -> 0.62512724 | G40: -0.45718369 | H40: =K40 -> -0.30414446 | I40: =H40/G40-1 -> -0.3347434 | J40: -0.30351171 | K40: =IS!AK82 -> -0.30414446 | L40: =K40/J40-1 -> 0.0020847702
B42: Fully Diluted Shares Outstanding | D42: =IS!AF84 -> 166.398 | E42: =K42 -> 178.093 | F42: =IFERROR(E42/D42-1, 0) -> 0.070283297 | G42: 174.945 | H42: =K42 -> 178.093 | I42: =H42/G42-1 -> 0.017994227 | J42: 175.40156 | K42: =IS!AK84 -> 178.093 | L42: =K42/J42-1 -> 0.015344476
B43: Source: Company reports and Needham & Company, LLC, estimates

Sheet IS
C2: Tempus Labs (NASDAQ: TEM)
AL3: =+Diagnostics!AL13 -> 362.78
AL4: =+AL3/AG15 -> 0.52319156
AL5: =+AL16-AL4 -> 0.31094832
C8: Income Statement | D8: 1Q19 | E8: 2Q19 | F8: 3Q19 | G8: 4Q19 | H8: FY19 | I8: 1Q20 | J8: 2Q20 | K8: 3Q20 | L8: 4Q20 | M8: FY20 | N8: 1Q21 | O8: 2Q21 | P8: 3Q21 | Q8: 4Q21 | R8: FY21 | S8: 1Q22 | T8: 2Q22 | U8: 3Q22 | V8: 4Q22 | W8: FY22 | X8: 1Q23 | Y8: 2Q23 | Z8: 3Q23 | AA8: 4Q23 | AB8: FY23 | AC8: 1Q24 | AD8: 2Q24 | AE8: 3Q24 | AF8: 4Q24 | AG8: FY24 | AH8: 1Q25 | AI8: 2Q25 | AJ8: 3Q25 | AK8: 4Q25 | AL8: FY25 | AM8: 1Q26E | AN8: 2Q26E | AO8: 3Q26E | AP8: 4Q26E | AQ8: FY26E
C9: Diagnostics Revenue | D9: =Diagnostics!D4 -> 4.4874457 | E9: =Diagnostics!E4 -> 5.8740361 | F9: =Diagnostics!F4 -> 8.7568856 | G9: =Diagnostics!G4 -> 8.7716656 | H9: =SUM(D9:G9) -> 27.890033 | I9: =Diagnostics!I4 -> 13.645173 | J9: =Diagnostics!J4 -> 12.499903 | K9: =Diagnostics!K4 -> 47.078495 | L9: =Diagnostics!L4 -> 78.687212 | M9: =SUM(I9:L9) -> 151.91078 | N9: =Diagnostics!N4 -> 59.830029 | O9: =Diagnostics!O4 -> 53.070446 | P9: =Diagnostics!P4 -> 41.613709 | Q9: =Diagnostics!Q4 -> 40.498048 | R9: =SUM(N9:Q9) -> 195.01223 | S9: =Diagnostics!S4 -> 37.901848 | T9: =Diagnostics!T4 -> 47.421609 | U9: =Diagnostics!U4 -> 54.73176 | V9: =Diagnostics!V4 -> 57.929274 | W9: =SUM(S9:V9) -> 197.98449 | X9: =Diagnostics!X4 -> 82.058168 | Y9: =Diagnostics!Y4 -> 91.923548 | Z9: =Diagnostics!Z4 -> 96.784312 | AA9: =Diagnostics!AA4 -> 92.191474 | AB9: =SUM(X9:AA9) -> 362.9575 | AC9: =Diagnostics!AC4 -> 102.56942 | AD9: =Diagnostics!AD4 -> 112.324 | AE9: =Diagnostics!AE4 -> 116.422 | AF9: =Diagnostics!AF4 -> 120.434 | AG9: =SUM(AC9:AF9) -> 451.74942 | AH9: =Diagnostics!AH4 -> 193.804 | AI9: =Diagnostics!AI4 -> 241.843 | AJ9: =Diagnostics!AJ4 -> 252.878 | AK9: =Diagnostics!AK4 -> 266.856 | AL9: =SUM(AH9:AK9) -> 955.381 | AM9: =Diagnostics!AM4 -> 258.2497 | AN9: =Diagnostics!AN4 -> 298.36928 | AO9: =Diagnostics!AO4 -> 307.97813 | AP9: =Diagnostics!AP4 -> 314.34736 | AQ9: =SUM(AM9:AP9) -> 1178.9445
C10: Y/y Growth | I10: =I9/D9-1 -> 2.040744 | J10: =J9/E9-1 -> 1.1279922 | K10: =K9/F9-1 -> 4.3761688 | L10: =L9/G9-1 -> 7.9706124 | M10: =M9/H9-1 -> 4.4467768 | N10: =N9/I9-1 -> 3.3847027 | O10: =O9/J9-1 -> 3.2456685 | P10: =P9/K9-1 -> -0.11607818 | ... AQ10: =AQ9/AL9-1 -> 0.23400452
C11: Q/q Growth | E11: =E9/D9-1 -> 0.30899324 | F11: =F9/E9-1 -> 0.49077832 | G11: =G9/F9-1 -> 0.0016878123 | I11: =I9/G9-1 -> 0.55559662 | J11: =J9/I9-1 -> -0.083932257 | K11: =K9/J9-1 -> 2.7663088 | L11: =L9/K9-1 -> 0.67140458 | N11: =N9/L9-1 -> -0.23964737 | O11: =O9/N9-1 -> -0.11297977 | P11: =P9/O9-1 -> -0.21587791 | Q11: =Q9/P9-1 -> -0.026809928 | S11: =S9/Q9-1 -> -0.064106792 | T11: =T9/S9-1 -> 0.25116876 | U11: =U9/T9-1 -> 0.15415233 | V11: =V9/U9-1 -> 0.058421545 | X11: =X9/V9-1 -> 0.41652332 | Y11: =Y9/X9-1 -> 0.12022423 | Z11: =Z9/Y9-1 -> 0.052878335 | AA11: =AA9/Z9-1 -> -0.047454359 | AC11: =AC9/AA9-1 -> 0.11256946 | AD11: =AD9/AC9-1 -> 0.095102237 | AE11: =AE9/AD9-1 -> 0.036483743 | AF11: =AF9/AE9-1 -> 0.034460841 | AH11: =AH9/AF9-1 -> 0.60921335 | AI11: =AI9/AH9-1 -> 0.24787414 | AJ11: =AJ9/AI9-1 -> 0.045628776 | AK11: =AK9/AJ9-1 -> 0.055275667 | AM11: =AM9/AK9-1 -> -0.032250727 | AN11: =AN9/AM9-1 -> 0.15535189 | AO11: =AO9/AN9-1 -> 0.032204555 | AP11: =AP9/AO9-1 -> 0.020680787
C12: Data and Other Revenue | D12: ='Data & Other'!D7 -> 3.1913215 | E12: ='Data & Other'!E7 -> 4.7110225 | F12: ='Data & Other'!F7 -> 6.5473935 | G12: ='Data & Other'!G7 -> 19.717319 | H12: =SUM(D12:G12) -> 34.167057 | I12: ='Data & Other'!I7 -> 4.5969503 | J12: ='Data & Other'!J7 -> 5.6771733 | K12: ='Data & Other'!K7 -> 3.654138 | L12: ='Data & Other'!L7 -> 22.164383 | M12: =SUM(I12:L12) -> 36.092645 | N12: ='Data & Other'!N7 -> 10.280028 | O12: ='Data & Other'!O7 -> 8.9152628 | P12: ='Data & Other'!P7 -> 10.833945 | Q12: ='Data & Other'!Q7 -> 32.811488 | R12: =SUM(N12:Q12) -> 62.840725 | S12: ='Data & Other'!S7 -> 22.84992 | T12: ='Data & Other'!T7 -> 26.297225 | U12: ='Data & Other'!U7 -> 30.839768 | V12: ='Data & Other'!V7 -> 42.697508 | W12: =SUM(S12:V12) -> 122.68442 | X12: ='Data & Other'!X7 -> 33.56625 | Y12: ='Data & Other'!Y7 -> 40.492787 | Z12: ='Data & Other'!Z7 -> 39.241917 | AA12: ='Data & Other'!AA7 -> 55.498725 | AB12: =SUM(X12:AA12) -> 168.79968 | AC12: ='Data & Other'!AC7 -> 43.250622 | AD12: ='Data & Other'!AD7 -> 53.645 | AE12: ='Data & Other'!AE7 -> 64.507 | AF12: ='Data & Other'!AF7 -> 80.246 | AG12: =SUM(AC12:AF12) -> 241.64862 | AH12: ='Data & Other'!AH7 -> 61.933 | AI12: ='Data & Other'!AI7 -> 72.792 | AJ12: ='Data & Other'!AJ7 -> 81.328 | AK12: ='Data & Other'!AK7 -> 100.355 | AL12: =SUM(AH12:AK12) -> 316.408 | AM12: ='Data & Other'!AM7 -> 86.708248 | AN12: ='Data & Other'!AN7 -> 96.613063 | AO12: ='Data & Other'!AO7 -> 107.18766 | AP12: ='Data & Other'!AP7 -> 120.53203 | AQ12: =SUM(AM12:AP12) -> 411.041
C13: Y/y Growth | I13: =I12/D12-1 -> 0.44045351 | J13: =J12/E12-1 -> 0.20508302 | K13: =K12/F12-1 -> -0.44189425 | L13: =L12/G12-1 -> 0.12410735 | M13: =M12/H12-1 -> 0.056358031 | N13: =N12/I12-1 -> 1.2362714 | O13: =O12/J12-1 -> 0.57037004 | P13: =P12/K12-1 -> 1.9648429 | ... AQ13: =AQ12/AL12-1 -> 0.29908536
C14: Q/q Growth | E14: =E12/D12-1 -> 0.47619802 | F14: =F12/E12-1 -> 0.38980306 | G14: =G12/F12-1 -> 2.0114761 | I14: =I12/G12-1 -> -0.76685723 | J14: =J12/I12-1 -> 0.23498687 | K14: =K12/J12-1 -> -0.35634553 | L14: =L12/K12-1 -> 5.0655573 | N14: =N12/L12-1 -> -0.53619154 | O14: =O12/N12-1 -> -0.13275893 | P14: =P12/O12-1 -> 0.21521321 | Q14: =Q12/P12-1 -> 2.0285817 | S14: =S12/Q12-1 -> -0.30360003 | T14: =T12/S12-1 -> 0.15086727 | U14: =U12/T12-1 -> 0.17273852 | V14: =V12/U12-1 -> 0.38449511 | X14: =X12/V12-1 -> -0.21385928 | Y14: =Y12/X12-1 -> 0.20635422 | Z14: =Z12/Y12-1 -> -0.030891185 | AA14: =AA12/Z12-1 -> 0.41427151 | AC14: =AC12/AA12-1 -> -0.2206916 | AD14: =AD12/AC12-1 -> 0.24032897 | AE14: =AE12/AD12-1 -> 0.20247926 | AF14: =AF12/AE12-1 -> 0.24398902 | AH14: =AH12/AF12-1 -> -0.22821075 | AI14: =AI12/AH12-1 -> 0.17533464 | AJ14: =AJ12/AI12-1 -> 0.11726563 | AK14: =AK12/AJ12-1 -> 0.23395387 | AM14: =AM12/AK12-1 -> -0.13598477 | AN14: =AN12/AM12-1 -> 0.11423152 | AO14: =AO12/AN12-1 -> 0.10945308 | AP14: =AP12/AO12-1 -> 0.12449536
C15: Total Revenues | D15: =D12+D9 -> 7.6787672 | E15: =E12+E9 -> 10.585059 | F15: =F12+F9 -> 15.304279 | G15: =G12+G9 -> 28.488985 | H15: =SUM(D15:G15) -> 62.05709 | I15: =I12+I9 -> 18.242124 | J15: =J12+J9 -> 18.177076 | K15: =K12+K9 -> 50.732633 | L15: =L12+L9 -> 100.8516 | M15: =SUM(I15:L15) -> 188.00343 | N15: =N12+N9 -> 70.110057 | O15: =O12+O9 -> 61.985708 | P15: =P12+P9 -> 52.447654 | Q15: =Q12+Q9 -> 73.309537 | R15: =SUM(N15:Q15) -> 257.85296 | S15: =S12+S9 -> 60.751768 | T15: =T12+T9 -> 73.718833 | U15: =U12+U9 -> 85.571528 | V15: =V12+V9 -> 100.62678 | W15: =SUM(S15:V15) -> 320.66891 | X15: =X12+X9 -> 115.62442 | Y15: =Y12+Y9 -> 132.41633 | Z15: =Z12+Z9 -> 136.02623 | AA15: =AA12+AA9 -> 147.6902 | AB15: =SUM(X15:AA15) -> 531.75718 | AC15: =AC12+AC9 -> 145.82004 | AD15: =AD12+AD9 -> 165.969 | AE15: =AE12+AE9 -> 180.929 | AF15: =AF12+AF9 -> 200.68 | AG15: =SUM(AC15:AF15) -> 693.39804 | AH15: =AH12+AH9 -> 255.737 | AI15: =AI12+AI9 -> 314.635 | AJ15: =AJ12+AJ9 -> 334.206 | AK15: =AK12+AK9 -> 367.211 | AL15: =SUM(AH15:AK15) -> 1271.789 | AM15: =AM12+AM9 -> 344.95795 | AN15: =AN12+AN9 -> 394.98234 | AO15: =AO12+AO9 -> 415.16579 | AP15: =AP12+AP9 -> 434.87939 | AQ15: =SUM(AM15:AP15) -> 1589.9855
C16: Y/y Growth | I16: =I15/D15-1 -> 1.3756579 | J16: =J15/E15-1 -> 0.71723909 | K16: =K15/F15-1 -> 2.3149312 | L16: =L15/G15-1 -> 2.5400207 | M16: =M15/H15-1 -> 2.0295238 | N16: =N15/I15-1 -> 2.8433056 | O16: =O15/J15-1 -> 2.4101033 | P16: =P15/K15-1 -> 0.033805086 | ... AQ16: =AQ15/AL15-1 -> 0.25019596
C17: Q/q Growth | E17: =E15/D15-1 -> 0.37848411 | F17: =F15/E15-1 -> 0.44583792 | G17: =G15/F15-1 -> 0.86150451 | I17: =I15/G15-1 -> -0.359678 | J17: =J15/I15-1 -> -0.0035657721 | K17: =K15/J15-1 -> 1.7910227 | L17: =L15/K15-1 -> 0.98790383 | N17: =N15/L15-1 -> -0.30481956 | O17: =O15/N15-1 -> -0.11587993 | P17: =P15/O15-1 -> -0.15387506 | Q17: =Q15/P15-1 -> 0.39776579 | S17: =S15/Q15-1 -> -0.17129789 | T17: =T15/S15-1 -> 0.21344342 | U17: =U15/T15-1 -> 0.16078246 | V17: =V15/U15-1 -> 0.17593766 | X17: =X15/V15-1 -> 0.14904218 | Y17: =Y15/X15-1 -> 0.14522812 | Z17: =Z15/Y15-1 -> 0.027261697 | AA17: =AA15/Z15-1 -> 0.085747953 | AC17: =AC15/AA15-1 -> -0.01266271 | AD17: =AD15/AC15-1 -> 0.13817688 | AE17: =AE15/AD15-1 -> 0.090137315 | AF17: =AF15/AE15-1 -> 0.10916437 | AH17: =AH15/AF15-1 -> 0.2743522 | AI17: =AI15/AH15-1 -> 0.23030692 | AJ17: =AJ15/AI15-1 -> 0.062202234 | AK17: =AK15/AJ15-1 -> 0.098756456 | AM17: =AM15/AK15-1 -> -0.060600178 | AN17: =AN15/AM15-1 -> 0.14501592 | AO17: =AO15/AN15-1 -> 0.051099619 | AP17: =AP15/AO15-1 -> 0.047483671
C19: Diagnostics Cost of Revenue | D19: =Diagnostics!D26 -> 6.1617353 | E19: =Diagnostics!E26 -> 8.8999742 | F19: =Diagnostics!F26 -> 10.816278 | G19: =Diagnostics!G26 -> 13.807414 | H19: =SUM(D19:G19) -> 39.685401 | I19: =Diagnostics!I26 -> 16.832318 | J19: =Diagnostics!J26 -> 17.227103 | K19: =Diagnostics!K26 -> 46.356053 | L19: =Diagnostics!L26 -> 71.782609 | M19: =SUM(I19:L19) -> 152.19808 | N19: =Diagnostics!N26 -> 58.1521 | O19: =Diagnostics!O26 -> 39.350144 | P19: =Diagnostics!P26 -> 31.780714 | Q19: =Diagnostics!Q26 -> 32.992517 | R19: =SUM(N19:Q19) -> 162.27547 | S19: =Diagnostics!S26 -> 39.083505 | T19: =Diagnostics!T26 -> 34.266354 | U19: =Diagnostics!U26 -> 35.401601 | V19: =Diagnostics!V26 -> 41.503107 | W19: =SUM(S19:V19) -> 150.25457 | X19: =Diagnostics!X26 -> 45.280278 | Y19: =Diagnostics!Y26 -> 46.96103 | Z19: =Diagnostics!Z26 -> 46.540149 | AA19: =Diagnostics!AA26 -> 50.336734 | AB19: =SUM(X19:AA19) -> 189.11819 | AC19: =Diagnostics!AC26 -> 52.834757 | AD19: =Diagnostics!AD26-11.327-0.136 -> 56.861 | AE19: =Diagnostics!AE26-1.083-0.026 -> 59.017 | AF19: =Diagnostics!AF26-1.215-0.293 -> 60.674 | AG19: =SUM(AC19:AF19) -> 229.38676 | AH19: =Diagnostics!AH26 -> 83.7 | AI19: =Diagnostics!AI26 -> 98.082 | AJ19: =Diagnostics!AJ26 -> 96.976 | AK19: =Diagnostics!AK26 -> 100.747 | AL19: =SUM(AH19:AK19) -> 379.505 | AM19: =Diagnostics!AM26 -> 101.80962 | AN19: =Diagnostics!AN26 -> 118.83941 | AO19: =Diagnostics!AO26 -> 120.29982 | AP19: =Diagnostics!AP26 -> 118.2509 | AQ19: =SUM(AM19:AP19) -> 459.19975
C21: Data & Other Cost of Revenue | D21: ='Data & Other'!D19 -> 1.8783008 | E21: ='Data & Other'!E19 -> 1.7794325 | F21: ='Data & Other'!F19 -> 1.2114378 | G21: ='Data & Other'!G19 -> 1.4606137 | H21: =SUM(D21:G21) -> 6.3297848 | I21: ='Data & Other'!I19 -> 1.411472 | J21: ='Data & Other'!J19 -> 1.477868 | K21: ='Data & Other'!K19 -> 2.1382459 | L21: ='Data & Other'!L19 -> 2.0641284 | M21: =SUM(I21:L21) -> 7.0917143 | N21: ='Data & Other'!N19 -> 2.249488 | O21: ='Data & Other'!O19 -> 2.6678312 | P21: ='Data & Other'!P19 -> 3.0303307 | Q21: ='Data & Other'!Q19 -> 3.9851527 | R21: =SUM(N21:Q21) -> 11.932803 | S21: ='Data & Other'!S19 -> 7.7879838 | T21: ='Data & Other'!T19 -> 10.613211 | U21: ='Data & Other'!U19 -> 11.101333 | V21: ='Data & Other'!V19 -> 10.724351 | W21: =SUM(S21:V21) -> 40.226879 | X21: ='Data & Other'!X19 -> 11.392877 | Y21: ='Data & Other'!Y19 -> 13.806998 | Z21: ='Data & Other'!Z19 -> 15.489291 | AA21: ='Data & Other'!AA19 -> 15.79287 | AB21: =SUM(X21:AA21) -> 56.482036 | AC21: ='Data & Other'!AC19 -> 15.288271 | AD21: ='Data & Other'!AD19-7.229-0.119 -> 14.784 | AE21: ='Data & Other'!AE19-0.916-0.043 -> 14.005 | AF21: ='Data & Other'!AF19-0.385-0.202 -> 15.847 | AG21: =SUM(AC21:AF21) -> 59.924271 | AH21: ='Data & Other'!AH19 -> 15.096 | AI21: ='Data & Other'!AI19 -> 19.033 | AJ21: ='Data & Other'!AJ19 -> 24.665 | AK21: ='Data & Other'!AK19 -> 25.637 | AL21: =SUM(AH21:AK21) -> 84.431 | AM21: ='Data & Other'!AM19 -> 21.112614 | AN21: ='Data & Other'!AN19 -> 23.097934 | AO21: ='Data & Other'!AO19 -> 23.672625 | AP21: ='Data & Other'!AP19 -> 25.339939 | AQ21: =SUM(AM21:AP21) -> 93.223113
C23: Total Cost of Revenue | D23: =D19+D21 -> 8.0400362 | E23: =E19+E21 -> 10.679407 | F23: =F19+F21 -> 12.027716 | G23: =G19+G21 -> 15.268027 | H23: =SUM(D23:G23) -> 46.015186 | I23: =I19+I21 -> 18.24379 | J23: =J19+J21 -> 18.704971 | K23: =K19+K21 -> 48.494299 | L23: =L19+L21 -> 73.846737 | M23: =SUM(I23:L23) -> 159.2898 | N23: =N19+N21 -> 60.401588 | O23: =O19+O21 -> 42.017975 | P23: =P19+P21 -> 34.811044 | Q23: =Q19+Q21 -> 36.97767 | R23: =SUM(N23:Q23) -> 174.20828 | S23: =S19+S21 -> 46.871489 | T23: =T19+T21 -> 44.879565 | U23: =U19+U21 -> 46.502934 | V23: =V19+V21 -> 52.227458 | W23: =SUM(S23:V23) -> 190.48145 | X23: =X19+X21 -> 56.673155 | Y23: =Y19+Y21 -> 60.768028 | Z23: =Z19+Z21 -> 62.02944 | AA23: =AA19+AA21 -> 66.129604 | AB23: =SUM(X23:AA23) -> 245.60023 | AC23: =AC19+AC21 -> 68.123028 | AD23: =AD19+AD21 -> 71.645 | AE23: =AE19+AE21 -> 73.022 | AF23: =AF19+AF21 -> 76.521 | AG23: =SUM(AC23:AF23) -> 289.31103 | AH23: =AH19+AH21 -> 98.796 | AI23: =AI19+AI21 -> 117.115 | AJ23: =AJ19+AJ21 -> 121.641 | AK23: =AK19+AK21 -> 126.384 | AL23: =SUM(AH23:AK23) -> 463.936 | AM23: =AM19+AM21 -> 122.92223 | AN23: =AN19+AN21 -> 141.93735 | AO23: =AO19+AO21 -> 143.97244 | AP23: =AP19+AP21 -> 143.59084 | AQ23: =SUM(AM23:AP23) -> 552.42286
C25: Gross Profit | D25: =D15-D23 -> -0.36126895 | E25: =E15-E23 -> -0.094348017 | F25: =F15-F23 -> 3.2765634 | G25: =G15-G23 -> 13.220957 | H25: =SUM(D25:G25) -> 16.041904 | I25: =I15-I23 -> -0.001666383 | J25: =J15-J23 -> -0.52789494 | K25: =K15-K23 -> 2.2383338 | L25: =L15-L23 -> 27.004859 | M25: =SUM(I25:L25) -> 28.713631 | N25: =N15-N23 -> 9.7084692 | O25: =O15-O23 -> 19.967733 | P25: =P15-P23 -> 17.63661 | Q25: =Q15-Q23 -> 36.331867 | R25: =SUM(N25:Q25) -> 83.64468 | S25: =S15-S23 -> 13.880279 | T25: =T15-T23 -> 28.839268 | U25: =U15-U23 -> 39.068595 | V25: =V15-V23 -> 48.399324 | W25: =SUM(S25:V25) -> 130.18747 | X25: =X15-X23 -> 58.951262 | Y25: =Y15-Y23 -> 71.648307 | Z25: =Z15-Z23 -> 73.996789 | AA25: =AA15-AA23 -> 81.560595 | AB25: =SUM(X25:AA25) -> 286.15695 | AC25: =AC15-AC23 -> 77.697013 | AD25: =AD15-AD23 -> 94.324 | AE25: =AE15-AE23 -> 107.907 | AF25: =AF15-AF23 -> 124.159 | AG25: =SUM(AC25:AF25) -> 404.08701 | AH25: =AH15-AH23 -> 156.941 | AI25: =AI15-AI23 -> 197.52 | AJ25: =AJ15-AJ23 -> 212.565 | AK25: =AK15-AK23 -> 240.827 | AL25: =SUM(AH25:AK25) -> 807.853 | AM25: =AM15-AM23 -> 222.03572 | AN25: =AN15-AN23 -> 253.045 | AO25: =AO15-AO23 -> 271.19335 | AP25: =AP15-AP23 -> 291.28854 | AQ25: =SUM(AM25:AP25) -> 1037.5626
C26: Gross Margin | D26: =D25/D15 -> -0.04704778 | E26: =E25/E15 -> -0.0089133202 | F26: =F25/F15 -> 0.21409459 | G26: =G25/G15 -> 0.46407261 | H26: =H25/H15 -> 0.25850236 | I26: =I25/I15 -> -9.1348081e-05 | J26: =J25/J15 -> -0.029041796 | K26: =K25/K15 -> 0.044120199 | ... AQ26: =AQ25/AQ15 -> 0.65256106
C28: Operating Expenses
C29: Technology | D29: 4.7624656 | E29: 6.0944848 | F29: 6.911936 | G29: 7.8389731 | H29: 25.607859 | I29: 9.508666 | J29: 11.386503 | K29: 11.904752 | L29: 13.061494 | M29: 45.861414 | N29: 15.568639 | O29: 16.724552 | P29: 17.249761 | Q29: 17.647216 | R29: 67.190168 | S29: 18.376445 | T29: 19.492077 | U29: 20.389383 | V29: 20.822457 | W29: 79.08036 | X29: 22.902143 | Y29: 23.417789 | Z29: 24.156428 | AA29: 24.669381 | AB29: 95.556287 | AC29: 27.05099 | AD29: =77.908-50.434-1.248 -> 26.226 | AE29: =30.68-3.929-0.192 -> 26.559 | AF29: =31.864-4.11-1.306 -> 26.448 | AG29: =SUM(AC29:AF29) -> 106.28399 | AH29: =33.391-3.319-0.261 -> 29.811 | AI29: =34.482-3.285-0.495 -> 30.702 | AJ29: =38.087-5.463-0.278 -> 32.346 | AK29: =40.147-6.995-0.186 -> 32.966 | AL29: =SUM(AH29:AK29) -> 125.825 | AM29: =AM15*AM30 -> 37.945374 | AN29: =AN15*AN30 -> 39.498234 | AO29: =AO15*AO30 -> 41.516579 | AP29: =AP15*AP30 -> 43.487939 | AQ29: =SUM(AM29:AP29) -> 162.44813
C30: % of Revenue | D30: =D29/D15 -> 0.62021226 | E30: =E29/E15 -> 0.57576297 | F30: =F29/F15 -> 0.4516342 | G30: =G29/G15 -> 0.27515804 | H30: =H29/H15 -> 0.41265002 | I30: =I29/I15 -> 0.52124776 | J30: =J29/J15 -> 0.62642101 | K30: =K29/K15 -> 0.23465669 | ... AL30: =AL29/AL15 -> 0.098935437 | AM30: 0.11 | AN30: 0.1 | AO30: 0.1 | AP30: 0.1 | AQ30: =AQ29/AQ15 -> 0.10216957
C31: Research & Development | D31: 6.7716534 | E31: 7.6130874 | F31: 8.3112565 | G31: 8.5567344 | H31: 31.252732 | I31: 9.4118219 | J31: 11.211381 | K31: 11.685697 | L31: 13.105903 | M31: 45.414803 | N31: 14.028102 | O31: 13.762828 | P31: 14.734902 | Q31: 18.635596 | R31: 61.161428 | S31: 17.961027 | T31: 20.609998 | U31: 22.980849 | V31: 21.605942 | W31: 83.157816 | X31: 20.86253 | Y31: 22.171365 | Z31: 23.234179 | AA31: 24.075411 | AB31: 90.025956 | AC31: 24.339652 | AD31: =68.025-42.233-0.676 -> 25.116 | AE31: =27.348-2.554-0.134 -> 24.66 | AF31: =29.612-2.851-0.756 -> 26.005 | AG31: =SUM(AC31:AF31) -> 100.12065 | AH31: =35.874-1.982-0.176 -> 33.716 | AI31: =41.619-2.335-0.235 -> 39.049 | AJ31: =44.96-3.301-0.122 -> 41.537 | AK31: =50.471-5.07-0.099 -> 45.302 | AL31: =SUM(AH31:AK31) -> 159.604 | AM31: =AM15*AM32 -> 53.123524 | AN31: =AN15*AN32 -> 59.247352 | AO31: =AO15*AO32 -> 62.274869 | AP31: =AP15*AP32 -> 63.057511 | AQ31: =SUM(AM31:AP31) -> 237.70326
C32: % of Revenue | D32: =D31/D15 -> 0.88186726 | E32: =E31/E15 -> 0.71922959 | F32: =F31/F15 -> 0.54306749 | G32: =G31/G15 -> 0.30035238 | H32: =H31/H15 -> 0.50361259 | I32: =I31/I15 -> 0.51593894 | J32: =J31/J15 -> 0.61678683 | K32: =K31/K15 -> 0.23033887 | ... AL32: =AL31/AL15 -> 0.12549566 | AM32: 0.154 | AN32: 0.15 | AO32: 0.15 | AP32: 0.145 | AQ32: =AQ31/AQ15 -> 0.14950027
C33: General & Administrative | D33: 13.395203 | E33: 17.570622 | F33: 23.223093 | G33: 24.773481 | H33: 78.962398 | I33: 28.752381 | J33: 28.305386 | K33: 30.94784 | L33: 42.886876 | M33: 130.89248 | N33: 41.545114 | O33: 52.353458 | P33: 50.259131 | Q33: 54.845885 | R33: 199.00359 | S33: 54.635154 | T33: 55.292462 | U33: 58.876205 | V33: 64.585736 | W33: 233.38956 | X33: 69.046574 | Y33: 71.198037 | Z33: 71.426542 | AA33: =81.347648493+3.75 -> 85.097648 | AB33: 284.3657 | AC33: 79.580613 | AD33: =463.072-377.09-2.582 -> 83.4 | AE33: =101.427-12.556-0.806 -> 88.065 | AF33: =111.288-16.226-5.023 -> 90.039 | AG33: =SUM(AC33:AF33) -> 341.08461 | AH33: =154.627-16.027-4.725-3.529-11.156 -> 119.19 | AI33: =180.712-14.722-0.774-1.992-16.771-1.647 -> 144.806 | AJ33: =187.891-22.69-0.541-0.552-16.764 -> 147.344 | AK33: =208.508-30.243-3.006-0.143-16.838 -> 158.278 | AL33: =SUM(AH33:AK33) -> 569.618 | AM33: =AM15*AM34 -> 173.85881 | AN33: =AN15*AN34 -> 181.69188 | AO33: =AO15*AO34 -> 182.67295 | AP33: =AP15*AP34 -> 185.91094 | AQ33: =SUM(AM33:AP33) -> 724.13457
C34: % of Revenue | D34: =D33/D15 -> 1.744447 | E34: =E33/E15 -> 1.6599456 | F34: =F33/F15 -> 1.5174248 | G34: =G33/G15 -> 0.86958102 | H34: =H33/H15 -> 1.2724154 | I34: =I33/I15 -> 1.5761532 | J34: =J33/J15 -> 1.5572024 | K34: =K33/K15 -> 0.61001842 | ... AL34: =AL33/AL15 -> 0.44788719 | AM34: 0.504 | AN34: 0.46 | AO34: 0.44 | AP34: 0.4275 | AQ34: =AQ33/AQ15 -> 0.45543471
C35: Total Operating Expenses | D35: =D29+D31+D33 -> 24.929322 | E35: =E29+E31+E33 -> 31.278194 | F35: =F29+F31+F33 -> 38.446285 | G35: =G29+G31+G33 -> 41.169188 | H35: =SUM(D35:G35) -> 135.82299 | I35: =I29+I31+I33 -> 47.672869 | J35: =J29+J31+J33 -> 50.90327 | K35: =K29+K31+K33 -> 54.538289 | L35: =L29+L31+L33 -> 69.054273 | M35: =SUM(I35:L35) -> 222.1687 | N35: =N29+N31+N33 -> 71.141855 | O35: =O29+O31+O33 -> 82.840837 | P35: =P29+P31+P33 -> 82.243794 | Q35: =Q29+Q31+Q33 -> 91.128697 | R35: =SUM(N35:Q35) -> 327.35518 | S35: =S29+S31+S33 -> 90.972625 | T35: =T29+T31+T33 -> 95.394536 | U35: =U29+U31+U33 -> 102.24644 | V35: =V29+V31+V33 -> 107.01413 | W35: =SUM(S35:V35) -> 395.62773 | X35: =X29+X31+X33 -> 112.81125 | Y35: =Y29+Y31+Y33 -> 116.78719 | Z35: =Z29+Z31+Z33 -> 118.81715 | AA35: =AA29+AA31+AA33 -> 133.84244 | AB35: =SUM(X35:AA35) -> 482.25803 | AC35: =AC29+AC31+AC33 -> 130.97126 | AD35: =AD29+AD31+AD33 -> 134.742 | AE35: =AE29+AE31+AE33 -> 139.284 | AF35: =AF29+AF31+AF33 -> 142.492 | AG35: =SUM(AC35:AF35) -> 547.48926 | AH35: =AH29+AH31+AH33 -> 182.717 | AI35: =AI29+AI31+AI33 -> 214.557 | AJ35: =AJ29+AJ31+AJ33 -> 221.227 | AK35: =AK29+AK31+AK33 -> 236.546 | AL35: =SUM(AH35:AK35) -> 855.047 | AM35: =AM29+AM31+AM33 -> 264.9277 | AN35: =AN29+AN31+AN33 -> 280.43746 | AO35: =AO29+AO31+AO33 -> 286.4644 | AP35: =AP29+AP31+AP33 -> 292.45639 | AQ35: =SUM(AM35:AP35) -> 1124.286
C37: Non-GAAP Operating Income | D37: =D25-D35 -> -25.290591 | E37: =E25-E35 -> -31.372542 | F37: =F25-F35 -> -35.169722 | G37: =G25-G35 -> -27.948231 | H37: =SUM(D37:G37) -> -119.78109 | I37: =I25-I35 -> -47.674535 | J37: =J25-J35 -> -51.431165 | K37: =K25-K35 -> -52.299956 | L37: =L25-L35 -> -42.049414 | M37: =SUM(I37:L37) -> -193.45507 | N37: =N25-N35 -> -61.433386 | O37: =O25-O35 -> -62.873104 | P37: =P25-P35 -> -64.607184 | Q37: =Q25-Q35 -> -54.79683 | R37: =SUM(N37:Q37) -> -243.7105 | S37: =S25-S35 -> -77.092346 | T37: =T25-T35 -> -66.555268 | U37: =U25-U35 -> -63.177842 | V37: =V25-V35 -> -58.61481 | W37: =SUM(S37:V37) -> -265.44027 | X37: =X25-X35 -> -53.859984 | Y37: =Y25-Y35 -> -45.138884 | Z37: =Z25-Z35 -> -44.820361 | AA37: =AA25-AA35 -> -52.281845 | AB37: =SUM(X37:AA37) -> -196.10107 | AC37: =AC25-AC35 -> -53.274242 | AD37: =AD25-AD35 -> -40.418 | AE37: =AE25-AE35 -> -31.377 | AF37: =AF25-AF35 -> -18.333 | AG37: =SUM(AC37:AF37) -> -143.40224 | AH37: =AH25-AH35 -> -25.776 | AI37: =AI25-AI35 -> -17.037 | AJ37: =AJ25-AJ35 -> -8.662 | AK37: =AK25-AK35 -> 4.281 | AL37: =SUM(AH37:AK37) -> -47.194 | AM37: =AM25-AM35 -> -42.891988 | AN37: =AN25-AN35 -> -27.392466 | AO37: =AO25-AO35 -> -15.271045 | AP37: =AP25-AP35 -> -1.1678442 | AQ37: =SUM(AM37:AP37) -> -86.723343
C38: Non-GAAP Operating Margin | D38: =D37/D15 -> -3.2935743 | E38: =E37/E15 -> -2.9638515 | F38: =F37/F15 -> -2.2980319 | G38: =G37/G15 -> -0.98101883 | H38: =H37/H15 -> -1.9301757 | I38: =I37/I15 -> -2.6134312 | J38: =J37/J15 -> -2.829452 | K38: =K37/K15 -> -1.0308938 | ... AQ38: =AQ37/AQ15 -> -0.054543482
C40: GAAP Adjustments:
C41: Change in fair value of warrant | D41: 0 | E41: 0 | F41: 0 | G41: 0 | H41: =SUM(D41:G41) -> 0 | I41: 0 | J41: 0 | K41: 0 | L41: 0 | M41: =SUM(I41:L41) -> 0 | N41: 0 | O41: 0 | P41: 0 | Q41: 0 | R41: =SUM(N41:Q41) -> 0 | S41: -0.2 | T41: 3.2 | U41: 1.2 | V41: 0.5 | W41: =SUM(S41:V41) -> 4.7 | X41: -6.4 | Y41: 0.7 | Z41: -2.3 | AA41: -4.1 | AB41: =SUM(X41:AA41) -> -12.1 | AC41: 5.5 | AD41: 4.87 | AE41: 15.605 | AF41: -47.753 | AG41: =SUM(AC41:AF41) -> -21.778 | AH41: 31.85 | AI41: -37.546 | AJ41: 1.255 | AK41: -13.366 | AL41: =SUM(AH41:AK41) -> -17.807 | AM41: 0 | AN41: 0 | AO41: 0 | AP41: 0 | AQ41: =SUM(AM41:AP41) -> 0
C42: Stock-based compensation expense | D42: 0.13238493 | E42: 0.13238493 | F42: 3.0243849 | G42: 0.13202261 | H42: =SUM(D42:G42) -> 3.4211774 | I42: 0.09965667 | J42: 0.09965667 | K42: 0.09965667 | L42: 0.09965667 | M42: =SUM(I42:L42) -> 0.39862668 | N42: 0 | O42: 0.558749 | P42: 0 | Q42: 0 | R42: =SUM(N42:Q42) -> 0.558749 | S42: 0 | T42: 0 | U42: 0 | V42: 0 | W42: =SUM(S42:V42) -> 0 | X42: 0 | Y42: 0 | Z42: 0 | AA42: 0 | AB42: =SUM(X42:AA42) -> 0 | AC42: 0 | AD42: 488.313 | AE42: 21.038 | AF42: 24.787 | AG42: =SUM(AC42:AF42) -> 534.138 | AH42: 21.328 | AI42: 22.455 | AJ42: 33.979 | AK42: 45.339 | AL42: =SUM(AH42:AK42) -> 123.101 | AM42: 55 | AN42: 48.33 | AO42: 48.33 | AP42: 48.33 | AQ42: =SUM(AM42:AP42) -> 199.99
C43: Change in fair value of contingent consideration | D43: 0 | E43: 0 | F43: 0 | G43: 0 | H43: =SUM(D43:G43) -> 0 | I43: 0 | J43: 0 | K43: 0 | L43: 6.891 | M43: =SUM(I43:L43) -> 6.891 | N43: 0 | O43: 4.1488117 | P43: 0.445 | Q43: 0.64017596 | R43: =SUM(N43:Q43) -> 5.2339876 | S43: -2.2343574 | T43: -1.6117633 | U43: -0.03491184 | V43: 0.18039239 | W43: =SUM(S43:V43) -> -3.7006401 | X43: 0 | Y43: 0.04300932 | Z43: -0.39807103 | AA43: 0.16396916 | AB43: =SUM(X43:AA43) -> -0.19109255 | AC43: 0.15597065 | AD43: 0 | AE43: 0 | AF43: 0 | AG43: =SUM(AC43:AF43) -> 0.15597065 | AH43: 0 | AI43: 0 | AJ43: 0 | AK43: 0 | AL43: =SUM(AH43:AK43) -> 0 | AM43: 0 | AN43: 0 | AO43: 0 | AP43: 0 | AQ43: =SUM(AM43:AP43) -> 0
C44: Unrealized Gain/Loss on Stock | D44: 0 | E44: 0 | F44: 0 | G44: 0 | H44: =SUM(D44:G44) -> 0 | I44: 0 | J44: 0 | K44: 0 | L44: 0 | M44: =SUM(I44:L44) -> 0 | N44: 0 | O44: 0 | P44: 0 | Q44: 0 | R44: =SUM(N44:Q44) -> 0 | S44: 0 | T44: 0 | U44: 0 | V44: 0 | W44: =SUM(S44:V44) -> 0 | X44: 0 | Y44: 0 | Z44: 0 | AA44: -9.8073937 | AB44: =SUM(X44:AA44) -> -9.8073937 | AC44: -0.165 | AD44: 0 | AE44: 0 | AF44: 0 | AG44: =SUM(AC44:AF44) -> -0.165 | AH44: 1.6 | AI44: 0 | AJ44: 0 | AK44: 0 | AL44: =SUM(AH44:AK44) -> 1.6 | AM44: 0 | AN44: 0 | AO44: 0 | AP44: 0 | AQ44: =SUM(AM44:AP44) -> 0
C45: Loss on debt extinguishment | AK45: 0
C46: Amortization of intangibles | AH46: 11.156 | AI46: 16.771 | AJ46: 16.764 | AK46: 16.838 | AL46: =SUM(AH46:AK46) -> 61.529
C47: Settlement Costs | D47: 0 | E47: 0 | F47: 0 | G47: 0 | H47: =SUM(D47:G47) -> 0 | I47: 0 | J47: 0 | K47: 0 | L47: 0 | M47: =SUM(I47:L47) -> 0 | N47: 0 | O47: 0 | P47: 0 | Q47: 0 | R47: =SUM(N47:Q47) -> 0 | S47: 0 | T47: 0 | U47: 0 | V47: 0 | W47: =SUM(S47:V47) -> 0 | X47: 0 | Y47: 0 | Z47: 0 | AA47: 8.625 | AB47: =SUM(X47:AA47) -> 8.625 | AC47: -6.0798898 | AD47: 0 | AE47: 0 | AF47: 0 | AG47: =SUM(AC47:AF47) -> -6.0798898 | AH47: 0 | AI47: 1.647 | AJ47: 0 | AK47: 0 | AL47: =SUM(AH47:AK47) -> 1.647 | AM47: 0 | AN47: 0 | AO47: 0 | AP47: 0 | AQ47: =SUM(AM47:AP47) -> 0
C48: Transaction Costs | D48: 0 | E48: 0 | F48: 0 | G48: 0 | H48: =SUM(D48:G48) -> 0 | I48: 0 | J48: 0 | K48: 0 | L48: 0 | M48: =SUM(I48:L48) -> 0 | N48: 0 | O48: 0 | P48: 0 | Q48: 0.194091 | R48: =SUM(N48:Q48) -> 0.194091 | S48: 0.0066863 | T48: 0 | U48: 0.475 | V48: 0 | W48: =SUM(S48:V48) -> 0.4816863 | X48: 0 | Y48: 0 | Z48: 0.671906 | AA48: -0.0145796 | AB48: =SUM(X48:AA48) -> 0.6573264 | AC48: 0 | AD48: 0 | AE48: 0 | AF48: 2.536 | AG48: =SUM(AC48:AF48) -> 2.536 | AH48: 3.529 | AI48: =1.992+1.647 -> 3.639 | AJ48: 0.552 | AK48: 3.149 | AL48: =SUM(AH48:AK48) -> 10.869 | AM48: 0 | AN48: 0 | AO48: 0 | AP48: 0 | AQ48: =SUM(AM48:AP48) -> 0
C49: Employer payroll tax related to SBC | AD49: 4.762 | AE49: 1.201 | AF49: 7.58 | AH49: 5.162 | AI49: 1.873 | AJ49: 1.039 | AK49: 3.374 | AL49: =SUM(AH49:AK49) -> 11.448
C50: G-4 Special Payment | AD50: 2.25 | AE50: 0 | AF50: 0 | AI50: 0 | AK50: 0 | AL50: =SUM(AH50:AK50) -> 0
...

Sheet BS
C2: Tempus Labs (NASDAQ: TEM)
B5: Balance Sheet | D5: 1Q19 | E5: 2Q19 | F5: 3Q19 | G5: 4Q19 | H5: FY19 | I5: 1Q20 | J5: 2Q20 | K5: 3Q20 | L5: 4Q20 | M5: FY20 | N5: 1Q21 | O5: 2Q21 | P5: 3Q21 | Q5: 4Q21 | R5: FY21 | S5: 1Q22 | T5: 2Q22 | U5: 3Q22 | V5: 4Q22 | W5: FY22 | X5: 1Q23 | Y5: 2Q23 | Z5: 3Q23 | AA5: 4Q23 | AB5: FY23 | AC5: 1Q24 | AD5: 2Q24 | AE5: 3Q24 | AF5: 4Q24 | AG5: FY24 | AH5: 1Q25 | AI5: 2Q25 | AJ5: 3Q25 | AK5: 4Q25 | AL5: FY25 | AM5: 1Q26E | AN5: 2Q26E | AO5: 3Q26E | AP5: 4Q26E | AQ5: FY26E
B6: Assets:
C7: Cash | D7: 162.63119 | E7: 322.80265 | F7: 296.20918 | G7: 228.1001 | H7: =G7 -> 228.1001 | I7: 268.0867 | J7: 532.96034 | K7: 465.50434 | L7: 514.216 | M7: =L7 -> 514.216 | N7: 471.931 | O7: 423.178 | P7: 345.725 | Q7: 278.466 | R7: =Q7 -> 278.466 | S7: 178.44295 | T7: 197.90377 | U7: 369.80596 | V7: 303.73118 | W7: =V7 -> 303.73118 | X7: 224.55794 | Y7: 203.07741 | Z7: 133.52737 | AA7: 166.60703 | AB7: =AA7 -> 166.60703 | AC7: 80.7923 | AD7: 478.811 | AE7: 388.006 | AF7: 340.954 | AG7: =AF7 -> 340.954 | AH7: 151.603 | AI7: 186.31 | AJ7: 655.918 | AK7: 604.787 | AL7: =AK7 -> 604.787 | AM7: =AK7+CF!AM80 -> 662.2392 | AN7: =AM7+CF!AN80 -> 658.89784 | AO7: =AN7+CF!AO80 -> 640.95473 | AP7: =AO7+CF!AP80 -> 659.00933 | AQ7: =AP7 -> 659.00933
C8: Marketable equity securities | D8: 0 | E8: 0 | F8: 0 | G8: 0 | H8: =G8 -> 0 | I8: 0 | J8: 0 | K8: 0 | L8: 0 | M8: =L8 -> 0 | N8: 0 | O8: 0 | P8: 0 | Q8: 0 | R8: =Q8 -> 0 | S8: 0 | T8: 0 | U8: 0 | V8: 0 | W8: =V8 -> 0 | X8: 0 | Y8: 0 | Z8: 0 | AA8: 31.807394 | AB8: =AA8 -> 31.807394 | AC8: 14.956498 | AD8: 11.255 | AE8: 78.317 | AF8: 107.309 | AG8: =AF8 -> 107.309 | AH8: 67.183 | AI8: 104.996 | AJ8: 103.72 | AK8: 150.211 | AL8: =AK8 -> 150.211 | AM8: =AK8 -> 150.211 | AN8: =AM8 -> 150.211 | AO8: =AN8 -> 150.211 | AP8: =AO8 -> 150.211 | AQ8: =AP8 -> 150.211
C9: Accounts receivable/ pre-paid expenses | D9: 16.203311 | E9: 20.730174 | F9: 22.028856 | G9: 39.82562 | H9: =G9 -> 39.82562 | I9: 27.820868 | J9: 32.032857 | K9: 63.333 | L9: 98.737 | M9: =L9 -> 98.737 | N9: 78.198 | O9: 9.263 | P9: 85.623 | Q9: 99.535 | R9: =Q9 -> 99.535 | S9: 99.751542 | T9: 95.903162 | U9: 97.190442 | V9: 113.40836 | W9: =V9 -> 113.40836 | X9: 123.60367 | Y9: 120.26196 | Z9: 140.99741 | AA9: 128.84206 | AB9: =AA9 -> 128.84206 | AC9: 144.33614 | AD9: =118.106+29.704 -> 147.81 | AE9: =31.335+145.616 -> 176.951 | AF9: =154.819+26.135 -> 180.954 | AG9: =AF9 -> 180.954 | AH9: =262.613+42.086 -> 304.699 | AI9: =266.284+36.476 -> 302.76 | AJ9: =283.626+42.611 -> 326.237 | AK9: =311.17+40.498 -> 351.668 | AL9: =AK9 -> 351.668 | AM9: =AM55*IS!AM15 -> 275.96636 | AN9: =AN55*IS!AN15 -> 296.23676 | AO9: =AO55*IS!AO15 -> 269.85776 | AP9: =AP55*IS!AP15 -> 239.61854 | AQ9: =AP9 -> 239.61854
C10: Warrant asset | AD10: 0.8 | AE10: 0 | AF10: 0 | AG10: =AF10 -> 0 | AH10: 0 | AI10: 2.535 | AJ10: 5.66 | AK10: 8.785 | AL10: =AK10 -> 8.785
C11: Inventory | D11: 5.4685583 | E11: 6.8028628 | F11: 6.494006 | G11: 8.2786812 | H11: =G11 -> 8.2786812 | I11: 8.369762 | J11: 25.423183 | K11: 32.601 | L11: 37.557 | M11: =L11 -> 37.557 | N11: 30.732 | O11: 27.704 | P11: 21.998 | Q11: 22.908 | R11: =Q11 -> 22.908 | S11: 17.299143 | T11: 20.64646 | U11: 21.028572 | V11: 22.281781 | W11: =V11 -> 22.281781 | X11: 25.211479 | Y11: 27.382672 | Z11: 27.157111 | AA11: 28.845248 | AB11: =AA11 -> 28.845248 | AC11: 30.129189 | AD11: 32.69 | AE11: 36.138 | AF11: 38.386 | AG11: =AF11 -> 38.386 | AH11: 50.485 | AI11: 47.6 | AJ11: 54.976 | AK11: 51.724 | AL11: =AK11 -> 51.724 | AM11: =AM56*IS!AM15 -> 50.018902 | AN11: =AN56*IS!AN15 -> 53.322616 | AO11: =AO56*IS!AO15 -> 51.895724 | AP11: =AP56*IS!AP15 -> 52.402966 | AQ11: =AP11 -> 52.402966
B12: Total Current Assets | D12: =SUM(D7:D11) -> 184.30306 | E12: =SUM(E7:E11) -> 350.33569 | F12: =SUM(F7:F11) -> 324.73204 | G12: =SUM(G7:G11) -> 276.2044 | H12: =G12 -> 276.2044 | I12: =SUM(I7:I11) -> 304.27733 | J12: =SUM(J7:J11) -> 590.41638 | K12: =SUM(K7:K11) -> 561.43834 | L12: =SUM(L7:L11) -> 650.51 | M12: =L12 -> 650.51 | N12: =SUM(N7:N11) -> 580.861 | O12: =SUM(O7:O11) -> 460.145 | P12: =SUM(P7:P11) -> 453.346 | Q12: =SUM(Q7:Q11) -> 400.909 | R12: =Q12 -> 400.909 | S12: =SUM(S7:S11) -> 295.49363 | T12: =SUM(T7:T11) -> 314.45339 | U12: =SUM(U7:U11) -> 488.02497 | V12: =SUM(V7:V11) -> 439.42132 | W12: =V12 -> 439.42132 | X12: =SUM(X7:X11) -> 373.37309 | Y12: =SUM(Y7:Y11) -> 350.72204 | Z12: =SUM(Z7:Z11) -> 301.68189 | AA12: =SUM(AA7:AA11) -> 356.10173 | AB12: =AA12 -> 356.10173 | AC12: =SUM(AC7:AC11) -> 270.21413 | AD12: =SUM(AD7:AD11) -> 671.366 | AE12: =SUM(AE7:AE11) -> 679.412 | AF12: =SUM(AF7:AF11) -> 667.603 | AG12: =AF12 -> 667.603 | AH12: =SUM(AH7:AH11) -> 573.97 | AI12: =SUM(AI7:AI11) -> 644.201 | AJ12: =SUM(AJ7:AJ11) -> 1146.511 | AK12: =SUM(AK7:AK11) -> 1167.175 | AL12: =AK12 -> 1167.175 | AM12: =SUM(AM7:AM11) -> 1138.4355 | AN12: =SUM(AN7:AN11) -> 1158.6682 | AO12: =SUM(AO7:AO11) -> 1112.9192 | AP12: =SUM(AP7:AP11) -> 1101.2418 | AQ12: =AP12 -> 1101.2418
C13: PP&E | D13: 20.596058 | E13: 23.187417 | F13: 25.607426 | G13: 36.065028 | H13: =G13 -> 36.065028 | I13: 34.408 | J13: 36.98096 | K13: 36.86 | L13: 38.435 | M13: =L13 -> 38.435 | N13: 36.3 | O13: 35.215 | P13: 35.999 | Q13: 35.395 | R13: =Q13 -> 35.395 | S13: 39.460915 | T13: 46.01009 | U13: 45.205557 | V13: 44.105478 | W13: =V13 -> 44.105478 | X13: 45.203759 | Y13: 50.451767 | Z13: 63.138071 | AA13: 61.680691 | AB13: =AA13 -> 61.680691 | AC13: 59.217122 | AD13: 60.539 | AE13: 59.362 | AF13: 58.056 | AG13: =AF13 -> 58.056 | AH13: 93.536 | AI13: 92.563 | AJ13: 90.71 | AK13: 89.156 | AL13: =AK13 -> 89.156 | AM13: =AK13-CF!AM9-CF!AM50 -> 61.656 | AN13: =AM13-CF!AN9-CF!AN50 -> 34.156 | AO13: =AN13-CF!AO9-CF!AO50 -> 6.656 | AP13: =AO13-CF!AP9-CF!AP50 -> -20.844 | AQ13: =AP13 -> -20.844
C14: Goodwill | AD14: 73.345 | AE14: 73.365 | AF14: 73.343 | AG14: =AF14 -> 73.343 | AH14: 325.774 | AI14: 325.793 | AJ14: 465.14 | AK14: 470.211 | AL14: =AK14 -> 470.211
C15: Warrant asset, less current portion | AD15: 1.5 | AE15: 0 | AF15: 0 | AG15: =AF15 -> 0 | AH15: 0 | AI15: 0 | AJ15: 0 | AK15: 0 | AL15: =AK15 -> 0
C16: Intangible assets, net | AD16: 16.252 | AE16: 14.289 | AF16: 11.716 | AG16: =AF16 -> 11.716 | AH16: 399.544 | AI16: 387.564 | AJ16: 372.876 | AK16: 355.253 | AL16: =AK16 -> 355.253
C17: Investments and other assets | D17: 27.056283 | E17: 25.422761 | F17: 28.424601 | G17: 57.9018 | H17: =G17 -> 57.9018 | I17: 68.945168 | J17: 66.463479 | K17: 64.407 | L17: 62.973 | M17: =L17 -> 62.973 | N17: 59.976 | O17: 108.826 | P17: 62.002 | Q17: 95.05 | R17: =Q17 -> 95.05 | S17: 149.50383 | T17: 145.34536 | U17: 139.73293 | V17: 147.83799 | W17: =V17 -> 147.83799 | X17: 150.52989 | Y17: 144.86559 | Z17: 139.24962 | AA17: 146.26981 | AB17: =AA17 -> 146.26981 | AC17: 139.84196 | AD17: 7.677 | AE17: =8.692+103.699 -> 112.391 | AF17: =8.305+91.45 -> 99.755 | AG17: =AF17 -> 99.755 | AH17: =14.811+94.153 -> 108.964 | AI17: =16.669+95.718 -> 112.387 | AJ17: =20.948+94.367 -> 115.315 | AK17: =86.557+21.111 -> 107.668 | AL17: =AK17 -> 107.668 | AM17: =AM58*IS!AM15 -> 189.72687 | AN17: =AN58*IS!AN15 -> 177.74205 | AO17: =AO58*IS!AO15 -> 145.30803 | AP17: =AP58*IS!AP15 -> 107.41521 | AQ17: =AP17 -> 107.41521
C18: Warrant contract asset, less current portion | AD18: 19.077 | AE18: 17.866 | AF18: 0 | AH18: 0 | AI18: 22.465 | AJ18: 19.34 | AK18: 16.215 | AL18: =AK18 -> 16.215
C19: Operating lease right-of-use assets | AD19: 13.994 | AE19: 14.141 | AF19: 14.762 | AH19: 39.626 | AI19: 38.651 | AJ19: 66.901 | AK19: 64.496 | AL19: =AK19 -> 64.496
C20: Restricted cash | AD20: 0.861 | AE20: 0.872 | AF20: 0.881 | AH20: 1.723 | AI20: 1.741 | AJ20: 4.631 | AK20: 4.664 | AL20: =AK20 -> 4.664
C21: Acquisition | D21: 0 | E21: 0 | F21: 0 | G21: 0 | H21: =G21 -> 0 | I21: 0 | J21: 0 | K21: 0 | L21: 0 | M21: =L21 -> 0 | N21: 0 | O21: 0 | P21: 0 | Q21: 0 | R21: =Q21 -> 0 | S21: 0 | T21: 0 | U21: 0 | V21: 0 | W21: =V21 -> 0 | X21: 0 | Y21: 0 | Z21: 0 | AA21: 0 | AB21: =AA21 -> 0 | AC21: 0 | AD21: 0 | AE21: 0 | AF21: 0 | AG21: =AF21 -> 0 | AH21: 0 | AI21: 0 | AJ21: 0 | AK21: 0 | AL21: =AK21 -> 0 | AM21: =AM59*IS!AM15 -> 0 | AN21: =AN59*IS!AN15 -> 0 | AO21: =AO59*IS!AO15 -> 0 | AP21: =AP59*IS!AP15 -> 0 | AQ21: =AP21 -> 0
B22: Total Assets | D22: =SUM(D12:D21) -> 231.9554 | E22: =SUM(E12:E21) -> 398.94587 | F22: =SUM(F12:F21) -> 378.76407 | G22: =SUM(G12:G21) -> 370.17123 | H22: =G22 -> 370.17123 | I22: =SUM(I12:I21) -> 407.63049 | J22: =SUM(J12:J21) -> 693.86082 | K22: =SUM(K12:K21) -> 662.70534 | L22: =SUM(L12:L21) -> 751.918 | M22: =L22 -> 751.918 | N22: =SUM(N12:N21) -> 677.137 | O22: =SUM(O12:O21) -> 604.186 | P22: =SUM(P12:P21) -> 551.347 | Q22: =SUM(Q12:Q21) -> 531.354 | R22: =Q22 -> 531.354 | S22: =SUM(S12:S21) -> 484.45838 | T22: =SUM(T12:T21) -> 505.80884 | U22: =SUM(U12:U21) -> 672.96346 | V22: =SUM(V12:V21) -> 631.36479 | W22: =V22 -> 631.36479 | X22: =SUM(X12:X21) -> 569.10673 | Y22: =SUM(Y12:Y21) -> 546.0394 | Z22: =SUM(Z12:Z21) -> 504.06958 | AA22: =SUM(AA12:AA21) -> 564.05223 | AB22: =AA22 -> 564.05223 | AC22: =SUM(AC12:AC21) -> 469.27321 | AD22: =SUM(AD12:AD21) -> 864.611 | AE22: =SUM(AE12:AE21) -> 971.698 | AF22: =SUM(AF12:AF21) -> 926.116 | AG22: =AF22 -> 926.116 | AH22: =SUM(AH12:AH21) -> 1543.137 | AI22: =SUM(AI12:AI21) -> 1625.365 | AJ22: =SUM(AJ12:AJ21) -> 2281.424 | AK22: =SUM(AK12:AK21) -> 2274.838 | AL22: =AK22 -> 2274.838 | AM22: =SUM(AM12:AM21) -> 1389.8183 | AN22: =SUM(AN12:AN21) -> 1370.5663 | AO22: =SUM(AO12:AO21) -> 1264.8832 | AP22: =SUM(AP12:AP21) -> 1187.813 | AQ22: =AP22 -> 1187.813
R23: =Q23 -> 0 | W23: =V23 -> 0 | AB23: =AA23 -> 0 | AG23: =AF23 -> 0 | AL23: =AK23 -> 0 | AQ23: =AP23 -> 0
B24: Liabilities: | R24: =Q24 -> 0 | W24: =V24 -> 0 | AB24: =AA24 -> 0 | AG24: =AF24 -> 0 | AL24: =AK24 -> 0 | AQ24: =AP24 -> 0
C25: Accounts payable/ accrued expenses | D25: 13.352296 | E25: 15.746838 | F25: 14.896405 | G25: 21.365342 | H25: =G25 -> 21.365342 | I25: 26.627932 | J25: 24.180251 | K25: 52.010728 | L25: 73.749 | M25: =L25 -> 73.749 | N25: 63.233 | O25: 59.033 | P25: 72.502 | Q25: 74.447 | R25: =Q25 -> 74.447 | S25: 82.930425 | T25: 85.8265 | U25: 91.386372 | V25: 106.19237 | W25: =V25 -> 106.19237 | X25: 105.82693 | Y25: 115.28837 | Z25: 128.23074 | AA25: 132.42166 | AB25: =AA25 -> 132.42166 | AC25: 117.42412 | AD25: =28.646+85.185 -> 113.831 | AE25: =49.027+101.985 -> 151.012 | AF25: =53.804+130.407 -> 184.211 | AG25: =AF25 -> 184.211 | AH25: =88.732+129.238 -> 217.97 | AI25: =79.323+165.903+25 -> 270.226 | AJ25: =59.553+160.773 -> 220.326 | AK25: =81.994+155.37 -> 237.364 | AL25: =AK25 -> 237.364 | AM25: =IS!AM15*BS!AM62 -> 241.47056 | AN25: =IS!AN15*BS!AN62 -> 256.73852 | AO25: =IS!AO15*BS!AO62 -> 249.09947 | AP25: =IS!AP15*BS!AP62 -> 247.22893 | AQ25: =AP25 -> 247.22893
C26: Deferred revenue | D26: 1.9963714 | E26: 5.2181112 | F26: 4.8041793 | G26: 5.5704542 | H26: =G26 -> 5.5704542 | I26: 4.3301905 | J26: 4.5862765 | K26: 4.1793549 | L26: 6.965 | M26: =L26 -> 6.965 | N26: 5.845 | O26: 5.917 | P26: 15.416 | Q26: 16.454 | R26: =Q26 -> 16.454 | S26: 17.344228 | T26: 12.146248 | U26: 82.148637 | V26: 85.27815 | W26: =V26 -> 85.27815 | X26: 82.208317 | Y26: 66.065964 | Z26: 69.396068 | AA26: 81.627424 | AB26: =AA26 -> 81.627424 | AC26: 65.655672 | AD26: 50.905 | AE26: =67.604+15.955 -> 83.559 | AF26: 75.981 | AG26: =AF26 -> 75.981 | AH26: 73.431 | AI26: 100.477 | AJ26: 84.719 | AK26: 92.673 | AL26: =AK26 -> 92.673 | AM26: =IS!AM15*BS!AM63 -> 155.23108 | AN26: =IS!AN15*BS!AN63 -> 157.99294 | AO26: =IS!AO15*BS!AO63 -> 145.30803 | AP26: =IS!AP15*BS!AP63 -> 139.68326 | AQ26: =AP26 -> 139.68326
C27: Deferred other income | AH27: 15.955 | AI27: 15.955 | AJ27: 15.955 | AK27: 15.955 | AL27: =AK27 -> 15.955
C28: Other current liabilities | AD28: 7.273 | AE28: =9.913 -> 9.913 | AF28: 6.964 | AH28: 18.194 | AI28: 16.554 | AJ28: 11.819 | AK28: 8.68 | AL28: =AK28 -> 8.68
C29: Operating lease liabilities | AD29: 5.828 | AE29: =5.894 -> 5.894 | AF29: 6.459 | AH29: 9.42 | AI29: 9.381 | AJ29: 12.417 | AK29: 13.355 | AL29: =AK29 -> 13.355
C30: Accrued data licensing fees | AD30: 3.727 | AE30: =2.242 -> 2.242 | AF30: 1.5 | AH30: 1.5 | AI30: 5.567 | AJ30: 4.792 | AK30: 4.361 | AL30: =AK30 -> 4.361
C31: Accrued dividends | AD31: 0 | AE31: 0 | AF31: 0 | AH31: 0 | AI31: 0 | AJ31: 0 | AK31: 0 | AL31: =AK31 -> 0
C32: Operating lease liabilities, less current portion | AD32: 27.238 | AE32: 26.664 | AF32: 26.199 | AH32: 47.567 | AI32: 45.866 | AJ32: 77.723 | AK32: 74.272 | AL32: =AK32 -> 74.272
C33: Convertible promissory note | D33: 0 | E33: 0 | F33: 0 | G33: 0 | H33: =G33 -> 0 | I33: 0 | J33: 330 | K33: 330 | L33: 250 | M33: =L33 -> 250 | N33: 249.058 | O33: 246.581 | P33: 243.42 | Q33: 238.236 | R33: =Q33 -> 238.236 | S33: 235.05403 | T33: 231.7628 | U33: 228.01513 | V33: 221.09384 | W33: =V33 -> 221.09384 | X33: 216.03447 | Y33: 207.16753 | Z33: 198.87366 | AA33: 193.12379 | AB33: =AA33 -> 193.12379 | AC33: 186.73266 | AD33: 180.648 | AE33: 174.46 | AF33: 168.192 | AG33: =AF33 -> 168.192 | AH33: 233.62 | AI33: 226.342 | AJ33: 217.959 | AK33: 208.672 | AL33: =AK33 -> 208.672 | AM33: =AK33-8.9 -> 199.772 | AN33: =AM33-8.9 -> 190.872 | AO33: =AN33-8.9 -> 181.972 | AP33: =AO33-8.9 -> 173.072 | AQ33: =AP33 -> 173.072
C34: Warrant liability | AD34: 33.6 | AE34: 76.9 | AF34: 0 | AH34: 0 | AI34: 0 | AJ34: 0 | AK34: 0 | AL34: =AK34 -> 0
C35: Interest payable | AD35: 62.608 | AE35: 66.529 | AF35: 70.45 | AH35: 1.47 | AI35: 5.084 | AJ35: 8.739 | AK35: 12.393 | AL35: =AK35 -> 12.393
C36: Revolving credit facility | AH36: 100 | AI36: 100 | AJ36: 100 | AK36: 100 | AL36: =AK36 -> 100
C37: Term loan debt | D37: 0 | E37: 0 | F37: 0 | G37: 0 | H37: =G37 -> 0 | I37: 0 | J37: 0 | K37: 0 | L37: 0 | M37: =L37 -> 0 | N37: 0 | O37: 0 | P37: 0 | Q37: 0 | R37: =Q37 -> 0 | S37: 0 | T37: -0.015 | U37: 168.07475 | V37: 168.45179 | W37: =V37 -> 168.45179 | X37: 168.79806 | Y37: 218.24333 | Z37: 220.4845 | AA37: 256.54135 | AB37: =AA37 -> 256.54135 | AC37: 259.1965 | AD37: 261.853 | AE37: 264.527 | AF37: 267.244 | AG37: =AF37 -> 267.244 | AH37: 467.144 | AI37: 471.663 | AJ37: 200.859 | AK37: 202.753 | AL37: =AK37 -> 202.753 | AM37: =AK37 -> 202.753 | AN37: =AM37 -> 202.753 | AO37: =AN37 -> 202.753 | AP37: =AO37 -> 202.753 | AQ37: =AP37 -> 202.753
C38: Convertible senior notes | AJ38: 726.863 | AK38: 728.078 | AL38: =AK38 -> 728.078
C39: Deferred revenue, less current portion | AD39: 2.059 | AE39: =12.976+27.921 -> 40.897 | AF39: =6.71+23.932+15.955 -> 46.597 | AH39: 1.058 | AI39: 23.225 | AJ39: 20.691 | AK39: 20.379 | AL39: =AK39 -> 20.379
C40: Deferred other income, less current portion | AH40: 19.944 | AI40: 15.955 | AJ40: 11.966 | AK40: 7.977 | AL40: =AK40 -> 7.977
C41: Other long-term liabilities | D41: 45.750416 | E41: 50.383916 | F41: 61.395561 | G41: 81.378557 | H41: =G41 -> 81.378557 | I41: 63.527681 | J41: 59.356797 | K41: 59.695985 | L41: 75.032 | M41: =L41 -> 75.032 | N41: 70.349 | O41: 71.699 | P41: 68.351 | Q41: 111.417 | R41: =Q41 -> 111.417 | S41: 140.74676 | T41: 150.56595 | U41: 147.71515 | V41: 153.23251 | W41: =V41 -> 153.23251 | X41: 154.47764 | Y41: 156.4313 | Z41: 160.14372 | AA41: 176.9576 | AB41: =AA41 -> 176.9576 | AC41: 179.88672 | AD41: 16.79 | AE41: 15.403 | AF41: 15.98 | AG41: =AF41 -> 15.98 | AH41: 9.67 | AI41: 9.508 | AJ41: 58.772 | AK41: 56.6 | AL41: =AK41 -> 56.6 | AM41: =IS!AM15*BS!AM66 -> 310.46215 | AN41: =IS!AN15*BS!AN66 -> 315.98587 | AO41: =IS!AO15*BS!AO66 -> 290.61605 | AP41: =IS!AP15*BS!AP66 -> 249.44682 | AQ41: =AP41 -> 249.44682
B42: Total Liabilities | D42: =SUM(D25:D41) -> 61.099084 | E42: =SUM(E25:E41) -> 71.348865 | F42: =SUM(F25:F41) -> 81.096145 | G42: =SUM(G25:G41) -> 108.31435 | H42: =G42 -> 108.31435 | I42: =SUM(I25:I41) -> 94.485804 | J42: =SUM(J25:J41) -> 418.12332 | K42: =SUM(K25:K41) -> 445.88607 | L42: =SUM(L25:L41) -> 405.746 | M42: =L42 -> 405.746 | N42: =SUM(N25:N41) -> 388.485 | O42: =SUM(O25:O41) -> 383.23 | P42: =SUM(P25:P41) -> 399.689 | Q42: =SUM(Q25:Q41) -> 440.554 | R42: =Q42 -> 440.554 | S42: =SUM(S25:S41) -> 476.07545 | T42: =SUM(T25:T41) -> 480.28649 | U42: =SUM(U25:U41) -> 717.34004 | V42: =SUM(V25:V41) -> 734.24866 | W42: =V42 -> 734.24866 | X42: =SUM(X25:X41) -> 727.34542 | Y42: =SUM(Y25:Y41) -> 763.19649 | Z42: =SUM(Z25:Z41) -> 777.12869 | AA42: =SUM(AA25:AA41) -> 840.67183 | AB42: =AA42 -> 840.67183 | AC42: =SUM(AC25:AC41) -> 808.89567 | AD42: =SUM(AD25:AD41) -> 766.36 | AE42: =SUM(AE25:AE41) -> 918 | AF42: =SUM(AF25:AF41) -> 869.777 | AG42: =AF42 -> 869.777 | AH42: =SUM(AH25:AH41) -> 1216.943 | AI42: =SUM(AI25:AI41) -> 1315.803 | AJ42: =SUM(AJ25:AJ41) -> 1773.6 | AK42: =SUM(AK25:AK41) -> 1783.512 | AL42: =AK42 -> 1783.512 | AM42: =SUM(AM25:AM41) -> 1109.6888 | AN42: =SUM(AN25:AN41) -> 1124.3423 | AO42: =SUM(AO25:AO41) -> 1069.7486 | AP42: =SUM(AP25:AP41) -> 1012.184 | AQ42: =AP42 -> 1012.184
M43: =L43 -> 0 | R43: =Q43 -> 0 | W43: =V43 -> 0 | AB43: =AA43 -> 0 | AG43: =AF43 -> 0 | AL43: =AK43 -> 0 | AQ43: =AP43 -> 0
...

Sheet CF
C2: Tempus Labs (NASDAQ: TEM)
B4: Statement of Cash Flows | D4: 1Q19 | E4: 2Q19 | F4: 3Q19 | G4: 4Q19 | H4: FY19 | I4: 1Q20 | J4: 2Q20 | K4: 3Q20 | L4: 4Q20 | M4: FY20 | N4: 1Q21 | O4: 2Q21 | P4: 3Q21 | Q4: 4Q21 | R4: FY21 | S4: 1Q22 | T4: 2Q22 | U4: 3Q22 | V4: 4Q22 | W4: FY22 | X4: 1Q23 | Y4: 2Q23 | Z4: 3Q23 | AA4: 4Q23 | AB4: FY23 | AC4: 1Q24 | AD4: 2Q24 | AE4: 3Q24 | AF4: 4Q24 | AG4: FY24 | AH4: 1Q25 | AI4: 2Q25 | AJ4: 3Q25 | AK4: 4Q25 | AL4: FY25 | AM4: 1Q26E | AN4: 2Q26E | AO4: 3Q26E | AP4: 4Q26E | AQ4: FY26E
B6: Net Income | D6: -24.393366 | E6: -30.204948 | F6: -33.560787 | G6: -26.792228 | H6: =SUM(D6:G6) -> -114.95133 | I6: -47.102917 | J6: -51.098613 | K6: -57.509399 | L6: -54.143518 | M6: =SUM(I6:L6) -> -209.85445 | N6: -65.020109 | O6: -66.84707 | P6: -68.342884 | Q6: -58.981033 | R6: =SUM(N6:Q6) -> -259.1911 | S6: -81.289321 | T6: -73.691057 | U6: -68.544865 | V6: -66.283812 | W6: =SUM(S6:V6) -> -289.80906 | X6: -54.375274 | Y6: -55.833222 | Z6: -53.425996 | AA6: -50.484901 | AB6: =SUM(X6:AA6) -> -214.11939 | AC6: -64.744056 | AD6: =-616.955-AC6 -> -552.21094 | AE6: =-692.795-AD6-AC6 -> -75.84 | AF6: =AG6-AE6-AD6-AC6 -> -13.014 | AG6: -705.809 | AH6: -68.037 | AI6: =-110.88-AH6 -> -42.843 | AJ6: =-190.862-AI6-AH6 -> -79.982 | AK6: =IS!AK78 -> -51.017 | AL6: -245.028 | AM6: =IS!AM78 -> -104.49199 | AN6: =IS!AN78 -> -82.322466 | AO6: =IS!AO78 -> -70.301045 | AP6: =IS!AP78 -> -56.197844 | AQ6: =SUM(AM6:AP6) -> -313.31334
B8: Operating Activities
C9: Depreciation | D9: 1.7927251 | E9: 1.9027783 | F9: 1.9379328 | G9: 2.4502838 | H9: =SUM(D9:G9) -> 8.08372 | I9: 3.3228243 | J9: 2.9640176 | K9: 3.2719049 | L9: 3.5203932 | M9: =SUM(I9:L9) -> 13.07914 | N9: 3.5948192 | O9: 3.5965499 | P9: 3.478544 | Q9: 3.0888472 | R9: =SUM(N9:Q9) -> 13.75876 | S9: 2.4045999 | T9: 3.8903675 | U9: 4.5265056 | V9: 4.7803052 | W9: =SUM(S9:V9) -> 15.601778 | X9: 5.0592569 | Y9: 5.1939829 | Z9: 5.4043979 | AA9: 5.137539 | AB9: =SUM(X9:AA9) -> 20.795177 | AC9: 6.2696247 | AD9: =18.348-AC9 -> 12.078375 | AE9: =27.788-AD9-AC9 -> 9.44 | AF9: =AG9-AE9-AD9-AC9 -> 9.457 | AG9: =37.245 -> 37.245 | AH9: 20.353 | AI9: =48.385-AH9 -> 28.032 | AJ9: =75.416-AI9-AH9 -> 27.031 | AK9: =AL9-AJ9-AI9-AH9 -> 26.908 | AL9: 102.324 | AM9: 30 | AN9: 30 | AO9: 30 | AP9: 30 | AQ9: =SUM(AM9:AP9) -> 120
C10: Change in fair value of warrant liability | AD10: =-0.9-AC10 -> -0.9 | AE10: =42.4-AD10 -> 43.3 | AF10: =AG10-AE10-AD10-AC10 -> 1.4432899e-15 | AG10: 42.4 | AH10: 0 | AI10: 0 | AJ10: 0 | AK10: =AL10-AJ10-AI10-AH10 -> 0 | AL10: 0
C11: Gain on warrant exercise | AD11: =-0.173-AC11 -> -0.173 | AE11: =-0.173-AD11 -> 0 | AF11: =AG11-AE11-AD11-AC11 -> -39.1 | AG11: =-39.1-0.173 -> -39.273 | AH11: 0 | AI11: 0 | AJ11: 0 | AK11: =AL11-AJ11-AI11-AH11 -> 0 | AL11: 0
C12: Gain on marketable securities | AD12: =-2.541-AC12 -> -2.541 | AE12: =-5.119-AD12 -> -2.578 | AF12: =AG12-AE12-AD12-AC12 -> -6.991 | AG12: -12.11 | AH12: 31.805 | AI12: =-6.007-AH12 -> -37.812 | AJ12: =-4.731-AI12-AH12 -> 1.276 | AK12: =AL12-AJ12-AI12-AH12 -> -11.74 | AL12: -16.471
C13: Loss on disposal of property and equipment | AK13: =AL13-AJ13-AI13-AH13 -> 0.415 | AL13: 0.415
C14: Loss on debt extinguishment | AH14: 0 | AI14: 0 | AJ14: =12.034-AI14-AH14 -> 12.034 | AK14: =AL14-AJ14-AI14-AH14 -> 0 | AL14: 12.034
C15: Deferred income taxes | AH15: -46.216 | AI15: =-46.216-AH15 -> 0 | AJ15: =-46.216-AI15-AH15 -> 0 | AK15: =AL15-AJ15-AI15-AH15 -> -6.449 | AL15: =-52.665 -> -52.665
C16: Amortization of original issue discount | AD16: =0.691-AC16 -> 0.691 | AE16: =1.036-AD16 -> 0.345 | AF16: =AG16-AE16-AD16-AC16 -> 0.346 | AG16: 1.382 | AH16: 0.56 | AI16: =1.169-AH16 -> 0.609 | AJ16: =2.615-AI16-AH16 -> 1.446 | AK16: =AL16-AJ16-AI16-AH16 -> 1.473 | AL16: =4.088 -> 4.088
C17: Amortization of deferred financing fees | AD17: =0.255-AC17 -> 0.255 | AE17: =0.383-AD17 -> 0.128 | AF17: =AG17-AE17-AD17-AC17 -> 0.127 | AG17: 0.51 | AH17: 0.157 | AI17: =0.332-AH17 -> 0.175 | AJ17: =0.398-AI17-AH17 -> 0.066 | AK17: =AL17-AJ17-AI17-AH17 -> 0.086 | AL17: 0.484
C18: Change in fair value of contingent consideration | AD18: =0.165-AC18 -> 0.165 | AE18: =0.165-AD18 -> 0 | AF18: =AG18-AE18-AD18-AC18 -> -0.093 | AG18: =0.072 -> 0.072 | AH18: 0 | AI18: 0 | AJ18: 0 | AK18: =AL18-AJ18-AI18-AH18 -> 0 | AL18: 0
C19: Change in fair value of holdback liability | AH19: 0.046 | AI19: =0.312-AH19 -> 0.266 | AJ19: =0.291-AI19-AH19 -> -0.021 | AK19: =AL19-AJ19-AI19-AH19 -> -1.628 | AL19: -1.337
C20: Amortization of warrant contract asset | AD20: =2.422-AC20 -> 2.422 | AE20: =3.633-AD20 -> 1.211 | AF20: =AG20-AE20-AD20-AC20 -> -15.091 | AG20: =-16.301+4.843 -> -11.458 | AH20: 0 | AI20: 0 | AJ20: 0 | AK20: =AL20-AJ20-AI20-AH20 -> 0 | AL20: 0
C21: Provision for bad debt expense | AD21: =0.327-AC21 -> 0.327 | AE21: =0.545-AD21 -> 0.218 | AF21: =AG21-AE21-AD21-AC21 -> 0.135 | AG21: =0.68 -> 0.68 | AH21: 0.316 | AI21: =0.625-AH21 -> 0.309 | AJ21: =0.767-AI21-AH21 -> 0.142 | AK21: =AL21-AJ21-AI21-AH21 -> 1.791 | AL21: 2.558
C22: Provision for obsolete inventory | AH22: 0 | AI22: 0 | AJ22: =1.135-AI22-AH22 -> 1.135 | AK22: =AL22-AJ22-AI22-AH22 -> 0.2 | AL22: 1.335
C23: Change in fair value of warrant asset | AD23: =7.7-AC23 -> 7.7 | AE23: =-18.302-AD23 -> -26.002 | AF23: =AG23-AE23-AD23-AC23 -> -8.8817842e-16 | AG23: -18.302 | AH23: 0 | AI23: 0 | AJ23: 0 | AK23: =AL23-AJ23-AI23-AH23 -> 0 | AL23: 0
C24: Loss from equity-method investments | AD24: 0 | AE24: =1.692-AD24 -> 1.692 | AF24: =AG24-AE24-AD24-AC24 -> 2.536 | AG24: =4.228 -> 4.228 | AH24: 1.883 | AI24: =3.983-AH24 -> 2.1 | AJ24: =2.465-AI24-AH24 -> -1.518 | AK24: =AL24-AJ24-AI24-AH24 -> 3.149 | AL24: 5.614
C25: Amortization of finance right-of-use lease assets | AD25: 0 | AE25: =0-AD25 -> 0 | AF25: =AG25-AE25-AD25-AC25 -> 0 | AG25: 0 | AH25: 0 | AI25: 0 | AJ25: 0 | AK25: =AL25-AJ25-AI25-AH25 -> 0 | AL25: 0
C26: Non-cash operating lease costs | AD26: =3.252-AC26 -> 3.252 | AE26: =4.67-AD26 -> 1.418 | AF26: =AG26-AE26-AD26-AC26 -> 1.377 | AG26: 6.047 | AH26: 2.089 | AI26: =4.573-AH26 -> 2.484 | AJ26: =7.866-AI26-AH26 -> 3.293 | AK26: =AL26-AJ26-AI26-AH26 -> 3.688 | AL26: 11.554
C27: Minimum accretion expense | AD27: =0.092-AC27 -> 0.092 | AE27: =0.085-AD27 -> -0.007 | AF27: =AG27-AE27-AD27-AC27 -> 0.112 | AG27: 0.197 | AH27: 0.248 | AI27: =0.108-AH27 -> -0.14 | AJ27: =0.109-AI27-AH27 -> 0.001 | AK27: =AL27-AJ27-AI27-AH27 -> 0.159 | AL27: 0.268
C28: Impairment of intangible assets | AD28: 0 | AE28: =0-AD28 -> 0 | AF28: =AG28-AE28-AD28-AC28 -> 0 | AG28: 0 | AH28: 0 | AI28: 0 | AJ28: 0 | AK28: =AL28-AJ28-AI28-AH28 -> 0 | AL28: 0
C29: PIK interest added to principal | AD29: =4.366-AC29 -> 4.366 | AE29: =6.567-AD29 -> 2.201 | AF29: =AG29-AE29-AD29-AC29 -> 2.244 | AG29: 8.811 | AH29: 3.274 | AI29: =7.157-AH29 -> 3.883 | AJ29: =8.839-AI29-AH29 -> 1.682 | AK29: =AL29-AJ29-AI29-AH29 -> 1.698 | AL29: 10.537
C30: Interest payable - Google | D30: 0.01021187 | E30: 0.00760304 | F30: 0.0057988 | G30: 0.00481166 | H30: =SUM(D30:G30) -> 0.02842537 | I30: 0.14312638 | J30: -0.13652574 | K30: 5.5213461 | L30: 13.400725 | M30: =SUM(I30:L30) -> 18.928672 | N30: 3.7722974 | O30: 3.789743 | P30: 3.7892903 | Q30: 3.8321984 | R30: =SUM(N30:Q30) -> 15.183529 | S30: 4.2903923 | T30: 3.8553121 | U30: 4.5259343 | V30: 4.131687 | W30: =SUM(S30:V30) -> 16.803326 | X30: 3.7847314 | Y30: 3.8267839 | Z30: 4.1122515 | AA30: 4.1122515 | AB30: =SUM(X30:AA30) -> 15.836018 | AC30: 3.6433407 | AD30: =0-AC30 -> -3.6433407 | AE30: =0-AD30-AC30 -> 0 | AF30: =AG30-AE30-AD30-AC30 -> 0 | AG30: 0 | AH30: 0 | AI30: 0 | AJ30: 0 | AK30: =AL30-AJ30-AI30-AH30 -> 0 | AL30: 0 | AM30: 3.275 | AN30: 3.275 | AO30: 3.275 | AP30: 3.275 | AQ30: =SUM(AM30:AP30) -> 13.1
