Workbook
Name _1994: #REF!
Name _1994: #REF!
Name _1995: #REF!
Name _1995: #REF!
Name _1996: #REF!
Name _1996: #REF!
Name _1997: #REF!
Name _1997: #REF!
Name _1998: #REF!
Name _1998: #REF!
Name _1999: #REF!
Name _1999: #REF!
Name _1Q94: #REF!
Name _1Q94: #REF!
Name _1Q95: #REF!
Name _1Q95: #REF!
Name _2007: #REF!
Name _2007: #REF!
Name _2008: #REF!
Name _2008: #REF!
Name _2Q94: #REF!
Name _2Q94: #REF!
Name _2Q95: #REF!
Name _2Q95: #REF!
Name _3Q94: #REF!
Name _3Q94: #REF!
Name _3Q95: #REF!
Name _3Q95: #REF!
Name _4Q94: #REF!
Name _4Q94: #REF!
Name _4Q95: #REF!
Name _4Q95: #REF!
Name _Key1: #REF!
Name _Key1: #REF!
Name _marketsource: #REF!
Name _Order1: 0
Name _Sort: #REF!
Name _Sort: #REF!
Name _strtyr: #REF!
Name a: #REF!
Name a: #REF!
Name Acc_payable: #REF!
Name Acc_payable: #REF!
Name Acc_payable_growth_fore: #REF!
Name Acc_payable_growth_fore: #REF!
Name Acc_Rec: #REF!
Name Acc_Rec: #REF!
Name Acc_Rec_growth_fore: #REF!
Name Acc_Rec_growth_fore: #REF!
Name Acc_Rec_turns: #REF!
Name Acc_Rec_turns: #REF!
Name Accel_Ratio: #REF!
Name Accel_Ratio: #REF!
Name Accrued_compensation: #REF!
Name Accrued_compensation: #REF!
Name Accrued_compensation_growth_fore: #REF!
Name Accrued_compensation_growth_fore: #REF!
Name Accrued_expenses: #REF!
Name Accrued_expenses: #REF!
Name Accrued_expenses_growth_fore: #REF!

Sheet __FDSCACHE__
B1: This sheet contains FactSet XML data for use with this workbook's =FDS codes. Modifying the worksheet's contents may damage the workbook's =FDS functionality.

Sheet Disclaimer
C5: Equity Research
C7: Financial Model
C8: Life Science Tools & Diagnostics
C9: 46073
C12: Guardant Health (GH)
C19: Brandon Couillard | E19: Evan Stampler, PhD, CFA | G19: Chris Mercado, CFA
C20: Senior Analyst | E20: Vice President | G20: Vice President
C21: 212.214.5053 | E21: 212.214.5312 | G21: 212.214.8092
C22: brandon.couillard@wellsfargo.com | E22: evan.stampler@wellsfargo.com | G22: chistopher.mercado2@wellsfargo.com
C26: Important Disclaimers:
BP437: 33.6
BP438: 16.1
BP443: 0
BQ513: 40 | BY513: 30
BP514: =0.9 -> 0.9 | BQ514: 1 | BT514: =+BR514 -> 0

Sheet IS
A1: Guardant Health, Inc. (NASDAQ: GH) | AT1: 1280
A2: Income Statement | AT2: =+AT1/AT7-1 -> 0.30343445 | AY2: =+AY7/AT7-1 -> 0.32372802
A3: $ millions except per share data, FY ending Dec
B5: Mar | C5: Jun | D5: Sep | E5: Dec | F5: 43070 | G5: Mar | H5: Jun | I5: Sep | J5: Dec | K5: =+DATE(YEAR(F5)+1,MONTH(F5),DAY(F5)) -> 43435 | L5: Mar | M5: Jun | N5: Sep | O5: Dec | P5: =+DATE(YEAR(K5)+1,MONTH(K5),DAY(K5)) -> 43800 | Q5: Mar | R5: Jun | S5: Sep | T5: Dec | U5: =+DATE(YEAR(P5)+1,MONTH(P5),DAY(P5)) -> 44166 | V5: Mar | W5: Jun | X5: Sep | Y5: Dec | Z5: =+DATE(YEAR(U5)+1,MONTH(U5),DAY(U5)) -> 44531 | AA5: Mar | AB5: Jun | AC5: Sep | AD5: Dec | AE5: =+DATE(YEAR(Z5)+1,MONTH(Z5),DAY(Z5)) -> 44896 | AF5: Mar | AG5: Jun | AH5: Sep | AI5: Dec | AJ5: =+DATE(YEAR(AE5)+1,MONTH(AE5),DAY(AE5)) -> 45261 | AK5: Mar | AL5: Jun | AM5: Sep | AN5: Dec | AO5: =+DATE(YEAR(AJ5)+1,MONTH(AJ5),DAY(AJ5)) -> 45627 | AP5: Mar | AQ5: Jun | AR5: Sep | AS5: Dec | AT5: =+DATE(YEAR(AO5)+1,MONTH(AO5),DAY(AO5)) -> 45992 | AU5: Mar | AV5: Jun | AW5: Sep | AX5: Dec | AY5: =+DATE(YEAR(AT5)+1,MONTH(AT5),DAY(AT5)) -> 46357 | AZ5: Mar | BA5: Jun | BB5: Sep | BC5: Dec | BD5: =+DATE(YEAR(AY5)+1,MONTH(AY5),DAY(AY5)) -> 46722 | BE5: Mar | BF5: Jun | BG5: Sep | BH5: Dec | BI5: =+DATE(YEAR(BD5)+1,MONTH(BD5),DAY(BD5)) -> 47088 | BJ5: Mar | BK5: Jun | BL5: Sep | BM5: Dec | BN5: =+DATE(YEAR(BI5)+1,MONTH(BI5),DAY(BI5)) -> 47453 | BO5: Mar | BP5: Jun | BQ5: Sep | BR5: Dec | BS5: =+DATE(YEAR(BN5)+1,MONTH(BN5),DAY(BN5)) -> 47818 | BT5: Mar | BU5: Jun | BV5: Sep | BW5: Dec | BX5: =+DATE(YEAR(BS5)+1,MONTH(BS5),DAY(BS5)) -> 48183 | BY5: Mar | BZ5: Jun | CA5: Sep | CB5: Dec | CC5: =+DATE(YEAR(BX5)+1,MONTH(BX5),DAY(BX5)) -> 48549 | CD5: Mar | CE5: Jun | CF5: Sep | CG5: Dec | CH5: =+DATE(YEAR(CC5)+1,MONTH(CC5),DAY(CC5)) -> 48914 | CI5: Mar | CJ5: Jun | CK5: Sep | CL5: Dec | CM5: =+DATE(YEAR(CH5)+1,MONTH(CH5),DAY(CH5)) -> 49279 | CO5: CAGRs
B6: 1Q17A | C6: 2Q17A | D6: 3Q17A | E6: 4Q17A | F6: FY17A | G6: 1Q18A | H6: 2Q18A | I6: 3Q18A | J6: 4Q18A | K6: FY18A | L6: 1Q19A | M6: 2Q19A | N6: 3Q19A | O6: 4Q19A | P6: FY19A | Q6: 1Q20A | R6: 2Q20A | S6: 3Q20A | T6: 4Q20A | U6: FY20A | V6: 1Q21A | W6: 2Q21A | X6: 3Q21A | Y6: 4Q21A | Z6: FY21A | AA6: 1Q22A | AB6: 2Q22A | AC6: 3Q22A | AD6: 4Q22A | AE6: FY22A | AF6: 1Q23A | AG6: 2Q23A | AH6: 3Q23A | AI6: 4Q23A | AJ6: FY23A | AK6: 1Q24A | AL6: 2Q24A | AM6: 3Q24A | AN6: 4Q24A | AO6: FY24A | AP6: 1Q25A | AQ6: 2Q25A | AR6: 3Q25A | AS6: 4Q25A | AT6: FY25A | AU6: 1Q26E | AV6: 2Q26E | AW6: 3Q26E | AX6: 4Q26E | AY6: FY26E | AZ6: 1Q27E | BA6: 2Q27E | BB6: 3Q27E | BC6: 4Q27E | BD6: FY27E | BE6: 1Q28E | BF6: 2Q28E | BG6: 3Q28E | BH6: 4Q28E | BI6: FY28E | BJ6: 1Q29E | BK6: 2Q29E | BL6: 3Q29E | BM6: 4Q29E | BN6: FY29E | BO6: 1Q30E | BP6: 2Q30E | BQ6: 3Q30E | BR6: 4Q30E | BS6: FY30E | BT6: 1Q31E | BU6: 2Q31E | BV6: 3Q31E | BW6: 4Q31E | BX6: FY31E | BY6: 1Q32E | BZ6: 2Q32E | CA6: 3Q32E | CB6: 4Q32E | CC6: FY32E | CD6: 1Q33E | CE6: 2Q33E | CF6: 3Q33E | CG6: 4Q33E | CH6: FY33E | CI6: 1Q34E | CJ6: 2Q34E | CK6: 3Q34E | CL6: 4Q34E | CM6: FY34E | CO6: 3YR | CP6: 5YR
A7: Net sales | B7: 8.512 | C7: 10.196 | D7: 11.132 | E7: 20.002 | F7: =+B7+C7+D7+E7 -> 49.842 | G7: 16.692 | H7: 19.382 | I7: 21.692 | J7: 32.873 | K7: =+G7+H7+I7+J7 -> 90.639 | L7: 36.655 | M7: 53.975 | N7: 60.848 | O7: 62.897 | P7: =+L7+M7+N7+O7 -> 214.375 | Q7: 67.51 | R7: 66.335 | S7: 74.569 | T7: 78.316 | U7: =+Q7+R7+S7+T7 -> 286.73 | V7: 78.665 | W7: 92.101 | X7: 94.779 | Y7: 108.108 | Z7: =+V7+W7+X7+Y7 -> 373.653 | AA7: 96.099 | AB7: 109.144 | AC7: 117.404 | AD7: 126.891 | AE7: =SUM(AA7:AD7) -> 449.538 | AF7: 128.714 | AG7: 137.15 | AH7: 143.03 | AI7: 155.054 | AJ7: =SUM(AF7:AI7) -> 563.948 | AK7: =168.491 -> 168.491 | AL7: 177.235 | AM7: 191.476 | AN7: 201.814 | AO7: =+AK7+AL7+AM7+AN7 -> 739.016 | AP7: 203.471 | AQ7: 232.088 | AR7: 265.196 | AS7: 281.266 | AT7: =SUM(AP7:AS7) -> 982.021 | AU7: =+Rev!AU36 -> 281.60532 | AV7: =+Rev!AV36 -> 311.50646 | AW7: =+Rev!AW36 -> 342.59686 | AX7: =+Rev!AX36 -> 364.22008 | AY7: =SUM(AU7:AX7) -> 1299.9287 | AZ7: =+Rev!AZ36 -> 413.59501 | BA7: =+Rev!BA36 -> 448.77172 | BB7: =+Rev!BB36 -> 470.63164 | BC7: =+Rev!BC36 -> 499.07065 | BD7: =SUM(AZ7:BC7) -> 1832.069 | BE7: =+Rev!BE36 -> 553.16834 | BF7: =+Rev!BF36 -> 592.87406 | BG7: =+Rev!BG36 -> 621.18652 | BH7: =+Rev!BH36 -> 651.68819 | BI7: =SUM(BE7:BH7) -> 2418.9171 | BJ7: =+Rev!BJ36 -> 688.0392 | BK7: =+Rev!BK36 -> 719.8563 | BL7: =+Rev!BL36 -> 752.57812 | BM7: =+Rev!BM36 -> 777.10023 | BN7: =SUM(BJ7:BM7) -> 2937.5738 | BO7: =+Rev!BO36 -> 818.64399 | BP7: =+Rev!BP36 -> 861.85048 | BQ7: =+Rev!BQ36 -> 888.40657 | BR7: =+Rev!BR36 -> 913.78389 | BS7: =SUM(BO7:BR7) -> 3482.6849 | BT7: =+Rev!BT36 -> 941.23611 | BU7: =+Rev!BU36 -> 978.11363 | BV7: =+Rev!BV36 -> 1001.4567 | BW7: =+Rev!BW36 -> 1023.3963 | BX7: =SUM(BT7:BW7) -> 3944.2028 | BY7: =+Rev!BY36 -> 1038.2503 | BZ7: =+Rev!BZ36 -> 1070.7141 | CA7: =+Rev!CA36 -> 1097.9244 | CB7: =+Rev!CB36 -> 1117.9568 | CC7: =SUM(BY7:CB7) -> 4324.8456 | CD7: =+Rev!CD36 -> 1134.0506 | CE7: =+Rev!CE36 -> 1172.2424 | CF7: =+Rev!CF36 -> 1190.4939 | CG7: =+Rev!CG36 -> 1207.8366 | CH7: =SUM(CD7:CG7) -> 4704.6235 | CI7: =+Rev!CI36 -> 1215.2078 | CJ7: =+Rev!CJ36 -> 1247.7237 | CK7: =+Rev!CK36 -> 1262.1706 | CL7: =+Rev!CL36 -> 1276.2324 | CM7: =SUM(CI7:CL7) -> 5001.3344 | CO7: =(BI7/AT7)^(1/3)-1 -> 0.35051705 | CP7: =(BS7/AT7)^(1/5)-1 -> 0.288127
A8: Cost of precision oncology testing | B8: =6.371-0.129/2 -> 6.3065 | C8: =6.954-0.129/2 -> 6.8895 | D8: =7.603-0.112 -> 7.491 | E8: =7.955-0.058 -> 7.897 | F8: =+B8+C8+D8+E8 -> 28.584 | G8: =8.045-0.063 -> 7.982 | H8: =9.506-0.079 -> 9.427 | I8: =9.671-0.112 -> 9.559 | J8: =12.624-0.258 -> 12.366 | K8: =+G8+H8+I8+J8 -> 39.334 | L8: =11.023-0.17 -> 10.853 | M8: =14.65-0.126 -> 14.524 | N8: =16.578-0.266 -> 16.312 | O8: =20.004-0.301 -> 19.703 | P8: =+L8+M8+N8+O8 -> 61.392 | Q8: =18.191-0.322 -> 17.869 | R8: =17.809-0.141-0.394 -> 17.274 | S8: =16.699-0.45 -> 16.249 | T8: =22.07-0.301-0.727 -> 21.042 | U8: =+Q8+R8+S8+T8 -> 72.434 | V8: =23.59-0.148-0.799 -> 22.643 | W8: =24.887-0.149-0.888 -> 23.85 | X8: =29.665-0.152-0.762 -> 28.751 | Y8: =32.254-0.152-1.174 -> 30.928 | Z8: =+V8+W8+X8+Y8 -> 106.172 | AA8: =30.684-0.148-1.176 -> 29.36 | AB8: =34.375-0.149-1.229 -> 32.997 | AC8: =39.434-0.285-1.377 -> 37.772 | AD8: =43.706-0.351-1.793 -> 41.562 | AE8: =SUM(AA8:AD8) -> 141.691 | AF8: =45.106-0.148-1.218 -> 43.74 | AG8: =49.357-0.149-1.225 -> 47.983 | AH8: =53.648-0.151-1.12 -> 52.377 | AI8: =57.417-0.151-1.164 -> 56.102 | AJ8: =SUM(AF8:AI8) -> 200.202 | AK8: =59.306-0.149-1.278 -> 57.879 | AL8: =65.715-0.15-1.309 -> 64.256 | AM8: =66.095-0.151-1.505 -> 64.439 | AN8: =69.465-0.151-1.337 -> 67.977 | AO8: =+AK8+AL8+AM8+AN8 -> 254.551
A9: Cost of development services | B9: 0.003 | C9: 0.481 | D9: 1.058 | E9: 1.193 | F9: =+B9+C9+D9+E9 -> 2.735 | G9: 1.208 | H9: 0.453 | I9: 0.38 | J9: 1.323 | K9: =+G9+H9+I9+J9 -> 3.364 | L9: 2.512 | M9: 2.183 | N9: 1.936 | O9: 1.834 | P9: =+L9+M9+N9+O9 -> 8.465 | Q9: 2.315 | R9: 4.626 | S9: 4.488 | T9: 6.337 | U9: =+Q9+R9+S9+T9 -> 17.766 | V9: 5.157 | W9: =5.04 -> 5.04 | X9: 1.151 | Y9: 1.168 | Z9: =+V9+W9+X9+Y9 -> 12.516 | AA9: 1.297 | AB9: 2.352 | AC9: 1.062 | AD9: 3.415 | AE9: =SUM(AA9:AD9) -> 8.126 | AF9: =7.967-0.201-0.476 -> 7.29 | AG9: =4.491-0.201-0.478 -> 3.812 | AH9: =3.966-0.201-0.437 -> 3.328 | AI9: =5.1-0.201-0.466 -> 4.433 | AJ9: =SUM(AF9:AI9) -> 18.863 | AK9: =5.99-0.2-0.499 -> 5.291 | AL9: =6.706-0.067-0.498 -> 6.141 | AM9: =8.394-2.412 -> 5.982 | AN9: =8.128-0.656 -> 7.472 | AO9: =+AK9+AL9+AM9+AN9 -> 24.886
A10: COGS | B10: =+B8+B9 -> 6.3095 | C10: =+C8+C9 -> 7.3705 | D10: =+D8+D9 -> 8.549 | E10: =+E8+E9 -> 9.09 | F10: =+F8+F9 -> 31.319 | G10: =+G8+G9 -> 9.19 | H10: =+H8+H9 -> 9.88 | I10: =+I8+I9 -> 9.939 | ... AO10: =+AO8+AO9 -> 279.437 | AP10: =74.723-0.148-2.39 -> 72.185 | AQ10: =81.205-0.15-2.759 -> 78.296 | AR10: 90.872 | AS10: 95.842 | AT10: =+AP10+AQ10+AR10+AS10 -> 337.195 | AU10: =+AU7-AU11 -> 102.1574 | AV10: =+AV7-AV11 -> 109.76079 | AW10: =+AW7-AW11 -> 120.13494 | AX10: =+AX7-AX11 -> 127.02254 | AY10: =+AU10+AV10+AW10+AX10 -> 459.07567 | AZ10: =+AZ7-AZ11 -> 147.97106 | BA10: =+BA7-BA11 -> 155.88301 | BB10: =+BB7-BB11 -> 162.67842 | BC10: =+BC7-BC11 -> 171.55662 | BD10: =+AZ10+BA10+BB10+BC10 -> 638.08912 | BE10: =+BE7-BE11 -> 195.14009 | BF10: =+BF7-BF11 -> 202.97328 | BG10: =+BG7-BG11 -> 211.61326 | BH10: =+BH7-BH11 -> 220.76079 | BI10: =+BE10+BF10+BG10+BH10 -> 830.48741 | BJ10: =+BJ7-BJ11 -> 239.27802 | BK10: =+BK7-BK11 -> 242.84697 | BL10: =+BL7-BL11 -> 252.6102 | BM10: =+BM7-BM11 -> 259.35889 | BN10: =+BJ10+BK10+BL10+BM10 -> 994.09408 | BO10: =+BO7-BO11 -> 280.60496 | BP10: =+BP7-BP11 -> 286.44014 | BQ10: =+BQ7-BQ11 -> 293.76031 | BR10: =+BR7-BR11 -> 300.40844 | BS10: =+BO10+BP10+BQ10+BR10 -> 1161.2139 | BT10: =+BT7-BT11 -> 317.91944 | BU10: =+BU7-BU11 -> 320.19019 | BV10: =+BV7-BV11 -> 326.13417 | BW10: =+BW7-BW11 -> 331.32679 | BX10: =+BT10+BU10+BV10+BW10 -> 1295.5706 | BY10: =+BY7-BY11 -> 345.49646 | BZ10: =+BZ7-BZ11 -> 345.14984 | CA10: =+CA7-CA11 -> 352.06017 | CB10: =+CB7-CB11 -> 356.35117 | CC10: =+BY10+BZ10+CA10+CB10 -> 1399.0576 | CD10: =+CD7-CD11 -> 371.70551 | CE10: =+CE7-CE11 -> 372.01676 | CF10: =+CF7-CF11 -> 375.79103 | CG10: =+CG7-CG11 -> 378.96134 | CH10: =+CD10+CE10+CF10+CG10 -> 1498.4746 | CI10: =+CI7-CI11 -> 392.23018 | CJ10: =+CJ7-CJ11 -> 389.73247 | CK10: =+CK7-CK11 -> 392.10563 | CL10: =+CL7-CL11 -> 394.03952 | CM10: =+CI10+CJ10+CK10+CL10 -> 1568.1078
A11: Gross profit | B11: =+B7-B10 -> 2.2025 | C11: =+C7-C10 -> 2.8255 | D11: =+D7-D10 -> 2.583 | E11: =+E7-E10 -> 10.912 | F11: =+F7-F10 -> 18.523 | G11: =+G7-G10 -> 7.502 | H11: =+H7-H10 -> 9.502 | I11: =+I7-I10 -> 11.753 | ... AK11: =+AK7-AK10 -> 105.321 | AL11: =AL7-AL10 -> 106.838 | AM11: =AM7-AM10 -> 121.055 | AN11: =AN7-AN10 -> 126.365 | AO11: =AO7-AO10 -> 459.579 | AP11: =AP7-AP10 -> 131.286 | AQ11: =AQ7-AQ10 -> 153.792 | AR11: =AR7-AR10 -> 174.324 | AS11: =AS7-AS10 -> 185.424 | AT11: =AT7-AT10 -> 644.826 | AU11: =+AU7*AU60 -> 179.44792 | AV11: =+AV7*AV60 -> 201.74566 | AW11: =+AW7*AW60 -> 222.46192 | AX11: =+AX7*AX60 -> 237.19754 | AY11: =AY7-AY10 -> 840.85304 | AZ11: =+AZ7*AZ60 -> 265.62395 | BA11: =+BA7*BA60 -> 292.88871 | BB11: =+BB7*BB60 -> 307.95322 | BC11: =+BC7*BC60 -> 327.51403 | BD11: =BD7-BD10 -> 1193.9799 | BE11: =+BE7*BE60 -> 358.02825 | BF11: =+BF7*BF60 -> 389.90078 | BG11: =+BG7*BG60 -> 409.57327 | BH11: =+BH7*BH60 -> 430.9274 | BI11: =BI7-BI10 -> 1588.4297 | BJ11: =+BJ7*BJ60 -> 448.76118 | BK11: =+BK7*BK60 -> 477.00932 | BL11: =+BL7*BL60 -> 499.96792 | BM11: =+BM7*BM60 -> 517.74134 | BN11: =BN7-BN10 -> 1943.4798 | BO11: =+BO7*BO60 -> 538.03903 | BP11: =+BP7*BP60 -> 575.41034 | BQ11: =+BQ7*BQ60 -> 594.64626 | BR11: =+BR7*BR60 -> 613.37545 | BS11: =BS7-BS10 -> 2321.4711 | BT11: =+BT7*BT60 -> 623.31667 | BU11: =+BU7*BU60 -> 657.92344 | BV11: =+BV7*BV60 -> 675.32256 | BW11: =+BW7*BW60 -> 692.06956 | BX11: =BX7-BX10 -> 2648.6322 | BY11: =+BY7*BY60 -> 692.75379 | BZ11: =+BZ7*BZ60 -> 725.5643 | CA11: =+CA7*CA60 -> 745.86419 | CB11: =+CB7*CB60 -> 761.60568 | CC11: =CC7-CC10 -> 2925.788 | CD11: =+CD7*CD60 -> 762.34512 | CE11: =+CE7*CE60 -> 800.22568 | CF11: =+CF7*CF60 -> 814.70287 | CG11: =+CG7*CG60 -> 828.87521 | CH11: =CH7-CH10 -> 3206.1489 | CI11: =+CI7*CI60 -> 822.97758 | CJ11: =+CJ7*CJ60 -> 857.99119 | CK11: =+CK7*CK60 -> 870.06497 | CL11: =+CL7*CL60 -> 882.19287 | CM11: =CM7-CM10 -> 3433.2266
A12: Gross profit (ex-screening) | AF12: 81.072 | AG12: 87.642 | AH12: 89.679 | AI12: 97.305 | AJ12: =+AF12+AG12+AH12+AI12 -> 355.698 | AK12: 107.951 | AL12: 109.732 | AM12: 123.963 | AN12: 126.29 | AO12: =+AK12+AL12+AM12+AN12 -> 467.936
A13: R&D expense | B13: =4.702-0.29/2 -> 4.557 | C13: =5.494-0.29/2 -> 5.349 | D13: =7.246-0.617 -> 6.629 | E13: =8.12-0.2 -> 7.92 | F13: =+B13+C13+D13+E13 -> 24.455 | G13: =8.255-0.204 -> 8.051 | H13: =11.554-0.214 -> 11.34 | I13: =14.253-0.617 -> 13.636 | J13: =16.652-0.649 -> 16.003 | K13: =+G13+H13+I13+J13 -> 49.03 | L13: =16.316-1.21 -> 15.106 | M13: =19.532-1.428 -> 18.104 | N13: =24.569-2.066 -> 22.503 | O13: =25.875-1.203 -> 24.672 | P13: =+L13+M13+N13+O13 -> 80.385 | Q13: =37.016-2.472-8.5 -> 26.044 | R13: =36.319-0.043-2.557 -> 33.719 | S13: =36.245-2.474 -> 33.771 | T13: =40.282-2.716 -> 37.566 | U13: =+Q13+R13+S13+T13 -> 131.1 | V13: =55.508-4.391 -> 51.117 | W13: =63.724-4.659 -> 59.065 | X13: =70.968-4.624 -> 66.344 | Y13: =73.021-5.696 -> 67.325 | Z13: =+V13+W13+X13+Y13 -> 243.851 | AA13: =81.757-5.41-2.12 -> 74.227 | AB13: =85.455-6.191-0.177 -> 79.087 | AC13: =100.017-7.256-0.355 -> 92.406 | AD13: =106.578-8.071-2.577 -> 95.93 | AE13: =SUM(AA13:AD13) -> 341.65 | AF13: =93.128-8.748-0.57 -> 83.81 | AG13: =90.359-8.518-0.531 -> 81.31 | AH13: =93.851-8.611-0.531 -> 84.709 | AI13: =89.856-9.409-0.45 -> 79.997 | AJ13: =SUM(AF13:AI13) -> 329.826 | AK13: =83.802-10.064-0.375 -> 73.363 | AL13: =83.102-10.001-0.11 -> 72.991 | AM13: =87.306-18.75-0.19 -> 68.366 | AN13: =93.543-12.397 -> 81.146 | AO13: =+AK13+AL13+AM13+AN13 -> 295.866 | AP13: =88.521-13.09-0.534 -> 74.897 | AQ13: =87.449-14.255-0.647 -> 72.547 | AR13: 75.79 | AS13: 85.944 | AT13: =+AP13+AQ13+AR13+AS13 -> 309.178 | AU13: =+AP13*(1+AU48) -> 78.791644 | AV13: =+AQ13*(1+AV48) -> 76.319444 | AW13: =+AR13*(1+AW48) -> 79.73108 | AX13: =+AS13*(1+AX48) -> 90.413088 | AY13: =+AU13+AV13+AW13+AX13 -> 325.25526 | AZ13: =+AU13*(1+AZ48) -> 82.731226 | BA13: =+AV13*(1+BA48) -> 80.135416 | BB13: =+AW13*(1+BB48) -> 83.717634 | BC13: =+AX13*(1+BC48) -> 94.933742 | BD13: =+AZ13+BA13+BB13+BC13 -> 341.51802 | BE13: =+AZ13*(1+BE48) -> 86.867788 | BF13: =+BA13*(1+BF48) -> 84.142187 | BG13: =+BB13*(1+BG48) -> 87.903516 | BH13: =+BC13*(1+BH48) -> 99.68043 | BI13: =+BE13+BF13+BG13+BH13 -> 358.59392 | BJ13: =+BE13*(1+BJ48) -> 91.211177 | BK13: =+BF13*(1+BK48) -> 88.349296 | BL13: =+BG13*(1+BL48) -> 92.298691 | BM13: =+BH13*(1+BM48) -> 104.66445 | BN13: =+BJ13+BK13+BL13+BM13 -> 376.52362 | BO13: =+BJ13*(1+BO48) -> 95.771736 | BP13: =+BK13*(1+BP48) -> 92.766761 | BQ13: =+BL13*(1+BQ48) -> 96.913626 | BR13: =+BM13*(1+BR48) -> 109.89767 | BS13: =+BO13+BP13+BQ13+BR13 -> 395.3498 | BT13: =+BO13*(1+BT48) -> 100.56032 | BU13: =+BP13*(1+BU48) -> 97.405099 | BV13: =+BQ13*(1+BV48) -> 101.75931 | BW13: =+BR13*(1+BW48) -> 115.39256 | BX13: =+BT13+BU13+BV13+BW13 -> 415.11729 | BY13: =+BT13*(1+BY48) -> 105.58834 | BZ13: =+BU13*(1+BZ48) -> 102.27535 | CA13: =+BV13*(1+CA48) -> 106.84727 | CB13: =+BW13*(1+CB48) -> 121.16219 | CC13: =+BY13+BZ13+CA13+CB13 -> 435.87315 | CD13: =+BY13*(1+CD48) -> 110.86776 | CE13: =+BZ13*(1+CE48) -> 107.38912 | CF13: =+CA13*(1+CF48) -> 112.18964 | CG13: =+CB13*(1+CG48) -> 127.22029 | CH13: =+CD13+CE13+CF13+CG13 -> 457.66681 | CI13: =+CD13*(1+CI48) -> 116.41114 | CJ13: =+CE13*(1+CJ48) -> 112.75858 | CK13: =+CF13*(1+CK48) -> 117.79912 | CL13: =+CG13*(1+CL48) -> 133.58131 | CM13: =+CI13+CJ13+CK13+CL13 -> 480.55015
A14: S&M expense | B14: =7.204-0.54/2 -> 6.934 | C14: =7.929-0.54/2 -> 7.659 | D14: =7.808-0.428 -> 7.38 | E14: =9.556-0.066 -> 9.49 | F14: =+B14+C14+D14+E14 -> 31.463 | G14: =11.312-0.374 -> 10.938 | H14: =11.575-0.259 -> 11.316 | I14: =13.464-0.428 -> 13.036 | J14: =17.114-0.666 -> 16.448 | K14: =+G14+H14+I14+J14 -> 51.738 | L14: =17.807-0.826 -> 16.981 | M14: =19.439-0.646 -> 18.793 | N14: =18.802-1.458 -> 17.344 | O14: =22.287-1.786 -> 20.501 | P14: =+L14+M14+N14+O14 -> 73.619 | Q14: =25.115-1.93 -> 23.185 | R14: =25.015-2.065 -> 22.95 | S14: =25.095-2.379 -> 22.716 | T14: =31.288-3.032 -> 28.256 | U14: =+Q14+R14+S14+T14 -> 97.107 | V14: =34.338-2.934 -> 31.404 | W14: =47.716-3.493 -> 44.223 | X14: =50.228-4.127 -> 46.101 | Y14: =59.599-5.208 -> 54.391 | Z14: =+V14+W14+X14+Y14 -> 176.119 | AA14: =64.432-5.57 -> 58.862 | AB14: =73.603-0.134-6.054 -> 67.415 | AC14: =80.37-0.067-6.643 -> 73.66 | AD14: =81.423-7.399 -> 74.024 | AE14: =SUM(AA14:AD14) -> 273.961 | AF14: =76.123-7.543 -> 68.58 | AG14: =71.043-5.977 -> 65.066 | AH14: =68.934-5.137 -> 63.797 | AI14: =79.127-6.438 -> 72.689 | AJ14: =SUM(AF14:AI14) -> 270.132 | AK14: =80.425-7.329 -> 73.096 | AL14: =81.867-7.258 -> 74.609 | AM14: =97.88-13.287 -> 84.593 | AN14: =104.763-8.997 -> 95.766 | AO14: =+AK14+AL14+AM14+AN14 -> 328.064 | AP14: =104.316-10.189 -> 94.127 | AQ14: =119.588-11.756 -> 107.832 | AR14: 115.924 | AS14: 130.536 | AT14: =+AP14+AQ14+AR14+AS14 -> 448.419 | AU14: =+AP14*(1+AU49) -> 117.18812 | AV14: =+AQ14*(1+AV49) -> 134.25084 | AW14: =+AR14*(1+AW49) -> 144.32538 | AX14: =+AS14*(1+AX49) -> 162.51732 | AY14: =+AU14+AV14+AW14+AX14 -> 558.28166 | AZ14: =+AU14*(1+AZ49) -> 140.62574 | BA14: =+AV14*(1+BA49) -> 161.10101 | BB14: =+AW14*(1+BB49) -> 173.19046 | BC14: =+AX14*(1+BC49) -> 195.02078 | BD14: =+AZ14+BA14+BB14+BC14 -> 669.93799 | BE14: =+AZ14*(1+BE49) -> 161.7196 | BF14: =+BA14*(1+BF49) -> 185.26616 | BG14: =+BB14*(1+BG49) -> 199.16902 | BH14: =+BC14*(1+BH49) -> 224.2739 | BI14: =+BE14+BF14+BG14+BH14 -> 770.42868 | BJ14: =+BE14*(1+BJ49) -> 182.90487 | BK14: =+BF14*(1+BK49) -> 209.53603 | BL14: =+BG14*(1+BL49) -> 225.26017 | BM14: =+BH14*(1+BM49) -> 253.65378 | BN14: =+BJ14+BK14+BL14+BM14 -> 871.35484 | BO14: =+BJ14*(1+BO49) -> 205.03635 | BP14: =+BK14*(1+BP49) -> 234.88989 | BQ14: =+BL14*(1+BQ49) -> 252.51665 | BR14: =+BM14*(1+BR49) -> 284.34589 | BS14: =+BO14+BP14+BQ14+BR14 -> 976.78878 | BT14: =+BO14*(1+BT49) -> 227.79539 | BU14: =+BP14*(1+BU49) -> 260.96266 | BV14: =+BQ14*(1+BV49) -> 280.54599 | BW14: =+BR14*(1+BW49) -> 315.90828 | BX14: =+BT14+BU14+BV14+BW14 -> 1085.2123 | BY14: =+BT14*(1+BY49) -> 250.80272 | BZ14: =+BU14*(1+BZ49) -> 287.31989 | CA14: =+BV14*(1+CA49) -> 308.88114 | CB14: =+BW14*(1+CB49) -> 347.81502 | CC14: =+BY14+BZ14+CA14+CB14 -> 1194.8188 | CD14: =+BY14*(1+CD49) -> 273.62577 | CE14: =+BZ14*(1+CE49) -> 313.466 | CF14: =+CA14*(1+CF49) -> 336.98932 | CG14: =+CB14*(1+CG49) -> 379.46619 | CH14: =+CD14+CE14+CF14+CG14 -> 1303.5473 | CI14: =+CD14*(1+CI49) -> 295.78946 | CJ14: =+CE14*(1+CJ49) -> 338.85675 | CK14: =+CF14*(1+CK49) -> 364.28546 | CL14: =+CG14*(1+CL49) -> 410.20295 | CM14: =+CI14+CJ14+CK14+CL14 -> 1409.1346
A15: G&A expense | B15: =5.212-0.331/2 -> 5.0465 | C15: =6.675-0.331/2 -> 6.5095 | D15: =16.095-0.674 -> 15.421 | E15: =8.795-1.248 -> 7.547 | F15: =+B15+C15+D15+E15 -> 34.524 | G15: =6.519-0.636 -> 5.883 | H15: =8.997-0.628 -> 8.369 | I15: =8.129-0.674 -> 7.455 | J15: =12.547-0.99 -> 11.557 | K15: =+G15+H15+I15+J15 -> 33.264 | L15: =12.661-0.976 -> 11.685 | M15: =13.439-1.015 -> 12.424 | N15: =16.44-1.694 -> 14.746 | O15: =18.859-1.782 -> 17.077 | P15: =+L15+M15+N15+O15 -> 55.932 | Q15: =19.785-0.229-1.911+0.19-1.207 -> 16.628 | R15: =37.186-0.349-20.651 -> 16.186 | S15: =66.294-0.503-50.397-0.07 -> 15.324 | T15: =69.505-0.189-50.428 -> 18.888 | U15: =+Q15+R15+S15+T15 -> 67.026 | V15: =67.935-0.333-49.375 -> 18.227 | W15: =48.376-0.336-25.735-0.875 -> 21.43 | X15: =50.055-0.339-26.044-0.97 -> 22.702 | Y15: =40.274-0.339-14.951-0.535 -> 24.449 | Z15: =+V15+W15+X15+Y15 -> 86.808 | AA15: =41.267-0.332-12.835-2.39-0.063 -> 25.647 | AB15: =43.68-0.336-12.252-1.415+0.063 -> 29.74 | AC15: =41.121-0.339-5.955-0.39 -> 34.437 | AD15: =37.888-0.339-6.24-0.11 -> 31.199 | AE15: =+AA15+AB15+AC15+AD15 -> 121.023 | AF15: =40.445-0.331-4.468+0.3 -> 35.946 | AG15: =41.516-0.336-6.755-0.31 -> 34.115 | AH15: =36.174-0.339-6.794-0.22 -> 28.821 | AI15: =37.665-0.339-7.081+0.12 -> 30.365 | AJ15: =+AF15+AG15+AH15+AI15 -> 129.247 | AK15: =38.651-0.336-8.164-0.12 -> 30.031 | AL15: =40.463-0.335-8.659-0.3 -> 31.169 | AM15: =49.129-0.34-14.068-0.34 -> 34.381 | AN15: =51.88-0.34-13.519-0.25 -> 37.771 | AO15: =+AK15+AL15+AM15+AN15 -> 133.352 | AP15: =46.952-0.332-13.571-0.49-2 -> 30.559 | AQ15: =50.259-0.266-14.832-0.23 -> 34.931 | AR15: 37.136 | AS15: 43.519 | AT15: =+AP15+AQ15+AR15+AS15 -> 146.145 | AU15: =+AP15*(1+AU50) -> 32.08695 | AV15: =+AQ15*(1+AV50) -> 36.67755 | AW15: =+AR15*(1+AW50) -> 38.9928 | AX15: =+AS15*(1+AX50) -> 45.69495 | AY15: =+AU15+AV15+AW15+AX15 -> 153.45225 | AZ15: =+AU15*(1+AZ50) -> 33.691298 | BA15: =+AV15*(1+BA50) -> 38.511428 | BB15: =+AW15*(1+BB50) -> 40.94244 | BC15: =+AX15*(1+BC50) -> 47.979698 | BD15: =+AZ15+BA15+BB15+BC15 -> 161.12486 | BE15: =+AZ15*(1+BE50) -> 35.375862 | BF15: =+BA15*(1+BF50) -> 40.436999 | BG15: =+BB15*(1+BG50) -> 42.989562 | BH15: =+BC15*(1+BH50) -> 50.378682 | BI15: =+BE15+BF15+BG15+BH15 -> 169.18111 | BJ15: =+BE15*(1+BJ50) -> 37.144655 | BK15: =+BF15*(1+BK50) -> 42.458849 | BL15: =+BG15*(1+BL50) -> 45.13904 | BM15: =+BH15*(1+BM50) -> 52.897616 | BN15: =+BJ15+BK15+BL15+BM15 -> 177.64016 | BO15: =+BJ15*(1+BO50) -> 39.001888 | BP15: =+BK15*(1+BP50) -> 44.581791 | BQ15: =+BL15*(1+BQ50) -> 47.395992 | BR15: =+BM15*(1+BR50) -> 55.542497 | BS15: =+BO15+BP15+BQ15+BR15 -> 186.52217 | BT15: =+BO15*(1+BT50) -> 40.951983 | BU15: =+BP15*(1+BU50) -> 46.810881 | BV15: =+BQ15*(1+BV50) -> 49.765792 | BW15: =+BR15*(1+BW50) -> 58.319622 | BX15: =+BT15+BU15+BV15+BW15 -> 195.84828 | BY15: =+BT15*(1+BY50) -> 42.999582 | BZ15: =+BU15*(1+BZ50) -> 49.151425 | CA15: =+BV15*(1+CA50) -> 52.254081 | CB15: =+BW15*(1+CB50) -> 61.235603 | CC15: =+BY15+BZ15+CA15+CB15 -> 205.64069 | CD15: =+BY15*(1+CD50) -> 45.149561 | CE15: =+BZ15*(1+CE50) -> 51.608996 | CF15: =+CA15*(1+CF50) -> 54.866785 | CG15: =+CB15*(1+CG50) -> 64.297383 | CH15: =+CD15+CE15+CF15+CG15 -> 215.92273 | CI15: =+CD15*(1+CI50) -> 47.407039 | CJ15: =+CE15*(1+CJ50) -> 54.189446 | CK15: =+CF15*(1+CK50) -> 57.610125 | CL15: =+CG15*(1+CL50) -> 67.512253 | CM15: =+CI15+CJ15+CK15+CL15 -> 226.71886
A16: Operating expenses | B16: =+B13+B14+B15 -> 16.5375 | C16: =+C13+C14+C15 -> 19.5175 | D16: =+D13+D14+D15 -> 29.43 | E16: =+E13+E14+E15 -> 24.957 | F16: =+F13+F14+F15 -> 90.442 | G16: =+G13+G14+G15 -> 24.872 | H16: =+H13+H14+H15 -> 31.025 | I16: =+I13+I14+I15 -> 34.127 | ... CM16: =+CM13+CM14+CM15 -> 2116.4036
A17: Operating income (EBITA , ex-SBC) | B17: =+B11-B16 -> -14.335 | C17: =+C11-C16 -> -16.692 | D17: =+D11-D16 -> -26.847 | E17: =+E11-E16 -> -14.045 | F17: =+F11-F16 -> -71.919 | G17: =+G11-G16 -> -17.37 | H17: =+H11-H16 -> -21.523 | I17: =+I11-I16 -> -22.374 | ... CM17: =+CM11-CM16 -> 1316.823
A18: Interest expense | B18: 1.039 | C18: 1.056 | D18: 0.303 | E18: 0.304 | F18: =+B18+C18+D18+E18 -> 2.702 | G18: 0.331 | H18: 0.317 | I18: 0.304 | J18: 0.299 | K18: =+G18+H18+I18+J18 -> 1.251 | L18: 0.293 | M18: 0.287 | N18: 0.28 | O18: 0.321 | P18: =+L18+M18+N18+O18 -> 1.181 | Q18: 0.012 | R18: 0.01 | S18: 0.008 | T18: 4.736 | U18: =+Q18+R18+S18+T18 -> 4.766 | V18: 0.646 | W18: 0.644 | X18: 0.644 | Y18: 0.643 | Z18: =+V18+W18+X18+Y18 -> 2.577 | AA18: 0.644 | AB18: 0.645 | AC18: 0.644 | AD18: 0.644 | AE18: 2.577 | AF18: 0.644 | AG18: 0.645 | AH18: 0.644 | AI18: 0.645 | AJ18: =SUM(AF18:AI18) -> 2.578 | AK18: 0.645 | AL18: 0.645 | AM18: 0.646 | AN18: 0.645 | AO18: =+AK18+AL18+AM18+AN18 -> 2.581 | AP18: 0.791 | AQ18: 0.983 | AR18: 0.943 | AS18: 1.18 | AT18: =SUM(AP18:AS18) -> 3.897 | AU18: ='Other Accts'!AU40 -> 0.869369 | AV18: ='Other Accts'!AV40 -> 0.869369 | AW18: ='Other Accts'!AW40 -> 0.869369 | AX18: ='Other Accts'!AX40 -> 0.869369 | AY18: =SUM(AU18:AX18) -> 3.477476 | AZ18: ='Other Accts'!AZ40 -> 0.869369 | BA18: ='Other Accts'!BA40 -> 0.869369 | BB18: ='Other Accts'!BB40 -> 0.869369 | BC18: ='Other Accts'!BC40 -> 0.869369 | BD18: =SUM(AZ18:BC18) -> 3.477476 | BE18: ='Other Accts'!BE40 -> 0.625077 | BF18: ='Other Accts'!BF40 -> 0.625077 | BG18: ='Other Accts'!BG40 -> 0.625077 | BH18: ='Other Accts'!BH40 -> 0.625077 | BI18: =SUM(BE18:BH18) -> 2.500308 | BJ18: ='Other Accts'!BJ40 -> 0.625077 | BK18: ='Other Accts'!BK40 -> 0.625077 | BL18: ='Other Accts'!BL40 -> 0.625077 | BM18: ='Other Accts'!BM40 -> 0.625077 | BN18: =SUM(BJ18:BM18) -> 2.500308 | BO18: ='Other Accts'!BO40 -> 0.625077 | BP18: ='Other Accts'!BP40 -> 0.625077 | BQ18: ='Other Accts'!BQ40 -> 0.625077 | BR18: ='Other Accts'!BR40 -> 0.625077 | BS18: =SUM(BO18:BR18) -> 2.500308 | BT18: ='Other Accts'!BT40 -> 0.625077 | BU18: ='Other Accts'!BU40 -> -0.006906419 | BV18: ='Other Accts'!BV40 -> -0.006906419 | BW18: ='Other Accts'!BW40 -> -0.006906419 | BX18: =SUM(BT18:BW18) -> 0.60435774 | BY18: ='Other Accts'!BY40 -> -0.006906419 | BZ18: ='Other Accts'!BZ40 -> 0 | CA18: ='Other Accts'!CA40 -> 0 | CB18: ='Other Accts'!CB40 -> 0 | CC18: =SUM(BY18:CB18) -> -0.006906419 | CD18: ='Other Accts'!CD40 -> 0 | CE18: ='Other Accts'!CE40 -> 0 | CF18: ='Other Accts'!CF40 -> 0 | CG18: ='Other Accts'!CG40 -> 0 | CH18: =SUM(CD18:CG18) -> 0 | CI18: ='Other Accts'!CI40 -> 0 | CJ18: ='Other Accts'!CJ40 -> 0 | CK18: ='Other Accts'!CK40 -> 0 | CL18: ='Other Accts'!CL40 -> 0 | CM18: =SUM(CI18:CL18) -> 0
A19: Interest income | B19: -0.205 | C19: -0.36 | D19: -0.657 | E19: -1.012 | F19: =+B19+C19+D19+E19 -> -2.234 | G19: -0.985 | H19: -0.989 | I19: -0.958 | J19: -2.334 | K19: =+G19+H19+I19+J19 -> -5.266 | L19: -2.485 | M19: -3.099 | N19: -4.286 | O19: -3.871 | P19: =+L19+M19+N19+O19 -> -13.741 | Q19: -3.318 | R19: -2.64 | S19: -2.313 | T19: -1.9 | U19: =+Q19+R19+S19+T19 -> -10.171 | V19: -1.551 | W19: -1.037 | X19: -0.689 | Y19: -0.653 | Z19: =+V19+W19+X19+Y19 -> -3.93 | AA19: -0.778 | AB19: -1.387 | AC19: -1.754 | AD19: -2.15 | AE19: -6.069 | AF19: -3.06 | AG19: -6.727 | AH19: -11.69 | AI19: -13.888 | AJ19: =SUM(AF19:AI19) -> -35.365 | AK19: -14.868 | AL19: -13.913 | AM19: -13.257 | AN19: -11.653 | AO19: =+AK19+AL19+AM19+AN19 -> -53.691 | AP19: -9.112 | AQ19: -7.56 | AR19: -7.391 | AS19: -10.032 | AT19: =SUM(AP19:AS19) -> -34.095 | AU19: =-'Other Accts'!AU8 -> -12.01598 | AV19: =-'Other Accts'!AV8 -> -11.319718 | AW19: =-'Other Accts'!AW8 -> -9.3321193 | AX19: =-'Other Accts'!AX8 -> -9.0730643 | AY19: =SUM(AU19:AX19) -> -41.740882 | AZ19: =-'Other Accts'!AZ8 -> -7.7207031 | BA19: =-'Other Accts'!BA8 -> -7.4608202 | BB19: =-'Other Accts'!BB8 -> -7.1863147 | BC19: =-'Other Accts'!BC8 -> -7.2443052 | BD19: =SUM(AZ19:BC19) -> -29.612143 | BE19: =-'Other Accts'!BE8 -> -3.9290411 | BF19: =-'Other Accts'!BF8 -> -4.0461887 | BG19: =-'Other Accts'!BG8 -> -4.0763709 | BH19: =-'Other Accts'!BH8 -> -4.5782476 | BI19: =SUM(BE19:BH19) -> -16.629848 | BJ19: =-'Other Accts'!BJ8 -> -5.4936504 | BK19: =-'Other Accts'!BK8 -> -6.2002691 | BL19: =-'Other Accts'!BL8 -> -6.5251801 | BM19: =-'Other Accts'!BM8 -> -7.4661191 | BN19: =SUM(BJ19:BM19) -> -25.685219 | BO19: =-'Other Accts'!BO8 -> -8.8860166 | BP19: =-'Other Accts'!BP8 -> -10.006369 | BQ19: =-'Other Accts'!BQ8 -> -10.719199 | BR19: =-'Other Accts'!BR8 -> -12.127092 | BS19: =SUM(BO19:BR19) -> -41.738677 | BT19: =-'Other Accts'!BT8 -> -14.103087 | BU19: =-'Other Accts'!BU8 -> -11.093802 | BV19: =-'Other Accts'!BV8 -> -12.092257 | BW19: =-'Other Accts'!BW8 -> -13.868346 | BX19: =SUM(BT19:BW19) -> -51.157493 | BY19: =-'Other Accts'!BY8 -> -16.263805 | BZ19: =-'Other Accts'!BZ8 -> -18.281468 | CA19: =-'Other Accts'!CA8 -> -19.517817 | CB19: =-'Other Accts'!CB8 -> -21.618196 | CC19: =SUM(BY19:CB19) -> -75.681286 | CD19: =-'Other Accts'!CD8 -> -24.368937 | CE19: =-'Other Accts'!CE8 -> -26.698893 | CF19: =-'Other Accts'!CF8 -> -25.292288 | CG19: =-'Other Accts'!CG8 -> -27.680061 | CH19: =SUM(CD19:CG19) -> -104.04018 | CI19: =-'Other Accts'!CI8 -> -30.743792 | CJ19: =-'Other Accts'!CJ8 -> -33.337621 | CK19: =-'Other Accts'!CK8 -> -35.047224 | CL19: =-'Other Accts'!CL8 -> -37.672196 | CM19: =SUM(CI19:CL19) -> -136.80083
A20: Other expense, net | B20: 0.204 | C20: 0.445 | D20: 0.266 | E20: 0.144 | F20: =+B20+C20+D20+E20 -> 1.059 | G20: -4.149 | H20: -0.395 | I20: -0.043 | J20: -0.115 | K20: =+G20+H20+I20+J20 -> -4.702 | L20: -0.147 | M20: 0.051 | N20: -0.179 | O20: 0.187 | P20: =+L20+M20+N20+O20 -> -0.088 | Q20: 0.209 | R20: -2.285 | S20: -0.345 | T20: =-1.22+1 -> -0.22 | U20: =+Q20+R20+S20+T20 -> -2.641 | V20: 0.29 | W20: 0.243 | X20: 0.187 | Y20: =-25.898+26.1 -> 0.202 | Z20: =+V20+W20+X20+Y20 -> 0.922 | AA20: 0.048 | AB20: =-0.378+99.785 -> 99.407 | AC20: =18.389-13.23-5.261 -> -0.102 | AD20: =-5.281+5.437+1.1 -> 1.256 | AE20: =SUM(AA20:AD20) -> 100.609 | AF20: =1.654+3.882-5.485 -> 0.051 | AG20: =-41.259+63.997-23.569 -> -0.831 | AH20: =-16.885+16.634 -> -0.251 | AI20: =3.316-4.803+2.631 -> 1.144 | AJ20: =SUM(AF20:AI20) -> 0.113 | AK20: =29.12-30.054 -> -0.934 | AL20: =15.145-15.485 -> -0.34 | AM20: =3.007-1.686 -> 1.321 | AN20: =-4.667+2.824+1.1 -> -0.743 | AO20: =+AK20+AL20+AM20+AN20 -> -0.696 | AP20: =-7.851-5+13.672 -> 0.821 | AQ20: 0.025 | AR20: 0.048 | AS20: =18.268-13.582-4.9 -> -0.214 | AT20: =SUM(AP20:AS20) -> 0.68 | AU20: 0 | AV20: 0 | AW20: 0 | AX20: 0 | AY20: =SUM(AU20:AX20) -> 0 | AZ20: 0 | BA20: 0 | BB20: 0 | BC20: 0 | BD20: =SUM(AZ20:BC20) -> 0 | BE20: 0 | BF20: 0 | BG20: 0 | BH20: 0 | BI20: =SUM(BE20:BH20) -> 0 | BJ20: 0 | BK20: 0 | BL20: 0 | BM20: 0 | BN20: =SUM(BJ20:BM20) -> 0 | BO20: 0 | BP20: 0 | BQ20: 0 | BR20: 0 | BS20: =SUM(BO20:BR20) -> 0 | BT20: 0 | BU20: 0 | BV20: 0 | BW20: 0 | BX20: =SUM(BT20:BW20) -> 0 | BY20: 0 | BZ20: 0 | CA20: 0 | CB20: 0 | CC20: =SUM(BY20:CB20) -> 0 | CD20: 0 | CE20: 0 | CF20: 0 | CG20: 0 | CH20: =SUM(CD20:CG20) -> 0 | CI20: 0 | CJ20: 0 | CK20: 0 | CL20: 0 | CM20: =SUM(CI20:CL20) -> 0
A21: Income before taxes | B21: =+B17-B18-B19-B20 -> -15.373 | C21: =+C17-C18-C19-C20 -> -17.833 | D21: =+D17-D18-D19-D20 -> -26.759 | E21: =+E17-E18-E19-E20 -> -13.481 | F21: =+F17-F18-F19-F20 -> -73.446 | G21: =+G17-G18-G19-G20 -> -12.567 | H21: =+H17-H18-H19-H20 -> -20.456 | I21: =+I17-I18-I19-I20 -> -21.677 | ... CM21: =+CM17-CM18-CM19-CM20 -> 1453.6238
A22: Income tax | B22: 0 | C22: 0 | D22: 0 | E22: 0.007 | F22: =+B22+C22+D22+E22 -> 0.007 | G22: 0 | H22: 0.003 | I22: 0 | J22: 0.035 | K22: =+G22+H22+I22+J22 -> 0.038 | L22: 0.026 | M22: -1.207 | N22: -0.202 | O22: -0.489 | P22: =+L22+M22+N22+O22 -> -1.872 | Q22: 0.014 | R22: 0.034 | S22: 0.068 | T22: 0.263 | U22: =+Q22+R22+S22+T22 -> 0.379 | V22: 0.11 | W22: 0.083 | X22: 0.096 | Y22: 0.011 | Z22: =+V22+W22+X22+Y22 -> 0.3 | AA22: -0.024 | AB22: 0.446 | AC22: 0.115 | AD22: 0.602 | AE22: =SUM(AA22:AD22) -> 1.139 | AF22: 0.24 | AG22: 0.496 | AH22: 0.49 | AI22: -0.541 | AJ22: =SUM(AF22:AI22) -> 0.685 | AK22: 0.405 | AL22: 0.133 | AM22: 0.03 | AN22: 0.716 | AO22: =+AK22+AL22+AM22+AN22 -> 1.284 | AP22: 0.29 | AQ22: 0.038 | AR22: 0.136 | AS22: -1.727 | AT22: =+AP22+AQ22+AR22+AS22 -> -1.263 | AU22: =AU21*AU71 -> -0.1873609 | AV22: =AV21*AV71 -> -0.17525911 | AW22: =AW21*AW71 -> -0.16062293 | AX22: =AX21*AX71 -> -0.26612063 | AY22: =+AU22+AV22+AW22+AX22 -> -0.78936357 | AZ22: =AZ21*AZ71 -> 0.077135125 | BA22: =BA21*BA71 -> 0.098661566 | BB22: =BB21*BB71 -> 0.082098157 | BC22: =BC21*BC71 -> -0.020226276 | BD22: =+AZ22+BA22+BB22+BC22 -> 0.23766857 | BE22: =BE21*BE71 -> 0.38684482 | BF22: =BF21*BF71 -> 0.41738274 | BG22: =BG21*BG71 -> 0.41481229 | BH22: =BH21*BH71 -> 0.30273778 | BI22: =+BE22+BF22+BG22+BH22 -> 1.5217776 | BJ22: =BJ21*BJ71 -> 0.7118453 | BK22: =BK21*BK71 -> 0.71120171 | BL22: =BL21*BL71 -> 0.71585063 | BM22: =BM21*BM71 -> 0.56683266 | BN22: =+BJ22+BK22+BL22+BM22 -> 2.7057303 | BO22: =BO21*BO71 -> 1.0324499 | BP22: =BP21*BP71 -> 1.062766 | BQ22: =BQ21*BQ71 -> 1.0395706 | BR22: =BR21*BR71 -> 0.87545702 | BS22: =+BO22+BP22+BQ22+BR22 -> 4.0102435 | BT22: =BT21*BT71 -> 1.3374349 | BU22: =BU21*BU71 -> 1.3192275 | BV22: =BV21*BV71 -> 1.2767532 | BW22: =BW21*BW71 -> 1.0816217 | BX22: =+BT22+BU22+BV22+BW22 -> 5.0150373 | BY22: =BY21*BY71 -> 1.5481693 | BZ22: =BZ21*BZ71 -> 1.5254955 | CA22: =CA21*CA71 -> 1.4869976 | CB22: =CB21*CB71 -> 1.2650553 | CC22: =+BY22+BZ22+CA22+CB22 -> 5.8257177 | CD22: =CD21*CD71 -> 1.7853548 | CE22: =CE21*CE71 -> 1.7723023 | CF22: =CF21*CF71 -> 1.679747 | CG22: =CG21*CG71 -> 1.427857 | CH22: =+CD22+CE22+CF22+CG22 -> 6.6652612 | CI22: =CI21*CI71 -> 1.9705686 | CJ22: =CJ21*CJ71 -> 1.9276202 | CK22: =CK21*CK71 -> 1.8270875 | CL22: =CL21*CL71 -> 1.5428428 | CM22: =+CI22+CJ22+CK22+CL22 -> 7.2681191
A23: Minority interest | B23: 0 | C23: 0 | D23: 0 | E23: 0 | F23: =+B23+C23+D23+E23 -> 0 | G23: 0 | H23: 0 | I23: 0 | J23: 0 | K23: =+G23+H23+I23+J23 -> 0 | L23: 0 | M23: 0 | N23: 0 | O23: 0 | P23: =+L23+M23+N23+O23 -> 0 | Q23: 0 | R23: 0 | S23: 0 | T23: 0 | U23: =+Q23+R23+S23+T23 -> 0 | V23: 0 | W23: 0 | X23: 0 | Y23: 0 | Z23: =+V23+W23+X23+Y23 -> 0 | AA23: 0 | AB23: 99.785 | AC23: 0 | AD23: 0 | AE23: =SUM(AA23:AD23) -> 99.785 | AF23: 0 | AG23: 0 | AH23: 0 | AI23: 0 | AJ23: =SUM(AF23:AI23) -> 0 | AK23: 0 | AL23: 0 | AM23: 0 | AN23: 0 | AO23: =+AK23+AL23+AM23+AN23 -> 0 | AP23: 0 | AQ23: 0 | AR23: 0 | AS23: 0 | AT23: =+AP23+AQ23+AR23+AS23 -> 0 | AU23: 0 | AV23: 0 | AW23: 0 | AX23: 0 | AY23: =+AU23+AV23+AW23+AX23 -> 0 | AZ23: 0 | BA23: 0 | BB23: 0 | BC23: 0 | BD23: =+AZ23+BA23+BB23+BC23 -> 0 | BE23: 0 | BF23: 0 | BG23: 0 | BH23: 0 | BI23: =+BE23+BF23+BG23+BH23 -> 0 | BJ23: 0 | BK23: 0 | BL23: 0 | BM23: 0 | BN23: =+BJ23+BK23+BL23+BM23 -> 0 | BO23: 0 | BP23: 0 | BQ23: 0 | BR23: 0 | BS23: =+BO23+BP23+BQ23+BR23 -> 0 | BT23: 0 | BU23: 0 | BV23: 0 | BW23: 0 | BX23: =+BT23+BU23+BV23+BW23 -> 0 | BY23: 0 | BZ23: 0 | CA23: 0 | CB23: 0 | CC23: =+BY23+BZ23+CA23+CB23 -> 0 | CD23: 0 | CE23: 0 | CF23: 0 | CG23: 0 | CH23: =+CD23+CE23+CF23+CG23 -> 0 | CI23: 0 | CJ23: 0 | CK23: 0 | CL23: 0 | CM23: =+CI23+CJ23+CK23+CL23 -> 0
A24: Non-GAAP net income | B24: =B21-B22+B23 -> -15.373 | C24: =C21-C22+C23 -> -17.833 | D24: =D21-D22+D23 -> -26.759 | E24: =E21-E22+E23 -> -13.488 | F24: =F21-F22+F23 -> -73.453 | G24: =G21-G22+G23 -> -12.567 | H24: =H21-H22+H23 -> -20.459 | I24: =I21-I22+I23 -> -21.677 | ... CM24: =CM21-CM22+CM23 -> 1446.3557
A25: Amortization of intangible assets | B25: 0 | C25: 0 | D25: 0 | E25: 0 | F25: =+B25+C25+D25+E25 -> 0 | G25: 0 | H25: 0 | I25: 0 | J25: 0 | K25: =+G25+H25+I25+J25 -> 0 | L25: 0 | M25: 0 | N25: 0 | O25: 0 | P25: =+L25+M25+N25+O25 -> 0 | Q25: 0.229 | R25: =0.141+0.043+0.349 -> 0.533 | S25: 0.503 | T25: 0.49 | U25: =+Q25+R25+S25+T25 -> 1.755 | V25: 0.481 | W25: =0.149+0.336 -> 0.485 | X25: 0.491 | Y25: 0.491 | Z25: =+V25+W25+X25+Y25 -> 1.948 | AA25: 0.48 | AB25: 0.619 | AC25: 0.691 | AD25: 0.69 | AE25: =SUM(AA25:AD25) -> 2.48 | AF25: 0.68 | AG25: =0.686 -> 0.686 | AH25: 0.691 | AI25: 0.691 | AJ25: =SUM(AF25:AI25) -> 2.748 | AK25: 0.685 | AL25: 0.552 | AM25: 0.491 | AN25: 0.491 | AO25: =+AK25+AL25+AM25+AN25 -> 2.219 | AP25: 0.48 | AQ25: 0.416 | AR25: 0.387 | AS25: 0.387 | AT25: =+AP25+AQ25+AR25+AS25 -> 1.67 | AU25: =-'Other Accts'!AU57 -> 0.81003125 | AV25: =-'Other Accts'!AV57 -> 0.81003125 | AW25: =-'Other Accts'!AW57 -> 0.81003125 | AX25: =-'Other Accts'!AX57 -> 0.81003125 | AY25: =+AU25+AV25+AW25+AX25 -> 3.240125 | AZ25: =-'Other Accts'!AZ57 -> 0.70877734 | BA25: =-'Other Accts'!BA57 -> 0.70877734 | BB25: =-'Other Accts'!BB57 -> 0.70877734 | BC25: =-'Other Accts'!BC57 -> 0.70877734 | BD25: =+AZ25+BA25+BB25+BC25 -> 2.8351094 | BE25: =-'Other Accts'!BE57 -> 0.62018018 | BF25: =-'Other Accts'!BF57 -> 0.62018018 | BG25: =-'Other Accts'!BG57 -> 0.62018018 | BH25: =-'Other Accts'!BH57 -> 0.62018018 | BI25: =+BE25+BF25+BG25+BH25 -> 2.4807207 | BJ25: =-'Other Accts'!BJ57 -> 0.54265765 | BK25: =-'Other Accts'!BK57 -> 0.54265765 | BL25: =-'Other Accts'!BL57 -> 0.54265765 | BM25: =-'Other Accts'!BM57 -> 0.54265765 | BN25: =+BJ25+BK25+BL25+BM25 -> 2.1706306 | BO25: =-'Other Accts'!BO57 -> 0.47482545 | BP25: =-'Other Accts'!BP57 -> 0.47482545 | BQ25: =-'Other Accts'!BQ57 -> 0.47482545 | BR25: =-'Other Accts'!BR57 -> 0.47482545 | BS25: =+BO25+BP25+BQ25+BR25 -> 1.8993018 | BT25: =-'Other Accts'!BT57 -> 0.41547227 | BU25: =-'Other Accts'!BU57 -> 0.41547227 | BV25: =-'Other Accts'!BV57 -> 0.41547227 | BW25: =-'Other Accts'!BW57 -> 0.41547227 | BX25: =+BT25+BU25+BV25+BW25 -> 1.6618891 | BY25: =-'Other Accts'!BY57 -> 0.36353823 | BZ25: =-'Other Accts'!BZ57 -> 0.36353823 | CA25: =-'Other Accts'!CA57 -> 0.36353823 | CB25: =-'Other Accts'!CB57 -> 0.36353823 | CC25: =+BY25+BZ25+CA25+CB25 -> 1.4541529 | CD25: =-'Other Accts'!CD57 -> 0.31809595 | CE25: =-'Other Accts'!CE57 -> 0.31809595 | CF25: =-'Other Accts'!CF57 -> 0.31809595 | CG25: =-'Other Accts'!CG57 -> 0.31809595 | CH25: =+CD25+CE25+CF25+CG25 -> 1.2723838 | CI25: =-'Other Accts'!CI57 -> 0.27833396 | CJ25: =-'Other Accts'!CJ57 -> 0.27833396 | CK25: =-'Other Accts'!CK57 -> 0.27833396 | CL25: =-'Other Accts'!CL57 -> 0.27833396 | CM25: =+CI25+CJ25+CK25+CL25 -> 1.1133358
A26: Equity compensation | B26: =1.29/2 -> 0.645 | C26: =1.29/2 -> 0.645 | D26: 1.831 | E26: 1.572 | F26: =+B26+C26+D26+E26 -> 4.693 | G26: 1.277 | H26: 1.18 | I26: 1.831 | J26: 2.563 | K26: =+G26+H26+I26+J26 -> 6.851 | L26: 3.182 | M26: 3.215 | N26: 5.484 | O26: 5.072 | P26: =+L26+M26+N26+O26 -> 16.953 | Q26: 6.635 | R26: 25.667 | S26: 55.7 | T26: 56.903 | U26: =+Q26+R26+S26+T26 -> 144.905 | V26: 57.499 | W26: 34.775 | X26: 35.557 | Y26: 27.029 | Z26: =+V26+W26+X26+Y26 -> 154.86 | AA26: 24.991 | AB26: 25.726 | AC26: 21.231 | AD26: 23.503 | AE26: =SUM(AA26:AD26) -> 95.451 | AF26: 22.453 | AG26: 22.953 | AH26: 22.099 | AI26: 24.558 | AJ26: =SUM(AF26:AI26) -> 92.063 | AK26: 27.334 | AL26: 27.725 | AM26: 50.022 | AN26: 36.906 | AO26: =+AK26+AL26+AM26+AN26 -> 141.987 | AP26: 39.24 | AQ26: 43.602 | AR26: 43.544 | AS26: 45.312 | AT26: =+AP26+AQ26+AR26+AS26 -> 171.698 | AU26: =+CF!AU13 -> 39.26728 | AV26: =+CF!AV13 -> 44.16048 | AW26: =+CF!AW13 -> 44.52032 | AX26: =+CF!AX13 -> 44.9176 | AY26: =+AU26+AV26+AW26+AX26 -> 172.86568 | AZ26: =+CF!AZ13 -> 40.837971 | BA26: =+CF!BA13 -> 45.926899 | BB26: =+CF!BB13 -> 46.301133 | BC26: =+CF!BC13 -> 46.714304 | BD26: =+AZ26+BA26+BB26+BC26 -> 179.78031 | BE26: =+CF!BE13 -> 42.47149 | BF26: =+CF!BF13 -> 47.763975 | BG26: =+CF!BG13 -> 48.153178 | BH26: =+CF!BH13 -> 48.582876 | BI26: =+BE26+BF26+BG26+BH26 -> 186.97152 | BJ26: =+CF!BJ13 -> 44.17035 | BK26: =+CF!BK13 -> 49.674534 | BL26: =+CF!BL13 -> 50.079305 | BM26: =+CF!BM13 -> 50.526191 | BN26: =+BJ26+BK26+BL26+BM26 -> 194.45038 | BO26: =+CF!BO13 -> 45.937164 | BP26: =+CF!BP13 -> 51.661516 | BQ26: =+CF!BQ13 -> 52.082477 | BR26: =+CF!BR13 -> 52.547239 | BS26: =+BO26+BP26+BQ26+BR26 -> 202.2284 | BT26: =+CF!BT13 -> 47.77465 | BU26: =+CF!BU13 -> 53.727976 | BV26: =+CF!BV13 -> 54.165777 | BW26: =+CF!BW13 -> 54.649128 | BX26: =+BT26+BU26+BV26+BW26 -> 210.31753 | BY26: =+CF!BY13 -> 49.685636 | BZ26: =+CF!BZ13 -> 55.877095 | CA26: =+CF!CA13 -> 56.332408 | CB26: =+CF!CB13 -> 56.835094 | CC26: =+BY26+BZ26+CA26+CB26 -> 218.73023 | CD26: =+CF!CD13 -> 51.673062 | CE26: =+CF!CE13 -> 58.112179 | CF26: =+CF!CF13 -> 58.585704 | CG26: =+CF!CG13 -> 59.108497 | CH26: =+CD26+CE26+CF26+CG26 -> 227.47944 | CI26: =+CF!CI13 -> 53.739984 | CJ26: =+CF!CJ13 -> 60.436666 | CK26: =+CF!CK13 -> 60.929132 | CL26: =+CF!CL13 -> 61.472837 | CM26: =+CI26+CJ26+CK26+CL26 -> 236.57862
A27: Fair value change in contingent exp. | B27: 0 | C27: 0 | D27: 0 | E27: 0 | F27: =+B27+C27+D27+E27 -> 0 | G27: 0 | H27: 0 | I27: 0 | J27: 0 | K27: =+G27+H27+I27+J27 -> 0 | L27: 0 | M27: 0 | N27: 0 | O27: 0 | P27: =+L27+M27+N27+O27 -> 0 | Q27: -0.19 | R27: 0 | S27: 0.07 | T27: 0 | U27: =+Q27+R27+S27+T27 -> -0.12 | V27: 0 | W27: 0.875 | X27: 0.97 | Y27: 0.535 | Z27: =+V27+W27+X27+Y27 -> 2.38 | AA27: 4.51 | AB27: 1.592 | AC27: 0.745 | AD27: 2.687 | AE27: =SUM(AA27:AD27) -> 9.534 | AF27: 0.27 | AG27: 0.841 | AH27: 0.751 | AI27: 0.33 | AJ27: =SUM(AF27:AI27) -> 2.192 | AK27: 0.495 | AL27: 0.41 | AM27: 0.53 | AN27: 0.25 | AO27: =+AK27+AL27+AM27+AN27 -> 1.685 | AP27: 1.024 | AQ27: 0.877 | AR27: 0.532 | AS27: 0.531 | AT27: =+AP27+AQ27+AR27+AS27 -> 2.964 | AU27: 0 | AV27: 0 | AW27: 0 | AX27: 0 | AY27: =+AU27+AV27+AW27+AX27 -> 0 | AZ27: 0 | BA27: 0 | BB27: 0 | BC27: 0 | BD27: =+AZ27+BA27+BB27+BC27 -> 0 | BE27: 0 | BF27: 0 | BG27: 0 | BH27: 0 | BI27: =+BE27+BF27+BG27+BH27 -> 0 | BJ27: 0 | BK27: 0 | BL27: 0 | BM27: 0 | BN27: =+BJ27+BK27+BL27+BM27 -> 0 | BO27: 0 | BP27: 0 | BQ27: 0 | BR27: 0 | BS27: =+BO27+BP27+BQ27+BR27 -> 0 | BT27: 0 | BU27: 0 | BV27: 0 | BW27: 0 | BX27: =+BT27+BU27+BV27+BW27 -> 0 | BY27: 0 | BZ27: 0 | CA27: 0 | CB27: 0 | CC27: =+BY27+BZ27+CA27+CB27 -> 0 | CD27: 0 | CE27: 0 | CF27: 0 | CG27: 0 | CH27: =+CD27+CE27+CF27+CG27 -> 0 | CI27: 0 | CJ27: 0 | CK27: 0 | CL27: 0 | CM27: =+CI27+CJ27+CK27+CL27 -> 0
A28: Acquisition related exp. | B28: 0 | C28: 0 | D28: 0 | E28: 0 | F28: =+B28+C28+D28+E28 -> 0 | G28: 0 | H28: 0 | I28: 0 | J28: 0 | K28: =+G28+H28+I28+J28 -> 0 | L28: 0 | M28: 0 | N28: 0 | O28: 0 | P28: =+L28+M28+N28+O28 -> 0 | Q28: 9.707 | R28: 0 | S28: 0 | T28: 0 | U28: =+Q28+R28+S28+T28 -> 9.707 | V28: 0 | W28: 0 | X28: 0 | Y28: 0 | Z28: =+V28+W28+X28+Y28 -> 0 | AA28: 0.063 | AB28: -0.063 | AC28: 0 | AD28: 0 | AE28: =SUM(AA28:AD28) -> 0 | AF28: 0 | AG28: 0 | AH28: 0 | AI28: 0 | AJ28: =SUM(AF28:AI28) -> 0 | AK28: 0 | AL28: 0 | AM28: 0 | AN28: 0 | AO28: =+AK28+AL28+AM28+AN28 -> 0 | AP28: 0 | AQ28: 0 | AR28: 0 | AS28: 0 | AT28: =+AP28+AQ28+AR28+AS28 -> 0 | AU28: 0 | AV28: 0 | AW28: 0 | AX28: 0 | AY28: =+AU28+AV28+AW28+AX28 -> 0 | AZ28: 0 | BA28: 0 | BB28: 0 | BC28: 0 | BD28: =+AZ28+BA28+BB28+BC28 -> 0 | BE28: 0 | BF28: 0 | BG28: 0 | BH28: 0 | BI28: =+BE28+BF28+BG28+BH28 -> 0 | BJ28: 0 | BK28: 0 | BL28: 0 | BM28: 0 | BN28: =+BJ28+BK28+BL28+BM28 -> 0 | BO28: 0 | BP28: 0 | BQ28: 0 | BR28: 0 | BS28: =+BO28+BP28+BQ28+BR28 -> 0 | BT28: 0 | BU28: 0 | BV28: 0 | BW28: 0 | BX28: =+BT28+BU28+BV28+BW28 -> 0 | BY28: 0 | BZ28: 0 | CA28: 0 | CB28: 0 | CC28: =+BY28+BZ28+CA28+CB28 -> 0 | CD28: 0 | CE28: 0 | CF28: 0 | CG28: 0 | CH28: =+CD28+CE28+CF28+CG28 -> 0 | CI28: 0 | CJ28: 0 | CK28: 0 | CL28: 0 | CM28: =+CI28+CJ28+CK28+CL28 -> 0
A29: Other | B29: 0 | C29: 5.075 | D29: 4.716 | E29: 0 | F29: =+B29+C29+D29+E29 -> 9.791 | G29: 0 | H29: 0 | I29: 0.95 | J29: -0.15 | K29: =+G29+H29+I29+J29 -> 0.8 | L29: 4.7 | M29: 0.3 | N29: -0.3 | O29: 3.1 | P29: =+L29+M29+N29+O29 -> 7.8 | Q29: -4.1 | R29: 4.9 | S29: 6 | T29: =-1+0.7 -> -0.3 | U29: =+Q29+R29+S29+T29 -> 6.5 | V29: 0 | W29: 0 | X29: 0 | Y29: =-26.1+18.6 -> -7.5 | Z29: =+V29+W29+X29+Y29 -> -7.5 | AA29: 0 | AB29: 99.785 | AC29: =13.23+5.261 -> 18.491 | AD29: =-1.1-5.437 -> -6.537 | AE29: =SUM(AA29:AD29) -> 111.739 | AF29: =-3.882+5.485 -> 1.603 | AG29: =-63.997+23.569 -> -40.428 | AH29: -16.634 | AI29: =83.4+4.803-2.631 -> 85.572 | AJ29: =SUM(AF29:AI29) -> 30.113 | AK29: 30.054 | AL29: 15.485 | AM29: 1.686 | AN29: =-2.824-1.1 -> -3.924 | AO29: =+AK29+AL29+AM29+AN29 -> 43.301 | AP29: =2+5-13.672 -> -6.672 | AQ29: 0 | AR29: 0 | AS29: =13.582+4.9 -> 18.482 | AT29: =+AP29+AQ29+AR29+AS29 -> 11.81 | AU29: 0 | AV29: 0 | AW29: 0 | AX29: 0 | AY29: =+AU29+AV29+AW29+AX29 -> 0 | AZ29: 0 | BA29: 0 | BB29: 0 | BC29: 0 | BD29: =+AZ29+BA29+BB29+BC29 -> 0 | BE29: 0 | BF29: 0 | BG29: 0 | BH29: 0 | BI29: =+BE29+BF29+BG29+BH29 -> 0 | BJ29: 0 | BK29: 0 | BL29: 0 | BM29: 0 | BN29: =+BJ29+BK29+BL29+BM29 -> 0 | BO29: 0 | BP29: 0 | BQ29: 0 | BR29: 0 | BS29: =+BO29+BP29+BQ29+BR29 -> 0 | BT29: 0 | BU29: 0 | BV29: 0 | BW29: 0 | BX29: =+BT29+BU29+BV29+BW29 -> 0 | BY29: 0 | BZ29: 0 | CA29: 0 | CB29: 0 | CC29: =+BY29+BZ29+CA29+CB29 -> 0 | CD29: 0 | CE29: 0 | CF29: 0 | CG29: 0 | CH29: =+CD29+CE29+CF29+CG29 -> 0 | CI29: 0 | CJ29: 0 | CK29: 0 | CL29: 0 | CM29: =+CI29+CJ29+CK29+CL29 -> 0
A30: Taxes | B30: 0 | C30: 0 | D30: 0 | E30: 0 | F30: =+B30+C30+D30+E30 -> 0 | G30: 0 | H30: 0 | I30: 0 | J30: 0 | K30: =+G30+H30+I30+J30 -> 0 | L30: 0 | M30: 0 | N30: 0 | O30: 0 | P30: =+L30+M30+N30+O30 -> 0 | Q30: 0 | R30: 0 | S30: 0 | T30: 0 | U30: =+Q30+R30+S30+T30 -> 0 | V30: 2.3 | W30: 0 | X30: 0 | Y30: 0 | Z30: =+V30+W30+X30+Y30 -> 2.3 | AA30: 0 | AB30: 0 | AC30: 0 | AD30: 0 | AE30: =SUM(AA30:AD30) -> 0 | AF30: 0 | AG30: 0 | AH30: 0 | AI30: 0 | AJ30: =SUM(AF30:AI30) -> 0 | AK30: 0 | AL30: 0 | AM30: 0 | AN30: 0 | AO30: =+AK30+AL30+AM30+AN30 -> 0 | AP30: 0 | AQ30: 0 | AR30: 0 | AS30: 0 | AT30: =+AP30+AQ30+AR30+AS30 -> 0 | AU30: 0 | AV30: 0 | AW30: 0 | AX30: 0 | AY30: =+AU30+AV30+AW30+AX30 -> 0 | AZ30: 0 | BA30: 0 | BB30: 0 | BC30: 0 | BD30: =+AZ30+BA30+BB30+BC30 -> 0 | BE30: 0 | BF30: 0 | BG30: 0 | BH30: 0 | BI30: =+BE30+BF30+BG30+BH30 -> 0 | BJ30: 0 | BK30: 0 | BL30: 0 | BM30: 0 | BN30: =+BJ30+BK30+BL30+BM30 -> 0 | BO30: 0 | BP30: 0 | BQ30: 0 | BR30: 0 | BS30: =+BO30+BP30+BQ30+BR30 -> 0 | BT30: 0 | BU30: 0 | BV30: 0 | BW30: 0 | BX30: =+BT30+BU30+BV30+BW30 -> 0 | BY30: 0 | BZ30: 0 | CA30: 0 | CB30: 0 | CC30: =+BY30+BZ30+CA30+CB30 -> 0 | CD30: 0 | CE30: 0 | CF30: 0 | CG30: 0 | CH30: =+CD30+CE30+CF30+CG30 -> 0 | CI30: 0 | CJ30: 0 | CK30: 0 | CL30: 0 | CM30: =+CI30+CJ30+CK30+CL30 -> 0
A31: GAAP net income | B31: =+B24-B25-B26-B27-B28-B29-B30 -> -16.018 | C31: =+C24-C25-C26-C27-C28-C29-C30 -> -23.553 | D31: =+D24-D25-D26-D27-D28-D29-D30 -> -33.306 | E31: =+E24-E25-E26-E27-E28-E29-E30 -> -15.06 | F31: =+F24-F25-F26-F27-F28-F29-F30 -> -87.937 | G31: =+G24-G25-G26-G27-G28-G29-G30 -> -13.844 | H31: =+H24-H25-H26-H27-H28-H29-H30 -> -21.639 | I31: =+I24-I25-I26-I27-I28-I29-I30 -> -24.458 | ... CM31: =+CM24-CM25-CM26-CM27-CM28-CM29-CM30 -> 1208.6637
A33: Basic shares outstanding | B33: -- | C33: -- | D33: 12.073 | E33: 11.851 | F33: 12.582 | G33: 11.92 | H33: 12.388 | I33: 12.582 | J33: 84.123 | K33: 30.403 | L33: 85.935 | M33: 89.036 | N33: 93.303 | O33: =P33*4-SUM(L33:N33) -> 94.114 | P33: 90.597 | Q33: 94.382 | R33: 96.011 | S33: 99.554 | T33: =U33*4-SUM(Q33:S33) -> 100.069 | U33: 97.504 | V33: 100.955 | W33: 101.172 | X33: 101.42 | Y33: 101.697 | Z33: 101.314 | AA33: 101.853 | AB33: 102.047 | AC33: 102.289 | AD33: 102.516 | AE33: 102.178 | AF33: 102.663 | AG33: 108.808 | AH33: 117.736 | AI33: 118.508 | AJ33: =AVERAGE(AF33:AI33) -> 111.92875 | AK33: 121.712 | AL33: 122.447 | AM33: 123.051 | AN33: 123.754 | AO33: =AVERAGE(AK33:AN33) -> 122.741 | AP33: 123.871 | AQ33: 124.114 | AR33: 124.807 | AS33: 128.657 | AT33: =AVERAGE(AP33:AS33) -> 125.36225 | AU33: =AS33+BS!AU57-BS!AU58 -> 129.157 | AV33: =AU33+BS!AV57-BS!AV58 -> 129.457 | AW33: =AV33+BS!AW57-BS!AW58 -> 129.757 | AX33: =AW33+BS!AX57-BS!AX58 -> 130.057 | AY33: =AVERAGE(AU33:AX33) -> 129.607 | AZ33: =AX33+BS!AZ57-BS!AZ58 -> 130.38214 | BA33: =AZ33+BS!BA57-BS!BA58 -> 130.70729 | BB33: =BA33+BS!BB57-BS!BB58 -> 131.03243 | BC33: =BB33+BS!BC57-BS!BC58 -> 131.35757 | BD33: =AVERAGE(AZ33:BC33) -> 130.86986 | BE33: =BC33+BS!BE57-BS!BE58 -> 131.68596 | BF33: =BE33+BS!BF57-BS!BF58 -> 132.01436 | BG33: =BF33+BS!BG57-BS!BG58 -> 132.34275 | BH33: =BG33+BS!BH57-BS!BH58 -> 132.67115 | BI33: =AVERAGE(BE33:BH33) -> 132.17855 | BJ33: =BH33+BS!BJ57-BS!BJ58 -> 133.00282 | BK33: =BJ33+BS!BK57-BS!BK58 -> 133.3345 | BL33: =BK33+BS!BL57-BS!BL58 -> 133.66618 | BM33: =BL33+BS!BM57-BS!BM58 -> 133.99786 | BN33: =AVERAGE(BJ33:BM33) -> 133.50034 | BO33: =BM33+BS!BO57-BS!BO58 -> 134.33285 | BP33: =BO33+BS!BP57-BS!BP58 -> 134.66785 | BQ33: =BP33+BS!BQ57-BS!BQ58 -> 135.00284 | BR33: =BQ33+BS!BR57-BS!BR58 -> 135.33784 | BS33: =AVERAGE(BO33:BR33) -> 134.83534 | BT33: =BR33+BS!BT57-BS!BT58 -> 135.67618 | BU33: =BT33+BS!BU57-BS!BU58 -> 136.01452 | BV33: =BU33+BS!BV57-BS!BV58 -> 136.35287 | BW33: =BV33+BS!BW57-BS!BW58 -> 136.69121 | BX33: =AVERAGE(BT33:BW33) -> 136.1837 | BY33: =BW33+BS!BY57-BS!BY58 -> 137.03294 | BZ33: =BY33+BS!BZ57-BS!BZ58 -> 137.37467 | CA33: =BZ33+BS!CA57-BS!CA58 -> 137.7164 | CB33: =CA33+BS!CB57-BS!CB58 -> 138.05813 | CC33: =AVERAGE(BY33:CB33) -> 137.54553 | CD33: =CB33+BS!CD57-BS!CD58 -> 138.40327 | CE33: =CD33+BS!CE57-BS!CE58 -> 138.74842 | CF33: =CE33+BS!CF57-BS!CF58 -> 139.09356 | CG33: =CF33+BS!CG57-BS!CG58 -> 139.43871 | CH33: =AVERAGE(CD33:CG33) -> 138.92099 | CI33: =CG33+BS!CI57-BS!CI58 -> 139.7873 | CJ33: =CI33+BS!CJ57-BS!CJ58 -> 140.1359 | CK33: =CJ33+BS!CK57-BS!CK58 -> 140.4845 | CL33: =CK33+BS!CL57-BS!CL58 -> 140.83309 | CM33: =AVERAGE(CI33:CL33) -> 140.3102
A34: Diluted shares outstanding | B34: -- | C34: -- | D34: 12.073 | E34: 11.851 | F34: 12.582 | G34: 11.92 | H34: 12.388 | I34: 12.582 | J34: 84.123 | K34: 30.403 | L34: 85.935 | M34: 89.036 | N34: 93.303 | O34: =P34*4-SUM(L34:N34) -> 94.114 | P34: 90.597 | Q34: 94.382 | R34: 96.011 | S34: 99.554 | T34: =U34*4-SUM(Q34:S34) -> 100.069 | U34: 97.504 | V34: 100.955 | W34: 101.172 | X34: 101.42 | Y34: 101.697 | Z34: 101.314 | AA34: 101.853 | AB34: 102.047 | AC34: 102.289 | AD34: 102.516 | AE34: 102.178 | AF34: 102.663 | AG34: 108.808 | AH34: 117.736 | AI34: 118.508 | AJ34: =AVERAGE(AF34:AI34) -> 111.92875 | AK34: 121.712 | AL34: 122.447 | AM34: 123.051 | AN34: 123.754 | AO34: =AVERAGE(AK34:AN34) -> 122.741 | AP34: 123.871 | AQ34: 124.114 | AR34: 124.807 | AS34: 128.657 | AT34: =AVERAGE(AP34:AS34) -> 125.36225 | AU34: =AS34+BS!AU57-BS!AU58 -> 129.157 | AV34: =AU34+BS!AV57-BS!AV58 -> 129.457 | AW34: =AV34+BS!AW57-BS!AW58 -> 129.757 | AX34: =AW34+BS!AX57-BS!AX58 -> 130.057 | AY34: =AVERAGE(AU34:AX34) -> 129.607 | AZ34: =AX34+BS!AZ57-BS!AZ58 -> 130.38214 | BA34: =AZ34+BS!BA57-BS!BA58 -> 130.70729 | BB34: =BA34+BS!BB57-BS!BB58 -> 131.03243 | BC34: =BB34+BS!BC57-BS!BC58 -> 131.35757 | BD34: =AVERAGE(AZ34:BC34) -> 130.86986 | BE34: =BC34+BS!BE57-BS!BE58 -> 131.68596 | BF34: =BE34+BS!BF57-BS!BF58 -> 132.01436 | BG34: =BF34+BS!BG57-BS!BG58 -> 132.34275 | BH34: =BG34+BS!BH57-BS!BH58 -> 132.67115 | BI34: =AVERAGE(BE34:BH34) -> 132.17855 | BJ34: =BH34+BS!BJ57-BS!BJ58 -> 133.00282 | BK34: =BJ34+BS!BK57-BS!BK58 -> 133.3345 | BL34: =BK34+BS!BL57-BS!BL58 -> 133.66618 | BM34: =BL34+BS!BM57-BS!BM58 -> 133.99786 | BN34: =AVERAGE(BJ34:BM34) -> 133.50034 | BO34: =BM34+BS!BO57-BS!BO58 -> 134.33285 | BP34: =BO34+BS!BP57-BS!BP58 -> 134.66785 | BQ34: =BP34+BS!BQ57-BS!BQ58 -> 135.00284 | BR34: =BQ34+BS!BR57-BS!BR58 -> 135.33784 | BS34: =AVERAGE(BO34:BR34) -> 134.83534 | BT34: =BR34+BS!BT57-BS!BT58 -> 135.67618 | BU34: =BT34+BS!BU57-BS!BU58 -> 136.01452 | BV34: =BU34+BS!BV57-BS!BV58 -> 136.35287 | BW34: =BV34+BS!BW57-BS!BW58 -> 136.69121 | BX34: =AVERAGE(BT34:BW34) -> 136.1837 | BY34: =BW34+BS!BY57-BS!BY58 -> 137.03294 | BZ34: =BY34+BS!BZ57-BS!BZ58 -> 137.37467 | CA34: =BZ34+BS!CA57-BS!CA58 -> 137.7164 | CB34: =CA34+BS!CB57-BS!CB58 -> 138.05813 | CC34: =AVERAGE(BY34:CB34) -> 137.54553 | CD34: =CB34+BS!CD57-BS!CD58 -> 138.40327 | CE34: =CD34+BS!CE57-BS!CE58 -> 138.74842 | CF34: =CE34+BS!CF57-BS!CF58 -> 139.09356 | CG34: =CF34+BS!CG57-BS!CG58 -> 139.43871 | CH34: =AVERAGE(CD34:CG34) -> 138.92099 | CI34: =CG34+BS!CI57-BS!CI58 -> 139.7873 | CJ34: =CI34+BS!CJ57-BS!CJ58 -> 140.1359 | CK34: =CJ34+BS!CK57-BS!CK58 -> 140.4845 | CL34: =CK34+BS!CL57-BS!CL58 -> 140.83309 | CM34: =AVERAGE(CI34:CL34) -> 140.3102
A36: Non-GAAP basic E.P.S. | B36: -- | C36: -- | D36: =D24/D33 -> -2.2164334 | E36: =E24/E33 -> -1.1381318 | F36: =F24/F33 -> -5.8379431 | G36: =G24/G33 -> -1.0542785 | H36: =H24/H33 -> -1.6515176 | I36: =I24/I33 -> -1.7228581 | J36: =J24/J33 -> -0.26994995 | K36: =K24/K33 -> -2.5461961 | ... CM36: =CM24/CM33 -> 10.308272
A37: Non-GAAP diluted E.P.S. | B37: -- | C37: -- | D37: =(D24)/D34 -> -2.2164334 | E37: =(E24)/E34 -> -1.1381318 | F37: =(F24)/F34 -> -5.8379431 | G37: =(G24)/G34 -> -1.0542785 | H37: =(H24)/H34 -> -1.6515176 | I37: =(I24)/I34 -> -1.7228581 | J37: =(J24)/J34 -> -0.26994995 | K37: =(K24)/K34 -> -2.5461961 | ... CM37: =(CM24)/CM34 -> 10.308272
A39: GAAP basic E.P.S. | B39: -- | C39: -- | D39: =D31/D33 -> -2.7587178 | E39: =E31/E33 -> -1.2707788 | F39: =F31/F33 -> -6.9891114 | G39: =G31/G33 -> -1.1614094 | H39: =H31/H33 -> -1.7467711 | I39: =I31/I33 -> -1.9438881 | J39: =J31/J33 -> -0.29863414 | K39: =K31/K33 -> -2.7978489 | ... AL39: =AL31/AL33 -> -0.83814222 | AM39: =+AM$31/AM33 -> -0.87568569 | AN39: =+AN$31/AN33 -> -0.89698919 | AO39: =+AO$31/AO33 -> -3.5552342 | AP39: =+AP$31/AP33 -> -0.76821048 | AQ39: =+AQ$31/AQ33 -> -0.80489711 | AR39: =+AR$31/AR33 -> -0.74294711 | AS39: =+AS$31/AS33 -> -0.99873307 | AT39: =+AT$31/AT33 -> -3.3205929 | ... CM39: =+CM$31/CM33 -> 8.6142258
A40: GAAP diluted E.P.S. | B40: -- | C40: -- | D40: =D31/D34 -> -2.7587178 | E40: =E31/E34 -> -1.2707788 | F40: =F31/F34 -> -6.9891114 | G40: =G31/G34 -> -1.1614094 | H40: =H31/H34 -> -1.7467711 | I40: =I31/I34 -> -1.9438881 | J40: =J31/J34 -> -0.29863414 | K40: =K31/K34 -> -2.7978489 | ... AL40: =AL31/AL34 -> -0.83814222 | AM40: =+AM$31/AM34 -> -0.87568569 | AN40: =+AN$31/AN34 -> -0.89698919 | AO40: =+AO$31/AO34 -> -3.5552342 | AP40: =+AP$31/AP34 -> -0.76821048 | AQ40: =+AQ$31/AQ34 -> -0.80489711 | AR40: =+AR$31/AR34 -> -0.74294711 | AS40: =+AS$31/AS34 -> -0.99873307 | AT40: =+AT$31/AT34 -> -3.3205929 | ... CM40: =+CM$31/CM34 -> 8.6142258
A42: EBITDA | B42: -- | C42: -- | D42: =D17+CF!D9-D25 -> -23.033 | E42: =E17+CF!E9-E25 -> -12.653 | F42: =F17+CF!F9-F25 -> -66.713 | G42: =G17+CF!G9-G25 -> -15.975 | H42: =H17+CF!H9-H25 -> -19.954 | I42: =I17+CF!I9-I25 -> -20.371 | J42: =J17+CF!J9-J25 -> -22.655 | K42: =K17+CF!K9-K25 -> -78.955 | ... CM42: =CM17+CF!CM9-CM25 -> 1381.2266
A44: Year-Over-Year
A45: =A7 -> Net sales | B45: -- | C45: -- | D45: -- | E45: -- | F45: -- | G45: =G7/B7-1 -> 0.96099624 | H45: =H7/C7-1 -> 0.90094155 | I45: =I7/D7-1 -> 0.9486166 | J45: =J7/E7-1 -> 0.64348565 | K45: =K7/F7-1 -> 0.81852654 | L45: =L7/G7-1 -> 1.1959621 | M45: =M7/H7-1 -> 1.7848003 | N45: =N7/I7-1 -> 1.8050894 | ... CM45: =CM7/CH7-1 -> 0.063067934
A46: Cost of Sales | B46: -- | C46: -- | D46: -- | E46: -- | F46: -- | G46: =G10/B10-1 -> 0.4565338 | H46: =H10/C10-1 -> 0.34047894 | I46: =I10/D10-1 -> 0.16259212 | J46: =J10/E10-1 -> 0.50594059 | K46: =K10/F10-1 -> 0.36332578 | L46: =L10/G10-1 -> 0.45429815 | M46: =M10/H10-1 -> 0.6909919 | N46: =N10/I10-1 -> 0.8359996 | ... CM46: =CM10/CH10-1 -> 0.04646936
...

Sheet Rev
A1: Guardant Health, Inc. (NASDAQ: GH)
A2: Revenue Build
A3: $ millions except per share data, FY ending Dec
AR4: =AR16/AQ16-1 -> 0.5
B5: =+IS!B5 -> Mar | C5: =+IS!C5 -> Jun | D5: =+IS!D5 -> Sep | E5: =+IS!E5 -> Dec | F5: =+IS!F5 -> 43070 | G5: =+IS!G5 -> Mar | H5: =+IS!H5 -> Jun | I5: =+IS!I5 -> Sep | ... CM5: =+IS!CM5 -> 49279
B6: =+IS!B6 -> 1Q17A | C6: =+IS!C6 -> 2Q17A | D6: =+IS!D6 -> 3Q17A | E6: =+IS!E6 -> 4Q17A | F6: =+IS!F6 -> FY17A | G6: =+IS!G6 -> 1Q18A | H6: =+IS!H6 -> 2Q18A | I6: =+IS!I6 -> 3Q18A | ... CM6: =+IS!CM6 -> FY34E
A7: Revenue Build
A8: Consolidated
A9: Volumes
A10: Oncology | B10: -- | C10: -- | D10: -- | E10: -- | F10: -- | G10: =+G55 -> 7246 | H10: =+H55 -> 6723 | I10: =+I55 -> 7027 | J10: =+J55 -> 8596 | K10: =+K55 -> 29592 | L10: =+L55 -> 9521 | M10: =+M55 -> 11875 | N10: =+N55 -> 13259 | ... CM10: =+CM55 -> 1213765.3
A11: % yoy | B11: -- | C11: -- | D11: -- | E11: -- | F11: -- | G11: -- | H11: -- | I11: -- | J11: -- | K11: -- | L11: =+L10/G10-1 -> 0.31396633 | M11: =+M10/H10-1 -> 0.76632456 | N11: =+N10/I10-1 -> 0.88686495 | O11: =+O10/J10-1 -> 0.77640763 | P11: =+P10/K10-1 -> 0.68711138 | Q11: =+Q10/L10-1 -> 0.60245773 | R11: =+R10/M10-1 -> 0.15317895 | S11: =+S10/N10-1 -> 0.27837695 | ... CM11: =+CM10/CH10-1 -> 0.07855407
A12: % seq | B12: -- | C12: -- | D12: -- | E12: -- | F12: -- | G12: -- | H12: =+H10/G10-1 -> -0.072177753 | I12: =+I10/H10-1 -> 0.045217909 | J12: =+J10/I10-1 -> 0.22328163 | K12: -- | L12: =+L10/J10-1 -> 0.10760819 | M12: =+M10/L10-1 -> 0.24724294 | N12: =+N10/M10-1 -> 0.11654737 | O12: =+O10/N10-1 -> 0.15167056 | P12: -- | Q12: =+Q10/O10-1 -> -0.0008513425 | R12: =+R10/Q10-1 -> -0.10244478 | S12: =+S10/R10-1 -> 0.23776837 | T12: =+T10/S10-1 -> 0.023775811 | U12: -- | V12: =+V10/T10-1 -> 0.059759119 | W12: =+W10/V10-1 -> 0.1326808 | X12: =+X10/W10-1 -> 0.094863178 | Y12: =+Y10/X10-1 -> 0.12251162 | Z12: -- | AA12: =+AA10/Y10-1 -> 0.05859375 | AB12: =+AB10/AA10-1 -> 0.081180812 | AC12: =+AC10/AB10-1 -> 0.10580205 | AD12: =+AD10/AC10-1 -> 0.11111111 | AE12: -- | AF12: =+AF10/AD10-1 -> 0.086111111 | AG12: =+AG10/AF10-1 -> 0.11253197 | AH12: =+AH10/AG10-1 -> 0.0091954023 | AI12: =+AI10/AH10-1 -> 0.056947608 | AJ12: -- | AK12: =+AK10/AI10-1 -> 0.010775862 | AL12: =+AL10/AK10-1 -> 0.053304904 | AM12: =+AM10/AL10-1 -> 0.074898785 | AN12: =+AN10/AM10-1 -> 0.079096045 | AO12: -- | AP12: =+AP10/AN10-1 -> 0.029668412 | AQ12: =+AQ10/AP10-1 -> 0.084745763 | AR12: =+AR10/AQ10-1 -> 0.15625 | AS12: =+AS10/AR10-1 -> 0.067567568 | AT12: -- | AU12: =+AU10/AS10-1 -> 0.0096600736 | AV12: =+AV10/AU10-1 -> 0.10709347 | AW12: =+AW10/AV10-1 -> 0.085531149 | AX12: =+AX10/AW10-1 -> 0.074416877 | AY12: -- | AZ12: =+AZ10/AX10-1 -> 0.09784274 | BA12: =+BA10/AZ10-1 -> 0.07269194 | BB12: =+BB10/BA10-1 -> 0.064688897 | BC12: =+BC10/BB10-1 -> 0.073286493 | BD12: -- | BE12: =+BE10/BC10-1 -> 0.077524558 | BF12: =+BF10/BE10-1 -> 0.059350169 | BG12: =+BG10/BF10-1 -> 0.053302786 | BH12: =+BH10/BG10-1 -> 0.055704631 | BI12: -- | BJ12: =+BJ10/BH10-1 -> 0.037163232 | BK12: =+BK10/BJ10-1 -> 0.021126 | BL12: =+BL10/BK10-1 -> 0.018033072 | BM12: =+BM10/BL10-1 -> 0.022867802 | BN12: -- | BO12: =+BO10/BM10-1 -> 0.048398659 | BP12: =+BP10/BO10-1 -> 0.03151502 | BQ12: =+BQ10/BP10-1 -> 0.027843179 | BR12: =+BR10/BQ10-1 -> 0.032289692 | BS12: -- | BT12: =+BT10/BR10-1 -> 0.01841678 | BU12: =+BU10/BT10-1 -> 0.029061713 | BV12: =+BV10/BU10-1 -> 0.025435737 | BW12: =+BW10/BV10-1 -> 0.030207214 | BX12: -- | BY12: =+BY10/BW10-1 -> 0.016697446 | BZ12: =+BZ10/BY10-1 -> 0.025639551 | CA12: =+CA10/BZ10-1 -> 0.02209215 | CB12: =+CB10/CA10-1 -> 0.027234158 | CC12: -- | CD12: =+CD10/CB10-1 -> 0.0066440227 | CE12: =+CE10/CD10-1 -> 0.024363565 | CF12: =+CF10/CE10-1 -> 0.020744662 | CG12: =+CG10/CF10-1 -> 0.026213819 | CH12: -- | CI12: =+CI10/CG10-1 -> 0.0068332503 | CJ12: =+CJ10/CI10-1 -> 0.023231647 | CK12: =+CK10/CJ10-1 -> 0.019544782 | CL12: =+CL10/CK10-1 -> 0.025305922 | CM12: --
A13: Biopharma & Data | B13: -- | C13: -- | D13: -- | E13: -- | F13: -- | G13: =+G178 -> 2300 | H13: =+H178 -> 2500 | I13: =+I178 -> 2505 | J13: =+J178 -> 3025 | K13: =+K178 -> 10330 | L13: =+L178 -> 3750 | M13: =+M178 -> 5250 | N13: =+N178 -> 5250 | ... CM13: =+CM178 -> 96472.889
A14: % yoy | B14: -- | C14: -- | D14: -- | E14: -- | F14: -- | G14: -- | H14: -- | I14: -- | J14: -- | K14: -- | L14: =+L13/G13-1 -> 0.63043478 | M14: =+M13/H13-1 -> 1.1 | N14: =+N13/I13-1 -> 1.0958084 | O14: =+O13/J13-1 -> 1.0661157 | P14: =+P13/K13-1 -> 0.98451113 | Q14: =+Q13/L13-1 -> 0.40426667 | R14: =+R13/M13-1 -> -0.46571429 | S14: =+S13/N13-1 -> -0.41504762 | ... CM14: =+CM13/CH13-1 -> 0.08
