Workbook
Name Billings: #REF!
Name Billings: #REF!
Name Billings: #REF!
Name BS: 'Balance Sheet'!$A$1:$BL$76
Name CF: 'Cash Flow'!$A$1:$BR$78
Name Current: #REF!
Name Current: #REF!
Name Current: #REF!
Name Current: #REF!
Name Current_Net_Cash: #REF!
Name Current_Shares: #REF!
Name Current_Shares: #REF!
Name Current_Shares: #REF!
Name Current_Shares: #REF!
Name Current_Shares: #REF!
Name Debt: #REF!
Name Rating: #REF!
Name Rating: #REF!
Name Rating: #REF!
Name Rating: #REF!
Name Rating: #REF!
Name REV: 'Revenue Build'!$A$1:$BL$677
Name REV_NOW: [1]Rev!$A$1:$EU$190
Name Target: #REF!

Sheet __FDSCACHE__
B1: This sheet contains FactSet XML data for use with this workbook's =FDS codes. Modifying the worksheet's contents may damage the workbook's =FDS functionality.

Sheet WFS
C5: Equity Research
C7: Financial Model
C8: Software
C9: 46090
C12: Intuit Inc.
C17: Wells Fargo Software Team
C19: Michael Turrin
C20: Senior Analyst
C21: +1 (628) 629-7565
C22: michael.turrin@wellsfargo.com
C24: Austin Williams | E24: Rich Poland | G24: Ronit Shah | I24: Griffin MacMaster
C25: Associate Analyst | E25: Associate Analyst | G25: Associate Analyst | I25: Associate Analyst
C26: +1 (628) 629-7572 | E26: +1 (212) 214-5333 | G26: +1 (212) 214-1379 | I26: +1 (908) 566-6943
C27: austin.r.williams@wellsfargo.com | E27: richard.d.poland@wellsfargo.com | G27: ronit.shah@wellsfargo.com | I27: griffin.macmaster@wellsfargo.com
C32: Important Disclaimers:
AD45: 1 | AE45: +RC[-1]+1*R[-5]C

Sheet Income Statement
A1: Intuit, Inc.
A2: Income Statement | N2: 2019/1F | O2: 2019/2F | P2: 2019/3F | Q2: 2019/4F | R2: 2020/1F | S2: 2020/2F | T2: 2020/3F | U2: 2020/4F | V2: 2021/1F | W2: 2021/2F | X2: 2021/3F | Y2: 2021/4F | Z2: 2022/1F | AA2: 2022/2F | AB2: 2022/3F | AC2: 2022/4F | AD2: 2023/1F | AE2: 2023/2F | AF2: 2023/3F | AG2: 2023/4F | AH2: 2024/1F | AI2: 2024/2F | AJ2: 2024/3F | AK2: 2024/4F | AL2: 2025/1F | AM2: 2025/2F | AN2: 2025/3F | AO2: 2025/4F | AP2: 2026/1F | AQ2: 2026/2F | AR2: 2026/3F | AS2: 2026/4F | AT2: 2027/1F | AU2: 2027/2F | AV2: 2027/3F | AW2: 2027/4F | AX2: 2028/1F | AY2: 2028/2F | AZ2: 2028/3F | BA2: 2028/4F
B3: Fiscal 2016 | F3: Fiscal 2017 | J3: Fiscal 2018 | N3: Fiscal 2019 | R3: Fiscal 2020 | V3: Fiscal 2021 | Z3: Fiscal 2022 | AD3: Fiscal 2023 | AH3: Fiscal 2024 | AL3: Fiscal 2025 | AP3: Fiscal 2026 | AT3: Fiscal 2027 | AX3: Fiscal 2028
A4: ($ in millions, unless otherwise stated) | B4: 42308 | C4: 42400 | D4: 42490 | E4: 42582 | F4: 42674 | G4: 42766 | H4: 42855 | I4: 42947 | J4: 43039 | K4: 43131 | L4: 43220 | M4: 43312 | N4: 43404 | O4: 43496 | P4: 43585 | Q4: 43677 | R4: 43769 | S4: 43861 | T4: 43951 | U4: 44043 | V4: 44135 | W4: Jan-21 | X4: Apr-21 | Y4: Jul-21 | Z4: Oct-21 | AA4: Jan-22 | AB4: Apr-22 | AC4: Jul-22 | AD4: Oct-22 | AE4: Jan-23 | AF4: Apr-23 | AG4: Jul-23 | AH4: Oct-23 | AI4: Jan-24 | AJ4: Apr-24 | AK4: Jul-24 | AL4: Oct-24 | AM4: Jan-25 | AN4: Apr-25 | AO4: Jul-25 | AP4: Oct-25 | AQ4: Jan-26 | AR4: Apr-26E | AS4: Jul-26E | AT4: Oct-26E | AU4: Jan-27E | AV4: Apr-27E | AW4: Jul-27E | AX4: Oct-27E | AY4: Jan-28E | AZ4: Apr-28E | BA4: Jul-28E | BC4: FY15 | BD4: FY16 | BE4: FY17 | BF4: FY18 | BG4: FY19 | BH4: FY20 | BI4: FY21 | BJ4: FY22 | BK4: FY23 | BL4: FY24 | BM4: FY25 | BN4: FY26E | BO4: FY27E | BP4: FY28E
A5: Non-GAAP Income Statement
A6: Revenue
A7: Product Revenue | B7: =+'Revenue Build'!B13 -> 271 | C7: =+'Revenue Build'!C13 -> 264 | D7: =+'Revenue Build'!D13 -> 459 | E7: =+'Revenue Build'!E13 -> 295 | F7: =+'Revenue Build'!F13 -> 297 | G7: =+'Revenue Build'!G13 -> 299 | H7: =+'Revenue Build'!H13 -> 467 | I7: =+'Revenue Build'!I13 -> 313 | ... BA7: =+'Revenue Build'!BA13 -> 644.78226 | BD7: =+SUM(B7:E7) -> 1289 | BE7: =+SUM(F7:I7) -> 1376 | BF7: =+SUM(J7:M7) -> 1624 | BG7: =SUM(N7:Q7) -> 1623 | BH7: =+SUM(R7:U7) -> 1635 | BI7: =SUM(V7:Y7) -> 1709 | BJ7: =+SUM(Z7:AC7) -> 2106.4922 | BK7: =+SUM(AD7:AG7) -> 2380.3345 | BL7: =+SUM(AH7:AK7) -> 2484.0248 | BM7: =+SUM(AL7:AO7) -> 2431.0061 | BN7: =+SUM(AP7:AS7) -> 2566.9111 | BO7: =+SUM(AT7:AW7) -> 2730.1957 | BP7: =+SUM(AX7:BA7) -> 2892.0071
A8: Service and Other Revenue | B8: =+'Revenue Build'!B18 -> 442 | C8: =+'Revenue Build'!C18 -> 659 | D8: =+'Revenue Build'!D18 -> 1845 | E8: =+'Revenue Build'!E18 -> 459 | F8: =+'Revenue Build'!F18 -> 481 | G8: =+'Revenue Build'!G18 -> 717 | H8: =+'Revenue Build'!H18 -> 2074 | I8: =+'Revenue Build'!I18 -> 529 | ... BA8: =+'Revenue Build'!BA18 -> 4688.0901 | BD8: =+SUM(B8:E8) -> 3405 | BE8: =+SUM(F8:I8) -> 3801 | BF8: =+SUM(J8:M8) -> 4401 | BG8: =SUM(N8:Q8) -> 5161 | BH8: =+SUM(R8:U8) -> 6044 | BI8: =SUM(V8:Y8) -> 7924 | BJ8: =+SUM(Z8:AC8) -> 10619.508 | BK8: =+SUM(AD8:AG8) -> 11987.666 | BL8: =+SUM(AH8:AK8) -> 13800.975 | BM8: =+SUM(AL8:AO8) -> 16399.994 | BN8: =+SUM(AP8:AS8) -> 18710.286 | BO8: =+SUM(AT8:AW8) -> 21037.141 | BP8: =+SUM(AX8:BA8) -> 23679.705
A9: Total Revenue | B9: =+'Revenue Build'!B6 -> 713 | C9: =+'Revenue Build'!C6 -> 923 | D9: =+'Revenue Build'!D6 -> 2304 | E9: =+'Revenue Build'!E6 -> 754 | F9: =+'Revenue Build'!F6 -> 778 | G9: =+'Revenue Build'!G6 -> 1016 | H9: =+'Revenue Build'!H6 -> 2541 | I9: =+'Revenue Build'!I6 -> 842 | ... BA9: =+'Revenue Build'!BA6 -> 5332.8724 | BD9: =+SUM(B9:E9) -> 4694 | BE9: =+SUM(F9:I9) -> 5177 | BF9: =+SUM(J9:M9) -> 6025 | BG9: =SUM(N9:Q9) -> 6784 | BH9: =+SUM(R9:U9) -> 7679 | BI9: =SUM(V9:Y9) -> 9633 | BJ9: =+SUM(Z9:AC9) -> 12726 | BK9: =+SUM(AD9:AG9) -> 14368 | BL9: =+SUM(AH9:AK9) -> 16285 | BM9: =+SUM(AL9:AO9) -> 18831 | BN9: =+SUM(AP9:AS9) -> 21277.197 | BO9: =+SUM(AT9:AW9) -> 23767.337 | BP9: =+SUM(AX9:BA9) -> 26571.712
A10: Consensus revenue | N10: {=_xll.FDS("INTU-US","FE_ESTIMATE(SALES,MEAN,QTR_ROLL,"&N2&",NOW,,,'')")} -> 1016 | O10: {=_xll.FDS("INTU-US","FE_ESTIMATE(SALES,MEAN,QTR_ROLL,"&O2&",NOW,,,'')")} -> 1502 | P10: {=_xll.FDS("INTU-US","FE_ESTIMATE(SALES,MEAN,QTR_ROLL,"&P2&",NOW,,,'')")} -> 3272 | Q10: {=_xll.FDS("INTU-US","FE_ESTIMATE(SALES,MEAN,QTR_ROLL,"&Q2&",NOW,,,'')")} -> 994 | R10: {=_xll.FDS("INTU-US","FE_ESTIMATE(SALES,MEAN,QTR_ROLL,"&R2&",NOW,,,'')")} -> 1165 | S10: {=_xll.FDS("INTU-US","FE_ESTIMATE(SALES,MEAN,QTR_ROLL,"&S2&",NOW,,,'')")} -> 1697.26 | T10: {=_xll.FDS("INTU-US","FE_ESTIMATE(SALES,MEAN,QTR_ROLL,"&T2&",NOW,,,'')")} -> 3002 | U10: {=_xll.FDS("INTU-US","FE_ESTIMATE(SALES,MEAN,QTR_ROLL,"&U2&",NOW,,,'')")} -> 1816 | ... BA10: {=_xll.FDS("INTU-US","FE_ESTIMATE(SALES,MEAN,QTR_ROLL,"&BA2&",NOW,,,'')")} -> 5422.1494 | BG10: =SUM(N10:Q10) -> 6784 | BH10: =+SUM(R10:U10) -> 7680.26 | BI10: =SUM(V10:Y10) -> 9633 | BJ10: =+SUM(Z10:AC10) -> 12726 | BK10: =+SUM(AD10:AG10) -> 14368 | BL10: =+SUM(AH10:AK10) -> 16285 | BM10: =+SUM(AL10:AO10) -> 18831 | BN10: =+SUM(AP10:AS10) -> 21180.996 | BO10: =+SUM(AT10:AW10) -> 23751.232 | BP10: =+SUM(AX10:BA10) -> 26404.916
A12: Cost of revenue
A13: Cost of Product Revenue | B13: =+B112 -> 29 | C13: =+C112 -> 40 | D13: =+D112 -> 30 | E13: =+E112 -> 32 | F13: =+F112 -> 29 | G13: =+G112 -> 37 | H13: =+H112 -> 29 | I13: =+I112 -> 25 | ... AQ13: =+AQ112 -> 18 | AR13: =+AR7*(1-AR94) -> 19.082807 | AS13: =+AS7*(1-AS94) -> 16.903711 | AT13: =+AT7*(1-AT94) -> 16.032485 | AU13: =+AU7*(1-AU94) -> 19.237959 | AV13: =+AV7*(1-AV94) -> 20.203133 | AW13: =+AW7*(1-AW94) -> 17.920396 | AX13: =+AX7*(1-AX94) -> 16.785895 | AY13: =+AY7*(1-AY94) -> 20.408013 | ... BA13: =+BA7*(1-BA94) -> 19.10328 | BD13: =+SUM(B13:E13) -> 131 | BE13: =+SUM(F13:I13) -> 120 | BF13: =+SUM(J13:M13) -> 82 | BG13: =SUM(N13:Q13) -> 77 | BH13: =+SUM(R13:U13) -> 72 | BI13: =SUM(V13:Y13) -> 69 | BJ13: =+SUM(Z13:AC13) -> 69 | BK13: =+SUM(AD13:AG13) -> 71 | BL13: =+SUM(AH13:AK13) -> 69 | BM13: =+SUM(AL13:AO13) -> 68 | BN13: =+SUM(AP13:AS13) -> 68.986518 | BO13: =+SUM(AT13:AW13) -> 73.393973 | BP13: =+SUM(AX13:BA13) -> 77.691225
A14: Cost of Service and Other Revenue | B14: =+B113-B146 -> 129 | C14: =+C113-C146 -> 151 | D14: =+D113-D146 -> 179 | E14: =+E113-E146 -> 132 | F14: =+F113-F146 -> 149 | G14: =+G113-G146 -> 164 | H14: =+H113-H146 -> 203 | I14: =+I113-I146 -> 153 | ... AQ14: =+AQ113-AQ146 -> 887 | AR14: =+AR8*(1-AR95) -> 1139.266 | AS14: =+AS8*(1-AS95) -> 820.11579 | AT14: =+AT8*(1-AT95) -> 832.10537 | AU14: =+AU8*(1-AU95) -> 1023.6911 | AV14: =+AV8*(1-AV95) -> 1253.2087 | AW14: =+AW8*(1-AW95) -> 922.24502 | AX14: =+AX8*(1-AX95) -> 944.7039 | AY14: =+AY8*(1-AY95) -> 1177.4226 | ... BA14: =+BA8*(1-BA95) -> 1044.1844 | BD14: =+SUM(B14:E14) -> 591 | BE14: =+SUM(F14:I14) -> 669 | BF14: =+SUM(J14:M14) -> 838 | BG14: =SUM(N14:Q14) -> 1012 | BH14: =+SUM(R14:U14) -> 1224 | BI14: =SUM(V14:Y14) -> 1495 | BJ14: =+SUM(Z14:AC14) -> 2051 | BK14: =+SUM(AD14:AG14) -> 2535 | BL14: =+SUM(AH14:AK14) -> 2848 | BM14: =+SUM(AL14:AO14) -> 3201 | BN14: =+SUM(AP14:AS14) -> 3573.3818 | BO14: =+SUM(AT14:AW14) -> 4031.2501 | BP14: =+SUM(AX14:BA14) -> 4550.7667
A15: Total Cost of Revenue | B15: =+SUM(B13:B14) -> 158 | C15: =+SUM(C13:C14) -> 191 | D15: =+SUM(D13:D14) -> 209 | E15: =+SUM(E13:E14) -> 164 | F15: =+SUM(F13:F14) -> 178 | G15: =+SUM(G13:G14) -> 201 | H15: =+SUM(H13:H14) -> 232 | I15: =+SUM(I13:I14) -> 178 | ... BA15: =+SUM(BA13:BA14) -> 1063.2877 | BD15: =+SUM(B15:E15) -> 722 | BE15: =+SUM(F15:I15) -> 789 | BF15: =+SUM(J15:M15) -> 920 | BG15: =SUM(N15:Q15) -> 1089 | BH15: =+SUM(R15:U15) -> 1296 | BI15: =SUM(V15:Y15) -> 1564 | BJ15: =+SUM(Z15:AC15) -> 2120 | BK15: =+SUM(AD15:AG15) -> 2606 | BL15: =+SUM(AH15:AK15) -> 2917 | BM15: =+SUM(AL15:AO15) -> 3269 | BN15: =+SUM(AP15:AS15) -> 3642.3683 | BO15: =+SUM(AT15:AW15) -> 4104.6441 | BP15: =+SUM(AX15:BA15) -> 4628.458
A16: Gross Profit | B16: =+B9-B15 -> 555 | C16: =+C9-C15 -> 732 | D16: =+D9-D15 -> 2095 | E16: =+E9-E15 -> 590 | F16: =+F9-F15 -> 600 | G16: =+G9-G15 -> 815 | H16: =+H9-H15 -> 2309 | I16: =+I9-I15 -> 664 | ... BA16: =+BA9-BA15 -> 4269.5847 | BD16: =+SUM(B16:E16) -> 3972 | BE16: =+SUM(F16:I16) -> 4388 | BF16: =+SUM(J16:M16) -> 5105 | BG16: =SUM(N16:Q16) -> 5695 | BH16: =+SUM(R16:U16) -> 6383 | BI16: =SUM(V16:Y16) -> 8069 | BJ16: =+SUM(Z16:AC16) -> 10606 | BK16: =+SUM(AD16:AG16) -> 11762 | BL16: =+SUM(AH16:AK16) -> 13368 | BM16: =+SUM(AL16:AO16) -> 15562 | BN16: =+SUM(AP16:AS16) -> 17634.829 | BO16: =+SUM(AT16:AW16) -> 19662.693 | BP16: =+SUM(AX16:BA16) -> 21943.254
A17: Consensus gross profit | N17: {=_xll.FDS("INTU-US","FE_ESTIMATE(GROSS_INC,MEAN,QTR_ROLL,"&N2&",NOW,,,'')")} -> 785.2857 | O17: {=_xll.FDS("INTU-US","FE_ESTIMATE(GROSS_INC,MEAN,QTR_ROLL,"&O2&",NOW,,,'')")} -> 1232 | P17: {=_xll.FDS("INTU-US","FE_ESTIMATE(GROSS_INC,MEAN,QTR_ROLL,"&P2&",NOW,,,'')")} -> 2935.1428 | Q17: {=_xll.FDS("INTU-US","FE_ESTIMATE(GROSS_INC,MEAN,QTR_ROLL,"&Q2&",NOW,,,'')")} -> 732 | R17: {=_xll.FDS("INTU-US","FE_ESTIMATE(GROSS_INC,MEAN,QTR_ROLL,"&R2&",NOW,,,'')")} -> 893 | S17: {=_xll.FDS("INTU-US","FE_ESTIMATE(GROSS_INC,MEAN,QTR_ROLL,"&S2&",NOW,,,'')")} -> 1370.8889 | T17: {=_xll.FDS("INTU-US","FE_ESTIMATE(GROSS_INC,MEAN,QTR_ROLL,"&T2&",NOW,,,'')")} -> 2590.2856 | U17: {=_xll.FDS("INTU-US","FE_ESTIMATE(GROSS_INC,MEAN,QTR_ROLL,"&U2&",NOW,,,'')")} -> 1509.8 | ... BA17: {=_xll.FDS("INTU-US","FE_ESTIMATE(GROSS_INC,MEAN,QTR_ROLL,"&BA2&",NOW,,,'')")} -> 4196.5 | BD17: =+SUM(B17:E17) -> 0 | BE17: =+SUM(F17:I17) -> 0 | BF17: =+SUM(J17:M17) -> 0 | BG17: =SUM(N17:Q17) -> 5684.4285 | BH17: =+SUM(R17:U17) -> 6363.9745 | BI17: =SUM(V17:Y17) -> 8041.3778 | BJ17: =+SUM(Z17:AC17) -> 10533.096 | BK17: =+SUM(AD17:AG17) -> 11621.468 | BL17: =+SUM(AH17:AK17) -> 13265.397 | BM17: =+SUM(AI17:AL17) -> 13533.468 | BN17: =+SUM(AJ17:AP17) -> 26942.214 | BO17: =+SUM(AK17:AT17) -> 39059.374 | BP17: =+SUM(AL17:AX17) -> 56552.509
A19: Operating Expenses
A20: Selling and marketing | B20: =+B119-B147-B155 -> 225 | C20: =+C119-C147-C155 -> 338 | D20: =+D119-D147-D155 -> 405 | E20: =+E119-E147-E155 -> 244 | F20: =+F119-F147-F155 -> 258 | G20: =+G119-G147-G155 -> 383 | H20: =+H119-H147-H155 -> 448 | I20: =+I119-I147-I155 -> 243 | ... AQ20: =+AQ119-AQ147-AQ155 -> 1245 | AR20: =+AR$9*AR97 -> 1733.9771 | AS20: =+AS$9*AS97 -> 1181.3191 | AT20: =+AT$9*AT97 -> 1039.6232 | AU20: =+AU$9*AU97 -> 1397.8687 | AV20: =+AV$9*AV97 -> 1853.8807 | AW20: =+AW$9*AW97 -> 1323.9873 | AX20: =+AX$9*AX97 -> 1161.7301 | AY20: =+AY$9*AY97 -> 1576.1365 | ... BA20: =+BA$9*BA97 -> 1461.207 | BD20: =+SUM(B20:E20) -> 1212 | BE20: =+SUM(F20:I20) -> 1332 | BF20: =+SUM(J20:M20) -> 1530 | BG20: =SUM(N20:Q20) -> 1824 | BH20: =+SUM(R20:U20) -> 1932 | BI20: =SUM(V20:Y20) -> 2461 | BJ20: =+SUM(Z20:AC20) -> 3217 | BK20: =+SUM(AD20:AG20) -> 3333 | BL20: =+SUM(AH20:AK20) -> 3806 | BM20: =+SUM(AL20:AO20) -> 4494 | BN20: =+SUM(AP20:AS20) -> 5086.2962 | BO20: =+SUM(AT20:AW20) -> 5615.3598 | BP20: =+SUM(AX20:BA20) -> 6220.6664
A21: Research and development | B21: =+B120-B148-B156 -> 192 | C21: =+C120-C148-C156 -> 184 | D21: =+D120-D148-D156 -> 207 | E21: =+E120-E148-E156 -> 208 | F21: =+F120-F148-F156 -> 210 | G21: =+G120-G148-G156 -> 214 | H21: =+H120-H148-H156 -> 222 | I21: =+I120-I148-I156 -> 230 | ... AQ21: =+AQ120-AQ148-AQ156 -> 658 | AR21: =+AR$9*AR98 -> 620.44506 | AS21: =+AS$9*AS98 -> 670.13017 | AT21: =+AT$9*AT98 -> 739.32072 | AU21: =+AU$9*AU98 -> 739.39788 | AV21: =+AV$9*AV98 -> 661.38627 | AW21: =+AW$9*AW98 -> 738.30214 | AX21: =+AX$9*AX98 -> 823.28005 | AY21: =+AY$9*AY98 -> 828.01772 | ... BA21: =+BA$9*BA98 -> 819.02396 | BD21: =+SUM(B21:E21) -> 791 | BE21: =+SUM(F21:I21) -> 876 | BF21: =+SUM(J21:M21) -> 1053 | BG21: =SUM(N21:Q21) -> 1097 | BH21: =+SUM(R21:U21) -> 1241 | BI21: =SUM(V21:Y21) -> 1397 | BJ21: =+SUM(Z21:AC21) -> 1826 | BK21: =+SUM(AD21:AG21) -> 2007 | BL21: =+SUM(AH21:AK21) -> 2115 | BM21: =+SUM(AL21:AO21) -> 2299 | BN21: =+SUM(AP21:AS21) -> 2606.5752 | BO21: =+SUM(AT21:AW21) -> 2878.407 | BP21: =+SUM(AX21:BA21) -> 3177.6399
A22: General and administrative | B22: =+B121-B149-B157-B162 -> 92 | C22: =+C121-C149-C157-C162 -> 96 | D22: =+D121-D149-D157-D162 -> 124 | E22: =+E121-E149-E157-E162 -> 102 | F22: =+F121-F149-F157-F162 -> 100 | G22: =+G121-G149-G157-G162 -> 112 | H22: =+H121-H149-H157-H162 -> 120 | I22: =+I121-I149-I157-I162 -> 113 | ... AQ22: =+AQ121-AQ149-AQ157-AQ162 -> 294 | AR22: =+AR$9*AR99 -> 347.85621 | AS22: =+AS$9*AS99 -> 335.61234 | AT22: =+AT$9*AT99 -> 333.40666 | AU22: =+AU$9*AU99 -> 324.504 | AV22: =+AV$9*AV99 -> 362.63547 | AW22: =+AW$9*AW99 -> 365.01628 | AX22: =+AX$9*AX99 -> 365.80258 | AY22: =+AY$9*AY99 -> 356.63778 | ... BA22: =+BA$9*BA99 -> 399.5325 | BD22: =+SUM(B22:E22) -> 414 | BE22: =+SUM(F22:I22) -> 445 | BF22: =+SUM(J22:M22) -> 478 | BG22: =SUM(N22:Q22) -> 492 | BH22: =+SUM(R22:U22) -> 542 | BI22: =SUM(V22:Y22) -> 726 | BJ22: =+SUM(Z22:AC22) -> 1059 | BK22: =+SUM(AD22:AG22) -> 919 | BL22: =+SUM(AH22:AK22) -> 1045 | BM22: =+SUM(AL22:AO22) -> 1197 | BN22: =+SUM(AP22:AS22) -> 1278.4686 | BO22: =+SUM(AT22:AW22) -> 1385.5624 | BP22: =+SUM(AX22:BA22) -> 1500.5441
A23: Total Operating Expenses | B23: =+SUM(B20:B22) -> 509 | C23: =+SUM(C20:C22) -> 618 | D23: =+SUM(D20:D22) -> 736 | E23: =+SUM(E20:E22) -> 554 | F23: =+SUM(F20:F22) -> 568 | G23: =+SUM(G20:G22) -> 709 | H23: =+SUM(H20:H22) -> 790 | I23: =+SUM(I20:I22) -> 586 | ... BA23: =+SUM(BA20:BA22) -> 2679.7635 | BD23: =+SUM(B23:E23) -> 2417 | BE23: =+SUM(F23:I23) -> 2653 | BF23: =+SUM(J23:M23) -> 3061 | BG23: =SUM(N23:Q23) -> 3413 | BH23: =+SUM(R23:U23) -> 3715 | BI23: =SUM(V23:Y23) -> 4584 | BJ23: =+SUM(Z23:AC23) -> 6102 | BK23: =+SUM(AD23:AG23) -> 6259 | BL23: =+SUM(AH23:AK23) -> 6966 | BM23: =+SUM(AL23:AO23) -> 7990 | BN23: =+SUM(AP23:AS23) -> 8971.34 | BO23: =+SUM(AT23:AW23) -> 9879.3293 | BP23: =+SUM(AX23:BA23) -> 10898.85
A24: Operating Income | B24: =+B16-B23 -> 46 | C24: =+C16-C23 -> 114 | D24: =+D16-D23 -> 1359 | E24: =+E16-E23 -> 36 | F24: =+F16-F23 -> 32 | G24: =+G16-G23 -> 106 | H24: =+H16-H23 -> 1519 | I24: =+I16-I23 -> 78 | ... BA24: =+BA16-BA23 -> 1589.8212 | BD24: =+SUM(B24:E24) -> 1555 | BE24: =+SUM(F24:I24) -> 1735 | BF24: =+SUM(J24:M24) -> 2044 | BG24: =SUM(N24:Q24) -> 2282 | BH24: =+SUM(R24:U24) -> 2668 | BI24: =SUM(V24:Y24) -> 3485 | BJ24: =+SUM(Z24:AC24) -> 4504 | BK24: =+SUM(AD24:AG24) -> 5503 | BL24: =+SUM(AH24:AK24) -> 6402 | BM24: =+SUM(AL24:AO24) -> 7572 | BN24: =+SUM(AP24:AS24) -> 8663.4892 | BO24: =+SUM(AT24:AW24) -> 9783.3637 | BP24: =+SUM(AX24:BA24) -> 11044.404
A25: Consensus non-GAAP operating income | N25: {=_xll.FDS("INTU-US","FE_ESTIMATE(EBIT,MEAN,QTR_ROLL,"&N2&",NOW,,,'')")} -> 102 | O25: {=_xll.FDS("INTU-US","FE_ESTIMATE(EBIT,MEAN,QTR_ROLL,"&O2&",NOW,,,'')")} -> 339 | P25: {=_xll.FDS("INTU-US","FE_ESTIMATE(EBIT,MEAN,QTR_ROLL,"&P2&",NOW,,,'')")} -> 1888 | Q25: {=_xll.FDS("INTU-US","FE_ESTIMATE(EBIT,MEAN,QTR_ROLL,"&Q2&",NOW,,,'')")} -> -47 | R25: {=_xll.FDS("INTU-US","FE_ESTIMATE(EBIT,MEAN,QTR_ROLL,"&R2&",NOW,,,'')")} -> 129 | S25: {=_xll.FDS("INTU-US","FE_ESTIMATE(EBIT,MEAN,QTR_ROLL,"&S2&",NOW,,,'')")} -> 383.92307 | T25: {=_xll.FDS("INTU-US","FE_ESTIMATE(EBIT,MEAN,QTR_ROLL,"&T2&",NOW,,,'')")} -> 1539 | U25: {=_xll.FDS("INTU-US","FE_ESTIMATE(EBIT,MEAN,QTR_ROLL,"&U2&",NOW,,,'')")} -> 616 | ... BA25: {=_xll.FDS("INTU-US","FE_ESTIMATE(EBIT,MEAN,QTR_ROLL,"&BA2&",NOW,,,'')")} -> 1589.6897 | BD25: =+SUM(B25:E25) -> 0 | BE25: =+SUM(F25:I25) -> 0 | BF25: =+SUM(J25:M25) -> 0 | BG25: =SUM(N25:Q25) -> 2282 | BH25: =+SUM(R25:U25) -> 2667.9231 | BI25: =SUM(V25:Y25) -> 3485 | BJ25: =+SUM(Z25:AC25) -> 4504 | BK25: =+SUM(AD25:AG25) -> 5503 | BL25: =+SUM(AH25:AK25) -> 6402 | BM25: =+SUM(AL25:AO25) -> 7572 | BN25: =+SUM(AP25:AS25) -> 8668.6563 | BO25: =+SUM(AT25:AW25) -> 9854.9521 | BP25: =+SUM(AX25:BA25) -> 10946.017
A26: Adjusted EBITDA | B26: =+B24+'Cash Flow'!B7+'Cash Flow'!B8 -> 101 | C26: =+C24+'Cash Flow'!C7+'Cash Flow'!C8 -> 172 | D26: =+D24+'Cash Flow'!D7+'Cash Flow'!D8 -> 1421 | E26: =+E24+'Cash Flow'!E7+'Cash Flow'!E8 -> 99 | F26: =+F24+'Cash Flow'!F7+'Cash Flow'!F8 -> 87 | G26: =+G24+'Cash Flow'!G7+'Cash Flow'!G8 -> 163 | H26: =+H24+'Cash Flow'!H7+'Cash Flow'!H8 -> 1581 | I26: =+I24+'Cash Flow'!I7+'Cash Flow'!I8 -> 140 | ... AS26: =+AS24+'Cash Flow'!AS7+'Cash Flow'!AS8 -> 1441.2788 | AT26: =+AT24+'Cash Flow'!BB7+'Cash Flow'!BB8 -> 1456.8116 | AU26: =+AU24+'Cash Flow'!BC7+'Cash Flow'!BC8 -> 1796.5955 | AV26: =+AV24+'Cash Flow'!BD7+'Cash Flow'!BD8 -> 5389.9535 | AW26: =+AW24+'Cash Flow'!BE7+'Cash Flow'!BE8 -> 1614.0031 | AX26: =+AX24+'Cash Flow'!BF7+'Cash Flow'!BF8 -> 1919.1288 | AY26: =+AY24+'Cash Flow'!BG7+'Cash Flow'!BG8 -> 2289.4217 | AZ26: =+AZ24+'Cash Flow'!BH7+'Cash Flow'!BH8 -> 5942.0323 | BA26: =+BA24+'Cash Flow'!BI7+'Cash Flow'!BI8 -> 1952.8212 | BD26: =+SUM(B26:E26) -> 1793 | BE26: =+SUM(F26:I26) -> 1971 | BF26: =+SUM(J26:M26) -> 2297 | BG26: =SUM(N26:Q26) -> 2507 | BH26: =+SUM(R26:U26) -> 2886 | BI26: =SUM(V26:Y26) -> 3848 | BJ26: =+SUM(Z26:AC26) -> 5250 | BK26: =+SUM(AD26:AG26) -> 6309 | BL26: =+SUM(AH26:AK26) -> 7191 | BM26: =+SUM(AL26:AO26) -> 8381 | BN26: =+SUM(AP26:AS26) -> 9506.2953 | BO26: =+SUM(AT26:AW26) -> 10257.364 | BP26: =+SUM(AX26:BA26) -> 12103.404
BJ27: =+(BJ24/BI24)-1 -> 0.29239598 | BK27: =+(BK24/BJ24)-1 -> 0.22180284
A28: Interest expense | B28: =+B127+B164+B165 -> -6 | C28: =+C127+C164+C165 -> -8 | D28: =+D127+D164+D165 -> -8 | E28: =+E127+E164+E165 -> -8 | F28: =+F127+F164+F165 -> -8 | G28: =+G127+G164+G165 -> -5 | H28: =+H127+H164+H165 -> -7 | I28: =+I127+I164+I165 -> -2 | ... AQ28: =+AQ127+AQ164+AQ165 -> -95 | AR28: =+AN28-50 -> -109 | AS28: =+AO28-20 -> -101 | AT28: =+AP28 -> -107 | AU28: =+AQ28 -> -95 | AV28: =+AR28 -> -109 | AW28: =+AS28 -> -101 | AX28: =+AT28 -> -107 | AY28: =+AU28 -> -95 | AZ28: =+AV28 -> -109 | BA28: =+AW28 -> -101 | BD28: =+SUM(B28:E28) -> -30 | BE28: =+SUM(F28:I28) -> -22 | BF28: =+SUM(J28:M28) -> -22 | BG28: =SUM(N28:Q28) -> -9 | BH28: =+SUM(R28:U28) -> -9 | BI28: =SUM(V28:Y28) -> -74 | BJ28: =+SUM(Z28:AC28) -> -130 | BK28: =+SUM(AD28:AG28) -> -231 | BL28: =+SUM(AH28:AK28) -> -233 | BM28: =+SUM(AL28:AO28) -> -226 | BN28: =+SUM(AP28:AS28) -> -412 | BO28: =+SUM(AT28:AW28) -> -412 | BP28: =+SUM(AX28:BA28) -> -412
A29: Other income (expense), net | B29: =+B128 -> -4 | C29: =+C128 -> -5 | D29: =+D128 -> 2 | E29: =+E128 -> 3 | F29: =+F128 -> -2 | G29: =+G128 -> -1 | H29: =+H128 -> 3 | I29: =+I128 -> 3 | ... AQ29: =+AQ128 -> 72 | AR29: =+AN29 -> 32 | AS29: =+AO29-40 -> 46 | AT29: =+AP29 -> 85 | AU29: =+AQ29 -> 72 | AV29: =+AR29 -> 32 | AW29: =+AS29 -> 46 | AX29: =+AT29 -> 85 | AY29: =+AU29 -> 72 | AZ29: =+AV29 -> 32 | BA29: =+AW29 -> 46 | BD29: =+SUM(B29:E29) -> -4 | BE29: =+SUM(F29:I29) -> 3 | BF29: =+SUM(J29:M29) -> 26 | BG29: =SUM(N29:Q29) -> 42 | BH29: =+SUM(R29:U29) -> 36 | BI29: =SUM(V29:Y29) -> 85 | BJ29: =+SUM(Z29:AC29) -> 52 | BK29: =+SUM(AD29:AG29) -> 96 | BL29: =+SUM(AH29:AK29) -> 162 | BM29: =+SUM(AL29:AO29) -> 158 | BN29: =+SUM(AP29:AS29) -> 235 | BO29: =+SUM(AT29:AW29) -> 235 | BP29: =+SUM(AX29:BA29) -> 235
A30: Pre-tax income | B30: =+B24+SUM(B28:B29) -> 36 | C30: =+C24+SUM(C28:C29) -> 101 | D30: =+D24+SUM(D28:D29) -> 1353 | E30: =+E24+SUM(E28:E29) -> 31 | F30: =+F24+SUM(F28:F29) -> 22 | G30: =+G24+SUM(G28:G29) -> 100 | H30: =+H24+SUM(H28:H29) -> 1515 | I30: =+I24+SUM(I28:I29) -> 79 | ... BA30: =+BA24+SUM(BA28:BA29) -> 1534.8212 | BD30: =+SUM(B30:E30) -> 1521 | BE30: =+SUM(F30:I30) -> 1716 | BF30: =+SUM(J30:M30) -> 2048 | BG30: =SUM(N30:Q30) -> 2315 | BH30: =+SUM(R30:U30) -> 2695 | BI30: =SUM(V30:Y30) -> 3496 | BJ30: =+SUM(Z30:AC30) -> 4426 | BK30: =+SUM(AD30:AG30) -> 5368 | BL30: =+SUM(AH30:AK30) -> 6331 | BM30: =+SUM(AL30:AO30) -> 7504 | BN30: =+SUM(AP30:AS30) -> 8486.4892 | BO30: =+SUM(AT30:AW30) -> 9606.3637 | BP30: =+SUM(AX30:BA30) -> 10867.404
A31: Income Taxes | B31: =+B130+B166 -> 12 | C31: =+C130+C166 -> 34 | D31: =+D130+D166 -> 460 | E31: =+E130+E166 -> 11 | F31: =+F130+F166 -> 7 | G31: =+G130+G166 -> 33 | H31: =+H130+H166 -> 500 | I31: =+I130+I166 -> 26 | ... AQ31: =+AQ130+AQ166 -> 366 | AR31: =+AR30*AR32 -> 1057.3785 | AS31: =+AS30*AS32 -> 272.66497 | AT31: =+AT30*AT32 -> 340.54209 | AU31: =+AU30*AU32 -> 420.95 | AV31: =+AV30*AV32 -> 1204.5033 | AW31: =+AW30*AW32 -> 314.00516 | AX31: =+AX30*AX32 -> 390.22202 | AY31: =+AY30*AY32 -> 484.51659 | ... BA31: =+BA30*BA32 -> 364.27865 | BD31: =+SUM(B31:E31) -> 517 | BE31: =+SUM(F31:I31) -> 566 | BF31: =+SUM(J31:M31) -> 537 | BG31: =SUM(N31:Q31) -> 533 | BH31: =+SUM(R31:U31) -> 620 | BI31: =SUM(V31:Y31) -> 839 | BJ31: =+SUM(Z31:AC31) -> 1061 | BK31: =+SUM(AD31:AG31) -> 1288 | BL31: =+SUM(AH31:AK31) -> 1520 | BM31: =+SUM(AL31:AO31) -> 1801 | BN31: =+SUM(AP31:AS31) -> 1993.0434 | BO31: =+SUM(AT31:AW31) -> 2280.0006 | BP31: =+SUM(AX31:BA31) -> 2579.2993
A32: Tax rate (GAAP) | B32: =+B31/B30 -> 0.33333333 | C32: =+C31/C30 -> 0.33663366 | D32: =+D31/D30 -> 0.33998522 | E32: =+E31/E30 -> 0.35483871 | F32: =+F31/F30 -> 0.31818182 | G32: =+G31/G30 -> 0.33 | H32: =+H31/H30 -> 0.330033 | I32: =+I31/I30 -> 0.32911392 | ... AQ32: =+AQ31/AQ30 -> 0.23984273 | AR32: =+AQ32-0.75% -> 0.23234273 | AS32: =+AR32 -> 0.23234273 | AT32: =+AS32+0.5% -> 0.23734273 | AU32: =+AT32 -> 0.23734273 | AV32: =+AU32 -> 0.23734273 | AW32: =+AV32 -> 0.23734273 | AX32: =+AW32 -> 0.23734273 | AY32: =+AX32 -> 0.23734273 | AZ32: =+AY32 -> 0.23734273 | BA32: =+AZ32 -> 0.23734273 | BD32: =+BD31/BD30 -> 0.33990796 | BE32: =+BE31/BE30 -> 0.32983683 | BF32: =+BF31/BF30 -> 0.26220703 | BG32: =+BG31/BG30 -> 0.23023758 | BH32: =+BH31/BH30 -> 0.23005566 | BI32: =+BI31/BI30 -> 0.23998856 | BJ32: =+BJ31/BJ30 -> 0.23971984 | BK32: =+BK31/BK30 -> 0.23994039 | ... BP32: =+BP31/BP30 -> 0.23734273
A33: Net income (loss) | B33: =+B30-B31 -> 24 | C33: =+C30-C31 -> 67 | D33: =+D30-D31 -> 893 | E33: =+E30-E31 -> 20 | F33: =+F30-F31 -> 15 | G33: =+G30-G31 -> 67 | H33: =+H30-H31 -> 1015 | I33: =+I30-I31 -> 53 | ... BA33: =+BA30-BA31 -> 1170.5426 | BD33: =+SUM(B33:E33) -> 1004 | BE33: =+SUM(F33:I33) -> 1150 | BF33: =+SUM(J33:M33) -> 1511 | BG33: =SUM(N33:Q33) -> 1782 | BH33: =+SUM(R33:U33) -> 2075 | BI33: =SUM(V33:Y33) -> 2657 | BJ33: =+SUM(Z33:AC33) -> 3365 | BK33: =+SUM(AD33:AG33) -> 4080 | BL33: =+SUM(AH33:AK33) -> 4811 | BM33: =+SUM(AL33:AO33) -> 5703 | BN33: =+SUM(AP33:AS33) -> 6493.4458 | BO33: =+SUM(AT33:AW33) -> 7326.3632 | BP33: =+SUM(AX33:BA33) -> 8288.1047
A35: Non-GAAP EPS | B35: =B33/B37 -> 0.088235294 | C35: =C33/C37 -> 0.2518797 | D35: =D33/D37 -> 3.4346154 | E35: =E33/E37 -> 0.076923077 | F35: =F33/F37 -> 0.058139535 | G35: =G33/G37 -> 0.25769231 | H35: =H33/H37 -> 3.9038462 | I35: =I33/I37 -> 0.20384615 | ... X35: =X33/X37 -> 6.0797101 | Y35: 1.97 | Z35: =Z33/Z37 -> 1.5270758 | AA35: =AA33/AA37 -> 1.554007 | AB35: =AB33/AB37 -> 7.6398601 | AC35: =AC33/AC37 -> 1.1028369 | AD35: =AD33/AD37 -> 1.6560958 | AE35: =AE33/AE37 -> 2.1954674 | AF35: =AF33/AF37 -> 8.9026112 | AG35: =AG33/AG37 -> 1.6493607 | ... BA35: =BA33/BA37 -> 4.1805092 | BD35: =+BD33/BD37 -> 3.7958412 | BE35: =+BE33/BE37 -> 4.4315992 | BF35: =+BF33/BF37 -> 5.8171319 | BG35: =+BG33/BG37 -> 6.7756654 | BH35: =+BH33/BH37 -> 7.8635718 | BI35: 9.67 | BJ35: =+SUM(Z35:AC35) -> 11.82378 | BK35: =+SUM(AD35:AG35) -> 14.403535 | BL35: =+SUM(AH35:AK35) -> 16.966271 | BM35: 20.15 | BN35: =+BN33/BN37 -> 23.188807 | BO35: =+BO33/BO37 -> 26.072467 | BP35: =+BP33/BP37 -> 29.600374 | BR35: =+BM35/BL35 -> 1.1876505 | BS35: =+BN35/BM35 -> 1.1508093
A36: Consensus non-GAAP EPS | N36: {=_xll.FDS("INTU-US","FE_ESTIMATE(EPS,MEAN,QTR_ROLL,"&N2&",NOW,,,'')")} -> 0.29 | O36: {=_xll.FDS("INTU-US","FE_ESTIMATE(EPS,MEAN,QTR_ROLL,"&O2&",NOW,,,'')")} -> 1 | P36: {=_xll.FDS("INTU-US","FE_ESTIMATE(EPS,MEAN,QTR_ROLL,"&P2&",NOW,,,'')")} -> 5.55 | Q36: {=_xll.FDS("INTU-US","FE_ESTIMATE(EPS,MEAN,QTR_ROLL,"&Q2&",NOW,,,'')")} -> -0.09 | R36: {=_xll.FDS("INTU-US","FE_ESTIMATE(EPS,MEAN,QTR_ROLL,"&R2&",NOW,,,'')")} -> 0.41 | S36: {=_xll.FDS("INTU-US","FE_ESTIMATE(EPS,MEAN,QTR_ROLL,"&S2&",NOW,,,'')")} -> 1.16 | T36: {=_xll.FDS("INTU-US","FE_ESTIMATE(EPS,MEAN,QTR_ROLL,"&T2&",NOW,,,'')")} -> 4.49 | U36: {=_xll.FDS("INTU-US","FE_ESTIMATE(EPS,MEAN,QTR_ROLL,"&U2&",NOW,,,'')")} -> 1.81 | ... BA36: {=_xll.FDS("INTU-US","FE_ESTIMATE(EPS,MEAN,QTR_ROLL,"&BA2&",NOW,,,'')")} -> 4.3006334 | BD36: =+SUM(B36:E36) -> 0 | BE36: =+SUM(F36:I36) -> 0 | BF36: =+SUM(J36:M36) -> 0 | BG36: =SUM(N36:Q36) -> 6.75 | BH36: =+SUM(R36:U36) -> 7.87 | BI36: =SUM(V36:Y36) -> 9.66 | BJ36: =+SUM(Z36:AC36) -> 11.83 | BK36: =+SUM(AD36:AG36) -> 14.43 | BL36: =+SUM(AH36:AK36) -> 16.97 | BM36: =+SUM(AL36:AO36) -> 20.22 | BN36: =+SUM(AP36:AS36) -> 23.142881 | BO36: =+SUM(AT36:AW36) -> 26.2979 | BP36: =+SUM(AX36:BA36) -> 29.418595
A37: Non-GAAP diluted shares outstanding | B37: =+B141 -> 272 | C37: =+C141 -> 266 | D37: =+D141 -> 260 | E37: =+E141 -> 260 | F37: =+F141 -> 258 | G37: =+G141 -> 260 | H37: =+H141 -> 260 | I37: =+I141 -> 260 | ... AQ37: =+AQ141 -> 279.7 | AR37: =+AQ37 -> 279.7 | AS37: =+AR37 -> 279.7 | AT37: 281 | AU37: =+AT37 -> 281 | AV37: =+AU37 -> 281 | AW37: =+AV37 -> 281 | AX37: 280 | AY37: =+AX37 -> 280 | AZ37: =+AY37 -> 280 | BA37: =+AZ37 -> 280 | BD37: =AVERAGE(B37:E37) -> 264.5 | BE37: =+AVERAGE(F37:I37) -> 259.5 | BF37: =+AVERAGE(J37:M37) -> 259.75 | BG37: =AVERAGE(N37:Q37) -> 263 | BH37: =+AVERAGE(R37:U37) -> 263.875 | BI37: =AVERAGE(V37:Y37) -> 272.75 | BJ37: =+AVERAGE(Z37:AC37) -> 283 | BK37: =+AVERAGE(AD37:AG37) -> 283.185 | BL37: =+AVERAGE(AH37:AK37) -> 283.425 | BM37: =+AVERAGE(AL37:AO37) -> 282.375 | BN37: =+AVERAGE(AP37:AS37) -> 280.025 | BO37: =+AVERAGE(AT37:AW37) -> 281 | BP37: =+AVERAGE(AX37:BA37) -> 280
AH38: =+AH35/AD35-1 -> 0.48930456 | AI38: =+AI35/AE35-1 -> 0.19644707 | AJ38: =+AJ35/AF35-1 -> 0.11020012 | AK38: =+AK35/AG35-1 -> 0.20616385 | AL38: =+AL35/AH35-1 -> 0.015759312 | AM38: =+AM35/AI35-1 -> 0.26181567 | AN38: =+AN35/AJ35-1 -> 0.17889947 | AO38: =+AO35/AK35-1 -> 0.38321807 | ... AQ38: =+AQ35/AM35-1 -> 0.25126449 | BD38: =+BD35/BC35 -> #DIV/0! | BE38: =+BE35/BD35 -> 1.167488 | BF38: =+BF35/BE35 -> 1.3126484 | BG38: =+BG35/BF35 -> 1.1647777 | BH38: =+BH35/BG35 -> 1.1605608 | BI38: =+BI35/BH35 -> 1.2297211 | BJ38: =+BJ35/BI35 -> 1.222728 | BK38: =+BK35/BJ35 -> 1.2181836 | BL38: =+BL35/BK35 -> 1.1779241
A39: Dividends per share | B39: 0.3 | C39: 0.3 | D39: 0.3 | E39: 0.3 | F39: 0.34 | G39: 0.34 | H39: 0.34 | I39: 0.34 | J39: 0.39 | K39: 0.39 | L39: 0.39 | M39: 0.39 | N39: 0.47 | O39: 0.47 | P39: 0.47 | Q39: 0.47 | R39: 0.53 | S39: 0.53 | T39: 0.53 | U39: 0.53 | V39: 0.59 | W39: 0.59 | X39: 0.59 | Y39: 0.59 | Z39: 0.68 | AA39: =+Z39 -> 0.68 | AB39: =+X39*(1+AB79) -> 0.68 | AC39: =+Y39*(1+AC79) -> 0.68 | AD39: 0.78 | AE39: =+AD39 -> 0.78 | AF39: =+AE39 -> 0.78 | AG39: =+AF39 -> 0.78 | AH39: 0.9 | AI39: =+AH39 -> 0.9 | AJ39: =+AF39*(1+AJ79) -> 0.9 | AK39: =+AG39*(1+AK79) -> 0.9 | AL39: 1.04 | AM39: =+AL39 -> 1.04 | AN39: 1.04 | AO39: 1.2 | AP39: 1.2 | AQ39: 1.2 | AR39: =+AN39*(1+AR79) -> 1.196 | AS39: =+AO39*(1+AS79) -> 1.38 | AT39: =+AP39*(1+AT79) -> 1.362 | AU39: =+AQ39*(1+AU79) -> 1.362 | AV39: =+AR39*(1+AV79) -> 1.35746 | AW39: =+AS39*(1+AW79) -> 1.5663 | AX39: =+AT39*(1+AX79) -> 1.54587 | AY39: =+AU39*(1+AY79) -> 1.54587 | ... BA39: =+AW39*(1+BA79) -> 1.7777505 | BD39: =+SUM(B39:E39) -> 1.2 | BE39: =+SUM(F39:I39) -> 1.36 | BF39: =+SUM(J39:M39) -> 1.56 | BG39: =SUM(N39:Q39) -> 1.88 | BH39: =+SUM(R39:U39) -> 2.12 | BI39: =SUM(V39:Y39) -> 2.36 | BJ39: =+SUM(Z39:AC39) -> 2.72 | BK39: =+SUM(AD39:AG39) -> 3.12 | BL39: =+SUM(AH39:AK39) -> 3.6 | BM39: =+SUM(AL39:AO39) -> 4.32 | BN39: =+SUM(AP39:AS39) -> 4.976 | BO39: =+SUM(AT39:AW39) -> 5.64776 | BP39: =+SUM(AX39:BA39) -> 6.4102076
A41: Non-GAAP Reconciliation
A42: Adjustments
A43: Share-based compensation | B43: =+B151 -> 67 | C43: =+C151 -> 65 | D43: =+D151 -> 65 | E43: =+E151 -> 81 | F43: =+F151 -> 89 | G43: =+G151 -> 81 | H43: =+H151 -> 71 | I43: =+I151 -> 85 | ... U43: =+U151 -> 114 | V43: =+SUM(V44:V45) -> 111 | W43: =+SUM(W44:W45) -> 180 | X43: =+SUM(X44:X45) -> 218 | Y43: =+SUM(Y44:Y45) -> 244 | Z43: =+SUM(Z44:Z45) -> 280 | AA43: =+SUM(AA44:AA45) -> 336 | AB43: =+SUM(AB44:AB45) -> 346 | AC43: =+SUM(AC44:AC45) -> 346 | ... BA43: =+SUM(BA44:BA45) -> 609.01235 | BD43: =+SUM(B43:E43) -> 278 | BE43: =+SUM(F43:I43) -> 326 | BF43: =+SUM(J43:M43) -> 382 | BG43: =SUM(N43:Q43) -> 401 | BH43: =+SUM(R43:U43) -> 435 | BI43: =SUM(V43:Y43) -> 753 | BJ43: =+SUM(Z43:AC43) -> 1308 | BK43: =+SUM(AD43:AG43) -> 1712 | BL43: =+SUM(AH43:AK43) -> 1915 | BM43: =+SUM(AL43:AO43) -> 1968 | BN43: =+SUM(AP43:AS43) -> 2182.5573 | BO43: =+SUM(AT43:AW43) -> 2247.6724 | BP43: =+SUM(AX43:BA43) -> 2318.7937
A44: Cost of revenue | B44: =+B146 -> 2 | C44: =+C146 -> 2 | D44: =+D146 -> 2 | E44: =+E146 -> 2 | F44: =+F146 -> 2 | G44: =+G146 -> 2 | H44: =+H146 -> 2 | I44: =+I146 -> 2 | ... AQ44: =+AQ146 -> 94 | AR44: =AN44/AN9*AR9*0.9 -> 99.511351 | AS44: =AO44/AO9*AS9*0.9 -> 100.90416 | AT44: =AP44/AP9*AT9 -> 110.29037 | AU44: =AQ44/AQ9*AU9 -> 107.14292 | AV44: =AR44/AR9*AV9 -> 109.06204 | AW44: =AS44/AS9*AW9 -> 112.59817 | AX44: =AT44/AT9*AX9 -> 124.3006 | AY44: =AU44/AU9*AY9 -> 121.72999 | AZ44: =AV44/AV9*AZ9 -> 120.01243 | BA44: =AW44/AW9*BA9 -> 126.53566 | BD44: =+SUM(B44:E44) -> 8 | BE44: =+SUM(F44:I44) -> 8 | BF44: =+SUM(J44:M44) -> 43 | BG44: =SUM(N44:Q44) -> 58 | BH44: =+SUM(R44:U44) -> 60 | BI44: =SUM(V44:Y44) -> 69 | BJ44: =+SUM(Z44:AC44) -> 146 | BK44: =+SUM(AD44:AG44) -> 374 | BL44: =+SUM(AH44:AK44) -> 402 | BM44: =+SUM(AL44:AO44) -> 423 | BN44: =+SUM(AP44:AS44) -> 391.41551 | BO44: =+SUM(AT44:AW44) -> 439.09351 | BP44: =+SUM(AX44:BA44) -> 492.57868
...

Sheet Revenue Build
A1: =+'Income Statement'!A1 -> Intuit, Inc.
A2: Revenue Build
B3: =+'Income Statement'!B3:E3 -> Fiscal 2016 | F3: =+'Income Statement'!F3:I3 -> Fiscal 2017 | J3: =+'Income Statement'!J3:M3 -> Fiscal 2018 | N3: =+'Income Statement'!N3:Q3 -> Fiscal 2019 | R3: =+'Income Statement'!R3:U3 -> Fiscal 2020 | V3: =+'Income Statement'!V3:Y3 -> Fiscal 2021 | Z3: =+'Income Statement'!Z3:AC3 -> Fiscal 2022 | AD3: =+'Income Statement'!AD3:AG3 -> Fiscal 2023 | AH3: =+'Income Statement'!AH3:AK3 -> Fiscal 2024 | AL3: =+'Income Statement'!AL3:AO3 -> Fiscal 2025 | AP3: =+'Income Statement'!AP3:AS3 -> Fiscal 2026 | AT3: =+'Income Statement'!AT3:AW3 -> Fiscal 2027 | AX3: =+'Income Statement'!AX3:BA3 -> Fiscal 2028
A4: ($ in millions, unless otherwise stated) | B4: =+'Income Statement'!B4 -> 42308 | C4: =+'Income Statement'!C4 -> 42400 | D4: =+'Income Statement'!D4 -> 42490 | E4: =+'Income Statement'!E4 -> 42582 | F4: =+'Income Statement'!F4 -> 42674 | G4: =+'Income Statement'!G4 -> 42766 | H4: =+'Income Statement'!H4 -> 42855 | I4: =+'Income Statement'!I4 -> 42947 | ... BA4: =+'Income Statement'!BA4 -> Jul-28E | BC4: =+'Income Statement'!BC4 -> FY15 | BD4: =+'Income Statement'!BD4 -> FY16 | BE4: =+'Income Statement'!BE4 -> FY17 | BF4: =+'Income Statement'!BF4 -> FY18 | BG4: =+'Income Statement'!BG4 -> FY19 | BH4: =+'Income Statement'!BH4 -> FY20 | BI4: =+'Income Statement'!BI4 -> FY21 | BJ4: =+'Income Statement'!BJ4 -> FY22 | ... BP4: =+'Income Statement'!BP4 -> FY28E
X5: 210.8 | Y5: 217.8
A6: Total Revenue | B6: =B13+B18 -> 713 | C6: =C13+C18 -> 923 | D6: =D13+D18 -> 2304 | E6: =E13+E18 -> 754 | F6: =F13+F18 -> 778 | G6: =G13+G18 -> 1016 | H6: =H13+H18 -> 2541 | I6: =I13+I18 -> 842 | ... BA6: =BA13+BA18 -> 5332.8724 | BD6: =SUM(B6:E6) -> 4694 | BE6: =SUM(F6:I6) -> 5177 | BF6: =SUM(J6:M6) -> 6025 | BG6: =SUM(N6:Q6) -> 6784 | BH6: =SUM(R6:U6) -> 7679 | BI6: =SUM(V6:Y6) -> 9633 | BJ6: =SUM(Z6:AC6) -> 12726 | BK6: =SUM(AD6:AG6) -> 14368 | BL6: =SUM(AH6:AK6) -> 16285 | BM6: =+BM24+BM178+BM207+BM202 -> 18831 | BN6: =SUM(AP6:AS6) -> 21277.197 | BO6: =SUM(AT6:AW6) -> 23767.337 | BP6: =SUM(AX6:BA6) -> 26571.712
A7: Y/Y Growth | B7: =IF(ISERROR(B6/#REF!-1),"NA",B6/#REF!-1) -> NA | C7: =IF(ISERROR(C6/#REF!-1),"NA",C6/#REF!-1) -> NA | D7: =IF(ISERROR(D6/#REF!-1),"NA",D6/#REF!-1) -> NA | E7: =IF(ISERROR(E6/A6-1),"NA",E6/A6-1) -> NA | F7: =IF(ISERROR(F6/B6-1),"NA",F6/B6-1) -> 0.091164095 | G7: =IF(ISERROR(G6/C6-1),"NA",G6/C6-1) -> 0.1007584 | H7: =IF(ISERROR(H6/D6-1),"NA",H6/D6-1) -> 0.10286458 | I7: =IF(ISERROR(I6/E6-1),"NA",I6/E6-1) -> 0.11671088 | J7: =IF(ISERROR(J6/F6-1),"NA",J6/F6-1) -> 0.16966581 | K7: =IF(ISERROR(K6/G6-1),"NA",K6/G6-1) -> 0.31791339 | L7: =IF(ISERROR(L6/H6-1),"NA",L6/H6-1) -> 0.14600551 | ... BA7: =IF(ISERROR(BA6/AW6-1),"NA",BA6/AW6-1) -> 0.1237807 | BD7: =IF(ISERROR(BD6/BC6-1),"NA",BD6/BC6-1) -> NA | BE7: =IF(ISERROR(BE6/BD6-1),"NA",BE6/BD6-1) -> 0.10289732 | BF7: =IF(ISERROR(BF6/BE6-1),"NA",BF6/BE6-1) -> 0.16380143 | BG7: =IF(ISERROR(BG6/BF6-1),"NA",BG6/BF6-1) -> 0.1259751 | BH7: =IF(ISERROR(BH6/BG6-1),"NA",BH6/BG6-1) -> 0.13192807 | BI7: =IF(ISERROR(BI6/BH6-1),"NA",BI6/BH6-1) -> 0.25446022 | BJ7: =IF(ISERROR(BJ6/BI6-1),"NA",BJ6/BI6-1) -> 0.32108377 | BK7: =IF(ISERROR(BK6/BJ6-1),"NA",BK6/BJ6-1) -> 0.12902719 | ... BP7: =IF(ISERROR(BP6/BO6-1),"NA",BP6/BO6-1) -> 0.11799283
A8: Y/Y Growth ($) | V8: =V6-R6 -> 158 | W8: =W6-S6 -> -120 | X8: =X6-T6 -> 1171 | Y8: =Y6-U6 -> 745 | Z8: =Z6-V6 -> 684 | AA8: =AA6-W6 -> 1097 | AB8: =AB6-X6 -> 1459 | AC8: =AC6-Y6 -> -147 | ... BA8: =BA6-AW6 -> 587.39813 | BJ8: =BJ6-BI6 -> 3093 | BK8: =BK6-BJ6 -> 1642 | BL8: =BL6-BK6 -> 1917 | BM8: =BM6-BL6 -> 2546 | BN8: =BN6-BM6 -> 2446.1975 | BO8: =BO6-BN6 -> 2490.1396 | BP8: =BP6-BO6 -> 2804.3753
A9: Q/Q Growth | B9: =IF(ISERROR(B6/A6-1),"NA",B6/A6-1) -> NA | C9: =IF(ISERROR(C6/B6-1),"NA",C6/B6-1) -> 0.29453015 | D9: =IF(ISERROR(D6/C6-1),"NA",D6/C6-1) -> 1.496208 | E9: =IF(ISERROR(E6/D6-1),"NA",E6/D6-1) -> -0.67274306 | F9: =IF(ISERROR(F6/E6-1),"NA",F6/E6-1) -> 0.031830239 | G9: =IF(ISERROR(G6/F6-1),"NA",G6/F6-1) -> 0.3059126 | H9: =IF(ISERROR(H6/G6-1),"NA",H6/G6-1) -> 1.5009843 | I9: =IF(ISERROR(I6/H6-1),"NA",I6/H6-1) -> -0.6686344 | ... BA9: =IF(ISERROR(BA6/AZ6-1),"NA",BA6/AZ6-1) -> -0.4790776 | BD9: NA | BE9: NA | BF9: NA | BG9: NA | BH9: NA | BI9: NA | BJ9: NA | BK9: NA | BL9: NA | BM9: NA | BN9: NA | BO9: NA | BP9: NA
A10: Q/Q Growth ($) | V10: =V6-U6 -> -493 | W10: =W6-V6 -> 253 | X10: =X6-W6 -> 2597 | Y10: =Y6-X6 -> -1612 | Z10: =Z6-Y6 -> -554 | AA10: =AA6-Z6 -> 666 | AB10: =AB6-AA6 -> 2959 | AC10: =AC6-AB6 -> -3218 | ... BA10: =BA6-AZ6 -> -4904.492 | BI10: N/A | BJ10: N/A | BK10: N/A | BL10: N/A | BM10: N/A | BN10: N/A | BO10: N/A | BP10: N/A
C11: 45761
A12: Revenue by Type
A13: Product Revenue | B13: 271 | C13: 264 | D13: 459 | E13: 295 | F13: 297 | G13: 299 | H13: 467 | I13: 313 | J13: =+J154+J185+J212 -> 370 | K13: =+K154+K185+K212 -> 529 | L13: =+L154+L185+L212 -> 479 | M13: =+M154+M185+M212 -> 246 | N13: =+N154+N185+N212 -> 347 | O13: =+O154+O185+O212 -> 533 | P13: =+P154+P185+P212 -> 498 | Q13: =+Q154+Q185+Q212 -> 245 | ... W13: =+W154+W185+W212 -> 495 | X13: =+X185+X212+X154 -> 533 | Y13: =+Y185+Y212+Y154 -> 314 | Z13: =+Z185+Z212+Z154 -> 410.56522 | AA13: =+AA185+AA212+AA154 -> 658.54466 | AB13: =+AB185+AB212+AB154 -> 674.48677 | AC13: =+AC185+AC212+AC154 -> 362.89554 | AD13: =+AD185+AD212+AD154 -> 543.97996 | AE13: =+AE185+AE212+AE154 -> 701.47606 | ... BA13: =+BA185+BA212+BA154 -> 644.78226 | BD13: =SUM(B13:E13) -> 1289 | BE13: =SUM(F13:I13) -> 1376 | BF13: =SUM(J13:M13) -> 1624 | BG13: =SUM(N13:Q13) -> 1623 | BH13: =SUM(R13:U13) -> 1635 | BI13: =SUM(V13:Y13) -> 1709 | BJ13: =SUM(Z13:AC13) -> 2106.4922 | BK13: =SUM(AD13:AG13) -> 2380.3345 | BL13: =SUM(AH13:AK13) -> 2484.0248 | BM13: =SUM(AL13:AO13) -> 2431.0061 | BN13: =SUM(AP13:AS13) -> 2566.9111 | BO13: =SUM(AT13:AW13) -> 2730.1957 | BP13: =SUM(AX13:BA13) -> 2892.0071
A14: Y/Y Growth | B14: =IF(ISERROR(B13/#REF!-1),"NA",B13/#REF!-1) -> NA | C14: =IF(ISERROR(C13/#REF!-1),"NA",C13/#REF!-1) -> NA | D14: =IF(ISERROR(D13/#REF!-1),"NA",D13/#REF!-1) -> NA | E14: =IF(ISERROR(E13/A13-1),"NA",E13/A13-1) -> NA | F14: =IF(ISERROR(F13/B13-1),"NA",F13/B13-1) -> 0.095940959 | G14: =IF(ISERROR(G13/C13-1),"NA",G13/C13-1) -> 0.13257576 | H14: =IF(ISERROR(H13/D13-1),"NA",H13/D13-1) -> 0.017429194 | I14: =IF(ISERROR(I13/E13-1),"NA",I13/E13-1) -> 0.061016949 | J14: =IF(ISERROR(J13/F13-1),"NA",J13/F13-1) -> 0.24579125 | K14: =IF(ISERROR(K13/G13-1),"NA",K13/G13-1) -> 0.76923077 | L14: =IF(ISERROR(L13/H13-1),"NA",L13/H13-1) -> 0.025695931 | ... BA14: =IF(ISERROR(BA13/AW13-1),"NA",BA13/AW13-1) -> 0.066007674 | BD14: =IF(ISERROR(BD13/BB13-1),"NA",BD13/BB13-1) -> NA | BE14: =IF(ISERROR(BE13/BD13-1),"NA",BE13/BD13-1) -> 0.067494182 | BF14: =IF(ISERROR(BF13/BE13-1),"NA",BF13/BE13-1) -> 0.18023256 | BG14: =IF(ISERROR(BG13/BF13-1),"NA",BG13/BF13-1) -> -0.00061576355 | BH14: =IF(ISERROR(BH13/BG13-1),"NA",BH13/BG13-1) -> 0.0073937153 | BI14: =IF(ISERROR(BI13/BH13-1),"NA",BI13/BH13-1) -> 0.045259939 | BJ14: =IF(ISERROR(BJ13/BI13-1),"NA",BJ13/BI13-1) -> 0.23258759 | BK14: =IF(ISERROR(BK13/BJ13-1),"NA",BK13/BJ13-1) -> 0.1299992 | BL14: =IF(ISERROR(BL13/BK13-1),"NA",BL13/BK13-1) -> 0.043561233 | ... BP14: =IF(ISERROR(BP13/BO13-1),"NA",BP13/BO13-1) -> 0.059267336
A15: Q/Q Growth | B15: =IF(ISERROR(B13/A13-1),"NA",B13/A13-1) -> NA | C15: =IF(ISERROR(C13/B13-1),"NA",C13/B13-1) -> -0.025830258 | D15: =IF(ISERROR(D13/C13-1),"NA",D13/C13-1) -> 0.73863636 | E15: =IF(ISERROR(E13/D13-1),"NA",E13/D13-1) -> -0.35729847 | F15: =IF(ISERROR(F13/E13-1),"NA",F13/E13-1) -> 0.006779661 | G15: =IF(ISERROR(G13/F13-1),"NA",G13/F13-1) -> 0.0067340067 | H15: =IF(ISERROR(H13/G13-1),"NA",H13/G13-1) -> 0.56187291 | I15: =IF(ISERROR(I13/H13-1),"NA",I13/H13-1) -> -0.32976445 | ... BA15: =IF(ISERROR(BA13/AZ13-1),"NA",BA13/AZ13-1) -> -0.30698564 | BD15: NA | BE15: NA | BF15: NA | BG15: NA | BH15: NA | BI15: NA | BJ15: NA | BK15: NA | BL15: NA | BM15: NA | BN15: NA | BO15: NA | BP15: NA
A16: % of total revenue | B16: =B13/B6 -> 0.38008415 | C16: =C13/C6 -> 0.28602384 | D16: =D13/D6 -> 0.19921875 | E16: =E13/E6 -> 0.39124668 | F16: =F13/F6 -> 0.38174807 | G16: =G13/G6 -> 0.29429134 | H16: =H13/H6 -> 0.18378591 | I16: =I13/I6 -> 0.37173397 | ... BA16: =BA13/BA6 -> 0.12090712 | BD16: =+BD13/BD$6 -> 0.27460588 | BE16: =+BE13/BE$6 -> 0.265791 | BF16: =+BF13/BF$6 -> 0.26954357 | BG16: =+BG13/BG$6 -> 0.23923939 | BH16: =+BH13/BH$6 -> 0.21291835 | BI16: =+BI13/BI$6 -> 0.17741098 | BJ16: =+BJ13/BJ$6 -> 0.16552665 | BK16: =+BK13/BK$6 -> 0.16566916 | ... BP16: =+BP13/BP$6 -> 0.10883782
BS17: total online payments 20%
A18: Service and Other Revenue | B18: 442 | C18: 659 | D18: 1845 | E18: 459 | F18: 481 | G18: 717 | H18: 2074 | I18: 529 | J18: =+J160+J191+J218 -> 540 | K18: =+K160+K191+K218 -> 810 | L18: =+L160+L191+L218 -> 2433 | M18: =+M160+M191+M218 -> 618 | N18: =+N160+N191+N218 -> 669 | O18: =+O160+O191+O218 -> 969 | P18: =+P160+P191+P218 -> 2774 | Q18: =+Q160+Q191+Q218 -> 749 | ... V18: =+V160+V191+V218 -> 956 | W18: =+W160+W191+W218+W202 -> 1081 | X18: =+X160+X191+X218+X202 -> 3640 | Y18: =+Y160+Y191+Y218+Y202 -> 2247 | Z18: =+Z160+Z191+Z218+Z202 -> 1596.4348 | AA18: =+AA160+AA191+AA218+AA202 -> 2014.4553 | AB18: =+AB160+AB191+AB218+AB202 -> 4957.5132 | AC18: =+AC160+AC191+AC218+AC202 -> 2051.1045 | AD18: =+AD160+AD191+AD218+AD202 -> 2053.02 | ... AO18: =+AO160+AO191+AO218+AO202 -> 3290.961 | AP18: =+AP160+AP191+AP218+AP197 -> 3497.23 | AQ18: =+AQ160+AQ191+AQ218+AQ197 -> 3872.29 | AR18: =+AR160+AR191+AR218+AR197 -> 7658.6803 | AS18: =+AS160+AS191+AS218+AS197 -> 3682.0861 | AT18: =+AT160+AT191+AT218+AT197 -> 4002.8389 | AU18: =+AU160+AU191+AU218+AU197 -> 4469.0289 | AV18: =+AV160+AV191+AV218+AV197 -> 8424.6564 | AW18: =+AW160+AW191+AW218+AW197 -> 4140.6172 | ... BA18: =+BA160+BA191+BA218+BA197 -> 4688.0901 | BD18: =SUM(B18:E18) -> 3405 | BE18: =SUM(F18:I18) -> 3801 | BF18: =SUM(J18:M18) -> 4401 | BG18: =SUM(N18:Q18) -> 5161 | BH18: =SUM(R18:U18) -> 6044 | BI18: =SUM(V18:Y18) -> 7924 | BJ18: =SUM(Z18:AC18) -> 10619.508 | BK18: =SUM(AD18:AG18) -> 11987.666 | BL18: =SUM(AH18:AK18) -> 13800.975 | BM18: =SUM(AL18:AO18) -> 16399.994 | BN18: =SUM(AP18:AS18) -> 18710.286 | BO18: =SUM(AT18:AW18) -> 21037.141 | BP18: =SUM(AX18:BA18) -> 23679.705
A19: Y/Y Growth | B19: =IF(ISERROR(B18/#REF!-1),"NA",B18/#REF!-1) -> NA | C19: =IF(ISERROR(C18/#REF!-1),"NA",C18/#REF!-1) -> NA | D19: =IF(ISERROR(D18/#REF!-1),"NA",D18/#REF!-1) -> NA | E19: =IF(ISERROR(E18/A18-1),"NA",E18/A18-1) -> NA | F19: =IF(ISERROR(F18/B18-1),"NA",F18/B18-1) -> 0.088235294 | G19: =IF(ISERROR(G18/C18-1),"NA",G18/C18-1) -> 0.08801214 | H19: =IF(ISERROR(H18/D18-1),"NA",H18/D18-1) -> 0.12411924 | I19: =IF(ISERROR(I18/E18-1),"NA",I18/E18-1) -> 0.15250545 | J19: =IF(ISERROR(J18/F18-1),"NA",J18/F18-1) -> 0.12266112 | K19: =IF(ISERROR(K18/G18-1),"NA",K18/G18-1) -> 0.12970711 | L19: =IF(ISERROR(L18/H18-1),"NA",L18/H18-1) -> 0.17309547 | ... BA19: =IF(ISERROR(BA18/AW18-1),"NA",BA18/AW18-1) -> 0.13222013 | BD19: =IF(ISERROR(BD18/BB18-1),"NA",BD18/BB18-1) -> NA | BE19: =IF(ISERROR(BE18/BD18-1),"NA",BE18/BD18-1) -> 0.11629956 | BF19: =IF(ISERROR(BF18/BE18-1),"NA",BF18/BE18-1) -> 0.1578532 | BG19: =IF(ISERROR(BG18/BF18-1),"NA",BG18/BF18-1) -> 0.17268803 | BH19: =IF(ISERROR(BH18/BG18-1),"NA",BH18/BG18-1) -> 0.17109087 | BI19: =IF(ISERROR(BI18/BH18-1),"NA",BI18/BH18-1) -> 0.31105228 | BJ19: =IF(ISERROR(BJ18/BI18-1),"NA",BJ18/BI18-1) -> 0.34017009 | BK19: =IF(ISERROR(BK18/BJ18-1),"NA",BK18/BJ18-1) -> 0.12883438 | BL19: =IF(ISERROR(BL18/BK18-1),"NA",BL18/BK18-1) -> 0.15126462 | ... BP19: =IF(ISERROR(BP18/BO18-1),"NA",BP18/BO18-1) -> 0.12561421
A20: Q/Q Growth | B20: =IF(ISERROR(B18/A18-1),"NA",B18/A18-1) -> NA | C20: =IF(ISERROR(C18/B18-1),"NA",C18/B18-1) -> 0.49095023 | D20: =IF(ISERROR(D18/C18-1),"NA",D18/C18-1) -> 1.7996965 | E20: =IF(ISERROR(E18/D18-1),"NA",E18/D18-1) -> -0.75121951 | F20: =IF(ISERROR(F18/E18-1),"NA",F18/E18-1) -> 0.047930283 | G20: =IF(ISERROR(G18/F18-1),"NA",G18/F18-1) -> 0.49064449 | H20: =IF(ISERROR(H18/G18-1),"NA",H18/G18-1) -> 1.8926081 | I20: =IF(ISERROR(I18/H18-1),"NA",I18/H18-1) -> -0.74493732 | ... BA20: =IF(ISERROR(BA18/AZ18-1),"NA",BA18/AZ18-1) -> -0.49628137 | BD20: NA | BE20: NA | BF20: NA | BG20: NA | BH20: NA | BI20: NA | BJ20: NA | BK20: NA | BL20: NA | BM20: NA | BN20: NA | BO20: NA | BP20: NA
A21: % of total revenue | B21: =+B18/B6 -> 0.61991585 | C21: =+C18/C6 -> 0.71397616 | D21: =+D18/D6 -> 0.80078125 | E21: =+E18/E6 -> 0.60875332 | F21: =+F18/F6 -> 0.61825193 | G21: =+G18/G6 -> 0.70570866 | H21: =+H18/H6 -> 0.81621409 | I21: =+I18/I6 -> 0.62826603 | ... BA21: =+BA18/BA6 -> 0.87909288 | BD21: =+BD18/BD$6 -> 0.72539412 | BE21: =+BE18/BE$6 -> 0.734209 | BF21: =+BF18/BF$6 -> 0.73045643 | BG21: =+BG18/BG$6 -> 0.76076061 | BH21: =+BH18/BH$6 -> 0.78708165 | BI21: =+BI18/BI$6 -> 0.82258902 | BJ21: =+BJ18/BJ$6 -> 0.83447335 | BK21: =+BK18/BK$6 -> 0.83433084 | ... BP21: =+BP18/BP$6 -> 0.89116218
AH22: 1QFY-2024 | AI22: 2QFY-2024 | AJ22: 3QFY-2024 | AK22: 4QFY-2024 | AL22: 1QFY-2025 | AM22: 2QFY-2025 | AN22: 3QFY-2025 | AO22: 4QFY-2025 | AP22: 1QFY-2026 | AQ22: 2QFY-2025 | AR22: 3QFY-2026 | AS22: 4QFY-2026 | AT22: 1QFY-2027 | AU22: 2QFY-2027 | AV22: 3QFY-2027 | AW22: 4QFY-2027 | AX22: 1QFY-2028 | AY22: 2QFY-2028 | AZ22: 3QFY-2028 | BA22: 4QFY-2028
A23: Segment Build(s)
A24: Global Business Solutions (QuickBooks) | B24: 530 | C24: 547 | D24: 557 | E24: 587 | F24: =+F154+F160 -> 593 | G24: =+G154+G160 -> 618 | H24: =+H154+H160 -> 655 | I24: =+I154+I160 -> 708 | J24: =+J154+J160 -> 819 | K24: =+K154+K160 -> 713 | L24: =+L154+L160 -> 747 | M24: =+M154+M160 -> 782 | ... V24: =+V154+V160 -> 1181 | W24: =+W32+W135 -> 1078 | X24: =+X32+X135 -> 1177 | Y24: =+Y154+Y160 -> 1252 | Z24: =+Z154+Z160 -> 1443 | AA24: 1581 | AB24: 1667 | AC24: 1769 | AD24: 1988 | AE24: 1897 | AF24: 2021 | AG24: 2132 | AH24: 2344 | AI24: 2245 | AJ24: =+AJ32+AJ135 -> 2387 | AK24: =+AK32+AK135 -> 2557 | AL24: =+AL32+AL135 -> 2544 | AM24: =+AM32+AM135 -> 2671 | AN24: =+AN32+AN135 -> 2849 | AO24: =+AO32+AO135 -> 3013 | AP24: =+AP32+AP135 -> 2991 | AQ24: =+AQ32+AQ135 -> 3164 | ... BA24: =+BA32+BA135 -> 4374.0334 | BD24: =SUM(B24:E24) -> 2221 | BE24: =SUM(F24:I24) -> 2574 | BF24: =SUM(J24:M24) -> 3061 | BG24: =SUM(N24:Q24) -> 3533 | BH24: =SUM(R24:U24) -> 4050 | BI24: =SUM(V24:Y24) -> 4688 | BJ24: =SUM(Z24:AC24) -> 6460 | BK24: =SUM(AD24:AG24) -> 8038 | BL24: =SUM(AH24:AK24) -> 9533 | BM24: =SUM(AL24:AO24) -> 11077 | BN24: =SUM(AP24:AS24) -> 12778.318 | BO24: =SUM(AT24:AW24) -> 14720.041 | BP24: =SUM(AX24:BA24) -> 16947.932
A25: Y/Y Growth (%) | B25: =IF(ISERROR(B24/#REF!-1),"NA",B24/#REF!-1) -> NA | C25: =IF(ISERROR(C24/#REF!-1),"NA",C24/#REF!-1) -> NA | D25: =IF(ISERROR(D24/#REF!-1),"NA",D24/#REF!-1) -> NA | E25: =IF(ISERROR(E24/A24-1),"NA",E24/A24-1) -> NA | F25: =IF(ISERROR(F24/B24-1),"NA",F24/B24-1) -> 0.11886792 | G25: =IF(ISERROR(G24/C24-1),"NA",G24/C24-1) -> 0.1297989 | H25: =IF(ISERROR(H24/D24-1),"NA",H24/D24-1) -> 0.17594255 | I25: =IF(ISERROR(I24/E24-1),"NA",I24/E24-1) -> 0.20613288 | J25: =IF(ISERROR(J24/F24-1),"NA",J24/F24-1) -> 0.38111298 | K25: =IF(ISERROR(K24/G24-1),"NA",K24/G24-1) -> 0.15372168 | L25: =IF(ISERROR(L24/H24-1),"NA",L24/H24-1) -> 0.14045802 | ... BA25: =IF(ISERROR(BA24/AW24-1),"NA",BA24/AW24-1) -> 0.14108959 | BD25: =IF(ISERROR(BD24/BB24-1),"NA",BD24/BB24-1) -> NA | BE25: =IF(ISERROR(BE24/BD24-1),"NA",BE24/BD24-1) -> 0.15893742 | BF25: =IF(ISERROR(BF24/BE24-1),"NA",BF24/BE24-1) -> 0.18919969 | BG25: =IF(ISERROR(BG24/BF24-1),"NA",BG24/BF24-1) -> 0.15419797 | BH25: =IF(ISERROR(BH24/BG24-1),"NA",BH24/BG24-1) -> 0.14633456 | BI25: =IF(ISERROR(BI24/BH24-1),"NA",BI24/BH24-1) -> 0.15753086 | BJ25: =IF(ISERROR(BJ24/BI24-1),"NA",BJ24/BI24-1) -> 0.37798635 | BK25: =IF(ISERROR(BK24/BJ24-1),"NA",BK24/BJ24-1) -> 0.24427245 | BL25: =IF(ISERROR(BL24/BK24-1),"NA",BL24/BK24-1) -> 0.18599154 | ... BP25: =IF(ISERROR(BP24/BO24-1),"NA",BP24/BO24-1) -> 0.15135087
A26: Y/Y Growth (%) ex Mailchimp | AE26: =(AE24-AE107)/(AA24-AA107)-1 -> 0.19835943 | AF26: =(AF24-AF107)/(AB24-AB107)-1 -> 0.21702128 | AG26: =(AG24-AG107)/(AC24-AC107)-1 -> 0.21409574 | AH26: =(AH24-AH107)/(AD24-AD107)-1 -> 0.17691415 | AI26: =(AI24-AI107)/(AE24-AE107)-1 -> 0.19788426 | AJ26: =(AJ24-AJ107)/(AF24-AF107)-1 -> 0.2016317 | AK26: =(AK24-AK107)/(AG24-AG107)-1 -> 0.2196057 | AL26: =(AL24-AL107)/(AH24-AH107)-1 -> 0.090192213 | ... BA26: =(BA24-BA107)/(AW24-AW107)-1 -> 0.14399647 | BK26: =(BK24-BK107)/(BJ24-BJ107)-1 -> 0.20621271 | BL26: =(BL24-BL107)/(BK24-BK107)-1 -> 0.19933071 | BM26: =(BM24-BM107)/(BL24-BL107)-1 -> 0.18488414 | BN26: =(BN24-BN107)/(BM24-BM107)-1 -> 0.17214267 | BO26: =(BO24-BO107)/(BN24-BN107)-1 -> 0.15912588 | BP26: =(BP24-BP107)/(BO24-BO107)-1 -> 0.15605761
A27: Q/Q Growth | B27: =IF(ISERROR(B24/A24-1),"NA",B24/A24-1) -> NA | C27: =IF(ISERROR(C24/B24-1),"NA",C24/B24-1) -> 0.032075472 | D27: =IF(ISERROR(D24/C24-1),"NA",D24/C24-1) -> 0.018281536 | E27: =IF(ISERROR(E24/D24-1),"NA",E24/D24-1) -> 0.053859964 | F27: =IF(ISERROR(F24/E24-1),"NA",F24/E24-1) -> 0.010221465 | G27: =IF(ISERROR(G24/F24-1),"NA",G24/F24-1) -> 0.042158516 | H27: =IF(ISERROR(H24/G24-1),"NA",H24/G24-1) -> 0.05987055 | I27: =IF(ISERROR(I24/H24-1),"NA",I24/H24-1) -> 0.080916031 | ... BA27: =IF(ISERROR(BA24/AZ24-1),"NA",BA24/AZ24-1) -> 0.026922596 | BD27: NA | BE27: NA | BF27: NA | BG27: NA | BH27: NA | BI27: NA | BJ27: NA | BK27: NA | BL27: NA | BM27: NA | BN27: NA | BO27: NA | BP27: NA
A28: % of total revenue | B28: =+B24/B$6 -> 0.74333801 | C28: =+C24/C$6 -> 0.59263272 | D28: =+D24/D$6 -> 0.24175347 | E28: =+E24/E$6 -> 0.77851459 | F28: =+F24/F$6 -> 0.7622108 | G28: =+G24/G$6 -> 0.60826772 | H28: =+H24/H$6 -> 0.25777253 | I28: =+I24/I$6 -> 0.84085511 | ... BA28: =+BA24/BA$6 -> 0.82020216 | BD28: =+BD24/BD$6 -> 0.47315722 | BE28: =+BE24/BE$6 -> 0.49719915 | BF28: =+BF24/BF$6 -> 0.50804979 | BG28: =+BG24/BG$6 -> 0.5207842 | BH28: =+BH24/BH$6 -> 0.52741242 | BI28: =+BI24/BI$6 -> 0.48666044 | BJ28: =+BJ24/BJ$6 -> 0.50762219 | BK28: =+BK24/BK$6 -> 0.55943764 | ... BP28: =+BP24/BP$6 -> 0.63781859
A29: Consensus | AH29: =_xll.VAData("INTU",AH$22,"Revenue - Global business solutions","consensus.vaactuals","CD","IMPL","Current","","","USD") -> 2344 | AI29: =_xll.VAData("INTU",AI$22,"Revenue - Global business solutions","consensus.vaactuals","CD","IMPL","Current","","","USD") -> 2245 | AJ29: =_xll.VAData("INTU",AJ$22,"Revenue - Global business solutions","consensus.vaactuals","CD","IMPL","Current","","","USD") -> 2387 | AK29: =_xll.VAData("INTU",AK$22,"Revenue - Global business solutions","consensus.vaactuals","CD","IMPL","Current","","","USD") -> 2557 | AL29: =_xll.VAData("INTU",AL$22,"Revenue - Global business solutions","consensus.vaactuals","CD","IMPL","Current","","","USD") -> 2544 | AM29: =_xll.VAData("INTU",AM$22,"Revenue - Global business solutions","consensus.vaactuals","CD","IMPL","Current","","","USD") -> 2671 | AN29: =_xll.VAData("INTU",AN$22,"Revenue - Global business solutions","consensus.vaactuals","CD","IMPL","Current","","","USD") -> 2849 | AO29: =_xll.VAData("INTU",AO$22,"Revenue - Global business solutions","consensus.vaactuals","CD","IMPL","Current","","","USD") -> 3013 | ... BA29: =_xll.VAData("INTU",BA$22,"Revenue - Global business solutions","consensus.vaactuals","CD","IMPL","Current","","","USD") -> 4389.4383 | BL29: =SUM(AH29:AK29) -> 9533 | BM29: =SUM(AL29:AO29) -> 11077 | BN29: =SUM(AP29:AS29) -> 12280.959 | BO29: =SUM(AT29:AW29) -> 14680.742 | BP29: =SUM(AX29:BA29) -> 16820.947
A30: Y/Y Growth (%) | B30: =IF(ISERROR(B29/#REF!-1),"NA",B29/#REF!-1) -> NA | C30: =IF(ISERROR(C29/#REF!-1),"NA",C29/#REF!-1) -> NA | D30: =IF(ISERROR(D29/#REF!-1),"NA",D29/#REF!-1) -> NA | E30: =IF(ISERROR(E29/A29-1),"NA",E29/A29-1) -> NA | F30: =IF(ISERROR(F29/B29-1),"NA",F29/B29-1) -> NA | G30: =IF(ISERROR(G29/C29-1),"NA",G29/C29-1) -> NA | H30: =IF(ISERROR(H29/D29-1),"NA",H29/D29-1) -> NA | I30: =IF(ISERROR(I29/E29-1),"NA",I29/E29-1) -> NA | J30: =IF(ISERROR(J29/F29-1),"NA",J29/F29-1) -> NA | K30: =IF(ISERROR(K29/G29-1),"NA",K29/G29-1) -> NA | L30: =IF(ISERROR(L29/H29-1),"NA",L29/H29-1) -> NA | ... AG30: =IF(ISERROR(AG29/AC29-1),"NA",AG29/AC29-1) -> NA | AL30: =IF(ISERROR(AL29/AH29-1),"NA",AL29/AH29-1) -> 0.085324232 | AM30: =IF(ISERROR(AM29/AI29-1),"NA",AM29/AI29-1) -> 0.18975501 | AN30: =IF(ISERROR(AN29/AJ29-1),"NA",AN29/AJ29-1) -> 0.19354839 | AO30: =IF(ISERROR(AO29/AK29-1),"NA",AO29/AK29-1) -> 0.17833399 | AP30: =IF(ISERROR(AP29/AL29-1),"NA",AP29/AL29-1) -> 0.17570755 | AQ30: =IF(ISERROR(AQ29/AM29-1),"NA",AQ29/AM29-1) -> 0 | AR30: =IF(ISERROR(AR29/AN29-1),"NA",AR29/AN29-1) -> 0.14861731 | AS30: =IF(ISERROR(AS29/AO29-1),"NA",AS29/AO29-1) -> 0.11070301 | ... BA30: =IF(ISERROR(BA29/AW29-1),"NA",BA29/AW29-1) -> 0.13835301 | BD30: =IF(ISERROR(BD29/BB29-1),"NA",BD29/BB29-1) -> NA | BE30: =IF(ISERROR(BE29/BD29-1),"NA",BE29/BD29-1) -> NA | BF30: =IF(ISERROR(BF29/BE29-1),"NA",BF29/BE29-1) -> NA | BG30: =IF(ISERROR(BG29/BF29-1),"NA",BG29/BF29-1) -> NA | BH30: =IF(ISERROR(BH29/BG29-1),"NA",BH29/BG29-1) -> NA | BI30: =IF(ISERROR(BI29/BH29-1),"NA",BI29/BH29-1) -> NA | BJ30: =IF(ISERROR(BJ29/BI29-1),"NA",BJ29/BI29-1) -> NA | BM30: =IF(ISERROR(BM29/BL29-1),"NA",BM29/BL29-1) -> 0.16196371 | BN30: =IF(ISERROR(BN29/BM29-1),"NA",BN29/BM29-1) -> 0.10868998 | BO30: =IF(ISERROR(BO29/BN29-1),"NA",BO29/BN29-1) -> 0.19540679 | BP30: =IF(ISERROR(BP29/BO29-1),"NA",BP29/BO29-1) -> 0.14578319
A32: Online Ecosystem | B32: =+SUM(B63,B86) -> 151 | C32: =+SUM(C63,C86) -> 155 | D32: =+SUM(D63,D86) -> 171 | E32: =+SUM(E63,E86) -> 179 | F32: =+SUM(F63,F86) -> 191 | G32: =+SUM(G63,G86) -> 200 | H32: =+SUM(H63,H86) -> 225 | I32: =+SUM(I63,I86) -> 242 | ... AQ32: =+SUM(AQ63,AQ86) -> 2467 | AR32: =AN32*(1+AR33) -> 2481.54 | AS32: =AO32*(1+AS33) -> 2595.06 | AT32: =AP32*(1+AT33) -> 2785.935 | AU32: =AQ32*(1+AU33) -> 2986.3047 | AV32: =AR32*(1+AV33) -> 2928.2172 | AW32: =AS32*(1+AW33) -> 3036.2202 | AX32: =AT32*(1+AX33) -> 3287.4033 | AY32: =AU32*(1+AY33) -> 3599.9918 | ... BA32: =AW32*(1+BA33) -> 3537.1965 | BD32: =SUM(B32:E32) -> 656 | BE32: =SUM(F32:I32) -> 858 | BF32: =SUM(J32:M32) -> 1206 | BG32: =SUM(N32:Q32) -> 1663 | BH32: =SUM(R32:U32) -> 2182 | BI32: =SUM(V32:Y32) -> 2750 | BJ32: =SUM(Z32:AC32) -> 4438 | BK32: =SUM(AD32:AG32) -> 5759 | BL32: =SUM(AH32:AK32) -> 6892 | BM32: =SUM(AL32:AO32) -> 8302 | BN32: =SUM(AP32:AS32) -> 9894.6 | BO32: =SUM(AT32:AW32) -> 11736.677 | BP32: =SUM(AX32:BA32) -> 13865.247
A33: Y/Y Growth (%) | B33: =IF(ISERROR(B32/#REF!-1),"NA",B32/#REF!-1) -> NA | C33: =IF(ISERROR(C32/#REF!-1),"NA",C32/#REF!-1) -> NA | D33: =IF(ISERROR(D32/#REF!-1),"NA",D32/#REF!-1) -> NA | E33: =IF(ISERROR(E32/A32-1),"NA",E32/A32-1) -> NA | F33: =IF(ISERROR(F32/B32-1),"NA",F32/B32-1) -> 0.26490066 | G33: =IF(ISERROR(G32/C32-1),"NA",G32/C32-1) -> 0.29032258 | H33: =IF(ISERROR(H32/D32-1),"NA",H32/D32-1) -> 0.31578947 | I33: =IF(ISERROR(I32/E32-1),"NA",I32/E32-1) -> 0.35195531 | J33: =IF(ISERROR(J32/F32-1),"NA",J32/F32-1) -> 0.37172775 | K33: =IF(ISERROR(K32/G32-1),"NA",K32/G32-1) -> 0.425 | L33: =IF(ISERROR(L32/H32-1),"NA",L32/H32-1) -> 0.41333333 | ... AQ33: =IF(ISERROR(AQ32/AM32-1),"NA",AQ32/AM32-1) -> 0.21050049 | AR33: 0.18 | AS33: 0.17 | AT33: 0.185 | AU33: =AQ33 -> 0.21050049 | AV33: =AR33 -> 0.18 | AW33: =AS33 -> 0.17 | AX33: =AT33-0.5% -> 0.18 | AY33: =AU33-0.5% -> 0.20550049 | AZ33: =AV33-0.5% -> 0.175 | BA33: =AW33-0.5% -> 0.165 | BD33: =IF(ISERROR(BD32/BB32-1),"NA",BD32/BB32-1) -> NA | BE33: =IF(ISERROR(BE32/BD32-1),"NA",BE32/BD32-1) -> 0.30792683 | BF33: =IF(ISERROR(BF32/BE32-1),"NA",BF32/BE32-1) -> 0.40559441 | BG33: =IF(ISERROR(BG32/BF32-1),"NA",BG32/BF32-1) -> 0.37893864 | BH33: =IF(ISERROR(BH32/BG32-1),"NA",BH32/BG32-1) -> 0.31208659 | BI33: =IF(ISERROR(BI32/BH32-1),"NA",BI32/BH32-1) -> 0.26031164 | BJ33: =IF(ISERROR(BJ32/BI32-1),"NA",BJ32/BI32-1) -> 0.61381818 | BK33: =IF(ISERROR(BK32/BJ32-1),"NA",BK32/BJ32-1) -> 0.2976566 | BL33: =IF(ISERROR(BL32/BK32-1),"NA",BL32/BK32-1) -> 0.19673554 | ... BP33: =IF(ISERROR(BP32/BO32-1),"NA",BP32/BO32-1) -> 0.18136051
A34: Y/Y Growth (%) ex Mailchimp | AH34: =(AH32-AH107)/(AD32-AD107)-1 -> 0.20092166 | AI34: =(AI32-AI107)/(AE32-AE107)-1 -> 0.24250681 | AJ34: =(AJ32-AJ107)/(AF32-AF107)-1 -> 0.22871883 | AK34: =(AK32-AK107)/(AG32-AG107)-1 -> 0.2064257 | AL34: =(AL32-AL107)/(AH32-AH107)-1 -> 0.23637759 | AM34: =(AM32-AM107)/(AI32-AI107)-1 -> 0.25146199 | AN34: =(AN32-AN107)/(AJ32-AJ107)-1 -> 0.24492652 | AO34: =(AO32-AO107)/(AK32-AK107)-1 -> 0.25832224 | ... BA34: =(BA32-BA107)/(AW32-AW107)-1 -> 0.1721573 | BK34: =(BK32-BK53)/(BJ32-BJ53)-1 -> 0.29765754 | BL34: =(BL32-BL53)/(BK32-BK53)-1 -> 0.1967368 | BM34: =(BM32-BM53)/(BL32-BL53)-1 -> 0.20458624 | BN34: =(BN32-BN53)/(BM32-BM53)-1 -> 0.19183432 | BO34: =(BO32-BO53)/(BN32-BN53)-1 -> 0.18617043 | BP34: =(BP32-BP53)/(BO32-BO53)-1 -> 0.18136238
A35: Y/Y Growth ($) | V35: =V32-R32 -> 120 | W35: =W32-S32 -> 114 | X35: =X32-T32 -> 155 | Y35: =Y32-U32 -> 179 | Z35: =Z32-V32 -> 224 | AA35: =AA32-W32 -> 477 | AB35: =AB32-X32 -> 477 | AC35: =AC32-Y32 -> 510 | ... BA35: =BA32-AW32 -> 500.97633 | BI35: =BI32-BH32 -> 568 | BJ35: =BJ32-BI32 -> 1688 | BK35: =BK32-BJ32 -> 1321 | BL35: =BL32-BK32 -> 1133 | BM35: =BM32-BL32 -> 1410 | BN35: =BN32-BM32 -> 1592.6 | BO35: =BO32-BN32 -> 1842.0771 | BP35: =BP32-BO32 -> 2128.5697
A36: Q/Q Growth (%) | B36: =IF(ISERROR(B32/A32-1),"NA",B32/A32-1) -> NA | C36: =IF(ISERROR(C32/B32-1),"NA",C32/B32-1) -> 0.026490066 | D36: =IF(ISERROR(D32/C32-1),"NA",D32/C32-1) -> 0.10322581 | E36: =IF(ISERROR(E32/D32-1),"NA",E32/D32-1) -> 0.046783626 | F36: =IF(ISERROR(F32/E32-1),"NA",F32/E32-1) -> 0.067039106 | G36: =IF(ISERROR(G32/F32-1),"NA",G32/F32-1) -> 0.047120419 | H36: =IF(ISERROR(H32/G32-1),"NA",H32/G32-1) -> 0.125 | I36: =IF(ISERROR(I32/H32-1),"NA",I32/H32-1) -> 0.075555556 | ... BA36: =IF(ISERROR(BA32/AZ32-1),"NA",BA32/AZ32-1) -> 0.028058994 | BD36: NA | BE36: NA | BF36: NA | BG36: NA | BH36: NA | BI36: N/A | BJ36: N/A | BK36: N/A | BL36: N/A | BM36: N/A | BN36: N/A | BO36: N/A | BP36: N/A
A37: Q/Q Growth ($) | V37: =V32-U32 -> 30 | W37: =W32-V32 -> 23 | X37: =X32-W32 -> 71 | Y37: =Y32-X32 -> 55 | Z37: =Z32-Y32 -> 75 | AA37: =AA32-Z32 -> 276 | AB37: =AB32-AA32 -> 71 | AC37: =AC32-AB32 -> 88 | ... BA37: =BA32-AZ32 -> 96.541323 | BI37: N/A | BJ37: N/A | BK37: N/A | BL37: N/A | BM37: N/A | BN37: N/A | BO37: N/A | BP37: N/A
A38: % of Total Revenue | B38: =+B32/B$6 -> 0.21178121 | C38: =+C32/C$6 -> 0.16793066 | D38: =+D32/D$6 -> 0.07421875 | E38: =+E32/E$6 -> 0.23740053 | F38: =+F32/F$6 -> 0.24550129 | G38: =+G32/G$6 -> 0.19685039 | H38: =+H32/H$6 -> 0.088547816 | I38: =+I32/I$6 -> 0.28741093 | ... BA38: =+BA32/BA$6 -> 0.66328168 | BD38: =+BD32/BD$6 -> 0.13975288 | BE38: =+BE32/BE$6 -> 0.16573305 | BF38: =+BF32/BF$6 -> 0.20016598 | BG38: =+BG32/BG$6 -> 0.24513561 | BH38: =+BH32/BH$6 -> 0.28415158 | BI38: =+BI32/BI$6 -> 0.28547701 | BJ38: =+BJ32/BJ$6 -> 0.34873487 | BK38: =+BK32/BK$6 -> 0.40082127 | ... BP38: =+BP32/BP$6 -> 0.52180479
A39: Consensus | AH39: =_xll.VAData("INTU",AH$22,"Revenue - Total online ecosystem","consensus.vaactuals") -> 1618 | AI39: =_xll.VAData("INTU",AI$22,"Revenue - Total online ecosystem","consensus.vaactuals") -> 1688 | AJ39: =_xll.VAData("INTU",AJ$22,"Revenue - Total online ecosystem","consensus.vaactuals") -> 1754 | AK39: =_xll.VAData("INTU",AK$22,"Revenue - Total online ecosystem","consensus.vaactuals") -> 1832 | AL39: =_xll.VAData("INTU",AL$22,"Revenue - Total online ecosystem","consensus.vaactuals") -> 1943 | AM39: =_xll.VAData("INTU",AM$22,"Revenue - Total online ecosystem","consensus.vaactuals") -> 2038 | AN39: =_xll.VAData("INTU",AN$22,"Revenue - Total online ecosystem","consensus.vaactuals") -> 2103 | AO39: =_xll.VAData("INTU",AO$22,"Revenue - Total online ecosystem","consensus.vaactuals") -> 2218 | ... BA39: =_xll.VAData("INTU",BA$22,"Revenue - Total online ecosystem","consensus.vaactuals") -> 3506.8234 | BL39: =SUM(AH39:AK39) -> 6892 | BM39: =SUM(AL39:AO39) -> 8302 | BN39: =SUM(AP39:AS39) -> 9429.8012 | BO39: =SUM(AT39:AW39) -> 11633.227 | BP39: =SUM(AX39:BA39) -> 13625.972
