Workbook
Name \P: #REF!
Name \P: #REF!
Name \P: #REF!
Name \P: #REF!
Name \S: #REF!
Name \S: #REF!
Name \T: #REF!
Name \T: #REF!
Name \T: #REF!
Name \X: #REF!
Name \X: #REF!
Name \Z: #REF!
Name \Z: #REF!
Name ____________________________________________EPS94: #REF!
Name ____________________________________________EPS94: #REF!
Name ____________________________________________EPS95: #REF!
Name ____________________________________________EPS95: #REF!
Name ____________________________________________EPS96: #REF!
Name ____________________________________________EPS96: #REF!
Name ____________________________________________QTR195: #REF!
Name ____________________________________________QTR295: #REF!
Name ____________________________________________QTR394: #REF!
Name ____________________________________________QTR395: #REF!
Name ____________________________________________QTR494: #REF!
Name ____________________________________________QTR495: #REF!
Name ___________________________________________EPS94: #REF!
Name ___________________________________________EPS95: #REF!
Name ___________________________________________EPS96: #REF!
Name ___________________________________________QTR195: #REF!
Name ___________________________________________QTR295: #REF!
Name ___________________________________________QTR394: #REF!
Name ___________________________________________QTR395: #REF!
Name ___________________________________________QTR494: #REF!
Name ___________________________________________QTR495: #REF!
Name _________________________________________EPS94: #REF!
Name _________________________________________EPS95: #REF!
Name _________________________________________EPS96: #REF!
Name _________________________________________QTR195: #REF!
Name _________________________________________QTR295: #REF!
Name _________________________________________QTR394: #REF!
Name _________________________________________QTR395: #REF!
Name _________________________________________QTR494: #REF!
Name _________________________________________QTR495: #REF!
Name _______________________________________EPS94: #REF!
Name _______________________________________EPS95: #REF!
Name _______________________________________EPS96: #REF!
Name _______________________________________QTR195: #REF!
Name _______________________________________QTR295: #REF!
Name _______________________________________QTR394: #REF!
Name _______________________________________QTR395: #REF!
Name _______________________________________QTR494: #REF!
Name _______________________________________QTR495: #REF!
Name ______________________________________EPS94: #REF!
Name ______________________________________EPS95: #REF!
Name ______________________________________EPS96: #REF!
Name ______________________________________QTR195: #REF!
Name ______________________________________QTR295: #REF!
Name ______________________________________QTR394: #REF!
Name ______________________________________QTR395: #REF!
Name ______________________________________QTR494: #REF!

Sheet __FDSCACHE__
B1: This sheet contains FactSet XML data for use with this workbook's =FDS codes. Modifying the worksheet's contents may damage the workbook's =FDS functionality.

Sheet CW_Drivers
A1: Curtiss-Wright
A2: ($ in millions) | Q2: C4Q11 | R2: C1Q12 | S2: C2Q12 | T2: C3Q12 | V2: C4Q12 | W2: C1Q13 | X2: C2Q13 | Y2: C3Q13 | AK2: C3Q15 | AL2: C4Q15 | AM2: C1Q16 | AN2: C2Q16
B3: 1Q09 | C3: 2Q09 | D3: 3Q09 | E3: 4Q09 | F3: 2009 | G3: 1Q10 | H3: 2Q10 | I3: 3Q10 | J3: 4Q10 | K3: 2010 | L3: 1Q11 | M3: 2Q11 | N3: 3Q11 | O3: 4Q11 | P3: 2011 | Q3: 1Q12 | R3: 2Q12 | S3: 3Q12 | T3: 4Q12 | U3: 2012 | V3: 1Q13 | W3: 2Q13 | X3: 3Q13 | Y3: 4Q13 | Z3: 2013 | AA3: 1Q14 | AB3: 2Q14 | AC3: 3Q14 | AD3: 4Q14 | AE3: F2014 | AF3: 1Q15 | AG3: 2Q15 | AH3: 3Q15 | AI3: 4Q15 | AJ3: F2015 | AK3: F1Q16 | AL3: F2Q16 | AM3: F3Q16 | AN3: F4Q16 | AO3: F2016 | AP3: F1Q17 | AQ3: F2Q17 | AR3: F3Q17 | AS3: F4Q17 | AT3: 2017 | AU3: 1Q18 | AV3: 2Q18 | AW3: 3Q18 | AX3: 4Q18 | AY3: 2018 | AZ3: F1Q19 | BA3: F2Q19 | BB3: F3Q19 | BC3: F4Q19 | BD3: 2019 | BE3: 1Q20 | BF3: 2Q20 | BG3: 3Q20 | BH3: 4Q20 | BI3: 2020 | BJ3: 1Q21 | BK3: 2Q21 | BL3: 3Q21 | BM3: 4Q21 | BN3: 2021 | BO3: 1Q22 | BP3: 2Q22 | BQ3: 3Q22 | BR3: 4Q22 | BS3: 2022 | BT3: 1Q23 | BU3: 2Q23 | BV3: 3Q23 | BW3: 4Q23 | BX3: 2023 | BY3: 1Q24 | BZ3: 2Q24 | CA3: 3Q24 | CB3: 4Q24 | CC3: 2024 | CD3: 1Q25 | CE3: 2Q25 | CF3: 3Q25 | CG3: 4Q25 | CH3: 2025 | CI3: 1Q26E | CJ3: 2Q26E | CK3: 3Q26E | CL3: 4Q26E | CM3: 2026E | CN3: 1Q27E | CO3: 2Q27E | CP3: 3Q27E | CQ3: 4Q27E | CR3: 2027E
A5: Aerospace & Defense Revenue
A6: Aerospace Defense | AT6: 372.678 | AY6: 376.951 | BD6: 416.841 | BE6: 101.827 | BF6: 109.506 | BG6: 122.735 | BH6: 130.785 | BI6: =SUM(BE6:BH6) -> 464.853 | BJ6: 111.016 | BK6: 99.977 | BL6: 116.853 | BM6: 124.815 | BN6: =SUM(BJ6:BM6) -> 452.661 | BO6: 98.004 | BP6: 94.545 | BQ6: 114.431 | BR6: 172.763 | BS6: =SUM(BO6:BR6) -> 479.743 | BT6: 99.879 | BU6: 132.192 | BV6: 148.023 | BW6: 171.527 | BX6: =SUM(BT6:BW6) -> 551.621 | BY6: 132.074 | BZ6: 154.104 | CA6: 158.98 | CB6: 171.432 | CC6: =SUM(BY6:CB6) -> 616.59 | CD6: 151.722 | CE6: 167.587 | CF6: 161.162 | CG6: 192.055 | CH6: =SUM(CD6:CG6) -> 672.526 | CI6: =CD6*(1+CI7) -> 166.8942 | CJ6: =CE6*(1+CJ7) -> 180.99396 | CK6: =CF6*(1+CK7) -> 185.3363 | CL6: =CG6*(1+CL7) -> 207.4194 | CM6: =SUM(CI6:CL6) -> 740.64386 | CN6: =CI6*(1+CN7) -> 175.23891 | CO6: =CJ6*(1+CO7) -> 190.04366 | CP6: =CK6*(1+CP7) -> 194.60312 | CQ6: =CL6*(1+CQ7) -> 217.79037 | CR6: =SUM(CN6:CQ6) -> 777.67605
A7: y/y growth | AY7: =AY6/AT6-1 -> 0.011465662 | BD7: =BD6/AY6-1 -> 0.10582277 | BI7: =BI6/BD6-1 -> 0.11518061 | BJ7: =BJ6/BE6-1 -> 0.090241292 | BK7: =BK6/BF6-1 -> -0.087018063 | BL7: =BL6/BG6-1 -> -0.04792439 | BM7: =BM6/BH6-1 -> -0.045647437 | BN7: =BN6/BI6-1 -> -0.026227646 | BO7: =BO6/BJ6-1 -> -0.11720833 | BP7: =BP6/BK6-1 -> -0.054332496 | ... CH7: =CH6/CC6-1 -> 0.090718306 | CI7: 0.1 | CJ7: 0.08 | CK7: 0.15 | CL7: 0.08 | CM7: =CM6/CH6-1 -> 0.10128658 | CN7: 0.05 | CO7: 0.05 | CP7: 0.05 | CQ7: 0.05 | CR7: =CR6/CM6-1 -> 0.05
A8: % of total | AT8: =AT6/AT77 -> 0.15784578 | AY8: =AY6/AY77 -> 0.1562922 | BD8: =BD6/BD77 -> 0.16754322 | BE8: =BE6/BE77 -> 0.16936419 | BF8: =BF6/BF77 -> 0.2055667 | BG8: =BG6/BG77 -> 0.22317808 | BH8: =BH6/BH77 -> 0.20388454 | BI8: =BI6/BI77 -> 0.19990737 | BJ8: =BJ6/BJ77 -> 0.18817643 | BK8: =BK6/BK77 -> 0.16406428 | ... CH8: =CH6/CH77 -> 0.1922397 | CM8: =CM6/CM77 -> 0.19808174 | CR8: =CR6/CR77 -> 0.19647926
A9: Guidance - Full Yr | BH9: 2-4% | BI9: =BH9 -> 2-4% | BJ9: 2-4% | BM9: 0-2% | BN9: =BM9 -> 0-2% | BP9: 9-11% | BQ9: 3-5% | BR9: 9-11% | BS9: =BR9 -> 9-11% | BT9: 9-11% | BU9: 9-11% | BV9: 11-13% | BW9: 5-7% | BX9: =BW9 -> 5-7% | BY9: 6-8% | BZ9: 7-9% | CA9: 9-11% | CB9: 6-8% | CC9: =CB9 -> 6-8% | CD9: 6-8% | CE9: 7-9% | CF9: 7-9% | CG9: 9-11% | CH9: =CG9 -> 9-11%
A11: Ground Defense | AT11: 96.042 | AY11: 97.131 | BD11: 93.432 | BE11: 22.657 | BF11: 20.029 | BG11: 20.519 | BH11: 44.963 | BI11: =SUM(BE11:BH11) -> 108.168 | BJ11: 56.826 | BK11: 49.301 | BL11: 56.204 | BM11: 61.559 | BN11: =SUM(BJ11:BM11) -> 223.89 | BO11: 39.108 | BP11: 44.393 | BQ11: 54.89 | BR11: 81.348 | BS11: =SUM(BO11:BR11) -> 219.739 | BT11: 66.256 | BU11: 70.875 | BV11: 83.185 | BW11: 87.691 | BX11: =SUM(BT11:BW11) -> 308.007 | BY11: 90.76 | BZ11: 84.939 | CA11: 92.973 | CB11: 84.654 | CC11: =SUM(BY11:CB11) -> 353.326 | CD11: 97.237 | CE11: 97.542 | CF11: 96.789 | CG11: 115.235 | CH11: =SUM(CD11:CG11) -> 406.803 | CI11: =CD11*(1+CI12) -> 93.34752 | CJ11: =CE11*(1+CJ12) -> 96.56658 | CK11: =CF11*(1+CK12) -> 96.789 | CL11: =CG11*(1+CL12) -> 103.7115 | CM11: =SUM(CI11:CL11) -> 390.4146 | CN11: =CI11*(1+CN12) -> 97.081421 | CO11: =CJ11*(1+CO12) -> 100.42924 | CP11: =CK11*(1+CP12) -> 100.66056 | CQ11: =CL11*(1+CQ12) -> 107.85996 | CR11: =SUM(CN11:CQ11) -> 406.03118
A12: y/y growth | AY12: =AY11/AT11-1 -> 0.011338789 | BD12: =BD11/AY11-1 -> -0.038082589 | BI12: =BI11/BD11-1 -> 0.15771898 | BJ12: =BJ11/BE11-1 -> 1.508099 | BK12: =BK11/BF11-1 -> 1.4614809 | BL12: =BL11/BG11-1 -> 1.7391198 | BM12: =BM11/BH11-1 -> 0.36910349 | BN12: =BN11/BI11-1 -> 1.0698358 | BO12: =BO11/BJ11-1 -> -0.3117939 | BP12: =BP11/BK11-1 -> -0.099551733 | ... CH12: =CH11/CC11-1 -> 0.15135314 | CI12: -0.04 | CJ12: -0.01 | CK12: 0 | CL12: -0.1 | CM12: =CM11/CH11-1 -> -0.040285839 | CN12: 0.04 | CO12: 0.04 | CP12: 0.04 | CQ12: 0.04 | CR12: =CR11/CM11-1 -> 0.04
A13: % of total | AT13: =AT11/AT77 -> 0.040678078 | AY13: =AY11/AY77 -> 0.040272655 | BD13: =BD11/BD77 -> 0.037553643 | BE13: =BE11/BE77 -> 0.037684351 | BF13: =BF11/BF77 -> 0.037598812 | BG13: =BG11/BG77 -> 0.037311207 | BH13: =BH11/BH77 -> 0.070094128 | BI13: =BI11/BI77 -> 0.046517028 | BJ13: =BJ11/BJ77 -> 0.096322274 | BK13: =BK11/BK77 -> 0.08090394 | ... CH13: =CH11/CH77 -> 0.11628352 | CM13: =CM11/CM77 -> 0.10441456 | CR13: =CR11/CR77 -> 0.10258347
A14: Guidance - Full Yr | BH14: 100-105% | BI14: =BH14 -> 100-105% | BM14: 2-4% | BN14: =BM14 -> 2-4% | BP14: (1-3)% | BQ14: (7-9)% | BR14: 4-6% | BS14: =BR14 -> 4-6% | BT14: 4-6% | BU14: 16-18% | BV14: 23-25% | BW14: 4-6% | BX14: =BW14 -> 4-6% | BY14: 10-12% | BZ14: 10-12% | CA14: 10-12% | CB14: 3-5% | CC14: =CB14 -> 3-5% | CD14: 6-8% | CE14: 6-8% | CF14: 6-8% | CG14: (4-6)% | CH14: =CG14 -> (4-6)%
A16: Naval Defense | AT16: 408.221 | AY16: 486.476 | BD16: 568.776 | BE16: 165.693 | BF16: 164.941 | BG16: 165.524 | BH16: 195.995 | BI16: =SUM(BE16:BH16) -> 692.153 | BJ16: 177.905 | BK16: 177.724 | BL16: 175.8 | BM16: 179.259 | BN16: =SUM(BJ16:BM16) -> 710.688 | BO16: 162.967 | BP16: 172.786 | BQ16: 174.844 | BR16: 183.418 | BS16: =SUM(BO16:BR16) -> 694.015 | BT16: 171.956 | BU16: 180.956 | BV16: 179.862 | BW16: 187.24 | BX16: =SUM(BT16:BW16) -> 720.014 | BY16: 177.647 | BZ16: 209.847 | CA16: 217.51 | CB16: 216.894 | CC16: =SUM(BY16:CB16) -> 821.898 | CD16: 221.086 | CE16: 240.086 | CF16: 245.906 | CG16: 234.576 | CH16: =SUM(CD16:CG16) -> 941.654 | CI16: =CD16*(1+CI17) -> 237.66745 | CJ16: =CE16*(1+CJ17) -> 254.49116 | CK16: =CF16*(1+CK17) -> 260.66036 | CL16: =CG16*(1+CL17) -> 246.3048 | CM16: =SUM(CI16:CL16) -> 999.12377 | CN16: =CI16*(1+CN17) -> 251.9275 | CO16: =CJ16*(1+CO17) -> 269.76063 | CP16: =CK16*(1+CP17) -> 276.29998 | CQ16: =CL16*(1+CQ17) -> 261.08309 | CR16: =SUM(CN16:CQ16) -> 1059.0712
A17: y/y growth | AY17: =AY16/AT16-1 -> 0.19169763 | BD17: =BD16/AY16-1 -> 0.16917587 | BI17: =BI16/BD16-1 -> 0.21691668 | BJ17: =BJ16/BE16-1 -> 0.07370257 | BK17: =BK16/BF16-1 -> 0.07750044 | BL17: =BL16/BG16-1 -> 0.062081632 | BM17: =BM16/BH16-1 -> -0.085389933 | BN17: =BN16/BI16-1 -> 0.026778761 | BO17: =BO16/BJ16-1 -> -0.083966162 | BP17: =BP16/BK16-1 -> -0.027784655 | ... CH17: =CH16/CC16-1 -> 0.14570664 | CI17: 0.075 | CJ17: 0.06 | CK17: 0.06 | CL17: 0.05 | CM17: =CM16/CH16-1 -> 0.061030665 | CN17: 0.06 | CO17: 0.06 | CP17: 0.06 | CQ17: 0.06 | CR17: =CR16/CM16-1 -> 0.06
A18: % of total | AT18: =AT16/AT77 -> 0.17289983 | AY18: =AY16/AY77 -> 0.20170368 | BD18: =BD16/BD77 -> 0.2286113 | BE18: =BE16/BE77 -> 0.27558958 | BF18: =BF16/BF77 -> 0.30963032 | BG18: =BG16/BG77 -> 0.30098447 | BH18: =BH16/BH77 -> 0.3055423 | BI18: =BI16/BI77 -> 0.29765643 | BJ18: =BJ16/BJ77 -> 0.30155588 | BK18: =BK16/BK77 -> 0.29164868 | ... CH18: =CH16/CH77 -> 0.2691692 | CM18: =CM16/CM77 -> 0.26721098 | CR18: =CR16/CR77 -> 0.26757352
A19: Guidance - Full Yr | BH19: 0 | BI19: =BH19 -> 0 | BK19: 0-2% | BM19: 1-3% | BN19: =BM19 -> 1-3% | BQ19: 0 | BR19: 4-6% | BS19: =BR19 -> 4-6% | BT19: 4-6% | BU19: 6-8% | BV19: 5-7% | BW19: 3-5% | BX19: =BW19 -> 3-5% | BY19: 3-5% | BZ19: 5-7% | CA19: 9-11% | CB19: 3-5% | CC19: =CB19 -> 3-5% | CD19: 5-7% | CE19: 7-9% | CF19: 9-11% | CG19: 5-7% | CH19: =CG19 -> 5-7%
A21: Total Defense Revenue | AT21: =AT16+AT11+AT6 -> 876.941 | AU21: =AU16+AU11+AU6 -> 0 | AV21: =AV16+AV11+AV6 -> 0 | AW21: =AW16+AW11+AW6 -> 0 | AX21: =AX16+AX11+AX6 -> 0 | AY21: =AY16+AY11+AY6 -> 960.558 | AZ21: =AZ16+AZ11+AZ6 -> 0 | BA21: =BA16+BA11+BA6 -> 0 | ... CR21: =CR16+CR11+CR6 -> 2242.7784
A22: y/y growth | AY22: =AY21/AT21-1 -> 0.09535077 | BD22: =BD21/AY21-1 -> 0.12335642 | BI22: =BI21/BD21-1 -> 0.17248985 | BJ22: =BJ21/BE21-1 -> 0.19150381 | BK22: =BK21/BF21-1 -> 0.11045382 | BL22: =BL21/BG21-1 -> 0.12979876 | BM22: =BM21/BH21-1 -> -0.016436086 | BN22: =BN21/BI21-1 -> 0.0964808 | BO22: =BO21/BJ21-1 -> -0.13208502 | BP22: =BP21/BK21-1 -> -0.046721427 | ... CR22: =CR21/CM21-1 -> 0.052857545
A23: % of total | AT23: =AT21/AT77 -> 0.37142369 | AU23: =AU21/AU77 -> #DIV/0! | AV23: =AV21/AV77 -> #DIV/0! | AW23: =AW21/AW77 -> #DIV/0! | AX23: =AX21/AX77 -> #DIV/0! | AY23: =AY21/AY77 -> 0.39826854 | AZ23: =AZ21/AZ77 -> #DIV/0! | BA23: =BA21/BA77 -> #DIV/0! | ... CR23: =CR21/CR77 -> 0.56663625
A26: Narrowbody | BI26: =BI27*BI30 -> 117.61025 | BN26: =BN27*BN30 -> 102.616 | BS26: =BS27*BS30 -> 132.72912 | BX26: =BX27*BX30 -> 165.72399 | CC26: =CC27*CC30 -> 204.16644 | CH26: =CH27*CH30 -> 232.25886 | CM26: =CM27*CM30 -> 252.71639
A27: % of total | BI27: 0.5 | BN27: 0.5 | BS27: 0.6 | BX27: 0.6 | CC27: 0.6 | CH27: 0.6 | CM27: 0.6
A28: Widebody | BI28: =BI30-BI26 -> 117.61025 | BN28: =BN30-BN26 -> 102.616 | BS28: =BS30-BS26 -> 88.48608 | BX28: =BX30-BX26 -> 110.48266 | CC28: =CC30-CC26 -> 136.11096 | CH28: =CH30-CH26 -> 154.83924 | CM28: =CM30-CM26 -> 168.47759
A29: % of total | BI29: =BI28/BI30 -> 0.5 | BN29: =BN28/BN30 -> 0.5 | BS29: =BS28/BS30 -> 0.4 | BX29: =BX28/BX30 -> 0.4 | CC29: =CC28/CC30 -> 0.4 | CH29: =CH28/CH30 -> 0.4 | CM29: =CM28/CM30 -> 0.4
A30: OEM | BI30: =BI31*BI34 -> 235.2205 | BN30: =BN31*BN34 -> 205.232 | BS30: =BS31*BS34 -> 221.2152 | BX30: =BX31*BX34 -> 276.20665 | CC30: =CC31*CC34 -> 340.2774 | CH30: =CH31*CH34 -> 387.0981 | CM30: =CM31*CM34 -> 421.19399
BI31: 0.85 | BN31: 0.8 | BS31: 0.8 | BX31: 0.85 | CC31: 0.9 | CH31: 0.9 | CM31: 0.88
A32: Aftermarket | BI32: =BI34-BI30 -> 41.5095 | BN32: =BN34-BN30 -> 51.308 | BS32: =BS34-BS30 -> 55.3038 | BX32: =BX34-BX30 -> 48.74235 | CC32: =CC34-CC30 -> 37.8086 | CH32: =CH34-CH30 -> 43.0109 | CM32: =CM34-CM30 -> 57.435544
BI33: =BI32/BI34 -> 0.15 | BN33: =BN32/BN34 -> 0.2 | BS33: =BS32/BS34 -> 0.2 | BX33: =BX32/BX34 -> 0.15 | CC33: =CC32/CC34 -> 0.1 | CH33: =CH32/CH34 -> 0.1 | CM33: =CM32/CM34 -> 0.12
A34: Commercial Aerospace | AT34: 409.384 | AY34: 414.422 | BD34: 433.038 | BE34: 100.68 | BF34: 59.374 | BG34: 54.419 | BH34: 62.257 | BI34: =SUM(BE34:BH34) -> 276.73 | BJ34: 54.67 | BK34: 65.771 | BL34: 67.08 | BM34: 69.019 | BN34: =SUM(BJ34:BM34) -> 256.54 | BO34: 60.892 | BP34: 68.192 | BQ34: 70.257 | BR34: 77.178 | BS34: =SUM(BO34:BR34) -> 276.519 | BT34: 70.49 | BU34: 82.033 | BV34: 79.703 | BW34: 92.723 | BX34: =SUM(BT34:BW34) -> 324.949 | BY34: 89.775 | BZ34: 93.316 | CA34: 96.677 | CB34: 98.318 | CC34: =SUM(BY34:CB34) -> 378.086 | CD34: 92.877 | CE34: 103.318 | CF34: 113.856 | CG34: 120.058 | CH34: =SUM(CD34:CG34) -> 430.109 | CI34: =CD34*(1+CI35) -> 106.80855 | CJ34: =CE34*(1+CJ35) -> 115.71616 | CK34: =CF34*(1+CK35) -> 125.2416 | CL34: =CG34*(1+CL35) -> 130.86322 | CM34: =SUM(CI34:CL34) -> 478.62953 | CN34: =CI34*(1+CN35) -> 114.28515 | CO34: =CJ34*(1+CO35) -> 123.81629 | CP34: =CK34*(1+CP35) -> 134.00851 | CQ34: =CL34*(1+CQ35) -> 140.02365 | CR34: =SUM(CN34:CQ34) -> 512.1336
A35: y/y growth | AY35: =AY34/AT34-1 -> 0.012306294 | BD35: =BD34/AY34-1 -> 0.044920395 | BI35: =BI34/BD34-1 -> -0.36095678 | BJ35: =BJ34/BE34-1 -> -0.45699245 | BK35: =BK34/BF34-1 -> 0.10774076 | BL35: =BL34/BG34-1 -> 0.23265771 | BM35: =BM34/BH34-1 -> 0.10861429 | BN35: =BN34/BI34-1 -> -0.072959202 | BO35: =BO34/BJ34-1 -> 0.11381013 | BP35: =BP34/BK34-1 -> 0.036809536 | ... CH35: =CH34/CC34-1 -> 0.13759568 | CI35: 0.15 | CJ35: 0.12 | CK35: 0.1 | CL35: 0.09 | CM35: =CM34/CH34-1 -> 0.11280985 | CN35: 0.07 | CO35: 0.07 | CP35: 0.07 | CQ35: 0.07 | CR35: =CR34/CM34-1 -> 0.07
A36: % of total | AT36: =AT34/AT77 -> 0.17339241 | AY36: =AY34/AY77 -> 0.1718285 | BD36: =BD34/BD77 -> 0.17405337 | BE36: =BE34/BE77 -> 0.16745644 | BF36: =BF34/BF77 -> 0.11145798 | BG36: =BG34/BG77 -> 0.098954072 | BH36: =BH34/BH77 -> 0.097054248 | BI36: =BI34/BI77 -> 0.11900615 | BJ36: =BJ34/BJ77 -> 0.092667771 | BK36: =BK34/BK77 -> 0.10793154 | ... CH36: =CH34/CH77 -> 0.12294547 | CM36: =CM34/CM77 -> 0.12800723 | CR36: =CR34/CR77 -> 0.12939016
A37: Guidance - Full Yr | BH37: 0 | BI37: =BH37 -> 0 | BM37: 9-11% | BN37: =BM37 -> 9-11% | BR37: 5-7% | BS37: =BR37 -> 5-7% | BT37: 5-7% | BU37: 9-11% | BV37: 14-16% | BW37: 10-12% | BX37: =BW37 -> 10-12% | BY37: 10-12% | BZ37: 13-15% | CA37: 16-18% | CB37: 10-12% | CC37: =CB37 -> 10-12% | CD37: 13-15% | CE37: 13-15% | CF37: 13-15% | CG37: 10-12% | CH37: =CG37 -> 10-12%
A40: Total Aerospace & Defense Revenue | AT40: =AT6+AT11+AT16+AT34 -> 1286.325 | AY40: =AY6+AY11+AY16+AY34 -> 1374.98 | BD40: =BD6+BD11+BD16+BD34 -> 1512.087 | BE40: =BE6+BE11+BE16+BE34 -> 390.857 | BF40: =BF6+BF11+BF16+BF34 -> 353.85 | BG40: =BG6+BG11+BG16+BG34 -> 363.197 | BH40: =BH6+BH11+BH16+BH34 -> 434 | BI40: =SUM(BE40:BH40) -> 1541.904 | BJ40: =BJ6+BJ11+BJ16+BJ34 -> 400.417 | BK40: =BK6+BK11+BK16+BK34 -> 392.773 | BL40: =BL6+BL11+BL16+BL34 -> 415.937 | BM40: =BM6+BM11+BM16+BM34 -> 434.652 | BN40: =SUM(BJ40:BM40) -> 1643.779 | BO40: =BO6+BO11+BO16+BO34 -> 360.971 | BP40: =BP6+BP11+BP16+BP34 -> 379.916 | BQ40: =BQ6+BQ11+BQ16+BQ34 -> 414.422 | BR40: =BR6+BR11+BR16+BR34 -> 514.707 | BS40: =SUM(BO40:BR40) -> 1670.016 | BT40: =BT6+BT11+BT16+BT34 -> 408.581 | BU40: =BU6+BU11+BU16+BU34 -> 466.056 | BV40: =BV6+BV11+BV16+BV34 -> 490.773 | BW40: =BW6+BW11+BW16+BW34 -> 539.181 | BX40: =SUM(BT40:BW40) -> 1904.591 | BY40: =BY6+BY11+BY16+BY34 -> 490.256 | BZ40: =BZ6+BZ11+BZ16+BZ34 -> 542.206 | CA40: =CA6+CA11+CA16+CA34 -> 566.14 | CB40: =CB6+CB11+CB16+CB34 -> 571.298 | CC40: =SUM(BY40:CB40) -> 2169.9 | CD40: =CD6+CD11+CD16+CD34 -> 562.922 | CE40: =CE6+CE11+CE16+CE34 -> 608.533 | CF40: =CF6+CF11+CF16+CF34 -> 617.713 | CG40: =CG6+CG11+CG16+CG34 -> 661.924 | CH40: =SUM(CD40:CG40) -> 2451.092 | CI40: =CI6+CI11+CI16+CI34 -> 604.71772 | CJ40: =CJ6+CJ11+CJ16+CJ34 -> 647.76786 | CK40: =CK6+CK11+CK16+CK34 -> 668.02726 | CL40: =CL6+CL11+CL16+CL34 -> 688.29892 | CM40: =SUM(CI40:CL40) -> 2608.8118 | CN40: =CN6+CN11+CN16+CN34 -> 638.53298 | CO40: =CO6+CO11+CO16+CO34 -> 684.04982 | CP40: =CP6+CP11+CP16+CP34 -> 705.57217 | CQ40: =CQ6+CQ11+CQ16+CQ34 -> 726.75706 | CR40: =SUM(CN40:CQ40) -> 2754.912
A41: y/y growth | AY41: =AY40/AT40-1 -> 0.068921151 | BD41: =BD40/AY40-1 -> 0.099715632 | BI41: =BI40/BD40-1 -> 0.019719103 | BJ41: =BJ40/BE40-1 -> 0.024459073 | BK41: =BK40/BF40-1 -> 0.10999859 | BL41: =BL40/BG40-1 -> 0.14521045 | BM41: =BM40/BH40-1 -> 0.0015023041 | BN41: =BN40/BI40-1 -> 0.06607091 | BO41: =BO40/BJ40-1 -> -0.098512301 | BP41: =BP40/BK40-1 -> -0.03273392 | ... CR41: =CR40/CM40-1 -> 0.056002611
A42: % of total | AT42: =AT40/AT77 -> 0.54481611 | AY42: =AY40/AY77 -> 0.57009704 | BD42: =BD40/BD77 -> 0.60776154 | BE42: =BE40/BE77 -> 0.65009456 | BF42: =BF40/BF77 -> 0.66425381 | BG42: =BG40/BG77 -> 0.66042783 | BH42: =BH40/BH77 -> 0.67657522 | BI42: =BI40/BI77 -> 0.66308698 | BJ42: =BJ40/BJ77 -> 0.67872235 | BK42: =BK40/BK77 -> 0.64454845 | ... CH42: =CH40/CH77 -> 0.7006379 | CM42: =CM40/CM77 -> 0.69771451 | CR42: =CR40/CR77 -> 0.6960264
A43: Guidance - Full Yr | BH43: 6-8% | BI43: 6-8% | BJ43: 7-9% | BM43: 2-4% | BN43: =BM43 -> 2-4% | BP43: 4-6% | BQ43: 1-3% | BR43: 6-8% | BS43: =BR43 -> 6-8% | BT43: 6-8% | BU43: 9-11% | BV43: 10-12% | BW43: 5-7% | BX43: =BW43 -> 5-7% | BY43: 6-8% | BZ43: 8-10% | CA43: 10-12% | CB43: 5-7% | CC43: =CB43 -> 5-7% | CD43: 7-9% | CE43: 8-10% | CF43: 10-11% | CG43: 5-7% | CH43: =CG43 -> 5-7%
A45: Commercial Revenue
A48: Aftermarket & Government | BS48: =BS49*BS52 -> 255.042 | BX48: =BX49*BX52 -> 275.39892 | CC48: =CC49*CC52 -> 292.02552 | CH48: =CH49*CH52 -> 342.9756 | CM48: =CM49*CM52 -> 410.77049
A49: % of total | BS49: 0.9 | BX49: 0.9 | CC49: 0.9 | CH49: 0.9 | CM49: 0.88
A50: New Build Gen III/IV (SMRs) | BS50: =BS52-BS48 -> 28.338 | BX50: =BX52-BX48 -> 30.59988 | CC50: =CC52-CC48 -> 32.44728 | CH50: =CH52-CH48 -> 38.1084 | CM50: =CM52-CM48 -> 56.014158
A51: % of total | BS51: =BS50/BS52 -> 0.1 | BX51: =BX50/BX52 -> 0.1 | CC51: =CC50/CC52 -> 0.1 | CH51: =CH50/CH52 -> 0.1 | CM51: =CM50/CM52 -> 0.12
...

Sheet CW_IS
B2: Curtiss-Wright Corporation
B3: Sales & Earnings Model
B4: ($ in millions; December fiscal year end)
B5: Period | C5: 1Q13 | D5: 2Q13 | E5: 3Q13 | F5: 4Q13 | G5: FY13 | H5: 1Q14 | I5: 2Q14 | J5: 3Q14 | K5: 4Q14 | L5: FY14 | M5: 1Q15 | N5: 2Q15 | O5: 3Q15 | P5: 4Q15 | Q5: FY15 | R5: 1Q16 | S5: 2Q16 | T5: 3Q16 | U5: 4Q16 | V5: FY16 | W5: 1Q17 | X5: 2Q17 | Y5: 3Q17 | Z5: 4Q17 | AA5: FY17 | AB5: 1Q18 | AC5: 2Q18 | AD5: 3Q18 | AE5: 4Q18 | AF5: FY18 | AG5: 1Q19 | AH5: 2Q19 | AI5: 3Q19 | AJ5: 4Q19 | AK5: FY19 | AL5: 1Q20 | AM5: 2Q20 | AN5: 3Q20 | AO5: 4Q20 | AP5: FY20 | AQ5: 1Q21 | AR5: 2Q21 | AS5: 3Q21 | AT5: 4Q21 | AU5: FY21 | AV5: 1Q22 | AW5: 2Q22 | AX5: 3Q22 | AY5: 4Q22 | AZ5: FY22 | BA5: 1Q23 | BB5: 2Q23 | BC5: 3Q23 | BD5: 4Q23 | BE5: FY23 | BF5: =CW_Drivers!BY3 -> 1Q24 | BG5: =CW_Drivers!BZ3 -> 2Q24 | BH5: =CW_Drivers!CA3 -> 3Q24 | BI5: =CW_Drivers!CB3 -> 4Q24 | BJ5: FY24 | BK5: =CW_Drivers!CD3 -> 1Q25 | BL5: =CW_Drivers!CE3 -> 2Q25 | BM5: =CW_Drivers!CF3 -> 3Q25 | BN5: =CW_Drivers!CG3 -> 4Q25 | BO5: FY25 | BP5: =CW_Drivers!CI3 -> 1Q26E | BQ5: =CW_Drivers!CJ3 -> 2Q26E | BR5: =CW_Drivers!CK3 -> 3Q26E | BS5: =CW_Drivers!CL3 -> 4Q26E | BT5: FY26E | BU5: =CW_Drivers!CN3 -> 1Q27E | BV5: =CW_Drivers!CO3 -> 2Q27E | BW5: =CW_Drivers!CP3 -> 3Q27E | BX5: =CW_Drivers!CQ3 -> 4Q27E | BY5: FY27E
B6: Fiscal Year Ends December | H6: 41729 | I6: 41820 | J6: 41912 | K6: 42004 | L6: FY 2014 | M6: =DATE(YEAR(H6)+1,MONTH(H6),DAY(H6)) -> 42094 | N6: =DATE(YEAR(I6)+1,MONTH(I6),DAY(I6)) -> 42185 | O6: =DATE(YEAR(J6)+1,MONTH(J6),DAY(J6)) -> 42277 | P6: =DATE(YEAR(K6)+1,MONTH(K6),DAY(K6)) -> 42369 | Q6: =CONCATENATE( "FY ", MID(L6,4,4)+1, IF(RIGHT(P5,1)="E", "E", "") ) -> FY 2015 | R6: =DATE(YEAR(M6)+1,MONTH(M6),DAY(M6)) -> 42460 | S6: =DATE(YEAR(N6)+1,MONTH(N6),DAY(N6)) -> 42551 | T6: =DATE(YEAR(O6)+1,MONTH(O6),DAY(O6)) -> 42643 | U6: =DATE(YEAR(P6)+1,MONTH(P6),DAY(P6)) -> 42735 | V6: =CONCATENATE( "FY ", MID(Q6,4,4)+1, IF(RIGHT(U5,1)="E", "E", "") ) -> FY 2016 | W6: =DATE(YEAR(R6)+1,MONTH(R6),DAY(R6)) -> 42825 | X6: =DATE(YEAR(S6)+1,MONTH(S6),DAY(S6)) -> 42916 | Y6: =DATE(YEAR(T6)+1,MONTH(T6),DAY(T6)) -> 43008 | Z6: =DATE(YEAR(U6)+1,MONTH(U6),DAY(U6)) -> 43100 | AA6: =CONCATENATE( "FY ", MID(V6,4,4)+1, IF(RIGHT(Z5,1)="E", "E", "") ) -> FY 2017 | AB6: =DATE(YEAR(W6)+1,MONTH(W6),DAY(W6)) -> 43190 | AC6: =DATE(YEAR(X6)+1,MONTH(X6),DAY(X6)) -> 43281 | AD6: =DATE(YEAR(Y6)+1,MONTH(Y6),DAY(Y6)) -> 43373 | AE6: =DATE(YEAR(Z6)+1,MONTH(Z6),DAY(Z6)) -> 43465 | AF6: =CONCATENATE( "FY ", MID(AA6,4,4)+1, IF(RIGHT(AE5,1)="E", "E", "") ) -> FY 2018 | AG6: =DATE(YEAR(AB6)+1,MONTH(AB6),DAY(AB6)) -> 43555 | AH6: =DATE(YEAR(AC6)+1,MONTH(AC6),DAY(AC6)) -> 43646 | AI6: =DATE(YEAR(AD6)+1,MONTH(AD6),DAY(AD6)) -> 43738 | AJ6: =DATE(YEAR(AE6)+1,MONTH(AE6),DAY(AE6)) -> 43830 | AK6: =CONCATENATE( "FY ", MID(AF6,4,4)+1, IF(RIGHT(AJ5,1)="E", "E", "") ) -> FY 2019 | AL6: =DATE(YEAR(AG6)+1,MONTH(AG6),DAY(AG6)) -> 43921 | AM6: =DATE(YEAR(AH6)+1,MONTH(AH6),DAY(AH6)) -> 44012 | AN6: =DATE(YEAR(AI6)+1,MONTH(AI6),DAY(AI6)) -> 44104 | AO6: =DATE(YEAR(AJ6)+1,MONTH(AJ6),DAY(AJ6)) -> 44196 | AP6: =CONCATENATE( "FY ", MID(AK6,4,4)+1, IF(RIGHT(AO5,1)="E", "E", "") ) -> FY 2020 | AQ6: =DATE(YEAR(AL6)+1,MONTH(AL6),DAY(AL6)) -> 44286 | AR6: =DATE(YEAR(AM6)+1,MONTH(AM6),DAY(AM6)) -> 44377 | AS6: =DATE(YEAR(AN6)+1,MONTH(AN6),DAY(AN6)) -> 44469 | AT6: =DATE(YEAR(AO6)+1,MONTH(AO6),DAY(AO6)) -> 44561 | AU6: =CONCATENATE( "FY ", MID(AP6,4,4)+1, IF(RIGHT(AT5,1)="E", "E", "") ) -> FY 2021 | AV6: =DATE(YEAR(AQ6)+1,MONTH(AQ6),DAY(AQ6)) -> 44651 | AW6: =DATE(YEAR(AR6)+1,MONTH(AR6),DAY(AR6)) -> 44742 | AX6: =DATE(YEAR(AS6)+1,MONTH(AS6),DAY(AS6)) -> 44834 | AY6: =DATE(YEAR(AT6)+1,MONTH(AT6),DAY(AT6)) -> 44926 | AZ6: =CONCATENATE( "FY ", MID(AU6,4,4)+1, IF(RIGHT(AY5,1)="E", "E", "") ) -> FY 2022 | BA6: =DATE(YEAR(AV6)+1,MONTH(AV6),DAY(AV6)) -> 45016 | BB6: =DATE(YEAR(AW6)+1,MONTH(AW6),DAY(AW6)) -> 45107 | BC6: =DATE(YEAR(AX6)+1,MONTH(AX6),DAY(AX6)) -> 45199 | BD6: =DATE(YEAR(AY6)+1,MONTH(AY6),DAY(AY6)) -> 45291 | BE6: =CONCATENATE( "FY ", MID(AZ6,4,4)+1, IF(RIGHT(BD5,1)="E", "E", "") ) -> FY 2023 | BF6: =DATE(YEAR(BA6)+1,MONTH(BA6),DAY(BA6)) -> 45382 | BG6: =DATE(YEAR(BB6)+1,MONTH(BB6),DAY(BB6)) -> 45473 | BH6: =DATE(YEAR(BC6)+1,MONTH(BC6),DAY(BC6)) -> 45565 | BI6: =DATE(YEAR(BD6)+1,MONTH(BD6),DAY(BD6)) -> 45657 | BJ6: =CONCATENATE( "FY ", MID(BE6,4,4)+1, IF(RIGHT(BI5,1)="E", "E", "") ) -> FY 2024 | BK6: =DATE(YEAR(BF6)+1,MONTH(BF6),DAY(BF6)) -> 45747 | BL6: =DATE(YEAR(BG6)+1,MONTH(BG6),DAY(BG6)) -> 45838 | BM6: =DATE(YEAR(BH6)+1,MONTH(BH6),DAY(BH6)) -> 45930 | BN6: =DATE(YEAR(BI6)+1,MONTH(BI6),DAY(BI6)) -> 46022 | BO6: =CONCATENATE( "FY ", MID(BJ6,4,4)+1, IF(RIGHT(BN5,1)="E", "E", "") ) -> FY 2025 | BP6: =DATE(YEAR(BK6)+1,MONTH(BK6),DAY(BK6)) -> 46112 | BQ6: =DATE(YEAR(BL6)+1,MONTH(BL6),DAY(BL6)) -> 46203 | BR6: =DATE(YEAR(BM6)+1,MONTH(BM6),DAY(BM6)) -> 46295 | BS6: =DATE(YEAR(BN6)+1,MONTH(BN6),DAY(BN6)) -> 46387 | BT6: =CONCATENATE( "FY ", MID(BO6,4,4)+1, IF(RIGHT(BS5,1)="E", "E", "") ) -> FY 2026E | BU6: =DATE(YEAR(BP6)+1,MONTH(BP6),DAY(BP6)) -> 46477 | BV6: =DATE(YEAR(BQ6)+1,MONTH(BQ6),DAY(BQ6)) -> 46568 | BW6: =DATE(YEAR(BR6)+1,MONTH(BR6),DAY(BR6)) -> 46660 | BX6: =DATE(YEAR(BS6)+1,MONTH(BS6),DAY(BS6)) -> 46752 | BY6: =CONCATENATE( "FY ", MID(BT6,4,4)+1, IF(RIGHT(BX5,1)="E", "E", "") ) -> FY 2027E
B8: Aerospace & Industrial | C8: 249.2 | D8: 272.8 | E8: 272.7 | F8: 281.4 | G8: =SUM(C8:F8) -> 1076.1 | H8: 300.953 | I8: 313.798 | J8: 312.808 | K8: 300.538 | AG8: 215.21941 | AH8: 230.30368 | AI8: 218.06607 | AJ8: 228.8875 | AK8: =SUM(AG8:AJ8) -> 892.47666 | AL8: 208.03326 | AM8: 165.70081 | AN8: 172.24312 | AO8: 192.21352 | AP8: =SUM(AL8:AO8) -> 738.19071 | AQ8: 177.7 | AR8: 193.9 | AS8: 195.9 | AT8: 207.576 | AU8: =SUM(AQ8:AT8) -> 775.076 | AV8: 191.112 | AW8: 208.572 | AX8: 213.093 | AY8: 223.258 | AZ8: =SUM(AV8:AY8) -> 836.035 | BA8: 202.447 | BB8: 226.26 | BC8: 220.297 | BD8: 238.224 | BE8: =SUM(BA8:BD8) -> 887.228 | BF8: 219.325 | BG8: 233.232 | BH8: 228.659 | BI8: 250.917 | BJ8: =SUM(BF8:BI8) -> 932.133 | BK8: 227.246 | BL8: 239.138 | BM8: 247.985 | BN8: 262.391 | BO8: =SUM(BK8:BN8) -> 976.76
B9: Y/Y Growth | H9: =H8/C8-1 -> 0.20767657 | I9: =I8/D8-1 -> 0.15028592 | J9: =J8/E8-1 -> 0.14707737 | K9: =K8/F8-1 -> 0.06800995 | AL9: =AL8/AG8-1 -> -0.03338987 | AM9: =AM8/AH8-1 -> -0.28051167 | AN9: =AN8/AI8-1 -> -0.21013333 | AO9: =AO8/AJ8-1 -> -0.1602271 | AP9: =AP8/AK8-1 -> -0.17287393 | AQ9: =AQ8/AL8-1 -> -0.14580965 | AR9: =AR8/AM8-1 -> 0.17018137 | AS9: =AS8/AN8-1 -> 0.13734584 | ... BO9: =BO8/BJ8-1 -> 0.047876215
B10: Forward Year Guidance | AV10: 805-825 | AW10: 820-840 | AY10: 845-860 | AZ10: =AY10 -> 845-860 | BA10: 845-860 | BB10: 865-885 | BC10: 873-888 | BD10: 915-930 | BE10: =BD10 -> 915-930 | BF10: 915-930 | BG10: 925-940 | BH10: 925-940 | BI10: 960-975 | BJ10: =BI10 -> 960-975 | BK10: 960-975 | BL10: 965-980 | BM10: 970-980 | BN10: 1030-1045 | BO10: =BN10 -> 1030-1045
BT11: {=_xll.FDS("CW-US","FE_ESTIMATE(PRODLINE_SALES_1,MEAN,ANN_ROLL,+1,NOW,,,'')")} -> 1027.8357 | BY11: {=_xll.FDS("CW-US","FE_ESTIMATE(PRODLINE_SALES_1,MEAN,ANN_ROLL,+2,NOW,,,'')")} -> 1072.335
B12: Organic | AQ12: -0.22 | AR12: 0.1 | AS12: 0.03 | AT12: =+AT9 -> 0.079924047 | AU12: =((AQ12*AL$8)+(AR12*AM$8)+(AS12*AN$8)+(AT12*AO$8))/AP$8 -> -0.011741491 | AV12: 0.07 | AW12: 0.07 | AX12: 0.12 | AY12: 0.11 | AZ12: =((AV12*AQ$8)+(AW12*AR$8)+(AX12*AS$8)+(AY12*AT$8))/AU$8 -> 0.09335002 | BA12: 0.08 | BB12: 0.09 | BC12: 0.02 | BD12: 0.06 | BE12: =((BA12*AV$8)+(BB12*AW$8)+(BC12*AX$8)+(BD12*AY$8))/AZ$8 -> 0.061860783 | BF12: 0.08 | BG12: 0.03 | BH12: 0.03 | BI12: 0.05 | BJ12: =((BF12*BA$8)+(BG12*BB$8)+(BH12*BC$8)+(BI12*BD$8))/BE$8 -> 0.046779035 | BK12: 0.04 | BL12: 0.02 | BM12: 0.08 | BN12: 0.04 | BO12: =((BK12*BF$8)+(BL12*BG$8)+(BM12*BH$8)+(BN12*BI$8))/BJ$8 -> 0.044808026 | BT12: =BT11/BO8-1 -> 0.052290941 | BY12: =BY11/BT11-1 -> 0.043294176
B13: Acq. / Divest | AQ13: 0 | AR13: 0 | AS13: 0 | AT13: 0 | AU13: =((AQ13*AL$8)+(AR13*AM$8)+(AS13*AN$8)+(AT13*AO$8))/AP$8 -> 0 | AV13: 0 | AW13: 0 | AX13: 0 | AY13: 0.01 | AZ13: =((AV13*AQ$8)+(AW13*AR$8)+(AX13*AS$8)+(AY13*AT$8))/AU$8 -> 0.0026781374 | BA13: 0 | BB13: 0 | BC13: 0 | BD13: 0 | BE13: =((BA13*AV$8)+(BB13*AW$8)+(BC13*AX$8)+(BD13*AY$8))/AZ$8 -> 0 | BF13: 0 | BG13: 0 | BH13: 0 | BI13: 0 | BJ13: =((BF13*BA$8)+(BG13*BB$8)+(BH13*BC$8)+(BI13*BD$8))/BE$8 -> 0 | BK13: 0 | BL13: 0 | BM13: 0 | BN13: 0 | BO13: =((BK13*BF$8)+(BL13*BG$8)+(BM13*BH$8)+(BN13*BI$8))/BJ$8 -> 0
B14: FX | AQ14: 0.02 | AR14: 0.03 | AS14: 0.01 | AT14: 0 | AU14: =((AQ14*AL$8)+(AR14*AM$8)+(AS14*AN$8)+(AT14*AO$8))/AP$8 -> 0.014703681 | AV14: 0.01 | AW14: -0.03 | AX14: 0.03 | AY14: 0.04 | AZ14: =((AV14*AQ$8)+(AW14*AR$8)+(AX14*AS$8)+(AY14*AT$8))/AU$8 -> 0.01308264 | BA14: 0.02 | BB14: 0.01 | BC14: -0.01 | BD14: -0.01 | BE14: =((BA14*AV$8)+(BB14*AW$8)+(BC14*AX$8)+(BD14*AY$8))/AZ$8 -> 0.0018473509 | BF14: 0 | BG14: 0 | BH14: -0.01 | BI14: 0 | BJ14: =((BF14*BA$8)+(BG14*BB$8)+(BH14*BC$8)+(BI14*BD$8))/BE$8 -> -0.0024829807 | BK14: 0 | BL14: 0.01 | BM14: 0 | BN14: -0.01 | BO14: =((BK14*BF$8)+(BL14*BG$8)+(BM14*BH$8)+(BN14*BI$8))/BJ$8 -> -0.00018972614
B16: Commercial Aerospace | AP16: =+(AP$8-AP$20)*(28/(28+21)) -> 234.57412 | AU16: =+(AU$8-AU$20)*(26/(26+21)) -> 217.95468 | AZ16: =+AZ8-AZ18-AZ20 -> 233.07396 | BE16: =+BE8-BE18-BE20 -> 252.50149 | BJ16: =+BJ8-BJ18-BJ20 -> 288.56238 | BO16: =+BO8-BO18-BO20 -> 312.34298
B17: y/y | AU17: =+AU16/AP16-1 -> -0.070849409 | AZ17: =+AZ16/AU16-1 -> 0.069368901 | BE17: =+BE16/AZ16-1 -> 0.083353508 | BJ17: =+BJ16/BE16-1 -> 0.14281458 | BO17: =+BO16/BJ16-1 -> 0.082410588
B18: Aerospace Defense | AP18: =+(AP$8-AP$20)*(21/(28+21)) -> 175.93059 | AU18: =+(AU$8-AU$20)*(21/(26+21)) -> 176.04032 | AZ18: =+(AZ$8-AZ$20)*(21/(26+21)) -> 188.25204 | BE18: =+(BE$8-BE$20)*(21/(26+21)) -> 203.94351 | BJ18: =+(BJ$8-BJ$20)*(21/(26+21)) -> 233.06962 | BO18: =+(BO$8-BO$20)*(21/(26+21)) -> 252.27702
B19: y/y | AU19: =+AU18/AP18-1 -> 0.00062371356 | AZ19: =+AZ18/AU18-1 -> 0.069368901 | BE19: =+BE18/AZ18-1 -> 0.083353508 | BJ19: =+BJ18/BE18-1 -> 0.14281458 | BO19: =+BO18/BJ18-1 -> 0.082410588
B20: General Industrial | AP20: 327.686 | AU20: 381.081 | AZ20: 414.709 | BE20: 430.783 | BJ20: 410.501 | BO20: 412.14
B21: y/y | AU21: =+AU20/AP20-1 -> 0.16294562 | AW21: MSD | AZ21: =+AZ20/AU20-1 -> 0.088243707 | BE21: =+BE20/AZ20-1 -> 0.038759709 | BJ21: =+BJ20/BE20-1 -> -0.047081709 | BO21: =+BO20/BJ20-1 -> 0.0039926821
B23: Defense Electronics | C23: 108.1 | D23: 113.4 | E23: 105.8 | F23: 153 | G23: =SUM(C23:F23) -> 480.3 | H23: 112.371 | I23: 118.507 | J23: 127.061 | K23: 131.918 | AG23: 110.30102 | AH23: 133.70865 | AI23: 134.96496 | AJ23: 146.46782 | AK23: =SUM(AG23:AJ23) -> 525.44245 | AL23: 139.581 | AM23: 139.812 | AN23: 149.073 | AO23: 182.173 | AP23: =SUM(AL23:AO23) -> 610.639 | AQ23: 182.3 | AR23: 163.4 | AS23: 182.6 | AT23: 199.619 | AU23: =SUM(AQ23:AT23) -> 727.919 | AV23: 143.069 | AW23: 149.549 | AX23: 161.188 | AY23: 236.456 | AZ23: =SUM(AV23:AY23) -> 690.262 | BA23: 162.154 | BB23: 197.722 | BC23: 216.285 | BD23: 239.751 | BE23: =SUM(BA23:BD23) -> 815.912 | BF23: 211.741 | BG23: 228.461 | BH23: 243.029 | BI23: 227.475 | BJ23: =SUM(BF23:BI23) -> 910.706 | BK23: 245.164 | BL23: 253.011 | BM23: 253.159 | BN23: 267.276 | BO23: =SUM(BK23:BN23) -> 1018.61
B24: Y/Y Growth | H24: =H23/C23-1 -> 0.039509713 | I24: =I23/D23-1 -> 0.045035273 | J24: =J23/E23-1 -> 0.20095463 | K24: =K23/F23-1 -> -0.13779085 | AL24: =AL23/AG23-1 -> 0.26545515 | AM24: =AM23/AH23-1 -> 0.045646668 | AN24: =AN23/AI23-1 -> 0.10453111 | AO24: =AO23/AJ23-1 -> 0.2437749 | AP24: =AP23/AK23-1 -> 0.16214249 | AQ24: =AQ23/AL23-1 -> 0.30605168 | AR24: =AR23/AM23-1 -> 0.16871227 | AS24: =AS23/AN23-1 -> 0.22490324 | ... BO24: =BO23/BJ23-1 -> 0.1184839
B25: Forward Year Guidance | AV25: 745-760 | AW25: 720-735 | AX25: 675-690 | AY25: 725-750 | AZ25: =AY25 -> 725-750 | BA25: 725-750 | BB25: 755-775 | BC25: 775-790 | BD25: 857-872 | BE25: =BD25 -> 857-872 | BF25: 882-897 | BG25: 882-897 | BH25: 892-907 | BI25: 975-990 | BJ25: =BI25 -> 975-990 | BK25: 995-1010 | BL25: 995-1010 | BM25: 1000-1010 | BN25: 1055-1075 | BO25: =BN25 -> 1055-1075
B26: Consensus | BT26: {=_xll.FDS("CW-US","FE_ESTIMATE(PRODLINE_SALES_2,MEAN,ANN_ROLL,+1,NOW,,,'')")} -> 1082.9347 | BY26: {=_xll.FDS("CW-US","FE_ESTIMATE(PRODLINE_SALES_2,MEAN,ANN_ROLL,+2,NOW,,,'')")} -> 1167.366
B27: Organic | AQ27: 0.04 | AR27: -0.06 | AS27: -0.03 | AT27: 0.04 | AU27: =((AQ27*AL$23)+(AR27*AM$23)+(AS27*AN$23)+(AT27*AO$23))/AP$23 -> 1.5148066e-05 | AV27: -0.21 | AW27: -0.07 | AX27: -0.1 | AY27: 0.185 | AZ27: =((AV27*AQ$23)+(AW27*AR$23)+(AX27*AS$23)+(AY27*AT$23))/AU$23 -> -0.042657885 | BA27: 0.14 | BB27: 0.32 | BC27: 0.33 | BD27: 0.01 | BE27: =((BA27*AV$23)+(BB27*AW$23)+(BC27*AX$23)+(BD27*AY$23))/AZ$23 -> 0.17883346 | BF27: 0.31 | BG27: 0.16 | BH27: 0.12 | BI27: -0.05 | BJ27: =((BF27*BA$23)+(BG27*BB$23)+(BH27*BC$23)+(BI27*BD$23))/BE$23 -> 0.11750031 | BK27: 0.16 | BL27: 0.1 | BM27: 0.04 | BN27: 0.17 | BO27: =((BK27*BF$23)+(BL27*BG$23)+(BM27*BH$23)+(BN27*BI$23))/BJ$23 -> 0.11542317 | BT27: =BT26/BO23-1 -> 0.063149488 | BY27: =BY26/BT26-1 -> 0.077965273
B28: Acq. / Divest | AQ28: 0.25 | AR28: 0.22 | AS28: 0.25 | AT28: 0.06 | AU28: =((AQ28*AL$23)+(AR28*AM$23)+(AS28*AN$23)+(AT28*AO$23))/AP$23 -> 0.18644816 | AV28: 0 | AW28: 0 | AX28: 0 | AY28: 0 | AZ28: =((AV28*AQ$23)+(AW28*AR$23)+(AX28*AS$23)+(AY28*AT$23))/AU$23 -> 0 | BA28: 0 | BB28: 0 | BC28: 0 | BD28: 0 | BE28: =((BA28*AV$23)+(BB28*AW$23)+(BC28*AX$23)+(BD28*AY$23))/AZ$23 -> 0 | BF28: 0 | BG28: 0 | BH28: 0 | BI28: 0 | BJ28: =((BF28*BA$23)+(BG28*BB$23)+(BH28*BC$23)+(BI28*BD$23))/BE$23 -> 0 | BK28: 0 | BL28: 0 | BM28: 0 | BN28: 0 | BO28: =((BK28*BF$23)+(BL28*BG$23)+(BM28*BH$23)+(BN28*BI$23))/BJ$23 -> 0
B29: FX | AQ29: 0.01 | AR29: 0 | AS29: 0 | AT29: 0 | AU29: =((AQ29*AL$23)+(AR29*AM$23)+(AS29*AN$23)+(AT29*AO$23))/AP$23 -> 0.0022858186 | AV29: 0 | AW29: 0.01 | AX29: -0.01 | AY29: 0 | AZ29: =((AV29*AQ$23)+(AW29*AR$23)+(AX29*AS$23)+(AY29*AT$23))/AU$23 -> -0.00026376561 | BA29: 0.01 | BB29: 0 | BC29: -0.01 | BD29: 0 | BE29: =((BA29*AV$23)+(BB29*AW$23)+(BC29*AX$23)+(BD29*AY$23))/AZ$23 -> -0.00026249453 | BF29: -0.01 | BG29: 0 | BH29: 0 | BI29: 0 | BJ29: =((BF29*BA$23)+(BG29*BB$23)+(BH29*BC$23)+(BI29*BD$23))/BE$23 -> -0.0019873957 | BK29: 0 | BL29: 0.01 | BM29: 0 | BN29: 0 | BO29: =((BK29*BF$23)+(BL29*BG$23)+(BM29*BH$23)+(BN29*BI$23))/BJ$23 -> 0.0025086142
B31: Commercial Aerospace | AP31: =+(AP$23-AP$35-AP$37)*(7/(7+45)) -> 38.653418 | AU31: =+(AU$23-AU$35-AU$37)*(6/(6+45)) -> 37.061765 | AZ31: =276.519-AZ16 -> 43.445043 | BE31: =324.949-BE16 -> 72.447511 | BJ31: =378.086-BJ16 -> 89.523617 | BO31: =430.109-BO16 -> 117.76602
B32: y/y | AU32: =+AU31/AP31-1 -> -0.041177561 | AZ32: =+AZ31/AU31-1 -> 0.17223351 | BE32: =+BE31/AZ31-1 -> 0.6675668 | BJ32: =+BJ31/BE31-1 -> 0.23570315 | BO32: =+BO31/BJ31-1 -> 0.31547434
B33: Aerospace Defense | AP33: =+(AP$23-AP$35-AP$37)*(45/(7+45)) -> 248.48626 | AU33: =+(AU$23-AU$35-AU$37)*(45/(6+45)) -> 277.96324 | AZ33: =479.743-AZ18 -> 291.49096 | BE33: =551.622-BE18 -> 347.67849 | BJ33: =616.59-BJ18 -> 383.52038 | BO33: =672.526-BO18 -> 420.24898
B34: y/y | AU34: =+AU33/AP33-1 -> 0.11862618 | AZ34: =+AZ33/AU33-1 -> 0.048667307 | BE34: =+BE33/AZ33-1 -> 0.19275909 | BJ34: =+BJ33/BE33-1 -> 0.10308919 | BO34: =+BO33/BJ33-1 -> 0.095766998
B35: Ground Defense | AP35: 107.448 | AU35: 223.89 | AZ35: 219.739 | BE35: 308.008 | BJ35: 353.326 | BO35: 406.803
B36: y/y | AU36: =+AU35/AP35-1 -> 1.0837056 | AZ36: =+AZ35/AU35-1 -> -0.018540355 | BE36: =+BE35/AZ35-1 -> 0.40169929 | BJ36: =+BJ35/BE35-1 -> 0.14713254 | BO36: =+BO35/BJ35-1 -> 0.15135314
B37: Naval Defense | AP37: =692.152-AP48 -> 216.05132 | AU37: =710.688-AU48 -> 189.004 | AZ37: =694.015-AZ48 -> 135.587 | BE37: =720.013-BE48 -> 87.778 | BJ37: =821.898-BJ48 -> 84.336 | BO37: =941.654-BO48 -> 73.792
B38: y/y | AU38: =+AU37/AP37-1 -> -0.12518934 | AZ38: =+AZ37/AU37-1 -> -0.28262365 | BE38: =+BE37/AZ37-1 -> -0.35260755 | BJ38: =+BJ37/BE37-1 -> -0.039212559 | BO38: =+BO37/BJ37-1 -> -0.12502371
B40: Naval & Power | C40: 137.1 | D40: 137.9 | E40: 132.9 | F40: 153.8 | G40: =SUM(C40:F40) -> 561.7 | H40: 129.635 | I40: 136.893 | J40: 118.514 | K40: 140.13 | AG40: 229.40577 | AH40: 247.97098 | AI40: 233.41161 | AJ40: 250.09977 | AK40: =SUM(AG40:AJ40) -> 960.88813 | AL40: 228.04815 | AM40: 227.18944 | AN40: 228.62577 | AO40: 267.07931 | AP40: =SUM(AL40:AO40) -> 950.94268 | AQ40: 229.9 | AR40: 252 | AS40: 235.3 | AT40: 248.104 | AU40: =SUM(AQ40:AT40) -> 965.304 | AV40: 225.28 | AW40: 251.236 | AX40: 256.261 | AY40: 297.951 | AZ40: =SUM(AV40:AY40) -> 1030.728 | BA40: 266.259 | BB40: 280.414 | BC40: 287.744 | BD40: 307.816 | BE40: =SUM(BA40:BD40) -> 1142.233 | BF40: 282.101 | BG40: 323.098 | BH40: 327.23 | BI40: 345.921 | BJ40: =SUM(BF40:BI40) -> 1278.35 | BK40: 333.235 | BL40: 384.427 | BM40: 368.026 | BN40: 417.314 | BO40: =SUM(BK40:BN40) -> 1503.002
B41: Y/Y Growth | H41: =H40/C40-1 -> -0.054449307 | I41: =I40/D40-1 -> -0.007302393 | J41: =J40/E40-1 -> -0.1082468 | K41: =K40/F40-1 -> -0.088881664 | AL41: =AL40/AG40-1 -> -0.0059179569 | AM41: =AM40/AH40-1 -> -0.083806329 | AN41: =AN40/AI40-1 -> -0.020503848 | AO41: =AO40/AJ40-1 -> 0.067891053 | AP41: =AP40/AK40-1 -> -0.010350268 | AQ41: =AQ40/AL40-1 -> 0.0081204165 | AR41: =AR40/AM40-1 -> 0.10920647 | AS41: =AS40/AN40-1 -> 0.029192816 | ... BO41: =BO40/BJ40-1 -> 0.17573591
B42: Forward Year Guidance | AV42: 980-995 | AW42: 1030-1045 | AY42: 1085-1100 | AZ42: =AY42 -> 1085-1100 | BA42: 1085-1100 | BB42: 1110-1130 | BC42: 1117-1137 | BD42: 1188-1208 | BE42: =BD42 -> 1188-1208 | BF42: 1188-1208 | BG42: 1203-1223 | BH42: 1233-1248 | BI42: 1400-1420 | BJ42: =BI42 -> 1400-1420 | BK42: 1410-1430 | BL42: 1430-1445 | BM42: 1450-1465 | BN42: 1625-1645 | BO42: =BN42 -> 1625-1645
B43: Consensus | BT43: {=_xll.FDS("CW-US","FE_ESTIMATE(PRODLINE_SALES_3,MEAN,ANN_ROLL,+1,NOW,,,'')")} -> 1592.35 | BY43: {=_xll.FDS("CW-US","FE_ESTIMATE(PRODLINE_SALES_3,MEAN,ANN_ROLL,+2,NOW,,,'')")} -> 1752.518
B44: Organic | AQ44: -0.01 | AR44: 0.1 | AS44: 0.03 | AT44: =+AT41 -> -0.071047476 | AU44: =((AQ44*AL$40)+(AR44*AM$40)+(AS44*AN$40)+(AT44*AO$40))/AP$40 -> 0.0087512371 | AV44: -0.04 | AW44: -0.03 | AX44: 0 | AY44: 0.12 | AZ44: =((AV44*AQ$40)+(AW44*AR$40)+(AX44*AS$40)+(AY44*AT$40))/AU$40 -> 0.013484332 | BA44: 0.11 | BB44: 0.03 | BC44: 0.12 | BD44: 0.03 | BE44: =((BA44*AV$40)+(BB44*AW$40)+(BC44*AX$40)+(BD44*AY$40))/AZ$40 -> 0.06986104 | BF44: 0.06 | BG44: 0.14 | BH44: 0.13 | BI44: 0.12 | BJ44: =((BF44*BA$40)+(BG44*BB$40)+(BH44*BC$40)+(BI44*BD$40))/BE$40 -> 0.11344283 | BK44: 0.18 | BL44: 0.12 | BM44: 0.08 | BN44: 0.13 | BO44: =((BK44*BF$40)+(BL44*BG$40)+(BM44*BH$40)+(BN44*BI$40))/BJ$40 -> 0.12570741 | BT44: =BT43/BO40-1 -> 0.059446361 | BY44: =BY43/BT43-1 -> 0.10058593
B45: Acq. / Divest | AQ45: 0.01 | AR45: 0 | AS45: 0 | AT45: 0 | AU45: =((AQ45*AL$40)+(AR45*AM$40)+(AS45*AN$40)+(AT45*AO$40))/AP$40 -> 0.0023981272 | AV45: 0 | AW45: 0 | AX45: -0.06 | AY45: 0.09 | AZ45: =((AV45*AQ$40)+(AW45*AR$40)+(AX45*AS$40)+(AY45*AT$40))/AU$40 -> 0.0085065016 | BA45: -0.07 | BB45: -0.09 | BC45: 0 | BD45: 0 | BE45: =((BA45*AV$40)+(BB45*AW$40)+(BC45*AX$40)+(BD45*AY$40))/AZ$40 -> -0.037236633 | BF45: 0 | BG45: -0.01 | BH45: -0.01 | BI45: 0 | BJ45: =((BF45*BA$40)+(BG45*BB$40)+(BH45*BC$40)+(BI45*BD$40))/BE$40 -> -0.004974099 | BK45: -0.07 | BL45: 0 | BM45: -0.04 | BN45: -0.08 | BO45: =((BK45*BF$40)+(BL45*BG$40)+(BM45*BH$40)+(BN45*BI$40))/BJ$40 -> -0.047334415
B46: FX | AQ46: 0 | AR46: 0.01 | AS46: 0.01 | AT46: 0 | AU46: =((AQ46*AL$40)+(AR46*AM$40)+(AS46*AN$40)+(AT46*AO$40))/AP$40 -> 0.0047932985 | AV46: 0 | AW46: 0 | AX46: 0 | AY46: -0.01 | AZ46: =((AV46*AQ$40)+(AW46*AR$40)+(AX46*AS$40)+(AY46*AT$40))/AU$40 -> -0.0025702162 | BA46: 0 | BB46: 0 | BC46: 0 | BD46: 0 | BE46: =((BA46*AV$40)+(BB46*AW$40)+(BC46*AX$40)+(BD46*AY$40))/AZ$40 -> 0 | BF46: 0 | BG46: 0 | BH46: 0 | BI46: 0 | BJ46: =((BF46*BA$40)+(BG46*BB$40)+(BH46*BC$40)+(BI46*BD$40))/BE$40 -> 0 | BK46: 0.01 | BL46: 0.07 | BM46: 0 | BN46: 0 | BO46: =((BK46*BF$40)+(BL46*BG$40)+(BM46*BH$40)+(BN46*BI$40))/BJ$40 -> 0.019898987
...

Sheet CW_FCF
A3: Curtiss-Wright Free Cash Flow Estimates
BD5: =-BD17/CW_IS!AZ91 -> 0.014945879 | BI5: =-BI17/CW_IS!BE91 -> 0.015661918 | BN5: =-BN17/CW_IS!BJ91 -> 0.019448678 | BS5: =-BS17/CW_IS!BO91 -> 0.025638211 | BX5: =-BX17/CW_IS!BT91 -> 0.030756212 | CC5: =-CC17/CW_IS!BY91 -> 0.03
A7: ($ in millions, except per share data) | B7: =[46]Drivers!V4 -> 1Q13 | C7: =[46]Drivers!W4 -> 2Q13 | D7: =[46]Drivers!X4 -> 3Q13 | E7: =[46]Drivers!Y4 -> 4Q13 | F7: =[46]Drivers!Z4 -> 2013 | G7: =[46]Drivers!AA4 -> 1Q14 | H7: =[46]Drivers!AB4 -> 2Q14 | I7: =[46]Drivers!AC4 -> 3Q14 | ... P7: =[46]Drivers!AJ4 -> 2015 | Q7: 1Q16 | R7: 2Q16 | S7: 3Q16 | T7: 4Q16 | U7: 2016 | V7: F1Q17 | W7: F2Q17 | X7: F3Q17 | Y7: 4Q17 | Z7: F2016 | AA7: F1Q17 | AB7: F2Q17 | AC7: F3Q17 | AD7: F4Q17 | AE7: F2017 | AF7: F1Q18 | AG7: F2Q18 | AH7: F3Q18 | AI7: F4Q18 | AJ7: F2018 | AK7: 1Q19 | AL7: 2Q19 | AM7: 3Q19 | AN7: 4Q19 | AO7: 2019 | AP7: 1Q20 | AQ7: 2Q20 | AR7: 3Q20 | AS7: 4Q20 | AT7: 2020 | AU7: 1Q21 | AV7: 2Q21 | AW7: 3Q21 | AX7: 4Q21 | AY7: 2021 | AZ7: 1Q22 | BA7: 2Q22 | BB7: 3Q22 | BC7: 4Q22 | BD7: 2022 | BE7: 1Q23 | BF7: 2Q23 | BG7: 3Q23 | BH7: 4Q23 | BI7: 2023 | BJ7: =CW_IS!BF5 -> 1Q24 | BK7: =CW_IS!BG5 -> 2Q24 | BL7: =CW_IS!BH5 -> 3Q24 | BM7: =CW_IS!BI5 -> 4Q24 | BN7: =CW_Drivers!CC3 -> 2024 | BO7: =CW_IS!BK5 -> 1Q25 | BP7: =CW_IS!BL5 -> 2Q25 | BQ7: =CW_IS!BM5 -> 3Q25 | BR7: =CW_IS!BN5 -> 4Q25 | BS7: =CW_Drivers!CH3 -> 2025 | BT7: =CW_IS!BP5 -> 1Q26E | BU7: =CW_IS!BQ5 -> 2Q26E | BV7: =CW_IS!BR5 -> 3Q26E | BW7: =CW_IS!BS5 -> 4Q26E | BX7: =CW_Drivers!CM3 -> 2026E | BY7: =CW_IS!BU5 -> 1Q27E | BZ7: =CW_IS!BV5 -> 2Q27E | CA7: =CW_IS!BW5 -> 3Q27E | CB7: =CW_IS!BX5 -> 4Q27E | CC7: =CW_Drivers!CR3 -> 2027E
A8: FCF Analysis
A9: BOP Cash | AO9: =+AK9 -> 0 | AT9: =+AP9 -> 0 | AU9: =+AT29 -> 198.248 | AV9: =+AU29 -> 147.069 | AW9: =AV29 -> 197.508 | AX9: =AW29 -> 234.416 | AY9: =+AU9 -> 198.248 | AZ9: =+AY29 -> 171.004 | BA9: =AZ29 -> 136.682 | BB9: =BA29 -> 171.414 | BC9: =BB29 -> 113.552 | BD9: =+AZ9 -> 171.004 | BE9: =+BD29 -> 256.974 | BF9: =BE29 -> 130.659 | BG9: =BF29 -> 158.737 | BH9: =BG29 -> 148.809 | BI9: =+BE9 -> 256.974 | BJ9: =+BI29 -> 406.867 | BK9: =BJ29 -> 338.034 | BL9: =BK29 -> 382.564 | BM9: =BL29 -> 443.85 | BN9: =+BJ9 -> 406.867 | BO9: =+BN29 -> 385.042 | BP9: =BO29 -> 226.459 | BQ9: =BP29 -> 331.664 | BR9: =BQ29 -> 225.427 | BS9: =+BO9 -> 385.042 | BT9: =+BR29 -> 371.345 | BU9: =BT29 -> 295.13765 | BV9: =BU29 -> 251.74069 | BW9: =BV29 -> 544.93353 | BX9: =+BT9 -> 371.345 | BY9: =+BW29 -> 856.72474 | BZ9: =BY29 -> 973.2768 | CA9: =BZ29 -> 1086.7074 | CB9: =CA29 -> 1212.2765 | CC9: =+BY9 -> 856.72474
A10: Adjusted EBITDA | AO10: =SUM(AK10:AN10) -> 0 | AT10: =CW_IS!AP118 -> 505.83419 | AU10: =CW_IS!AQ118 -> 120.683 | AV10: =CW_IS!AR118 -> 127.459 | AW10: =CW_IS!AS118 -> 140.26 | AX10: =CW_IS!AT118 -> 159.813 | AY10: =SUM(AU10:AX10) -> 548.215 | AZ10: =CW_IS!AV118 -> 101.985 | BA10: =CW_IS!AW118 -> 128.158 | BB10: =CW_IS!AX118 -> 148.81 | BC10: =CW_IS!AY118 -> 191.536 | BD10: =SUM(AZ10:BC10) -> 570.489 | BE10: =CW_IS!BA118 -> 115.397 | BF10: =CW_IS!BB118 -> 148.162 | BG10: =CW_IS!BC118 -> 167.067 | BH10: =CW_IS!BD118 -> 196.62633 | BI10: =SUM(BE10:BH10) -> 627.25233 | BJ10: =CW_IS!BF118 -> 131.639 | BK10: =CW_IS!BG118 -> 165.284 | BL10: =CW_IS!BH118 -> 181.458 | BM10: =CW_IS!BI118 -> 192.74767 | BN10: =SUM(BJ10:BM10) -> 671.12867 | BO10: =CW_IS!BK118 -> 170.102 | BP10: =CW_IS!BL118 -> 196.562 | BQ10: =CW_IS!BM118 -> 207.69 | BR10: =CW_IS!BN118 -> 222.978 | BS10: =SUM(BO10:BR10) -> 797.332 | BT10: =CW_IS!BP118 -> 183.85759 | BU10: =CW_IS!BQ118 -> 209.26725 | BV10: =CW_IS!BR118 -> 224.02635 | BW10: =CW_IS!BS118 -> 236.8683 | BX10: =SUM(BT10:BW10) -> 854.01949 | BY10: =CW_IS!BU118 -> 197.41493 | BZ10: =CW_IS!BV118 -> 225.72303 | CA10: =CW_IS!BW118 -> 241.31168 | CB10: =CW_IS!BX118 -> 255.3138 | CC10: =SUM(BY10:CB10) -> 919.76344
A11: Taxes | AO11: =SUM(AK11:AN11) -> 0 | AT11: =(CW_IS!AP124)*-1 -> -82.6456 | AU11: =(CW_IS!AQ124)*-1 -> -21.381 | AV11: =(CW_IS!AR124)*-1 -> -21.335 | AW11: =(CW_IS!AS124)*-1 -> -24.338 | AX11: =(CW_IS!AT124)*-1 -> -27.33036 | AY11: =SUM(AU11:AX11) -> -94.38436 | AZ11: =(CW_IS!AV124)*-1 -> -13.541 | BA11: =(CW_IS!AW124)*-1 -> -22 | BB11: =(CW_IS!AX124)*-1 -> -24.264 | BC11: =(CW_IS!AY124)*-1 -> -34.80528 | BD11: =SUM(AZ11:BC11) -> -94.61028 | BE11: =(CW_IS!BA124)*-1 -> -16.642 | BF11: =(CW_IS!BB124)*-1 -> -24.738 | BG11: =(CW_IS!BC124)*-1 -> -30.268 | BH11: =(CW_IS!BD124)*-1 -> -36.963 | BI11: =SUM(BE11:BH11) -> -108.611 | BJ11: =(CW_IS!BF124)*-1 -> -22.504 | BK11: =(CW_IS!BG124)*-1 -> -26.77 | BL11: =(CW_IS!BH124)*-1 -> -32.461 | BM11: =(CW_IS!BI124)*-1 -> -35.343 | BN11: =SUM(BJ11:BM11) -> -117.078 | BO11: =(CW_IS!BK124)*-1 -> -23.755 | BP11: =(CW_IS!BL124)*-1 -> -35.704 | BQ11: =(CW_IS!BM124)*-1 -> -36.321 | BR11: =(CW_IS!BN124)*-1 -> -40.002 | BS11: =SUM(BO11:BR11) -> -135.782 | BT11: =(CW_IS!BP124)*-1 -> -22.023456 | BU11: =(CW_IS!BQ124)*-1 -> -39.627527 | BV11: =(CW_IS!BR124)*-1 -> -42.801632 | BW11: =(CW_IS!BS124)*-1 -> -47.050008 | BX11: =SUM(BT11:BW11) -> -151.50262 | BY11: =(CW_IS!BU124)*-1 -> -23.959299 | BZ11: =(CW_IS!BV124)*-1 -> -43.26316 | CA11: =(CW_IS!BW124)*-1 -> -46.617036 | CB11: =(CW_IS!BX124)*-1 -> -51.235998 | CC11: =SUM(BY11:CB11) -> -165.07549
A12: Cash interest | AO12: =SUM(AK12:AN12) -> 0 | AT12: =CW_IS!AP121 -> -35.545 | AU12: =CW_IS!AQ121 -> -9.959 | AV12: =CW_IS!AR121 -> -10.18 | AW12: =CW_IS!AS121 -> -9.955 | AX12: =CW_IS!AT121 -> -10.146 | AY12: =SUM(AU12:AX12) -> -40.24 | AZ12: =CW_IS!AV121 -> -9.53 | BA12: =CW_IS!AW121 -> -9.788 | BB12: =CW_IS!AX121 -> -13.997 | BC12: =CW_IS!AY121 -> -13.665 | BD12: =SUM(AZ12:BC12) -> -46.98 | BE12: =CW_IS!BA121 -> -12.944 | BF12: =CW_IS!BB121 -> -14.992 | BG12: =CW_IS!BC121 -> -12.496 | BH12: =CW_IS!BD121 -> -10.961 | BI12: =SUM(BE12:BH12) -> -51.393 | BJ12: =CW_IS!BF121 -> -10.57 | BK12: =CW_IS!BG121 -> -11.216 | BL12: =CW_IS!BH121 -> -11.408 | BM12: =CW_IS!BI121 -> -11.675 | BN12: =SUM(BJ12:BM12) -> -44.869 | BO12: =CW_IS!BK121 -> -10.143 | BP12: =CW_IS!BL121 -> -10.524 | BQ12: =CW_IS!BM121 -> -10.484 | BR12: =CW_IS!BN121 -> -11.997 | BS12: =SUM(BO12:BR12) -> -43.148 | BT12: =CW_IS!BP121 -> -10.375 | BU12: =CW_IS!BQ121 -> -10.375 | BV12: =CW_IS!BR121 -> -10.375 | BW12: =CW_IS!BS121 -> -10.375 | BX12: =SUM(BT12:BW12) -> -41.5 | BY12: =CW_IS!BU121 -> -10.375 | BZ12: =CW_IS!BV121 -> -10.375 | CA12: =CW_IS!BW121 -> -10.375 | CB12: =CW_IS!BX121 -> -10.375 | CC12: =SUM(BY12:CB12) -> -41.5
A13: Working Capital | AO13: =SUM(AK13:AN13) -> 0 | AT13: -121.526 | AU13: -96 | AV13: -20 | AW13: 0 | AX13: 100 | AY13: =SUM(AU13:AX13) -> -16 | AZ13: -100 | BA13: -25 | BB13: 0 | BC13: 25 | BD13: =SUM(AZ13:BC13) -> -100 | BE13: =6.153-42.773-0.163-85.442-8.252-4.946-44.602 -> -180.025 | BF13: =(-22.37-57.557+1.83-72.019+21.586-9.392-40.867)-BE13 -> 1.236 | BG13: =(-56.138-56.753+0.064-42.02+37.598-14.128-31.343)-BF13-BE13 -> 16.069 | BH13: 25 | BI13: =SUM(BE13:BH13) -> -137.72 | BJ13: -151 | BK13: =-85.914-54.113-55.306+36.573-9.528+0.751-BJ13 -> -16.537 | BL13: =(-120.795-71.683-15.206+85.579-13.218+5.034)-BK13-BJ13 -> 37.248 | BM13: =(-2.394-21.568-15.779+47.914-18.307-29.286)-BL13-BK13-BJ13 -> 90.869 | BN13: =SUM(BJ13:BM13) -> -39.42 | BO13: =-72.749-34.079-35.967-12.714-6.03-12.862 -> -174.401 | BP13: =-110.541-57.614-40.083+35.719-10.691-13.544 -> -196.754 | BQ13: =(-128.774-86.139+28.48+40.119-14.433-12.116)-BP13-BO13 -> 198.292 | BR13: =(-88.808-34.5+16.024+144.269-18.88+2.195)-BQ13-BP13-BO13 -> 193.163 | BS13: =SUM(BO13:BR13) -> 20.3 | BT13: -175 | BU13: -150 | BV13: 175 | BW13: 185 | BX13: =SUM(BT13:BW13) -> 35 | BY13: 5 | BZ13: -5 | CA13: -5 | CB13: 5 | CC13: =SUM(BY13:CB13) -> 0
A14: Other, net | AO14: =SUM(AK14:AN14) -> 0 | AT14: =SUM(AP14:AS14) -> 0 | AU14: 0 | AV14: 0 | AW14: 0 | AX14: 0 | AY14: =SUM(AU14:AX14) -> 0 | AZ14: 0 | BA14: 0 | BB14: 0 | BC14: 0 | BD14: =SUM(AZ14:BC14) -> 0 | BE14: 0 | BF14: 0 | BG14: 0 | BH14: 0 | BI14: =SUM(BE14:BH14) -> 0 | BJ14: -145 | BK14: 0 | BL14: 0 | BM14: 0 | BN14: =SUM(BJ14:BM14) -> -145 | BO14: 0 | BP14: 0 | BQ14: 0 | BR14: 0 | BS14: =SUM(BO14:BR14) -> 0 | BT14: 0 | BU14: 0 | BV14: 0 | BW14: 0 | BX14: =SUM(BT14:BW14) -> 0 | BY14: 0 | BZ14: 0 | CA14: 0 | CB14: 0 | CC14: =SUM(BY14:CB14) -> 0
A15: Guidance - Full Year
A16: Cash flows from operations | AO16: =SUM(AK16:AN16) -> 0 | AT16: 261.18 | AU16: -26.603 | AV16: 75.079 | AW16: 107.195 | AX16: 231.997 | AY16: =SUM(AU16:AX16) -> 387.668 | AZ16: -124.315 | BA16: 31 | BB16: 95.658 | BC16: 292.389 | BD16: =SUM(AZ16:BC16) -> 294.732 | BE16: -91.599 | BF16: =19.353-BE16 -> 110.952 | BG16: 146.364 | BH16: 282 | BI16: =SUM(BE16:BH16) -> 447.717 | BJ16: -45.633 | BK16: 111.335 | BL16: =242.976-BK16-BJ16 -> 177.274 | BM16: 301 | BN16: =SUM(BJ16:BM16) -> 543.976 | BO16: -38.765 | BP16: 136.585 | BQ16: 192.838 | BR16: 352.744 | BS16: =SUM(BO16:BR16) -> 643.402 | BT16: =SUM(BT10:BT14) -> -23.540868 | BU16: =SUM(BU10:BU14) -> 9.2647198 | BV16: =SUM(BV10:BV14) -> 345.84972 | BW16: =SUM(BW10:BW14) -> 364.44329 | BX16: =SUM(BT16:BW16) -> 696.01686 | BY16: =SUM(BY10:BY14) -> 168.08064 | BZ16: =SUM(BZ10:BZ14) -> 167.08487 | CA16: =SUM(CA10:CA14) -> 179.31964 | CB16: =SUM(CB10:CB14) -> 198.7028 | CC16: =SUM(BY16:CB16) -> 713.18795
A17: Capex | AO17: =SUM(AK17:AN17) -> 0 | AT17: -47.499 | AU17: -8.537 | AV17: -9.234 | AW17: -10.087 | AX17: -13.25 | AY17: =SUM(AU17:AX17) -> -41.108 | AZ17: -10.896 | BA17: -8.596 | BB17: -9.297 | BC17: -9.428 | BD17: =SUM(AZ17:BC17) -> -38.217 | BE17: -10.661 | BF17: =-22.191-BE17 -> -11.53 | BG17: -9.373 | BH17: -13 | BI17: =SUM(BE17:BH17) -> -44.564 | BJ17: -12.055 | BK17: -11.064 | BL17: =-37.703-BK17-BJ17 -> -14.584 | BM17: -23 | BN17: =SUM(BJ17:BM17) -> -60.703 | BO17: -15.773 | BP17: -19.381 | BQ17: -16.9 | BR17: -37.638 | BS17: =SUM(BO17:BR17) -> -89.692 | BT17: =-115/4 -> -28.75 | BU17: =-115/4 -> -28.75 | BV17: =-115/4 -> -28.75 | BW17: =-115/4 -> -28.75 | BX17: =SUM(BT17:BW17) -> -115 | BY17: =-(0.03*CW_IS!BU91) -> -27.631305 | BZ17: =-(0.03*CW_IS!BV91) -> -29.761827 | CA17: =-(0.03*CW_IS!BW91) -> -29.862781 | CB17: =-(0.03*CW_IS!BX91) -> -31.485789 | CC17: =SUM(BY17:CB17) -> -118.7417
A18: FCF | AO18: =AO16+AO17 -> 0 | AT18: =+AT16+AT17 -> 213.681 | AU18: =+AU16+AU17 -> -35.14 | AV18: =+AV16+AV17 -> 65.845 | AW18: =+AW16+AW17 -> 97.108 | AX18: =+AX16+AX17 -> 218.747 | AY18: =SUM(AU18:AX18) -> 346.56 | AZ18: =+AZ16+AZ17 -> -135.211 | BA18: =+BA16+BA17 -> 22.404 | BB18: =+BB16+BB17 -> 86.361 | BC18: =+BC16+BC17 -> 282.961 | BD18: =SUM(AZ18:BC18) -> 256.515 | BE18: =+BE16+BE17 -> -102.26 | BF18: =+BF16+BF17 -> 99.422 | BG18: =+BG16+BG17 -> 136.991 | BH18: 270 | BI18: =SUM(BE18:BH18) -> 404.153 | BJ18: =+BJ16+BJ17 -> -57.688 | BK18: =+BK16+BK17 -> 100.271 | BL18: =+BL16+BL17 -> 162.69 | BM18: =+BM16+BM17 -> 278 | BN18: =SUM(BJ18:BM18) -> 483.273 | BO18: =+BO16+BO17 -> -54.538 | BP18: =+BP16+BP17 -> 117.204 | BQ18: =+BQ16+BQ17 -> 175.938 | BR18: =+BR16+BR17 -> 315.106 | BS18: =SUM(BO18:BR18) -> 553.71 | BT18: =+BT16+BT17 -> -52.290868 | BU18: =+BU16+BU17 -> -19.48528 | BV18: =+BV16+BV17 -> 317.09972 | BW18: =+BW16+BW17 -> 335.69329 | BX18: =SUM(BT18:BW18) -> 581.01686 | BY18: =+BY16+BY17 -> 140.44933 | BZ18: =+BZ16+BZ17 -> 137.32304 | CA18: =+CA16+CA17 -> 149.45686 | CB18: =+CB16+CB17 -> 167.21701 | CC18: =SUM(BY18:CB18) -> 594.44625
A19: Consensus | BS19: =-BS17/-BN17-1 -> 0.47755465 | BX19: =-BX17/-BS17-1 -> 0.28216563
A20: Guidance - Full Year | AT20: 330-360 | AX20: 345-365 | AY20: =AX20 -> 345-365 | BB20: 275-315 | BC20: 360-400 | BD20: =BC20 -> 360-400 | BE20: 360-400 | BF20: 370-400 | BG20: 380-400 | BH20: 415-435 | BI20: =BH20 -> 415-435 | BJ20: 415-435 | BK20: 425-445 | BL20: 430-450 | BM20: 485-505 | BN20: =BM20 -> 485-505 | BO20: 495-515 | BP20: 520-535 | BQ20: 520-535 | BR20: 575-595 | BS20: =BR20 -> 575-595
A22: CapEx % of revenue | AT22: =-AT17/CW_IS!AP91 -> 0.020426673 | AY22: =-AY17/CW_IS!AU91 -> 0.01665317 | BD22: =-BD17/CW_IS!AZ91 -> 0.014945879 | BI22: =-BI17/CW_IS!BE91 -> 0.015661918 | BN22: =-BN17/CW_IS!BJ91 -> 0.019448678 | BS22: =-BS17/CW_IS!BO91 -> 0.025638211 | BX22: =-BX17/CW_IS!BT91 -> 0.030756212 | CC22: =-CC17/CW_IS!BY91 -> 0.03
A23: FCF Conversion | AT23: =AT18/CW_IS!AP128 -> 0.7712679 | AY23: =AY18/CW_IS!AU128 -> 1.1636417 | BD23: =BD18/CW_IS!AZ128 -> 0.81635551 | BI23: =BI18/CW_IS!BE128 -> 1.1113607 | BN23: =BN18/CW_IS!BJ128 -> 1.152167 | BS23: =BS18/CW_IS!BO128 -> 1.1036631 | BX23: =BX18/CW_IS!BT128 -> 1.0489167 | CC23: =CC18/CW_IS!BY128 -> 0.9850597
A25: Dividends | AO25: =SUM(AK25:AN25) -> 0 | AT25: -28.175 | AU25: 0 | AV25: -6.961 | AW25: =-14.32-AV25-AU25 -> -7.359 | AX25: =-28.66-AW25-AV25-AU25 -> -14.34 | AY25: =SUM(AU25:AX25) -> -28.66 | AZ25: 0 | BA25: -14.22 | BB25: =-14.22-BA25-AZ25 -> 0 | BC25: =-28.779-BB25-BA25-AZ25 -> -14.559 | BD25: =SUM(AZ25:BC25) -> -28.779 | BE25: 0 | BF25: =-7.29-BE25 -> -7.29 | BG25: =-0.2*CW_IS!BC140 -> -7.7116 | BH25: =-0.2*CW_IS!BD140 -> -7.701 | BI25: =SUM(BE25:BH25) -> -22.7026 | BJ25: 0 | BK25: =-7.665-BJ25 -> -7.665 | BL25: =-15.707-BK25-BJ25 -> -8.042 | BM25: =-0.21*CW_IS!BI140 -> -8.00877 | BN25: =SUM(BJ25:BM25) -> -23.71577 | BO25: 0 | BP25: =-7.923-BO25 -> -7.923 | BQ25: =-16.967-BP25-BO25 -> -9.044 | BR25: =-34.727-BQ25-BP25-BO25 -> -17.76 | BS25: =SUM(BO25:BR25) -> -34.727 | BT25: =-0.24*CW_IS!BP140 -> -8.91648 | BU25: =-0.24*CW_IS!BQ140 -> -8.91168 | BV25: =-0.24*CW_IS!BR140 -> -8.90688 | BW25: =-0.24*CW_IS!BS140 -> -8.90208 | BX25: =SUM(BT25:BW25) -> -35.63712 | BY25: =-0.24*CW_IS!BU140 -> -8.89728 | BZ25: =-0.24*CW_IS!BV140 -> -8.89248 | CA25: =-0.24*CW_IS!BW140 -> -8.88768 | CB25: =-0.24*CW_IS!BX140 -> -8.88288 | CC25: =SUM(BY25:CB25) -> -35.56032
A26: Proceeds (Repayments) of debt | AO26: =SUM(AK26:AN26) -> 0 | AT26: 300 | AU26: 0 | AV26: 0 | AW26: 0 | AX26: =(455.95-362.05-100)-AW26-AV26-AU26 -> -6.1 | AY26: =SUM(AU26:AX26) -> -6.1 | AZ26: =241.198-121.198 -> 120 | BA26: =(653.547-494.347)-AZ26 -> 39.2 | BB26: =(1332.219-1038.019)-BA26-AZ26 -> 135 | BC26: =(1697.647-1791.547+300)-BB26-BA26-AZ26 -> -88.1 | BD26: =SUM(AZ26:BC26) -> 206.1 | BE26: =BE32-BC32 -> -24.781 | BF26: =BF32-BE32 -> -53.553 | BG26: =BG32-BF32 -> -125.353 | BH26: =BH32-BG32 -> -0.351 | BI26: =SUM(BE26:BH26) -> -204.038 | BJ26: =BJ32-BH32 -> -0.353 | BK26: =BK32-BJ32 -> -0.354 | BL26: =BL32-BK32 -> -0.353 | BM26: =BM32-BL32 -> -0.353 | BN26: =SUM(BJ26:BM26) -> -1.413 | BO26: =BO32-BM32 -> -90.32 | BP26: =BP32-BO32 -> -0.248 | BQ26: =BQ32-BP32 -> 10.251 | BR26: =BR32-BQ32 -> -10.748 | BS26: =SUM(BO26:BR26) -> -91.065 | BT26: 0 | BU26: 0 | BV26: 0 | BW26: 0 | BX26: =SUM(BT26:BW26) -> 0 | BY26: 0 | BZ26: 0 | CA26: 0 | CB26: 0 | CC26: =SUM(BY26:CB26) -> 0
A27: Acquisitions, distributions | AO27: =SUM(AK27:AN27) -> 0 | AT27: =-487.944+2.93 -> -485.014 | AU27: =1.022-5.34 -> -4.318 | AV27: =(2.982-5.34)-AU27 -> 1.96 | AW27: =(3.389-AV27-AU27) -> 5.747 | AX27: =(4.045-5.34)-AW27-AV27-AU27 -> -4.684 | AY27: =SUM(AU27:AX27) -> -1.295 | AZ27: =5.567-5.062 -> 0.505 | BA27: =(6.319-5.062)-AZ27 -> 0.752 | BB27: =(9.11-247.215)-BA27-AZ27 -> -239.362 | BC27: =(9.841-282.429)-BB27-BA27-AZ27 -> -34.483 | BD27: =SUM(AZ27:BC27) -> -272.588 | BE27: 0 | BF27: =0.473 -> 0.473 | BG27: 0 | BH27: 0 | BI27: =SUM(BE27:BH27) -> 0.473 | BJ27: 0 | BK27: =-33.756-BJ27 -> -33.756 | BL27: =-33.756-BK27-BJ27 -> 0 | BM27: -200 | BN27: =SUM(BJ27:BM27) -> -233.756 | BO27: -9.619 | BP27: =-9.619-BO27 -> 0 | BQ27: =-9.619-BP27-BO27 -> 0 | BR27: =-9.619 -> -9.619 | BS27: =SUM(BO27:BR27) -> -19.238 | BT27: 0 | BU27: 0 | BV27: 0 | BW27: 0 | BX27: =SUM(BT27:BW27) -> 0 | BY27: 0 | BZ27: 0 | CA27: 0 | CB27: 0 | CC27: =SUM(BY27:CB27) -> 0
A28: Share buybacks | AO28: =SUM(AK28:AN28) -> 0 | AT28: -200.018 | AU28: -11.797 | AV28: =-24.395-AU28 -> -12.598 | AW28: =-79.092-AV28-AU28 -> -54.697 | AX28: =-343.129-AW28-AV28-AU28 -> -264.037 | AY28: =SUM(AU28:AX28) -> -343.129 | AZ28: -18.857 | BA28: =-31.645-AZ28 -> -12.788 | BB28: =-44.434-BA28-AZ28 -> -12.789 | BC28: =-56.87-BB28-BA28-AZ28 -> -12.436 | BD28: =SUM(AZ28:BC28) -> -56.87 | BE28: -12 | BF28: =-24.365-BE28 -> -12.365 | BG28: -13 | BH28: -13 | BI28: =SUM(BE28:BH28) -> -50.365 | BJ28: -12.19 | BK28: =-24.796-BJ28 -> -12.606 | BL28: =-137.58-BK28-BJ28 -> -112.784 | BM28: -112 | BN28: =SUM(BJ28:BM28) -> -249.58 | BO28: -14 | BP28: =-35.075-BO28 -> -21.075 | BQ28: =-325.112-BP28-BO28 -> -290.037 | BR28: =-464.95-BQ28-BP28-BO28 -> -139.838 | BS28: =SUM(BO28:BR28) -> -464.95 | BT28: =-15 -> -15 | BU28: =-15 -> -15 | BV28: =-15 -> -15 | BW28: =-15 -> -15 | BX28: =SUM(BT28:BW28) -> -60 | BY28: =-15 -> -15 | BZ28: =-15 -> -15 | CA28: =-15 -> -15 | CB28: =-15 -> -15 | CC28: =SUM(BY28:CB28) -> -60
A29: EOP Cash | AO29: 391.033 | AT29: 198.248 | AU29: 147.069 | AV29: =197.508 -> 197.508 | AW29: 234.416 | AX29: 171.004 | AY29: =+AX29 -> 171.004 | AZ29: 136.682 | BA29: 171.414 | BB29: 113.552 | BC29: 256.974 | BD29: =+BC29 -> 256.974 | BE29: 130.659 | BF29: 158.737 | BG29: 148.809 | BH29: 406.867 | BI29: =+BH29 -> 406.867 | BJ29: 338.034 | BK29: 382.564 | BL29: 443.85 | BM29: 385.042 | BN29: =+BM29 -> 385.042 | BO29: 226.459 | BP29: 331.664 | BQ29: 225.427 | BR29: 371.345 | BS29: =+BR29 -> 371.345 | BT29: =+BT18+BT9+SUM(BT25:BT28) -> 295.13765 | BU29: =+BU18+BU9+SUM(BU25:BU28) -> 251.74069 | BV29: =+BV18+BV9+SUM(BV25:BV28) -> 544.93353 | BW29: =+BW18+BW9+SUM(BW25:BW28) -> 856.72474 | BX29: =+BW29 -> 856.72474 | BY29: =+BY18+BY9+SUM(BY25:BY28) -> 973.2768 | BZ29: =+BZ18+BZ9+SUM(BZ25:BZ28) -> 1086.7074 | CA29: =+CA18+CA9+SUM(CA25:CA28) -> 1212.2765 | CB29: =+CB18+CB9+SUM(CB25:CB28) -> 1355.6107 | CC29: =+CB29 -> 1355.6107
A31: Debt/Leverage Analysis | AW31: =CW_IS!AS136 -> 0
A32: Total debt | AO32: =AN32 -> 0 | AT32: =100+958.292 -> 1058.292 | AU32: 1050.61 | AV32: 1050.61 | AW32: 1050.61 | AX32: 1050.61 | AY32: =AX32 -> 1050.61 | AZ32: =202.5+967.744 -> 1170.244 | BA32: =202.5+1006.577 -> 1209.077 | BB32: =202.5+1141.211 -> 1343.711 | BC32: =202.5+1051.9 -> 1254.4 | BD32: =BC32 -> 1254.4 | BE32: 1229.619 | BF32: 1176.066 | BG32: 1050.713 | BH32: 1050.362 | BI32: =BH32 -> 1050.362 | BJ32: =90+960.009 -> 1050.009 | BK32: =90+959.655 -> 1049.655 | BL32: =90+959.302 -> 1049.302 | BM32: =90+958.949 -> 1048.949 | BN32: =BM32 -> 1048.949 | BO32: =958.629 -> 958.629 | BP32: 958.381 | BQ32: 968.632 | BR32: =200+757.884 -> 957.884 | BS32: =BR32 -> 957.884 | BT32: =BS32 -> 957.884 | BU32: =BT32 -> 957.884 | BV32: =BU32 -> 957.884 | BW32: =BV32+BW26 -> 957.884 | BX32: =BW32 -> 957.884 | BY32: =BX32 -> 957.884 | BZ32: =BY32 -> 957.884 | CA32: =BZ32 -> 957.884 | CB32: =CA32 -> 957.884 | CC32: =CB32 -> 957.884
A33: Net debt | AT33: =AT32-AT29 -> 860.044 | AU33: =AU32-AU29 -> 903.541 | AV33: =AV32-AV29 -> 853.102 | AW33: =AW32-AW29 -> 816.194 | AX33: =AX32-AX29 -> 879.606 | AY33: =AY32-AY29 -> 879.606 | AZ33: =AZ32-AZ29 -> 1033.562 | BA33: =BA32-BA29 -> 1037.663 | ... CC33: =CC32-CC29 -> -397.72667
A34: Net leverage (Net debt /EBITDA) | AT34: =AT33/AT10 -> 1.7002488 | AY34: =AY33/AY10 -> 1.6044909 | BD34: =BD33/BD10 -> 1.7483703 | BI34: =BI33/BI10 -> 1.0258949 | BN34: =BN33/BN10 -> 0.98923952 | BS34: =BS33/BS10 -> 0.73562707 | BX34: =BX33/BX10 -> 0.11845076 | CC34: =CC33/CC10 -> -0.43242279
A36: Liquidity
A37: Cash | AO37: =AO29 -> 391.033 | AT37: =AT29 -> 198.248 | AU37: =AU29 -> 147.069 | AV37: =AV29 -> 197.508 | AW37: =AW29 -> 234.416 | AX37: =AX29 -> 171.004 | AY37: =AY29 -> 171.004 | AZ37: =AZ29 -> 136.682 | BA37: =BA29 -> 171.414 | ... CC37: =CC29 -> 1355.6107
