Workbook
Name blank: #REF!
Name blank: #REF!
Name blank: #REF!
Name Current_Q: #REF!
Name Current_Q: #REF!
Name Current_Q: #REF!
Name export: #REF!
Name export: #REF!
Name export: #REF!
Name FY_92: #REF!
Name FY_92: #REF!
Name FY_92: #REF!
Name FY_93: #REF!
Name FY_93: #REF!
Name FY_93: #REF!
Name FY_94: #REF!
Name FY_94: #REF!
Name FY_94: #REF!
Name N_A: #REF!
Name N_A: #REF!
Name N_M: #REF!
Name N_M: #REF!
Name Next_Actual_Period_Range: '[16]Income Statement'!$D$3:$BE$6
Name NM_T: #REF!
Name NM_T: #REF!
Name NM_T: #REF!
Name Prior_Q: #REF!
Name Prior_Q: #REF!
Name Prior_Q: #REF!
Name Same_Q_Last_Yr: #REF!
Name Same_Q_Last_Yr: #REF!
Name Same_Q_Last_Yr: #REF!
Name source: #REF!
Name source: #REF!
Name source: #REF!
Name SPR01A_18: #REF!
Name SPR01C_18: #REF!
Name test: #REF!
Name WIZARD_3YRATCF: #REF!
Name WIZARD_3YRATCF: #REF!
Name WIZARD_3YRATCF: #REF!
Name WIZARD_3YREBITDA: #REF!
Name WIZARD_3YREBITDA: #REF!
Name WIZARD_3YREBITDA: #REF!
Name WIZARD_3YRSECGROWTH: #REF!
Name WIZARD_3YRSECGROWTH: #REF!
Name WIZARD_3YRSECGROWTH: #REF!
Name WIZARD_AVGTRADINGVOLUME: #REF!
Name WIZARD_AVGTRADINGVOLUME: #REF!
Name WIZARD_BKVALSHR: #REF!
Name WIZARD_BKVALSHR: #REF!
Name WIZARD_BURNRATE: #REF!
Name WIZARD_BURNRATE: #REF!
Name WIZARD_CASH: #REF!
Name WIZARD_CASH: #REF!
Name WIZARD_DIVYIELD: #REF!
Name WIZARD_DIVYIELD: #REF!
Name WIZARD_EARNINGS: #REF!
Name WIZARD_EARNINGS: #REF!
Name WIZARD_EBITDABYSHROO: #REF!

Sheet __FDSCACHE__
B1: This sheet contains FactSet XML data for use with this workbook's =FDS codes. Modifying the worksheet's contents may damage the workbook's =FDS functionality.

Sheet Comparison
B2: ='Income Statement'!B2 -> Five9, Inc (Nasdaq: FIVN)
B4: Variance Analysis | D4: 4Q24 | E4: =K4 -> 4Q25 | F4: Y/Y Chg. | G4: 3Q25 | H4: =K4 -> 4Q25 | I4: Q/Q Chg. | J4: =K4&"E" -> 4Q25E | K4: 4Q25 | L4: % Delta | O4: 1Q Cons. | P4: 2Q Guide | Q4: 2Q Cons. | R4: FY Guide Prev | S4: FY Guide New | T4: FY Cons
B5: Total Revenue | D5: ='Income Statement'!BP28 -> 278660 | E5: =K5 -> 300282 | F5: =E5/D5-1 -> 0.077592765 | G5: ='Income Statement'!BT28 -> 285832 | H5: =K5 -> 300282 | I5: =H5/G5-1 -> 0.050554172 | J5: 298082.6 | K5: ='Income Statement'!BU28 -> 300282 | L5: =K5/J5-1 -> 0.007378485 | O5: 170900 | P5: =(179000+180000)/2 -> 179500 | Q5: 174100 | R5: 756000 | S5: =(770000+773000)/2 -> 771500 | T5: 756800 | V5: Initial guide for 24% Y/Y growth
C6: Total Cost of Revenue | D6: ='Income Statement'!BP35 -> 111603 | E6: =K6 -> 123898 | F6: =E6/D6-1 -> 0.11016729 | G6: ='Income Statement'!BT35 -> 118234 | H6: =K6 -> 123898 | I6: =H6/G6-1 -> 0.047905002 | J6: 119233.04 | K6: ='Income Statement'!BU35 -> 123898 | L6: =K6/J6-1 -> 0.039124719
B7: Gross Profit | D7: =D5-D6 -> 167057 | E7: =K7 -> 176384 | F7: =E7/D7-1 -> 0.055831243 | G7: =G5-G6 -> 167598 | H7: =K7 -> 176384 | I7: =H7/G7-1 -> 0.05242306 | J7: 178849.56 | K7: =K5-K6 -> 176384 | L7: =K7/J7-1 -> -0.013785671 | O7: 102000 | Q7: 103300 | T7: 453300
C8: Gross Margins | D8: =D7/D5 -> 0.59950118 | E8: =K8 -> 0.58739452 | G8: =G7/G5 -> 0.58635142 | H8: =K8 -> 0.58739452 | J8: 0.6 | K8: =K7/K5 -> 0.58739452 | N8: =+K8-J8 -> -0.012605484 | O8: =IF(AND(ISNUMBER(O$5), ISNUMBER(O7)), O7/O$5, "- ") -> 0.59684026 | P8: =IF(AND(ISNUMBER(P$5), ISNUMBER(P7)), P7/P$5, "- ") -> - | Q8: =IF(AND(ISNUMBER(Q$5), ISNUMBER(Q7)), Q7/Q$5, "- ") -> 0.59333716 | R8: =IF(AND(ISNUMBER(R$5), ISNUMBER(R7)), R7/R$5, "- ") -> - | S8: =IF(AND(ISNUMBER(S$5), ISNUMBER(S7)), S7/S$5, "- ") -> - | T8: =IF(AND(ISNUMBER(T$5), ISNUMBER(T7)), T7/T$5, "- ") -> 0.59896934
B10: Operating Expenses
C11: R&D | D11: ='Income Statement'!BP41 -> 33221 | E11: =K11 -> 27217 | F11: =E11/D11-1 -> -0.18072906 | G11: ='Income Statement'!BT41 -> 27127 | H11: =K11 -> 27217 | I11: =H11/G11-1 -> 0.0033177277 | J11: 32789.086 | K11: ='Income Statement'!BU41 -> 27217 | L11: =K11/J11-1 -> -0.16993722
C12: S&M | D12: ='Income Statement'!BP43 -> 60261 | E12: =K12 -> 67757 | F12: =E12/D12-1 -> 0.12439223 | G12: ='Income Statement'!BT43 -> 63074 | H12: =K12 -> 67757 | I12: =H12/G12-1 -> 0.074246124 | J12: 67068.585 | K12: ='Income Statement'!BU43 -> 67757 | L12: =K12/J12-1 -> 0.010264337
C13: G&A | D13: ='Income Statement'!BP45 -> 24056 | E13: =K13 -> 19795 | F13: =E13/D13-1 -> -0.17712837 | G13: ='Income Statement'!BT45 -> 20285 | H13: =K13 -> 19795 | I13: =H13/G13-1 -> -0.02415578 | J13: 21760.03 | K13: ='Income Statement'!BU45 -> 19795 | L13: =K13/J13-1 -> -0.090304561
B14: Total Operating Expenses | D14: =SUM(D11:D13) -> 117538 | E14: =K14 -> 114769 | F14: =E14/D14-1 -> -0.023558339 | G14: =SUM(G11:G13) -> 110486 | H14: =K14 -> 114769 | I14: =H14/G14-1 -> 0.038765092 | J14: 121617.7 | K14: =SUM(K11:K13) -> 114769 | L14: =K14/J14-1 -> -0.056313362 | N14: =+K14-J14 -> -6848.7016 | O14: =K14-J14 -> -6848.7016
B16: Non-GAAP Operating Income (Loss) | D16: =D7-D14 -> 49519 | E16: =K16 -> 61615 | F16: =E16/D16-1 -> 0.24426988 | G16: =G7-G14 -> 57112 | H16: =K16 -> 61615 | I16: =H16/G16-1 -> 0.078845076 | J16: 57231.86 | K16: =K7-K14 -> 61615 | L16: =K16/J16-1 -> 0.076585672 | O16: 10800 | Q16: 11900 | T16: 86000
C17: Non-GAAP Operating Margins | D17: =D16/D5 -> 0.17770401 | E17: =K17 -> 0.20519045 | G17: =G16/G5 -> 0.19980968 | H17: =K17 -> 0.20519045 | J17: 0.192 | K17: =K16/K5 -> 0.20519045 | O17: =IF(AND(ISNUMBER(O$5), ISNUMBER(O16)), O16/O$5, "- ") -> 0.063194851 | P17: =IF(AND(ISNUMBER(P$5), ISNUMBER(P16)), P16/P$5, "- ") -> - | Q17: =IF(AND(ISNUMBER(Q$5), ISNUMBER(Q16)), Q16/Q$5, "- ") -> 0.068351522 | R17: =IF(AND(ISNUMBER(R$5), ISNUMBER(R16)), R16/R$5, "- ") -> - | S17: =IF(AND(ISNUMBER(S$5), ISNUMBER(S16)), S16/S$5, "- ") -> - | T17: =IF(AND(ISNUMBER(T$5), ISNUMBER(T16)), T16/T$5, "- ") -> 0.11363636
B19: GAAP & Non-cash charges | D19: ='Income Statement'!BP64 -> 45339 | E19: =K19 -> 41819 | F19: =E19/D19-1 -> -0.077637354 | G19: ='Income Statement'!BT64 -> 41069 | H19: =K19 -> 41819 | I19: =H19/G19-1 -> 0.018261949 | J19: 45600 | K19: ='Income Statement'!BU64 -> 41819 | L19: =K19/J19-1 -> -0.082916667
B21: GAAP Operating Income | D21: =D16-D19 -> 4180 | E21: =K21 -> 19796 | F21: =E21/D21-1 -> 3.7358852 | G21: =G16-G19 -> 16043 | H21: =K21 -> 19796 | I21: =H21/G21-1 -> 0.2339338 | J21: 11631.86 | K21: =K16-K19 -> 19796 | L21: =K21/J21-1 -> 0.70187749
C22: GAAP Operating Margins | D22: =D21/D5 -> 0.015000359 | E22: =K22 -> 0.065924697 | G22: =G21/G5 -> 0.056127376 | H22: =K22 -> 0.065924697 | J22: 0.039022269 | K22: =K21/K5 -> 0.065924697 | O22: =IF(AND(ISNUMBER(O$5), ISNUMBER(O21)), O21/O$5, "- ") -> - | P22: =IF(AND(ISNUMBER(P$5), ISNUMBER(P21)), P21/P$5, "- ") -> - | Q22: =IF(AND(ISNUMBER(Q$5), ISNUMBER(Q21)), Q21/Q$5, "- ") -> - | R22: =IF(AND(ISNUMBER(R$5), ISNUMBER(R21)), R21/R$5, "- ") -> - | S22: =IF(AND(ISNUMBER(S$5), ISNUMBER(S21)), S21/S$5, "- ") -> - | T22: =IF(AND(ISNUMBER(T$5), ISNUMBER(T21)), T21/T$5, "- ") -> -
B24: Total GAAP Other Income | D24: ='Income Statement'!BP74 -> 6971 | E24: =K24 -> 3234 | G24: ='Income Statement'!BT74 -> 2573 | H24: =K24 -> 3234 | J24: 2400 | K24: ='Income Statement'!BU74 -> 3234
B25: Total Non GAAP Other Income | D25: ='Income Statement'!BP79 -> 10956 | E25: =K25 -> 4138 | G25: ='Income Statement'!BT79 -> 3611 | H25: =K25 -> 4138 | J25: 3600 | K25: ='Income Statement'!BU79 -> 4138
B27: Non-GAAP Income before Taxes | D27: =D16+D25 -> 60475 | E27: =K27 -> 65753 | F27: =E27/D27-1 -> 0.087275734 | G27: =G16+G25 -> 60723 | H27: =K27 -> 65753 | I27: =H27/G27-1 -> 0.08283517 | J27: 60831.86 | K27: =K16+K25 -> 65753 | L27: =K27/J27-1 -> 0.080897419
C28: Income Tax | D28: ='Income Statement'!BP87 -> 224 | E28: =K28 -> 3317 | G28: ='Income Statement'!BT87 -> 119 | H28: =K28 -> 3317 | J28: 1000 | K28: ='Income Statement'!BU87 -> 3317 | P28: 500 | S28: 1900
B29: Non-GAAP Net Income | D29: =D27-D28 -> 60251 | E29: =K29 -> 62436 | F29: =E29/D29-1 -> 0.036264958 | G29: =G27-G28 -> 60604 | H29: =K29 -> 62436 | I29: =H29/G29-1 -> 0.030229028 | J29: 59831.86 | K29: =K27-K28 -> 62436 | L29: =K29/J29-1 -> 0.04352431
B31: GAAP Income before Taxes | D31: =D21+D24 -> 11151 | E31: =K31 -> 23030 | F31: =E31/D31-1 -> 1.0652856 | G31: =G21+G24 -> 18616 | H31: =K31 -> 23030 | I31: =H31/G31-1 -> 0.23710786 | J31: 14031.86 | K31: =K21+K24 -> 23030 | L31: =K31/J31-1 -> 0.641265
C32: Income Tax | D32: ='Income Statement'!BP93 -> -426 | E32: =K32 -> 3317 | G32: ='Income Statement'!BT93 -> 643 | H32: =K32 -> 3317 | J32: 1000 | K32: ='Income Statement'!BU93 -> 3317
B33: GAAP Net Income | D33: =D31-D32 -> 11577 | E33: =K33 -> 19713 | F33: =E33/D33-1 -> 0.70277274 | G33: =G31-G32 -> 17973 | H33: =K33 -> 19713 | I33: =H33/G33-1 -> 0.096811884 | J33: 13031.86 | K33: =K31-K32 -> 19713 | L33: =K33/J33-1 -> 0.51267744
B35: Non-GAAP EPS | D35: =D29/D39 -> 0.79278675 | E35: =K35 -> 0.80433886 | F35: =E35/D35-1 -> 0.014571532 | G35: =G29/G39 -> 0.77814157 | H35: =K35 -> 0.80433886 | I35: =H35/G35-1 -> 0.033666487 | J35: 0.76332699 | K35: =K29/K39 -> 0.80433886 | L35: =K35/J35-1 -> 0.05372779 | O35: 0.13 | P35: =(0.17+0.19)/2 -> 0.18 | Q35: 0.15 | R35: 1.14 | S35: =(1.22+1.24)/2 -> 1.23 | T35: 1.12
B36: GAAP EPS | D36: =D33/D38 -> 0.15348005 | E36: =K36 -> 0.25433176 | G36: =G33/G38 -> 0.23182592 | H36: =K36 -> 0.25433176 | J36: 0.16701517 | K36: =K33/K38 -> 0.25433176
B38: Basic Shares Outstanding | D38: ='Income Statement'!BP103 -> 75430 | E38: =K38 -> 77509 | G38: ='Income Statement'!BT103 -> 77528 | H38: =K38 -> 77509 | J38: 78028 | K38: ='Income Statement'!BU103 -> 77509
B39: Diluted Shares Outstanding | D39: ='Income Statement'!BP104 -> 75999 | E39: =K39 -> 77624 | G39: ='Income Statement'!BT104 -> 77883 | H39: =K39 -> 77624 | J39: 78383 | K39: ='Income Statement'!BU104 -> 77624 | P39: 72000 | S39: 73000
B42: Source: Company reports and Needham & Co estimates | L42: Capex | P42: =(10000+11000)/2 -> 10500 | S42: =(69000+71000)/2 -> 70000

Sheet G CHANGE
C5: FY26 Guidance | D5: FY26 Street Expectations | E5: Initial FY26 Guide | F5: Delta | G5: 3Q25 Guide | H5: 3Q25 Results | I5: 3Q25 Beat | J5: Rest of Year Raise / (Reduce)
C6: Revenue ($mm) | D6: 1254 | E6: 1254 | F6: =E6-D6 -> 0 | G6: 284.5 | H6: =Comparison!K5/1000 -> 300.282 | I6: =H6-G6 -> 15.782 | J6: =F6-I6 -> -15.782
C7: Growth | D7: =D6/('Income Statement'!BV28/1000)-1 -> 0.091300231 | E7: =E6/('Income Statement'!BV28/1000)-1 -> 0.091300231
C8: Non-GAAP EPS | D8: 3.18 | E8: 3.18 | F8: =E8-D8 -> 0 | G8: 0.73 | H8: =Comparison!K35 -> 0.80433886 | I8: =H8-G8 -> 0.074338864 | J8: =F8-I8 -> -0.074338864

Sheet Income Statement
B2: Five9, Inc (Nasdaq: FIVN)
B4: Income Statement | D4: 2011 | E4: 1Q12 | F4: 2Q12 | G4: 3Q12 | H4: 4Q12 | I4: 2012 | J4: 1Q13 | K4: 2Q13 | L4: 3Q13 | M4: 4Q13 | N4: 2013 | O4: 1Q14 | P4: 2Q14 | Q4: 3Q14 | R4: 4Q14 | S4: 2014 | T4: 1Q15 | U4: 2Q15 | V4: 3Q15 | W4: 4Q15 | X4: 2015 | Y4: 1Q16 | Z4: 2Q16 | AA4: 3Q16 | AB4: 4Q16 | AC4: 2016 | AD4: 1Q17 | AE4: 2Q17 | AF4: 3Q17 | AG4: 4Q17 | AH4: 2017 | AI4: 1Q18 | AJ4: 2Q18 | AK4: 3Q18 | AL4: 4Q18 | AM4: 2018 | AN4: 1Q19 | AO4: 2Q19 | AP4: 3Q19 | AQ4: 4Q19 | AR4: 2019 | AS4: 1Q20 | AT4: 2Q20 | AU4: 3Q20 | AV4: 4Q20 | AW4: 2020 | AX4: 1Q21 | AY4: 2Q21 | AZ4: 3Q21 | BA4: 4Q21 | BB4: 2021 | BC4: 1Q22 | BD4: 2Q22 | BE4: 3Q22 | BF4: 4Q22 | BG4: 2022 | BH4: 1Q23 | BI4: 2Q23 | BJ4: 3Q23 | BK4: 4Q23 | BL4: 2023 | BM4: 1Q24 | BN4: 2Q24 | BO4: 3Q24 | BP4: 4Q24 | BQ4: 2024 | BR4: 1Q25 | BS4: 2Q25 | BT4: 3Q25 | BU4: 4Q25 | BV4: 2025 | BW4: 1Q26E | BX4: 2Q26E | BY4: 3Q26E | BZ4: 4Q26E | CA4: 2026E
B5: Total Revenues | D5: 43188 | E5: 14321.11 | F5: 15027.74 | G5: 16202.043 | H5: 18271.429 | I5: =SUM(E5:H5) -> 63822.321 | J5: 19115.125 | K5: 20282.901 | L5: 21091.22 | M5: 23642.754 | N5: =SUM(J5:M5) -> 84132 | O5: 24274 | P5: 24685 | Q5: 25869 | R5: 28274 | S5: =SUM(O5:R5) -> 103102 | T5: 30274 | U5: 30274 | V5: 32287 | W5: 36033 | X5: =SUM(T5:W5) -> 128868 | Y5: 38015 | Z5: 38886 | AA5: 40982 | AB5: 44207 | AC5: =SUM(Y5:AB5) -> 162090 | AD5: 47014 | AE5: 47727 | AF5: 50081 | AG5: 55403 | AH5: =SUM(AD5:AG5) -> 200225 | AI5: 58905 | AJ5: 61120 | AK5: 65304 | AL5: 72335 | AM5: =SUM(AI5:AL5) -> 257664 | AN5: 74538 | AO5: =77436 -> 77436 | AP5: 83769 | AQ5: =92263 -> 92263 | AR5: =SUM(AN5:AQ5) -> 328006 | AS5: 95088 | AT5: 99792 | AU5: =112143 -> 112143 | AV5: =127885 -> 127885 | AW5: =SUM(AS5:AV5) -> 434908 | AX5: 137882 | AY5: 143782 | AZ5: 154328 | BA5: 173599 | BB5: =SUM(AX5:BA5) -> 609591 | BC5: 182777 | BD5: 189382 | BE5: 198342 | BF5: 208345 | BG5: =SUM(BC5:BF5) -> 778846 | BH5: 218439 | BI5: 222882 | BJ5: 230105 | BK5: 239062 | BL5: =SUM(BH5:BK5) -> 910488 | BM5: 247010 | BN5: 252086 | BO5: 264182 | BP5: 278660 | BQ5: =SUM(BM5:BP5) -> 1041938 | BR5: 279705 | BS5: 283269 | BT5: 285832 | BU5: 300282 | BV5: =SUM(BR5:BU5) -> 1149088 | BW5: =BW9+BW24 -> 299228.41 | BX5: =BX9+BX24 -> 306327.1 | BY5: =BY9+BY24 -> 313729.2 | BZ5: =BZ9+BZ24 -> 337396.86 | CA5: =SUM(BW5:BZ5) -> 1256681.6
C6: Y/Y Growth | I6: =I5/D5-1 -> 0.47777905 | J6: =J5/E5-1 -> 0.33475164 | K6: =K5/F5-1 -> 0.34969741 | L6: =L5/G5-1 -> 0.30176301 | M6: =M5/H5-1 -> 0.29397397 | N6: =N5/I5-1 -> 0.31822218 | O6: =O5/J5-1 -> 0.26988446 | P6: =P5/K5-1 -> 0.21703497 | ... CA6: =CA5/BV5-1 -> 0.093633877
C7: Q/Q Growth | F7: =F5/E5-1 -> 0.049341833 | G7: =G5/F5-1 -> 0.078142386 | H7: =H5/G5-1 -> 0.12772378 | J7: =J5/H5-1 -> 0.046175674 | K7: =K5/J5-1 -> 0.06109175 | L7: =L5/K5-1 -> 0.039852237 | M7: =M5/L5-1 -> 0.1209761 | O7: =O5/M5-1 -> 0.026699351 | P7: =P5/O5-1 -> 0.016931696 | Q7: =Q5/P5-1 -> 0.047964351 | R7: =R5/Q5-1 -> 0.092968418 | T7: =T5/R5-1 -> 0.070736366 | U7: =U5/T5-1 -> 0 | V7: =V5/U5-1 -> 0.0664927 | W7: =W5/V5-1 -> 0.11602193 | Y7: =Y5/W5-1 -> 0.055005134 | Z7: =Z5/Y5-1 -> 0.022912008 | AA7: =AA5/Z5-1 -> 0.053901147 | AB7: =AB5/AA5-1 -> 0.078693085 | AD7: =AD5/AB5-1 -> 0.063496731 | AE7: =AE5/AD5-1 -> 0.015165695 | AF7: =AF5/AE5-1 -> 0.049322187 | AG7: =AG5/AF5-1 -> 0.10626785 | AI7: =AI5/AG5-1 -> 0.063209573 | AJ7: =AJ5/AI5-1 -> 0.03760292 | AK7: =AK5/AJ5-1 -> 0.068455497 | AL7: =AL5/AK5-1 -> 0.10766569 | AN7: =AN5/AL5-1 -> 0.030455519 | AO7: =AO5/AN5-1 -> 0.038879498 | AP7: =AP5/AO5-1 -> 0.081783667 | AQ7: =AQ5/AP5-1 -> 0.10139789 | AS7: =AS5/AQ5-1 -> 0.030618991 | AT7: =AT5/AS5-1 -> 0.049469965 | AU7: =AU5/AT5-1 -> 0.12376744 | AV7: =AV5/AU5-1 -> 0.14037434 | AX7: =AX5/AV5-1 -> 0.078171795 | AY7: =AY5/AX5-1 -> 0.042790212 | AZ7: =AZ5/AY5-1 -> 0.073347151 | BA7: =BA5/AZ5-1 -> 0.12487041 | BC7: =BC5/BA5-1 -> 0.052868968 | BD7: =BD5/BC5-1 -> 0.036136932 | BE7: =BE5/BD5-1 -> 0.047311783 | BF7: =BF5/BE5-1 -> 0.05043309 | BH7: =BH5/BF5-1 -> 0.048448487 | BI7: =BI5/BH5-1 -> 0.020339774 | BJ7: =BJ5/BI5-1 -> 0.032407283 | BK7: =BK5/BJ5-1 -> 0.038925708 | BM7: =BM5/BK5-1 -> 0.033246605 | BN7: =BN5/BM5-1 -> 0.020549775 | BO7: =BO5/BN5-1 -> 0.047983625 | BP7: =BP5/BO5-1 -> 0.054803128 | BR7: =BR5/BP5-1 -> 0.0037500897 | BS7: =BS5/BR5-1 -> 0.012741996 | BT7: =BT5/BS5-1 -> 0.0090479368 | BU7: =BU5/BT5-1 -> 0.050554172 | BW7: =BW5/BU5-1 -> -0.0035086718 | BX7: =BX5/BW5-1 -> 0.023723308 | BY7: =BY5/BX5-1 -> 0.024164061 | BZ7: =BZ5/BY5-1 -> 0.075439748
B9: Recurring Revenue | T9: =T10*T5 -> 29365.78 | U9: =U10*U5 -> 29063.04 | V9: =V10*V5 -> 30995.52 | W9: =W10*W5 -> 34591.68 | Y9: =Y10*Y5 -> 36114.25 | Z9: =Z10*Z5 -> 36552.84 | AA9: =AA10*AA5 -> 39342.72 | AB9: =AB10*AB5 -> 41996.65 | AD9: =AD10*AD5 -> 44193.16 | AE9: =AE10*AE5 -> 44863.38 | AF9: =AF10*AF5 -> 46575.33 | AG9: =AG10*AG5 -> 52632.85 | AH9: =SUM(AD9:AG9) -> 188264.72 | AI9: =AI10*AI5 -> 54192.6 | AJ9: =AJ10*AJ5 -> 56841.6 | AK9: =AK10*AK5 -> 60732.72 | AL9: =AL10*AL5 -> 67271.55 | AM9: =SUM(AI9:AL9) -> 239038.47 | AN9: =AN10*AN5 -> 69320.34 | AO9: =AO10*AO5 -> 71241.12 | AP9: =AP10*AP5 -> 76229.79 | AQ9: =AQ10*AQ5 -> 84881.96 | AR9: =SUM(AN9:AQ9) -> 301673.21 | AS9: =AS10*AS5 -> 86530.08 | AT9: =AT10*AT5 -> 91808.64 | AU9: =AU10*AU5 -> 104292.99 | AV9: =AV10*AV5 -> 118933.05 | AW9: =SUM(AS9:AV9) -> 401564.76 | AX9: =AX10*AX5 -> 126851.44 | AY9: =AY10*AY5 -> 132279.44 | AZ9: =AZ10*AZ5 -> 141981.76 | BA9: =BA10*BA5 -> 161447.07 | BB9: =SUM(AX9:BA9) -> 562559.71 | BC9: =BC10*BC5 -> 166327.07 | BD9: =BD10*BD5 -> 172337.62 | BE9: =BE10*BE5 -> 180491.22 | BF9: =BF10*BF5 -> 191677.4 | BG9: =SUM(BC9:BF9) -> 710833.31 | BH9: =BH10*BH5 -> 200963.88 | BI9: =BI10*BI5 -> 202822.62 | BJ9: =BJ10*BJ5 -> 211696.6 | BK9: =BK10*BK5 -> 219937.04 | BL9: =SUM(BH9:BK9) -> 835420.14 | BM9: =BM10*BM5 -> 229719.3 | BN9: =BN10*BN5 -> 231919.12 | BO9: =+BO14+BO19 -> 245689.26 | BP9: =+BP14+BP19 -> 259153.8 | BQ9: =SUM(BM9:BP9) -> 966481.48 | BR9: =+BR14+BR19 -> 260125.65 | BS9: =+BS14+BS19 -> 263440.17 | BT9: =+BT14+BT19 -> 265823.76 | BU9: =+BU14+BU19 -> 279262.26 | BV9: =SUM(BR9:BU9) -> 1068651.8 | BW9: =+BW14+BW19 -> 278865.89 | BX9: =+BX14+BX19 -> 285705.11 | BY9: =+BY14+BY19 -> 292920.63 | BZ9: =+BZ14+BZ19 -> 315536.33 | CA9: =SUM(BW9:BZ9) -> 1173028
C10: % of Revenue | T10: 0.97 | U10: 0.96 | V10: 0.96 | W10: 0.96 | Y10: 0.95 | Z10: 0.94 | AA10: 0.96 | AB10: 0.95 | AC10: 0.95 | AD10: 0.94 | AE10: 0.94 | AF10: 0.93 | AG10: 0.95 | AH10: 0.93 | AI10: 0.92 | AJ10: 0.93 | AK10: 0.93 | AL10: 0.93 | AM10: 0.93 | AN10: 0.93 | AO10: 0.92 | AP10: 0.91 | AQ10: 0.92 | AR10: 0.92 | AS10: 0.91 | AT10: 0.92 | AU10: 0.93 | AV10: 0.93 | AX10: 0.92 | AY10: 0.92 | AZ10: 0.92 | BA10: 0.93 | BC10: 0.91 | BD10: 0.91 | BE10: 0.91 | BF10: 0.92 | BH10: 0.92 | BI10: 0.91 | BJ10: 0.92 | BK10: 0.92 | BM10: 0.93 | BN10: 0.92 | BO10: =+BO15+BO20 -> 0.93 | BP10: =+BP15+BP20 -> 0.93 | BR10: =BR9/BR5 -> 0.93 | BS10: =BS9/BS5 -> 0.93 | BT10: =BT9/BT5 -> 0.93 | BU10: =BU9/BU5 -> 0.93 | BW10: =BW9/BW5 -> 0.9319499 | BX10: =BX9/BX5 -> 0.93267986 | BY10: =BY9/BY5 -> 0.93367347 | BZ10: =BZ9/BZ5 -> 0.93520826
C11: Y/Y Growth | T11: =T9/O9-1 -> #DIV/0! | U11: =U9/P9-1 -> #DIV/0! | V11: =V9/Q9-1 -> #DIV/0! | W11: =W9/R9-1 -> #DIV/0! | Y11: =Y9/T9-1 -> 0.22980728 | Z11: =Z9/U9-1 -> 0.25770876 | AA11: =AA9/V9-1 -> 0.26930343 | AB11: =AB9/W9-1 -> 0.21406795 | AD11: =AD9/Y9-1 -> 0.22370422 | AE11: =AE9/Z9-1 -> 0.22735689 | AF11: =AF9/AA9-1 -> 0.18383604 | AG11: =AG9/AB9-1 -> 0.25326306 | AI11: =AI9/AD9-1 -> 0.22626669 | AJ11: =AJ9/AE9-1 -> 0.26699326 | AK11: =AK9/AF9-1 -> 0.30396757 | AL11: =AL9/AG9-1 -> 0.27812858 | AN11: =AN9/AI9-1 -> 0.27914771 | AO11: =AO9/AJ9-1 -> 0.25332714 | AP11: =AP9/AK9-1 -> 0.25516838 | AQ11: =AQ9/AL9-1 -> 0.26178095 | AR11: =AR9/AM9-1 -> 0.26202787 | AS11: =AS9/AN9-1 -> 0.24826393 | AT11: =AT9/AO9-1 -> 0.28870293 | AU11: =AU9/AP9-1 -> 0.36813954 | ... CA11: =CA9/BV9-1 -> 0.097670835
C12: Q/Q Growth | T12: =T9/R9-1 -> #DIV/0! | U12: =U9/T9-1 -> -0.010309278 | V12: =V9/U9-1 -> 0.0664927 | W12: =W9/V9-1 -> 0.11602193 | Y12: =Y9/W9-1 -> 0.044015497 | Z12: =Z9/Y9-1 -> 0.012144514 | AA12: =AA9/Z9-1 -> 0.076324576 | AB12: =AB9/AA9-1 -> 0.067456698 | AD12: =AD9/AB9-1 -> 0.052302029 | AE12: =AE9/AD9-1 -> 0.015165695 | AF12: =AF9/AE9-1 -> 0.038159185 | AG12: =AG9/AF9-1 -> 0.13005855 | AI12: =AI9/AG9-1 -> 0.029634534 | AJ12: =AJ9/AI9-1 -> 0.048881213 | AK12: =AK9/AJ9-1 -> 0.068455497 | AL12: =AL9/AK9-1 -> 0.10766569 | AN12: =AN9/AL9-1 -> 0.030455519 | AO12: =AO9/AN9-1 -> 0.02770875 | AP12: =AP9/AO9-1 -> 0.070025148 | AQ12: =AQ9/AP9-1 -> 0.11350117 | AS12: =AS9/AQ9-1 -> 0.019416611 | AT12: =AT9/AS9-1 -> 0.061002602 | AU12: =AU9/AT9-1 -> 0.1359823 | AV12: =AV9/AU9-1 -> 0.14037434 | AX12: =AX9/AV9-1 -> 0.06657855 | AY12: =AY9/AX9-1 -> 0.042790212 | AZ12: =AZ9/AY9-1 -> 0.073347151 | BA12: =BA9/AZ9-1 -> 0.13709726 | BC12: =BC9/BA9-1 -> 0.030226625 | BD12: =BD9/BC9-1 -> 0.036136932 | BE12: =BE9/BD9-1 -> 0.047311783 | BF12: =BF9/BE9-1 -> 0.061976311 | BH12: =BH9/BF9-1 -> 0.048448487 | BI12: =BI9/BH9-1 -> 0.0092491248 | BJ12: =BJ9/BI9-1 -> 0.043752418 | BK12: =BK9/BJ9-1 -> 0.038925708 | BM12: =BM9/BK9-1 -> 0.044477547 | BN12: =BN9/BL9-1 -> -0.72239223 | BO12: =BO9/BN9-1 -> 0.059374751 | BP12: =BP9/BO9-1 -> 0.054803128 | BR12: =BR9/BP9-1 -> 0.0037500897 | BS12: =BS9/BR9-1 -> 0.012741996 | BT12: =BT9/BS9-1 -> 0.0090479368 | BU12: =BU9/BT9-1 -> 0.050554172 | BW12: =BW9/BU9-1 -> -0.0014193647 | BX12: =BX9/BW9-1 -> 0.024525153 | BY12: =BY9/BX9-1 -> 0.025255131 | BZ12: =BZ9/BY9-1 -> 0.077207576
C14: Subscription Revenue | BM14: =((BR14)/(1.14)) -> 196284.21 | BN14: =+BS14/1.16 -> 197799.91 | BO14: =BO15*BO5 -> 211345.6 | BP14: =BP15*BP5 -> 220141.4 | BQ14: =SUM(BM14:BP14) -> 825571.12 | BR14: =BR15*BR5 -> 223764 | BS14: =BS15*BS5 -> 229447.89 | BT14: =BT15*BT5 -> 231523.92 | BU14: =BU15*BU5 -> 246231.24 | BV14: =SUM(BR14:BU14) -> 930967.05 | BW14: =BR14*(1+BW16) -> 246140.4 | BX14: =BS14*(1+BX16) -> 252392.68 | BY14: =BT14*(1+BY16) -> 259306.79 | BZ14: =BU14*(1+BZ16) -> 283165.93 | CA14: =SUM(BW14:BZ14) -> 1041005.8
C15: % of Revenue | BO15: 0.8 | BP15: 0.79 | BR15: 0.8 | BS15: 0.81 | BT15: 0.81 | BU15: 0.82 | BW15: =BW14/BW5 -> 0.82258366 | BX15: =BX14/BX5 -> 0.82393194 | BY15: =BY14/BY5 -> 0.82653061 | BZ15: =BZ14/BZ5 -> 0.83926664
C16: Y/Y Growth | BR16: =+BR14/BM14-1 -> 0.14 | BS16: =+BS14/BN14-1 -> 0.16 | BT16: =+BT14/BO14-1 -> 0.095475468 | BU16: =+BU14/BP14-1 -> 0.11851401 | BW16: 0.1 | BX16: 0.1 | BY16: 0.12 | BZ16: 0.15 | CA16: =CA14/BV14-1 -> 0.11819832
C17: Q/Q Growth | BR17: =BR14/BP14-1 -> 0.016455787 | BS17: =BS14/BR14-1 -> 0.025401271 | BT17: =BT14/BS14-1 -> 0.0090479368 | BU17: =BU14/BT14-1 -> 0.063523976 | BW17: =BW14/BU14-1 -> -0.00036892151 | BX17: =BX14/BW14-1 -> 0.025401271 | BY17: =BY14/BX14-1 -> 0.027394263 | BZ17: =BZ14/BY14-1 -> 0.092011226
C19: Usage Revenue | BM19: =+BM9-BM14 -> 33435.089 | BN19: =+BN9-BN14 -> 34119.215 | BO19: =BO20*BO5 -> 34343.66 | BP19: =BP20*BP5 -> 39012.4 | BQ19: =SUM(BM19:BP19) -> 140910.36 | BR19: =BR20*BR5 -> 36361.65 | BS19: =BS20*BS5 -> 33992.28 | BT19: =BT20*BT5 -> 34299.84 | BU19: =BU20*BU5 -> 33031.02 | BV19: =SUM(BR19:BU19) -> 137684.79 | BW19: =BR19*(1+BW21) -> 32725.485 | BX19: =BS19*(1+BX21) -> 33312.434 | BY19: =BT19*(1+BY21) -> 33613.843 | BZ19: =BU19*(1+BZ21) -> 32370.4 | CA19: =SUM(BW19:BZ19) -> 132022.16
C20: % of Revenue | BO20: 0.13 | BP20: 0.14 | BR20: 0.13 | BS20: 0.12 | BT20: 0.12 | BU20: 0.11 | BW20: =BW19/BW5 -> 0.10936624 | BX20: =BX19/BX5 -> 0.10874792 | BY20: =BY19/BY5 -> 0.10714286 | BZ20: =BZ19/BZ5 -> 0.095941616
C21: Y/Y Growth | BR21: =BR19/BM19-1 -> 0.087529616 | BS21: =BS19/BN19-1 -> -0.0037203326 | BT21: =BT19/BO19-1 -> -0.0012759269 | BU21: =BU19/BP19-1 -> -0.15331997 | BV21: =BV19/BQ19-1 -> -0.022890966 | BW21: -0.1 | BX21: -0.02 | BY21: -0.02 | BZ21: -0.02 | CA21: =CA19/BV19-1 -> -0.041127475
C22: Q/Q Growth | BR22: =BR19/BP19-1 -> -0.067946345 | BS22: =BS19/BR19-1 -> -0.065161234 | BT22: =BT19/BS19-1 -> 0.0090479368 | BU22: =BU19/BT19-1 -> -0.036992009 | BW22: =BW19/BU19-1 -> -0.0092499414 | BX22: =BX19/BW19-1 -> 0.017935545 | BY22: =BY19/BX19-1 -> 0.0090479368 | BZ22: =BZ19/BY19-1 -> -0.036992009
B24: Non-Recurring Revenue | T24: =T25*T5 -> 908.22 | U24: =U25*U5 -> 1210.96 | V24: =V25*V5 -> 1291.48 | W24: =W25*W5 -> 1441.32 | Y24: =Y25*Y5 -> 1900.75 | Z24: =Z25*Z5 -> 2333.16 | AA24: =AA25*AA5 -> 1639.28 | AB24: =AB25*AB5 -> 2210.35 | AD24: =AD25*AD5 -> 2820.84 | AE24: =AE25*AE5 -> 2863.62 | AF24: =AF25*AF5 -> 3505.67 | AG24: =AG25*AG5 -> 2770.15 | AI24: =AI25*AI5 -> 4712.4 | AJ24: =AJ25*AJ5 -> 4278.4 | AK24: =AK25*AK5 -> 4571.28 | AL24: =AL25*AL5 -> 5063.45 | AM24: =SUM(AI24:AL24) -> 18625.53 | AN24: =AN25*AN5 -> 5217.66 | AO24: =AO25*AO5 -> 6194.88 | AP24: =AP25*AP5 -> 7539.21 | AQ24: =AQ25*AQ5 -> 7381.04 | AR24: =SUM(AN24:AQ24) -> 26332.79 | AS24: =AS25*AS5 -> 8557.92 | AT24: =AT25*AT5 -> 7983.36 | AU24: =AU25*AU5 -> 7850.01 | AV24: =AV25*AV5 -> 8951.95 | AW24: =SUM(AS24:AV24) -> 33343.24 | AX24: =AX25*AX5 -> 11030.56 | AY24: =AY25*AY5 -> 11502.56 | AZ24: =AZ25*AZ5 -> 12346.24 | BA24: =BA25*BA5 -> 12151.93 | BB24: =SUM(AX24:BA24) -> 47031.29 | BC24: =BC25*BC5 -> 16449.93 | BD24: =BD25*BD5 -> 17044.38 | BE24: =BE25*BE5 -> 17850.78 | BF24: =BF25*BF5 -> 16667.6 | BG24: =SUM(BC24:BF24) -> 68012.69 | BH24: =BH25*BH5 -> 17475.12 | BI24: =BI25*BI5 -> 20059.38 | BJ24: =BJ25*BJ5 -> 18408.4 | BK24: =BK25*BK5 -> 19124.96 | BL24: =SUM(BH24:BK24) -> 75067.86 | BM24: =BM25*BM5 -> 17290.7 | BN24: =BN25*BN5 -> 20166.88 | BO24: =BO25*BO5 -> 18492.74 | BP24: =BP25*BP5 -> 19506.2 | BQ24: =SUM(BM24:BP24) -> 75456.52 | BR24: =BR25*BR5 -> 19579.35 | BS24: =BS25*BS5 -> 19828.83 | BT24: =BT25*BT5 -> 20008.24 | BU24: =BU25*BU5 -> 21019.74 | BV24: =SUM(BR24:BU24) -> 80436.16 | BW24: =BR24*(1+BW26) -> 20362.524 | BX24: =BS24*(1+BX26) -> 20621.983 | BY24: =BT24*(1+BY26) -> 20808.57 | BZ24: =BU24*(1+BZ26) -> 21860.53 | CA24: =SUM(BW24:BZ24) -> 83653.606
C25: % of Revenue | T25: =1-T10 -> 0.03 | U25: =1-U10 -> 0.04 | V25: =1-V10 -> 0.04 | W25: =1-W10 -> 0.04 | Y25: =1-Y10 -> 0.05 | Z25: =1-Z10 -> 0.06 | AA25: =1-AA10 -> 0.04 | AB25: =1-AB10 -> 0.05 | AD25: =1-AD10 -> 0.06 | AE25: =1-AE10 -> 0.06 | AF25: =1-AF10 -> 0.07 | AG25: =1-AG10 -> 0.05 | AI25: =1-AI10 -> 0.08 | AJ25: =1-AJ10 -> 0.07 | AK25: =1-AK10 -> 0.07 | AL25: =1-AL10 -> 0.07 | AN25: =1-AN10 -> 0.07 | AO25: =1-AO10 -> 0.08 | AP25: =1-AP10 -> 0.09 | AQ25: =1-AQ10 -> 0.08 | AS25: =1-AS10 -> 0.09 | AT25: 0.08 | AU25: 0.07 | AV25: 0.07 | AX25: =1-AX10 -> 0.08 | AY25: 0.08 | AZ25: 0.08 | BA25: 0.07 | BC25: =1-BC10 -> 0.09 | BD25: =1-BD10 -> 0.09 | BE25: =1-BE10 -> 0.09 | BF25: =1-BF10 -> 0.08 | BH25: =1-BH10 -> 0.08 | BI25: =1-BI10 -> 0.09 | BJ25: 0.08 | BK25: 0.08 | BM25: =1-BM10 -> 0.07 | BN25: =1-BN10 -> 0.08 | BO25: =1-BO10 -> 0.07 | BP25: =1-BP10 -> 0.07 | BR25: 0.07 | BS25: 0.07 | BT25: 0.07 | BU25: 0.07 | BW25: =1-BW10 -> 0.068050103 | BX25: =BX24/BX5 -> 0.067320141 | BY25: =BY24/BY5 -> 0.066326531 | BZ25: =BZ24/BZ5 -> 0.064791741
C26: Y/Y Growth | T26: =T24/O24-1 -> #DIV/0! | U26: =U24/P24-1 -> #DIV/0! | V26: =V24/Q24-1 -> #DIV/0! | W26: =W24/R24-1 -> #DIV/0! | Y26: =Y24/T24-1 -> 1.0928299 | Z26: =Z24/U24-1 -> 0.92670278 | AA26: =AA24/V24-1 -> 0.26930343 | AB26: =AB24/W24-1 -> 0.53355951 | AD26: =AD24/Y24-1 -> 0.48406682 | AE26: =AE24/Z24-1 -> 0.22735689 | AF26: =AF24/AA24-1 -> 1.1385425 | AG26: =AG24/AB24-1 -> 0.25326306 | AI26: =AI24/AD24-1 -> 0.67056621 | AJ26: =AJ24/AE24-1 -> 0.49405298 | AK26: =AK24/AF24-1 -> 0.30396757 | AL26: =AL24/AG24-1 -> 0.82786131 | AN26: =AN24/AI24-1 -> 0.10721925 | AO26: =AO24/AJ24-1 -> 0.44794316 | AP26: =AP24/AK24-1 -> 0.64925579 | AQ26: =AQ24/AL24-1 -> 0.45770966 | AR26: =AR24/AM24-1 -> 0.41380084 | AS26: =AS24/AN24-1 -> 0.64018353 | AT26: =AT24/AO24-1 -> 0.28870293 | AU26: =AU24/AP24-1 -> 0.041224478 | ... BV26: =BV24/BQ24-1 -> 0.065993502 | BW26: 0.04 | BX26: 0.04 | BY26: 0.04 | BZ26: 0.04 | CA26: =CA24/BV24-1 -> 0.04
C27: Q/Q Growth | T27: =T24/R24-1 -> #DIV/0! | U27: =U24/T24-1 -> 0.33333333 | V27: =V24/U24-1 -> 0.0664927 | W27: =W24/V24-1 -> 0.11602193 | Y27: =Y24/W24-1 -> 0.31875642 | Z27: =Z24/Y24-1 -> 0.22749441 | AA27: =AA24/Z24-1 -> -0.29739924 | AB27: =AB24/AA24-1 -> 0.34836636 | AD27: =AD24/AB24-1 -> 0.27619608 | AE27: =AE24/AD24-1 -> 0.015165695 | AF27: =AF24/AE24-1 -> 0.22420922 | AG27: =AG24/AF24-1 -> -0.20980868 | AI27: =AI24/AG24-1 -> 0.70113532 | AJ27: =AJ24/AI24-1 -> -0.092097445 | AK27: =AK24/AJ24-1 -> 0.068455497 | AL27: =AL24/AK24-1 -> 0.10766569 | AN27: =AN24/AL24-1 -> 0.030455519 | AO27: =AO24/AN24-1 -> 0.18729085 | AP27: =AP24/AO24-1 -> 0.21700662 | AQ27: =AQ24/AP24-1 -> -0.020979652 | AS27: =AS24/AQ24-1 -> 0.15944637 | AT27: =AT24/AS24-1 -> -0.067137809 | AU27: =AU24/AT24-1 -> -0.016703493 | AV27: =AV24/AU24-1 -> 0.14037434 | AX27: =AX24/AV24-1 -> 0.23219634 | AY27: =AY24/AX24-1 -> 0.042790212 | AZ27: =AZ24/AY24-1 -> 0.073347151 | BA27: =BA24/AZ24-1 -> -0.015738395 | BC27: =BC24/BA24-1 -> 0.35368867 | BD27: =BD24/BC24-1 -> 0.036136932 | BE27: =BE24/BD24-1 -> 0.047311783 | BF27: =BF24/BE24-1 -> -0.066281697 | BH27: =BH24/BF24-1 -> 0.048448487 | BI27: =BI24/BH24-1 -> 0.14788225 | BJ27: =BJ24/BI24-1 -> -0.082304638 | BK27: =BK24/BJ24-1 -> 0.038925708 | BM27: =BM24/BK24-1 -> -0.09590922 | BN27: =BN24/BM24-1 -> 0.1663426 | BO27: =BO24/BN24-1 -> -0.083014328 | BP27: =BP24/BO24-1 -> 0.054803128 | BR27: =BR24/BP24-1 -> 0.0037500897 | BS27: =BS24/BR24-1 -> 0.012741996 | BT27: =BT24/BS24-1 -> 0.0090479368 | BU27: =BU24/BT24-1 -> 0.050554172 | BW27: =BW24/BU24-1 -> -0.031266609 | BX27: =BX24/BW24-1 -> 0.012741996 | BY27: =BY24/BX24-1 -> 0.0090479368 | BZ27: =BZ24/BY24-1 -> 0.050554172
B28: Total Revenues | D28: =D5 -> 43188 | E28: =E5 -> 14321.11 | F28: =F5 -> 15027.74 | G28: =G5 -> 16202.043 | H28: =H5 -> 18271.429 | I28: =SUM(I5) -> 63822.321 | J28: =J5 -> 19115.125 | K28: =K5 -> 20282.901 | L28: =L5 -> 21091.22 | M28: =M5 -> 23642.754 | N28: =SUM(N5) -> 84132 | O28: =O5 -> 24274 | P28: =P5 -> 24685 | Q28: =Q5 -> 25869 | R28: =R5 -> 28274 | S28: =SUM(S5) -> 103102 | T28: =T5 -> 30274 | U28: =U5 -> 30274 | V28: =V5 -> 32287 | W28: =W5 -> 36033 | X28: =SUM(X5) -> 128868 | Y28: =Y5 -> 38015 | Z28: =Z5 -> 38886 | AA28: =AA5 -> 40982 | AB28: =AB5 -> 44207 | AC28: =SUM(AC5) -> 162090 | AD28: =AD5 -> 47014 | AE28: =AE5 -> 47727 | AF28: =AF5 -> 50081 | AG28: =AG5 -> 55403 | AH28: =AH5 -> 200225 | AI28: =AI5 -> 58905 | AJ28: =AJ5 -> 61120 | AK28: =AK5 -> 65304 | ... AX28: =AX5 -> 137882 | AY28: 143782 | AZ28: =AZ5 -> 154328 | BA28: =BA5 -> 173599 | BB28: =BB5 -> 609591 | BC28: =BC5 -> 182777 | BD28: =BD5 -> 189382 | BE28: =BE5 -> 198342 | BF28: =BF5 -> 208345 | BG28: =BG5 -> 778846 | ... BI28: =BI5 -> 222882 | BJ28: 230105 | BK28: =BK5 -> 239062 | BL28: =BL5 -> 910488 | BM28: =BM5 -> 247010 | BN28: =BN5 -> 252086 | BO28: =BO5 -> 264182 | BP28: 278660 | BQ28: =BQ5 -> 1041938 | BR28: 279705 | BS28: =BS5 -> 283269 | BT28: =BT5 -> 285832 | BU28: =BU5 -> 300282 | BV28: =BV5 -> 1149088 | BW28: =BW5 -> 299228.41 | BX28: =BX5 -> 306327.1 | BY28: =BY5 -> 313729.2 | BZ28: =BZ5 -> 337396.86 | CA28: =CA5 -> 1256681.6
C29: Y/Y Growth | I29: =I28/D28-1 -> 0.47777905 | J29: =J28/E28-1 -> 0.33475164 | K29: =K28/F28-1 -> 0.34969741 | L29: =L28/G28-1 -> 0.30176301 | M29: =M28/H28-1 -> 0.29397397 | N29: =N28/I28-1 -> 0.31822218 | O29: =O28/J28-1 -> 0.26988446 | P29: =P28/K28-1 -> 0.21703497 | ... CA29: =CA28/BV28-1 -> 0.093633877
C30: Q/Q Growth | F30: =F28/E28-1 -> 0.049341833 | G30: =G28/F28-1 -> 0.078142386 | H30: =H28/G28-1 -> 0.12772378 | J30: =J28/H28-1 -> 0.046175674 | K30: =K28/J28-1 -> 0.06109175 | L30: =L28/K28-1 -> 0.039852237 | M30: =M28/L28-1 -> 0.1209761 | O30: =O28/M28-1 -> 0.026699351 | P30: =P28/O28-1 -> 0.016931696 | Q30: =Q28/P28-1 -> 0.047964351 | R30: =R28/Q28-1 -> 0.092968418 | T30: =T28/R28-1 -> 0.070736366 | U30: =U28/T28-1 -> 0 | V30: =V28/U28-1 -> 0.0664927 | W30: =W28/V28-1 -> 0.11602193 | Y30: =Y28/W28-1 -> 0.055005134 | Z30: =Z28/Y28-1 -> 0.022912008 | AA30: =AA28/Z28-1 -> 0.053901147 | AB30: =AB28/AA28-1 -> 0.078693085 | AD30: =AD28/AB28-1 -> 0.063496731 | AE30: =AE28/AD28-1 -> 0.015165695 | AF30: =AF28/AE28-1 -> 0.049322187 | AG30: =AG28/AF28-1 -> 0.10626785 | AI30: =AI28/AG28-1 -> 0.063209573 | AJ30: =AJ28/AI28-1 -> 0.03760292 | AK30: =AK28/AJ28-1 -> 0.068455497 | AL30: =AL28/AK28-1 -> 0.10766569 | AN30: =AN28/AL28-1 -> 0.030455519 | AO30: =AO28/AN28-1 -> 0.038879498 | AP30: =AP28/AO28-1 -> 0.081783667 | AQ30: =AQ28/AP28-1 -> 0.10139789 | AS30: =AS28/AQ28-1 -> 0.030618991 | AT30: =AT28/AS28-1 -> 0.049469965 | AU30: =AU28/AT28-1 -> 0.12376744 | AV30: =AV28/AU28-1 -> 0.14037434 | AX30: =AX28/AV28-1 -> 0.078171795 | AY30: =AY28/AX28-1 -> 0.042790212 | AZ30: =AZ28/AY28-1 -> 0.073347151 | BA30: =BA28/AZ28-1 -> 0.12487041 | BC30: =BC28/BA28-1 -> 0.052868968 | BD30: =BD28/BC28-1 -> 0.036136932 | BE30: =BE28/BD28-1 -> 0.047311783 | BF30: =BF28/BE28-1 -> 0.05043309 | BH30: =BH28/BF28-1 -> 0.048448487 | BI30: =BI28/BH28-1 -> 0.020339774 | BJ30: =BJ28/BI28-1 -> 0.032407283 | BK30: =BK28/BJ28-1 -> 0.038925708 | BM30: =BM28/BK28-1 -> 0.033246605 | BN30: =BN28/BM28-1 -> 0.020549775 | BO30: =BO28/BN28-1 -> 0.047983625 | BP30: =BP28/BO28-1 -> 0.054803128 | BR30: =BR28/BP28-1 -> 0.0037500897 | BS30: =BS28/BR28-1 -> 0.012741996 | BT30: =BT28/BS28-1 -> 0.0090479368 | BU30: =BU28/BT28-1 -> 0.050554172 | BW30: =BW28/BU28-1 -> -0.0035086718 | BX30: =BX28/BW28-1 -> 0.023723308 | BY30: =BY28/BX28-1 -> 0.024164061 | BZ30: =BZ28/BY28-1 -> 0.075439748
B32: Cost of Revenue
C33: Cost of Revenue | D33: 24546 | E33: 8959 | F33: 9224 | G33: 9887 | H33: 11176 | I33: =SUM(E33:H33) -> 39246 | J33: =11681-32 -> 11649 | K33: =12215-44 -> 12171 | L33: =12265-51 -> 12214 | M33: =12646-67-72 -> 12507 | N33: =SUM(J33:M33) -> 48541 | O33: =13148-88-87 -> 12973 | P33: =13469-121-88 -> 13260 | Q33: =13504-158-88 -> 13258 | R33: =14540-176-87 -> 14277 | S33: =SUM(O33:R33) -> 53768 | T33: =14778-188-88 -> 14502 | U33: =14270-218-88 -> 13964 | V33: =14812-233-88 -> 14491 | W33: =15635-227-87 -> 15321 | X33: =SUM(T33:W33) -> 58278 | Y33: =16610-88-265 -> 16257 | Z33: =16764-88-329 -> 16347 | AA33: =17790-88-357 -> 17345 | AB33: =15770-424-87+3114 -> 18373 | AC33: =SUM(Y33:AB33) -> 68322 | AD33: =19971-88-434 -> 19449 | AE33: =20273-575-88 -> 19610 | AF33: =20497-599-87 -> 19811 | AG33: =22363-88-594 -> 21681 | AH33: =SUM(AD33:AG33) -> 80551 | AI33: =24702-88-678 -> 23936 | AJ33: =24814-853-88 -> 23873 | AK33: =26179-860-88 -> 25231 | AL33: =28339-942-88 -> 27309 | AM33: =SUM(AI33:AL33) -> 100349 | AN33: =30851-1229-88 -> 29534 | AO33: =31248-1658-88 -> 29502 | AP33: =34472-1702-88 -> 32682 | AQ33: =37940-1745-618 -> 35577 | AR33: =SUM(AN33:AQ33) -> 127295 | AS33: =40037-1090-1989 -> 36958 | AT33: =42453-1738-2499-618 -> 37598 | AU33: =46561-2603-1738 -> 42220 | AV33: =51233-2331-2283 -> 46619 | AW33: =SUM(AS33:AV33) -> 163395 | AX33: =59803-3105-2947-30 -> 53721 | AY33: =64395-3781-2947 -> 57667 | AZ33: =67137-2947-3994 -> 60196 | BA33: =79764-6854-2947 -> 69963 | BB33: =SUM(AX33:BA33) -> 241547 | BC33: =88867-2947-7793-380-48 -> 77699 | BD33: =88229-2935-8538-3-80+3511 -> 80184 | BE33: =94111-2934-8329-96-187 -> 82565 | BF33: =96294-2890-8638-219-86 -> 84461 | BG33: =SUM(BC33:BF33) -> 324909 | BH33: =104756-2846-9333-23-34 -> 92520 | BI33: =104361-2845-9888-51 -> 91577 | BJ33: =111080-3182-9856-18-492 -> 97532 | BK33: =112493-3146-9182-12-63 -> 100090 | BL33: =SUM(BH33:BK33) -> 381719 | BM33: =114530-7603-2648-53-25 -> 104201 | BN33: =118414-7789-2648-72 -> 107905 | BO33: =121933-3196-7512-94-2115 -> 109016 | BP33: =122663-4099-6921-40 -> 111603 | BQ33: =SUM(BM33:BP33) -> 432725 | BR33: =125973-7184-4100 -> 114689 | BS33: =127865-7296-3464-1565 -> 115540 | BT33: =128552-6852-3464-2 -> 118234 | BU33: =133844-3438-6504-4 -> 123898 | BV33: =SUM(BR33:BU33) -> 472361 | BW33: =BW5*(1-BW34) -> 122683.65 | BX33: =BX5*(1-BX34) -> 124062.47 | BY33: =BY5*(1-BY34) -> 125491.68 | BZ33: =BZ5*(1-BZ34) -> 134958.74 | CA33: =SUM(BW33:BZ33) -> 507196.55
C34: Gross Margin | D34: =(D5-D33)/D5 -> 0.43164768 | E34: =(E5-E33)/E5 -> 0.37441999 | F34: =(F5-F33)/F5 -> 0.38620177 | G34: =(G5-G33)/G5 -> 0.38976831 | H34: =(H5-H33)/H5 -> 0.38833466 | I34: =(I5-I33)/I5 -> 0.38507408 | J34: =(J5-J33)/J5 -> 0.39058729 | K34: =(K5-K33)/K5 -> 0.39993791 | ... BV34: =(BV5-BV33)/BV5 -> 0.5889253 | BW34: 0.59 | BX34: 0.595 | BY34: 0.6 | BZ34: 0.6 | CA34: =(CA5-CA33)/CA5 -> 0.59640011
B35: Total Cost of Revenues | D35: =D33 -> 24546 | E35: =E33 -> 8959 | F35: =F33 -> 9224 | G35: =G33 -> 9887 | H35: =H33 -> 11176 | I35: =SUM(E35:H35) -> 39246 | J35: =J33 -> 11649 | K35: =K33 -> 12171 | L35: =L33 -> 12214 | M35: =M33 -> 12507 | N35: =SUM(J35:M35) -> 48541 | O35: =O33 -> 12973 | P35: =P33 -> 13260 | Q35: =Q33 -> 13258 | R35: =R33 -> 14277 | S35: =SUM(O35:R35) -> 53768 | T35: =T33 -> 14502 | U35: =U33 -> 13964 | V35: =V33 -> 14491 | W35: =W33 -> 15321 | X35: =SUM(T35:W35) -> 58278 | Y35: =Y33 -> 16257 | Z35: =Z33 -> 16347 | AA35: =AA33 -> 17345 | AB35: =AB33 -> 18373 | AC35: =AC33 -> 68322 | AD35: =AD33 -> 19449 | AE35: =AE33 -> 19610 | AF35: =AF33 -> 19811 | ... CA35: =CA33 -> 507196.55
B37: Gross Profit | D37: =D28-D35 -> 18642 | E37: =E28-E35 -> 5362.1097 | F37: =F28-F35 -> 5803.7395 | G37: =G28-G35 -> 6315.043 | H37: =H28-H35 -> 7095.4292 | I37: =I28-I35 -> 24576.321 | J37: =J28-J35 -> 7466.1248 | K37: =K28-K35 -> 8111.9012 | ... CA37: =CA28-CA35 -> 749485.02
C38: Gross Margin | D38: =D37/D28 -> 0.43164768 | E38: =E37/E28 -> 0.37441999 | F38: =F37/F28 -> 0.38620177 | G38: =G37/G28 -> 0.38976831 | H38: =H37/H28 -> 0.38833466 | I38: =I37/I28 -> 0.38507408 | J38: =J37/J28 -> 0.39058729 | K38: =K37/K28 -> 0.39993791 | ... AZ38: =AZ37/AZ28 -> 0.60994764 | BA38: 0.61 | BB38: =BB37/BB28 -> 0.60375563 | BC38: =BC37/BC28 -> 0.57489728 | BD38: =BD37/BD28 -> 0.57660179 | BE38: =BE37/BE28 -> 0.58372407 | BF38: =BF37/BF28 -> 0.5946099 | BG38: =BG37/BG28 -> 0.58283281 | BH38: =BH37/BH28 -> 0.57644926 | BI38: =BI37/BI28 -> 0.58912339 | ... CA38: =CA37/CA28 -> 0.59640011
B40: Operating Expenses
C41: Research & Development | D41: 8688 | E41: 2846 | F41: 3002 | G41: 3439 | H41: 3775 | I41: =SUM(E41:H41) -> 13062 | J41: =4154-53 -> 4101 | K41: =4106-49 -> 4057 | L41: =4419-136 -> 4283 | M41: =4850-261 -> 4589 | N41: =SUM(J41:M41) -> 17030 | O41: =5225-350 -> 4875 | P41: =5554-471 -> 5083 | Q41: =5503-583 -> 4920 | R41: =5828-527 -> 5301 | S41: =SUM(O41:R41) -> 20179 | T41: =6038-574 -> 5464 | U41: =5568-340 -> 5228 | V41: =5473-475 -> 4998 | W41: =5580-401 -> 5179 | X41: =SUM(T41:W41) -> 20869 | Y41: =5802-435 -> 5367 | Z41: =5799-528 -> 5271 | AA41: =6041-547 -> 5494 | AB41: =6236-549 -> 5687 | AC41: =SUM(Y41:AB41) -> 21819 | AD41: =6847-637 -> 6210 | AE41: =6836-801 -> 6035 | AF41: =6689-797 -> 5892 | AG41: =6748-807 -> 5941 | AH41: =SUM(AD41:AG41) -> 24078 | AI41: =7772-877 -> 6895 | AJ41: =8367-1064 -> 7303 | AK41: =9582-2352 -> 7230 | AL41: =8451-1010 -> 7441 | AM41: =SUM(AI41:AL41) -> 28869 | AN41: =10546-1470 -> 9076 | AO41: =10811-1907 -> 8904 | AP41: =11665-2022 -> 9643 | AQ41: =12168-2259 -> 9909 | AR41: =SUM(AN41:AQ41) -> 37532 | AS41: =15189-2806 -> 12383 | AT41: =17208-3684-327 -> 13197 | AU41: =17674-3876 -> 13798 | AV41: =18676-3675 -> 15001 | AW41: =SUM(AS41:AV41) -> 54379 | AX41: =22121-4763 -> 17358 | AY41: =24648-6152 -> 18496 | AZ41: =29680-9101 -> 20579 | BA41: =30448-9163 -> 21285 | BB41: =SUM(AX41:BA41) -> 77718 | BC41: =35824-10145-656-2629 -> 22394 | BD41: =34992-11818-1307-59-334 -> 21474 | BE41: =34113-10603-1654-557 -> 21299 | BF41: =36865-11799-1449-2615 -> 21002 | BG41: =SUM(BC41:BF41) -> 86169 | BH41: =38108-12382 -> 25726 | BI41: =39210-13013 -> 26197 | BJ41: =40391-12980 -> 27411 | BK41: =38873-12055-12-197 -> 26609 | BL41: =SUM(BH41:BK41) -> 105943 | BM41: =41518-10930-323 -> 30265 | BN41: =40717-9827-488 -> 30402 | BO41: =42482-8244-412-18-1942 -> 31866 | BP41: =41480-8259 -> 33221 | BQ41: =SUM(BM41:BP41) -> 125754 | BR41: =41100-8690 -> 32410 | BS41: =39912-8829-742-1931 -> 28410 | BT41: =35218-6896-1170-25 -> 27127 | BU41: =36104-7349-1538 -> 27217 | BV41: =SUM(BR41:BU41) -> 115164 | BW41: =BW28*BW42 -> 32915.125 | BX41: =BX28*BX42 -> 32164.345 | BY41: =BY28*BY42 -> 32941.566 | BZ41: =BZ28*BZ42 -> 32727.495 | CA41: =SUM(BW41:BZ41) -> 130748.53
C42: % of Revenue | D42: =D41/D28 -> 0.20116699 | E42: =E41/E28 -> 0.19872762 | F42: =F41/F28 -> 0.19976391 | G42: =G41/G28 -> 0.21225718 | H42: =H41/H28 -> 0.20660672 | I42: =I41/I28 -> 0.20466194 | J42: =J41/J28 -> 0.21454215 | K42: =K41/K28 -> 0.2000207 | ... BV42: =BV41/BV28 -> 0.10022209 | BW42: 0.11 | BX42: 0.105 | BY42: 0.105 | BZ42: 0.097 | CA42: =CA41/CA28 -> 0.10404269
C43: Sales and Marketing | D43: 10171 | E43: 3289 | F43: 3993 | G43: 4309 | H43: 5105 | I43: =SUM(E43:H43) -> 16696 | J43: =6147-105 -> 6042 | K43: =7227-134 -> 7093 | L43: =6964-182 -> 6782 | M43: =7727-330-23 -> 7374 | N43: =SUM(J43:M43) -> 27291 | O43: =9022-326-28 -> 8668 | P43: =9674-368-28 -> 9278 | Q43: =9296-361-29 -> 8906 | R43: =9453-455-29 -> 8969 | S43: =SUM(O43:R43) -> 35821 | T43: =9931-524-28 -> 9379 | U43: =10594-458-28 -> 10108 | V43: =10797-448-29 -> 10320 | W43: =10720-370-29 -> 10321 | X43: =SUM(T43:W43) -> 40128 | Y43: =12706-434-28 -> 12244 | Z43: =12637-544-28 -> 12065 | AA43: =12925-626-29 -> 12270 | AB43: =14480-759-117+87 -> 13691 | AC43: =SUM(Y43:AB43) -> 50270 | AD43: =15778-928-29 -> 14821 | AE43: =16932-1224-29 -> 15679 | AF43: =16502-1084-28 -> 15390 | AG43: =17358-1128-28 -> 16202 | AH43: =SUM(AD43:AG43) -> 62092 | AI43: =17478-1362-28 -> 16088 | AJ43: =17912-1585-28 -> 16299 | AK43: =17818-1613 -> 16205 | AL43: =18793-1747 -> 17046 | AM43: =SUM(AI43:AL43) -> 65638 | AN43: =21701-2249 -> 19452 | AO43: =23250-2749 -> 20501 | AP43: =25014-3017 -> 21997 | AQ43: =25627-3353 -> 22274 | AR43: =SUM(AN43:AQ43) -> 84224 | AS43: =30160-4106 -> 26054 | AT43: =32231-5265-651 -> 26315 | AU43: =32969-5427 -> 27542 | AV43: =37053-5366 -> 31687 | AW43: =SUM(AS43:AV43) -> 111598 | AX43: =44799-6771 -> 38028 | AY43: =46024-8208 -> 37816 | AZ43: =49712-8304 -> 41408 | BA43: =53394-11987 -> 41407 | BB43: =SUM(AX43:BA43) -> 158659 | BC43: =64611-13424-46 -> 51141 | BD43: =64098-14963-23 -> 49112 | BE43: =67353-15761 -> 51592 | BF43: =65928-15152 -> 50776 | BG43: =SUM(BC43:BF43) -> 202621 | BH43: =76314-17045-1 -> 59268 | BI43: =74077-17391 -> 56686 | BJ43: =73366-16404 -> 56962 | BK43: =72956-15389 -> 57567 | BL43: =SUM(BH43:BK43) -> 230483 | BM43: =81109-14020 -> 67089 | BN43: =78332-13824 -> 64508 | BO43: =78615-12490-4424 -> 61701 | BP43: =73898-10880-2757 -> 60261 | BQ43: =SUM(BM43:BP43) -> 253559 | BR43: =82855-11574 -> 71281 | BS43: =80668-13355-3319 -> 63994 | BT43: =71657-8401-182 -> 63074 | BU43: =76636-8879 -> 67757 | BV43: =SUM(BR43:BU43) -> 266106 | BW43: =BW28*BW44 -> 71814.818 | BX43: =BX28*BX44 -> 71986.868 | BY43: =BY28*BY44 -> 72157.717 | BZ43: =BZ28*BZ44 -> 75914.292 | CA43: =SUM(BW43:BZ43) -> 291873.7
C44: % of Revenue | D44: =D43/D28 -> 0.23550523 | E44: =E43/E28 -> 0.22966097 | F44: =F43/F28 -> 0.26570862 | G44: =G43/G28 -> 0.26595412 | H44: =H43/H28 -> 0.27939796 | I44: =I43/I28 -> 0.26160126 | J44: =J43/J28 -> 0.31608478 | K44: =K43/K28 -> 0.34970342 | ... BV44: =BV43/BV28 -> 0.23158017 | BW44: 0.24 | BX44: 0.235 | BY44: 0.23 | BZ44: 0.225 | CA44: =CA43/CA28 -> 0.23225748
C45: G&A | D45: 6737 | E45: 2364 | F45: 2543 | G45: 2949 | H45: 3552 | I45: =SUM(E45:H45) -> 11408 | J45: =3825-74 -> 3751 | K45: =4052-77 -> 3975 | L45: =4223-89 -> 4134 | M45: =5953-10-265 -> 5678 | N45: =SUM(J45:M45) -> 17538 | O45: =6171-433-12 -> 5726 | P45: =3515-12-763 -> 2740 | Q45: =7967-11-775 -> 7181 | R45: =6763-799-12 -> 5952 | S45: =SUM(O45:R45) -> 21599 | T45: =7275-949-12 -> 6314 | U45: =6027-814-12 -> 5201 | V45: =6087-789-11 -> 5287 | W45: =6433-722-12 -> 5699 | X45: =SUM(T45:W45) -> 22501 | Y45: =6536-860-12 -> 5664 | Z45: =5882-1013-12 -> 4857 | AA45: =6143-989-12 -> 5142 | AB45: =6511-984 -> 5527 | AC45: =SUM(Y45:AB45) -> 21190 | AD45: =8860-1130-1700-135 -> 5895 | AE45: =6845-1254 -> 5591 | AF45: =4679-1240+2133 -> 5572 | AG45: =8767-2111 -> 6656 | AH45: =SUM(AD45:AG45) -> 23714 | AI45: =9103-2408 -> 6695 | AJ45: =9833-3295-241 -> 6297 | AK45: =10746-4044-258-117+88 -> 6415 | AL45: =10766-3794-93-93+88 -> 6874 | AM45: =SUM(AI45:AL45) -> 26281 | AN45: =11762-3738-292 -> 7732 | AO45: =12042-4122-420-64 -> 7436 | AP45: =12146-4334 -> 7812 | AQ45: =13496-4511-338 -> 8647 | AR45: =SUM(AN45:AQ45) -> 31627 | AS45: =14658-4893-329 -> 9436 | AT45: =16129-5343-1637-221 -> 8928 | AU45: =16724-5380-2030 -> 9314 | AV45: =18258-5504-2339 -> 10415 | AW45: =SUM(AS45:AV45) -> 38093 | AX45: =22245-6269-1064-2500 -> 12412 | AY45: =22909-6760-973-2700 -> 12476 | AZ45: =26790-5996-60-9158 -> 11576 | BA45: =21972-7597-2351-380 -> 11644 | BB45: =SUM(AX45:BA45) -> 48108 | BC45: =24314-8032-888-218-260-105 -> 14811 | BD45: =23824-9467-304-152-335 -> 13566 | BE45: =24496-9810-103-121 -> 14462 | BF45: =22509-8235-70-141 -> 14063 | BG45: =SUM(BC45:BF45) -> 56902 | BH45: =28258-11983-1455+34-596+23 -> 14281 | BI45: =30477-13075-877-815+51 -> 15761 | BJ45: =31006-13371-268-659 -> 16708 | BK45: =33338-12945-3595-34 -> 16764 | BL45: =SUM(BH45:BK45) -> 63514 | BM45: =30548-12131-556 -> 17861 | BN45: =33988-12192-3529-32 -> 18235 | BO45: =36575-1144-3-3980-11310 -> 20138 | BP45: =36439-12383 -> 24056 | BQ45: =SUM(BM45:BP45) -> 80290 | BR45: =35205-11797-1265-141-982 -> 21020 | BS45: =36385-12379-746-952-95-974-368 -> 20871 | BT45: =34362-11190-448-196-1851-392 -> 20285 | BU45: =33902-10893-613-1728-873 -> 19795 | BV45: =SUM(BR45:BU45) -> 81971 | BW45: =BW28*BW46 -> 21544.445 | BX45: =BX28*BX46 -> 21442.897 | BY45: =BY28*BY46 -> 20392.398 | BZ45: =BZ28*BZ46 -> 20243.811 | CA45: =SUM(BW45:BZ45) -> 83623.552
C46: % of Revenue | D46: =D45/D28 -> 0.15599241 | E46: =E45/E28 -> 0.16507101 | F46: =F45/F28 -> 0.16922039 | G46: =G45/G28 -> 0.18201408 | H46: =H45/H28 -> 0.19440187 | I46: =I45/I28 -> 0.17874624 | J46: =J45/J28 -> 0.19623204 | K46: =K45/K28 -> 0.19597788 | ... BV46: =BV45/BV28 -> 0.071335703 | BW46: 0.072 | BX46: 0.07 | BY46: 0.065 | BZ46: 0.06 | CA46: =CA45/CA28 -> 0.066543152
B47: Total Operating Expense | D47: =D45+D43+D41 -> 25596 | E47: =E45+E43+E41 -> 8499 | F47: =F45+F43+F41 -> 9538 | G47: =G45+G43+G41 -> 10697 | H47: =H45+H43+H41 -> 12432 | I47: =SUM(E47:H47) -> 41166 | J47: =J45+J43+J41 -> 13894 | K47: =K45+K43+K41 -> 15125 | L47: =L45+L43+L41 -> 15199 | M47: =M45+M43+M41 -> 17641 | N47: =N41+N43+N45 -> 61859 | O47: =O41+O43+O45 -> 19269 | P47: =P41+P43+P45 -> 17101 | Q47: =Q41+Q43+Q45 -> 21007 | R47: =R41+R43+R45 -> 20222 | S47: =S41+S43+S45 -> 77599 | T47: =T41+T43+T45 -> 21157 | U47: =U41+U43+U45 -> 20537 | ... CA47: =CA41+CA43+CA45 -> 506245.78
B49: Non-GAAP Operating Income | D49: =D37-D47 -> -6954 | E49: =E37-E47 -> -3136.8903 | F49: =F37-F47 -> -3734.2605 | G49: =G37-G47 -> -4381.957 | H49: =H37-H47 -> -5336.5708 | I49: =I37-I47 -> -16589.679 | J49: =J37-J47 -> -6427.8752 | K49: =K37-K47 -> -7013.0988 | ... CA49: =CA37-CA47 -> 243239.24
C50: Non-GAAP Operating Margin | D50: =D49/D28 -> -0.16101695 | E50: =E49/E28 -> -0.21903961 | F50: =F49/F28 -> -0.24849116 | G50: =G49/G28 -> -0.27045707 | H50: =H49/H28 -> -0.29207189 | I50: =I49/I28 -> -0.25993537 | J50: =J49/J28 -> -0.33627169 | K50: =K49/K28 -> -0.34576409 | ... CA50: =CA49/CA28 -> 0.19355678
...

Sheet Balance Sheet 
B2: ='Income Statement'!B2 -> Five9, Inc (Nasdaq: FIVN)
B4: Balance Sheet | D4: 2011 | E4: 1Q12 | F4: 2Q12 | G4: 3Q12 | H4: 4Q12 | I4: 2012 | J4: 1Q13 | K4: 2Q13 | L4: 3Q13 | M4: 4Q13 | N4: 2013 | O4: 1Q14 | P4: 2Q14 | Q4: 3Q14 | R4: 4Q14 | S4: 2014 | T4: 1Q15 | U4: 2Q15 | V4: 3Q15 | W4: 4Q15 | X4: 2015 | Y4: 1Q16 | Z4: 2Q16 | AA4: 3Q16 | AB4: 4Q16 | AC4: 2016 | AD4: 1Q17 | AE4: 2Q17 | AF4: 3Q17 | AG4: 4Q17 | AH4: 2017 | AI4: 1Q18 | AJ4: 2Q18 | AK4: 3Q18 | AL4: 4Q18 | AM4: 2018 | AN4: 1Q19 | AO4: 2Q19 | AP4: 3Q19 | AQ4: 4Q19 | AR4: 2019 | AS4: 1Q20 | AT4: 2Q20 | AU4: 3Q20 | AV4: 4Q20 | AW4: 2020 | AX4: 1Q21 | AY4: 2Q21 | AZ4: 3Q21 | BA4: 4Q21 | BB4: 2021 | BC4: 1Q22 | BD4: 2Q22 | BE4: 3Q22 | BF4: 4Q22 | BG4: 2022 | BH4: 1Q23 | BI4: 2Q23 | BJ4: 3Q23 | BK4: 4Q23 | BL4: 2023 | BM4: 1Q24 | BN4: 2Q24 | BO4: 3Q24 | BP4: 4Q24 | BQ4: 2024 | BR4: 1Q25 | BS4: 2Q25 | BT4: ='Income Statement'!BT4 -> 3Q25 | BU4: 4Q25 | BV4: 2025 | BW4: 1Q26E | BX4: 2Q26E | BY4: 3Q26E | BZ4: 4Q26E | CA4: 2026E
B5: Assets:
C6: Cash and Equivalents | D6: 5378 | E6: 1735 | F6: 13129 | G6: 8468 | H6: 5961 | I6: =H6 -> 5961 | J6: 5475 | K6: 17742 | L6: 10110 | M6: 17748 | N6: =M6 -> 17748 | O6: 29238 | P6: 61577 | Q6: 53489 | R6: 58289 | S6: =R6 -> 58289 | T6: 50646 | U6: 65333 | V6: 59501 | W6: 58484 | X6: =W6 -> 58484 | Y6: 57767 | Z6: 57638 | AA6: 57333 | AB6: 58122 | AC6: =AB6 -> 58122 | AD6: 56452 | AE6: 57149 | AF6: 63364 | AG6: 68947 | AH6: =AG6 -> 68947 | AI6: 80676 | AJ6: 166162 | AK6: 79619 | AL6: 81912 | AM6: =AL6 -> 81912 | AN6: 93492 | AO6: =110469 -> 110469 | AP6: 120573 | AQ6: 77976 | AR6: =AQ6 -> 77976 | AS6: 155863 | AT6: 233235 | AU6: 301767 | AV6: =+AV7 -> 383171 | AW6: =AV6 -> 383171 | AX6: 176326 | AY6: 175199 | AZ6: 82465 | BA6: 90878 | BB6: =BA6 -> 90878 | BC6: 100151 | BD6: 101315 | BE6: 129492 | BF6: 180520 | BG6: =BF6 -> 180520 | BH6: 141359 | BI6: 195592 | BJ6: 127828 | BK6: 143201 | BL6: =BK6 -> 143201 | BM6: 240190 | BN6: 175699 | BO6: 290959 | BP6: 362546 | BQ6: =BP6 -> 362546 | BR6: 370344 | BS6: 205479 | BT6: 193409 | BU6: 232084 | BV6: =BU6 -> 232084 | BW6: =BV6+'Cash Flows'!BW93 -> 275266.52 | BX6: =BW6+'Cash Flows'!BX93 -> 299270.19 | BY6: =BX6+'Cash Flows'!BY93 -> 334709.62 | BZ6: =BY6+'Cash Flows'!BZ93 -> 383119.71 | CA6: =BZ6 -> 383119.71
C7: Short-Term Investments | D7: 3581 | E7: 3581 | F7: 2738 | G7: 2490 | H7: 2490 | I7: =H7 -> 2490 | J7: 2241 | K7: 0 | L7: 0 | M7: 0 | N7: =M7 -> 0 | O7: 0 | P7: 29995 | Q7: 29999 | R7: 20000 | S7: =R7 -> 20000 | T7: 19999 | U7: 0 | V7: 0 | W7: 0 | X7: =W7 -> 0 | Y7: 0 | AC7: =AB7 -> 0 | AH7: =AG7 -> 0 | AJ7: 108140 | AK7: 200007 | AL7: 209907 | AM7: =AL7 -> 209907 | AN7: 205450 | AO7: =197007 -> 197007 | AP7: 200385 | AQ7: 241973 | AR7: =AQ7 -> 241973 | AS7: 170433 | AT7: 452708 | AU7: 479141 | AV7: 383171 | AW7: =AV7 -> 383171 | AX7: 467143 | AY7: 390986 | AZ7: 332824 | BA7: 378980 | BB7: =BA7 -> 378980 | BC7: 377519 | BD7: 397067 | BE7: 447612 | BF7: 433743 | BG7: =BF7 -> 433743 | BH7: 488381 | BI7: 464244 | BJ7: 572462 | BK7: 587096 | BL7: =BK7 -> 587096 | BM7: 843212 | BN7: 930639 | BO7: 675704 | BP7: 643410 | BQ7: =BP7 -> 643410 | BR7: 671394 | BS7: 430397 | BT7: 482747 | BU7: 464835 | BV7: =BU7 -> 464835 | BW7: =BV7 -> 464835 | BX7: =BW7 -> 464835 | BY7: =BX7 -> 464835 | BZ7: =BY7 -> 464835 | CA7: =BZ7 -> 464835
C8: Accounts Rec, Net | D8: 3530 | E8: 4064 | F8: 4127 | G8: 4102 | H8: 5441 | I8: =H8 -> 5441 | J8: 5528 | K8: 5625 | L8: 5124 | M8: 6970 | N8: =M8 -> 6970 | O8: 6650 | P8: 7098 | Q8: 7725 | R8: 8335 | S8: =R8 -> 8335 | T8: 8719 | U8: 8250 | V8: 9309 | W8: 10567 | X8: =W8 -> 10567 | Y8: 12528 | Z8: 10765 | AA8: 12899 | AB8: 13881 | AC8: =AB8 -> 13881 | AD8: 15453 | AE8: 16281 | AF8: 17231 | AG8: 19048 | AH8: =AG8 -> 19048 | AI8: 18534 | AJ8: 20167 | AK8: 23903 | AL8: 24797 | AM8: =AL8 -> 24797 | AN8: 25840 | AO8: 28153 | AP8: 31407 | AQ8: 37655 | AR8: =AQ8 -> 37655 | AS8: 39972 | AT8: 39607 | AU8: 42542 | AV8: 48731 | AW8: =AV8 -> 48731 | AX8: 51987 | AY8: 53811 | AZ8: 60383 | BA8: 83731 | BB8: =BA8 -> 83731 | BC8: 77912 | BD8: 82885 | BE8: 88225 | BF8: 87494 | BG8: =BF8 -> 87494 | BH8: 88085 | BI8: 88461 | BJ8: 94436 | BK8: 97424 | BL8: =BK8 -> 97424 | BM8: 103157 | BN8: 104382 | BO8: 116430 | BP8: 115172 | BQ8: =BP8 -> 115172 | BR8: 118614 | BS8: 127835 | BT8: 138486 | BU8: 130984 | BV8: =BU8 -> 130984 | BW8: =BW61*'Income Statement'!BW28 -> 131660.5 | BX8: =BX61*'Income Statement'!BX28 -> 128657.38 | BY8: =BY61*'Income Statement'!BY28 -> 138040.85 | BZ8: =BZ61*'Income Statement'!BZ28 -> 151828.58 | CA8: =BZ8 -> 151828.58
C9: Prepaid expenses and other current | D9: 592 | E9: 961 | F9: 950 | G9: 1200 | H9: 942 | I9: =H9 -> 942 | J9: 2194 | K9: 1505 | L9: 1592 | M9: 1651 | N9: =M9 -> 1651 | O9: 2647 | P9: 2779 | Q9: 2726 | R9: 1960 | S9: =R9 -> 1960 | T9: 3170 | U9: 4228 | V9: 2917 | W9: 2184 | X9: =W9 -> 2184 | Y9: 3899 | Z9: 3390 | AA9: 4097 | AB9: 3008 | AC9: =AB9 -> 3008 | AD9: 5117 | AE9: 7074 | AF9: 4809 | AG9: 4840 | AH9: =AG9 -> 4840 | AI9: 7150 | AJ9: 8437 | AK9: 7962 | AL9: 9014 | AM9: =AL9 -> 9014 | AN9: 9719 | AO9: 12036 | AP9: 11140 | AQ9: 10656 | AR9: =AQ9 -> 10656 | AS9: 13396 | AT9: 17529 | AU9: 15908 | AV9: 16149 | AW9: =AV9 -> 16149 | AX9: 19673 | AY9: 22110 | AZ9: 29814 | BA9: 30342 | BB9: =BA9 -> 30342 | BC9: 32534 | BD9: 38464 | BE9: 32600 | BF9: 29711 | BG9: =BF9 -> 29711 | BH9: 32018 | BI9: 38476 | BJ9: 37627 | BK9: 34622 | BL9: =BK9 -> 34622 | BM9: 35627 | BN9: 41760 | BO9: 48640 | BP9: 50840 | BQ9: =BP9 -> 50840 | BR9: 47832 | BS9: 47986 | BT9: 49590 | BU9: 43107 | BV9: =BU9 -> 43107 | BW9: =BW62*'Income Statement'!BW28 -> 56853.398 | BX9: =BX62*'Income Statement'!BX28 -> 61265.419 | BY9: =BY62*'Income Statement'!BY28 -> 62745.841 | BZ9: =BZ62*'Income Statement'!BZ28 -> 67479.371 | CA9: =BZ9 -> 67479.371
C10: Deferred contract acquistion cost | AI10: 7562 | AJ10: 8083 | AK10: 8633 | AL10: 9372 | AM10: =AL10 -> 9372 | AN10: 10095 | AO10: 10954 | AP10: 11947 | AQ10: 13014 | AR10: =AQ10 -> 13014 | AS10: 14317 | AT10: 16151 | AU10: 17932 | AV10: 20695 | AW10: =AV10 -> 20695 | AX10: 23249 | AY10: 26791 | AZ10: 29649 | BA10: 33295 | BB10: =BA10 -> 33295 | BC10: 36478 | BD10: 40306 | BE10: 43587 | BF10: 47242 | BG10: =BF10 -> 47242 | BH10: 50566 | BI10: 54462 | BJ10: 58320 | BK10: 61711 | BL10: =BK10 -> 61711 | BM10: 67169 | BN10: 69622 | BO10: 72534 | BP10: 76600 | BQ10: =BP10 -> 76600 | BR10: 79267 | BS10: 82497 | BT10: 85181 | BU10: 88714 | BV10: =BU10 -> 88714 | BW10: =BV10-'Cash Flows'!BW35 -> 108714 | BX10: =BW10-'Cash Flows'!BX35 -> 128714 | BY10: =BX10-'Cash Flows'!BY35 -> 148714 | BZ10: =BY10-'Cash Flows'!BZ35 -> 168714 | CA10: =BZ10 -> 168714
B11: Total Current Assets | D11: =SUM(D6:D9) -> 13081 | E11: =SUM(E6:E9) -> 10341 | F11: =SUM(F6:F9) -> 20944 | G11: =SUM(G6:G9) -> 16260 | H11: =SUM(H6:H9) -> 14834 | I11: =SUM(I6:I9) -> 14834 | J11: =SUM(J6:J9) -> 15438 | K11: =SUM(K6:K9) -> 24872 | ... R11: =SUM(R6:R9) -> 88584 | S11: =R11 -> 88584 | T11: =SUM(T6:T9) -> 82534 | U11: =SUM(U6:U9) -> 77811 | V11: =SUM(V6:V9) -> 71727 | W11: =SUM(W6:W9) -> 71235 | X11: =W11 -> 71235 | Y11: =SUM(Y6:Y9) -> 74194 | Z11: =SUM(Z6:Z9) -> 71793 | AA11: =SUM(AA6:AA9) -> 74329 | AB11: =SUM(AB6:AB9) -> 75011 | AC11: =AB11 -> 75011 | AD11: =SUM(AD6:AD9) -> 77022 | AE11: =SUM(AE6:AE9) -> 80504 | AF11: =SUM(AF6:AF9) -> 85404 | AG11: =SUM(AG6:AG9) -> 92835 | AH11: =AG11 -> 92835 | AI11: =SUM(AI6:AI10) -> 113922 | AJ11: =SUM(AJ6:AJ10) -> 310989 | AK11: =SUM(AK6:AK10) -> 320124 | AL11: =SUM(AL6:AL10) -> 335002 | AM11: =AL11 -> 335002 | AN11: =SUM(AN6:AN10) -> 344596 | AO11: =SUM(AO6:AO10) -> 358619 | AP11: =SUM(AP6:AP10) -> 375452 | AQ11: =SUM(AQ6:AQ10) -> 381274 | AR11: =AQ11 -> 381274 | AS11: =SUM(AS6:AS10) -> 393981 | AT11: =SUM(AT6:AT10) -> 759230 | AU11: =SUM(AU6:AU10) -> 857290 | AV11: =SUM(AV6:AV10) -> 851917 | AW11: =AV11 -> 851917 | AX11: =SUM(AX6:AX10) -> 738378 | AY11: =SUM(AY6:AY10) -> 668897 | AZ11: =SUM(AZ6:AZ10) -> 535135 | BA11: =SUM(BA6:BA10) -> 617226 | BB11: =BA11 -> 617226 | BC11: =SUM(BC6:BC10) -> 624594 | BD11: =SUM(BD6:BD10) -> 660037 | BE11: =SUM(BE6:BE10) -> 741516 | BF11: =SUM(BF6:BF10) -> 778710 | BG11: =BF11 -> 778710 | BH11: =SUM(BH6:BH10) -> 800409 | BI11: =SUM(BI6:BI10) -> 841235 | BJ11: =SUM(BJ6:BJ10) -> 890673 | BK11: =SUM(BK6:BK10) -> 924054 | BL11: =BK11 -> 924054 | BM11: =SUM(BM6:BM10) -> 1289355 | BN11: =SUM(BN6:BN10) -> 1322102 | BO11: =SUM(BO6:BO10) -> 1204267 | BP11: =SUM(BP6:BP10) -> 1248568 | BQ11: =BP11 -> 1248568 | BR11: =SUM(BR6:BR10) -> 1287451 | BS11: =SUM(BS6:BS10) -> 894194 | BT11: =SUM(BT6:BT10) -> 949413 | BU11: =SUM(BU6:BU10) -> 959724 | BV11: =BU11 -> 959724 | BW11: =SUM(BW6:BW10) -> 1037329.4 | BX11: =SUM(BX6:BX10) -> 1082742 | BY11: =SUM(BY6:BY10) -> 1149045.3 | BZ11: =SUM(BZ6:BZ10) -> 1235976.7 | CA11: =BZ11 -> 1235976.7
C12: PPE, net | D12: 4437 | E12: 5787 | F12: 7958 | G12: 8130 | H12: 10874 | I12: =H12 -> 10874 | J12: 10885 | K12: 11672 | L12: 11955 | M12: 11607 | N12: =M12 -> 11607 | O12: 11179 | P12: 11521 | Q12: 12117 | R12: 12571 | S12: =R12 -> 12571 | T12: 12426 | U12: 11964 | V12: 12376 | W12: 13225 | X12: =W12 -> 13225 | Y12: 12795 | Z12: 13188 | AA12: 13690 | AB12: 14688 | AC12: =AB12 -> 14688 | AD12: 15830 | AE12: 15656 | AF12: 17958 | AG12: 19888 | AH12: =AG12 -> 19888 | AI12: 20876 | AJ12: 22019 | AK12: 22909 | AL12: 25885 | AM12: =AL12 -> 25885 | AN12: 27496 | AO12: 28255 | AP12: 28399 | AQ12: 33190 | AR12: =AQ12 -> 33190 | AS12: 34940 | AT12: 39799 | AU12: 41676 | AV12: 51213 | AW12: =AV12 -> 51213 | AX12: 58296 | AY12: 63107 | AZ12: 71444 | BA12: 77785 | BB12: =BA12 -> 77785 | BC12: 91476 | BD12: 99994 | BE12: 101696 | BF12: 101221 | BG12: =BF12 -> 101221 | BH12: 104057 | BI12: 98879 | BJ12: 102029 | BK12: 108572 | BL12: =BK12 -> 108572 | BM12: 113640 | BN12: 124600 | BO12: 136052 | BP12: 144888 | BQ12: =BP12 -> 144888 | BR12: 146460 | BS12: 154499 | BT12: 164305 | BU12: 164635 | BV12: =BU12 -> 164635 | BW12: =BV12-'Cash Flows'!BW46-(0.05*'Cash Flows'!BW8) -> 175883.78 | BX12: =BW12-'Cash Flows'!BX46-(0.05*'Cash Flows'!BX8) -> 187093.18 | BY12: =BX12-'Cash Flows'!BY46-(0.05*'Cash Flows'!BY8) -> 198310.13 | BZ12: =BY12-'Cash Flows'!BZ46-(0.05*'Cash Flows'!BZ8) -> 209490.62 | CA12: =BZ12 -> 209490.62
C13: Operating lease right to use | AN13: 6735 | AO13: 10219 | AP13: 8933 | AQ13: 8746 | AR13: =AQ13 -> 8746 | AS13: 11034 | AT13: 10006 | AU13: 8669 | AV13: 9010 | AW13: =AV13 -> 9010 | AX13: 44960 | AY13: 46966 | AZ13: 45778 | BA13: 48703 | BB13: =BA13 -> 48703 | BC13: 46536 | BD13: 43593 | BE13: 44941 | BF13: 44120 | BG13: =BF13 -> 44120 | BH13: 45339 | BI13: 43748 | BJ13: 41522 | BK13: 38873 | BL13: =BK13 -> 38873 | BM13: 36215 | BN13: 34107 | BO13: 43480 | BP13: 38880 | BQ13: =BP13 -> 38880 | BR13: 36444 | BS13: 37433 | BT13: 37695 | BU13: 46375 | BV13: =BU13 -> 46375 | BW13: =BV13 -> 46375 | BX13: =BW13 -> 46375 | BY13: =BX13 -> 46375 | BZ13: =BY13 -> 46375 | CA13: =BZ13 -> 46375
C14: Finance lease right of use | BI14: 2167 | BJ14: 4612 | BK14: 4564 | BL14: =BK14 -> 4564 | BM14: 4108 | BN14: 3653 | BO14: 21262 | BP14: 19269 | BQ14: =BP14 -> 19269 | BR14: 21113 | BS14: 18803 | BT14: 16507 | BU14: 14216 | BV14: =BU14 -> 14216 | CA14: =BZ14 -> 0
C15: Intangible assets, Net | D15: 0 | E15: 0 | F15: 0 | G15: 0 | H15: 0 | I15: =H15 -> 0 | J15: 0 | K15: 0 | L15: 0 | M15: 3065 | N15: =M15 -> 3065 | O15: 2937 | P15: 2809 | Q15: 2681 | R15: 2553 | S15: =R15 -> 2553 | T15: 2425 | U15: 2297 | V15: 2169 | W15: 2041 | X15: =W15 -> 2041 | Y15: 1913 | Z15: 1785 | AA15: 1657 | AB15: 1539 | AC15: =AB15 -> 1539 | AD15: 1422 | AE15: 1306 | AF15: 1190 | AG15: 1073 | AH15: =AG15 -> 1073 | AI15: 957 | AJ15: 841 | AK15: 724 | AL15: 631 | AM15: =AL15 -> 631 | AN15: 543 | AO15: 455 | AP15: 367 | AQ15: 15533 | AR15: =AQ15 -> 15533 | AS15: 14543 | AT15: 25605 | AU15: 23867 | AV15: 51684 | AW15: =AV15 -> 51684 | AX15: 48737 | AY15: 45790 | AZ15: 42843 | BA15: 39897 | BB15: =BA15 -> 39897 | BC15: 36950 | BD15: 34015 | BE15: 31081 | BF15: 28192 | BG15: =BF15 -> 28192 | BH15: 25346 | BI15: 22501 | BJ15: 41469 | BK15: 38323 | BL15: =BK15 -> 38323 | BM15: 35675 | BN15: 33027 | BO15: 69731 | BP15: 65632 | BQ15: =BP15 -> 65632 | BR15: 61532 | BS15: 58068 | BT15: 54604 | BU15: 51166 | BV15: =BU15 -> 51166 | BW15: =BV15 -> 51166 | BX15: =BW15 -> 51166 | BY15: =BX15 -> 51166 | BZ15: =BY15 -> 51166 | CA15: =BZ15 -> 51166
C16: Goodwill | D16: 0 | E16: 0 | F16: 0 | G16: 0 | H16: 0 | I16: =H16 -> 0 | J16: 0 | K16: 0 | L16: 0 | M16: 11798 | N16: =M16 -> 11798 | O16: =M16 -> 11798 | P16: 11798 | Q16: 11798 | R16: 11798 | S16: =R16 -> 11798 | T16: 11798 | U16: 11798 | V16: 11798 | W16: 11798 | X16: =W16 -> 11798 | Y16: 11798 | Z16: 11798 | AA16: 11798 | AB16: 11798 | AC16: =AB16 -> 11798 | AD16: 11798 | AE16: 11798 | AF16: 11798 | AG16: 11798 | AH16: =AG16 -> 11798 | AI16: 11798 | AJ16: 11798 | AK16: 11798 | AL16: 11798 | AM16: =AL16 -> 11798 | AN16: 11798 | AO16: 11798 | AP16: =AO16 -> 11798 | AQ16: 11798 | AR16: =AQ16 -> 11798 | AS16: 11798 | AT16: 34444 | AU16: 34444 | AV16: 165420 | AW16: =AV16 -> 165420 | AX16: 165420 | AY16: =AX16 -> 165420 | AZ16: 165420 | BA16: 165420 | BB16: =BA16 -> 165420 | BC16: 165420 | BD16: 165420 | BE16: 165420 | BF16: 165420 | BG16: =BF16 -> 165420 | BH16: 165420 | BI16: 165420 | BJ16: 227412 | BK16: =BJ16 -> 227412 | BL16: =BK16 -> 227412 | BM16: 227269 | BN16: 227269 | BO16: 365450 | BP16: 365436 | BQ16: =BP16 -> 365436 | BR16: 366698 | BS16: 366698 | BT16: 366253 | BU16: 366253 | BV16: =BU16 -> 366253 | BW16: =BV16 -> 366253 | BX16: =BW16 -> 366253 | BY16: =BX16 -> 366253 | BZ16: =BY16 -> 366253 | CA16: =BZ16 -> 366253
C17: Marketable investments | AV17: 42127 | AW17: =AV17 -> 42127 | AX17: 0 | AY17: 72758 | AZ17: 208468 | BA17: 147377 | BB17: =BA17 -> 147377 | BC17: 118707 | BD17: 60424 | BE17: 1961 | BF17: 885 | BG17: =BF17 -> 885 | BH17: 13498 | BI17: 85110 | BL17: =BK17 -> 0 | BQ17: =BP17 -> 0 | BV17: =BU17 -> 0 | CA17: =BZ17 -> 0
