Workbook
Name ___eps95: #REF!
Name ___eps95: #REF!
Name ___eps95: #REF!
Name ___eps95: #REF!
Name ___eps95: #REF!
Name ___eps95: #REF!
Name ___eps95: #REF!
Name ___eps95: #REF!
Name ___eps96: #REF!
Name ___eps96: #REF!
Name ___eps96: #REF!
Name ___eps96: #REF!
Name ___eps96: #REF!
Name ___eps96: #REF!
Name ___eps96: #REF!
Name ___eps96: #REF!
Name ___eps97: #REF!
Name ___eps97: #REF!
Name ___eps97: #REF!
Name ___eps97: #REF!
Name ___eps97: #REF!
Name ___eps97: #REF!
Name ___eps97: #REF!
Name ___eps97: #REF!
Name ___eps98: #REF!
Name ___eps98: #REF!
Name ___eps98: #REF!
Name ___eps98: #REF!
Name ___eps98: #REF!
Name ___fcc97: #REF!
Name ___fcc97: #REF!
Name ___fcc97: #REF!
Name ___fcc97: #REF!
Name ___fcc97: #REF!
Name ___grm98: #REF!
Name ___grm98: #REF!
Name ___grm98: #REF!
Name ___grm98: #REF!
Name ___grm98: #REF!
Name ___grm99: #REF!
Name ___grm99: #REF!
Name ___grm99: #REF!
Name ___grm99: #REF!
Name ___grm99: #REF!
Name ___net96: #REF!
Name ___net96: #REF!
Name ___net96: #REF!
Name ___net96: #REF!
Name ___net96: #REF!
Name ___net97: #REF!
Name ___net97: #REF!
Name ___net97: #REF!
Name ___net97: #REF!
Name ___net97: #REF!
Name ___net98: #REF!
Name ___net98: #REF!
Name ___net98: #REF!
Name ___net98: #REF!
Name ___net98: #REF!
Name ___net99: #REF!

Sheet __FDSCACHE__
B1: This sheet contains FactSet XML data for use with this workbook's =FDS codes. Modifying the worksheet's contents may damage the workbook's =FDS functionality.

Sheet BM Upload
A1: ALL FISCAL DATA MUST BE ENTERED IN MILLION (INCLUDING NUMBER OF SHARE) | CV1: NULL:FISCAL
A2: ALL PER SHARE DATA MUST BE IN UNIT | CV2: ADJUSTED:FISCAL
A3: DATA MUST BE ENTERED IN THE CURRENCY OF THE COMPANY | CV3: BASIC:FISCAL
A4: Click here to find a list of BlueMatrix Client Codes | CV4: DILUTED:FISCAL
BW5: Strong Buy | CV5: GAAP:FISCAL
BW6: Buy | CV6: INDICATED:FISCAL
BW7: Hold | CV7: MANAGED:FISCAL
BW8: Under Perform | CV8: NON-GAAP:FISCAL
A9: Company name | C9: Rapid 7 | BW9: Rating Suspended | CV9: OPERATING:FISCAL
A10: Rating | B10: RATING | C10: Hold | D10: =_xll.BLUEMATRIX2("/servlet/excelData",C10, $C$14,$B10) -> #NAME? | BW10: Restricted | CV10: PRIMARY:FISCAL
A11: Currency | C11: USD | BW11: Under Review | CV11: PROFORMA:FISCAL
BW12: Sell | CV12: RESTATED:FISCAL
A13: 12-Month Price Target | B13: TARGET_PRICE | C13: NA | D13: =_xll.BLUEMATRIX2("/servlet/excelData",C13, $C$14,$B13) -> #NAME? | CV13: REVENUE:FISCAL
A14: Ticker | C14: RPD | BW14: A | CV14: NULL:CALENDAR
BW15: E | CV15: ADJUSTED:CALENDAR
D16: =$B$17-3 -> 2014 | E16: =$B$17-3 -> 2014 | F16: =$B$17-3 -> 2014 | G16: =$B$17-3 -> 2014 | H16: =$B$17-3 -> 2014 | I16: =$B$17-2 -> 2015 | J16: =$B$17-2 -> 2015 | K16: =$B$17-2 -> 2015 | L16: =$B$17-2 -> 2015 | M16: =$B$17-2 -> 2015 | N16: =$B$17-1 -> 2016 | O16: =$B$17-1 -> 2016 | P16: =$B$17-1 -> 2016 | Q16: =$B$17-1 -> 2016 | R16: =$B$17-1 -> 2016 | S16: =$B$17-0 -> 2017 | T16: =$B$17-0 -> 2017 | U16: =$B$17-0 -> 2017 | V16: =$B$17-0 -> 2017 | W16: =$B$17-0 -> 2017 | X16: =$B$17+1 -> 2018 | Y16: =$B$17+1 -> 2018 | Z16: =$B$17+1 -> 2018 | AA16: =$B$17+1 -> 2018 | AB16: =$B$17+1 -> 2018 | AC16: =$B$17+2 -> 2019 | AD16: =$B$17+2 -> 2019 | AE16: =$B$17+2 -> 2019 | AF16: =$B$17+2 -> 2019 | AG16: =$B$17+2 -> 2019 | AH16: =$B$17+3 -> 2020 | AI16: =$B$17+3 -> 2020 | AJ16: =$B$17+3 -> 2020 | AK16: =$B$17+3 -> 2020 | AL16: =$B$17+3 -> 2020 | AM16: =$B$17+4 -> 2021 | AN16: =$B$17+4 -> 2021 | AO16: =$B$17+4 -> 2021 | AP16: =$B$17+4 -> 2021 | AQ16: =$B$17+4 -> 2021 | AR16: =$B$17+5 -> 2022 | AS16: =$B$17+5 -> 2022 | AT16: =$B$17+5 -> 2022 | AU16: =$B$17+5 -> 2022 | AV16: =$B$17+5 -> 2022 | AW16: =$B$17+6 -> 2023 | AX16: =$B$17+6 -> 2023 | AY16: =$B$17+6 -> 2023 | AZ16: =$B$17+6 -> 2023 | BA16: =$B$17+6 -> 2023 | BB16: =$B$17+7 -> 2024 | BC16: =$B$17+7 -> 2024 | BD16: =$B$17+7 -> 2024 | BE16: =$B$17+7 -> 2024 | BF16: =$B$17+7 -> 2024 | BG16: =BB16+1 -> 2025 | BH16: =BC16+1 -> 2025 | BI16: =BD16+1 -> 2025 | BJ16: =BE16+1 -> 2025 | BK16: =BF16+1 -> 2025 | BL16: =BG16+1 -> 2026 | BM16: =BH16+1 -> 2026 | BN16: =BI16+1 -> 2026 | ... BU16: =BP16+1 -> 2027 | BX16: BASIC:CALENDAR
A17: Current Year (Matching What Selected From Drop-down Bars - ie. Fiscal or Calendar) | B17: 2017 | D17: A | E17: A | F17: A | G17: A | H17: A | I17: A | J17: A | K17: A | L17: A | M17: A | N17: A | O17: A | P17: A | Q17: A | R17: A | S17: A | T17: A | U17: A | V17: A | W17: A | X17: A | Y17: A | Z17: A | AA17: A | AB17: A | AC17: A | AD17: A | AE17: A | AF17: A | AG17: =+AF17 -> A | AH17: A | AI17: A | AJ17: A | AK17: A | AL17: =+AK17 -> A | AM17: A | AN17: A | AO17: A | AP17: A | AQ17: =+AP17 -> A | AR17: A | AS17: A | AT17: A | AU17: A | AV17: =+AU17 -> A | AW17: A | AX17: A | AY17: A | AZ17: A | BA17: =+AZ17 -> A | BB17: A | BC17: A | BD17: A | BE17: A | BF17: =+BE17 -> A | BG17: A | BH17: A | BI17: A | BJ17: A | BK17: =+BJ17 -> A | BL17: E | BM17: E | BN17: E | BO17: E | BP17: =+BO17 -> E | BQ17: E | BR17: E | BS17: E | BT17: E | BU17: =+BT17 -> E | BX17: DILUTED:CALENDAR
A18: Current Base Quarter (NOT one just reported - One After That) | B18: Q3 | D18: =D16&D19 -> 2014Q1 | E18: =E16&E19 -> 2014Q2 | F18: =F16&F19 -> 2014Q3 | G18: =G16&G19 -> 2014Q4 | H18: =H16 -> 2014 | I18: =I16&I19&I17 -> 2015Q1A | J18: =J16&J19&J17 -> 2015Q2A | K18: =K16&K19&K17 -> 2015Q3A | L18: =L16&L19&L17 -> 2015Q4A | M18: =M16&M17 -> 2015A | N18: =N16&N19&N17 -> 2016Q1A | O18: =O16&O19&O17 -> 2016Q2A | P18: =P16&P19&P17 -> 2016Q3A | Q18: =Q16&Q19&Q17 -> 2016Q4A | R18: =R16&R17 -> 2016A | S18: =S16&S19&S17 -> 2017Q1A | T18: =T16&T19&T17 -> 2017Q2A | U18: =U16&U19&U17 -> 2017Q3A | V18: =V16&V19&V17 -> 2017Q4A | W18: =W16&W17 -> 2017A | X18: =X16&X19&X17 -> 2018Q1A | Y18: =Y16&Y19&Y17 -> 2018Q2A | Z18: =Z16&Z19&Z17 -> 2018Q3A | AA18: =AA16&AA19&AA17 -> 2018Q4A | AB18: =AB16&AB17 -> 2018A | AC18: =AC16&AC19&AC17 -> 2019Q1A | AD18: =AD16&AD19&AD17 -> 2019Q2A | AE18: =AE16&AE19&AE17 -> 2019Q3A | AF18: =AF16&AF19&AF17 -> 2019Q4A | AG18: =AG16&AG17 -> 2019A | AH18: =AH16&AH19&AH17 -> 2020Q1A | AI18: =AI16&AI19&AI17 -> 2020Q2A | AJ18: =AJ16&AJ19&AJ17 -> 2020Q3A | AK18: =AK16&AK19&AK17 -> 2020Q4A | AL18: =AL16&AL17 -> 2020A | AM18: =AM16&AM19&AM17 -> 2021Q1A | AN18: =AN16&AN19&AN17 -> 2021Q2A | AO18: =AO16&AO19&AO17 -> 2021Q3A | AP18: =AP16&AP19&AP17 -> 2021Q4A | AQ18: =AQ16&AQ17 -> 2021A | AR18: =AR16&AR19&AR17 -> 2022Q1A | AS18: =AS16&AS19&AS17 -> 2022Q2A | AT18: =AT16&AT19&AT17 -> 2022Q3A | AU18: =AU16&AU19&AU17 -> 2022Q4A | AV18: =AV16&AV17 -> 2022A | AW18: =AW16&AW19&AW17 -> 2023Q1A | AX18: =AX16&AX19&AX17 -> 2023Q2A | AY18: =AY16&AY19&AY17 -> 2023Q3A | AZ18: =AZ16&AZ19&AZ17 -> 2023Q4A | BA18: =BA16&BA17 -> 2023A | BB18: =BB16&BB19&BB17 -> 2024Q1A | BC18: =BC16&BC19&BC17 -> 2024Q2A | BD18: =BD16&BD19&BD17 -> 2024Q3A | BE18: =BE16&BE19&BE17 -> 2024Q4A | BF18: =BF16&BF17 -> 2024A | BG18: =BG16&BG19&BG17 -> 2025Q1A | BH18: =BH16&BH19&BH17 -> 2025Q2A | BI18: =BI16&BI19&BI17 -> 2025Q3A | BJ18: =BJ16&BJ19&BJ17 -> 2025Q4A | BK18: =BK16&BK17 -> 2025A | BL18: =BL16&BL19&BL17 -> 2026Q1E | BM18: =BM16&BM19&BM17 -> 2026Q2E | BN18: =BN16&BN19&BN17 -> 2026Q3E | BO18: =BO16&BO19&BO17 -> 2026Q4E | BP18: =BP16&BP17 -> 2026E | BQ18: =BQ16&BQ19&BQ17 -> 2027Q1E | BR18: =BR16&BR19&BR17 -> 2027Q2E | BS18: =BS16&BS19&BS17 -> 2027Q3E | BT18: =BT16&BT19&BT17 -> 2027Q4E | BU18: =BU16&BU17 -> 2027E | BX18: GAAP:CALENDAR
D19: Q1 | E19: Q2 | F19: Q3 | G19: Q4 | H19: AN | I19: Q1 | J19: Q2 | K19: Q3 | L19: Q4 | M19: AN | N19: Q1 | O19: Q2 | P19: Q3 | Q19: Q4 | R19: AN | S19: Q1 | T19: Q2 | U19: Q3 | V19: Q4 | W19: AN | X19: Q1 | Y19: Q2 | Z19: Q3 | AA19: Q4 | AB19: AN | AC19: Q1 | AD19: Q2 | AE19: Q3 | AF19: Q4 | AG19: AN | AH19: Q1 | AI19: Q2 | AJ19: Q3 | AK19: Q4 | AL19: AN | AM19: Q1 | AN19: Q2 | AO19: Q3 | AP19: Q4 | AQ19: AN | AR19: Q1 | AS19: Q2 | AT19: Q3 | AU19: Q4 | AV19: AN | AW19: Q1 | AX19: Q2 | AY19: Q3 | AZ19: Q4 | BA19: AN | BB19: Q1 | BC19: Q2 | BD19: Q3 | BE19: Q4 | BF19: AN | BG19: Q1 | BH19: Q2 | BI19: Q3 | BJ19: Q4 | BK19: AN | BL19: Q1 | BM19: Q2 | BN19: Q3 | BO19: Q4 | BP19: AN | BQ19: Q1 | BR19: Q2 | BS19: Q3 | BT19: Q4 | BU19: AN | BX19: INDICATED:CALENDAR
A20: BlueMatrix Time Series Grids | D20: =($B$45&"/"&31&"/"&(D16+$D$45)) -> 3/31/2014 | E20: =$B$46&"/"&31&"/"&(E16+$D$46) -> 6/31/2014 | F20: =$B$47&"/"&31&"/"&(F16+$D$47) -> 9/31/2014 | G20: =$B$48&"/"&31&"/"&(G16+$D$48) -> 12/31/2014 | H20: =G20 -> 12/31/2014 | I20: =($B$45&"/"&31&"/"&(I16+$D$45)) -> 3/31/2015 | J20: =$B$46&"/"&31&"/"&(J16+$D$46) -> 6/31/2015 | K20: =$B$47&"/"&31&"/"&(K16+$D$47) -> 9/31/2015 | L20: =$B$48&"/"&31&"/"&(L16+$D$48) -> 12/31/2015 | M20: =L20 -> 12/31/2015 | N20: =($B$45&"/"&31&"/"&(N16+$D$45)) -> 3/31/2016 | O20: =$B$46&"/"&31&"/"&(O16+$D$46) -> 6/31/2016 | P20: =$B$47&"/"&31&"/"&(P16+$D$47) -> 9/31/2016 | Q20: =$B$48&"/"&31&"/"&(Q16+$D$48) -> 12/31/2016 | R20: =Q20 -> 12/31/2016 | S20: =($B$45&"/"&31&"/"&(S16+$D$45)) -> 3/31/2017 | T20: =$B$46&"/"&31&"/"&(T16+$D$46) -> 6/31/2017 | U20: =$B$47&"/"&31&"/"&(U16+$D$47) -> 9/31/2017 | V20: =$B$48&"/"&31&"/"&(V16+$D$48) -> 12/31/2017 | W20: =V20 -> 12/31/2017 | X20: =($B$45&"/"&31&"/"&(X16+$D$45)) -> 3/31/2018 | Y20: =$B$46&"/"&31&"/"&(Y16+$D$46) -> 6/31/2018 | Z20: =$B$47&"/"&31&"/"&(Z16+$D$47) -> 9/31/2018 | AA20: =$B$48&"/"&31&"/"&(AA16+$D$48) -> 12/31/2018 | AB20: =AA20 -> 12/31/2018 | AC20: =($B$45&"/"&31&"/"&(AC16+$D$45)) -> 3/31/2019 | AD20: =$B$46&"/"&31&"/"&(AD16+$D$46) -> 6/31/2019 | AE20: =$B$47&"/"&31&"/"&(AE16+$D$47) -> 9/31/2019 | AF20: =$B$48&"/"&31&"/"&(AF16+$D$48) -> 12/31/2019 | AG20: =AF20 -> 12/31/2019 | AH20: =($B$45&"/"&31&"/"&(AH16+$D$45)) -> 3/31/2020 | AI20: =$B$46&"/"&31&"/"&(AI16+$D$46) -> 6/31/2020 | AJ20: =$B$47&"/"&31&"/"&(AJ16+$D$47) -> 9/31/2020 | AK20: =$B$48&"/"&31&"/"&(AK16+$D$48) -> 12/31/2020 | AL20: =AK20 -> 12/31/2020 | AM20: =($B$45&"/"&31&"/"&(AM16+$D$45)) -> 3/31/2021 | AN20: =$B$46&"/"&31&"/"&(AN16+$D$46) -> 6/31/2021 | AO20: =$B$47&"/"&31&"/"&(AO16+$D$47) -> 9/31/2021 | AP20: =$B$48&"/"&31&"/"&(AP16+$D$48) -> 12/31/2021 | AQ20: =AP20 -> 12/31/2021 | AR20: =($B$45&"/"&31&"/"&(AR16+$D$45)) -> 3/31/2022 | AS20: =$B$46&"/"&31&"/"&(AS16+$D$46) -> 6/31/2022 | AT20: =$B$47&"/"&31&"/"&(AT16+$D$47) -> 9/31/2022 | AU20: =$B$48&"/"&31&"/"&(AU16+$D$48) -> 12/31/2022 | AV20: =AU20 -> 12/31/2022 | AW20: =($B$45&"/"&31&"/"&(AW16+$D$45)) -> 3/31/2023 | AX20: =$B$46&"/"&31&"/"&(AX16+$D$46) -> 6/31/2023 | AY20: =$B$47&"/"&31&"/"&(AY16+$D$47) -> 9/31/2023 | AZ20: =$B$48&"/"&31&"/"&(AZ16+$D$48) -> 12/31/2023 | BA20: =AZ20 -> 12/31/2023 | BB20: =($B$45&"/"&31&"/"&(BB16+$D$45)) -> 3/31/2024 | BC20: =$B$46&"/"&31&"/"&(BC16+$D$46) -> 6/31/2024 | BD20: =$B$47&"/"&31&"/"&(BD16+$D$47) -> 9/31/2024 | BE20: =$B$48&"/"&31&"/"&(BE16+$D$48) -> 12/31/2024 | BF20: =BE20 -> 12/31/2024 | BG20: =($B$45&"/"&31&"/"&(BG16+$D$45)) -> 3/31/2025 | BH20: =$B$46&"/"&31&"/"&(BH16+$D$46) -> 6/31/2025 | BI20: =$B$47&"/"&31&"/"&(BI16+$D$47) -> 9/31/2025 | BJ20: =$B$48&"/"&31&"/"&(BJ16+$D$48) -> 12/31/2025 | BK20: =BJ20 -> 12/31/2025 | BL20: =($B$45&"/"&31&"/"&(BL16+$D$45)) -> 3/31/2026 | BM20: =$B$46&"/"&31&"/"&(BM16+$D$46) -> 6/31/2026 | BN20: =$B$47&"/"&31&"/"&(BN16+$D$47) -> 9/31/2026 | BO20: =$B$48&"/"&31&"/"&(BO16+$D$48) -> 12/31/2026 | BP20: =BO20 -> 12/31/2026 | BQ20: =($B$45&"/"&31&"/"&(BQ16+$D$45)) -> 3/31/2027 | BR20: =$B$46&"/"&31&"/"&(BR16+$D$46) -> 6/31/2027 | BS20: =$B$47&"/"&31&"/"&(BS16+$D$47) -> 9/31/2027 | BT20: =$B$48&"/"&31&"/"&(BT16+$D$48) -> 12/31/2027 | BU20: =BT20 -> 12/31/2027 | BX20: MANAGED:CALENDAR
A21: Revenue ($M) | B21: REVENUE | D21: =+IS!D52/1000 -> 16.736 | E21: =+IS!E52/1000 -> 17.88 | F21: =+IS!F52/1000 -> 20.329 | G21: =+IS!G52/1000 -> 21.935 | H21: =+IS!H52/1000 -> 76.88 | I21: =+IS!I52/1000 -> 23.571 | J21: =+IS!J52/1000 -> 25.79 | K21: =+IS!K52/1000 -> 28.312 | ... BU21: =+IS!BU52/1000 -> 852.86558 | BX21: NON-GAAP:CALENDAR
B22: NON-GAAP:CALENDAR | D22: =_xll.BLUEMATRIX2("/servlet/excelData",D21, $C$14,$B21&":"&D$16&D$17&":"&D$19&":"&$B22) -> #NAME? | E22: =_xll.BLUEMATRIX2("/servlet/excelData",E21, $C$14,$B21&":"&E$16&E$17&":"&E$19&":"&$B22) -> #NAME? | F22: =_xll.BLUEMATRIX2("/servlet/excelData",F21, $C$14,$B21&":"&F$16&F$17&":"&F$19&":"&$B22) -> #NAME? | G22: =_xll.BLUEMATRIX2("/servlet/excelData",G21, $C$14,$B21&":"&G$16&G$17&":"&G$19&":"&$B22) -> #NAME? | H22: =_xll.BLUEMATRIX2("/servlet/excelData",H21, $C$14,$B21&":"&H$16&H$17&":"&H$19&":"&$B22) -> #NAME? | I22: =_xll.BLUEMATRIX2("/servlet/excelData",I21, $C$14,$B21&":"&I$16&I$17&":"&I$19&":"&$B22) -> #NAME? | J22: =_xll.BLUEMATRIX2("/servlet/excelData",J21, $C$14,$B21&":"&J$16&J$17&":"&J$19&":"&$B22) -> #NAME? | K22: =_xll.BLUEMATRIX2("/servlet/excelData",K21, $C$14,$B21&":"&K$16&K$17&":"&K$19&":"&$B22) -> #NAME? | ... BU22: =_xll.BLUEMATRIX2("/servlet/excelData",BU21, $C$14,$B21&":"&BU$16&BU$17&":"&BU$19&":"&$B22) -> #NAME? | BX22: OPERATING:CALENDAR
A23: EPS | B23: EPS | D23: =+IS!D117 -> -0.53622507 | E23: =+IS!E117 -> -0.57502434 | F23: =+IS!F117 -> -0.54374463 | G23: =+IS!G117 -> -0.70322603 | H23: =+IS!H117 -> -2.3584839 | I23: =+IS!I117 -> -0.54167839 | J23: =+IS!J117 -> -0.61019764 | K23: =+IS!K117 -> -0.27495054 | ... BU23: =+IS!BU117 -> 1.7035276 | BX23: PRIMARY:CALENDAR
B24: NON-GAAP:CALENDAR | D24: =_xll.BLUEMATRIX2("/servlet/excelData",D23, $C$14,$B23&":"&D$16&D$17&":"&D$19&":"&$B24) -> #NAME? | E24: =_xll.BLUEMATRIX2("/servlet/excelData",E23, $C$14,$B23&":"&E$16&E$17&":"&E$19&":"&$B24) -> #NAME? | F24: =_xll.BLUEMATRIX2("/servlet/excelData",F23, $C$14,$B23&":"&F$16&F$17&":"&F$19&":"&$B24) -> #NAME? | G24: =_xll.BLUEMATRIX2("/servlet/excelData",G23, $C$14,$B23&":"&G$16&G$17&":"&G$19&":"&$B24) -> #NAME? | H24: =_xll.BLUEMATRIX2("/servlet/excelData",H23, $C$14,$B23&":"&H$16&H$17&":"&H$19&":"&$B24) -> #NAME? | I24: =_xll.BLUEMATRIX2("/servlet/excelData",I23, $C$14,$B23&":"&I$16&I$17&":"&I$19&":"&$B24) -> #NAME? | J24: =_xll.BLUEMATRIX2("/servlet/excelData",J23, $C$14,$B23&":"&J$16&J$17&":"&J$19&":"&$B24) -> #NAME? | K24: =_xll.BLUEMATRIX2("/servlet/excelData",K23, $C$14,$B23&":"&K$16&K$17&":"&K$19&":"&$B24) -> #NAME? | ... BU24: =_xll.BLUEMATRIX2("/servlet/excelData",BU23, $C$14,$B23&":"&BU$16&BU$17&":"&BU$19&":"&$B24) -> #NAME? | BX24: PROFORMA:CALENDAR
A25: FCF | B25: FCF | BF25: RESTATED:CALENDAR | BK25: RESTATED:CALENDAR
D26: =_xll.BLUEMATRIX2("/servlet/excelData",D25, $C$14,$B25&":"&D$16&D$17&":"&D$19&":"&$B26) -> #NAME? | E26: =_xll.BLUEMATRIX2("/servlet/excelData",E25, $C$14,$B25&":"&E$16&E$17&":"&E$19&":"&$B26) -> #NAME? | F26: =_xll.BLUEMATRIX2("/servlet/excelData",F25, $C$14,$B25&":"&F$16&F$17&":"&F$19&":"&$B26) -> #NAME? | G26: =_xll.BLUEMATRIX2("/servlet/excelData",G25, $C$14,$B25&":"&G$16&G$17&":"&G$19&":"&$B26) -> #NAME? | H26: =_xll.BLUEMATRIX2("/servlet/excelData",H25, $C$14,$B25&":"&H$16&H$17&":"&H$19&":"&$B26) -> #NAME? | I26: =_xll.BLUEMATRIX2("/servlet/excelData",I25, $C$14,$B25&":"&I$16&I$17&":"&I$19&":"&$B26) -> #NAME? | J26: =_xll.BLUEMATRIX2("/servlet/excelData",J25, $C$14,$B25&":"&J$16&J$17&":"&J$19&":"&$B26) -> #NAME? | K26: =_xll.BLUEMATRIX2("/servlet/excelData",K25, $C$14,$B25&":"&K$16&K$17&":"&K$19&":"&$B26) -> #NAME? | ... W26: =_xll.BLUEMATRIX2("/servlet/excelData",W25, $C$14,$B25&":"&W$16&W$17&":"&W$19&":"&$B26) -> #NAME? | BF26: REVENUE:CALENDAR | BK26: REVENUE:CALENDAR
A27: FFO | B27: FFO
D28: =_xll.BLUEMATRIX2("/servlet/excelData",D27, $C$14,$B27&":"&D$16&D$17&":"&D$19&":"&$B28) -> #NAME? | E28: =_xll.BLUEMATRIX2("/servlet/excelData",E27, $C$14,$B27&":"&E$16&E$17&":"&E$19&":"&$B28) -> #NAME? | F28: =_xll.BLUEMATRIX2("/servlet/excelData",F27, $C$14,$B27&":"&F$16&F$17&":"&F$19&":"&$B28) -> #NAME? | G28: =_xll.BLUEMATRIX2("/servlet/excelData",G27, $C$14,$B27&":"&G$16&G$17&":"&G$19&":"&$B28) -> #NAME? | H28: =_xll.BLUEMATRIX2("/servlet/excelData",H27, $C$14,$B27&":"&H$16&H$17&":"&H$19&":"&$B28) -> #NAME? | I28: =_xll.BLUEMATRIX2("/servlet/excelData",I27, $C$14,$B27&":"&I$16&I$17&":"&I$19&":"&$B28) -> #NAME? | J28: =_xll.BLUEMATRIX2("/servlet/excelData",J27, $C$14,$B27&":"&J$16&J$17&":"&J$19&":"&$B28) -> #NAME? | K28: =_xll.BLUEMATRIX2("/servlet/excelData",K27, $C$14,$B27&":"&K$16&K$17&":"&K$19&":"&$B28) -> #NAME? | ... W28: =_xll.BLUEMATRIX2("/servlet/excelData",W27, $C$14,$B27&":"&W$16&W$17&":"&W$19&":"&$B28) -> #NAME?
A29: Net Cash/Debt ($M) | B29: NET_CASH_DEBT
D30: =_xll.BLUEMATRIX2("/servlet/excelData",D29, $C$14,$B29&":"&D$16&D$17&":"&D$19&":"&$B30) -> #NAME? | E30: =_xll.BLUEMATRIX2("/servlet/excelData",E29, $C$14,$B29&":"&E$16&E$17&":"&E$19&":"&$B30) -> #NAME? | F30: =_xll.BLUEMATRIX2("/servlet/excelData",F29, $C$14,$B29&":"&F$16&F$17&":"&F$19&":"&$B30) -> #NAME? | G30: =_xll.BLUEMATRIX2("/servlet/excelData",G29, $C$14,$B29&":"&G$16&G$17&":"&G$19&":"&$B30) -> #NAME? | H30: =_xll.BLUEMATRIX2("/servlet/excelData",H29, $C$14,$B29&":"&H$16&H$17&":"&H$19&":"&$B30) -> #NAME? | I30: =_xll.BLUEMATRIX2("/servlet/excelData",I29, $C$14,$B29&":"&I$16&I$17&":"&I$19&":"&$B30) -> #NAME? | J30: =_xll.BLUEMATRIX2("/servlet/excelData",J29, $C$14,$B29&":"&J$16&J$17&":"&J$19&":"&$B30) -> #NAME? | K30: =_xll.BLUEMATRIX2("/servlet/excelData",K29, $C$14,$B29&":"&K$16&K$17&":"&K$19&":"&$B30) -> #NAME? | ... W30: =_xll.BLUEMATRIX2("/servlet/excelData",W29, $C$14,$B29&":"&W$16&W$17&":"&W$19&":"&$B30) -> #NAME?
A31: Operating Margin | B31: OP_MARGIN
D32: =_xll.BLUEMATRIX2("/servlet/excelData",D31, $C$14,$B31&":"&D$16&D$17&":"&D$19&":"&$B32) -> #NAME? | E32: =_xll.BLUEMATRIX2("/servlet/excelData",E31, $C$14,$B31&":"&E$16&E$17&":"&E$19&":"&$B32) -> #NAME? | F32: =_xll.BLUEMATRIX2("/servlet/excelData",F31, $C$14,$B31&":"&F$16&F$17&":"&F$19&":"&$B32) -> #NAME? | G32: =_xll.BLUEMATRIX2("/servlet/excelData",G31, $C$14,$B31&":"&G$16&G$17&":"&G$19&":"&$B32) -> #NAME? | H32: =_xll.BLUEMATRIX2("/servlet/excelData",H31, $C$14,$B31&":"&H$16&H$17&":"&H$19&":"&$B32) -> #NAME? | I32: =_xll.BLUEMATRIX2("/servlet/excelData",I31, $C$14,$B31&":"&I$16&I$17&":"&I$19&":"&$B32) -> #NAME? | J32: =_xll.BLUEMATRIX2("/servlet/excelData",J31, $C$14,$B31&":"&J$16&J$17&":"&J$19&":"&$B32) -> #NAME? | K32: =_xll.BLUEMATRIX2("/servlet/excelData",K31, $C$14,$B31&":"&K$16&K$17&":"&K$19&":"&$B32) -> #NAME? | ... W32: =_xll.BLUEMATRIX2("/servlet/excelData",W31, $C$14,$B31&":"&W$16&W$17&":"&W$19&":"&$B32) -> #NAME?
A33: Revenue ($M) | B33: REVENUE
D34: =_xll.BLUEMATRIX2("/servlet/excelData",D33, $C$14,$B33&":"&D$16&D$17&":"&D$19&":"&$B34) -> #NAME? | E34: =_xll.BLUEMATRIX2("/servlet/excelData",E33, $C$14,$B33&":"&E$16&E$17&":"&E$19&":"&$B34) -> #NAME? | F34: =_xll.BLUEMATRIX2("/servlet/excelData",F33, $C$14,$B33&":"&F$16&F$17&":"&F$19&":"&$B34) -> #NAME? | G34: =_xll.BLUEMATRIX2("/servlet/excelData",G33, $C$14,$B33&":"&G$16&G$17&":"&G$19&":"&$B34) -> #NAME? | H34: =_xll.BLUEMATRIX2("/servlet/excelData",H33, $C$14,$B33&":"&H$16&H$17&":"&H$19&":"&$B34) -> #NAME? | I34: =_xll.BLUEMATRIX2("/servlet/excelData",I33, $C$14,$B33&":"&I$16&I$17&":"&I$19&":"&$B34) -> #NAME? | J34: =_xll.BLUEMATRIX2("/servlet/excelData",J33, $C$14,$B33&":"&J$16&J$17&":"&J$19&":"&$B34) -> #NAME? | K34: =_xll.BLUEMATRIX2("/servlet/excelData",K33, $C$14,$B33&":"&K$16&K$17&":"&K$19&":"&$B34) -> #NAME? | ... W34: =_xll.BLUEMATRIX2("/servlet/excelData",W33, $C$14,$B33&":"&W$16&W$17&":"&W$19&":"&$B34) -> #NAME?
A35: ROIC | B35: ROIC
D36: =_xll.BLUEMATRIX2("/servlet/excelData",D35, $C$14,$B35&":"&D$16&D$17&":"&D$19&":"&$B36) -> #NAME? | E36: =_xll.BLUEMATRIX2("/servlet/excelData",E35, $C$14,$B35&":"&E$16&E$17&":"&E$19&":"&$B36) -> #NAME? | F36: =_xll.BLUEMATRIX2("/servlet/excelData",F35, $C$14,$B35&":"&F$16&F$17&":"&F$19&":"&$B36) -> #NAME? | G36: =_xll.BLUEMATRIX2("/servlet/excelData",G35, $C$14,$B35&":"&G$16&G$17&":"&G$19&":"&$B36) -> #NAME? | H36: =_xll.BLUEMATRIX2("/servlet/excelData",H35, $C$14,$B35&":"&H$16&H$17&":"&H$19&":"&$B36) -> #NAME? | I36: =_xll.BLUEMATRIX2("/servlet/excelData",I35, $C$14,$B35&":"&I$16&I$17&":"&I$19&":"&$B36) -> #NAME? | J36: =_xll.BLUEMATRIX2("/servlet/excelData",J35, $C$14,$B35&":"&J$16&J$17&":"&J$19&":"&$B36) -> #NAME? | K36: =_xll.BLUEMATRIX2("/servlet/excelData",K35, $C$14,$B35&":"&K$16&K$17&":"&K$19&":"&$B36) -> #NAME? | ... W36: =_xll.BLUEMATRIX2("/servlet/excelData",W35, $C$14,$B35&":"&W$16&W$17&":"&W$19&":"&$B36) -> #NAME?
D44: Calendar Year = Fiscal Year (If yes =0, if less= -1, if more = 1)
A45: Fiscal 1Q Ending Month Number | B45: 3 | D45: 0
A46: Fiscal 2Q Ending Month Number | B46: 6 | D46: 0
A47: Fiscal 3Q Ending Month Number | B47: 9 | D47: 0
...

Sheet Variance
B3: Rapid7 Inc. Quarterly Variance Analysis
B4: (Thousands Of Dollars, Except Per-Share Data)
D5: Actual | E5: Actual | F5: Needham | G5: Actual | I5: Variance | L5: Yr-Yr | O5: Q-Q
B6: Fiscal Year Ends December | D6: =+IS!BE23 -> 4Q-Dec 24A | E6: 3Q-Sep 25A | F6: 4Q-Dec 25E | G6: =+IS!BJ23 -> 4Q-Dec 25A | I6: % | J6: Absolute | L6: % | M6: Absolute | O6: % | P6: Absolute
B8: Calculated Billings | D8: =+IS!BE25 -> 252578 | E8: 193374 | F8: 252966.34 | G8: =+IS!BJ25 -> 247229 | I8: =+G8/F8-1 -> -0.022680266 | J8: =+G8-F8 -> -5737.344 | L8: =+G8/D8-1 -> -0.021177616 | M8: =+G8-D8 -> -5349 | O8: =+G8/E8-1 -> 0.27850176 | P8: =+G8-E8 -> 53855
B10: Annual Recurring Revenue | D10: =Metrics!BE41*1000 -> 839819 | E10: 837730 | F10: 836459.72 | G10: =Metrics!BJ41*1000 -> 839900 | I10: =+G10/F10-1 -> 0.004112901 | J10: =+G10-F10 -> 3440.276 | L10: =+G10/D10-1 -> 9.6449354e-05 | M10: =+G10-D10 -> 81 | O10: =+G10/E10-1 -> 0.0025903334 | P10: =+G10-E10 -> 2170
B12: Revenue
B13: Product Subscriptions | D13: =+IS!BE39 -> 206328 | E13: 210146 | F13: 207978.62 | G13: =+IS!BJ39 -> 209147 | I13: =+G13/F13-1 -> 0.0056177696 | J13: =+G13-F13 -> 1168.376 | L13: =+G13/D13-1 -> 0.013662712 | M13: =+G13-D13 -> 2819 | O13: =+G13/E13-1 -> -0.0047538378 | P13: =+G13-E13 -> -999
B14: % of Revenue | D14: =+IS!BE31 -> 0.9223724 | E14: 0.93364297 | F14: 0.93240442 | G14: =+IS!BJ31 -> 0.93150414
B15: Yr-Yr Growth | D15: =+IS!BE32 -> 0.062428065 | E15: 0.023944291 | F15: 0.009305856 | G15: =+IS!BJ32 -> 0.015163165
B16: Q-Q Growth | D16: =+IS!BE33 -> 0.0036983332 | E16: 0.010148246 | F16: -0.010650663 | G16: =+IS!BJ33 -> -0.0049091676
B17: Maintenance and Support | D17: =+IS!BE34 -> 6854.8222 | E17: 6649.1776 | F17: 6649.1776 | G17: =+IS!BJ34 -> 6649.1776 | I17: =+G17/F17-1 -> 0 | J17: =+G17-F17 -> 0 | L17: =+G17/D17-1 -> -0.03 | M17: =+G17-D17 -> -205.64467 | O17: =+G17/E17-1 -> 0 | P17: =+G17-E17 -> 0
B18: % of Revenue | D18: =+IS!BE35 -> 0.031696988 | E18: 0.030506412 | F18: 0.030793918 | G18: =+IS!BJ35 -> 0.030586682
B19: Yr-Yr Growth | D19: =+IS!BE36 -> -0.03 | E19: -0.03 | F19: -0.03 | G19: =+IS!BJ36 -> -0.03
B20: Q-Q Growth | D20: =+IS!BE37 -> 0 | E20: 0.00069397085 | F20: 0 | G20: =+IS!BJ37 -> 0
B21: Professional Services | D21: =+IS!BE47 -> 9933 | E21: 7814 | F21: 7946.4 | G21: =+IS!BJ47 -> 8241 | I21: =+G21/F21-1 -> 0.037073392 | J21: =+G21-F21 -> 294.6 | L21: =+G21/D21-1 -> -0.17034129 | M21: =+G21-D21 -> -1692 | O21: =+G21/E21-1 -> 0.054645508 | P21: =+G21-E21 -> 427
B22: % of Revenue | D22: =+IS!BE50 -> 0.045930612 | E22: 0.035850615 | F22: 0.036801663 | G22: =+IS!BJ50 -> 0.037909176
B23: Yr-Yr Growth | D23: =+IS!BE48 -> -0.049382716 | E23: -0.13762278 | F23: -0.2 | G23: =+IS!BJ48 -> -0.17034129
B24: Q-Q Growth | D24: =+IS!BE49 -> 0.096236618 | E24: 0.28182415 | F24: 0.016943947 | G24: =+IS!BJ49 -> 0.054645508
D25: ______ | E25: ______ | F25: ______ | G25: ______ | I25: ______ | J25: ______ | L25: ______ | M25: ______ | O25: ______ | P25: ______
B26: Total Revenues | D26: =+IS!BE52 -> 216261 | E26: 217960 | F26: 215925.02 | G26: =+IS!BJ52 -> 217388 | I26: =+G26/F26-1 -> 0.0067753888 | J26: =+G26-F26 -> 1462.976 | L26: =+G26/D26-1 -> 0.0052112956 | M26: =+G26-D26 -> 1127 | O26: =+G26/E26-1 -> -0.0026243347 | P26: =+G26-E26 -> -572
C27: Guide: $214-$216M | F27: 215020 | I27: =+G26/F27-1 -> 0.011012929 | J27: =+G26-F27 -> 2368
B28: Yr-Yr Growth | D28: =+IS!BE53 -> 0.053554378 | E28: 0.01540153 | F28: 0.034211336 | G28: =+IS!BJ53 -> 0.0052112956
B29: Q-Q Growth | D29: =+IS!BE54 -> 0.0074864666 | E29: 0.017586943 | F29: -0.011010778 | G29: =+IS!BJ54 -> -0.0026243347
B31: Cost of Goods Sold
B32: Product Subscriptions | D32: =+IS!BE65 -> 51932 | E32: 51908 | F32: 53034.549 | G32: =+IS!BJ65 -> 54081 | I32: =+G32/F32-1 -> 0.019731494 | J32: =+G32-F32 -> 1046.4509 | L32: =+G32/D32-1 -> 0.041381037 | M32: =+G32-D32 -> 2149 | O32: =+G32/E32-1 -> 0.041862526 | P32: =+G32-E32 -> 2173
B33: % of Revenue | D33: =+IS!BE58 -> 0 | E33: 0 | F33: 0 | G33: =+IS!BJ58 -> 0
B34: Yr-Yr Growth | D34: =+IS!BE59 -> 0 | E34: 0 | F34: 0 | G34: =+IS!BJ59 -> 0
B35: Q-Q Growth | D35: =+IS!BE60 -> 0 | E35: 0 | F35: 0 | G35: =+IS!BJ60 -> 0
B36: Maintenance and Support | D36: =+IS!BE61 -> 0 | E36: 0 | F36: 0 | G36: =+IS!BJ61 -> 0 | I36: =+G36/F36-1 -> #DIV/0! | J36: =+G36-F36 -> 0 | L36: =+G36/D36-1 -> #DIV/0! | M36: =+G36-D36 -> 0 | O36: =IFERROR(+G36/E36-1, "N/A") -> N/A | P36: =+G36-E36 -> 0
B37: % of Revenue | D37: =+IS!BE62 -> 0 | E37: 0 | F37: 0 | G37: =+IS!BJ62 -> 0
B38: Yr-Yr Growth | D38: =+IS!BE63 -> 0 | E38: 0 | F38: 0 | G38: =+IS!BJ63 -> 0
B39: Q-Q Growth | D39: =+IS!BE64 -> 0 | E39: 0 | F39: 0 | G39: =+IS!BJ64 -> 0
B40: Professional Services | D40: =+IS!BE69 -> 6427 | E40: 6195 | F40: 6357.12 | G40: =+IS!BJ69 -> 6673 | I40: =+G40/F40-1 -> 0.049689167 | J40: =+G40-F40 -> 315.88 | L40: =+G40/D40-1 -> 0.038276023 | M40: =+G40-D40 -> 246 | O40: =+G40/E40-1 -> 0.077158999 | P40: =+G40-E40 -> 478
B41: % of Revenue | D41: =+IS!BE70 -> 0.02971872 | E41: 0.028422646 | F41: 0.029441331 | G41: =+IS!BJ70 -> 0.030696267
B42: Yr-Yr Growth | D42: =+IS!BE71 -> -0.076447765 | E42: 0.045216804 | F42: -0.01087288 | G42: =+IS!BJ71 -> 0.038276023
B43: Q-Q Growth | D43: =+IS!BE72 -> 0.08435971 | E43: 0.16952992 | F43: 0.026169492 | G43: =+IS!BJ72 -> 0.077158999
D44: =+IS!BE73 -> ______ | E44: ______ | F44: ______ | G44: =+IS!BJ73 -> ______ | I44: ______ | J44: ______ | L44: ______ | M44: ______ | O44: ______ | P44: ______
B45: Total Cost Of Goods Sold (Non GAAP) | D45: =+D32+D40 -> 58359 | E45: 58103 | F45: 59391.669 | G45: =+G32+G40 -> 60754 | I45: =+G45/F45-1 -> 0.02293808 | J45: =+G45-F45 -> 1362.3309 | L45: =+G45/D45-1 -> 0.041039086 | M45: =+G45-D45 -> 2395 | O45: =+G45/E45-1 -> 0.045625871 | P45: =+G45-E45 -> 2651
D46: =+IS!BE75 -> ______ | E46: ______ | F46: ______ | G46: =+IS!BJ75 -> ______ | I46: ______ | J46: ______ | L46: ______ | M46: ______ | O46: ______ | P46: ______
...

Sheet BS
B3: Rapid7 Inc.—Balance Sheet
B4: (Thousands Of Dollars, Except Per-Share Data) | D4: March | E4: June | F4: Sept | G4: Dec | H4: Dec | I4: March | J4: June | K4: Sept | L4: Dec | M4: Dec | N4: March | O4: June | P4: Sept | Q4: Dec | R4: Dec | S4: March | T4: June | U4: Sept | V4: Dec | W4: Dec | X4: March | Y4: June | Z4: Sept | AA4: Dec | AB4: Dec | AC4: March | AD4: June | AE4: Sept | AF4: Dec | AG4: Dec | AH4: March | AI4: June | AJ4: Sept | AK4: Dec | AL4: Dec | AM4: March | AN4: June | AO4: Sept | AP4: Dec | AQ4: Dec | AR4: March | AS4: June | AT4: Sept | AU4: Dec | AV4: Dec | AW4: March | AX4: June | AY4: Sept | AZ4: Dec | BA4: Dec | BB4: March | BC4: June | BD4: Sept | BE4: Dec | BF4: Dec | BG4: March | BH4: June | BI4: Sept | BJ4: Dec | BK4: Dec | BL4: March | BM4: June | BN4: Sept | BO4: Dec | BP4: Dec | BQ4: March | BR4: June | BS4: Sept | BT4: Dec | BU4: Dec
D5: 2014A | E5: 2014A | F5: 2014A | G5: 2014A | H5: 2014A | I5: 2015A | J5: 2015A | K5: 2015A | L5: 2015A | M5: 2015A | N5: 2016A | O5: 2016A | P5: 2016A | Q5: 2016A | R5: 2016A | S5: 2017A | T5: 2017A | U5: 2017A | V5: 2017A | W5: 2017A | X5: 2018A | Y5: 2018A | Z5: 2018A | AA5: 2018A | AB5: 2018A | AC5: 2019A | AD5: 2019A | AE5: 2019A | AF5: 2019A | AG5: =AF5 -> 2019A | AH5: 2020A | AI5: 2020A | AJ5: 2020A | AK5: 2020A | AL5: =AK5 -> 2020A | AM5: 2021A | AN5: 2021A | AO5: 2021A | AP5: 2021A | AQ5: =AP5 -> 2021A | AR5: 2022A | AS5: 2022A | AT5: 2022A | AU5: 2022A | AV5: =AU5 -> 2022A | AW5: 2023A | AX5: 2023A | AY5: 2023A | AZ5: 2023A | BA5: =AZ5 -> 2023A | BB5: 2024A | BC5: 2024A | BD5: 2024A | BE5: 2024A | BF5: =BE5 -> 2024A | BG5: 2025A | BH5: 2025A | BI5: 2025A | BJ5: 2025A | BK5: =BJ5 -> 2025A | BL5: 2026E | BM5: 2026E | BN5: 2026E | BO5: 2026E | BP5: =BO5 -> 2026E | BQ5: 2027E | BR5: 2027E | BS5: 2027E | BT5: 2027E | BU5: =BT5 -> 2027E
B6: Current Assets
B7: Cash and Cash Equivalents | G7: 36823 | H7: 36823 | I7: 33343 | J7: 27000 | K7: 123984 | L7: 86553 | M7: =+L7 -> 86553 | N7: 83508 | O7: 84755 | P7: 87715 | Q7: 53148 | R7: =+Q7 -> 53148 | S7: 50662 | T7: 53068 | U7: 49055 | V7: 51562 | W7: =+V7 -> 51562 | X7: 99646 | Y7: 100731 | Z7: 131160 | AA7: 99565 | AB7: =+AA7 -> 99565 | AC7: 89869 | AD7: 126569 | AE7: 114925 | AF7: =123413 -> 123413 | AG7: =+AF7 -> 123413 | AH7: 204434 | AI7: 279343 | AJ7: =239409 -> 239409 | AK7: =173617 -> 173617 | AL7: =+AK7 -> 173617 | AM7: =503804 -> 503804 | AN7: =493568 -> 493568 | AO7: =227104 -> 227104 | AP7: =164582 -> 164582 | AQ7: =+AP7 -> 164582 | AR7: =141365 -> 141365 | AS7: =163469 -> 163469 | AT7: =168353 -> 168353 | AU7: =207287 -> 207287 | AV7: =+AU7 -> 207287 | AW7: =205757 -> 205757 | AX7: =185929 -> 185929 | AY7: =182727 -> 182727 | AZ7: =213629 -> 213629 | BA7: =+AZ7 -> 213629 | BB7: =198716 -> 198716 | BC7: =236975 -> 236975 | BD7: =222571 -> 222571 | BE7: =334686 -> 334686 | BF7: =+BE7 -> 334686 | BG7: =291462 -> 291462 | BH7: =261327 -> 261327 | BI7: =130613 -> 130613 | BJ7: =246664 -> 246664 | BK7: =+BJ7 -> 246664 | BL7: =+CF!BL68 -> 271891.32 | BM7: =+CF!BM68 -> 306313.54 | BN7: =+CF!BN68 -> 333933.51 | BO7: =+CF!BO68 -> 383052.41 | BP7: =+BO7 -> 383052.41 | BQ7: =+CF!BQ68 -> 406981.17 | BR7: =+CF!BR68 -> 437336.4 | BS7: =+CF!BS68 -> 467636.61 | BT7: =+CF!BT68 -> 520132.76 | BU7: =+BT7 -> 520132.76
B8: Short-Term Investments | G8: 0 | H8: 0 | I8: 0 | J8: 0 | K8: 0 | L8: 0 | M8: =+L8 -> 0 | N8: 0 | O8: 0 | P8: 0 | Q8: 18779 | R8: =+Q8 -> 18779 | S8: 28561 | T8: 31213 | U8: 34825 | V8: 39178 | W8: =+V8 -> 39178 | X8: 29630 | Y8: 13983 | Z8: 140633 | AA8: 159210 | AB8: =+AA8 -> 159210 | AC8: 161600 | AD8: 119138 | AE8: 131815 | AF8: =116158 -> 116158 | AG8: =+AF8 -> 116158 | AH8: 36384 | AI8: 36313 | AJ8: =81209 -> 81209 | AK8: =138839 -> 138839 | AL8: =+AK8 -> 138839 | AM8: =101996 -> 101996 | AN8: =114284 -> 114284 | AO8: =77145 -> 77145 | AP8: =58850 -> 58850 | AQ8: =+AP8 -> 58850 | AR8: =93155 -> 93155 | AS8: =76244 -> 76244 | AT8: =83231 -> 83231 | AU8: =84162 -> 84162 | AV8: =+AU8 -> 84162 | AW8: =56483 -> 56483 | AX8: =107573 -> 107573 | AY8: =139434 -> 139434 | AZ8: =169544 -> 169544 | BA8: =+AZ8 -> 169544 | BB8: =213001 -> 213001 | BC8: =205671 -> 205671 | BD8: =221122 -> 221122 | BE8: =187025 -> 187025 | BF8: =+BE8 -> 187025 | BG8: =202011 -> 202011 | BH8: =250410 -> 250410 | BI8: =276515 -> 276515 | BJ8: =228006 -> 228006 | BK8: =+BJ8 -> 228006 | BL8: =+BJ8 -> 228006 | BM8: =+BL8 -> 228006 | BN8: =+BM8 -> 228006 | BO8: =+BN8 -> 228006 | BP8: =+BO8 -> 228006 | BQ8: =+BO8 -> 228006 | BR8: =+BQ8 -> 228006 | BS8: =+BR8 -> 228006 | BT8: =+BS8 -> 228006 | BU8: =+BT8 -> 228006
B9: Accounts Receivable, net | G9: 25412 | H9: 25412 | I9: 21027 | J9: 26363 | K9: 31969 | L9: 44164 | M9: =+L9 -> 44164 | N9: 29817 | O9: 38663 | P9: 38286 | Q9: 49154 | R9: =+Q9 -> 49154 | S9: 33703 | T9: 47560 | U9: 48690 | V9: 73661 | W9: =+V9 -> 73661 | X9: 38718 | Y9: 48476 | Z9: 53771 | AA9: 74935 | AB9: =+AA9 -> 74935 | AC9: 59707 | AD9: 69289 | AE9: 62422 | AF9: =87927 -> 87927 | AG9: =+AF9 -> 87927 | AH9: 64388 | AI9: 76823 | AJ9: =73625 -> 73625 | AK9: =111599 -> 111599 | AL9: =+AK9 -> 111599 | AM9: =76714 -> 76714 | AN9: =98483 -> 98483 | AO9: =96775 -> 96775 | AP9: =146094 -> 146094 | AQ9: =+AP9 -> 146094 | AR9: =107320 -> 107320 | AS9: =124701 -> 124701 | AT9: =121017 -> 121017 | AU9: =152045 -> 152045 | AV9: =+AU9 -> 152045 | AW9: =116683 -> 116683 | AX9: =136300 -> 136300 | AY9: =137690 -> 137690 | AZ9: =164862 -> 164862 | BA9: =+AZ9 -> 164862 | BB9: =124595 -> 124595 | BC9: =143671 -> 143671 | BD9: =141891 -> 141891 | BE9: =168242 -> 168242 | BF9: =+BE9 -> 168242 | BG9: =140541 -> 140541 | BH9: =150683 -> 150683 | BI9: =141339 -> 141339 | BJ9: =167017 -> 167017 | BK9: =+BJ9 -> 167017 | BL9: =+BL62*BL75/90 -> 140957.26 | BM9: =+BM62*BM75/90 -> 148575.13 | BN9: =+BN62*BN75/90 -> 135493.86 | BO9: =+BO62*BO75/90 -> 159967.49 | BP9: =+BO9 -> 159967.49 | BQ9: =+BQ62*BQ75/90 -> 141015.06 | BR9: =+BR62*BR75/90 -> 151120.08 | BS9: =+BS62*BS75/90 -> 144831.07 | BT9: =+BT62*BT75/90 -> 172116.16 | BU9: =+BT9 -> 172116.16
B10: Deferred Contract Acquisition and Fulfillment Costs, Current Portion | G10: 0 | H10: 0 | I10: 0 | J10: 0 | K10: 0 | L10: 0 | M10: =+L10 -> 0 | N10: 0 | O10: 0 | P10: 0 | Q10: 0 | R10: =+Q10 -> 0 | S10: 0 | T10: 0 | U10: =+T10 -> 0 | V10: 7844 | W10: =+V10 -> 7844 | X10: 8583 | Y10: 9481 | Z10: 10376 | AA10: 12321 | AB10: =+AA10 -> 12321 | AC10: 12994 | AD10: 13851 | AE10: 14905 | AF10: =17047 -> 17047 | AG10: =+AF10 -> 17047 | AH10: 17486 | AI10: 18439 | AJ10: =19269 -> 19269 | AK10: =21536 -> 21536 | AL10: =+AK10 -> 21536 | AM10: =22598 -> 22598 | AN10: =23960 -> 23960 | AO10: =25863 -> 25863 | AP10: =29974 -> 29974 | AQ10: =+AP10 -> 29974 | AR10: =30984 -> 30984 | AS10: =31367 -> 31367 | AT10: =33307 -> 33307 | AU10: =34906 -> 34906 | AV10: =+AU10 -> 34906 | AW10: =36171 -> 36171 | AX10: =38661 -> 38661 | AY10: =40909 -> 40909 | AZ10: =45008 -> 45008 | BA10: =+AZ10 -> 45008 | BB10: =47003 -> 47003 | BC10: =48880 -> 48880 | BD10: =49710 -> 49710 | BE10: =52134 -> 52134 | BF10: =+BE10 -> 52134 | BG10: =50667 -> 50667 | BH10: =49292 -> 49292 | BI10: =47557 -> 47557 | BJ10: =48370 -> 48370 | BK10: =+BJ10 -> 48370 | BL10: =+BJ10*(1+BL139) -> 49821.1 | BM10: =+BL10*(1+BM139) -> 51315.733 | BN10: =+BM10*(1+BN139) -> 52855.205 | BO10: =+BN10*(1+BO139) -> 54440.861 | BP10: =+BO10 -> 54440.861 | BQ10: =+BO10*(1+BQ139) -> 56618.496 | BR10: =+BQ10*(1+BR139) -> 58883.235 | BS10: =+BR10*(1+BS139) -> 61238.565 | BT10: =+BS10*(1+BT139) -> 63688.107 | BU10: =+BT10 -> 63688.107
B11: Prepaid Expenses & Other Current Assets | G11: 4209 | H11: 4209 | I11: 4995 | J11: 6297 | K11: 4165 | L11: 6148 | M11: =+L11 -> 6148 | N11: 6618 | O11: 7183 | P11: 6705 | Q11: 9152 | R11: =+Q11 -> 9152 | S11: 7742 | T11: 8892 | U11: 8747 | V11: 8907 | W11: =+V11 -> 8907 | X11: 12232 | Y11: 13212 | Z11: 11616 | AA11: 9746 | AB11: =+AA11 -> 9746 | AC11: 15773 | AD11: 15416 | AE11: 15827 | AF11: =20051 -> 20051 | AG11: =+AF11 -> 20051 | AH11: 19624 | AI11: 20708 | AJ11: =20521 -> 20521 | AK11: =27844 -> 27844 | AL11: =+AK11 -> 27844 | AM11: =28943 -> 28943 | AN11: =27555 -> 27555 | AO11: =27079 -> 27079 | AP11: =33236 -> 33236 | AQ11: =+AP11 -> 33236 | AR11: =38051 -> 38051 | AS11: =34221 -> 34221 | AT11: =33402 -> 33402 | AU11: =31907 -> 31907 | AV11: =+AU11 -> 31907 | AW11: =39527 -> 39527 | AX11: =56463 -> 56463 | AY11: =35087 -> 35087 | AZ11: =41407 -> 41407 | BA11: =+AZ11 -> 41407 | BB11: =42552 -> 42552 | BC11: =39194 -> 39194 | BD11: =37328 -> 37328 | BE11: =44024 -> 44024 | BF11: =+BE11 -> 44024 | BG11: =47964 -> 47964 | BH11: =42805 -> 42805 | BI11: =39001 -> 39001 | BJ11: =47230 -> 47230 | BK11: =+BJ11 -> 47230 | BL11: =+(BL63+BL64)*BL78 -> 43181.964 | BM11: =+(BM63+BM64)*BM78 -> 39749.821 | BN11: =+(BN63+BN64)*BN78 -> 42901.288 | BO11: =+(BO63+BO64)*BO78 -> 41316.794 | BP11: =+BO11 -> 41316.794 | BQ11: =+(BQ63+BQ64)*BQ78 -> 40258.715 | BR11: =+(BR63+BR64)*BR78 -> 36775.366 | BS11: =+(BS63+BS64)*BS78 -> 34973.848 | BT11: =+(BT63+BT64)*BT78 -> 37064.287 | BU11: =+BT11 -> 37064.287
D12: ______ | E12: ______ | F12: ______ | G12: ______ | H12: ______ | I12: ______ | J12: ______ | K12: ______ | L12: ______ | M12: ______ | N12: ______ | O12: ______ | P12: ______ | Q12: ______ | R12: ______ | S12: ______ | T12: ______ | U12: ______ | V12: ______ | W12: ______ | X12: ______ | Y12: ______ | Z12: ______ | AA12: ______ | AB12: ______ | AC12: ______ | AD12: ______ | AE12: ______ | AF12: ______ | AG12: ______ | AH12: ______ | AI12: ______ | AJ12: ______ | AK12: ______ | AL12: ______ | AM12: ______ | AN12: ______ | AO12: ______ | AP12: ______ | AQ12: ______ | AR12: ______ | AS12: ______ | AT12: ______ | AU12: ______ | AV12: ______ | AW12: ______ | AX12: ______ | AY12: ______ | AZ12: ______ | BA12: ______ | BB12: ______ | BC12: ______ | BD12: ______ | BE12: ______ | BF12: ______ | BG12: ______ | BH12: ______ | BI12: ______ | BJ12: ______ | BK12: ______ | BL12: ______ | BM12: ______ | BN12: ______ | BO12: ______ | BP12: ______ | BQ12: ______ | BR12: ______ | BS12: ______ | BT12: ______ | BU12: ______
B13: Total Current Assets | D13: =SUM(D7:D11)-#REF! -> #REF! | E13: =SUM(E7:E11)-#REF! -> #REF! | F13: =SUM(F7:F11)-#REF! -> #REF! | G13: =SUM(G7:G11)-#REF! -> #REF! | H13: =SUM(H7:H11)-#REF! -> #REF! | I13: =SUM(I7:I11)-#REF! -> #REF! | J13: =SUM(J7:J11)-#REF! -> #REF! | K13: =SUM(K7:K11)-#REF! -> #REF! | L13: =SUM(L7:L11)-#REF! -> #REF! | M13: =SUM(M7:M11) -> 136865 | N13: =SUM(N7:N11) -> 119943 | O13: =SUM(O7:O11) -> 130601 | P13: =SUM(P7:P11) -> 132706 | Q13: =SUM(Q7:Q11) -> 130233 | R13: =SUM(R7:R11) -> 130233 | S13: =SUM(S7:S11) -> 120668 | T13: =SUM(T7:T11) -> 140733 | ... BU13: =SUM(BU7:BU11) -> 1021007.3
B15: Long-Term Investments | G15: 0 | H15: 0 | I15: 0 | J15: 0 | K15: 0 | L15: 0 | M15: =+L15 -> 0 | N15: 0 | O15: 0 | P15: 0 | Q15: 20162 | R15: =+Q15 -> 20162 | S15: 16803 | T15: 8799 | U15: 1110 | V15: 1102 | W15: =+V15 -> 1102 | X15: 1096 | Y15: 3929 | Z15: 39275 | AA15: 44892 | AB15: =+AA15 -> 44892 | AC15: 33613 | AD15: 18680 | AE15: 10997 | AF15: =22887 -> 22887 | AG15: =+AF15 -> 22887 | AH15: 12804 | AI15: 5365 | AJ15: =10813 -> 10813 | AK15: =10124 -> 10124 | AL15: =+AK15 -> 10124 | AM15: =11133 -> 11133 | AN15: =5377 -> 5377 | AO15: =5364 -> 5364 | AP15: =34068 -> 34068 | AQ15: =+AP15 -> 34068 | AR15: =28295 -> 28295 | AS15: =14330 -> 14330 | AT15: =16707 -> 16707 | AU15: =9756 -> 9756 | AV15: =+AU15 -> 9756 | AW15: =7343 -> 7343 | AX15: =2437 -> 2437 | AY15: =50603 -> 50603 | AZ15: =56171 -> 56171 | BA15: =+AZ15 -> 56171 | BB15: =52454 -> 52454 | BC15: =51434 -> 51434 | BD15: =60382 -> 60382 | BE15: =37274 -> 37274 | BF15: =+BE15 -> 37274 | BG15: =99136 -> 99136 | BH15: =88012 -> 88012 | BI15: =227418 -> 227418 | BJ15: =184119 -> 184119 | BK15: =+BJ15 -> 184119 | BL15: =+BJ15 -> 184119 | BM15: =+BL15 -> 184119 | BN15: =+BM15 -> 184119 | BO15: =+BN15 -> 184119 | BP15: =+BO15 -> 184119 | BQ15: =+BO15 -> 184119 | BR15: =+BQ15 -> 184119 | BS15: =+BR15 -> 184119 | BT15: =+BS15 -> 184119 | BU15: =+BT15 -> 184119
B16: Property, Plant, And Equipment, net | G16: 7922 | H16: 7922 | I16: 7619 | J16: 7607 | K16: 7356 | L16: 7532 | M16: =+L16 -> 7532 | N16: 7611 | O16: 7386 | P16: 8009 | Q16: 8088 | R16: =+Q16 -> 8088 | S16: 8010 | T16: 8287 | U16: 7995 | V16: 8589 | W16: =+V16 -> 8589 | X16: 9238 | Y16: 11184 | Z16: 11859 | AA16: 17523 | AB16: =+AA16 -> 17523 | AC16: 32771 | AD16: 51860 | AE16: 51519 | AF16: =50670 -> 50670 | AG16: =+AF16 -> 50670 | AH16: 50075 | AI16: 48904 | AJ16: =50305 -> 50305 | AK16: =53114 -> 53114 | AL16: =+AK16 -> 53114 | AM16: =51141 -> 51141 | AN16: =49431 -> 49431 | AO16: =49034 -> 49034 | AP16: =50225 -> 50225 | AQ16: =+AP16 -> 50225 | AR16: =49804 -> 49804 | AS16: =50533 -> 50533 | AT16: =55002 -> 55002 | AU16: =57891 -> 57891 | AV16: =+AU16 -> 57891 | AW16: =56638 -> 56638 | AX16: =47104 -> 47104 | AY16: =42449 -> 42449 | AZ16: =39642 -> 39642 | BA16: =+AZ16 -> 39642 | BB16: =37266 -> 37266 | BC16: =34884 -> 34884 | BD16: =33936 -> 33936 | BE16: =32245 -> 32245 | BF16: =+BE16 -> 32245 | BG16: =31659 -> 31659 | BH16: =29639 -> 29639 | BI16: =31966 -> 31966 | BJ16: =31990 -> 31990 | BK16: =+BJ16 -> 31990 | BL16: =+BL89 -> 31510.497 | BM16: =+BM89 -> 31078.995 | BN16: =+BN89 -> 30695.167 | BO16: =+BO89 -> 30356.77 | BP16: =+BO16 -> 30356.77 | BQ16: =+BQ89 -> 30043.454 | BR16: =+BR89 -> 29765.104 | BS16: =+BS89 -> 29520.748 | BT16: =+BT89 -> 29310.54 | BU16: =+BT16 -> 29310.54
B17: Operating Lease ROU Assets | M17: =+L17 -> 0 | R17: =+Q17 -> 0 | W17: =+V17 -> 0 | AB17: =+AA17 -> 0 | AC17: 15888 | AD17: 59417 | AE17: 61217 | AF17: =60984 -> 60984 | AG17: =+AF17 -> 60984 | AH17: 62942 | AI17: 72005 | AJ17: =69797 -> 69797 | AK17: =67178 -> 67178 | AL17: =+AK17 -> 67178 | AM17: =64965 -> 64965 | AN17: =63472 -> 63472 | AO17: =62105 -> 62105 | AP17: =83751 -> 83751 | AQ17: =+AP17 -> 83751 | AR17: =89196 -> 89196 | AS17: =84937 -> 84937 | AT17: =85250 -> 85250 | AU17: =79342 -> 79342 | AV17: =+AU17 -> 79342 | AW17: =77420 -> 77420 | AX17: =56817 -> 56817 | AY17: =53275 -> 53275 | AZ17: =54693 -> 54693 | BA17: =+AZ17 -> 54693 | BB17: =53036 -> 53036 | BC17: =50645 -> 50645 | BD17: =50756 -> 50756 | BE17: =48877 -> 48877 | BF17: =+BE17 -> 48877 | BG17: =46404 -> 46404 | BH17: =43654 -> 43654 | BI17: =47536 -> 47536 | BJ17: =45485 -> 45485 | BK17: =+BJ17 -> 45485 | BL17: =+BK17 -> 45485 | BM17: =+BL17 -> 45485 | BN17: =+BM17 -> 45485 | BO17: =+BN17 -> 45485 | BP17: =+BO17 -> 45485 | BQ17: =+BP17 -> 45485 | BR17: =+BQ17 -> 45485 | ... BU17: =+BT17 -> 45485
B18: Deferred Contract Acquisition and Fulfillment Costs, Non-Current Portion | G18: 0 | H18: 0 | I18: 0 | J18: 0 | K18: 0 | L18: 0 | M18: =+L18 -> 0 | N18: 0 | O18: 0 | P18: 0 | Q18: 0 | R18: =+Q18 -> 0 | S18: 0 | T18: 0 | U18: =+T18 -> 0 | V18: 19321 | W18: =+V18 -> 19321 | X18: 20295 | Y18: 22214 | Z18: 23174 | AA18: 27634 | AB18: =+AA18 -> 27634 | AC18: 28054 | AD18: 29275 | AE18: 30452 | AF18: =34213 -> 34213 | AG18: =+AF18 -> 34213 | AH18: 34289 | AI18: 35815 | AJ18: =37269 -> 37269 | AK18: =43103 -> 43103 | AL18: =+AK18 -> 43103 | AM18: =43997 -> 43997 | AN18: =46132 -> 46132 | AO18: =48548 -> 48548 | AP18: =57191 -> 57191 | AQ18: =+AP18 -> 57191 | AR18: =59121 -> 59121 | AS18: =60878 -> 60878 | AT18: =61857 -> 61857 | AU18: =68169 -> 68169 | AV18: =+AU18 -> 68169 | AW18: =69144 -> 69144 | AX18: =70377 -> 70377 | AY18: =71654 -> 71654 | AZ18: =76601 -> 76601 | BA18: =+AZ18 -> 76601 | BB18: =75287 -> 75287 | BC18: =74693 -> 74693 | BD18: =72392 -> 72392 | BE18: =73672 -> 73672 | BF18: =+BE18 -> 73672 | BG18: =69843 -> 69843 | BH18: =66714 -> 66714 | BI18: =64109 -> 64109 | BJ18: =66978 -> 66978 | BK18: =+BJ18 -> 66978 | BL18: =+BJ18*(1+BL144) -> 66308.22 | BM18: =+BL18*(1+BM144) -> 65645.138 | BN18: =+BM18*(1+BN144) -> 64988.686 | BO18: =+BN18*(1+BO144) -> 64338.8 | BP18: =+BO18 -> 64338.8 | BQ18: =+BO18*(1+BQ144) -> 63695.412 | BR18: =+BQ18*(1+BR144) -> 63058.457 | BS18: =+BR18*(1+BS144) -> 62427.873 | BT18: =+BS18*(1+BT144) -> 61803.594 | BU18: =+BT18 -> 61803.594
B19: Goodwill | G19: 11265 | H19: 11265 | I19: 11265 | J19: 15758 | K19: 15847 | L19: 74565 | M19: =+L19 -> 74565 | N19: 74943 | O19: 75048 | P19: 75110 | Q19: 75110 | R19: =+Q19 -> 75110 | S19: 75110 | T19: 75110 | U19: 83170 | V19: 83164 | W19: =+V19 -> 83164 | X19: 83164 | Y19: 83164 | Z19: 83164 | AA19: 88420 | AB19: =+AA19 -> 88420 | AC19: 88420 | AD19: 97866 | AE19: 97866 | AF19: =97866 -> 97866 | AG19: =+AF19 -> 97866 | AH19: 97866 | AI19: 213686 | AJ19: =213727 -> 213727 | AK19: =213601 -> 213601 | AL19: =+AK19 -> 213601 | AM19: =253324 -> 253324 | AN19: =254418 -> 254418 | AO19: =515297 -> 515297 | AP19: =515258 -> 515258 | AQ19: =+AP19 -> 515258 | AR19: =515333 -> 515333 | AS19: =515631 -> 515631 | AT19: =515631 -> 515631 | AU19: =515631 -> 515631 | AV19: =+AU19 -> 515631 | AW19: =538037 -> 538037 | AX19: =536326 -> 536326 | AY19: =536305 -> 536305 | AZ19: =536351 -> 536351 | BA19: =+AZ19 -> 536351 | BB19: =536351 -> 536351 | BC19: =536351 -> 536351 | BD19: =575165 -> 575165 | BE19: =575268 -> 575268 | BF19: =+BE19 -> 575268 | BG19: =575268 -> 575268 | BH19: =575268 -> 575268 | BI19: =575268 -> 575268 | BJ19: =575268 -> 575268 | BK19: =+BJ19 -> 575268 | BL19: =+BJ19 -> 575268 | BM19: =+BL19 -> 575268 | BN19: =+BM19 -> 575268 | BO19: =+BN19 -> 575268 | BP19: =+BO19 -> 575268 | BQ19: =+BO19 -> 575268 | BR19: =+BQ19 -> 575268 | BS19: =+BR19 -> 575268 | BT19: =+BS19 -> 575268 | BU19: =+BT19 -> 575268
B20: Intangible Assets, net | G20: 1156 | H20: 1156 | I20: 953 | J20: 2767 | K20: 2482 | L20: 11385 | M20: =+L20 -> 11385 | N20: 10802 | O20: 10219 | P20: 9450 | Q20: 8946 | R20: =+Q20 -> 8946 | S20: 8460 | T20: 8294 | U20: 17208 | V20: 16640 | W20: =+V20 -> 16640 | X20: 16316 | Y20: 16002 | Z20: 16023 | AA20: 23955 | AB20: =+AA20 -> 23955 | AC20: 23979 | AD20: 29726 | AE20: 29183 | AF20: =28561 -> 28561 | AG20: =+AF20 -> 28561 | AH20: 27867 | AI20: 47706 | AJ20: =45942 -> 45942 | AK20: =44296 -> 44296 | AL20: =+AK20 -> 44296 | AM20: =52708 -> 52708 | AN20: =54179 -> 54179 | AO20: =115746 -> 115746 | AP20: =111591 -> 111591 | AQ20: =+AP20 -> 111591 | AR20: =108246 -> 108246 | AS20: =105785 -> 105785 | AT20: =103660 -> 103660 | AU20: =101269 -> 101269 | AV20: =+AU20 -> 101269 | AW20: =111432 -> 111432 | AX20: =104698 -> 104698 | AY20: =99993 -> 99993 | AZ20: =94546 -> 94546 | BA20: =+AZ20 -> 94546 | BB20: =88844 -> 88844 | BC20: =84019 -> 84019 | BD20: =90748 -> 90748 | BE20: =85719 -> 85719 | BF20: =+BE20 -> 85719 | BG20: =79763 -> 79763 | BH20: =74981 -> 74981 | BI20: =69877 -> 69877 | BJ20: =65105 -> 65105 | BK20: =+BJ20 -> 65105 | BL20: =+BL98 -> 57292.4 | BM20: =+BM98 -> 50417.312 | BN20: =+BN98 -> 44367.235 | BO20: =+BO98 -> 39043.166 | BP20: =+BO20 -> 39043.166 | BQ20: =+BQ98 -> 34357.986 | BR20: =+BR98 -> 30235.028 | BS20: =+BS98 -> 26606.825 | BT20: =+BT98 -> 23414.006 | BU20: =+BT20 -> 23414.006
B21: Other Assets | G21: 179 | H21: 179 | I21: 180 | J21: 682 | K21: 735 | L21: 214 | M21: =+L21 -> 214 | N21: 481 | O21: 598 | P21: 760 | Q21: 764 | R21: =+Q21 -> 764 | S21: 720 | T21: 630 | U21: 640 | V21: 1363 | W21: =+V21 -> 1363 | X21: 1552 | Y21: 1395 | Z21: 906 | AA21: 1168 | AB21: =+AA21 -> 1168 | AC21: =1238 -> 1238 | AD21: =5192 -> 5192 | AE21: 5466 | AF21: =5136 -> 5136 | AG21: =+AF21 -> 5136 | AH21: 5518 | AI21: 5304 | AJ21: =4931 -> 4931 | AK21: =8271 -> 8271 | AL21: =+AK21 -> 8271 | AM21: =11370 -> 11370 | AN21: =9450 -> 9450 | AO21: =10820 -> 10820 | AP21: =11191 -> 11191 | AQ21: =+AP21 -> 11191 | AR21: =13000 -> 13000 | AS21: =23452 -> 23452 | AT21: =18132 -> 18132 | AU21: =16626 -> 16626 | AV21: =+AU21 -> 16626 | AW21: =14824 -> 14824 | AX21: =12974 -> 12974 | AY21: =9174 -> 9174 | AZ21: =12894 -> 12894 | BA21: =+AZ21 -> 12894 | BB21: =19368 -> 19368 | BC21: =20176 -> 20176 | BD21: =18530 -> 18530 | BE21: =12868 -> 12868 | BF21: =+BE21 -> 12868 | BG21: =10092 -> 10092 | BH21: =15955 -> 15955 | BI21: =15208 -> 15208 | BJ21: =20232 -> 20232 | BK21: =+BJ21 -> 20232 | BL21: =+BJ21 -> 20232 | BM21: =+BL21 -> 20232 | BN21: =+BM21 -> 20232 | BO21: =+BN21 -> 20232 | BP21: =+BO21 -> 20232 | BQ21: =+BO21 -> 20232 | BR21: =+BQ21 -> 20232 | BS21: =+BR21 -> 20232 | BT21: =+BS21 -> 20232 | BU21: =+BT21 -> 20232
D22: ______ | E22: ______ | F22: ______ | G22: ______ | H22: ______ | I22: ______ | J22: ______ | K22: ______ | L22: ______ | M22: ______ | N22: ______ | O22: ______ | P22: ______ | Q22: ______ | R22: ______ | S22: ______ | T22: ______ | U22: ______ | V22: ______ | W22: ______ | X22: ______ | Y22: ______ | Z22: ______ | AA22: ______ | AB22: ______ | AC22: ______ | AD22: ______ | AE22: ______ | AF22: ______ | AG22: ______ | AH22: ______ | AI22: ______ | AJ22: ______ | AK22: ______ | AL22: ______ | AM22: ______ | AN22: ______ | AO22: ______ | AP22: ______ | AQ22: ______ | AR22: ______ | AS22: ______ | AT22: ______ | AU22: ______ | AV22: ______ | AW22: ______ | AX22: ______ | AY22: ______ | AZ22: ______ | BA22: ______ | BB22: ______ | BC22: ______ | BD22: ______ | BE22: ______ | BF22: ______ | BG22: ______ | BH22: ______ | BI22: ______ | BJ22: ______ | BK22: ______ | BL22: ______ | BM22: ______ | BN22: ______ | BO22: ______ | BP22: ______ | BQ22: ______ | BR22: ______ | BS22: ______ | BT22: ______ | BU22: ______
B23: Total Assets | D23: =SUM(D15:D21)+D13-#REF!-#REF! -> #REF! | E23: =SUM(E15:E21)+E13-#REF!-#REF! -> #REF! | F23: =SUM(F15:F21)+F13-#REF!-#REF! -> #REF! | G23: =SUM(G15:G21)+G13-#REF!-#REF! -> #REF! | H23: =SUM(H15:H21)+H13-#REF!-#REF! -> #REF! | I23: =SUM(I15:I21)+I13-#REF!-#REF! -> #REF! | J23: =SUM(J15:J21)+J13-#REF!-#REF! -> #REF! | K23: =SUM(K15:K21)+K13-#REF!-#REF! -> #REF! | L23: =SUM(L15:L21)+L13-#REF!-#REF! -> #REF! | M23: =SUM(M15:M21)+M13 -> 230561 | N23: =SUM(N15:N21)+N13 -> 213780 | O23: =SUM(O15:O21)+O13 -> 223852 | P23: =SUM(P15:P21)+P13 -> 226035 | Q23: =SUM(Q15:Q21)+Q13 -> 243303 | R23: =SUM(R15:R21)+R13 -> 243303 | S23: =SUM(S15:S21)+S13 -> 229771 | T23: =SUM(T15:T21)+T13 -> 241853 | ... AU23: =SUM(AU15:AU21)+AU13 -> 1358991 | AV23: =SUM(AV13:AV22) -> 1358991 | AW23: =SUM(AW13:AW22) -> 1329459 | AX23: =SUM(AX13:AX22) -> 1355659 | AY23: =SUM(AY13:AY22) -> 1399300 | AZ23: =SUM(AZ13:AZ22) -> 1505348 | BA23: =SUM(BA13:BA22) -> 1505348 | BB23: =SUM(BB13:BB22) -> 1488473 | BC23: =SUM(BC13:BC22) -> 1526593 | ... BU23: =SUM(BU13:BU22) -> 1960639.5
B25: Liabilities and Stock Holders' Equity
B27: Current Liabilities
B28: Accounts Payable | G28: 3536 | H28: 3536 | I28: 2892 | J28: 2990 | K28: 2868 | L28: 2038 | M28: =+L28 -> 2038 | N28: 1657 | O28: 4200 | P28: 2675 | Q28: 4012 | R28: =+Q28 -> 4012 | S28: 3495 | T28: 2257 | U28: 3567 | V28: 2240 | W28: =+V28 -> 2240 | X28: 5669 | Y28: 4612 | Z28: 2766 | AA28: 7048 | AB28: =+AA28 -> 7048 | AC28: 6297 | AD28: 12975 | AE28: 6549 | AF28: =6836 -> 6836 | AG28: =+AF28 -> 6836 | AH28: 10062 | AI28: 7078 | AJ28: =9033 -> 9033 | AK28: =3860 -> 3860 | AL28: =+AK28 -> 3860 | AM28: =4296 -> 4296 | AN28: =2063+44730 -> 46793 | AO28: =7514+44804 -> 52318 | AP28: =3521 -> 3521 | AQ28: =+AP28 -> 3521 | AR28: =12163 -> 12163 | AS28: =6832 -> 6832 | AT28: =13864 -> 13864 | AU28: =10255 -> 10255 | AV28: =+AU28 -> 10255 | AW28: =8475 -> 8475 | AX28: =8989 -> 8989 | AY28: =8951 -> 8951 | AZ28: =15812 -> 15812 | BA28: =+AZ28 -> 15812 | BB28: =11516 -> 11516 | BC28: =12820 -> 12820 | BD28: =6005 -> 6005 | BE28: =18908 -> 18908 | BF28: =+BE28 -> 18908 | BG28: =12318 -> 12318 | BH28: =15943 -> 15943 | BI28: =15571 -> 15571 | BJ28: =11041 -> 11041 | BK28: =+BJ28 -> 11041 | BL28: =+BL63*BL104/90 -> 12555.274 | BM28: =+BM63*BM104/90 -> 16930.954 | BN28: =+BN63*BN104/90 -> 15597.351 | BO28: =+BO63*BO104/90 -> 14755.652 | BP28: =+BO28 -> 14755.652 | BQ28: =+BQ63*BQ104/90 -> 12317.348 | BR28: =+BR63*BR104/90 -> 11747.807 | BS28: =+BS63*BS104/90 -> 15851.806 | BT28: =+BT63*BT104/90 -> 14235.823 | BU28: =+BT28 -> 14235.823
B29: Accrued Expenses and Other Current Liabilities | G29: 11907 | H29: 11907 | I29: 7956 | J29: 12765 | K29: 15725 | L29: 24707 | M29: =+L29 -> 24707 | N29: 14424 | O29: 19798 | P29: 22226 | Q29: 23499 | R29: =+Q29 -> 23499 | S29: 16346 | T29: 20667 | U29: 23737 | V29: 29728 | W29: =+V29 -> 29728 | X29: 18372 | Y29: 21832 | Z29: 27392 | AA29: 37376 | AB29: =+AA29 -> 37376 | AC29: 25062 | AD29: 33069 | AE29: 33174 | AF29: =41021 -> 41021 | AG29: =+AF29 -> 41021 | AH29: 26486 | AI29: 36165 | AJ29: =48035 -> 48035 | AK29: =61677 -> 61677 | AL29: =+AK29 -> 61677 | AM29: =47806 -> 47806 | AN29: =55633 -> 55633 | AO29: =57975 -> 57975 | AP29: =82620 -> 82620 | AQ29: =+AP29 -> 82620 | AR29: =56502 -> 56502 | AS29: =66348 -> 66348 | AT29: =64427 -> 64427 | AU29: =80306 -> 80306 | AV29: =+AU29 -> 80306 | AW29: =57545 -> 57545 | AX29: =69456 -> 69456 | AY29: =63388 -> 63388 | AZ29: =84489 -> 84489 | BA29: =+AZ29 -> 84489 | BB29: =60605 -> 60605 | BC29: =67242 -> 67242 | BD29: =82319 -> 82319 | BE29: =88802 -> 88802 | BF29: =+BE29 -> 88802 | BG29: =69458 -> 69458 | BH29: =78125 -> 78125 | BI29: =80539 -> 80539 | BJ29: =96998 -> 96998 | BK29: =+BJ29 -> 96998 | BL29: =+(BL63+BL64)*BL107 -> 69466.637 | BM29: =+(BM63+BM64)*BM107 -> 72272.403 | BN29: =+(BN63+BN64)*BN107 -> 80439.915 | BO29: =+(BO63+BO64)*BO107 -> 89819.118 | BP29: =+BO29 -> 89819.118 | BQ29: =+(BQ63+BQ64)*BQ107 -> 67707.838 | BR29: =+(BR63+BR64)*BR107 -> 73550.732 | BS29: =+(BS63+BS64)*BS107 -> 82832.797 | BT29: =+(BT63+BT64)*BT107 -> 103780 | BU29: =+BT29 -> 103780
B30: Convertible Senior Notes | AV30: =+AU30 -> 0 | BA30: =+AZ30 -> 0 | BB30: =0 -> 0 | BC30: =45737 -> 45737 | BD30: =45816 -> 45816 | BE30: =45895 -> 45895 | BF30: =+BE30 -> 45895 | BG30: =45967 -> 45967 | BH30: 0 | BI30: =0 -> 0 | BJ30: 0 | BK30: =+BJ30 -> 0 | BP30: =+BO30 -> 0 | BU30: =+BT30 -> 0
B31: Operating Lease Liabilities, Current | M31: =+L31 -> 0 | R31: =+Q31 -> 0 | W31: =+V31 -> 0 | AB31: =+AA31 -> 0 | AC31: 5231 | AD31: =6057 -> 6057 | AE31: 6460 | AF31: =7179 -> 7179 | AG31: =+AF31 -> 7179 | AH31: 8866 | AI31: 9436 | AJ31: =9568 -> 9568 | AK31: =9612 -> 9612 | AL31: =+AK31 -> 9612 | AM31: =9261 -> 9261 | AN31: =9285 -> 9285 | AO31: =9395 -> 9395 | AP31: =9630 -> 9630 | AQ31: =+AP31 -> 9630 | AR31: =11336 -> 11336 | AS31: =11809 -> 11809 | AT31: =11858 -> 11858 | AU31: =12444 -> 12444 | AV31: =+AU31 -> 12444 | AW31: =12853 -> 12853 | AX31: =12116 -> 12116 | AY31: =12472 -> 12472 | AZ31: =13452 -> 13452 | BA31: =+AZ31 -> 13452 | BB31: =14257 -> 14257 | BC31: =15592 -> 15592 | BD31: =15849 -> 15849 | BE31: =15493 -> 15493 | BF31: =+BE31 -> 15493 | BG31: =13614 -> 13614 | BH31: =15185 -> 15185 | BI31: =15955 -> 15955 | BJ31: =16176 -> 16176 | BK31: =+BJ31 -> 16176 | BL31: =+BK31 -> 16176 | BM31: =+BL31 -> 16176 | BN31: =+BM31 -> 16176 | BO31: =+BN31 -> 16176 | BP31: =+BO31 -> 16176 | BQ31: =+BP31 -> 16176 | BR31: =+BQ31 -> 16176 | ... BU31: =+BT31 -> 16176
B32: Deferred Revenue | G32: 58164 | H32: 58164 | I32: 60539 | J32: 66040 | K32: 74347 | L32: 87917 | M32: =+L32 -> 87917 | N32: 90081 | O32: 99360 | P32: 104663 | Q32: 116903 | R32: =+Q32 -> 116903 | S32: 116564 | T32: 126085 | U32: 133117 | V32: 142020 | W32: =+V32 -> 142020 | X32: 140448 | Y32: 153634 | Z32: 159408 | AA32: 189855 | AB32: =+AA32 -> 189855 | AC32: 184453 | AD32: 199048 | AE32: 200314 | AF32: =231518 -> 231518 | AG32: =+AF32 -> 231518 | AH32: 219432 | AI32: 227318 | AJ32: =231560 -> 231560 | AK32: =278585 -> 278585 | AL32: =+AK32 -> 278585 | AM32: =282245 -> 282245 | AN32: =302186 -> 302186 | AO32: =316045 -> 316045 | AP32: =372067 -> 372067 | AQ32: =+AP32 -> 372067 | AR32: =378338 -> 378338 | AS32: =395208 -> 395208 | AT32: =391761 -> 391761 | AU32: =426599 -> 426599 | AV32: =+AU32 -> 426599 | AW32: =413992 -> 413992 | AX32: =429328 -> 429328 | AY32: =421898 -> 421898 | AZ32: =455503 -> 455503 | BA32: =+AZ32 -> 455503 | BB32: =437687 -> 437687 | BC32: =437222 -> 437222 | BD32: =423640 -> 423640 | BE32: =461118 -> 461118 | BF32: =+BE32 -> 461118 | BG32: =447798 -> 447798 | BH32: =446688 -> 446688 | BI32: =422943 -> 422943 | BJ32: =451155 -> 451155 | BK32: =+BJ32 -> 451155 | BL32: =+BG32*(1+BL112) -> 447798 | BM32: =+BH32*(1+BM112) -> 451154.88 | BN32: =+BI32*(1+BN112) -> 427172.43 | BO32: =+BJ32*(1+BO112) -> 460178.1 | BP32: =+BO32 -> 460178.1 | BQ32: =+BL32*(1+BQ112) -> 456753.96 | BR32: =+BM32*(1+BR112) -> 460177.98 | BS32: =+BN32*(1+BS112) -> 435715.88 | BT32: =+BO32*(1+BT112) -> 469381.66 | BU32: =+BT32 -> 469381.66
B33: Term Loan Payable, net of Unamortized Debt Discount | G33: 0 | H33: 0 | I33: 1703 | J33: 3976 | K33: 0 | L33: 0 | M33: =+L33 -> 0 | N33: 0 | O33: 0 | P33: 0 | Q33: 0 | R33: =+Q33 -> 0 | S33: 0 | T33: 0 | U33: =+T33 -> 0 | V33: 0 | W33: =+V33 -> 0 | X33: 0 | Y33: 0 | Z33: 0 | AA33: 0 | AB33: =+AA33 -> 0 | AC33: 0 | AD33: =+AC33 -> 0 | AE33: 0 | AF33: =+AE33 -> 0 | AG33: =+AF33 -> 0 | AH33: =+AF33 -> 0 | AI33: =+AH33 -> 0 | AJ33: =+AI33 -> 0 | AK33: =+AJ33 -> 0 | AL33: =+AK33 -> 0 | AM33: =+AK33 -> 0 | AP33: 0 | AQ33: =+AP33 -> 0 | AV33: =+AU33 -> 0 | BA33: =+AZ33 -> 0 | BF33: =+BE33 -> 0 | BI33: =+BH33 -> 0 | BK33: =+BJ33 -> 0 | BL33: =+BJ33 -> 0 | BM33: =+BL33 -> 0 | BN33: =+BM33 -> 0 | BO33: =+BN33 -> 0 | BP33: =+BO33 -> 0 | BQ33: =+BO33 -> 0 | BR33: =+BQ33 -> 0 | BS33: =+BR33 -> 0 | BT33: =+BS33 -> 0 | BU33: =+BT33 -> 0
B34: Contingent Consideration | G34: 0 | H34: 0 | I34: 0 | J34: 0 | K34: 0 | L34: 0 | M34: =+L34 -> 0 | N34: 0 | O34: 0 | P34: 0 | Q34: 0 | R34: =+Q34 -> 0 | S34: 0 | T34: 0 | U34: =+T34 -> 0 | V34: 0 | W34: =+V34 -> 0 | X34: 0 | Y34: 0 | Z34: 0 | AA34: 0 | AB34: =+AA34 -> 0 | AC34: 0 | AD34: =+AC34 -> 0 | AE34: 0 | AF34: =+AE34 -> 0 | AG34: =+AF34 -> 0 | AH34: =+AF34 -> 0 | AI34: =+AH34 -> 0 | AJ34: =+AI34 -> 0 | AK34: =+AJ34 -> 0 | AL34: =+AK34 -> 0 | AM34: =+AK34 -> 0 | AP34: 0 | AQ34: =+AP34 -> 0 | AV34: =+AU34 -> 0 | BA34: =+AZ34 -> 0 | BF34: =+BE34 -> 0 | BI34: =+BH34 -> 0 | BK34: =+BJ34 -> 0 | BL34: =+BJ34 -> 0 | BM34: =+BL34 -> 0 | BN34: =+BM34 -> 0 | BO34: =+BN34 -> 0 | BP34: =+BO34 -> 0 | BQ34: =+BO34 -> 0 | BR34: =+BQ34 -> 0 | BS34: =+BR34 -> 0 | BT34: =+BS34 -> 0 | BU34: =+BT34 -> 0
B35: Other Current Liabilities | G35: 642 | H35: 642 | I35: 887 | J35: 991 | K35: 1030 | L35: 1105 | M35: =+L35 -> 1105 | N35: 767 | O35: 1047 | P35: 1352 | Q35: 1195 | R35: =+Q35 -> 1195 | S35: 1239 | T35: 1334 | U35: 1394 | V35: 1706 | W35: =+V35 -> 1706 | X35: 1702 | Y35: 1079 | Z35: 838 | AA35: 707 | AB35: =+AA35 -> 707 | AC35: =7385 -> 7385 | AD35: 126 | AE35: 285 | AF35: =119 -> 119 | AG35: =+AF35 -> 119 | AH35: 35 | AI35: 0 | AJ35: =85 -> 85 | AK35: =0 -> 0 | AL35: =+AK35 -> 0 | AM35: =127 -> 127 | AN35: =303 -> 303 | AO35: =809 -> 809 | AP35: =842 -> 842 | AQ35: =+AP35 -> 842 | AR35: =1264 -> 1264 | AS35: =3473 -> 3473 | AT35: =5254 -> 5254 | AU35: =1663 -> 1663 | AV35: =+AU35 -> 1663 | AW35: =809 -> 809 | AX35: =562 -> 562 | AY35: =888 -> 888 | AZ35: =536 -> 536 | BA35: =+AZ35 -> 536 | BB35: 0 | BC35: =0 -> 0 | BD35: =0 -> 0 | BE35: =0 -> 0 | BF35: =+BE35 -> 0 | BG35: =0 -> 0 | BH35: =0 -> 0 | BI35: =0 -> 0 | BK35: =+BJ35 -> 0 | BL35: =+BJ35 -> 0 | BM35: =+BL35 -> 0 | BN35: =+BM35 -> 0 | BO35: =+BN35 -> 0 | BP35: =+BO35 -> 0 | BQ35: =+BO35 -> 0 | BR35: =+BQ35 -> 0 | BS35: =+BR35 -> 0 | BT35: =+BS35 -> 0 | BU35: =+BT35 -> 0
D36: ______ | E36: ______ | F36: ______ | G36: ______ | H36: ______ | I36: ______ | J36: ______ | K36: ______ | L36: ______ | M36: ______ | N36: ______ | O36: ______ | P36: ______ | Q36: ______ | R36: ______ | S36: ______ | T36: ______ | U36: ______ | V36: ______ | W36: ______ | X36: ______ | Y36: ______ | Z36: ______ | AA36: ______ | AB36: ______ | AC36: ______ | AD36: ______ | AE36: ______ | AF36: ______ | AG36: ______ | AH36: ______ | AI36: ______ | AJ36: ______ | AK36: ______ | AL36: ______ | AM36: ______ | AN36: ______ | AO36: ______ | AP36: ______ | AQ36: ______ | AR36: ______ | AS36: ______ | AT36: ______ | AU36: ______ | AV36: ______ | AW36: ______ | AX36: ______ | AY36: ______ | AZ36: ______ | BA36: ______ | BB36: ______ | BC36: ______ | BD36: ______ | BE36: ______ | BF36: ______ | BG36: ______ | BH36: ______ | BI36: ______ | BJ36: ______ | BK36: ______ | BL36: ______ | BM36: ______ | BN36: ______ | BO36: ______ | BP36: ______ | BQ36: ______ | BR36: ______ | BS36: ______ | BT36: ______ | BU36: ______
B37: Total Current Liabilities | D37: =SUM(D28:D35)-#REF! -> #REF! | E37: =SUM(E28:E35)-#REF! -> #REF! | F37: =SUM(F28:F35)-#REF! -> #REF! | G37: =SUM(G28:G35)-#REF! -> #REF! | H37: =SUM(H28:H35)-#REF! -> #REF! | I37: =SUM(I28:I35)-#REF! -> #REF! | J37: =SUM(J28:J35)-#REF! -> #REF! | K37: =SUM(K28:K35)-#REF! -> #REF! | L37: =SUM(L28:L35)-#REF! -> #REF! | M37: =SUM(M28:M35) -> 115767 | N37: =SUM(N28:N35) -> 106929 | O37: =SUM(O28:O35) -> 124405 | P37: =SUM(P28:P35) -> 130916 | Q37: =SUM(Q28:Q35) -> 145609 | R37: =SUM(R28:R35) -> 145609 | S37: =SUM(S28:S35) -> 137644 | T37: =SUM(T28:T35) -> 150343 | ... BU37: =SUM(BU28:BU35) -> 603573.49
