Workbook
Name \M: [1]VALUE2_1.XLS!#REF!
Name _: #REF!
Name __: #REF!
Name ___: #REF!
Name ____: #REF!
Name ____________Z04: #REF!
Name ____________Z05: #REF!
Name ___________Inv1: #REF!
Name ___________TOP10: #REF!
Name _________Inv1: #REF!
Name _________TOP10: #REF!
Name _______Inv1: #REF!
Name _______TOP10: #REF!
Name ______Inv1: #REF!
Name ______TOP10: #REF!
Name ______Z04: #REF!
Name ______Z05: #REF!
Name _____Inv1: #REF!
Name _____TOP10: #REF!
Name _____Z04: #REF!
Name _____Z05: #REF!
Name ____cat2: #REF!
Name ____Inv1: #REF!
Name ____TOP10: #REF!
Name ____USD03: #REF!
Name ____Z04: #REF!
Name ____Z05: #REF!
Name ___cat2: #REF!
Name ___Inv1: #REF!
Name ___nm1: #REF!
Name ___SEC2: #REF!
Name ___SEC4: #REF!
Name ___SEC5: #REF!
Name ___TOP10: #REF!
Name ___USD03: #REF!
Name ___www2: #REF!
Name ___Z04: #REF!
Name ___Z05: #REF!
Name __1__123Graph_ACHART_3: #REF!
Name __123Graph_A: #REF!
Name __123Graph_AChart1: #REF!
Name __123Graph_AChart2: #REF!
Name __123Graph_AChart3: #REF!
Name __123Graph_AChart4: #REF!
Name __123Graph_AChart5: #REF!
Name __123Graph_AChart6: #REF!
Name __123Graph_AChart7: #REF!
Name __123Graph_ACurrent: #REF!
Name __123Graph_B: #REF!
Name __123Graph_BChart1: #REF!
Name __123Graph_BChart2: #REF!
Name __123Graph_BChart3: #REF!
Name __123Graph_BChart4: #REF!
Name __123Graph_BChart5: #REF!
Name __123Graph_BChart6: #REF!
Name __123Graph_BChart7: #REF!
Name __123Graph_BCurrent: #REF!
Name __123Graph_C: #REF!
Name __123Graph_CChart1: #REF!
Name __123Graph_CChart2: #REF!

Sheet __FDSCACHE__
B1: This sheet contains FactSet XML data for use with this workbook's =FDS codes. Modifying the worksheet's contents may damage the workbook's =FDS functionality.

Sheet Income Statement
C2: Mar | D2: Jun | E2: Sep | F2: Dec | H2: Mar | I2: Jun | J2: Sep | K2: Dec | M2: Mar | N2: Jun | O2: Sep | P2: Dec | R2: Mar | S2: Jun | T2: Sep | U2: Dec | W2: Mar | X2: Jun | Y2: Sep | Z2: Dec | AB2: Mar | AC2: Jun | AD2: Sep | AE2: Dec | AG2: Mar | AH2: Jun | AI2: Sep | AJ2: Dec | AL2: Mar | AM2: Jun | AN2: Sep | AO2: Dec | AQ2: Mar | AR2: Jun | AS2: Sep | AT2: Dec | AV2: Mar | AW2: Jun | AX2: Sep | AY2: Dec | BA2: Mar | BB2: Jun | BC2: Sep | BD2: Dec
B3: (Amounts in millions, except per share data) | C3: 1Q16 | D3: 2Q16 | E3: 3Q16 | F3: 4Q16 | G3: 2016 | H3: 1Q17 | I3: 2Q17 | J3: 3Q17 | K3: 4Q17 | L3: 2017 | M3: 1Q18 | N3: 2Q18 | O3: 3Q18 | P3: 4Q18 | Q3: 2018 | R3: 1Q19 | S3: 2Q19 | T3: 3Q19 | U3: 4Q19 | V3: 2019 | W3: 1Q20 | X3: 2Q20 | Y3: 3Q20 | Z3: 4Q20 | AA3: 2020 | AB3: 1Q21 | AC3: 2Q21 | AD3: 3Q21 | AE3: 4Q21 | AF3: 2021 | AG3: 1Q22 | AH3: 2Q22 | AI3: 3Q22 | AJ3: 4Q22 | AK3: 2022 | AL3: 1Q23 | AM3: 2Q23 | AN3: 3Q23 | AO3: 4Q23 | AP3: 2023 | AQ3: 1Q24 | AR3: 2Q24 | AS3: 3Q24 | AT3: 4Q24 | AU3: 2024 | AV3: 1Q25 | AW3: 2Q25 | AX3: 3Q25 | AY3: 4Q25 | AZ3: 2025 | BA3: 1Q26E | BB3: 2Q26E | BC3: 3Q26E | BD3: 4Q26E | BE3: 2026E | BF3: 2027E | BG3: 2028E | BH3: 2029E | BI3: 2030E | BJ3: 2031E
B4: Bookings | C4: =+C5+C13 -> 75.698 | D4: =+D5+D13 -> 81.453 | E4: =+E5+E13 -> 87.269 | F4: =+F5+F13 -> 97.656 | G4: =SUM(G5:G13) -> 342.076 | H4: =+H5+H13 -> 114.548 | I4: =+I5+I13 -> 117.119 | J4: =+J5+J13 -> 120.118 | K4: =+K5+K13 -> 132.198 | L4: =SUM(L5:L13) -> 483.983 | M4: =M136+M157 -> 159.655 | N4: =N136+N157 -> 159.895 | O4: =O136+O157 -> 162.777 | P4: =P136+P157 -> 176.058 | Q4: =SUM(Q5:Q13) -> 658.385 | R4: =R136+R157 -> 200.379 | S4: =S136+S157 -> 199.563 | T4: =T136+T157 -> 205.86 | U4: =U136+U157 -> 226.683 | V4: =SUM(V5:V13) -> 832.485 | W4: =W136+W157 -> 248.858 | X4: =X136+X157 -> 265.851 | Y4: =Y136+Y157 -> 280.941 | Z4: =Z136+Z157 -> 306.381 | AA4: =SUM(AA5:AA13) -> 1102.031 | AB4: =AB136+AB157 -> 351.109 | AC4: =AC136+AC157 -> 342.861 | AD4: =AD136+AD157 -> 373.297 | AE4: =AE136+AE157 -> 351.556 | AF4: =SUM(AF5:AF13) -> 1418.823 | AG4: =AG136+AG157 -> 393.248 | AH4: =AH136+AH157 -> 354.594 | AI4: =AI136+AI157 -> 352.464 | AJ4: =AJ136+AJ157 -> 371.813 | AK4: =SUM(AK5:AK13) -> 1472.119 | AL4: =AL136+AL157 -> 414.905 | AM4: =AM136+AM157 -> 398.496 | AN4: =AN136+AN157 -> 389.095 | AO4: =AO136+AO157 -> 395.004 | AP4: =AP136+AP157 -> 1597.5 | AQ4: =AQ136+AQ157 -> 457.281 | AR4: =AR136+AR157 -> 458.399 | AS4: =AS136+AS157 -> 452.486 | ... BJ4: =BJ136+BJ157 -> 3477.4955
B5: Change in deferred revenue | C5: 14.108 | D5: 12.723 | E5: 11.659 | F5: 13.476 | G5: =SUM(C5:F5) -> 51.966 | H5: 22.008 | I5: 13.599 | J5: 9.088 | K5: 13.658 | L5: =SUM(H5:K5) -> 58.353 | M5: =M4-M13 -> 21.88 | N5: =N4-N13 -> 13.763 | O5: =O4-O13 -> 7.177 | P5: =P4-P13 -> 11.861 | Q5: =SUM(M5:P5) -> 54.681 | R5: =R4-R13 -> 26.089 | S5: =S4-S13 -> 14.144 | T5: =T4-T13 -> 9.069 | U5: =U4-U13 -> 22.095 | V5: =SUM(R5:U5) -> 71.397 | W5: =W4-W13 -> 32.871 | X5: =X4-X13 -> 29.792 | Y5: =Y4-Y13 -> 26.761 | Z5: =Z4-Z13 -> 23.847 | AA5: =SUM(W5:Z5) -> 113.271 | AB5: =AB4-AB13 -> 46.997 | AC5: =AC4-AC13 -> 26.455 | AD5: =AD4-AD13 -> 52.5 | AE5: =AE4-AE13 -> 23.214 | AF5: =SUM(AB5:AE5) -> 149.166 | AG5: =AG4-AG13 -> 51.651 | AH5: =AH4-AH13 -> 9.37 | AI5: =AI4-AI13 -> 6.659 | AJ5: =AJ4-AJ13 -> 16.773 | AK5: =SUM(AG5:AJ5) -> 84.453 | AL5: =AL4-AL13 -> 40.829 | AM5: =AM4-AM13 -> 8.519 | AN5: =AN4-AN13 -> -4.746 | AO5: =AO4-AO13 -> -8.767 | AP5: =AP4-AP13 -> 35.835 | AQ5: =AQ4-AQ13 -> 37.505 | AR5: =AR4-AR13 -> 22.653 | AS5: =AS4-AS13 -> 7.813 | ... BJ5: =BJ4-BJ13 -> 86.177594
B7: Guide
B8: High | AU8: 1832 | AZ8: 2078
B9: Midpoint | AU9: =+AVERAGE(AU8,AU10) -> 1827 | AZ9: =+AVERAGE(AZ8,AZ10) -> 2069
B10: Low | AU10: 1822 | AZ10: 2060
B11: Needham vs Midpoint | AU11: =+AU4/AU9-1 -> 0.0031559934 | AZ11: =+AZ4/AZ9-1 -> -0.0021899468
B13: Revenue | C13: =SUM(C14:C15) -> 61.59 | D13: =SUM(D14:D15) -> 68.73 | E13: =SUM(E14:E15) -> 75.61 | F13: =SUM(F14:F15) -> 84.18 | G13: =SUM(G14:G15) -> 290.11 | H13: =SUM(H14:H15) -> 92.54 | I13: =SUM(I14:I15) -> 103.52 | J13: =SUM(J14:J15) -> 111.03 | ... BJ13: =SUM(BJ14:BJ15) -> 3391.3179
B14: Creative Subscriptions | C14: 61.59 | D14: 68.73 | E14: 75.61 | F14: 84.18 | G14: =SUM(C14:F14) -> 290.11 | H14: 92.54 | I14: 103.52 | J14: 111.03 | K14: 118.54 | L14: =SUM(H14:K14) -> 425.63 | M14: 120.434 | N14: 126.716 | O14: 134.579 | P14: 143.621 | Q14: =SUM(M14:P14) -> 525.35 | R14: 151.364 | S14: 157.012 | T14: 164.761 | U14: 171.355 | V14: =SUM(R14:U14) -> 644.492 | W14: 176.546 | X14: 190.169 | Y14: 202.996 | Z14: 213.745 | AA14: =SUM(W14:Z14) -> 783.456 | AB14: 226.436 | AC14: 235.891 | AD14: 241.303 | AE14: 246.669 | AF14: =SUM(AB14:AE14) -> 950.299 | AG14: 254.968 | AH14: 258.177 | AI14: 261.066 | AJ14: 265.268 | AK14: =SUM(AG14:AJ14) -> 1039.479 | AL14: 278.13 | AM14: 287.089 | AN14: 290.634 | AO14: 296.154 | AP14: =AP143 -> 1152.007 | AQ14: 304.293 | AR14: 312.125 | AS14: 318.825 | AT14: 329.732 | AU14: =AU143 -> 1264.975 | AV14: 337.676 | AW14: 345.456 | AX14: 356.174 | AY14: 370.421 | AZ14: =AZ143 -> 1409.727 | BA14: =BA143 -> 385.06825 | BB14: =BB143 -> 398.07197 | BC14: =BC143 -> 415.8902 | BD14: =BD143 -> 438.7287 | BE14: =BE143 -> 1637.7591 | BF14: =BF143 -> 1834.2902 | BG14: =BG143 -> 2010.3821 | ... BJ14: =BJ143 -> 2412.6726
B15: Business Solutions | M15: 17.341 | N15: 19.416 | O15: 21.021 | P15: 20.576 | Q15: =SUM(M15:P15) -> 78.354 | R15: 22.926 | S15: 28.407 | T15: 32.03 | U15: 33.233 | V15: =SUM(R15:U15) -> 116.596 | W15: 39.441 | X15: 45.89 | Y15: 51.184 | Z15: 68.789 | AA15: =SUM(W15:Z15) -> 205.304 | AB15: 77.676 | AC15: 80.515 | AD15: 79.494 | AE15: 81.673 | AF15: =SUM(AB15:AE15) -> 319.358 | AG15: 86.629 | AH15: 87.047 | AI15: 84.739 | AJ15: 89.772 | AK15: =SUM(AG15:AJ15) -> 348.187 | AL15: 95.946 | AM15: 102.888 | AN15: 103.207 | AO15: 107.617 | AP15: =AP164 -> 409.658 | AQ15: 115.483 | AR15: 123.621 | AS15: 125.848 | AT15: 130.723 | AU15: =AU164 -> 495.675 | AV15: 135.975 | AW15: 144.474 | AX15: 149.02 | AY15: 153.848 | AZ15: =AZ164 -> 583.317 | BA15: =BA164 -> 156.75407 | BB15: =BB164 -> 165.26937 | BC15: =BC164 -> 170.63025 | BD15: =BD164 -> 173.9681 | BE15: =BE164 -> 666.6218 | BF15: =BF164 -> 740.6983 | BG15: =BG164 -> 809.04966 | ... BJ15: =BJ164 -> 978.64523
B17: Guide | AV17: =AV13/AQ13-1 -> 0.12834226 | AW17: =AW18/AR13-1 -> 0.1222134 | AX17: =AX18/AS13-1 -> 0.13341714
B18: High | AG18: 343 | AH18: 346 | AI18: 345 | AJ18: 354 | AL18: 371 | AM18: 385 | AN18: 391 | AO18: 405 | AP18: 1558 | AQ18: 419 | AR18: 435 | AS18: 445 | AT18: 464 | AU18: 1764 | AV18: 473 | AW18: 489 | AX18: 504 | AY18: 531 | AZ18: 2000
B19: Midpoint | AG19: =AVERAGE(AG18,AG20) -> 340.5 | AH19: =AVERAGE(AH18,AH20) -> 344 | AI19: =AVERAGE(AI18,AI20) -> 343 | AJ19: =AVERAGE(AJ18,AJ20) -> 351.5 | AL19: =AVERAGE(AL18,AL20) -> 369 | AM19: =AVERAGE(AM18,AM20) -> 382.5 | AN19: =AVERAGE(AN18,AN20) -> 388.5 | AO19: =AVERAGE(AO18,AO20) -> 402.5 | AP19: =+AVERAGE(AP18,AP20) -> 1560.5 | AQ19: =AVERAGE(AQ18,AQ20) -> 417 | AR19: =AVERAGE(AR18,AR20) -> 433 | AS19: =AVERAGE(AS18,AS20) -> 442.5 | AT19: =AVERAGE(AT18,AT20) -> 460.5 | AU19: =+AVERAGE(AU18,AU20) -> 1760.5 | AV19: =+AVERAGE(AV18,AV20) -> 471 | AW19: =+AVERAGE(AW18,AW20) -> 487 | AX19: =+AVERAGE(AX18,AX20) -> 501 | AY19: =+AVERAGE(AY18,AY20) -> 526 | AZ19: =+AVERAGE(AZ18,AZ20) -> 1995 | BA19: mid teens | BE19: mid teens
B20: Low | AG20: 338 | AH20: 342 | AI20: 341 | AJ20: 349 | AL20: 367 | AM20: 380 | AN20: 386 | AO20: 400 | AP20: 1563 | AQ20: 415 | AR20: 431 | AS20: 440 | AT20: 457 | AU20: 1757 | AV20: 469 | AW20: 485 | AX20: 498 | AY20: 521 | AZ20: 1990 | BA20: =BA13/AV13-1 -> 0.14392733 | BE20: =BE13/AZ13-1 -> 0.15621176
B21: Needham vs Midpoint | AG21: =AG13/AG19-1 -> 0.0032217327 | AH21: =AH13/AH19-1 -> 0.0035581395 | AI21: =AI13/AI19-1 -> 0.0081778426 | AJ21: =AJ13/AJ19-1 -> 0.010071124 | AL21: =AL13/AL19-1 -> 0.013756098 | AM21: =AM13/AM19-1 -> 0.019547712 | AN21: =AN13/AN19-1 -> 0.013747748 | AO21: =AO13/AO19-1 -> 0.003157764 | AP21: =+AP13/AP19-1 -> 0.00074655559 | AQ21: =AQ13/AQ19-1 -> 0.0066570743 | AR21: =AR13/AR19-1 -> 0.0063418014 | AS21: =AS13/AS19-1 -> 0.0049107345 | AT21: =AT13/AT19-1 -> -9.771987e-05 | AU21: =+AU13/AU19-1 -> 8.5203067e-05 | AV21: =+AV13/AV19-1 -> 0.0056284501 | AW21: =+AW13/AW19-1 -> 0.0060164271 | AX21: =+AX13/AX19-1 -> 0.0083712575 | AY21: =+AY13/AY19-1 -> -0.0032908745 | AZ21: =+AZ13/AZ19-1 -> -0.00098045113
B23: Cost of revenue, non GAAP | C23: =10.51-0.428 -> 10.082 | D23: =11.02-0.475 -> 10.545 | E23: =11.02-0.466 -> 10.554 | F23: =12.74-0.429 -> 12.311 | G23: =SUM(C23:F23) -> 43.492 | H23: 14.329 | I23: 16.29 | J23: 17.287 | K23: 18.022 | L23: =SUM(H23:K23) -> 65.928 | M23: =29.044-1.079 -> 27.965 | N23: =30.437-1.087 -> 29.35 | O23: =32.977-1.102 -> 31.875 | P23: =34.489-1.15 -> 33.339 | Q23: =SUM(M23:P23) -> 122.529 | R23: =39.715-1.311 -> 38.404 | S23: =46.662-1.436 -> 45.226 | T23: =53.295-1.525 -> 51.77 | U23: =57.235-1.582 -> 55.653 | V23: =SUM(R23:U23) -> 191.053 | W23: =62.07-1.631 -> 60.439 | X23: =70.482-1.869 -> 68.613 | Y23: =79.84-2.455 -> 77.385 | Z23: =103.307-3.172 -> 100.135 | AA23: =SUM(W23:Z23) -> 306.572 | AB23: =115.832-3.501 -> 112.331 | AC23: =121.419-3.809 -> 117.61 | AD23: =122.529-4.057 -> 118.472 | AE23: =128.799-4.095 -> 124.704 | AF23: =SUM(AB23:AE23) -> 473.117 | AG23: =AG13-AG24 -> 129.676 | AH23: =AH13-AH24 -> 129.484 | AI23: =AI13-AI24 -> 122.68 | AJ23: =AJ13-AJ24 -> 123.468 | AK23: =SUM(AG23:AJ23) -> 505.308 | AL23: =AL13-AL24 -> 124.549 | AM23: =AM13-AM24 -> 123.565 | AN23: =AN13-AN24 -> 124.737 | AO23: =AO13-AO24 -> 121.766 | AP23: =SUM(AL23:AO23) -> 494.617 | AQ23: =AQ13-AQ24 -> 133.04 | AR23: =AR13-AR24 -> 137.49 | AS23: =AS13-AS24 -> 137.787 | AT23: =AT13-AT24 -> 139.503 | AU23: =SUM(AQ23:AT23) -> 547.82 | AV23: =AV13-AV24 -> 147.805 | AW23: =AW13-AW24 -> 149.037 | AX23: =AX13-AX24 -> 155.454 | AY23: =AY13-AY24 -> 165.517 | AZ23: =SUM(AV23:AY23) -> 617.813 | BA23: =BA152+BA182 -> 179.7069 | BB23: =BB152+BB182 -> 183.15036 | BC23: =BC152+BC182 -> 185.95404 | BD23: =BD152+BD182 -> 191.73185 | BE23: =SUM(BA23:BD23) -> 740.54315 | BF23: =BF152+BF182 -> 815.57666 | BG23: =BG152+BG182 -> 881.18877 | BH23: =BH152+BH182 -> 937.32941 | BI23: =BI152+BI182 -> 984.42171 | BJ23: =BJ152+BJ182 -> 1023.4782
B24: Gross profit, non GAAP | C24: =+C13-C23 -> 51.508 | D24: =+D13-D23 -> 58.185 | E24: =+E13-E23 -> 65.056 | F24: =+F13-F23 -> 71.869 | G24: =+G13-G23 -> 246.618 | H24: =+H13-H23 -> 78.211 | I24: =+I13-I23 -> 87.23 | J24: =+J13-J23 -> 93.743 | ... AF24: =+AF13-AF23 -> 796.54 | AG24: 211.921 | AH24: 215.74 | AI24: 223.125 | AJ24: 231.572 | AK24: =+AK13-AK23 -> 882.358 | AL24: 249.527 | AM24: 266.412 | AN24: 269.104 | AO24: 282.005 | AP24: =+AP13-AP23 -> 1067.048 | AQ24: 286.736 | AR24: 298.256 | AS24: 306.886 | AT24: 320.952 | AU24: =+AU13-AU23 -> 1212.83 | AV24: 325.846 | AW24: 340.893 | AX24: 349.74 | AY24: 358.752 | AZ24: =+AZ13-AZ23 -> 1375.231 | BA24: =+BA13-BA23 -> 362.11542 | BB24: =+BB13-BB23 -> 380.19099 | BC24: =+BC13-BC23 -> 400.56641 | BD24: =+BD13-BD23 -> 420.96495 | BE24: =+BE13-BE23 -> 1563.8378 | BF24: =+BF13-BF23 -> 1759.4118 | BG24: =+BG13-BG23 -> 1938.243 | ... BJ24: =+BJ13-BJ23 -> 2367.8396
B26: Sales & marketing, non GAAP | C26: =40.45-0.981-0.05 -> 39.419 | D26: =36.03-1.122-0.136 -> 34.772 | E26: =40.01-1.237-0.138 -> 38.635 | F26: =40.02-1.213-0.136 -> 38.671 | G26: =SUM(C26:F26) -> 151.497 | H26: 52.249 | I26: 46.176 | J26: 49.303 | K26: 47.313 | L26: =SUM(H26:K26) -> 195.041 | M26: =67.011-2.042 -> 64.969 | N26: =58.855-2.352 -> 56.503 | O26: =49.36-2.597 -> 46.763 | P26: =61.065-2.779 -> 58.286 | Q26: =SUM(M26:P26) -> 226.521 | R26: =85.718-4.748 -> 80.97 | S26: =71.329-4.506 -> 66.823 | T26: =75.862-4.59 -> 71.272 | U26: =74.809-4.614 -> 70.195 | V26: =SUM(R26:U26) -> 289.26 | W26: =96.156-4.568 -> 91.588 | X26: =119.333-5.395 -> 113.938 | Y26: =113.092-6.108 -> 106.984 | Z26: =109.629-6.774 -> 102.855 | AA26: =SUM(W26:Z26) -> 415.365 | AB26: =144.455-7.442 -> 137.013 | AC26: =123.021-24.49 -> 98.531 | AD26: =119.991-8.715 -> 111.276 | AE26: =124.56-28.028 -> 96.532 | AF26: =SUM(AB26:AE26) -> 443.352 | AG26: 146.027 | AH26: 109.94 | AI26: 107.367 | AJ26: 87.564 | AK26: =SUM(AG26:AJ26) -> 450.898 | AL26: 88.755 | AM26: 85.564 | AN26: 89.11 | AO26: 91.589 | AP26: =SUM(AL26:AO26) -> 355.018 | AQ26: 95.936 | AR26: 92.496 | AS26: 98.862 | AT26: 95.838 | AU26: =SUM(AQ26:AT26) -> 383.132 | AV26: 101.582 | AW26: 103.519 | AX26: 127.228 | AY26: 142.112 | AZ26: =SUM(AV26:AY26) -> 474.441 | BA26: =AV26+80 -> 181.582 | BB26: =AW26+80 -> 183.519 | BC26: =AX26+50 -> 177.228 | BD26: =AY26+30 -> 172.112 | BE26: =SUM(BA26:BD26) -> 714.441 | BF26: =BF13*BF99 -> 678.58823 | BG26: =BG13*BG99 -> 687.28101 | BH26: =BH13*BH99 -> 684.61424 | BI26: =BI13*BI99 -> 672.78344 | BJ26: =BJ13*BJ99 -> 654.28423 | BL26: =+AZ98 -> 0.49880033
B27: Research and development, non GAAP | C27: =24.472-3.111-1.183-0.137 -> 20.041 | D27: =25.48-3.558-0.397-0.05 -> 21.475 | E27: =26.54-3.718-0.514-0.05 -> 22.258 | F27: =28.88-4.156-0.614-0.05 -> 24.06 | G27: =SUM(C27:F27) -> 87.834 | H27: 26.094 | I27: 29.165 | J27: 32.037 | K27: 33.997 | L27: =SUM(H27:K27) -> 121.293 | M27: =46.502-8.485 -> 38.017 | N27: =48.492-9.47 -> 39.022 | O27: =62.247-10.372 -> 51.875 | P27: =54.558-11.09 -> 43.468 | Q27: =SUM(M27:P27) -> 172.382 | R27: =58.183-12.256 -> 45.927 | S27: =61.486-14.119 -> 47.367 | T27: =64.488-14.886 -> 49.602 | U27: =66.634-14.9 -> 51.734 | V27: =SUM(R27:U27) -> 194.63 | W27: =70.716-16.185 -> 54.531 | X27: =75.464-18.216 -> 57.248 | Y27: =84.473-20.312 -> 64.161 | Z27: =89.625-22.17 -> 67.455 | AA27: =SUM(W27:Z27) -> 243.395 | AB27: =95.086-23.288 -> 71.798 | AC27: =104.199-8.213 -> 95.986 | AD27: =109.323-26.25 -> 83.073 | AE27: =116.329-9.483 -> 106.846 | AF27: =SUM(AB27:AE27) -> 357.703 | AG27: 89.53 | AH27: 90.607 | AI27: 90.193 | AJ27: 87.003 | AK27: =SUM(AG27:AJ27) -> 357.333 | AL27: 86.477 | AM27: 86.656 | AN27: 94.684 | AO27: 93.757 | AP27: =SUM(AL27:AO27) -> 361.574 | AQ27: 93.138 | AR27: 88.474 | AS27: 92.335 | AT27: 94.866 | AU27: =SUM(AQ27:AT27) -> 368.813 | AV27: 96.006 | AW27: 98.389 | AX27: 104.863 | AY27: 104.981 | AZ27: =SUM(AV27:AY27) -> 404.239 | BA27: =+AY27+5 -> 109.981 | BB27: =+BA27 -> 109.981 | BC27: =+BB27 -> 109.981 | BD27: =+BC27 -> 109.981 | BE27: =SUM(BA27:BD27) -> 439.924 | BF27: =+BE27*1.05 -> 461.9202 | BG27: =+BF27*1.05 -> 485.01621 | BH27: =+BG27*1.05 -> 509.26702 | BI27: =+BH27*1.05 -> 534.73037 | BJ27: =+BI27*1.05 -> 561.46689
B28: General & administrative, non GAAP | C28: =5.92-1.617 -> 4.303 | D28: =6.69-1.772 -> 4.918 | E28: =7.07-1.743 -> 5.327 | F28: =7.28-2.022 -> 5.258 | G28: =SUM(C28:F28) -> 19.806 | H28: =11.15-2.331-1.413 -> 7.406 | I28: =11.3-2.92 -> 8.38 | J28: =12.22-3.236 -> 8.984 | K28: =13.52-3.471-0.54 -> 9.509 | L28: =SUM(H28:K28) -> 34.279 | M28: =13.67-4.068 -> 9.602 | N28: =14.855-4.86 -> 9.995 | O28: =14.514-4.689 -> 9.825 | P28: =16.258-5.108 -> 11.15 | Q28: =SUM(M28:P28) -> 40.572 | R28: =18.466-6.592 -> 11.874 | S28: =20.103-7.504 -> 12.599 | T28: =23.751-7.391 -> 16.36 | U28: =23.602-7.377 -> 16.225 | V28: =SUM(R28:U28) -> 57.058 | W28: =25.436-8.334 -> 17.102 | X28: =24.531-9.487 -> 15.044 | Y28: =26.515-10.047 -> 16.468 | Z28: =35.433-10.59 -> 24.843 | AA28: =SUM(W28:Z28) -> 73.457 | AB28: =34.394-12.4 -> 21.994 | AC28: =39.411-13.884 -> 25.527 | AD28: =38.917-14.048 -> 24.869 | AE28: =56.926-29.688 -> 27.238 | AF28: =SUM(AB28:AE28) -> 99.628 | AG28: 27.352 | AH28: 28.12 | AI28: 28.731 | AJ28: 26.305 | AK28: =SUM(AG28:AJ28) -> 110.508 | AL28: 25.777 | AM28: 25.336 | AN28: 27.352 | AO28: 31.957 | AP28: =SUM(AL28:AO28) -> 110.422 | AQ28: 28.241 | AR28: 27.092 | AS28: 27.265 | AT28: 29.712 | AU28: =SUM(AQ28:AT28) -> 112.31 | AV28: 28.421 | AW28: 28.832 | AX28: 27.723 | AY28: 30.475 | AZ28: =SUM(AV28:AY28) -> 115.451 | BA28: =+AY28 -> 30.475 | BB28: =+BA28 -> 30.475 | BC28: =+BB28 -> 30.475 | BD28: =+BC28 -> 30.475 | BE28: =SUM(BA28:BD28) -> 121.9 | BF28: =+BE28*1.02 -> 124.338 | BG28: =+BF28*1.02 -> 126.82476 | BH28: =+BG28*1.02 -> 129.36126 | BI28: =+BH28*1.02 -> 131.94848 | BJ28: =+BI28*1.02 -> 134.58745
B29: Operating Non GAAP adjustments | M29: =-0.588-1.428 -> -2.016 | N29: =-0.731-0.946 -> -1.677 | O29: =-0.733-0.261 -> -0.994 | P29: =-0.732-0.125 -> -0.857 | R29: -0.732 | S29: =-0.738-0.053 -> -0.791 | T29: =-0.733-3.174-0.564 -> -4.471 | U29: =-2.385-2.135-1.868 -> -6.388 | V29: =SUM(R29:U29) -> -12.382 | W29: =-0.566-1.974-0.939 -> -3.479 | X29: =-0.566+0.485-1.697 -> -1.778 | Y29: =-0.826-1.489 -> -2.315 | Z29: =-0.619-2.81-1.686 -> -5.115 | AA29: =SUM(W29:Z29) -> -12.687 | AB29: =-0.599-0.452-1.705 -> -2.756 | AC29: =-0.846-0.579-2.351 -> -3.776 | AD29: =-3.045-0.341-2.579 -> -5.965 | AE29: =-0.462-0.32-2.045 -> -2.827 | AF29: =SUM(AB29:AE29) -> -15.324 | AG29: 0 | AH29: =AG29 -> 0 | AI29: 0 | AJ29: =AI29 -> 0 | AK29: =SUM(AG29:AJ29) -> 0 | AL29: =AJ29 -> 0 | AM29: 0 | AN29: 0 | AO29: 0 | AP29: =SUM(AL29:AO29) -> 0 | AQ29: 0 | AR29: =AQ29 -> 0 | AS29: =AR29 -> 0 | AT29: =AS29 -> 0 | AU29: =SUM(AQ29:AT29) -> 0 | AV29: 0 | AW29: =AV29 -> 0 | AX29: =AW29 -> 0 | AY29: =AX29 -> 0 | AZ29: =SUM(AV29:AY29) -> 0 | BA29: =AY29 -> 0 | BB29: =BA29 -> 0 | BC29: =BB29 -> 0 | BD29: =BC29 -> 0 | BE29: =SUM(BA29:BD29) -> 0 | BF29: =BE29 -> 0 | BG29: =BF29 -> 0 | BH29: =BG29 -> 0 | BI29: =BH29 -> 0 | BJ29: =BI29 -> 0 | BL29: =+SUM(AX27:AY27)*2*1.05 -> 440.6724
B30: Total operating expenses | C30: =SUM(C26:C29) -> 63.763 | D30: =SUM(D26:D29) -> 61.165 | E30: =SUM(E26:E29) -> 66.22 | F30: =SUM(F26:F29) -> 67.989 | G30: =SUM(G26:G29) -> 259.137 | H30: =SUM(H26:H29) -> 85.749 | I30: =SUM(I26:I29) -> 83.721 | J30: =SUM(J26:J29) -> 90.324 | ... BJ30: =SUM(BJ26:BJ29) -> 1350.3386
AP31: =+AP30/AP13 -> 0.52957196
B32: Non-GAAP Operating Income | C32: =C24-C30 -> -12.255 | D32: =D24-D30 -> -2.98 | E32: =E24-E30 -> -1.164 | F32: =F24-F30 -> 3.88 | G32: =G24-G30 -> -12.519 | H32: =H24-H30 -> -7.538 | I32: =I24-I30 -> 3.509 | J32: =J24-J30 -> 3.419 | ... BJ32: =BJ24-BJ30 -> 1017.5011
B33: SBC | W33: =+W45 -> 30.718 | X33: =+X45 -> 34.967 | Y33: =+Y45 -> 38.922 | Z33: =+Z45 -> 42.706 | AA33: =+AA45 -> 147.313 | AB33: =+AB45 -> 46.631 | AC33: =+AC45 -> 50.396 | AD33: =+AD45 -> 53.07 | ... BJ33: =+BJ45 -> 251.97941
B34: Amortization | AG34: 1.574 | AH34: 1.58 | AI34: 1.581 | AJ34: 1.511 | AK34: =+SUM(AG34:AJ34) -> 6.246 | AL34: 1.488 | AM34: 1.489 | AN34: 1.489 | AO34: 1.489 | AP34: =+SUM(AL34:AO34) -> 5.955 | AQ34: 1.483 | AR34: 1.465 | AS34: 1.461 | AT34: 1.834 | AU34: =+SUM(AQ34:AT34) -> 6.243 | AV34: 1.472 | AW34: 1.259 | AX34: 1.355 | AY34: 2.923 | AZ34: =+SUM(AV34:AY34) -> 7.009 | BA34: =+AY34 -> 2.923 | BB34: =+BA34 -> 2.923 | BC34: =+BB34 -> 2.923 | BD34: =+BC34 -> 2.923 | BE34: =+SUM(BA34:BD34) -> 11.692 | BF34: =+BE34 -> 11.692 | BG34: =+BF34 -> 11.692 | BH34: =+BG34 -> 11.692 | BI34: =+BH34 -> 11.692 | BJ34: =+BI34 -> 11.692
B35: Other | AG35: =1.699+0.172 -> 1.871 | AH35: =1.187+0.189 -> 1.376 | AI35: =0.585+0.183 -> 0.768 | AJ35: =1.656+0.219 -> 1.875 | AK35: =+SUM(AG35:AJ35) -> 5.89 | AL35: =0.196+0.308+25.338 -> 25.842 | AM35: =0.244+0.157+0.33 -> 0.731 | AN35: =0.023+0.146+3.843 -> 4.012 | AO35: =0.009+0.137+3.103 -> 3.249 | AP35: =+SUM(AL35:AO35) -> 33.834 | AQ35: =0.005+0.121 -> 0.126 | AR35: 0 | AS35: 0 | AT35: 0.881 | AU35: =+SUM(AQ35:AT35) -> 1.007 | AV35: 0.699 | AW35: =6.087-0.938 -> 5.149 | AX35: =0.945+35.432 -> 36.377 | AY35: =90.044+2.694 -> 92.738 | AZ35: 0 | BA35: 0 | BB35: 0 | BC35: 0 | BD35: 0 | BE35: 0 | BF35: =+BE35 -> 0 | BG35: =+BF35 -> 0 | BH35: =+BG35 -> 0 | BI35: =+BH35 -> 0 | BJ35: =+BI35 -> 0
B36: GAAP Operating Income | AG36: =+AG32-AG33-AG34-AG35 -> -115.417 | AH36: =+AH32-AH33-AH34-AH35 -> -75.022 | AI36: =+AI32-AI33-AI34-AI35 -> -62.311 | AJ36: =+AJ32-AJ33-AJ34-AJ35 -> -32.603 | AK36: =+AK32-AK33-AK34-AK35 -> -285.353 | AL36: =+AL32-AL33-AL34-AL35 -> -33.333 | AM36: =+AM32-AM33-AM34-AM35 -> 12.976 | AN36: =+AN32-AN33-AN34-AN35 -> -5.792 | ... BJ36: =+BJ32-BJ33-BJ34-BJ35 -> 753.82965
B38: GAAP to Non GAAP Adj | M38: =M45+0.588+1.428-0.566 -> 17.124 | N38: =N45+0.731+0.946 -> 19.446 | O38: =O45+0.733+0.261+4.965 -> 24.719 | P38: =P45+0.732+0.125+5.039+0.5 -> 26.523 | Q38: =SUM(M38:P38) -> 87.812 | R38: =R45+0.732+5.117+1.452 -> 32.208 | S38: =S45+0.738+0.053+5.194+0.14 -> 33.69 | T38: =T45+0.733+0.564+5.274+3.174+0.056 -> 38.193 | U38: =U45+2.385+1.868+5.353+2.135+1.257 -> 41.471 | V38: =SUM(R38:U38) -> 145.562 | W38: =W45+0.566+0.939+5.433+1.974-0.873 -> 38.757 | X38: =X45+0.566+1.697+5.516-0.485+1.305 -> 43.566 | Y38: =Y45+0.826+1.489+7.594-0.005 -> 48.826 | Z38: =Z45+0.619+1.686+11.411+2.81-66.709+1.925+15.343 -> 9.791 | AA38: =SUM(W38:Z38) -> 140.94 | AB38: =AB45+0.599+1.705+62.345+0.452-29.513+2.59+6.788 -> 91.597 | AC38: =AC45+0.846+2.351+1.296+0.579-142.348+0.363+32.74 -> -53.777 | AD38: =AD45+3.045+2.579+1.297+0.341-112.165+1.745+21.48 -> -28.608 | AE38: =AE45+0.462+2.045+1.298+0.32+16.195+2.013-3.725 -> 89.902 | AF38: =SUM(AB38:AE38) -> 99.114 | AG38: =AG45+1.574+1.699+1.301+0.172+151.645+4.132-35.612 -> 185.895 | AH38: =AH45+1.58+1.187+1.302+0.189+54.92-2.274-12.632 -> 103.411 | AI38: =AI45+1.581+0.585+1.305+0.183-1.675+2.342-10.182 -> 50.935 | AJ38: =AJ45+1.511+1.656+1.305+0.219+3.955+6.22-0.176 -> 74.607 | AK38: =SUM(AG38:AJ38) -> 414.848 | AL38: =+AL45+1.488+0.196+0.308+25.338 -> 81.851 | AM38: =AM45+1.489+0.244+1.31+0.33+0.157-8.814-1.843-2.022 -> 44.511 | AN38: =AN45+1.489+0.023+0.787+3.843+0.146-8.283-0.552+2.4 -> 58.102 | AO38: =AO45 -> 58.195 | AP38: =SUM(AL38:AO38) -> 242.659 | AQ38: =AQ45 -> 58.142 | AR38: =AR45+AR48 -> 58.183 | AS38: =AS45+AS48 -> 59.206 | AT38: =AT45 -> 61.801 | AU38: =SUM(AQ38:AT38) -> 237.332 | AV38: =AV45 -> 60.261 | AW38: =AW45 -> 59.439 | AX38: =AX45 -> 59.565 | AY38: =AY45 -> 58.111 | AZ38: =SUM(AV38:AY38) -> 237.376 | BA38: =BA45 -> 60.86361 | BB38: =BB45 -> 60.03339 | BC38: =BC45 -> 60.16065 | BD38: =BD45 -> 58.69211 | BE38: =SUM(BA38:BD38) -> 239.74976 | BF38: =BF45 -> 242.14726 | BG38: =BG45 -> 244.56873 | BH38: =BH45 -> 247.01442 | BI38: =BI45 -> 249.48456 | BJ38: =BJ45 -> 251.97941
B39: Non GAAP net Income | M39: =M52+M38 -> -2.689 | N39: =N52+N38 -> 13.806 | O39: =O52+O38 -> 18.803 | P39: =P52+P38 -> 20.77 | Q39: =SUM(M39:P39) -> 50.69 | R39: =R52+R38 -> 1.468 | S39: =S52+S38 -> 16.958 | T39: =T52+T38 -> 20.826 | U39: =U52+U38 -> 19.898 | V39: =SUM(R39:U39) -> 59.15 | W39: =W52+W38 -> -0.396 | X39: =X52+X38 -> -14.17 | Y39: =Y52+Y38 -> -8.016 | Z39: =Z52+Z38 -> -1.632 | AA39: =AA52+AA38 -> -24.214 | AB39: =AB52+AB38 -> -30.155 | AC39: =AC52+AC38 -> -15.82 | AD39: =AD52+AD38 -> -11.941 | ... BJ39: =BJ52+BJ38 -> 1017.8595
B41: Depreciation | C41: 1.2 | D41: 1.2 | E41: 1.2 | F41: 0.9 | G41: =+SUM(C41:F41) -> 4.5 | H41: 1.3 | I41: 1.3 | J41: 1.5 | K41: 1.6 | L41: =+SUM(H41:K41) -> 5.7 | M41: 1.897 | N41: 2.196 | O41: 2.213 | P41: 2.418 | Q41: =+SUM(M41:P41) -> 8.724 | R41: 2.658 | S41: 2.927 | T41: 3.194 | U41: 3.347 | V41: =+SUM(R41:U41) -> 12.126 | W41: 3.572 | X41: 3.537 | Y41: 3.712 | Z41: 3.789 | AA41: =+SUM(W41:Z41) -> 14.61 | AB41: 3.432 | AC41: 3.378 | AD41: =3.595 -> 3.595 | AE41: 3.524 | AF41: =+SUM(AB41:AE41) -> 13.929 | AG41: 3.535 | AH41: 4.022 | AI41: 3.845 | AJ41: 5.209 | AK41: =+SUM(AG41:AJ41) -> 16.611 | AL41: 4.922 | AM41: =AL41 -> 4.922 | AN41: =AM41 -> 4.922 | AO41: =18-SUM(AL41:AN41) -> 3.234 | AP41: =+SUM(AL41:AO41) -> 18 | AQ41: 6.442 | AR41: 4.5 | AS41: 4.5 | AT41: 6.278 | AU41: =+SUM(AQ41:AT41) -> 21.72 | AV41: 6.137 | AW41: 6.099 | AX41: 6.19 | AY41: 6.065 | AZ41: =+SUM(AV41:AY41) -> 24.491 | BA41: =AY41 -> 6.065 | BB41: =BA41 -> 6.065 | BC41: =BB41 -> 6.065 | BD41: =BC41 -> 6.065 | BE41: =+SUM(BA41:BD41) -> 24.26 | BF41: =+BE41 -> 24.26 | BG41: =+BF41 -> 24.26 | BH41: =+BG41 -> 24.26 | BI41: =+BH41 -> 24.26 | BJ41: =+BI41 -> 24.26
B42: Non-GAAP Adjustments | C42: =2.664-C32-C41 -> 13.719 | D42: =10.682-D32-D41 -> 12.462 | E42: =11.365-E32-E41 -> 11.329 | F42: =17.877-F32-F41 -> 13.097 | G42: =+SUM(C42:F42) -> 50.607 | H42: =15-H32-H41 -> 21.238 | I42: =17.3-I32-I41 -> 12.491 | J42: =12.9-J32-J41 -> 7.981 | K42: =23.9-K32-K41 -> 12.601 | L42: =+SUM(H42:K42) -> 54.311 | M42: =+M5 -> 21.88 | N42: =+N5 -> 13.763 | O42: =+O5 -> 7.177 | P42: =+P5 -> 11.861 | Q42: =+SUM(M42:P42) -> 54.681 | R42: =+R5 -> 26.089 | S42: =+S5 -> 14.144 | T42: =+T5 -> 9.069 | U42: =+U5 -> 22.095 | V42: =+SUM(R42:U42) -> 71.397 | W42: =+W5 -> 32.871 | X42: =+X5 -> 29.792 | Y42: =+Y5 -> 26.761 | Z42: =+Z5 -> 23.847 | AA42: =+SUM(W42:Z42) -> 113.271 | AB42: =+AB5 -> 46.997 | AC42: =+AC5 -> 26.455 | AD42: =+AD5 -> 52.5 | AE42: =+AE5 -> 23.214 | AF42: =+SUM(AB42:AE42) -> 149.166 | AG42: =+AG5 -> 51.651 | AH42: =+AH5 -> 9.37 | AI42: =+AI5 -> 6.659 | AJ42: =+AJ5 -> 16.773 | AK42: =+SUM(AG42:AJ42) -> 84.453 | AL42: =+AL5 -> 40.829 | AM42: =+AM5 -> 8.519 | AN42: =+AN5 -> -4.746 | AO42: =+AO5 -> -8.767 | AP42: =+SUM(AL42:AO42) -> 35.835 | AQ42: =+AQ5 -> 37.505 | AR42: =+AR5 -> 22.653 | AS42: =+AS5 -> 7.813 | AT42: =+AT5 -> 4.145 | AU42: =+SUM(AQ42:AT42) -> 72.116 | AV42: =+AV5 -> 37.254 | AW42: =+AW5 -> 19.994 | AX42: =+AX5 -> 9.349 | AY42: =+AY5 -> 4.828 | AZ42: =+SUM(AV42:AY42) -> 71.425 | BA42: =+BA5 -> 34.9723 | BB42: =+BB5 -> 21.3565 | BC42: =+BC5 -> 11.1936 | BD42: =+BD5 -> 0 | BE42: =+SUM(BA42:BD42) -> 67.5224 | BF42: =+BF5 -> 70.89852 | BG42: =+BG5 -> 74.443446 | BH42: =+BH5 -> 78.165618 | BI42: =+BI5 -> 82.073899 | BJ42: =+BJ5 -> 86.177594
B43: Adjusted EBITDA | C43: =C32+SUM(C41:C42) -> 2.664 | D43: =D32+SUM(D41:D42) -> 10.682 | E43: =E32+SUM(E41:E42) -> 11.365 | F43: =F32+SUM(F41:F42) -> 17.877 | G43: =G32+SUM(G41:G42) -> 42.588 | H43: =H32+SUM(H41:H42) -> 15 | I43: =I32+SUM(I41:I42) -> 17.3 | J43: =J32+SUM(J41:J42) -> 12.9 | ... BJ43: =BJ32+SUM(BJ41:BJ42) -> 1127.9386
B45: SBC | M45: 15.674 | N45: 17.769 | O45: 18.76 | P45: 20.127 | Q45: =SUM(M45:P45) -> 72.33 | R45: 24.907 | S45: 27.565 | T45: 28.392 | U45: 28.473 | V45: =SUM(R45:U45) -> 109.337 | W45: 30.718 | X45: 34.967 | Y45: 38.922 | Z45: 42.706 | AA45: =SUM(W45:Z45) -> 147.313 | AB45: 46.631 | AC45: 50.396 | AD45: =53.07 -> 53.07 | AE45: 71.294 | AF45: =SUM(AB45:AE45) -> 221.391 | AG45: 60.984 | AH45: 59.139 | AI45: 56.796 | AJ45: 59.917 | AK45: =SUM(AG45:AJ45) -> 236.836 | AL45: 54.521 | AM45: 53.66 | AN45: 58.249 | AO45: 58.195 | AP45: =SUM(AL45:AO45) -> 224.625 | AQ45: 58.142 | AR45: 59.886 | AS45: 60.892 | AT45: 61.801 | AU45: =SUM(AQ45:AT45) -> 240.721 | AV45: 60.261 | AW45: 59.439 | AX45: 59.565 | AY45: 58.111 | AZ45: =SUM(AV45:AY45) -> 237.376 | BA45: ='Cash Flow'!BA8 -> 60.86361 | BB45: ='Cash Flow'!BB8 -> 60.03339 | BC45: ='Cash Flow'!BC8 -> 60.16065 | BD45: ='Cash Flow'!BD8 -> 58.69211 | BE45: =SUM(BA45:BD45) -> 239.74976 | BF45: ='Cash Flow'!BF8 -> 242.14726 | BG45: ='Cash Flow'!BG8 -> 244.56873 | BH45: ='Cash Flow'!BH8 -> 247.01442 | BI45: ='Cash Flow'!BI8 -> 249.48456 | BJ45: ='Cash Flow'!BJ8 -> 251.97941
B46: Financial income | C46: 0.51 | D46: -0.11 | E46: 0.3 | F46: -0.45 | G46: =SUM(C46:F46) -> 0.25 | H46: 0.15 | I46: -2.04 | J46: -1.98 | K46: -1.14 | L46: =SUM(H46:K46) -> -5.01 | M46: -0.13 | N46: 1.532 | O46: -2.509 | P46: -1.688 | Q46: =SUM(M46:P46) -> -2.795 | R46: -1.73 | S46: -0.58 | T46: =1.242 -> 1.242 | U46: -2.553 | V46: =SUM(R46:U46) -> -3.621 | W46: 1.145 | X46: -3.339 | Y46: =-7.298 -> -7.298 | Z46: 56.551 | AA46: =SUM(W46:Z46) -> 47.059 | AB46: =-28.013 -> -28.013 | AC46: 143.969 | AD46: =111.917 -> 111.917 | AE46: =-16.868 -> -16.868 | AF46: =SUM(AB46:AE46) -> 211.005 | AG46: -144.473 | AH46: -54.92 | AI46: 21.142 | AJ46: -13.256 | AK46: =SUM(AG46:AJ46) -> -191.507 | AL46: 21.377 | AM46: 20.053 | AN46: 14.583 | AO46: 6.461 | AP46: =SUM(AL46:AO46) -> 62.474 | AQ46: 18.884 | AR46: 12.383 | AS46: 4.198 | AT46: 16.355 | AU46: =SUM(AQ46:AT46) -> 51.82 | AV46: 5.832 | AW46: -38.377 | AX46: 14.926 | AY46: 12.604 | AZ46: =SUM(AV46:AY46) -> -5.015 | BA46: =+'Balance Sheet'!BA55 -> 13.08829 | BB46: =+'Balance Sheet'!BB55 -> 12.691698 | BC46: =+'Balance Sheet'!BC55 -> 10.439836 | BD46: =+'Balance Sheet'!BD55 -> 8.3564899 | BE46: =SUM(BA46:BD46) -> 44.576313 | BF46: =+'Balance Sheet'!BE55 -> 25.733221 | BG46: =+'Balance Sheet'!BF55 -> 31.713193 | BH46: =+'Balance Sheet'!BG55 -> 54.163856 | BI46: =+'Balance Sheet'!BH55 -> 80.203281 | BJ46: =+'Balance Sheet'!BI55 -> 109.76984
B47: Other income | C47: 0 | D47: 0 | E47: 0 | F47: -0.01 | G47: =SUM(C47:F47) -> -0.01 | H47: 0 | I47: 0 | J47: 0 | K47: 0.08 | L47: =SUM(H47:K47) -> 0.08 | M47: 0.02 | N47: 0.063 | O47: 0.017 | P47: -0.59 | Q47: =SUM(M47:P47) -> -0.49 | R47: 0.024 | S47: 0.01 | T47: 0.117 | U47: -0.094 | V47: =SUM(R47:U47) -> 0.057 | W47: 0.031 | X47: 0.028 | Y47: 0.025 | Z47: 0.034 | AA47: =SUM(W47:Z47) -> 0.118 | AB47: 0.065 | AC47: 0.041 | AD47: 0.087 | AE47: 0.391 | AF47: =SUM(AB47:AE47) -> 0.584 | AG47: 0.046 | AH47: 0 | AI47: 0 | AJ47: 0.788 | AK47: =SUM(AG47:AJ47) -> 0.834 | AL47: 0.057 | AM47: 0.118 | AN47: -0.474 | AO47: 0.044 | AP47: =SUM(AL47:AO47) -> -0.255 | AQ47: 0.211 | AR47: 0.038 | AS47: -0.191 | AT47: -0.094 | AU47: =SUM(AQ47:AT47) -> -0.036 | AV47: 0.064 | AW47: 0.123 | AX47: 4.136 | AY47: 0.029 | AZ47: =SUM(AV47:AY47) -> 4.352 | BA47: 0 | BB47: 0 | BC47: 0 | BD47: 0 | BE47: =SUM(BA47:BD47) -> 0 | BF47: 0 | BG47: 0 | BH47: 0 | BI47: 0 | BJ47: 0
B48: =B29 -> Operating Non GAAP adjustments | C48: =-12.23-C66-C32-SUM(C46:C47) -> 0.165 | D48: =-3.713-D66-D32-SUM(D46:D47) -> 0.207 | E48: =-1.569-E66-E32-SUM(E46:E47) -> 0.205 | F48: =2.957-F66-F32-SUM(F46:F47) -> 0.261 | G48: =SUM(C48:F48) -> 0.838 | H48: =-7.952-H66-H32-SUM(H46:H47) -> -0.004 | I48: =-0.185-I66-I32-SUM(I46:I47) -> 0.006 | J48: =0.353-J66-J32-SUM(J46:J47) -> -0.006 | K48: =7.235-K66-K32-SUM(K46:K47) -> -3.384 | L48: =SUM(H48:K48) -> -3.388 | M48: =M29 -> -2.016 | N48: =N29 -> -1.677 | O48: =O29 -> -0.994 | P48: =P29 -> -0.857 | Q48: =SUM(M48:P48) -> -5.544 | R48: =R29 -> -0.732 | S48: =S29 -> -0.791 | T48: =T29 -> -4.471 | U48: =U29 -> -6.388 | V48: =SUM(R48:U48) -> -12.382 | W48: =W29 -> -3.479 | X48: =X29 -> -1.778 | Y48: =Y29 -> -2.315 | Z48: =Z29 -> -5.115 | AA48: =SUM(W48:Z48) -> -12.687 | AB48: =AB29 -> -2.756 | AC48: =AC29 -> -3.776 | AD48: =AD29 -> -5.965 | AE48: =-(0.462+0.32+2.045) -> -2.827 | AF48: =SUM(AB48:AE48) -> -15.324 | AG48: =-1.574-0.172-1.699 -> -3.445 | AH48: 5.096 | AI48: -2.22 | AJ48: =-(1.511+0.219+1.656) -> -3.386 | AK48: =SUM(AG48:AJ48) -> -3.955 | AL48: =-(1.488+0.196+0.308)-25.338 -> -27.33 | AM48: =-(1.489+0.244+0.157+0.33) -> -2.22 | AN48: =-1.489-0.023-0.146-3.843 -> -5.501 | AO48: =-3.103-1.489-0.009-0.137 -> -4.738 | AP48: =SUM(AL48:AO48) -> -39.789 | AQ48: =-1.483-0.005-0.121 -> -1.609 | AR48: =-(1.465+0.001+0.237) -> -1.703 | AS48: =-(1.461+0.225) -> -1.686 | AT48: =-(AT35+AT34) -> -2.715 | AU48: =SUM(AQ48:AT48) -> -7.713 | AV48: =-(AV35+AV34) -> -2.171 | AW48: =-(AW35+AW34) -> -6.408 | AX48: =-(AX35+AX34) -> -37.732 | AY48: =-(AY35+AY34) -> -95.661 | AZ48: =SUM(AV48:AY48) -> -141.972 | BA48: 0 | BB48: 0 | BC48: 0 | BD48: 0 | BE48: =SUM(BA48:BD48) -> 0 | BF48: 0 | BG48: 0 | BH48: 0 | BI48: 0 | BJ48: 0
B49: Pretax income | C49: =C32+SUM(C46:C48) -> -11.58 | D49: =D32+SUM(D46:D48) -> -2.883 | E49: =E32+SUM(E46:E48) -> -0.659 | F49: =F32+SUM(F46:F48) -> 3.681 | G49: =G32+SUM(G46:G48) -> -11.441 | H49: =H32+SUM(H46:H48) -> -7.392 | I49: =I32+SUM(I46:I48) -> 1.475 | J49: =J32+SUM(J46:J48) -> 1.433 | ... L49: =L32+SUM(L46:L48) -> 0.771 | M49: =M32-M45+M46+M47+M48 -> -18.562 | N49: =N32-N45+N46+N47+N48 -> -4.912 | O49: =O32-O45+O46+O47+O48 -> -5.99 | P49: =P32-P45+P46+P47+P48 -> -4.451 | Q49: =Q32+SUM(Q46:Q48) -> 32.871 | R49: =R32-R45+R46+R47+R48 -> -29.498 | S49: =S32-S45+S46+S47+S48 -> -14.731 | T49: =T32-T45+T46+T47+T48 -> -19.246 | U49: =U32-U45+U46+U47+U48 -> -20.339 | V49: =V32-V45+V46+V47+V48 -> -83.814 | W49: =W32-W45+W46+W47+W48 -> -37.215 | X49: =X32-X45+X46+X47+X48 -> -57.062 | Y49: =Y32-Y45+Y46+Y47+Y48 -> -57.013 | ... BJ49: =BJ32-BJ45+BJ46+BJ47+BJ48 -> 875.29149
...

Sheet Core Growth
K2: babd
D5: 2019 | E5: 2020 | F5: 2021 | G5: 2022 | H5: 2023E | I5: 2024E | J5: 2025E | K5: 2026E | L5: 2027E | M5: 2028E | N5: 2029E | O5: 2030E | P5: 2031E | R5: 1Q19 | S5: 2Q19 | T5: 3Q19 | U5: 4Q19 | W5: 1Q20 | X5: 2Q20 | Y5: 3Q20 | Z5: 4Q20 | AB5: 1Q21 | AC5: 2Q21 | AD5: 3Q21 | AE5: 4Q21 | AG5: 1Q22 | AH5: 2Q22 | AI5: 3Q22 | AJ5: 4Q22 | AL5: 1Q23 | AM5: 2Q23 | AN5: 3Q23 | AO5: 4Q23 | AQ5: 1Q24 | AR5: 2Q24 | AS5: 3Q24 | AT5: 4Q24 | AV5: 1Q25 | AW5: 2Q25 | AX5: 3Q25 | AY5: 4Q25 | BA5: 1Q26E | BB5: 2Q26E | BC5: 3Q26E | BD5: 4Q26E
C6: Partner Revenue | D6: 93 | E6: 154 | F6: 270 | G6: =+SUM(AG6:AJ6) -> 348.18 | H6: =+SUM(AL6:AO6) -> 468.6 | I6: =+SUM(AQ6:AT6) -> 610 | J6: =+SUM(AV6:AY6) -> 750.651 | K6: =+SUM(BA6:BD6) -> 900.7812 | L6: =+K6*(1+L8) -> 1044.9062 | M6: =+L6*(1+M8) -> 1178.6542 | N6: =+M6*(1+N8) -> 1299.3484 | O6: =+N6*(1+O8) -> 1405.791 | P6: =+O6*(1+P8) -> 1497.9209 | Q6: =+(J6/G6)^(1/3)-1 -> 0.291848 | R6: =+D6-SUM(S6:U6) -> 21 | S6: =+T6-2.5 -> 21.5 | T6: =+U6-2.5 -> 24 | U6: =+W6-2.5 -> 26.5 | W6: 29 | X6: 32.725 | Y6: 38.145 | Z6: =E6-SUM(W6:Y6) -> 54.13 | AB6: 58 | AC6: =+AH6/1.31 -> 64.80916 | AD6: 71 | AE6: =F6-SUM(AB6:AD6) -> 76.19084 | AF6: =SUM(AB6:AE6) -> 270 | AG6: 82 | AH6: 84.9 | AI6: 86.696 | AJ6: 94.584 | AK6: =SUM(AG6:AJ6) -> 348.18 | AL6: 103.9 | AM6: 115.2 | AN6: 119.4 | AO6: 130.1 | AQ6: 138.4 | AR6: 148.4 | AS6: 155 | AT6: =610-SUM(AQ6:AS6) -> 168.2 | AV6: 172 | AW6: 183.316 | AX6: 192.117 | AY6: 203.218 | BA6: =AV6*(1+BA8) -> 206.4 | BB6: =AW6*(1+BB8) -> 219.9792 | BC6: =AX6*(1+BC8) -> 230.5404 | BD6: =AY6*(1+BD8) -> 243.8616
C7: QoQ Growth | W7: =+W6/U6-1 -> 0.094339623 | X7: =+X6/W6-1 -> 0.12844828 | Y7: =+Y6/X6-1 -> 0.16562261 | Z7: =+Z6/Y6-1 -> 0.41905885 | AB7: =+AB6/Z6-1 -> 0.07149455 | AC7: =+AC6/AB6-1 -> 0.11739932 | AD7: =+AD6/AC6-1 -> 0.095524146 | AE7: =+AE6/AD6-1 -> 0.073110418 | AG7: =+AG6/AE6-1 -> 0.076244865 | AH7: =+AH6/AG6-1 -> 0.035365854 | AI7: =+AI6/AH6-1 -> 0.021154299 | AJ7: =+AJ6/AI6-1 -> 0.09098459 | AL7: =+AL6/AJ6-1 -> 0.09849446 | AM7: =+AM6/AL6-1 -> 0.10875842 | AN7: =+AN6/AM6-1 -> 0.036458333 | AO7: =+AO6/AN6-1 -> 0.08961474 | AQ7: =+AQ6/AO6-1 -> 0.063797079 | AR7: =+AR6/AQ6-1 -> 0.072254335 | AS7: =+AS6/AR6-1 -> 0.044474394 | AT7: =+AT6/AS6-1 -> 0.08516129 | AV7: =+AV6/AT6-1 -> 0.022592152 | AW7: =+AW6/AV6-1 -> 0.065790698 | AX7: =+AX6/AW6-1 -> 0.048009994 | AY7: =+AY6/AX6-1 -> 0.057782497 | BA7: =+BA6/AY6-1 -> 0.015658062 | BB7: =+BB6/BA6-1 -> 0.065790698 | BC7: =+BC6/BB6-1 -> 0.048009994 | BD7: =+BD6/BC6-1 -> 0.057782497
C8: YoY Growth | E8: =+E6/D6-1 -> 0.65591398 | F8: =+F6/E6-1 -> 0.75324675 | G8: =+G6/F6-1 -> 0.28955556 | H8: =+H6/G6-1 -> 0.34585559 | I8: =+I6/H6-1 -> 0.30174989 | J8: =+J6/I6-1 -> 0.23057541 | K8: =+K6/J6-1 -> 0.2 | L8: =+K8*0.8 -> 0.16 | M8: =+L8*0.8 -> 0.128 | N8: =+M8*0.8 -> 0.1024 | O8: =+N8*0.8 -> 0.08192 | P8: =+O8*0.8 -> 0.065536 | AB8: =+AB6/W6-1 -> 1 | AC8: =+AC6/X6-1 -> 0.98041743 | AD8: =+AD6/Y6-1 -> 0.86131865 | AE8: =+AE6/Z6-1 -> 0.40755292 | AG8: =+AG6/AB6-1 -> 0.4137931 | AH8: =+AH6/AC6-1 -> 0.31 | AI8: =+AI6/AD6-1 -> 0.22107042 | AJ8: =+AJ6/AE6-1 -> 0.24140908 | AL8: =+AL6/AG6-1 -> 0.26707317 | AM8: =+AM6/AH6-1 -> 0.35689046 | AN8: =+AN6/AI6-1 -> 0.37722617 | AO8: =+AO6/AJ6-1 -> 0.37549691 | AQ8: =+AQ6/AL6-1 -> 0.33205005 | AR8: =+AR6/AM6-1 -> 0.28819444 | AS8: =+AS6/AN6-1 -> 0.29815745 | AT8: =+AT6/AO6-1 -> 0.29285165 | AV8: =+AV6/AQ6-1 -> 0.24277457 | AW8: =+AW6/AR6-1 -> 0.23528302 | AX8: =+AX6/AS6-1 -> 0.23946452 | AY8: =+AY6/AT6-1 -> 0.20819263 | BA8: 0.2 | BB8: 0.2 | BC8: 0.2 | BD8: 0.2
C9: Partner Revenue - Creative | D9: =+D6*D10 -> 86.49 | E9: =+E6*E10 -> 103.18 | F9: =+F6*F10 -> 139.725 | G9: =+SUM(AG9:AJ9) -> 183.299 | H9: =+SUM(AL9:AO9) -> 246.015 | I9: =+SUM(AQ9:AT9) -> 320.25 | J9: =+SUM(AV9:AY9) -> 382.83201 | K9: =+SUM(BA9:BD9) -> 450.3906 | L9: =+L6*L10 -> 512.00403 | M9: =+M6*M10 -> 565.75401 | N9: =+N6*N10 -> 610.69374 | O9: =+O6*O10 -> 646.66386 | P9: =+P6*P10 -> 674.06441 | R9: =+R6*R10 -> 19.53 | S9: =+S6*S10 -> 19.995 | T9: =+T6*T10 -> 22.32 | U9: =+U6*U10 -> 24.645 | W9: =+W6*W10 -> 23.2 | X9: =+X6*X10 -> 22.9075 | Y9: =+Y6*Y10 -> 24.79425 | Z9: =+E9-SUM(W9:Y9) -> 32.27825 | AB9: =+AB6*AB10 -> 34.8 | AC9: =+AC6*AC10 -> 35.645038 | AD9: =+AD6*AD10 -> 35.5 | AE9: =+F9-SUM(AB9:AD9) -> 33.779962 | AG9: =+AG6*AG10 -> 36.9 | AH9: =+AH6*AH10 -> 46.695 | AI9: =+AI6*AI10 -> 47.6828 | AJ9: =+AJ6*AJ10 -> 52.0212 | AL9: =+AL6*AL10 -> 54.5475 | AM9: =+AM6*AM10 -> 60.48 | AN9: =+AN6*AN10 -> 62.685 | AO9: =+AO6*AO10 -> 68.3025 | AQ9: =+AQ6*AQ10 -> 72.66 | AR9: =+AR6*AR10 -> 77.91 | AS9: =+AS6*AS10 -> 81.375 | AT9: =+AT6*AT10 -> 88.305 | AV9: =+AV6*AV10 -> 87.72 | AW9: =+AW6*AW10 -> 93.49116 | AX9: =+AX6*AX10 -> 97.97967 | AY9: =+AY6*AY10 -> 103.64118 | BA9: =+BA6*BA10 -> 103.2 | BB9: =+BB6*BB10 -> 109.9896 | BC9: =+BC6*BC10 -> 115.2702 | BD9: =+BD6*BD10 -> 121.9308
C10: % CS | D10: 0.93 | E10: 0.67 | F10: 0.5175 | G10: =+G9/G6 -> 0.52644896 | H10: =+H9/H6 -> 0.525 | I10: =+I9/I6 -> 0.525 | J10: =+J9/J6 -> 0.51 | K10: =+K9/K6 -> 0.5 | L10: =+K10-1% -> 0.49 | M10: =+L10-1% -> 0.48 | N10: =+M10-1% -> 0.47 | O10: =+N10-1% -> 0.46 | P10: =+O10-1% -> 0.45 | R10: =+D10 -> 0.93 | S10: =+R10 -> 0.93 | T10: =+S10 -> 0.93 | U10: =+T10 -> 0.93 | W10: 0.8 | X10: 0.7 | Y10: 0.65 | Z10: =+Z9/Z6 -> 0.59630981 | AB10: 0.6 | AC10: 0.55 | AD10: 0.5 | AE10: =+AE9/AE6 -> 0.44335988 | AG10: 0.45 | AH10: 0.55 | AI10: 0.55 | AJ10: 0.55 | AL10: 0.525 | AM10: 0.525 | AN10: 0.525 | AO10: 0.525 | AQ10: 0.525 | AR10: 0.525 | AS10: 0.525 | AT10: 0.525 | AV10: 0.51 | AW10: 0.51 | AX10: 0.51 | AY10: 0.51 | BA10: 0.5 | BB10: 0.5 | BC10: 0.5 | BD10: 0.5
C11: YoY Growth | E11: =+E9/D9-1 -> 0.19297029 | F11: =+F9/E9-1 -> 0.35418686 | G11: =+G9/F9-1 -> 0.31185543 | H11: =+H9/G9-1 -> 0.34215135 | I11: =+I9/H9-1 -> 0.30174989 | J11: =+J9/I9-1 -> 0.19541611 | K11: =+K9/J9-1 -> 0.17647059 | L11: =+L9/K9-1 -> 0.1368 | ... P11: =+P9/O9-1 -> 0.042372174
C12: Partner Revenue - Business | D12: =+D6-D9 -> 6.51 | E12: =+E6-E9 -> 50.82 | F12: =+F6-F9 -> 130.275 | G12: =+SUM(AG12:AJ12) -> 164.881 | H12: =+SUM(AL12:AO12) -> 222.585 | I12: =+SUM(AQ12:AT12) -> 289.75 | J12: =+SUM(AV12:AY12) -> 367.81899 | K12: =+SUM(BA12:BD12) -> 450.3906 | L12: =+L6-L9 -> 532.90216 | M12: =+M6-M9 -> 612.90018 | N12: =+N6-N9 -> 688.65464 | O12: =+O6-O9 -> 759.12714 | P12: =+P6-P9 -> 823.8565 | R12: =+R6-R9 -> 1.47 | S12: =+S6-S9 -> 1.505 | T12: =+T6-T9 -> 1.68 | U12: =+U6-U9 -> 1.855 | W12: =+W6-W9 -> 5.8 | X12: =+X6-X9 -> 9.8175 | Y12: =+Y6-Y9 -> 13.35075 | Z12: =+Z6-Z9 -> 21.85175 | AB12: =+AB6-AB9 -> 23.2 | AC12: =+AC6-AC9 -> 29.164122 | AD12: =+AD6-AD9 -> 35.5 | AE12: =+AE6-AE9 -> 42.410878 | AG12: =+AG6-AG9 -> 45.1 | AH12: =+AH6-AH9 -> 38.205 | AI12: =+AI6-AI9 -> 39.0132 | AJ12: =+AJ6-AJ9 -> 42.5628 | AL12: =+AL6-AL9 -> 49.3525 | AM12: =+AM6-AM9 -> 54.72 | AN12: =+AN6-AN9 -> 56.715 | AO12: =+AO6-AO9 -> 61.7975 | AQ12: =+AQ6-AQ9 -> 65.74 | AR12: =+AR6-AR9 -> 70.49 | AS12: =+AS6-AS9 -> 73.625 | AT12: =+AT6-AT9 -> 79.895 | AV12: =+AV6-AV9 -> 84.28 | AW12: =+AW6-AW9 -> 89.82484 | AX12: =+AX6-AX9 -> 94.13733 | AY12: =+AY6-AY9 -> 99.57682 | BA12: =+BA6-BA9 -> 103.2 | BB12: =+BB6-BB9 -> 109.9896 | BC12: =+BC6-BC9 -> 115.2702 | BD12: =+BD6-BD9 -> 121.9308
C13: % BS | D13: =+D12/D6 -> 0.07 | E13: =+E12/E6 -> 0.33 | F13: =+F12/F6 -> 0.4825 | G13: =+G12/G6 -> 0.47355104 | H13: =+H12/H6 -> 0.475 | I13: =+I12/I6 -> 0.475 | J13: =+J12/J6 -> 0.49 | K13: =+K12/K6 -> 0.5 | ... P13: =+P12/P6 -> 0.55 | R13: =+R12/R6 -> 0.07 | S13: =+S12/S6 -> 0.07 | T13: =+T12/T6 -> 0.07 | U13: =+U12/U6 -> 0.07 | W13: =+W12/W6 -> 0.2 | X13: =+X12/X6 -> 0.3 | Y13: =+Y12/Y6 -> 0.35 | Z13: =+Z12/Z6 -> 0.40369019 | AB13: =+AB12/AB6 -> 0.4 | AC13: =+AC12/AC6 -> 0.45 | AD13: =+AD12/AD6 -> 0.5 | AE13: =+AE12/AE6 -> 0.55664012 | AG13: =+AG12/AG6 -> 0.55 | AH13: =+AH12/AH6 -> 0.45 | AI13: =+AI12/AI6 -> 0.45 | AJ13: =+AJ12/AJ6 -> 0.45 | AL13: =+AL12/AL6 -> 0.475 | AM13: =+AM12/AM6 -> 0.475 | AN13: =+AN12/AN6 -> 0.475 | AO13: =+AO12/AO6 -> 0.475 | AQ13: =+AQ12/AQ6 -> 0.475 | AR13: =+AR12/AR6 -> 0.475 | AS13: =+AS12/AS6 -> 0.475 | AT13: =+AT12/AT6 -> 0.475 | AV13: =+AV12/AV6 -> 0.49 | AW13: =+AW12/AW6 -> 0.49 | AX13: =+AX12/AX6 -> 0.49 | AY13: =+AY12/AY6 -> 0.49 | BA13: =+BA12/BA6 -> 0.5 | BB13: =+BB12/BB6 -> 0.5 | BC13: =+BC12/BC6 -> 0.5 | BD13: =+BD12/BD6 -> 0.5 | CK13: ='Income Statement'!BM15 -> 0
C14: YoY Growth | E14: =+E12/D12-1 -> 6.8064516 | F14: =+F12/E12-1 -> 1.5634593 | G14: =+G12/F12-1 -> 0.26563807 | H14: =+H12/G12-1 -> 0.34997362 | I14: =+I12/H12-1 -> 0.30174989 | J14: =+J12/I12-1 -> 0.26943569 | K14: =+K12/J12-1 -> 0.2244898 | L14: =+L12/K12-1 -> 0.1832 | ... P14: =+P12/O12-1 -> 0.085268148
C16: Transaction Revenue | D16: 11 | E16: 56 | F16: 130 | G16: =+SUM(AG16:AJ16) -> 149.71 | H16: =+SUM(AL16:AO16) -> 177.5 | I16: =+SUM(AQ16:AT16) -> 214.5 | J16: =+SUM(AV16:AY16) -> 254.988 | K16: =+SUM(BA16:BD16) -> 289.04345 | L16: =+'Income Statement'!BF173 -> 314.97871 | M16: =+'Income Statement'!BG173 -> 337.19271 | N16: =+'Income Statement'!BH173 -> 356.10418 | O16: =+'Income Statement'!BI173 -> 372.20596 | P16: =+'Income Statement'!BJ173 -> 385.98773 | R16: =+D16-SUM(S16:U16) -> 2.255 | S16: =+T16-0.5 -> 2.415 | T16: =+U16-0.5 -> 2.915 | U16: =+W16-2.5 -> 3.415 | W16: 5.915 | X16: 10.669 | Y16: 12.432 | Z16: 26.767 | AB16: 29.455 | AC16: 32.438 | AD16: 32.29 | AE16: 36.132 | AG16: 38 | AH16: 36.8 | AI16: 36.04 | AJ16: 38.87 | AL16: 42.3 | AM16: 44.5 | AN16: 44.1 | AO16: 46.6 | AQ16: 49.5 | AR16: 53.9 | AS16: 54 | AT16: 57.1 | AV16: 58.887 | AW16: 63.551 | AX16: 65.268 | AY16: 67.282 | BA16: =+'Income Statement'!BA173 -> 68.102873 | BB16: =+'Income Statement'!BB173 -> 72.207924 | BC16: =+'Income Statement'!BC173 -> 74.31545 | BD16: =+'Income Statement'!BD173 -> 74.4172
C17: QoQ | AB17: =+AB16/Z16-1 -> 0.10042216 | AC17: =+AC16/AB16-1 -> 0.10127313 | AD17: =+AD16/AC16-1 -> -0.0045625501 | AE17: =+AE16/AD16-1 -> 0.11898421 | AG17: =+AG16/AE16-1 -> 0.051699325 | AH17: =+AH16/AG16-1 -> -0.031578947 | AI17: =+AI16/AH16-1 -> -0.020652174 | AJ17: =+AJ16/AI16-1 -> 0.078523862 | AL17: =+AL16/AJ16-1 -> 0.088242861 | AM17: =+AM16/AL16-1 -> 0.052009456 | AN17: =+AN16/AM16-1 -> -0.008988764 | AO17: =+AO16/AN16-1 -> 0.056689342 | AQ17: =+AQ16/AO16-1 -> 0.06223176 | AR17: =+AR16/AQ16-1 -> 0.088888889 | AS17: =+AS16/AR16-1 -> 0.0018552876 | AT17: =+AT16/AS16-1 -> 0.057407407 | AV17: =+AV16/AT16-1 -> 0.031295972 | AW17: =+AW16/AV16-1 -> 0.07920254 | AX17: =+AX16/AW16-1 -> 0.027017671 | AY17: =+AY16/AX16-1 -> 0.030857388 | BA17: =+BA16/AY16-1 -> 0.012200484 | BB17: =+BB16/BA16-1 -> 0.060277213 | BC17: =+BC16/BB16-1 -> 0.029186903 | BD17: =+BD16/BC16-1 -> 0.0013691635
C18: YoY | E18: =+E16/D16-1 -> 4.0909091 | F18: =+F16/E16-1 -> 1.3214286 | G18: =+G16/F16-1 -> 0.15161538 | H18: =+H16/G16-1 -> 0.18562554 | I18: =+I16/H16-1 -> 0.2084507 | J18: =+J16/I16-1 -> 0.18875524 | K18: =+K16/J16-1 -> 0.13355706 | L18: =+L16/K16-1 -> 0.08972789 | ... P18: =+P16/O16-1 -> 0.037027264 | AB18: =+AB16/W16-1 -> 3.9797126 | AC18: =+AC16/X16-1 -> 2.0403974 | AD18: =+AD16/Y16-1 -> 1.5973295 | AE18: =+AE16/Z16-1 -> 0.34987111 | AG18: =+AG16/AB16-1 -> 0.29010355 | AH18: =+AH16/AC16-1 -> 0.13447192 | AI18: =+AI16/AD16-1 -> 0.11613503 | AJ18: =+AJ16/AE16-1 -> 0.075777704 | AL18: =+AL16/AG16-1 -> 0.11315789 | AM18: =+AM16/AH16-1 -> 0.20923913 | AN18: =+AN16/AI16-1 -> 0.2236404 | AO18: =+AO16/AJ16-1 -> 0.19886802 | AQ18: =+AQ16/AL16-1 -> 0.17021277 | AR18: =+AR16/AM16-1 -> 0.21123596 | AS18: =+AS16/AN16-1 -> 0.2244898 | AT18: =+AT16/AO16-1 -> 0.22532189 | AV18: =+AV16/AQ16-1 -> 0.18963636 | AW18: =+AW16/AR16-1 -> 0.1790538 | AX18: =+AX16/AS16-1 -> 0.20866667 | AY18: =+AY16/AT16-1 -> 0.17831874 | BA18: =+BA16/AV16-1 -> 0.15650098 | BB18: =+BB16/AW16-1 -> 0.13622011 | BC18: =+BC16/AX16-1 -> 0.13862 | BD18: =+BD16/AY16-1 -> 0.10604917
C20: Self Creator Revenue | D20: 664 | E20: =+E24-E6 -> 830.907 | F20: =+F24-F6 -> 999.657 | G20: =+SUM(AG20:AJ20) -> 1039.486 | H20: =+SUM(AL20:AO20) -> 1093.065 | I20: =+SUM(AQ20:AT20) -> 1150.65 | J20: =+SUM(AV20:AY20) -> 1242.393 | K20: =+SUM(BA20:BD20) -> 1403.5997 | L20: =+L24-L12-L9 -> 1530.0823 | M20: =+M24-M12-M9 -> 1640.7775 | N20: =+N24-N12-N9 -> 1736.859 | O20: =+O24-O12-O9 -> 1819.8726 | P20: =+P24-P12-P9 -> 1893.397 | R20: =+R24-R12-R9 -> 153.29 | S20: =+S24-S12-S9 -> 163.919 | T20: =+T24-T12-T9 -> 172.791 | U20: =+U24-U12-U9 -> 174 | W20: =+W24-W12-W9 -> 186.987 | X20: =+X24-X12-X9 -> 203.334 | Y20: =+Y24-Y12-Y9 -> 216.035 | Z20: =+Z24-Z12-Z9 -> 224.551 | AB20: =+AB24-AB12-AB9 -> 246.112 | AC20: =+AC24-AC12-AC9 -> 251.59684 | AD20: =+AD24-AD12-AD9 -> 249.797 | AE20: =+AE24-AE12-AE9 -> 252.15116 | AF20: =SUM(AB20:AE20) -> 999.657 | AG20: =+AG24-AG6 -> 259.597 | AH20: =+AH24-AH6 -> 260.324 | AI20: =+AI24-AI6 -> 259.109 | AJ20: =+AJ24-AJ6 -> 260.456 | AK20: =SUM(AG20:AJ20) -> 1039.486 | AL20: =+AL24-AL6 -> 270.176 | AM20: =+AM24-AM6 -> 274.777 | AN20: =+AN24-AN6 -> 274.441 | AO20: =+AO24-AO6 -> 273.671 | AP20: =SUM(AL20:AO20) -> 1093.065 | AQ20: =+AQ24-AQ6 -> 281.376 | AR20: =+AR24-AR6 -> 287.346 | AS20: =+AS24-AS6 -> 289.673 | AT20: =+AT24-AT6 -> 292.255 | AV20: =+AV24-AV6 -> 301.651 | AW20: =+AW24-AW6 -> 306.614 | AX20: =+AX24-AX6 -> 313.077 | AY20: =+AY24-AY6 -> 321.051 | BA20: =+BA24-BA6 -> 335.42232 | BB20: =+BB24-BB6 -> 343.36214 | BC20: =+BC24-BC6 -> 355.98005 | BD20: =+BD24-BD6 -> 368.8352 | BF20: =SUM(AQ20:AT20) -> 1150.65
C21: QoQ Growth | S21: =+S20/R20-1 -> 0.069339161 | T21: =+T20/S20-1 -> 0.054124293 | U21: =+U20/T20-1 -> 0.0069968922 | W21: =+W20/U20-1 -> 0.074637931 | X21: =+X20/W20-1 -> 0.08742319 | Y21: =+Y20/X20-1 -> 0.06246373 | Z21: =+Z20/Y20-1 -> 0.039419539 | AB21: =+AB20/Z20-1 -> 0.096018276 | AC21: =+AC20/AB20-1 -> 0.02228595 | AD21: =+AD20/AC20-1 -> -0.0071536657 | AE21: =+AE20/AD20-1 -> 0.0094242937 | AG21: =+AG20/AE20-1 -> 0.02952927 | AH21: =+AH20/AG20-1 -> 0.0028004946 | AI21: =+AI20/AH20-1 -> -0.0046672608 | AJ21: =+AJ20/AI20-1 -> 0.0051985844 | AL21: =+AL20/AJ20-1 -> 0.037319163 | AM21: =+AM20/AL20-1 -> 0.01702964 | AN21: =+AN20/AM20-1 -> -0.0012228098 | AO21: =+AO20/AN20-1 -> -0.0028057032 | AQ21: =+AQ20/AO20-1 -> 0.028154244 | AR21: =+AR20/AQ20-1 -> 0.021217161 | AS21: =+AS20/AR20-1 -> 0.0080982509 | AT21: =+AT20/AS20-1 -> 0.008913499 | AV21: =+AV20/AT20-1 -> 0.032150006 | AW21: =+AW20/AV20-1 -> 0.016452788 | AX21: =+AX20/AW20-1 -> 0.02107862 | AY21: =+AY20/AX20-1 -> 0.025469773 | BA21: =+BA20/AY20-1 -> 0.04476337 | BB21: =+BB20/BA20-1 -> 0.023671108 | BC21: =+BC20/BB20-1 -> 0.036748098 | BD21: =+BD20/BC20-1 -> 0.036111991
C22: YoY Growth | E22: =+E20/D20-1 -> 0.25136596 | F22: =+F20/E20-1 -> 0.20309132 | G22: =+G20/F20-1 -> 0.039842666 | H22: =+H20/G20-1 -> 0.051543744 | I22: =+I20/H20-1 -> 0.052682137 | J22: =+J20/I20-1 -> 0.079731456 | K22: =+K20/J20-1 -> 0.12975501 | L22: =+L20/K20-1 -> 0.090113014 | ... P22: =+P20/O20-1 -> 0.040400828 | W22: =+W20/R20-1 -> 0.21982517 | X22: =+X20/S20-1 -> 0.24045413 | Y22: =+Y20/T20-1 -> 0.25026766 | Z22: =+Z20/U20-1 -> 0.29052299 | AB22: =+AB20/W20-1 -> 0.31619845 | AC22: =+AC20/X20-1 -> 0.23735745 | AD22: =+AD20/Y20-1 -> 0.15628023 | AE22: =+AE20/Z20-1 -> 0.12291266 | AG22: =+AG20/AB20-1 -> 0.054792127 | AH22: =+AH20/AC20-1 -> 0.034687082 | AI22: =+AI20/AD20-1 -> 0.03727827 | AJ22: =+AJ20/AE20-1 -> 0.032935957 | AK22: =+AK20/AF20-1 -> 0.039842666 | AL22: =+AL20/AG20-1 -> 0.040751627 | AM22: =+AM20/AH20-1 -> 0.055519276 | AN22: =+AN20/AI20-1 -> 0.059172009 | ... AT22: =+AT20/AO20-1 -> 0.067906355 | AV22: =+AV20/AQ20-1 -> 0.072056608 | AW22: =+AW20/AR20-1 -> 0.067055049 | AX22: =+AX20/AS20-1 -> 0.080794551 | AY22: =+AY20/AT20-1 -> 0.098530393 | BA22: =+BA20/AV20-1 -> 0.11195496 | BB22: =+BB20/AW20-1 -> 0.11985148 | BC22: =+BC20/AX20-1 -> 0.13703673 | BD22: =+BD20/AY20-1 -> 0.14883678 | BF22: =+BF20/AP20-1 -> 0.052682137
C24: Total Revenue | D24: =+D20+D6 -> 757 | E24: =213.105+235.337+253.931+282.534 -> 984.907 | F24: =+'Income Statement'!AF13 -> 1269.657 | G24: =+SUM(AG24:AJ24) -> 1387.666 | H24: =+SUM(AL24:AO24) -> 1561.665 | I24: =+SUM(AQ24:AT24) -> 1760.65 | J24: =+SUM(AV24:AY24) -> 1993.044 | K24: =+SUM(BA24:BD24) -> 2304.3809 | L24: =+'Income Statement'!BF13 -> 2574.9885 | M24: =+'Income Statement'!BG13 -> 2819.4317 | N24: =+'Income Statement'!BH13 -> 3036.2074 | O24: =+'Income Statement'!BI13 -> 3225.6636 | P24: =+'Income Statement'!BJ13 -> 3391.3179 | R24: =+'Income Statement'!R13 -> 174.29 | S24: =+'Income Statement'!S13 -> 185.419 | T24: =+'Income Statement'!T13 -> 196.791 | U24: =+D24-SUM(R24:T24) -> 200.5 | W24: =+'Income Statement'!W13 -> 215.987 | X24: =+'Income Statement'!X13 -> 236.059 | Y24: =+'Income Statement'!Y13 -> 254.18 | Z24: =+E24-SUM(W24:Y24) -> 278.681 | AB24: =+'Income Statement'!AB13 -> 304.112 | AC24: =+'Income Statement'!AC13 -> 316.406 | AD24: =+'Income Statement'!AD13 -> 320.797 | AE24: =+'Income Statement'!AE13 -> 328.342 | AG24: =+'Income Statement'!AG13 -> 341.597 | AH24: =+'Income Statement'!AH13 -> 345.224 | AI24: =+'Income Statement'!AI13 -> 345.805 | AJ24: =+'Income Statement'!AJ13 -> 355.04 | AK24: =SUM(AG24:AJ24) -> 1387.666 | AL24: =+'Income Statement'!AL13 -> 374.076 | AM24: =+'Income Statement'!AM13 -> 389.977 | AN24: =+'Income Statement'!AN13 -> 393.841 | AO24: =+'Income Statement'!AO13 -> 403.771 | AQ24: =+'Income Statement'!AQ13 -> 419.776 | AR24: =+'Income Statement'!AR13 -> 435.746 | AS24: =+'Income Statement'!AS13 -> 444.673 | AT24: =+'Income Statement'!AT13 -> 460.455 | AV24: =+'Income Statement'!AV13 -> 473.651 | AW24: =+'Income Statement'!AW13 -> 489.93 | AX24: =+'Income Statement'!AX13 -> 505.194 | AY24: =+'Income Statement'!AY13 -> 524.269 | BA24: =+'Income Statement'!BA13 -> 541.82232 | BB24: =+'Income Statement'!BB13 -> 563.34134 | BC24: =+'Income Statement'!BC13 -> 586.52045 | BD24: =+'Income Statement'!BD13 -> 612.6968
C25: YoY Growth | E25: =+E24/D24-1 -> 0.30106605 | F25: =+F24/E24-1 -> 0.28911359 | G25: =+G24/F24-1 -> 0.092945575 | H25: =+H24/G24-1 -> 0.12538968 | I25: =+I24/H24-1 -> 0.12741849 | J25: =+J24/I24-1 -> 0.1319933 | K25: =+K24/J24-1 -> 0.15621176 | L25: =+L24/K24-1 -> 0.1174318 | ... P25: =+P24/O24-1 -> 0.051355101 | W25: =+W24/R24-1 -> 0.2392392 | X25: =+X24/S24-1 -> 0.27311117 | Y25: =+Y24/T24-1 -> 0.29162411 | Z25: =+Z24/U24-1 -> 0.38993017 | AB25: =+AB24/W24-1 -> 0.40801067 | AC25: =+AC24/X24-1 -> 0.3403683 | AD25: =+AD24/Y24-1 -> 0.26208592 | AE25: =+AE24/Z24-1 -> 0.17820016 | AG25: =+AG24/AB24-1 -> 0.12326051 | AH25: =+AH24/AC24-1 -> 0.091079183 | AI25: =+AI24/AD24-1 -> 0.077955841 | AJ25: =+AJ24/AE24-1 -> 0.081311559 | AL25: =+AL24/AG24-1 -> 0.095079875 | AM25: =+AM24/AH24-1 -> 0.12963467 | AN25: =+AN24/AI24-1 -> 0.13891066 | AO25: =+AO24/AJ24-1 -> 0.13725496 | AQ25: =+AQ24/AL24-1 -> 0.12216769 | AR25: =+AR24/AM24-1 -> 0.11736333 | AS25: =+AS24/AN24-1 -> 0.12906731 | AT25: =+AT24/AO24-1 -> 0.14038651 | AV25: =+AV24/AQ24-1 -> 0.12834226 | AW25: =+AW24/AR24-1 -> 0.12434767 | AX25: =+AX24/AS24-1 -> 0.13610226 | AY25: =+AY24/AT24-1 -> 0.138589 | BA25: =+BA24/AV24-1 -> 0.14392733 | BB25: =+BB24/AW24-1 -> 0.14984047 | BC25: =+BC24/AX24-1 -> 0.16098063 | BD25: =+BD24/AY24-1 -> 0.16866875
C29: Partner BS | D29: =+D12 -> 6.51 | E29: =+E12 -> 50.82 | F29: =+F12 -> 130.275 | G29: =+G12 -> 164.881 | H29: =+H12 -> 222.585 | N29: =+N12 -> 688.65464 | O29: =+O12 -> 759.12714 | P29: =+P12 -> 823.8565 | Q29: =+(J29/G29)^(1/3)-1 -> -1
E30: =+E29/D29-1 -> 6.8064516 | F30: =+F29/E29-1 -> 1.5634593 | G30: =+G29/F29-1 -> 0.26563807 | H30: =+H29/G29-1 -> 0.34997362 | N30: =+N29/M29-1 -> #DIV/0! | O30: =+O29/N29-1 -> 0.10233358 | P30: =+P29/O29-1 -> 0.085268148
C31: Self Creator BS | D31: =+D33-D29 -> 110.086 | E31: =+E33-E29 -> 154.484 | F31: =+F33-F29 -> 189.083 | G31: =+G33-G29 -> 183.306 | H31: =+H33-H29 -> 187.073 | N31: =+N33-N29 -> 182.77337 | O31: =+O33-O29 -> 168.75299 | P31: =+P33-P29 -> 154.78873 | Q31: =+(J31/G31)^(1/3)-1 -> -1 | AO31: 237.5
E32: =+E31/D31-1 -> 0.40330287 | F32: =+F31/E31-1 -> 0.22396494 | G32: =+G31/F31-1 -> -0.03055272 | H32: =+H31/G31-1 -> 0.020550337 | N32: =+N31/M31-1 -> #DIV/0! | O32: =+O31/N31-1 -> -0.076709082 | P32: =+P31/O31-1 -> -0.082749705 | AO32: 205
C33: Business Solutions | D33: ='Income Statement'!V15 -> 116.596 | E33: ='Income Statement'!AA15 -> 205.304 | F33: ='Income Statement'!AF15 -> 319.358 | G33: ='Income Statement'!AK15 -> 348.187 | H33: ='Income Statement'!AP15 -> 409.658 | N33: ='Income Statement'!BH15 -> 871.42801 | O33: ='Income Statement'!BI15 -> 927.88013 | P33: ='Income Statement'!BJ15 -> 978.64523 | AO33: =+AO31/AO32-1 -> 0.15853659
E34: =+E33/D33-1 -> 0.76081512 | F34: =+F33/E33-1 -> 0.55553715 | G34: =+G33/F33-1 -> 0.090271733 | H34: =+H33/G33-1 -> 0.17654594 | N34: =+N33/M33-1 -> #DIV/0! | O34: =+O33/N33-1 -> 0.064781164 | P34: =+P33/O33-1 -> 0.054710844
C36: Partner CS | D36: =+D9 -> 86.49 | E36: =+E9 -> 103.18 | F36: =+F9 -> 139.725 | G36: =+G9 -> 183.299 | H36: =+H9 -> 246.015 | N36: =+N9 -> 610.69374 | O36: =+O9 -> 646.66386 | P36: =+P9 -> 674.06441 | Q36: =+(J36/G36)^(1/3)-1 -> -1
E37: =+E36/D36-1 -> 0.19297029 | F37: =+F36/E36-1 -> 0.35418686 | G37: =+G36/F36-1 -> 0.31185543 | H37: =+H36/G36-1 -> 0.34215135 | N37: =+N36/M36-1 -> #DIV/0! | O37: =+O36/N36-1 -> 0.058900426 | P37: =+P36/O36-1 -> 0.042372174
C38: Self Creator CS | D38: =+D20-D31 -> 553.914 | E38: =+E20-E31 -> 676.423 | F38: =+F20-F31 -> 810.574 | G38: =+G20-G31 -> 856.18 | H38: =+H20-H31 -> 905.992 | N38: =+N20-N31 -> 1554.0857 | O38: =+O20-O31 -> 1651.1196 | P38: =+P20-P31 -> 1738.6082 | Q38: =+(J38/G38)^(1/3)-1 -> -1
E39: =+E38/D38-1 -> 0.22116971 | F39: =+F38/E38-1 -> 0.19832413 | G39: =+G38/F38-1 -> 0.056263833 | H39: =+H38/G38-1 -> 0.058179355 | N39: =+N38/M38-1 -> #DIV/0! | O39: =+O38/N38-1 -> 0.062437952 | P39: =+P38/O38-1 -> 0.052987451
C40: Creative Subscriptions | D40: ='Income Statement'!V14 -> 644.492 | E40: ='Income Statement'!AA14 -> 783.456 | F40: ='Income Statement'!AF14 -> 950.299 | G40: ='Income Statement'!AK14 -> 1039.479 | H40: ='Income Statement'!AP14 -> 1152.007 | N40: ='Income Statement'!BH14 -> 2164.7794 | O40: ='Income Statement'!BI14 -> 2297.7835 | P40: ='Income Statement'!BJ14 -> 2412.6726
E41: =+E40/D40-1 -> 0.21561788 | F41: =+F40/E40-1 -> 0.21295772 | G41: =+G40/F40-1 -> 0.093844148 | H41: =+H40/G40-1 -> 0.10825423 | N41: =+N40/M40-1 -> #DIV/0! | O41: =+O40/N40-1 -> 0.06144 | P41: =+P40/O40-1 -> 0.05
D48: 2019 | E48: 2020 | F48: 2021 | G48: 2022 | H48: 2023E | I48: 2024E | J48: 2025E
C49: Total Users | D49: =+E49-31 -> 169 | E49: 200 | F49: 220 | G49: 243 | H49: 263
C50: YoY Growth | E50: =+E49/D49-1 -> 0.18343195 | F50: =+F49/E49-1 -> 0.1 | G50: =+G49/F49-1 -> 0.10454545 | H50: =+H49/G49-1 -> 0.082304527
C52: Premium Subs | E52: =+F52-0.478 -> 5.537 | F52: =+G52-0.096 -> 6.015 | G52: =+H52-0.189 -> 6.111 | H52: 6.3 | I52: 6.2 | J52: =+I52+0.5 -> 6.7 | K52: =+J52+0.5 -> 7.2
C53: YoY Growth | F53: =+F52/E52-1 -> 0.086328337 | G53: =+G52/F52-1 -> 0.0159601 | H53: =+H52/G52-1 -> 0.030927835 | I53: =+I52/H52-1 -> -0.015873016 | J53: =+J52/I52-1 -> 0.080645161 | K53: =+K52/J52-1 -> 0.074626866
C54: Average Subs | F54: =+AVERAGE(E52:F52) -> 5.776 | G54: =+AVERAGE(F52:G52) -> 6.063 | H54: =+AVERAGE(G52:H52) -> 6.2055 | I54: =+AVERAGE(H52:I52) -> 6.25 | J54: =+AVERAGE(I52:J52) -> 6.45 | K54: =+AVERAGE(J52:K52) -> 6.95
C55: YoY Growth | G55: =+G54/F54-1 -> 0.049688366 | H55: =+H54/G54-1 -> 0.023503216 | I55: =+I54/H54-1 -> 0.0071710579 | J55: =+J54/I54-1 -> 0.032 | K55: =+K54/J54-1 -> 0.07751938
N56: Price increase
C57: CS Revenue | F57: =+'Income Statement'!AF143 -> 950.299 | G57: =+'Income Statement'!AK143 -> 1039.479 | H57: =+'Income Statement'!AP143 -> 1152.007 | I57: =+'Income Statement'!AU143 -> 1264.975 | J57: =+'Income Statement'!AZ143 -> 1409.727 | K57: =+'Income Statement'!BE143 -> 1637.7591 | N57: early in '24
...

Sheet Balance Sheet
C3: ='Income Statement'!H2 -> Mar | D3: ='Income Statement'!I2 -> Jun | E3: ='Income Statement'!J2 -> Sep | F3: ='Income Statement'!K2 -> Dec | H3: ='Income Statement'!M2 -> Mar | I3: ='Income Statement'!N2 -> Jun | J3: ='Income Statement'!O2 -> Sep | K3: ='Income Statement'!P2 -> Dec | M3: ='Income Statement'!R2 -> Mar | N3: ='Income Statement'!S2 -> Jun | O3: ='Income Statement'!T2 -> Sep | P3: ='Income Statement'!U2 -> Dec | R3: ='Income Statement'!W2 -> Mar | S3: ='Income Statement'!X2 -> Jun | T3: ='Income Statement'!Y2 -> Sep | U3: ='Income Statement'!Z2 -> Dec | AB3: ='Income Statement'!AB2 -> Mar | AC3: ='Income Statement'!AC2 -> Jun | AD3: ='Income Statement'!AD2 -> Sep | AE3: ='Income Statement'!AE2 -> Dec | AG3: ='Income Statement'!AG2 -> Mar | AH3: ='Income Statement'!AH2 -> Jun | AI3: ='Income Statement'!AI2 -> Sep | AJ3: ='Income Statement'!AJ2 -> Dec | AL3: ='Income Statement'!AL2 -> Mar | AM3: ='Income Statement'!AM2 -> Jun | AN3: ='Income Statement'!AN2 -> Sep | AO3: ='Income Statement'!AO2 -> Dec | AQ3: ='Income Statement'!AQ2 -> Mar | AR3: ='Income Statement'!AR2 -> Jun | AS3: ='Income Statement'!AS2 -> Sep | AT3: ='Income Statement'!AT2 -> Dec | AV3: ='Income Statement'!AV2 -> Mar | AW3: ='Income Statement'!AW2 -> Jun | AX3: ='Income Statement'!AX2 -> Sep | AY3: ='Income Statement'!AY2 -> Dec | BA3: ='Income Statement'!BA2 -> Mar | BB3: ='Income Statement'!BB2 -> Jun | BC3: ='Income Statement'!BC2 -> Sep | BD3: ='Income Statement'!BD2 -> Dec
