Workbook
Name blank: #REF!
Name blank: #REF!
Name blank: #REF!
Name blank: #REF!
Name Current_Q: #REF!
Name Current_Q: #REF!
Name Current_Q: #REF!
Name Current_Q: #REF!
Name export: #REF!
Name export: #REF!
Name export: #REF!
Name export: #REF!
Name FY_92: #REF!
Name FY_92: #REF!
Name FY_92: #REF!
Name FY_92: #REF!
Name FY_93: #REF!
Name FY_93: #REF!
Name FY_93: #REF!
Name FY_94: #REF!
Name FY_94: #REF!
Name FY_94: #REF!
Name N_A: #REF!
Name N_A: #REF!
Name N_A: #REF!
Name N_A: #REF!
Name N_M: #REF!
Name N_M: #REF!
Name Next_Actual_Period_Range: '[16]Income Statement'!$D$3:$BE$6
Name NM_T: #REF!
Name NM_T: #REF!
Name NM_T: #REF!
Name NM_T: #REF!
Name Prior_Q: #REF!
Name Prior_Q: #REF!
Name Prior_Q: #REF!
Name Prior_Q: #REF!
Name Same_Q_Last_Yr: #REF!
Name Same_Q_Last_Yr: #REF!
Name Same_Q_Last_Yr: #REF!
Name Same_Q_Last_Yr: #REF!
Name source: #REF!
Name source: #REF!
Name source: #REF!
Name source: #REF!
Name SPR01A_18: #REF!
Name SPR01C_18: #REF!
Name WIZARD_3YRATCF: #REF!
Name WIZARD_3YRATCF: #REF!
Name WIZARD_3YRATCF: #REF!
Name WIZARD_3YRATCF: #REF!
Name WIZARD_3YREBITDA: #REF!
Name WIZARD_3YREBITDA: #REF!
Name WIZARD_3YREBITDA: #REF!
Name WIZARD_3YRSECGROWTH: #REF!
Name WIZARD_3YRSECGROWTH: #REF!
Name WIZARD_3YRSECGROWTH: #REF!
Name WIZARD_AVGTRADINGVOLUME: #REF!
Name WIZARD_BKVALSHR: #REF!
Name WIZARD_BURNRATE: #REF!

Sheet __FDSCACHE__
B1: This sheet contains FactSet XML data for use with this workbook's =FDS codes. Modifying the worksheet's contents may damage the workbook's =FDS functionality.

Sheet Comparison
B2: SPS Commerce (SPSC)
D5: =IS!CL3 -> 4Q24 | E5: =K5 -> 4Q25 | F5: % Change | G5: =IS!CP3 -> 3Q25 | H5: =K5 -> 4Q25 | I5: % Change | J5: 4Q25E | K5: =IS!CQ3 -> 4Q25 | L5: % Change
B6: Total Revenue | D6: =IS!CL4 -> 170907 | E6: =K6 -> 192652 | F6: =E6/D6-1 -> 0.12723294 | G6: =IS!CP4 -> 189904 | H6: =K6 -> 192652 | I6: =H6/G6-1 -> 0.014470469 | J6: 193547.39 | K6: =IS!CQ4 -> 192652 | L6: =K6/J6-1 -> -0.0046261819
B7: Cost of Revenue | D7: =IS!CL20 -> 52766 | E7: =K7 -> 55144 | F7: =E7/D7-1 -> 0.045066899 | G7: =IS!CP20 -> 54761 | H7: =K7 -> 55144 | I7: =H7/G7-1 -> 0.0069940286 | J7: 58451.31 | K7: =IS!CQ20 -> 55144 | L7: =K7/J7-1 -> -0.056582314
B8: Gross Profit | D8: =D6-D7 -> 118141 | E8: =E6-E7 -> 137508 | F8: =E8/D8-1 -> 0.16393123 | G8: =G6-G7 -> 135143 | H8: =K8 -> 137508 | I8: =H8/G8-1 -> 0.017499982 | J8: 135096.08 | K8: =K6-K7 -> 137508 | L8: =K8/J8-1 -> 0.017853405
C9: Gross Margins | D9: =D8/D6 -> 0.69125899 | E9: =K9 -> 0.71376368 | G9: =G8/G6 -> 0.71163851 | H9: =K9 -> 0.71376368 | J9: 0.698 | K9: =K8/K6 -> 0.71376368 | N9: =K9-D9*1000 -> -690.54523
B11: Operating Expenses
B12: Sales and marketing | D12: =IS!CL25 -> 36449 | E12: =K12 -> 40067 | F12: =E12/D12-1 -> 0.099261982 | G12: =IS!CP25 -> 38836 | H12: =K12 -> 40067 | I12: =H12/G12-1 -> 0.031697394 | J12: 40064.309 | K12: =IS!CQ25 -> 40067 | L12: =K12/J12-1 -> 6.7172457e-05 | N12: =K12-J12 -> 2.6912181
B13: Research and development | D13: =IS!CL27 -> 15049 | E13: =K13 -> 14797 | F13: =E13/D13-1 -> -0.016745299 | G13: =IS!CP27 -> 14922 | H13: =K13 -> 14797 | I13: =H13/G13-1 -> -0.0083768932 | J13: 16451.528 | K13: =IS!CQ27 -> 14797 | L13: =K13/J13-1 -> -0.10056985 | N13: =K13-J13 -> -1654.5278
B14: General and administrative | D14: =IS!CL29 -> 21744 | E14: =K14 -> 27969 | F14: =E14/D14-1 -> 0.28628587 | G14: =IS!CP29 -> 26248 | H14: =K14 -> 27969 | I14: =H14/G14-1 -> 0.0655669 | J14: 24580.518 | K14: =IS!CQ29 -> 27969 | L14: =K14/J14-1 -> 0.13785235 | N14: =K14-J14 -> 3388.4821
B15: Total Operating Expense | D15: =SUM(D12:D14) -> 73242 | E15: =K15 -> 82833 | F15: =E15/D15-1 -> 0.13094946 | G15: =SUM(G12:G14) -> 80006 | H15: =K15 -> 82833 | I15: =H15/G15-1 -> 0.03533485 | J15: 81096.354 | K15: =SUM(K12:K14) -> 82833 | L15: =K15/J15-1 -> 0.021414594
B17: Proforma Operating Income | D17: =D8-D15 -> 44899 | E17: =K17 -> 54675 | F17: =E17/D17-1 -> 0.21773313 | G17: =G8-G15 -> 55137 | H17: =K17 -> 54675 | I17: =H17/G17-1 -> -0.0083791284 | J17: 53999.721 | K17: =K8-K15 -> 54675 | L17: =K17/J17-1 -> 0.01250524 | N17: =K17-J17 -> 675.27947
C18: Proforma Operating Margins | D18: =D17/D6 -> 0.26271013 | E18: =K18 -> 0.28380188 | F18: =E18/D18-1 -> 0.080285265 | G18: =G17/G6 -> 0.29034144 | H18: =K18 -> 0.28380188 | I18: =H18/G18-1 -> -0.02252367 | J18: 0.279 | K18: =K17/K6 -> 0.28380188 | L18: =K18/J18-1 -> 0.017211043
B20: GAAP Adjustments | D20: =IS!CL40 -> 20155 | E20: =K20 -> 19989 | F20: =E20/D20-1 -> -0.0082361697 | G20: =IS!CP40 -> 23946 | H20: =K20 -> 19989 | I20: =H20/G20-1 -> -0.16524681 | J20: 24500 | K20: =IS!CQ40 -> 19989 | L20: =K20/J20-1 -> -0.18412245
B22: GAAP Operating Income | D22: =D17-D20 -> 24744 | E22: =K22 -> 34686 | F22: =E22/D22-1 -> 0.40179437 | G22: =G17-G20 -> 31191 | H22: =K22 -> 34686 | I22: =H22/G22-1 -> 0.11205155 | J22: 29499.721 | K22: =K17-K20 -> 34686 | L22: =K22/J22-1 -> 0.17580775
C23: GAAP Operating Margins | D23: =D22/D6 -> 0.14478049 | E23: =K23 -> 0.18004485 | F23: =E23/D23-1 -> 0.24357116 | G23: =G22/G6 -> 0.16424615 | H23: =K23 -> 0.18004485 | I23: =H23/G23-1 -> 0.096189181 | J23: 0.15241601 | K23: =K22/K6 -> 0.18004485 | L23: =K23/J23-1 -> 0.18127253
B25: Other Income | D25: =IS!CL47 -> -373 | E25: =K25 -> 1292 | F25: =E25/D25-1 -> -4.463807 | G25: =IS!CP47 -> 1260 | H25: =K25 -> 1292 | I25: =H25/G25-1 -> 0.025396825 | J25: 900 | K25: =IS!CQ47 -> 1292 | L25: =K25/J25-1 -> 0.43555556
B26: Non-GAAP Other Income | D26: =IS!CL50 -> 2234 | E26: =K26 -> 1036 | F26: =E26/D26-1 -> -0.53625783 | G26: =IS!CP50 -> 1065 | H26: =K26 -> 1036 | I26: =H26/G26-1 -> -0.027230047 | J26: 900 | K26: =IS!CQ50 -> 1036 | L26: =K26/J26-1 -> 0.15111111
B28: Proforma Income Before Taxes | D28: =IS!CL55 -> 47133 | E28: =K28 -> 55711 | F28: =E28/D28-1 -> 0.18199563 | G28: =IS!CP55 -> 56202 | H28: =K28 -> 55711 | I28: =H28/G28-1 -> -0.0087363439 | J28: 54899.721 | K28: =IS!CQ55 -> 55711 | L28: =K28/J28-1 -> 0.014777479
B29: Income Tax | D29: =IS!CL56 -> 13183 | E29: =K29 -> 12481 | F29: =E29/D29-1 -> -0.053250398 | G29: =IS!CP56 -> 13247 | H29: =K29 -> 12481 | I29: =H29/G29-1 -> -0.057824413 | J29: 16469.916 | K29: =IS!CQ56 -> 12481 | L29: =K29/J29-1 -> -0.24219408
B30: Proforma Net Income | D30: =D28-D29 -> 33950 | E30: =K30 -> 43230 | F30: =E30/D30-1 -> 0.27334315 | G30: =G28-G29 -> 42955 | H30: =K30 -> 43230 | I30: =H30/G30-1 -> 0.0064020487 | J30: 38429.804 | K30: =K28-K29 -> 43230 | L30: =K30/J30-1 -> 0.12490815
B32: GAAP Income Before Taxes | D32: =D22+D25 -> 24371 | E32: =K32 -> 35978 | F32: =E32/D32-1 -> 0.47626277 | G32: =G22+G25 -> 32451 | H32: =K32 -> 35978 | I32: =H32/G32-1 -> 0.10868694 | J32: 30399.721 | K32: =K22+K25 -> 35978 | L32: =K32/J32-1 -> 0.18349772
B33: Income Tax | D33: =IS!CL62 -> 6812 | E33: =K33 -> 10137 | F33: =E33/D33-1 -> 0.48810922 | G33: =IS!CP62 -> 6882 | H33: =K33 -> 10137 | I33: =H33/G33-1 -> 0.47297297 | J33: 9119.9162 | K33: =IS!CQ62 -> 10137 | L33: =K33/J33-1 -> 0.11152338
B34: GAAP Net Income | D34: =D32-D33 -> 17559 | E34: =K34 -> 25841 | F34: =E34/D34-1 -> 0.47166695 | G34: =G32-G33 -> 25569 | H34: =K34 -> 25841 | I34: =H34/G34-1 -> 0.010637882 | J34: 21279.804 | K34: =K32-K33 -> 25841 | L34: =K34/J34-1 -> 0.21434387
B35: Proforma EPS | D35: =D30/D37 -> 0.89681953 | E35: =K35 -> 1.1447713 | F35: =E35/D35-1 -> 0.27647905 | G35: =G30/G37 -> 1.130603 | H35: =K35 -> 1.1447713 | I35: =H35/G35-1 -> 0.012531659 | J35: 1.0035726 | K35: =K30/K37 -> 1.1447713 | L35: =K35/J35-1 -> 0.14069612 | N35: =K35-J35 -> 0.14119877
B36: GAAP EPS | D36: =D34/D37 -> 0.46383664 | E36: =K36 -> 0.68429415 | F36: =E36/D36-1 -> 0.47529127 | G36: =G34/G37 -> 0.67299239 | H36: =H34/H37 -> 0.68429415 | I36: =H36/G36-1 -> 0.016793291 | J36: 0.55571004 | K36: =K34/K37 -> 0.68429415 | L36: =K36/J36-1 -> 0.23138707
B37: Diluted Shares Outstanding | D37: =IS!CL73 -> 37856 | E37: =K37 -> 37763 | F37: =E37/D37-1 -> -0.0024566779 | G37: =IS!CP73 -> 37993 | H37: =K37 -> 37763 | I37: =H37/G37-1 -> -0.0060537467 | J37: 38293 | K37: =IS!CQ73 -> 37763 | L37: =K37/J37-1 -> -0.01384065
B39: Source: Company reports and Needham & Co estimates

Sheet Guidance
D4: Prior FY26 Guide | E4: New FY26 Guide | F4: Delta | G4: 3Q26 Guide | H4: =LEFT(G4,4)&" Result" -> 3Q26 Result | I4: =LEFT(G4,4)&" Beat" -> 3Q26 Beat | J4: Rest of Year Raise / (Reduce)
C5: Revenue | D5: =IS!CR4*1.075/1000 -> 807.86788 | E5: =AVERAGE(798.5,806.9) -> 802.7 | F5: =E5-D5 -> -5.167875 | G5: =AVERAGE(191.7,193.2) -> 192.45 | H5: =Comparison!K6/1000 -> 192.652 | I5: =H5-G5 -> 0.202 | J5: =F5-I5 -> -5.369875
C6: Growth | D6: =D5/(IS!CR4/1000)-1 -> 0.075 | E6: =E5/(IS!CR4/1000)-1 -> 0.068123299
C7: Adj EBITDA | D7: =D8*D5 -> 264.87688 | E7: 263.25 | F7: =E7-D7 -> -1.6268825 | G7: =AVERAGE(57.9,59.9) -> 58.9 | H7: =IS!CP52/1000 -> 60.48 | I7: =H7-G7 -> 1.58 | J7: =F7-I7 -> -3.2068825
C8: Margin | D8: =IS!CR53+0.02 -> 0.32787154 | E8: =E7/E5 -> 0.32795565
C9: Non-GAAP EPS | D9: N/A | E9: 4.46 | F9: N/A | G9: 0.98 | H9: =Comparison!K35 -> 1.1447713 | I9: =H9-G9 -> 0.16477134 | J9: =F9-I9 -> #VALUE!

Sheet IS
B2: SPS Commerce (SPSC)
B3: Income Statement | D3: 2005 | E3: 2006 | F3: 2007 | G3: 1Q08 | H3: 2Q08 | I3: 2Q08 | J3: 4Q08 | K3: 2008 | L3: 1Q09 | M3: 2Q09 | N3: 2Q09 | O3: 4Q09 | P3: 2009 | Q3: 1QA10 | R3: 2QA10 | S3: 3Q10 | T3: 4Q10 | U3: 2010 | V3: 1Q11 | W3: 2Q11 | X3: 3Q11 | Y3: 4Q11 | Z3: 2011 | AA3: 1Q12 | AB3: 2Q12 | AC3: 3Q12 | AD3: 4Q12 | AE3: 2012 | AF3: 1Q13 | AG3: 2Q13 | AH3: 3Q13 | AI3: 4Q13 | AJ3: 2013 | AK3: 1Q14 | AL3: 2Q14 | AM3: 3Q14 | AN3: 4Q14 | AO3: 2014 | AP3: 1Q15 | AQ3: 2Q15 | AR3: 3Q15 | AS3: 4Q15 | AT3: 2015 | AU3: 1Q16 | AV3: 2Q16 | AW3: 3Q16 | AX3: 4Q16 | AY3: 2016 | AZ3: 1Q17 | BA3: 2Q17 | BB3: 3Q17 | BC3: 4Q17 | BD3: 2017 | BE3: 1Q18 | BF3: 2Q18 | BG3: 3Q18 | BH3: 4Q18 | BI3: 2018 | BJ3: 1Q19 | BK3: 2Q19 | BL3: 3Q19 | BM3: 4Q19 | BN3: 2019 | BO3: 1Q20 | BP3: 2Q20 | BQ3: 3Q20 | BR3: 4Q20 | BS3: 2020 | BT3: 1Q21 | BU3: 2Q21 | BV3: 3Q21 | BW3: 4Q21 | BX3: 2021 | BY3: 1Q22 | BZ3: 2Q22 | CA3: 3Q22 | CB3: 4Q22 | CC3: 2022 | CD3: 1Q23 | CE3: 2Q23 | CF3: 3Q23 | CG3: 4Q23 | CH3: 2023 | CI3: 1Q24 | CJ3: 2Q24 | CK3: 3Q24 | CL3: 4Q24 | CM3: 2024 | CN3: 1Q25 | CO3: 2Q25 | CP3: 3Q25 | CQ3: 4Q25 | CR3: 2025 | CS3: 1Q26E | CT3: 2Q26E | CU3: 3Q26E | CV3: 4Q26E | CW3: 2026E
B4: Total Revenue | D4: 13827 | E4: 19859 | F4: 25198 | G4: 6957 | H4: 7586 | I4: 8074 | J4: 8080 | K4: =SUM(G4:J4) -> 30697 | L4: 8531 | M4: 9600 | N4: 9634 | O4: 9981 | P4: =SUM(L4:O4) -> 37746 | Q4: 10243 | R4: 10944 | S4: 11491 | T4: 11919 | U4: =SUM(Q4:T4) -> 44597 | V4: 12649 | W4: 13937 | X4: 15529 | Y4: 15854 | Z4: =SUM(V4:Y4) -> 57969 | AA4: 16534 | AB4: 17821 | AC4: 20267 | AD4: 22484 | AE4: =SUM(AA4:AD4) -> 77106 | AF4: 23752 | AG4: 25658 | AH4: 27008 | AI4: 27973 | AJ4: =SUM(AF4:AI4) -> 104391 | AK4: 28939 | AL4: 31100 | AM4: 32506 | AN4: 35402 | AO4: =SUM(AK4:AN4) -> 127947 | AP4: 36970 | AQ4: 38846 | AR4: 40354 | AS4: 42348 | AT4: =SUM(AP4:AS4) -> 158518 | AU4: 45599 | AV4: 47351 | AW4: 49284 | AX4: 51061 | AY4: =SUM(AU4:AX4) -> 193295 | AZ4: 51932 | BA4: 54284 | BB4: 56150 | BC4: 58200 | BD4: =SUM(AZ4:BC4) -> 220566 | BE4: 59092 | BF4: 61091 | BG4: 62868 | BH4: 65189 | BI4: =SUM(BE4:BH4) -> 248240 | BJ4: 66934 | BK4: 68529 | BL4: 70928 | BM4: 72733 | BN4: =SUM(BJ4:BM4) -> 279124 | BO4: 74192 | BP4: 75573 | BQ4: =79557 -> 79557 | BR4: 83308 | BS4: =SUM(BO4:BR4) -> 312630 | BT4: 90094 | BU4: 94539 | BV4: 97887 | BW4: 102756 | BX4: =SUM(BT4:BW4) -> 385276 | BY4: 105193 | BZ4: 109178 | CA4: 114486 | CB4: 122018 | CC4: =SUM(BY4:CB4) -> 450875 | CD4: 125868 | CE4: 130416 | CF4: 135661 | CG4: 144965 | CH4: =SUM(CD4:CG4) -> 536910 | CI4: 149576 | CJ4: 153596 | CK4: 163686 | CL4: 170907 | CM4: =SUM(CI4:CL4) -> 637765 | CN4: 181549 | CO4: 187400 | CP4: 189904 | CQ4: 192652 | CR4: =SUM(CN4:CQ4) -> 751505 | CS4: =CS7+CS16 -> 192631.61 | CT4: =CT7+CT16 -> 197698.72 | CU4: =CU7+CU16 -> 204419.39 | CV4: =CV7+CV16 -> 207966.86 | CW4: =SUM(CS4:CV4) -> 802716.59
C5: Y/Y Growth | E5: =E4/D4-1 -> 0.43624792 | F5: =F4/E4-1 -> 0.26884536 | K5: =K4/F4-1 -> 0.21823161 | L5: =L4/G4-1 -> 0.22624695 | M5: =M4/H4-1 -> 0.26548906 | N5: =N4/I4-1 -> 0.19321278 | O5: =O4/J4-1 -> 0.23527228 | P5: =P4/K4-1 -> 0.22963156 | Q5: =Q4/L4-1 -> 0.20067987 | R5: =R4/M4-1 -> 0.14 | ... CW5: =CW4/CR4-1 -> 0.068145371
C6: Q/Q Growth | H6: =H4/G4-1 -> 0.090412534 | I6: =I4/H4-1 -> 0.064329027 | J6: =J4/I4-1 -> 0.00074312608 | L6: =L4/J4-1 -> 0.055816832 | M6: =M4/L4-1 -> 0.1253077 | N6: =N4/M4-1 -> 0.0035416667 | O6: =O4/N4-1 -> 0.036018269 | Q6: =Q4/O4-1 -> 0.026249875 | R6: =R4/Q4-1 -> 0.068436981 | S6: =S4/R4-1 -> 0.049981725 | T6: =T4/S4-1 -> 0.037246541 | V6: =V4/T4-1 -> 0.061246749 | W6: =W4/V4-1 -> 0.10182623 | X6: =X4/W4-1 -> 0.11422831 | Y6: =Y4/X4-1 -> 0.020928585 | AA6: =AA4/Y4-1 -> 0.042891384 | AB6: =AB4/AA4-1 -> 0.077839603 | AC6: =AC4/AB4-1 -> 0.1372538 | AD6: =AD4/AC4-1 -> 0.10938965 | AF6: =AF4/AD4-1 -> 0.056395659 | AG6: =AG4/AF4-1 -> 0.080245874 | AH6: =AH4/AG4-1 -> 0.052615169 | AI6: =AI4/AH4-1 -> 0.035730154 | AK6: =AK4/AI4-1 -> 0.0345333 | AL6: =AL4/AK4-1 -> 0.074674315 | AM6: =AM4/AL4-1 -> 0.045209003 | AN6: =AN4/AM4-1 -> 0.089091245 | AP6: =AP4/AN4-1 -> 0.044291283 | AQ6: =AQ4/AP4-1 -> 0.050743846 | AR6: =AR4/AQ4-1 -> 0.038819956 | AS6: =AS4/AR4-1 -> 0.049412698 | AU6: =AU4/AS4-1 -> 0.076768679 | AV6: =AV4/AU4-1 -> 0.038421895 | AW6: =AW4/AV4-1 -> 0.040822791 | AX6: =AX4/AW4-1 -> 0.036056327 | AZ6: =AZ4/AX4-1 -> 0.017058029 | BA6: =BA4/AZ4-1 -> 0.045289995 | BB6: =BB4/BA4-1 -> 0.03437477 | BC6: =BC4/BB4-1 -> 0.03650935 | BE6: =BE4/BC4-1 -> 0.01532646 | BF6: =BF4/BE4-1 -> 0.033828606 | BG6: =BG4/BF4-1 -> 0.029087754 | BH6: =BH4/BG4-1 -> 0.036918623 | BJ6: =BJ4/BH4-1 -> 0.02676832 | BK6: =BK4/BJ4-1 -> 0.023829444 | BL6: =BL4/BK4-1 -> 0.035007077 | BM6: =BM4/BL4-1 -> 0.025448342 | BO6: =BO4/BM4-1 -> 0.02005967 | BP6: =BP4/BO4-1 -> 0.018613867 | BQ6: =BQ4/BP4-1 -> 0.05271724 | BR6: =BR4/BQ4-1 -> 0.047148585 | BT6: =BT4/BR4-1 -> 0.081456763 | BU6: =BU4/BT4-1 -> 0.049337359 | BV6: =BV4/BU4-1 -> 0.035413956 | BW6: =BW4/BV4-1 -> 0.049741028 | BY6: =BY4/BW4-1 -> 0.023716377 | BZ6: =BZ4/BY4-1 -> 0.037882749 | CA6: =CA4/BZ4-1 -> 0.048617853 | CB6: =CB4/CA4-1 -> 0.065789704 | CD6: =CD4/CB4-1 -> 0.031552722 | CE6: =CE4/CD4-1 -> 0.036133092 | CF6: =CF4/CE4-1 -> 0.040217458 | CG6: =CG4/CF4-1 -> 0.068582717 | CI6: =CI4/CG4-1 -> 0.031807678 | CJ6: =CJ4/CI4-1 -> 0.026875969 | CK6: =CK4/CJ4-1 -> 0.065691815 | CL6: =CL4/CK4-1 -> 0.044114952 | CN6: =CN4/CL4-1 -> 0.062267783 | CO6: =CO4/CN4-1 -> 0.032228214 | CP6: =CP4/CO4-1 -> 0.013361793 | CQ6: =CQ4/CP4-1 -> 0.014470469 | CS6: =CS4/CQ4-1 -> -0.00010581515 | CT6: =CT4/CS4-1 -> 0.026304641 | CU6: =CU4/CT4-1 -> 0.033994498 | CV6: =CV4/CU4-1 -> 0.017353908
C7: Organic Revenue | V7: =V4 -> 12649 | W7: =W4-W9 -> 13687 | X7: =X4-X9 -> 14579 | Y7: =Y4-Y9 -> 14904 | Z7: =SUM(V7:Y7) -> 55819 | AA7: =AA4-AA9 -> 15584 | AB7: =AB4-AB9 -> 17221 | AC7: =AC4-AC9 -> 18467 | AD7: =AD4-AD9 -> 19384 | AE7: =SUM(AA7:AD7) -> 70656 | AF7: =AF4-AF9 -> 20752 | AG7: =AG4-AG9 -> 22658 | AH7: =AH4-AH9 -> 25508 | AI7: =AI4-AI9 -> 27973 | AJ7: =SUM(AF7:AI7) -> 96891 | AK7: =AK4-AK9 -> 28939 | AL7: =AL4-AL9 -> 31100 | AM7: =AM4-AM9 -> 32506 | AN7: =AN4-AN9 -> 35402 | AO7: =SUM(AK7:AN7) -> 127947 | AP7: =AP4-AP9 -> 36970 | AQ7: =AQ4-AQ9 -> 38846 | AR7: =AR4-AR9 -> 40354 | AS7: =AS4-AS9 -> 42348 | AT7: =SUM(AP7:AS7) -> 158518 | AU7: =AU14+AU18 -> 44031.51 | AV7: =AV14+AV18 -> 45500.915 | AW7: =AW14+AW18 -> 46907.624 | AX7: =AX14+AX18 -> 48781.036 | AY7: =SUM(AU7:AX7) -> 185221.08 | AZ7: =AZ14+AZ18 -> 51932 | BA7: =BA14+BA18 -> 54284 | BB7: =BB14+BB18 -> 56150 | BC7: =BC14+BC18 -> 58200 | BD7: =SUM(AZ7:BC7) -> 220566 | BE7: =BE14+BE18 -> 59092 | BF7: =BF14+BF18 -> 61091 | BG7: =BG14+BG18 -> 62868 | BH7: =BH14+BH18 -> 65189 | BI7: =SUM(BE7:BH7) -> 248240 | BJ7: =BJ14+BJ18 -> 65809 | BK7: =BK14+BK18 -> 67404 | BL7: =BL14+BL18 -> 69803 | BM7: =BM14+BM18 -> 71733 | BN7: =SUM(BJ7:BM7) -> 274749 | BO7: =BO14+BO18 -> 74192 | BP7: =BP14+BP18 -> 75573 | BQ7: =BQ14+BQ18 -> 79557 | BR7: =BR14+BR18 -> 83308 | BS7: =SUM(BO7:BR7) -> 312630 | BT7: =BT14+BT18 -> 88644 | BU7: =BU14+BU18 -> 92639 | BV7: =BV14+BV18 -> 95537 | BW7: =BW14+BW18 -> 99406 | BX7: =SUM(BT7:BW7) -> 376226 | BY7: =BY14+BY18 -> 104493 | BZ7: =BZ14+BZ18 -> 108428 | CA7: =CA14+CA18 -> 112736 | CB7: =CB14+CB18 -> 118268 | CC7: =SUM(BY7:CB7) -> 443925 | CD7: =CD14+CD18 -> 122368 | CE7: =CE14+CE18 -> 126641 | CF7: =CF14+CF18 -> 132711 | CG7: =CG14+CG18 -> 138765 | CH7: =SUM(CD7:CG7) -> 520485 | CI7: =CI14+CI18 -> 145576 | CJ7: =CJ14+CJ18 -> 148996 | CK7: =CK14+CK18 -> 160736 | CL7: =CL14+CL18 -> 164707 | CM7: =SUM(CI7:CL7) -> 620015 | CN7: =CN14+CN18 -> 167349 | CO7: =CO14+CO18 -> 170950 | CP7: =CP14+CP18 -> 177654 | CQ7: =CQ14+CQ18 -> 182952 | CR7: =SUM(CN7:CQ7) -> 698905 | CS7: =CS14+CS18 -> 188631.61 | CT7: =CT14+CT18 -> 197698.72 | CU7: =CU14+CU18 -> 204419.39 | CV7: =CV14+CV18 -> 207966.86 | CW7: =SUM(CS7:CV7) -> 798716.59
C8: y/y growth | W8: =W7/R4-1 -> 0.25063962 | X8: =X7/S4-1 -> 0.26873205 | Y8: =Y7/T4-1 -> 0.25044047 | Z8: =Z7/U4-1 -> 0.25163128 | AA8: =AA7/V4-1 -> 0.23203415 | AB8: =AB7/W4-1 -> 0.23563177 | AC8: =AC7/X4-1 -> 0.18919441 | AD8: =AD7/Y4-1 -> 0.22265674 | ... AT8: =AT7/AO4-1 -> 0.23893487 | AU8: =AU7/AP7-1 -> 0.19100649 | AV8: =AV7/AQ7-1 -> 0.17131532 | AW8: =AW7/AR7-1 -> 0.16240333 | AX8: =AX7/AS7-1 -> 0.15190884 | AY8: =AY7/AT4-1 -> 0.16845459 | AZ8: =AZ7/AU4-1 -> 0.13888462 | BA8: =BA7/AV4-1 -> 0.14641718 | BB8: =BB7/AW4-1 -> 0.13931499 | BC8: =BC7/AX4-1 -> 0.13981316 | BD8: =BD7/AY4-1 -> 0.14108487 | BE8: =BE7/AZ4-1 -> 0.1378726 | BF8: =BF7/BA4-1 -> 0.12539607 | ... CW8: =CW7/CR4-1 -> 0.062822719
V9: DirectEDI | W9: 250 | X9: 950 | Y9: 950 | Z9: =SUM(V9:Y9) -> 2150 | AA9: 950 | AB9: 600 | AC9: 1800 | AD9: 3100 | AE9: =SUM(AA9:AD9) -> 6450 | AF9: 3000 | AG9: 3000 | AH9: 1500 | AJ9: =SUM(AF9:AI9) -> 7500 | AO9: =SUM(AK9:AN9) -> 0 | AT9: =SUM(AP9:AS9) -> 0
C10: Recurring revenue | K10: =K11*K4 -> 25478.51 | L10: =L11*L4 -> 6910.11 | M10: =M11*M4 -> 7488 | N10: =N11*N4 -> 7803.54 | O10: =P10-(L10+M10+N10) -> 7995.15 | P10: =P11*P4 -> 30196.8 | Q10: =Q11*Q4 -> 8399.26 | R10: =R11*R4 -> 9083.52 | S10: =S11*S4 -> 9652.44 | T10: =U10-(Q10+R10+S10) -> 10326.26 | U10: =U11*U4 -> 37461.48 | V10: =V11*V4 -> 10498.67 | W10: =W11*W4 -> 11707.08 | X10: =X11*X4 -> 13199.65 | Y10: =Z10-(V10+W10+X10) -> 13868.25 | Z10: =Z11*Z4 -> 49273.65 | AA10: =AA11*AA4 -> 14384.58 | AB10: =AB11*AB4 -> 15326.06 | AC10: =AC11*AC4 -> 17834.96 | AD10: =AE10-(AA10+AB10+AC10) -> 20307.68 | AE10: =AE11*AE4 -> 67853.28 | AF10: =AF4*AF11 -> 21139.28 | AG10: =AG4*AG11 -> 22579.04 | AH10: =AH4*AH11 -> 24037.12 | AI10: =AJ10-(AF10+AG10+AH10) -> 25152.55 | AJ10: =AJ11*AJ4 -> 92907.99 | AK10: =AK4*AK11 -> 26001.314 | AL10: =AL4*AL11 -> 28087.813 | AM10: =AM4*AM11 -> 29325.286 | AN10: =AO10-(AK10+AL10+AM10) -> 31737.887 | AO10: =AO11*AO4 -> 115152.3 | AP10: =AP4*AP11 -> 33273 | AQ10: =AQ4*AQ11 -> 35349.86 | AR10: =AR4*AR11 -> 36722.14 | AS10: =AT10-(AP10+AQ10+AR10) -> 38589.344 | AT10: =AT11*AT4 -> 143934.34 | AU10: =AU11*AU4 -> 41495.09 | AV10: =AV11*AV4 -> 43562.92 | AW10: =AW11*AW4 -> 45341.28 | AX10: =AY10-(AU10+AV10+AW10) -> 46657.71 | AY10: 177057 | AZ10: =AZ11*AZ4 -> 47777.44 | BA10: =BA11*BA4 -> 49941.28 | BB10: =BB11*BB4 -> 51658 | BC10: =BD10-(AZ10+BA10+BB10) -> 54543.28 | BD10: 203920 | BE10: 54860 | BF10: 56430 | BG10: 58644 | BH10: =BI10-(BE10+BF10+BG10) -> 60720 | BI10: =230654 -> 230654 | BJ10: =BJ4*BJ11 -> 62917.96 | BK10: =BK4*BK11 -> 64417.26 | BL10: =BL4*BL11 -> 66672.32 | BM10: =BM4*BM11 -> 68369.02 | BN10: =SUM(BJ10:BM10) -> 262376.56 | BO10: =BO11*BO4 -> 69740.48 | BP10: =BP11*BP4 -> 71038.62 | BQ10: =BQ11*BQ4 -> 75579.15 | BR10: =BR11*BR4 -> 78309.52 | BS10: =SUM(BO10:BR10) -> 294667.77 | BT10: =BT4*BT11 -> 82886.48 | BU10: =BU11*BU4 -> 86975.88 | BV10: =BV11*BV4 -> 90056.04 | BW10: =BW11*BW4 -> 94535.52 | BX10: =SUM(BT10:BW10) -> 354453.92 | BY10: 97567 | BZ10: 101163 | CA10: 106553 | CB10: =419047-SUM(BY10:CA10) -> 113764 | CC10: =SUM(BY10:CB10) -> 419047 | CD10: 117301 | CE10: 121523 | CF10: 127371 | CG10: =502013-SUM(CD10:CF10) -> 135818 | CH10: =SUM(CD10:CG10) -> 502013 | CI10: 139684 | CJ10: =CJ11*CJ4 -> 144380.24 | CK10: =CK4*CK11 -> 153864.84 | CL10: =CG10*1.19 -> 161623.42 | CM10: =SUM(CI10:CL10) -> 599552.5 | CN10: 172329 | CO10: =CO11*CO4 -> 179904 | CP10: =CP11*CP4 -> 182307.84 | CQ10: =CQ11*CQ4 -> 184945.92 | CR10: =SUM(CN10:CQ10) -> 719486.76 | CS10: =CS14+CS16 -> 185031.61 | CT10: =CT14+CT16 -> 189798.72 | CU10: =CU14+CU16 -> 195069.39 | CV10: =CV14+CV16 -> 198816.86 | CW10: =SUM(CS10:CV10) -> 768716.59
C11: % ot total Rev | K11: 0.83 | L11: 0.81 | M11: 0.78 | N11: 0.81 | O11: 0.82 | P11: 0.8 | Q11: 0.82 | R11: 0.83 | S11: 0.84 | T11: =T10/T4 -> 0.86636966 | U11: 0.84 | V11: 0.83 | W11: 0.84 | X11: 0.85 | Y11: =Y10/Y4 -> 0.8747477 | Z11: 0.85 | AA11: 0.87 | AB11: 0.86 | AC11: 0.88 | AD11: =AD10/AD4 -> 0.90320584 | AE11: 0.88 | AF11: 0.89 | AG11: 0.88 | AH11: 0.89 | AI11: =AI10/AI4 -> 0.89917242 | AJ11: 0.89 | AK11: 0.89848697 | AL11: 0.9031451 | AM11: 0.90214995 | AN11: =AN10/AN4 -> 0.89649982 | AO11: 0.9 | AP11: 0.9 | AQ11: 0.91 | AR11: 0.91 | AS11: =AS10/AS4 -> 0.9112436 | AT11: 0.908 | AU11: 0.91 | AV11: 0.92 | AW11: 0.92 | AX11: =AX10/AX4 -> 0.91376413 | AY11: =AY10/AY4 -> 0.91599369 | AZ11: 0.92 | BA11: 0.92 | BB11: 0.92 | BC11: =BC10/BC4 -> 0.93716976 | BD11: =BD10/BD4 -> 0.92453053 | BE11: =BE10/BE4 -> 0.92838286 | BF11: =BF10/BF4 -> 0.92370398 | BG11: =BG10/BG4 -> 0.93281161 | BH11: =BH10/BH4 -> 0.93144549 | BI11: =BI10/BI4 -> 0.92915727 | BJ11: 0.94 | BK11: 0.94 | BL11: 0.94 | BM11: 0.94 | BO11: 0.94 | BP11: 0.94 | BQ11: 0.95 | BR11: 0.94 | BT11: 0.92 | BU11: 0.92 | BV11: 0.92 | BW11: 0.92 | BY11: =BY10/BY4 -> 0.92750468 | BZ11: =BZ10/BZ4 -> 0.92658777 | CA11: =CA10/CA4 -> 0.93070768 | CB11: =CB10/CB4 -> 0.93235424 | CD11: =CD10/CD4 -> 0.93193663 | CE11: =CE10/CE4 -> 0.93181051 | CF11: =CF10/CF4 -> 0.9388918 | CG11: =CG10/CG4 -> 0.93690201 | CI11: =CI10/CI4 -> 0.9338664 | CJ11: 0.94 | CK11: 0.94 | CL11: =CL10/CL4 -> 0.94568052 | CN11: 0.95 | CO11: 0.96 | CP11: 0.96 | CQ11: 0.96 | CS11: =CS10/CS4 -> 0.96054646 | CT11: =CT10/CT4 -> 0.96004021 | CU11: =CU10/CU4 -> 0.9542607 | CV11: =CV10/CV4 -> 0.95600261
C12: Y/Y Growth | K12: =K10/F10-1 -> #DIV/0! | L12: =L10/G10-1 -> #DIV/0! | M12: =M10/H10-1 -> #DIV/0! | N12: =N10/I10-1 -> #DIV/0! | O12: =O10/J10-1 -> #DIV/0! | P12: =P10/K10-1 -> 0.18518705 | Q12: =Q10/L10-1 -> 0.21550308 | R12: =R10/M10-1 -> 0.21307692 | ... CW12: =CW10/CR10-1 -> 0.068423535
C13: Q/Q Growth | L13: =L4/J4-1 -> 0.055816832 | M13: =M4/L4-1 -> 0.1253077 | N13: =N4/M4-1 -> 0.0035416667 | O13: =O4/N4-1 -> 0.036018269 | Q13: =Q4/O4-1 -> 0.026249875 | R13: =R4/Q4-1 -> 0.068436981 | S13: =S4/R4-1 -> 0.049981725 | T13: =T4/S4-1 -> 0.037246541 | V13: =V4/T4-1 -> 0.061246749 | W13: =W4/V4-1 -> 0.10182623 | X13: =X4/W4-1 -> 0.11422831 | Y13: =Y4/X4-1 -> 0.020928585 | AA13: =AA4/Y4-1 -> 0.042891384 | AB13: =AB4/AA4-1 -> 0.077839603 | AC13: =AC4/AB4-1 -> 0.1372538 | AD13: =AD4/AC4-1 -> 0.10938965 | AF13: =AF10/AD10-1 -> 0.040950025 | AG13: =AG10/AF10-1 -> 0.06810828 | AH13: =AH10/AG10-1 -> 0.064576705 | AI13: =AI10/AH10-1 -> 0.046404478 | AK13: =AK10/AI10-1 -> 0.033744666 | AL13: =AL10/AK10-1 -> 0.080245874 | AM13: =AM10/AL10-1 -> 0.044057322 | AN13: =AN10/AM10-1 -> 0.082270303 | AP13: =AP10/AN10-1 -> 0.048368482 | AQ13: =AQ10/AP10-1 -> 0.062418778 | AR13: =AR10/AQ10-1 -> 0.038819956 | AS13: =AS10/AR10-1 -> 0.050846819 | AU13: =AU4/AS4-1 -> 0.076768679 | AV13: =AV4/AU4-1 -> 0.038421895 | AW13: =AW4/AV4-1 -> 0.040822791 | AX13: =AX4/AW4-1 -> 0.036056327 | AZ13: =AZ4/AX4-1 -> 0.017058029 | BA13: =BA4/AZ4-1 -> 0.045289995 | BB13: =BB4/BA4-1 -> 0.03437477 | BC13: =BC4/BB4-1 -> 0.03650935 | BE13: =BE4/BC4-1 -> 0.01532646 | BF13: =BF4/BE4-1 -> 0.033828606 | BG13: =BG4/BF4-1 -> 0.029087754 | BH13: =BH4/BG4-1 -> 0.036918623 | BJ13: =BJ4/BH4-1 -> 0.02676832 | BK13: =BK4/BJ4-1 -> 0.023829444 | BL13: =BL4/BK4-1 -> 0.035007077 | BM13: =BM4/BL4-1 -> 0.025448342 | BO13: =BO4/BM4-1 -> 0.02005967 | BP13: =BP4/BO4-1 -> 0.018613867 | BQ13: =BQ4/BP4-1 -> 0.05271724 | BR13: =BR4/BQ4-1 -> 0.047148585 | BT13: =BT4/BR4-1 -> 0.081456763 | BU13: =BU4/BT4-1 -> 0.049337359 | BV13: =BV4/BU4-1 -> 0.035413956 | BW13: =BW4/BV4-1 -> 0.049741028 | BY13: =BY4/BW4-1 -> 0.023716377 | BZ13: =BZ4/BY4-1 -> 0.037882749 | CA13: =CA4/BZ4-1 -> 0.048617853 | CB13: =CB4/CA4-1 -> 0.065789704 | CD13: =CD4/CB4-1 -> 0.031552722 | CE13: =CE4/CD4-1 -> 0.036133092 | CF13: =CF4/CE4-1 -> 0.040217458 | CG13: =CG4/CF4-1 -> 0.068582717 | CI13: =CI4/CG4-1 -> 0.031807678 | CJ13: =CJ4/CI4-1 -> 0.026875969 | CK13: =CK4/CJ4-1 -> 0.065691815 | CL13: =CL4/CK4-1 -> 0.044114952 | CN13: =CN4/CL4-1 -> 0.062267783 | CO13: =CO4/CN4-1 -> 0.032228214 | CP13: =CP4/CO4-1 -> 0.013361793 | CQ13: =CQ4/CP4-1 -> 0.014470469 | CS13: =CS4/CQ4-1 -> -0.00010581515 | CT13: =CT4/CS4-1 -> 0.026304641 | CU13: =CU4/CT4-1 -> 0.033994498 | CV13: =CV4/CU4-1 -> 0.017353908
C14: Organic Recurring revenue | W14: =R10*(1+W15) -> 11263.565 | X14: =S10*(1+X15) -> 12065.55 | Y14: =T10*(1+Y15) -> 12907.825 | AA14: =V10*(1+AA15) -> 13333.311 | AB14: =W10*(1+AB15) -> 14750.921 | AC14: =X10*(1+AC15) -> 16103.573 | AD14: =Y10*(1+AD15) -> 17196.63 | AE14: =Z10*(1+AE15) -> 61099.326 | AF14: =AA10*(1+AF15) -> 17836.879 | AG14: =AB10*(1+AG15) -> 19310.836 | AH14: =AC10*(1+AH15) -> 22472.05 | AN14: =AI10*(1+AN15) -> 31189.162 | AP14: =AK10*(1+AP15) -> 32241.63 | AQ14: =AL10*(1+AQ15) -> 34267.131 | AR14: =AM10*(1+AR15) -> 35776.849 | AS14: =AN10*(1+AS15) -> 38085.464 | AT14: =SUM(AP14:AS14) -> 140371.07 | AU14: =AP10*(1+AU15) -> 39927.6 | AV14: =AQ10*(1+AV15) -> 41712.835 | AW14: =AR10*(1+AW15) -> 42964.904 | AX14: =AS10*(1+AX15) -> 44377.746 | AY14: =SUM(AU14:AX14) -> 168983.08 | AZ14: =AZ10-AZ16 -> 47777.44 | BA14: =BA10-BA16 -> 49941.28 | BB14: =BB10-BB16 -> 51658 | BC14: =BC10-BC16 -> 54543.28 | BD14: =SUM(AZ14:BC14) -> 203920 | BE14: =BE10-BE16 -> 54860 | BF14: =BF10-BF16 -> 56430 | BG14: =BG10-BG16 -> 58644 | BH14: =BH10-BH16 -> 60720 | BI14: =SUM(BE14:BH14) -> 230654 | BJ14: =BJ10-BJ16 -> 61792.96 | BK14: =BK10-BK16 -> 63292.26 | BL14: =BL10-BL16 -> 65547.32 | BM14: =BM10-BM16 -> 67369.02 | BN14: =SUM(BJ14:BM14) -> 258001.56 | BO14: =BO10-BO16 -> 69740.48 | BP14: =BP10-BP16 -> 71038.62 | BQ14: =BQ10-BQ16 -> 75579.15 | BR14: =BR10-BR16 -> 78309.52 | BS14: =SUM(BO14:BR14) -> 294667.77 | BT14: =BT10-BT16 -> 81436.48 | BU14: =BU10-BU16 -> 85075.88 | BV14: =BV10-BV16 -> 87706.04 | BW14: =BW10-BW16 -> 91185.52 | BX14: =SUM(BT14:BW14) -> 345403.92 | BY14: =BY10-BY16 -> 96867 | BZ14: =BZ10-BZ16 -> 100413 | CA14: =CA10-CA16 -> 104803 | CB14: =CB10-CB16 -> 110014 | CC14: =SUM(BY14:CB14) -> 412097 | CD14: =CD10-CD16 -> 113801 | CE14: =CE10-CE16 -> 117748 | CF14: =CF10-CF16 -> 124421 | CG14: =CG10-CG16 -> 129618 | CH14: =SUM(CD14:CG14) -> 485588 | CI14: =CI10-CI16 -> 135684 | CJ14: =CJ10-CJ16 -> 139780.24 | CK14: =CK10-CK16 -> 150914.84 | CL14: =CL10-CL16 -> 155423.42 | CM14: =SUM(CI14:CL14) -> 581802.5 | CN14: =CN10-CN16 -> 158129 | CO14: =CO10-CO16 -> 163454 | CP14: =CP10-CP16 -> 170057.84 | CQ14: =CQ10-CQ16 -> 175245.92 | CR14: =SUM(CN14:CQ14) -> 666886.76 | CS14: =CN10*(1+CS15) -> 181031.61 | CT14: =CO10*(1+CT15) -> 189798.72 | CU14: =CP10*(1+CU15) -> 195069.39 | CV14: =CQ10*(1+CV15) -> 198816.86 | CW14: =SUM(CS14:CV14) -> 764716.59
C15: Y/Y Growth | W15: 0.24 | X15: 0.25 | Y15: 0.25 | AA15: 0.27 | AB15: 0.26 | AC15: 0.22 | AD15: 0.24 | AE15: 0.24 | AF15: 0.24 | AG15: 0.26 | AH15: 0.26 | AN15: 0.24 | AP15: 0.24 | AQ15: 0.22 | AR15: 0.22 | AS15: 0.2 | AU15: 0.2 | AV15: 0.18 | AW15: 0.17 | AX15: 0.15 | AY15: =AY14/AT14-1 -> 0.20383124 | AZ15: =AZ14/AU10-1 -> 0.15139984 | BA15: =BA14/AV10-1 -> 0.14641718 | BB15: =BB14/AW10-1 -> 0.13931499 | BC15: =BC14/AX10-1 -> 0.16900894 | BD15: =BD14/AY14-1 -> 0.20674801 | BE15: =BE14/AZ10-1 -> 0.14824068 | BF15: =BF14/BA10-1 -> 0.12992699 | BG15: =BG14/BB10-1 -> 0.13523559 | BH15: =BH14/BC10-1 -> 0.11324438 | BI15: =BI14/BD14-1 -> 0.13110043 | BJ15: =BJ14/BE10-1 -> 0.1263755 | BK15: =BK14/BF10-1 -> 0.12160659 | BL15: =BL14/BG10-1 -> 0.11771571 | BM15: =BM14/BH10-1 -> 0.10950296 | BN15: =BN14/BI14-1 -> 0.1185653 | BO15: =BO14/BJ10-1 -> 0.10843517 | BP15: =BP14/BK10-1 -> 0.1027886 | BQ15: =BQ14/BL10-1 -> 0.13359112 | BR15: =BR14/BM10-1 -> 0.1453948 | BS15: =BS14/BN14-1 -> 0.14211623 | BT15: =BT14/BO10-1 -> 0.16770748 | BU15: =BU14/BP10-1 -> 0.1976004 | BV15: =BV14/BQ10-1 -> 0.16045285 | BW15: =BW14/BR10-1 -> 0.16442445 | BX15: =BX14/BS14-1 -> 0.17218086 | BY15: =BY14/BT10-1 -> 0.16867069 | BZ15: =BZ14/BU10-1 -> 0.15449249 | CA15: =CA14/BV10-1 -> 0.16375315 | CB15: =CB14/BW10-1 -> 0.1637319 | CC15: =CC14/BX14-1 -> 0.19308721 | CD15: =CD14/BY10-1 -> 0.16638823 | CE15: =CE14/BZ10-1 -> 0.16394334 | CF15: =CF14/CA10-1 -> 0.1676912 | CG15: =CG14/CB10-1 -> 0.13935867 | CH15: =CH14/CC14-1 -> 0.17833423 | CI15: =CI14/CD10-1 -> 0.15671648 | CJ15: =CJ14/CE10-1 -> 0.15023691 | CK15: =CK14/CF10-1 -> 0.18484459 | CL15: =CL14/CG10-1 -> 0.14435068 | CM15: =CM14/CH14-1 -> 0.19814019 | CN15: =CN14/CI10-1 -> 0.13204805 | CO15: =CO14/CJ10-1 -> 0.13210783 | CP15: =CP14/CK10-1 -> 0.10524172 | CQ15: =CQ14/CL10-1 -> 0.084285433 | CR15: =CR14/CM10-1 -> 0.11230753 | CS15: 0.0505 | CT15: 0.055 | CU15: 0.07 | CV15: 0.075 | CW15: =CW14/CR10-1 -> 0.062864016
C16: Inorganic Recurring revenue | W16: =W10-W14 -> 443.5152 | X16: =X10-X14 -> 1134.1 | Y16: =Y10-Y14 -> 960.425 | AA16: =AA10-AA14 -> 1051.2691 | AB16: 1000 | AC16: 1000 | AD16: =AD10-AD14 -> 3111.05 | AE16: =AE10-AE14 -> 6753.954 | AF16: =AF10-AF14 -> 3302.4008 | AG16: =AG10-AG14 -> 3268.2044 | AH16: =AH10-AH14 -> 1565.0704 | AN16: =AN10-AN14 -> 548.7246 | AP16: =AP10-AP14 -> 1031.3701 | AQ16: =AQ10-AQ14 -> 1082.7286 | AR16: =AR10-AR14 -> 945.29059 | AT16: =SUM(AP16:AS16) -> 3059.3894 | AU16: =AU10-AU14 -> 1567.49 | AV16: =AV10-AV14 -> 1850.0852 | AW16: =AW10-AW14 -> 2376.3762 | AX16: =AX10-AX14 -> 2279.9644 | AY16: =SUM(AU16:AX16) -> 8073.9158 | BD16: =SUM(AZ16:BC16) -> 0 | BI16: =SUM(BE16:BH16) -> 0 | BJ16: 1125 | BK16: 1125 | BL16: 1125 | BM16: 1000 | BN16: =SUM(BJ16:BM16) -> 4375 | BS16: =SUM(BO16:BR16) -> 0 | BT16: 1450 | BU16: 1900 | BV16: 2350 | BW16: =2900+450 -> 3350 | BX16: =SUM(BT16:BW16) -> 9050 | BY16: 700 | BZ16: 750 | CA16: =750+1000 -> 1750 | CB16: =800+1250+1700 -> 3750 | CC16: =SUM(BY16:CB16) -> 6950 | CD16: =1600+1900 -> 3500 | CE16: =1675+2100 -> 3775 | CF16: =750+2200 -> 2950 | CG16: =2300+3900 -> 6200 | CH16: =SUM(CD16:CG16) -> 16425 | CI16: 4000 | CJ16: =4000+600 -> 4600 | CK16: =750+2200 -> 2950 | CL16: =2300+3900 -> 6200 | CM16: =SUM(CI16:CL16) -> 17750 | CN16: =1200+6000+7000 -> 14200 | CO16: 16450 | CP16: =6250-3000+10000-1000 -> 12250 | CQ16: =1000+10000-1300 -> 9700 | CR16: =SUM(CN16:CQ16) -> 52600 | CS16: =5000-500-500 -> 4000 | CT16: 0 | CU16: 0 | CV16: 0 | CW16: =SUM(CS16:CV16) -> 4000
C17: Y/Y Growth | W17: =W12-W15 -> 0.048826358 | X17: =X12-X15 -> 0.11749361 | Y17: =Y12-Y15 -> 0.09300802 | AA17: =AA12-AA15 -> 0.10013355 | AB17: =AB12-AB15 -> 0.049127468 | AC17: =AC12-AC15 -> 0.13116916 | AD17: =AD12-AD15 -> 0.22432895 | AE17: =AE12-AE15 -> 0.1370703 | AF17: =AF12-AF15 -> 0.22957923 | AG17: =AG12-AG15 -> 0.21324492 | AH17: =AH12-AH15 -> 0.087752953 | AN17: =AN12-AN15 -> 0.021815864 | AP17: =AP8-AP15 -> 0.037514772 | AQ17: =AQ8-AQ15 -> 0.029067524 | AR17: =AR8-AR15 -> 0.021432351 | AS17: 0
C18: Non-recurring revenue | K18: =K4-K10 -> 5218.49 | L18: =L4-L10 -> 1620.89 | M18: =M4-M10 -> 2112 | N18: =N4-N10 -> 1830.46 | O18: =O4-O10 -> 1985.85 | P18: =P4-P10 -> 7549.2 | Q18: =Q4-Q10 -> 1843.74 | R18: =R4-R10 -> 1860.48 | ... AX18: =AX4-AX10 -> 4403.29 | AY18: 16096 | AZ18: =AZ4-AZ10 -> 4154.56 | BA18: =BA4-BA10 -> 4342.72 | BB18: =BB4-BB10 -> 4492 | BC18: =BC4-BC10 -> 3656.72 | BD18: 16165 | BE18: =BE4-BE10 -> 4232 | BF18: =BF4-BF10 -> 4661 | BG18: =BG4-BG10 -> 4224 | BH18: =BH4-BH10 -> 4469 | BI18: =SUM(BE18:BH18) -> 17586 | BJ18: =BJ4-BJ10 -> 4016.04 | BK18: =BK4-BK10 -> 4111.74 | BL18: =BL4-BL10 -> 4255.68 | BM18: =BM4-BM10 -> 4363.98 | BN18: =SUM(BJ18:BM18) -> 16747.44 | BO18: =BO4-BO10 -> 4451.52 | BP18: =BP4-BP10 -> 4534.38 | BQ18: =BQ4-BQ10 -> 3977.85 | BR18: =BR4-BR10 -> 4998.48 | BS18: =SUM(BO18:BR18) -> 17962.23 | BT18: =BT4-BT10 -> 7207.52 | BU18: =BU4-BU10 -> 7563.12 | BV18: =BV4-BV10 -> 7830.96 | BW18: =BW4-BW10 -> 8220.48 | BX18: =SUM(BT18:BW18) -> 30822.08 | BY18: =BY4-BY10 -> 7626 | BZ18: =BZ4-BZ10 -> 8015 | CA18: =CA4-CA10 -> 7933 | CB18: =CB4-CB10 -> 8254 | CC18: =SUM(BY18:CB18) -> 31828 | CD18: =CD4-CD10 -> 8567 | CE18: =CE4-CE10 -> 8893 | CF18: =CF4-CF10 -> 8290 | CG18: =CG4-CG10 -> 9147 | CH18: =SUM(CD18:CG18) -> 34897 | CI18: =CI4-CI10 -> 9892 | CJ18: =CJ4-CJ10 -> 9215.76 | CK18: =CK4-CK10 -> 9821.16 | CL18: =CL4-CL10 -> 9283.58 | CM18: =SUM(CI18:CL18) -> 38212.5 | CN18: 9220 | CO18: =CO4-CO10 -> 7496 | CP18: =CP4-CP10 -> 7596.16 | CQ18: =CQ4-CQ10 -> 7706.08 | CR18: =SUM(CN18:CQ18) -> 32018.24 | CS18: 7600 | CT18: 7900 | CU18: 9350 | CV18: 9150 | CW18: =SUM(CS18:CV18) -> 34000
C19: % of total Rev | AK19: =AK18/AK4 -> 0.10151303 | AL19: =AL18/AL4 -> 0.0968549 | AM19: =AM18/AM4 -> 0.097850046 | AN19: =AN18/AN4 -> 0.10350018 | AO19: =AO18/AO4 -> 0.1 | AP19: =AP18/AP4 -> 0.1 | AQ19: =AQ18/AQ4 -> 0.09 | AR19: =AR18/AR4 -> 0.09 | ... AX19: =AX18/AX4 -> 0.086235875 | AZ19: =AZ18/AZ4 -> 0.08 | BA19: =BA18/BA4 -> 0.08 | BB19: =BB18/BB4 -> 0.08 | BC19: =BC18/BC4 -> 0.062830241 | BE19: =BE18/BE4 -> 0.071617139 | BF19: =BF18/BF4 -> 0.076296017 | BG19: =BG18/BG4 -> 0.067188395 | BH19: =BH18/BH4 -> 0.068554511 | BJ19: =BJ18/BJ4 -> 0.06 | BK19: =BK18/BK4 -> 0.06 | BL19: =BL18/BL4 -> 0.06 | BM19: =BM18/BM4 -> 0.06 | BO19: =BO18/BO4 -> 0.06 | BP19: =BP18/BP4 -> 0.06 | BQ19: =BQ18/BQ4 -> 0.05 | BR19: =BR18/BR4 -> 0.06 | BT19: =BT18/BT4 -> 0.08 | BU19: =BU18/BU4 -> 0.08 | BV19: =BV18/BV4 -> 0.08 | BW19: =BW18/BW4 -> 0.08 | BY19: =BY18/BY4 -> 0.072495318 | BZ19: =BZ18/BZ4 -> 0.073412226 | CA19: =CA18/CA4 -> 0.069292315 | CB19: =CB18/CB4 -> 0.067645757 | CC19: =CC18/CC4 -> 0.070591627 | CD19: =CD18/CD4 -> 0.068063368 | CE19: =CE18/CE4 -> 0.068189486 | CF19: =CF18/CF4 -> 0.061108204 | ... CW19: =CW18/CW4 -> 0.04235617
B20: Cost of Revenue | D20: 3823 | E20: 5219 | F20: =6379-2 -> 6377 | G20: =1986-4 -> 1982 | H20: =2199-4 -> 2195 | I20: =2435-4 -> 2431 | J20: =2638-7 -> 2631 | K20: =SUM(G20:J20) -> 9239 | L20: =2837-12 -> 2825 | M20: =2896-11 -> 2885 | N20: =3009-20 -> 2989 | O20: =2973-10 -> 2963 | P20: =SUM(L20:O20) -> 11662 | Q20: =2981-10 -> 2971 | R20: =3101-24 -> 3077 | S20: =3211-31 -> 3180 | T20: =3333-38 -> 3295 | U20: =SUM(Q20:T20) -> 12523 | V20: =3321-46 -> 3275 | W20: =3750-72 -> 3678 | X20: =4076-68 -> 4008 | Y20: =4219-69 -> 4150 | Z20: =SUM(V20:Y20) -> 15111 | AA20: =4448-178 -> 4270 | AB20: =4843-116 -> 4727 | AC20: =5945-122 -> 5823 | AD20: =6804-46 -> 6758 | AE20: =SUM(AA20:AD20) -> 21578 | AF20: =7066-103 -> 6963 | AG20: =7943-122 -> 7821 | AH20: =8249-128 -> 8121 | AI20: =8523-122 -> 8401 | AJ20: =SUM(AF20:AI20) -> 31306 | AK20: =9255-153 -> 9102 | AL20: =9627-152 -> 9475 | AM20: =9970-134 -> 9836 | AN20: =11139-175 -> 10964 | AO20: =SUM(AK20:AN20) -> 39377 | AP20: =11572-172 -> 11400 | AQ20: =12335-288 -> 12047 | AR20: =12700-256 -> 12444 | AS20: =13436-273 -> 13163 | AT20: =SUM(AP20:AS20) -> 49054 | AU20: =14881-280 -> 14601 | AV20: =15972-317 -> 15655 | AW20: =16171-319 -> 15852 | AX20: =17322-393 -> 16929 | AY20: =SUM(AU20:AX20) -> 63037 | AZ20: =17330-451 -> 16879 | BA20: =18191-469 -> 17722 | BB20: =18645-494 -> 18151 | BC20: =19459-473 -> 18986 | BD20: =SUM(AZ20:BC20) -> 71738 | BE20: =19758-548 -> 19210 | BF20: =20402-504 -> 19898 | BG20: =20411-535 -> 19876 | BH20: =21177-581 -> 20596 | BI20: =SUM(BE20:BH20) -> 79580 | BJ20: =21367-587 -> 20780 | BK20: =23700-662 -> 23038 | BL20: =23263-778 -> 22485 | BM20: =23909-792 -> 23117 | BN20: =SUM(BJ20:BM20) -> 89420 | BO20: =23544-808 -> 22736 | BP20: =24326-956 -> 23370 | BQ20: =25045-1003 -> 24042 | BR20: =26921-1181 -> 25740 | BS20: =SUM(BO20:BR20) -> 95888 | BT20: =29970-1503 -> 28467 | BU20: =31730-1746 -> 29984 | BV20: =34343-1696 -> 32647 | BW20: =35635-1815 -> 33820 | BX20: =SUM(BT20:BW20) -> 124918 | BY20: =35389-2179 -> 33210 | BZ20: =37530-2152 -> 35378 | CA20: =38605-2146 -> 36459 | CB20: =41541-2207 -> 39334 | CC20: =SUM(BY20:CB20) -> 144381 | CD20: =42964-2503 -> 40461 | CE20: =44544-2586 -> 41958 | CF20: =45521-2506 -> 43015 | CG20: =49040-2574 -> 46466 | CH20: =SUM(CD20:CG20) -> 171900 | CI20: =51487-4082 -> 47405 | CJ20: =52018-2730 -> 49288 | CK20: =51624-1412 -> 50212 | CL20: =55585-2819 -> 52766 | CM20: =SUM(CI20:CL20) -> 199671 | CN20: =56914-3111 -> 53803 | CO20: =59826-3328 -> 56498 | CP20: =57932-3171 -> 54761 | CQ20: =56957-1813 -> 55144 | CR20: =SUM(CN20:CQ20) -> 220206 | CS20: =CS4*(1-CS22) -> 55477.905 | CT20: =CT4*(1-CT22) -> 56344.135 | CU20: =CU4*(1-CU22) -> 56828.59 | CV20: =CV4*(1-CV22) -> 57606.821 | CW20: =SUM(CS20:CV20) -> 226257.45
B21: Gross Profit | D21: =D4-D20 -> 10004 | E21: =E4-E20 -> 14640 | F21: =F4-F20 -> 18821 | G21: =G4-G20 -> 4975 | H21: =H4-H20 -> 5391 | I21: =I4-I20 -> 5643 | J21: =J4-J20 -> 5449 | K21: =K4-K20 -> 21458 | ... CW21: =CW4-CW20 -> 576459.14
C22: Gross Margin | D22: =D21/D4 -> 0.72351197 | E22: =E21/E4 -> 0.73719724 | F22: =F21/F4 -> 0.74692436 | G22: =G21/G4 -> 0.71510709 | H22: =H21/H4 -> 0.7106512 | I22: =I21/I4 -> 0.69891008 | J22: =J21/J4 -> 0.67438119 | K22: =K21/K4 -> 0.69902596 | ... CR22: =CR21/CR4 -> 0.70697999 | CS22: 0.712 | CT22: 0.715 | CU22: 0.722 | CV22: 0.723 | CW22: =CW21/CW4 -> 0.71813532
B24: Operating Expenses
C25: Sales and marketing | D25: 5034 | E25: 8098 | F25: =11636-33 -> 11603 | G25: =3162-14 -> 3148 | H25: =3240-15 -> 3225 | I25: =3101-15 -> 3086 | J25: =2990-16 -> 2974 | K25: =SUM(G25:J25) -> 12433 | L25: =3075-15 -> 3060 | M25: =3397-17 -> 3380 | N25: =3533-42 -> 3491 | O25: =3501-17 -> 3484 | P25: =SUM(L25:O25) -> 13415 | Q25: =3507-17 -> 3490 | R25: =4122-48 -> 4074 | S25: =4139-64 -> 4075 | T25: =4833-82 -> 4751 | U25: =SUM(Q25:T25) -> 16390 | V25: =5126-89 -> 5037 | W25: =5852-137 -> 5715 | X25: =6404-121 -> 6283 | Y25: =6454-124 -> 6330 | Z25: =SUM(V25:Y25) -> 23365 | AA25: =6447-98 -> 6349 | AB25: =6972-217 -> 6755 | AC25: =7840-232 -> 7608 | AD25: =8778-268 -> 8510 | AE25: =SUM(AA25:AD25) -> 29222 | AF25: =9225-342 -> 8883 | AG25: =9647-386 -> 9261 | AH25: =10291-378 -> 9913 | AI25: =10458-375 -> 10083 | AJ25: =SUM(AF25:AI25) -> 38140 | AK25: =10884-482 -> 10402 | AL25: =11570-472 -> 11098 | AM25: =12046-469 -> 11577 | AN25: =12490-510 -> 11980 | AO25: =SUM(AK25:AN25) -> 45057 | AP25: =13744-542 -> 13202 | AQ25: =14101-482 -> 13619 | AR25: =13795-466 -> 13329 | AS25: =13734-488 -> 13246 | AT25: =SUM(AP25:AS25) -> 53396 | AU25: =15889-654 -> 15235 | AV25: =16677-639 -> 16038 | AW25: =16526-620 -> 15906 | AX25: =16794-499 -> 16295 | AY25: =SUM(AU25:AX25) -> 63474 | AZ25: =17079-517 -> 16562 | BA25: =18741-574 -> 18167 | BB25: =18239-565 -> 17674 | BC25: =19236-541 -> 18695 | BD25: =SUM(AZ25:BC25) -> 71098 | BE25: =18647-653 -> 17994 | BF25: =18424-710 -> 17714 | BG25: =16952-691 -> 16261 | BH25: =17696-621 -> 17075 | BI25: =SUM(BE25:BH25) -> 69044 | BJ25: =17922-730 -> 17192 | BK25: =17545-694 -> 16851 | BL25: =16937-784 -> 16153 | BM25: =17736-738 -> 16998 | BN25: =SUM(BJ25:BM25) -> 67194 | BO25: =18299-846 -> 17453 | BP25: =18611-1010 -> 17601 | BQ25: =19233-1123 -> 18110 | BR25: =19812-1140 -> 18672 | BS25: =SUM(BO25:BR25) -> 71836 | BT25: =21355-1482 -> 19873 | BU25: =21952-1738 -> 20214 | BV25: =22079-1634 -> 20445 | BW25: =22658-1394 -> 21264 | BX25: =SUM(BT25:BW25) -> 81796 | BY25: =24655-2032 -> 22623 | BZ25: =24582-1958 -> 22624 | CA25: =25334-1845 -> 23489 | CB25: =27201-1755 -> 25446 | CC25: =SUM(BY25:CB25) -> 94182 | CD25: =29083-2423 -> 26660 | CE25: =30349-2528 -> 27821 | CF25: =30289-2428 -> 27861 | CG25: =33214-2394 -> 30820 | CH25: =SUM(CD25:CG25) -> 113162 | CI25: =36432-4444 -> 31988 | CJ25: =35691-2512 -> 33179 | CK25: =37577-2820 -> 34757 | CL25: =39220-2771 -> 36449 | CM25: =SUM(CI25:CL25) -> 136373 | CN25: =41634-2427 -> 39207 | CO25: =43434-3357 -> 40077 | CP25: =42322-3486 -> 38836 | CQ25: =41740-1673 -> 40067 | CR25: =SUM(CN25:CQ25) -> 158187 | CS25: =CS26*CS4 -> 41030.534 | CT25: =CT26*CT4 -> 41121.334 | CU25: =CU26*CU4 -> 41905.975 | CV25: =CV26*CV4 -> 41801.34 | CW25: =SUM(CS25:CV25) -> 165859.18
C26: % of Revenue | D26: =D25/D4 -> 0.3640703 | E26: =E25/E4 -> 0.40777481 | F26: =F25/F4 -> 0.46047305 | G26: =G25/G4 -> 0.45249389 | H26: =H25/H4 -> 0.42512523 | I26: =I25/I4 -> 0.38221452 | J26: =J25/J4 -> 0.36806931 | K26: =K25/K4 -> 0.40502329 | ... CR26: =CR25/CR4 -> 0.21049361 | CS26: 0.213 | CT26: 0.208 | CU26: 0.205 | CV26: 0.201 | CW26: =CW25/CW4 -> 0.20662234
C27: Research and development | D27: 2129 | E27: 3190 | F27: =3546-2 -> 3544 | G27: =949-1 -> 948 | H27: =954-1 -> 953 | I27: =875-1 -> 874 | J27: =862-1 -> 861 | K27: =SUM(G27:J27) -> 3636 | L27: =1044-1 -> 1043 | M27: =1059-1 -> 1058 | N27: =1123-1 -> 1122 | O27: =1079-1 -> 1078 | P27: =SUM(L27:O27) -> 4301 | Q27: =1043-1 -> 1042 | R27: =1067-4 -> 1063 | S27: =1108-7 -> 1101 | T27: =1131-8 -> 1123 | U27: =SUM(Q27:T27) -> 4329 | V27: =1240-7 -> 1233 | W27: =1414-16 -> 1398 | X27: =1605-18 -> 1587 | Y27: =1579-15 -> 1564 | Z27: =SUM(V27:Y27) -> 5782 | AA27: =1732-22 -> 1710 | AB27: =1830-29 -> 1801 | AC27: =2088-39 -> 2049 | AD27: =2516-50 -> 2466 | AE27: =SUM(AA27:AD27) -> 8026 | AF27: =2503-61 -> 2442 | AG27: =2657-63 -> 2594 | AH27: =2806-71 -> 2735 | AI27: =2904-71 -> 2833 | AJ27: =SUM(AF27:AI27) -> 10604 | AK27: =2974-93 -> 2881 | AL27: =3365-95 -> 3270 | AM27: =3338-134 -> 3204 | AN27: =3817-122 -> 3695 | AO27: =SUM(AK27:AN27) -> 13050 | AP27: =4069-135 -> 3934 | AQ27: =4495-173 -> 4322 | AR27: =4494-178 -> 4316 | AS27: =4896-154 -> 4742 | AT27: =SUM(AP27:AS27) -> 17314 | AU27: =5069-138 -> 4931 | AV27: =5542-141 -> 5401 | AW27: =5574-143 -> 5431 | AX27: =5796-196 -> 5600 | AY27: =SUM(AU27:AX27) -> 21363 | AZ27: =5105-229 -> 4876 | BA27: =5369-228 -> 5141 | BB27: =6549-241 -> 6308 | BC27: =6160-251 -> 5909 | BD27: =SUM(AZ27:BC27) -> 22234 | BE27: =5132-329 -> 4803 | BF27: =5293-357 -> 4936 | BG27: =5146-287 -> 4859 | BH27: =6516-532 -> 5984 | BI27: =SUM(BE27:BH27) -> 20582 | BJ27: =6192-523 -> 5669 | BK27: =6509-602 -> 5907 | BL27: =7743-697 -> 7046 | BM27: =7861-829 -> 7032 | BN27: =SUM(BJ27:BM27) -> 25654 | BO27: =7568-923 -> 6645 | BP27: =7466-883 -> 6583 | BQ27: =8053-983 -> 7070 | BR27: =7937-837 -> 7100 | BS27: =SUM(BO27:BR27) -> 27398 | BT27: =8706-911 -> 7795 | BU27: =8899-1106 -> 7793 | BV27: =10854-1195 -> 9659 | BW27: =10579-1172 -> 9407 | BX27: =SUM(BT27:BW27) -> 34654 | BY27: =10701-1474 -> 9227 | BZ27: =11432-1380 -> 10052 | CA27: =11135-1396 -> 9739 | CB27: =12480-1384 -> 11096 | CC27: =SUM(BY27:CB27) -> 40114 | CD27: =12563-1777 -> 10786 | CE27: =13318-1812 -> 11506 | CF27: =13558-1798 -> 11760 | CG27: =14216-1813 -> 12403 | CH27: =SUM(CD27:CG27) -> 46455 | CI27: =16009-3242 -> 12767 | CJ27: =14366-1820 -> 12546 | CK27: =15292-1939 -> 13353 | CL27: =17142-2093 -> 15049 | CM27: =SUM(CI27:CL27) -> 53715 | CN27: =17439-2017 -> 15422 | CO27: =17271-2135 -> 15136 | CP27: =17276-2354 -> 14922 | CQ27: =16694-1897 -> 14797 | CR27: =SUM(CN27:CQ27) -> 60277 | CS27: =+CS28*CS4 -> 16181.056 | CT27: =+CT28*CT4 -> 16013.596 | CU27: =+CU28*CU4 -> 15944.712 | CV27: =+CV28*CV4 -> 16221.415 | CW27: =SUM(CS27:CV27) -> 64360.78
C28: % of Revenue | D28: =D27/D4 -> 0.15397411 | E28: =E27/E4 -> 0.16063246 | F28: =F27/F4 -> 0.14064608 | G28: =G27/G4 -> 0.13626563 | H28: =H27/H4 -> 0.12562615 | I28: =I27/I4 -> 0.1082487 | J28: =J27/J4 -> 0.10655941 | K28: =K27/K4 -> 0.11844806 | ... CR28: =CR27/CR4 -> 0.080208382 | CS28: 0.084 | CT28: 0.081 | CU28: 0.078 | CV28: 0.078 | CW28: =CW27/CW4 -> 0.080178709
C29: General and administrative | D29: 3180 | E29: 4199 | F29: =5458-9 -> 5449 | G29: =1639-17 -> 1622 | H29: =1669-17 -> 1652 | I29: =1684-17 -> 1667 | J29: =1724-23 -> 1701 | K29: =SUM(G29:J29) -> 6642 | L29: =1652-20 -> 1632 | M29: =1514-21 -> 1493 | N29: =1505-16 -> 1489 | O29: =1668-23 -> 1645 | P29: =SUM(L29:O29) -> 6259 | Q29: =1665-23 -> 1642 | R29: =1975-99 -> 1876 | S29: =2165-130 -> 2035 | T29: =2180-164 -> 2016 | U29: =SUM(Q29:T29) -> 7569 | V29: =2455-170 -> 2285 | W29: =2839-262 -> 2577 | X29: =2914-280 -> 2634 | Y29: =2943-274 -> 2669 | Z29: =SUM(V29:Y29) -> 10165 | AA29: =3188-314 -> 2874 | AB29: =3165-353 -> 2812 | AC29: =3726-322 -> 3404 | AD29: =3445-349 -> 3096 | AE29: =SUM(AA29:AD29) -> 12186 | AF29: =4047-418 -> 3629 | AG29: =4211-540 -> 3671 | AH29: =4284-508 -> 3776 | AI29: =4647-515 -> 4132 | AJ29: =SUM(AF29:AI29) -> 15208 | AK29: =4511-611 -> 3900 | AL29: =4842-640 -> 4202 | AM29: =5153-556 -> 4597 | AN29: =5727-598 -> 5129 | AO29: =SUM(AK29:AN29) -> 17828 | AP29: =5818-650 -> 5168 | AQ29: =6055-704 -> 5351 | AR29: =6276-710 -> 5566 | AS29: =6668-708 -> 5960 | AT29: =SUM(AP29:AS29) -> 22045 | AU29: =7285-855 -> 6430 | AV29: =7082-968 -> 6114 | AW29: =7149-930 -> 6219 | AX29: =7311-931 -> 6380 | AY29: =SUM(AU29:AX29) -> 25143 | AZ29: =7827-1103 -> 6724 | BA29: =8139-915 -> 7224 | BB29: =8744-1047 -> 7697 | BC29: =12752-4629 -> 8123 | BD29: =SUM(AZ29:BC29) -> 29768 | BE29: =10130-2003 -> 8127 | BF29: =9974-1608 -> 8366 | BG29: =11174-1753 -> 9421 | BH29: =10584-798 -> 9786 | BI29: =SUM(BE29:BH29) -> 35700 | BJ29: =12770-3454+61 -> 9377 | BK29: =10179-917+400 -> 9662 | BL29: =10725-888+22 -> 9859 | BM29: =11045-1015+5 -> 10035 | BN29: =SUM(BJ29:BM29) -> 38933 | BO29: =11909-1767-72 -> 10070 | BP29: =12743-2160-82 -> 10501 | BQ29: =11939-1784-103 -> 10052 | BR29: =13528-1532+583 -> 12579 | BS29: =SUM(BO29:BR29) -> 43202 | BT29: =14737-3029 -> 11708 | BU29: =15758-2909 -> 12849 | BV29: =14691-2324 -> 12367 | BW29: =16119-1920 -> 14199 | BX29: =SUM(BT29:BW29) -> 51123 | BY29: =15468-3330 -> 12138 | BZ29: =17198-3171 -> 14027 | CA29: =16724-2573 -> 14151 | CB29: =17950-2417 -> 15533 | CC29: =SUM(BY29:CB29) -> 55849 | CD29: =20677-5077 -> 15600 | CE29: =21693-5955 -> 15738 | CF29: =21906-4704 -> 17202 | CG29: =20612-2630 -> 17982 | CH29: =SUM(CD29:CG29) -> 66522 | CI29: =25907-8250 -> 17657 | CJ29: =23516-4432 -> 19084 | CK29: =27152-4581 -> 22571 | CL29: =26354-4610 -> 21744 | CM29: =SUM(CI29:CL29) -> 81056 | CN29: =31018-6312 -> 24706 | CO29: =30890-6178 -> 24712 | CP29: =31690-5442 -> 26248 | CQ29: =32996-5027 -> 27969 | CR29: =SUM(CN29:CQ29) -> 103635 | CS29: =CS30*CS4 -> 27931.584 | CT29: =CT30*CT4 -> 25107.737 | CU29: =CU30*CU4 -> 25756.843 | CV29: =CV30*CV4 -> 25787.891 | CW29: =SUM(CS29:CV29) -> 104584.06
C30: % of Revenue | D30: =D29/D4 -> 0.22998481 | E30: =E29/E4 -> 0.21144066 | F30: =F29/F4 -> 0.21624732 | G30: =G29/G4 -> 0.23314647 | H30: =H29/H4 -> 0.21776958 | I30: =I29/I4 -> 0.2064652 | J30: =J29/J4 -> 0.2105198 | K30: =K29/K4 -> 0.21637294 | ... CR30: =CR29/CR4 -> 0.13790327 | CS30: 0.145 | CT30: 0.127 | CU30: 0.126 | CV30: 0.124 | CW30: =CW29/CW4 -> 0.13028765
C31: Total Operating Expenses | D31: =D29+D27+D25 -> 10343 | E31: =E29+E27+E25 -> 15487 | F31: =F29+F27+F25 -> 20596 | G31: =G29+G27+G25 -> 5718 | H31: =H29+H27+H25 -> 5830 | I31: =I29+I27+I25 -> 5627 | J31: =J29+J27+J25 -> 5536 | K31: =K29+K27+K25 -> 22711 | ... CW31: =CW29+CW27+CW25 -> 334804.02
B33: Proforma Operating Income | D33: =D21-D31 -> -339 | E33: =E21-E31 -> -847 | F33: =F21-F31 -> -1775 | G33: =G21-G31 -> -743 | H33: =H21-H31 -> -439 | I33: =I21-I31 -> 16 | J33: =J21-J31 -> -87 | K33: =K21-K31 -> -1253 | ... CW33: =CW21-CW31 -> 241655.12
C34: Proforma Operating Margins | D34: =D33/D4 -> -0.024517249 | E34: =E33/E4 -> -0.042650687 | F34: =F33/F4 -> -0.070442099 | G34: =G33/G4 -> -0.10679891 | H34: =H33/H4 -> -0.05786976 | I34: =I33/I4 -> 0.0019816696 | J34: =J33/J4 -> -0.010767327 | K34: =K33/K4 -> -0.040818321 | ... CW34: =CW33/CW4 -> 0.30104662
C36: Amortization of Intangible assets | W36: 123 | X36: 260 | Y36: 260 | Z36: =SUM(V36:Y36) -> 643 | AA36: 260 | AB36: 260 | AC36: 530 | AD36: 717 | AE36: =SUM(AA36:AD36) -> 1767 | AF36: 717 | AG36: 717 | AH36: 1007 | AI36: 717 | AJ36: =SUM(AF36:AI36) -> 3158 | AK36: 717 | AL36: 682 | AM36: 645 | AN36: 812 | AO36: =SUM(AK36:AN36) -> 2856 | AP36: 845 | AQ36: 833 | AR36: 829 | AS36: 800 | AT36: =SUM(AP36:AS36) -> 3307 | AU36: 1161 | AV36: 1198 | AW36: 1194 | AX36: 1185 | AY36: =SUM(AU36:AX36) -> 4738 | AZ36: 1215 | BA36: 1117 | BB36: 1128 | BC36: 1114 | BD36: =SUM(AZ36:BC36) -> 4574 | BE36: 1125 | BF36: 1033 | BG36: 928 | BH36: 1007 | BI36: =SUM(BE36:BH36) -> 4093 | BJ36: 1304 | BK36: 1266 | BL36: =1327 -> 1327 | BM36: 1418 | BN36: =SUM(BJ36:BM36) -> 5315 | BO36: 1336 | BP36: 1316 | BQ36: 1333 | BR36: 1553 | BS36: =SUM(BO36:BR36) -> 5538 | BT36: 2664 | BU36: 2671 | BV36: 2399 | BW36: 2392 | BX36: =SUM(BT36:BW36) -> 10126 | BY36: 2470 | BZ36: 2468 | CA36: 2998 | CB36: 3832 | CC36: =SUM(BY36:CB36) -> 11768 | CD36: 3851 | CE36: 3479 | CF36: 3788 | CG36: 4998 | CH36: =SUM(CD36:CG36) -> 16116 | CI36: 4338 | CJ36: 4840 | CK36: 6470 | CL36: 7862 | CM36: =SUM(CI36:CL36) -> 23510 | CN36: 8588 | CO36: =9509 -> 9509 | CP36: 9493 | CQ36: 9579 | CR36: =SUM(CN36:CQ36) -> 37169 | CS36: 9600 | CT36: 9600 | CU36: 9550 | CV36: 9550 | CW36: =SUM(CS36:CV36) -> 38300
C37: Stock-based Compensation | F37: 46 | G37: 36 | H37: 37 | I37: 37 | J37: 47 | K37: =SUM(G37:J37) -> 157 | L37: 48 | M37: 50 | N37: 79 | O37: 51 | P37: =SUM(L37:O37) -> 228 | Q37: 51 | R37: 175 | S37: 232 | T37: 292 | U37: =SUM(Q37:T37) -> 750 | V37: 312 | W37: 487 | X37: 487 | Y37: 482 | Z37: =SUM(V37:Y37) -> 1768 | AA37: 612 | AB37: 715 | AC37: 715 | AD37: 713 | AE37: =SUM(AA37:AD37) -> 2755 | AF37: 924 | AG37: 1111 | AH37: 1085 | AI37: 1083 | AJ37: =SUM(AF37:AI37) -> 4203 | AK37: 1339 | AL37: 1359 | AM37: 1293 | AN37: 1405 | AO37: =SUM(AK37:AN37) -> 5396 | AP37: 1499 | AQ37: 1647 | AR37: 1610 | AS37: 1623 | AT37: =SUM(AP37:AS37) -> 6379 | AU37: 1927 | AV37: 2065 | AW37: 2012 | AX37: 2019 | AY37: =SUM(AU37:AX37) -> 8023 | AZ37: 2300 | BA37: 2186 | BB37: 2347 | BC37: 5894 | BD37: =SUM(AZ37:BC37) -> 12727 | BE37: 3533 | BF37: 3179 | BG37: 3266 | BH37: 2532 | BI37: =SUM(BE37:BH37) -> 12510 | BJ37: 5294 | BK37: 2875 | BL37: 3147 | BM37: 3374 | BN37: =SUM(BJ37:BM37) -> 14690 | BO37: 4344 | BP37: 5009 | BQ37: 4893 | BR37: 4690 | BS37: =SUM(BO37:BR37) -> 18936 | BT37: 6925 | BU37: 7499 | BV37: 6849 | BW37: 6301 | BX37: =SUM(BT37:BW37) -> 27574 | BY37: 9015 | BZ37: 8661 | CA37: 7960 | CB37: 7763 | CC37: =SUM(BY37:CB37) -> 33399 | CD37: 11780 | CE37: 12881 | CF37: 11436 | CG37: 9411 | CH37: =SUM(CD37:CG37) -> 45508 | CI37: 20018 | CJ37: 11494 | CK37: 10752 | CL37: 12293 | CM37: =SUM(CI37:CL37) -> 54557 | CN37: 13867 | CO37: 14998 | CP37: 14453 | CQ37: 10410 | CR37: =SUM(CN37:CQ37) -> 53728 | CS37: 17200 | CT37: 16635 | CU37: 16635 | CV37: 16635 | CW37: =SUM(CS37:CV37) -> 67105
C38: % of Revenue | D38: =D37/D4 -> 0 | E38: =E37/E4 -> 0 | F38: =F37/F4 -> 0.0018255417 | G38: =G37/G4 -> 0.0051746442 | H38: =H37/H4 -> 0.0048774057 | I38: =I37/I4 -> 0.0045826108 | J38: =J37/J4 -> 0.0058168317 | K38: =K37/K4 -> 0.0051145063 | ... CW38: =CW37/CW4 -> 0.083597376
C39: Other | AY39: =SUM(AU39:AX39) -> 0 | BH39: 94 | BI39: =SUM(BE39:BH39) -> 94 | BJ39: -61 | BK39: -400 | BL39: -22 | BM39: -5 | BN39: =SUM(BJ39:BM39) -> -488 | BO39: =72 -> 72 | BP39: =82 -> 82 | BQ39: =103 -> 103 | BR39: =-583 -> -583 | BS39: =SUM(BO39:BR39) -> -326 | BX39: =SUM(BT39:BW39) -> 0 | CC39: =SUM(BY39:CB39) -> 0 | CH39: =SUM(CD39:CG39) -> 0 | CM39: =SUM(CI39:CL39) -> 0 | CR39: =SUM(CN39:CQ39) -> 0 | CW39: =SUM(CS39:CV39) -> 0
B40: GAAP Adjustments | F40: =F37 -> 46 | G40: =G37 -> 36 | H40: =H37 -> 37 | I40: =I37 -> 37 | J40: =J37 -> 47 | K40: =SUM(G40:J40) -> 157 | L40: =L37 -> 48 | M40: =M37 -> 50 | N40: =N37 -> 79 | O40: =O37 -> 51 | P40: =SUM(L40:O40) -> 228 | Q40: =Q37 -> 51 | R40: =R37 -> 175 | S40: =S37 -> 232 | T40: =T37 -> 292 | U40: =U37 -> 750 | V40: =V37 -> 312 | W40: =W37+W36 -> 610 | X40: =X37+X36 -> 747 | Y40: =Y37+Y36 -> 742 | Z40: =Z37+Z36 -> 2411 | AA40: =AA37+AA36 -> 872 | AB40: =AB37+AB36 -> 975 | AC40: =AC37+AC36 -> 1245 | AD40: =AD37+AD36 -> 1430 | ... AT40: =AT37+AT36 -> 9686 | AU40: =AU37+AU36+AU39 -> 3088 | AV40: =AV37+AV36+AV39 -> 3263 | AW40: =AW37+AW36+AW39 -> 3206 | AX40: =AX37+AX36+AX39 -> 3204 | AY40: =AY37+AY36+AY39 -> 12761 | AZ40: =AZ37+AZ36+AZ39 -> 3515 | BA40: =BA37+BA36 -> 3303 | BB40: =BB37+BB36 -> 3475 | BC40: =BC37+BC36 -> 7008 | BD40: =BD37+BD36 -> 17301 | BE40: =BE37+BE36+BE39 -> 4658 | BF40: =BF37+BF36 -> 4212 | BG40: =BG37+BG36 -> 4194 | BH40: =BH37+BH36 -> 3539 | BI40: =BI37+BI36 -> 16603 | BJ40: =BJ37+BJ36+BJ39 -> 6537 | BK40: =BK37+BK36+BK39 -> 3741 | BL40: =BL37+BL36+BL39 -> 4452 | BM40: =BM37+BM36+BM39 -> 4787 | BN40: =BN37+BN36 -> 20005 | BO40: =BO37+BO36+BO39 -> 5752 | BP40: =BP37+BP36+BP39 -> 6407 | BQ40: =BQ37+BQ36+BQ39 -> 6329 | BR40: =BR37+BR36+BR39 -> 5660 | BS40: =BS37+BS36+BS39 -> 24148 | BT40: =BT37+BT36+BT39 -> 9589 | BU40: =BU37+BU36+BU39 -> 10170 | BV40: =BV37+BV36+BV39 -> 9248 | ... CW40: =CW37+CW36+CW39 -> 105405
BO41: =11536-BO42 -> 0
B42: GAAP Operating Income | D42: =D33-D40 -> -339 | E42: =E33-E40 -> -847 | F42: =F33-F40 -> -1821 | G42: =G33-G40 -> -779 | H42: =H33-H40 -> -476 | I42: =I33-I40 -> -21 | J42: =J33-J40 -> -134 | K42: =K33-K40 -> -1410 | ... CW42: =CW33-CW40 -> 136250.12
C43: GAAP Operating Margin | D43: =D42/D4 -> -0.024517249 | E43: =E42/E4 -> -0.042650687 | F43: =F42/F4 -> -0.07226764 | G43: =G42/G4 -> -0.11197355 | H43: =H42/H4 -> -0.062747166 | I43: =I42/I4 -> -0.0026009413 | J43: =J42/J4 -> -0.016584158 | K43: =K42/K4 -> -0.045932827 | ... CW43: =CW42/CW4 -> 0.16973627
C45: Investment Income | D45: -314 | E45: -450 | F45: -319 | G45: -133 | H45: -77 | I45: -110 | J45: -71 | K45: -391 | L45: 34 | M45: -77 | N45: -61 | O45: -516 | P45: -620 | Q45: -45 | R45: -13 | S45: 96 | T45: 46 | U45: 84 | V45: 32 | W45: 26 | X45: 16 | Y45: 15 | Z45: 89 | AA45: 15 | AB45: 13 | AC45: 6 | AD45: 12 | AE45: 46 | AF45: 23 | AG45: 22 | AH45: 31 | AI45: 36 | AJ45: 112 | AK45: 49 | AL45: 50 | AM45: 52 | AN45: 36 | AO45: 187 | AP45: 37 | AQ45: 37 | AR45: 49 | AS45: 74 | AT45: 197 | AU45: 145 | AV45: 151 | AW45: 112 | AX45: 193 | AY45: 601 | AZ45: 191 | BA45: 242 | BB45: 272 | BC45: 328 | BD45: 1033 | BE45: 414 | BF45: 547 | BG45: 628 | BH45: 740 | BI45: =SUM(BE45:BH45) -> 2329 | BJ45: 577 | BK45: 813 | BL45: 843 | BM45: 714 | BN45: =SUM(BJ45:BM45) -> 2947 | BO45: 640 | BP45: 332 | BQ45: 107 | BR45: 129 | BS45: =SUM(BO45:BR45) -> 1208 | BT45: 97 | BU45: 79 | BV45: 66 | BW45: 36 | BX45: =SUM(BT45:BW45) -> 278 | BY45: 48 | BZ45: 172 | CA45: 586 | CB45: 864 | CC45: =SUM(BY45:CB45) -> 1670 | CD45: 1127 | CE45: 1611 | CF45: 2635 | CG45: 2288 | CH45: =SUM(CD45:CG45) -> 7661 | CI45: 2879 | CJ45: 2794 | CK45: 2704 | CL45: 2205 | CM45: =SUM(CI45:CL45) -> 10582 | CN45: 1849 | CO45: 688 | CP45: 1076 | CQ45: 1036 | CR45: =SUM(CN45:CQ45) -> 4649 | CS45: 950 | CT45: 820 | CU45: =CT45-45 -> 775 | CV45: =CU45-45 -> 730 | CW45: =SUM(CS45:CV45) -> 3275
...

Sheet BS
B4: Balance Sheet | D4: =IS!D3 -> 2005 | E4: =IS!E3 -> 2006 | F4: =IS!F3 -> 2007 | G4: =IS!G3 -> 1Q08 | H4: =IS!H3 -> 2Q08 | I4: =IS!I3 -> 2Q08 | J4: =IS!J3 -> 4Q08 | K4: =IS!K3 -> 2008 | ... CW4: =IS!CW3 -> 2026E
B5: Assets
C6: Cash and equivalents | J6: 3715 | O6: 5931 | Q6: 5996 | R6: 37973 | S6: 39113 | T6: 40473 | V6: =T6+CF!V62 -> 40447 | W6: 29788 | X6: 31546 | Y6: 31985 | AA6: 33063 | AB6: 35501 | AC6: 69715 | AD6: 66050 | AE6: =AD6 -> 66050 | AF6: 72559 | AG6: 75134 | AH6: 80813 | AI6: 131294 | AJ6: =AI6 -> 131294 | AK6: 134603 | AL6: =AK6+CF!AL62 -> 136508 | AM6: 140822 | AN6: 130795 | AO6: =AN6 -> 130795 | AP6: 133550 | AQ6: 121344 | AR6: =117887 -> 117887 | AS6: =121538 -> 121538 | AT6: =AS6 -> 121538 | AU6: 110889 | AV6: 107160 | AW6: 109635 | AX6: 115877 | AY6: =AX6 -> 115877 | AZ6: 128707 | BA6: 131744 | BB6: 128984 | BC6: 123127 | BD6: =BC6 -> 123127 | BE6: 120547 | BF6: 125385 | BG6: 144748 | BH6: 133859 | BI6: =BH6 -> 133859 | BJ6: 143715 | BK6: 147023 | BL6: 149727 | BM6: 179252 | BN6: =BM6 -> 179252 | BO6: 184484 | BP6: 174850 | BQ6: 208930 | BR6: 149692 | BS6: =BR6 -> 149692 | BT6: 169274 | BU6: 184367 | BV6: 195803 | BW6: 207552 | BX6: =BW6 -> 207552 | BY6: 203088 | BZ6: 212725 | CA6: 186230 | CB6: 162893 | CC6: =CB6 -> 162893 | CD6: 182304 | CE6: 209264 | CF6: 178702 | CG6: 219081 | CH6: =CG6 -> 219081 | CI6: 234637 | CJ6: 240232 | CK6: 198842 | CL6: 241017 | CM6: =CL6 -> 241017 | CN6: 94921 | CO6: 107603 | CP6: 133725 | CQ6: 151355 | CR6: =CQ6 -> 151355 | CS6: =CR6+CF!CS62 -> 239503.56 | CT6: =CS6+CF!CT62 -> 290198.54 | CU6: =CT6+CF!CU62 -> 342559.1 | CV6: =CU6+CF!CV62 -> 396561.05 | CW6: =CV6 -> 396561.05
C7: Short term marketable securities | AR7: 5014 | AS7: 7517 | AT7: =AS7 -> 7517 | AU7: 10010 | AV7: 21010 | AW7: 15616 | AX7: 23076 | AY7: =AX7 -> 23076 | AZ7: 25550 | BA7: 26896 | BB7: 34869 | BC7: 40192 | BD7: =BC7 -> 40192 | BE7: 45272 | BF7: 47352 | BG7: 44654 | BH7: 44537 | BI7: =BH7 -> 44537 | BJ7: 41683 | BK7: 51651 | BL7: 51446 | BM7: 34284 | BN7: =BM7 -> 34284 | BO7: 30074 | BP7: 50775 | BQ7: 52300 | BR7: 37786 | BS7: =BR7 -> 37786 | BT7: 39174 | BU7: 48999 | BV7: 56183 | BW7: 49758 | BX7: =BW7 -> 49758 | BY7: 39968 | BZ7: 46513 | CA7: 50928 | CB7: 51412 | CC7: =CB7 -> 51412 | CD7: 51146 | CE7: 60914 | CF7: 60628 | CG7: 56359 | CH7: =CG7 -> 56359 | CI7: 56174 | CJ7: 31554 | CK7: 6931 | CL7: 0 | CM7: =CL7 -> 0 | CN7: =CM7 -> 0 | CP7: =CO7 -> 0 | CR7: =CQ7 -> 0 | CS7: =CR7 -> 0 | CT7: =CS7 -> 0 | CU7: =CT7 -> 0 | CV7: =CU7 -> 0 | CW7: =CV7 -> 0
C8: Accounts receivables | J8: 4564 | O8: 4766 | Q8: 5125 | R8: 4987 | S8: 5517 | T8: 5574 | V8: 6356 | W8: 7353 | X8: 7695 | Y8: 7958 | AA8: 7981 | AB8: 9029 | AC8: 10146 | AD8: 10940 | AE8: =AD8 -> 10940 | AF8: 10788 | AG8: 11707 | AH8: 11148 | AI8: 11611 | AJ8: =AI8 -> 11611 | AK8: 12166 | AL8: 13348 | AM8: 13594 | AN8: 15422 | AO8: =AN8 -> 15422 | AP8: 15823 | AQ8: 17255 | AR8: 17945 | AS8: 17615 | AT8: =AS8 -> 17615 | AU8: 20426 | AV8: 20432 | AW8: 21361 | AX8: 20746 | AY8: =AX8 -> 20746 | AZ8: 22683 | BA8: 21545 | BB8: 24175 | BC8: 24897 | BD8: =BC8 -> 24897 | BE8: 25948 | BF8: 28171 | BG8: 27289 | BH8: 27488 | BI8: =BH8 -> 27488 | BJ8: 28301 | BK8: 30747 | BL8: 29383 | BM8: 31532 | BN8: =BM8 -> 31532 | BO8: 33275 | BP8: 37840 | BQ8: 34048 | BR8: =37811-4233 -> 33578 | BS8: =BR8 -> 33578 | BT8: 35270 | BU8: 37936 | BV8: 35330 | BW8: 34562 | BX8: =BW8 -> 34562 | BY8: 38778 | BZ8: =44559-4454 -> 40105 | CA8: 36787 | CB8: =42501-3066 -> 39435 | CC8: =CB8 -> 39435 | CD8: =46654-3217 -> 43437 | CE8: =48092-3100 -> 44992 | CF8: =48218-3077 -> 45141 | CG8: 46840 | CH8: =CG8 -> 46840 | CI8: 52135 | CJ8: 55397 | CK8: 55570 | CL8: 52035 | CM8: =CL8 -> 52035 | CN8: 63390 | CO8: 67512 | CP8: 67439 | CQ8: 68166 | CR8: =CQ8 -> 68166 | CS8: =CS55*IS!CS4 -> 63568.433 | CT8: =CT55*IS!CT4 -> 65240.578 | CU8: =CU55*IS!CU4 -> 67458.398 | CV8: =CV55*IS!CV4 -> 68629.065 | CW8: =CV8 -> 68629.065
