Workbook
Name \0: #REF!
Name \1: #N/A
Name \2: #N/A
Name \3: #N/A
Name \4: #N/A
Name \5: #N/A
Name \6: #N/A
Name \a: #N/A
Name \b: #REF!
Name \c: #REF!
Name \d: #REF!
Name \e: #REF!
Name \f: #REF!
Name \g: #REF!
Name \h: #REF!
Name \i: #REF!
Name \j: #REF!
Name \k: #N/A
Name \l: #REF!
Name \m: #REF!
Name \n: #REF!
Name \o: #REF!
Name \p: #REF!
Name \PRINJV: #REF!
Name \q: #REF!
Name \r: #REF!
Name \s: #REF!
Name \t: #REF!
Name \u: #REF!
Name \v: #N/A
Name \w: #REF!
Name \x: #REF!
Name \y: #REF!
Name \z: #REF!
Name _: #REF!
Name _.4: #REF!
Name _????_3: #REF!
Name _????1_3: #REF!
Name _????8_3: #REF!
Name _??_3: #REF!
Name _??1???_3: #REF!
Name __: #REF!
Name ___: #REF!
Name ____: #REF!
Name _____: #REF!
Name ______: #REF!
Name ________: #REF!
Name __________: #REF!
Name ____________: #REF!
Name _____________: #REF!
Name ______________: #REF!
Name _______________________________________________tax2: #REF!
Name ______________________________________________tax2: #REF!
Name _____________________________________________tax2: #REF!
Name ____________________________________________tax2: #REF!
Name ___________________________________________tax2: #REF!
Name __________________________________________tax2: #REF!
Name _________________________________________tax2: #REF!
Name ________________________________________tax2: #REF!
Name _______________________________________tax2: #REF!

Sheet Disclaimer
C5: Equity Research
C7: Financial Model
C8: Software
C9: 46083
C12: Varonis Systems, Inc. (VRNS)
C17: Wells Fargo Software Team
C19: Richard Poland | E19: David Unger
C20: Analyst | E20: Associate Analyst
C21: (212) 214-5333 | E21: (212) 214-5317
C22: richard.d.poland@wellsfargo.com | E22: David.Unger@wellsfargo.com
C24: Important Disclaimers:

Sheet Income Statement
A1: Varonis Systems, Inc. (VRNS)
A2: Income Statement | B2: 2017/1F | C2: 2017/2F | D2: 2017/3F | E2: 2017/4F | F2: 2018/1F | G2: 2018/2F | H2: 2018/3F | I2: 2018/4F | J2: 2019/1F | K2: 2019/2F | L2: 2019/3F | M2: 2019/4F | N2: 2019/1F | O2: 2019/2F | P2: 2019/3F | Q2: 2019/4F | R2: 2021/1F | S2: 2021/2F | T2: 2021/3F | U2: 2021/4F | V2: 2022/1F | W2: 2022/2F | X2: 2022/3F | Y2: 2022/4F | Z2: 2023/1F | AA2: 2023/2F | AB2: 2023/3F | AC2: 2023/4F | AD2: 2024/1F | AE2: 2024/2F | AF2: 2024/3F | AG2: 2024/4F | AH2: 2025/1F | AI2: 2025/2F | AJ2: 2025/3F | AK2: 2025/4F | AL2: 2026/1F | AM2: 2026/2F | AN2: 2026/3F | AO2: 2026/4F | AP2: 2027/1F | AQ2: 2027/2F | AR2: 2027/3F | AS2: 2027/4F | AU2: 2017 | AV2: 2018 | AW2: 2019 | AX2: 2020 | AY2: 2021 | AZ2: 2022 | BA2: 2023 | BB2: 2024 | BC2: =BB2+1 -> 2025 | BD2: =BC2+1 -> 2026 | BE2: =BD2+1 -> 2027
B3: 2017 | F3: 2018 | J3: 2019 | N3: 2020 | R3: 2021 | V3: 2022 | Z3: 2023 | AD3: 2024 | AH3: =AD3+1 -> 2025 | AL3: =AH3+1 -> 2026 | AP3: =AL3+1 -> 2027
A4: ($ in millions, unless otherwise stated) | B4: 42825 | C4: 42916 | D4: 43008 | E4: 43100 | F4: 43190 | G4: 43281 | H4: 43373 | I4: 43465 | J4: 43555 | K4: 43646 | L4: 43738 | M4: 43830 | N4: 43921 | O4: 44012 | P4: 44104 | Q4: 44196 | R4: 44286 | S4: 44377 | T4: 44469 | U4: 44561 | V4: 44651 | W4: 44742 | X4: 44834 | Y4: 44926 | Z4: 45016 | AA4: 45107 | AB4: 45199 | AC4: 45291 | AD4: 45382 | AE4: 45473 | AF4: Sep-24 | AG4: Dec-24 | AH4: Mar-25 | AI4: Jun-25 | AJ4: Sep-25 | AK4: Dec-25 | AL4: Mar-26E | AM4: Jun-26E | AN4: Sep-26E | AO4: Dec-26E | AP4: Mar-27E | AQ4: Jun-27E | AR4: Sep-27E | AS4: Dec-27E | AU4: 2017 | AV4: 2018 | AW4: 2019 | AX4: 2020 | AY4: 2021 | AZ4: 2022 | BA4: 2023 | BB4: 2024 | BC4: 2025 | BD4: 2026E | BE4: 2027E
A5: Subscription | B5: =+'Revenue Build'!B13 -> 0 | C5: =+'Revenue Build'!C13 -> 0 | D5: =+'Revenue Build'!D13 -> 0 | E5: =+'Revenue Build'!E13 -> 0 | F5: =+'Revenue Build'!F13 -> 1.071 | G5: =+'Revenue Build'!G13 -> 1.291 | H5: =+'Revenue Build'!H13 -> 2.539 | I5: =+'Revenue Build'!I13 -> 3.849 | ... AI5: =+'Revenue Build'!AI13 -> 138.269 | AJ5: ='Revenue Build'!AJ13 -> 150.636 | AK5: ='Revenue Build'!AK13 -> 163.277 | AL5: ='Revenue Build'!AL13 -> 159.38907 | AM5: ='Revenue Build'!AM13 -> 171.24836 | AN5: ='Revenue Build'!AN13 -> 183.01573 | AO5: ='Revenue Build'!AO13 -> 195.52477 | AP5: ='Revenue Build'!AP13 -> 206.81946 | AQ5: ='Revenue Build'!AQ13 -> 214.59312 | ... AS5: ='Revenue Build'!AS13 -> 231.88418 | AU5: =SUM(B5:E5) -> 0 | AV5: =SUM(F5:I5) -> 8.75 | AW5: =SUM(J5:M5) -> 76.73 | AX5: =SUM(N5:Q5) -> 161.188 | AY5: =SUM(R5:U5) -> 268.942 | AZ5: =SUM(V5:Y5) -> 366.144 | BA5: =SUM(Z5:AC5) -> 400.907 | BB5: =SUM(AD5:AG5) -> 463.022 | BC5: =SUM(AH5:AK5) -> 572.23 | BD5: =SUM(AL5:AO5) -> 709.17794 | BE5: =SUM(AP5:AS5) -> 876.61962
A6: Perpetual Licnese | B6: ='Revenue Build'!B28 -> 18.092 | C6: ='Revenue Build'!C28 -> 27.31 | D6: ='Revenue Build'!D28 -> 29 | E6: ='Revenue Build'!E28 -> 45.939 | F6: ='Revenue Build'!F28 -> 24.086 | G6: ='Revenue Build'!G28 -> 32.27 | H6: ='Revenue Build'!H28 -> 33.432 | I6: ='Revenue Build'!I28 -> 49.79 | ... AS6: ='Revenue Build'!AS28 -> 0 | AU6: =SUM(B6:E6) -> 120.341 | AV6: =SUM(F6:I6) -> 139.578 | AW6: =SUM(J6:M6) -> 42.093 | AX6: =SUM(N6:Q6) -> 1.473 | AY6: =SUM(R6:U6) -> 1.89 | AZ6: =SUM(V6:Y6) -> 0 | BA6: =SUM(Z6:AC6) -> 0 | BB6: =SUM(AD6:AG6) -> 0 | BC6: =SUM(AH6:AK6) -> 0 | BD6: =SUM(AI6:AL6) -> 0 | BE6: =SUM(AM6:AP6) -> 0
A7: Maintenance and Services | B7: =+'Revenue Build'!B33 -> 21.501 | C7: =+'Revenue Build'!C33 -> 22.121 | D7: =+'Revenue Build'!D33 -> 24.365 | E7: =+'Revenue Build'!E33 -> 27.062 | F7: =+'Revenue Build'!F33 -> 28.371 | G7: =+'Revenue Build'!G33 -> 28.629 | H7: =+'Revenue Build'!H33 -> 31.081 | I7: =+'Revenue Build'!I33 -> 33.879 | ... AI7: =+'Revenue Build'!AI33 -> 13.894 | AJ7: ='Revenue Build'!AJ33 -> 10.941 | AK7: ='Revenue Build'!AK33 -> 10.092 | AL7: ='Revenue Build'!AL33 -> 5.9497918 | AM7: ='Revenue Build'!AM33 -> 4.6623359 | AN7: ='Revenue Build'!AN33 -> 3.3456197 | AO7: ='Revenue Build'!AO33 -> 2 | AP7: ='Revenue Build'!AP33 -> 2 | AQ7: ='Revenue Build'!AQ33 -> 2 | ... AS7: ='Revenue Build'!AS33 -> 2 | AU7: =SUM(B7:E7) -> 95.049 | AV7: =SUM(F7:I7) -> 121.96 | AW7: =SUM(J7:M7) -> 135.367 | AX7: =SUM(N7:Q7) -> 130.028 | AY7: =SUM(R7:U7) -> 119.302 | AZ7: =SUM(V7:Y7) -> 107.49 | BA7: =SUM(Z7:AC7) -> 98.253 | BB7: =SUM(AD7:AG7) -> 87.928 | BC7: =SUM(AH7:AK7) -> 51.302 | BD7: =SUM(AL7:AO7) -> 15.957747 | BE7: =SUM(AP7:AS7) -> 8
A8: Total revenue | B8: =+'Revenue Build'!B5 -> 39.593 | C8: =+'Revenue Build'!C5 -> 49.431 | D8: =+'Revenue Build'!D5 -> 53.365 | E8: =+'Revenue Build'!E5 -> 73.001 | F8: =+'Revenue Build'!F5 -> 53.528 | G8: =+'Revenue Build'!G5 -> 62.19 | H8: =+'Revenue Build'!H5 -> 67.052 | I8: =+'Revenue Build'!I5 -> 87.518 | ... AS8: =+'Revenue Build'!AS5 -> 233.88418 | AU8: =SUM(B8:E8) -> 215.39 | AV8: =SUM(F8:I8) -> 270.288 | AW8: =SUM(J8:M8) -> 254.19 | AX8: =SUM(N8:Q8) -> 292.689 | AY8: =SUM(R8:U8) -> 390.134 | AZ8: =SUM(V8:Y8) -> 473.634 | BA8: =SUM(Z8:AC8) -> 499.16 | BB8: =SUM(AD8:AG8) -> 550.95 | BC8: =SUM(AH8:AK8) -> 623.532 | BD8: =SUM(AL8:AO8) -> 725.13568 | BE8: =SUM(AP8:AS8) -> 884.61962
A9: Consensus revenue | B9: ='Revenue Build'!B6 -> 40.38 | C9: ='Revenue Build'!C6 -> 47.532444 | D9: ='Revenue Build'!D6 -> 50.554272 | E9: ='Revenue Build'!E6 -> 66.51052 | F9: ='Revenue Build'!F6 -> 49.838929 | G9: ='Revenue Build'!G6 -> 62.105238 | H9: ='Revenue Build'!H6 -> 64.53161 | I9: ='Revenue Build'!I6 -> 87.408971 | ... AS9: ='Revenue Build'!AS6 -> 230.41508 | AU9: ='Revenue Build'!AU6 -> 210.66552 | AV9: ='Revenue Build'!AV6 -> 270.18211 | AW9: ='Revenue Build'!AW6 -> 253.4685 | AX9: ='Revenue Build'!AX6 -> 281.78387 | AY9: ='Revenue Build'!AY6 -> 385.55766 | AZ9: ='Revenue Build'!AZ6 -> 471.20837 | BA9: ='Revenue Build'!BA6 -> 496.67471 | BB9: ='Revenue Build'!BB6 -> 557.97652 | ... BE9: ='Revenue Build'!BE6 -> 857.74118
A10: Management Guidance - Total Revenue
A11: Low | N11: ='Revenue Build'!N9 -> 53.9 | O11: ='Revenue Build'!O9 -> 56 | P11: ='Revenue Build'!P9 -> 68 | Q11: ='Revenue Build'!Q9 -> 82 | R11: ='Revenue Build'!R9 -> 68 | S11: ='Revenue Build'!S9 -> 82.5 | T11: ='Revenue Build'!T9 -> 96 | U11: ='Revenue Build'!U9 -> 120 | ... AS11: ='Revenue Build'!AS9 | AY11: ='Revenue Build'!AY9 -> 383.5 | AZ11: ='Revenue Build'!AZ9 -> 519 | BA11: ='Revenue Build'!BA9 -> 495 | BB11: ='Revenue Build'!BB9 -> 554.4 | BC11: ='Revenue Build'!BC9 -> 615.2 | BD11: ='Revenue Build'!BD9 -> 722
A12: Mid | N12: ='Revenue Build'!N10 -> 54.1 | O12: ='Revenue Build'!O10 -> 57 | P12: ='Revenue Build'!P10 -> 69.5 | Q12: ='Revenue Build'!Q10 -> 83.5 | R12: ='Revenue Build'!R10 -> 68.75 | S12: ='Revenue Build'!S10 -> 83.25 | T12: ='Revenue Build'!T10 -> 97 | U12: ='Revenue Build'!U10 -> 121.5 | ... AS12: ='Revenue Build'!AS10 | AY12: ='Revenue Build'!AY10 -> 385 | AZ12: ='Revenue Build'!AZ10 -> 496 | BA12: ='Revenue Build'!BA10 -> 497 | BB12: ='Revenue Build'!BB10 -> 556.9 | BC12: ='Revenue Build'!BC10 -> 618.2 | BD12: ='Revenue Build'!BD10 -> 726
A13: High | N13: ='Revenue Build'!N11 -> 54.3 | O13: ='Revenue Build'!O11 -> 58 | P13: ='Revenue Build'!P11 -> 71 | Q13: ='Revenue Build'!Q11 -> 85 | R13: ='Revenue Build'!R11 -> 69.5 | S13: ='Revenue Build'!S11 -> 84 | T13: ='Revenue Build'!T11 -> 98 | U13: ='Revenue Build'!U11 -> 123 | ... AS13: ='Revenue Build'!AS11 | AY13: ='Revenue Build'!AY11 -> 386.5 | AZ13: ='Revenue Build'!AZ11 -> 473 | BA13: ='Revenue Build'!BA11 -> 499 | BB13: ='Revenue Build'!BB11 -> 559.4 | BC13: ='Revenue Build'!BC11 -> 621.2 | BD13: ='Revenue Build'!BD11 -> 730
A15: Total cost of revenue | B15: =B105-B129-B138-B147 -> 4.433 | C15: =C105-C129-C138-C147 -> 4.596 | D15: =D105-D129-D138-D147 -> 5.115 | E15: =E105-E129-E138-E147 -> 5.401 | F15: =F105-F129-F138-F147 -> 5.813 | G15: =G105-G129-G138-G147 -> 5.894 | H15: =H105-H129-H138-H147 -> 6.571 | I15: =I105-I129-I138-I147 -> 7.285 | ... AK15: =AK105-AK129-AK138-AK147 -> 34.685 | AL15: =AL8*(1-AL63) -> 36.374551 | AM15: =AM8*(1-AM63) -> 38.348532 | AN15: =AN8*(1-AN63) -> 40.254052 | AO15: =AO8*(1-AO63) -> 42.270301 | AP15: =AP8*(1-AP63) -> 44.269726 | AQ15: =AQ8*(1-AQ63) -> 45.484555 | AR15: =AR8*(1-AR63) -> 46.867156 | AS15: =AS8*(1-AS63) -> 48.18014 | AU15: =SUM(B15:E15) -> 19.545 | AV15: =SUM(F15:I15) -> 25.563 | AW15: =SUM(J15:M15) -> 32.348 | AX15: =SUM(N15:Q15) -> 38.686 | AY15: =SUM(R15:U15) -> 47.82 | AZ15: =SUM(V15:Y15) -> 56.996 | BA15: =SUM(Z15:AC15) -> 62.6 | BB15: =SUM(AD15:AG15) -> 86.756 | BC15: =SUM(AH15:AK15) -> 124.578 | BD15: =SUM(AL15:AO15) -> 157.24744 | BE15: =SUM(AP15:AS15) -> 184.80158
A16: Gross profit | B16: =B8-B15 -> 35.16 | C16: =C8-C15 -> 44.835 | D16: =D8-D15 -> 48.25 | E16: =E8-E15 -> 67.6 | F16: =F8-F15 -> 47.715 | G16: =G8-G15 -> 56.296 | H16: =H8-H15 -> 60.481 | I16: =I8-I15 -> 80.233 | ... AS16: =AS8-AS15 -> 185.70404 | AU16: =SUM(B16:E16) -> 195.845 | AV16: =SUM(F16:I16) -> 244.725 | AW16: =SUM(J16:M16) -> 221.842 | AX16: =SUM(N16:Q16) -> 254.003 | AY16: =SUM(R16:U16) -> 342.314 | AZ16: =SUM(V16:Y16) -> 416.638 | BA16: =SUM(Z16:AC16) -> 436.56 | BB16: =SUM(AD16:AG16) -> 464.194 | BC16: =SUM(AH16:AK16) -> 498.954 | BD16: =SUM(AL16:AO16) -> 567.88825 | BE16: =SUM(AP16:AS16) -> 699.81804
A17: Consensus gross profit | B17: ='[2]VA Consensus'!C30 -> 35.935 | C17: ='[2]VA Consensus'!D30 -> 42.827976 | D17: ='[2]VA Consensus'!E30 -> 45.832307 | E17: ='[2]VA Consensus'!F30 -> 60.840642 | F17: ='[2]VA Consensus'!G30 -> 44.527167 | G17: ='[2]VA Consensus'!H30 -> 56.212896 | H17: ='[2]VA Consensus'!I30 -> 58.323792 | I17: ='[2]VA Consensus'!J30 -> 80.246522 | ... AS17: ='[2]VA Consensus'!AT30 -> 183.49853 | AU17: ='[2]VA Consensus'!AV30 -> 190.83621 | AV17: ='[2]VA Consensus'!AW30 -> 244.69338 | AW17: ='[2]VA Consensus'!AX30 -> 221.50528 | AX17: ='[2]VA Consensus'!AY30 -> 243.40759 | AY17: ='[2]VA Consensus'!AZ30 -> 336.28952 | AZ17: ='[2]VA Consensus'!BA30 -> 412.79012 | BA17: ='[2]VA Consensus'!BB30 -> 433.41782 | BB17: ='[2]VA Consensus'!BC30 -> 472.21847 | ... BE17: ='[2]VA Consensus'!BF30 -> 682.00556
A19: Operating expenses
A20: Research and development | B20: =B109-B130-B139-B148 -> 9.264 | C20: =C109-C130-C139-C148 -> 10.184 | D20: =D109-D130-D139-D148 -> 10.502 | E20: =E109-E130-E139-E148 -> 12.143 | F20: =F109-F130-F139-F148 -> 13.401 | G20: =G109-G130-G139-G148 -> 14.628 | H20: =H109-H130-H139-H148 -> 15.154 | I20: =I109-I130-I139-I148 -> 16.963 | ... AK20: =AK109-AK130-AK139-AK148 -> 51.862 | AL20: =AL$8*AL65 -> 52.908437 | AM20: =AM$8*AM65 -> 46.792246 | AN20: =AN$8*AN65 -> 51.249371 | AO20: =AO$8*AO65 -> 49.381192 | AP20: =AP$8*AP65 -> 60.557644 | AQ20: =AQ$8*AQ65 -> 57.397176 | AR20: =AR$8*AR65 -> 60.837173 | AS20: =AS$8*AS65 -> 56.132202 | AU20: =SUM(B20:E20) -> 42.093 | AV20: =SUM(F20:I20) -> 60.146 | AW20: =SUM(J20:M20) -> 67.414 | AX20: =SUM(N20:Q20) -> 76.151 | AY20: =SUM(R20:U20) -> 96.238 | AZ20: =SUM(V20:Y20) -> 124.495 | BA20: =SUM(Z20:AC20) -> 133.431 | BB20: =SUM(AD20:AG20) -> 154.395 | BC20: =SUM(AH20:AK20) -> 187.357 | BD20: =SUM(AL20:AO20) -> 200.33125 | BE20: =SUM(AP20:AS20) -> 234.9242
A21: Sales and marketing | B21: =B110-B131-B140-B149 -> 28.536 | C21: =C110-C131-C140-C149 -> 30.052 | D21: =D110-D131-D140-D149 -> 30.389 | E21: =E110-E131-E140-E149 -> 35.465 | F21: =F110-F131-F140-F149 -> 35.401 | G21: =G110-G131-G140-G149 -> 36.644 | H21: =H110-H131-H140-H149 -> 36.798 | I21: =I110-I131-I140-I149 -> 40.25 | ... AK21: =AK110-AK131-AK140-AK149 -> 67.992 | AL21: =AL$8*AL66 -> 71.922407 | AM21: =AM$8*AM66 -> 72.123387 | AN21: =AN$8*AN66 -> 76.408154 | AO21: =AO$8*AO66 -> 80.985155 | AP21: =AP$8*AP66 -> 85.615979 | AQ21: =AQ$8*AQ66 -> 85.554281 | AR21: =AR$8*AR66 -> 86.974626 | AS21: =AS$8*AS66 -> 90.045408 | AU21: =SUM(B21:E21) -> 124.442 | AV21: =SUM(F21:I21) -> 149.093 | AW21: =SUM(J21:M21) -> 153.208 | AX21: =SUM(N21:Q21) -> 151.533 | AY21: =SUM(R21:U21) -> 185.64 | AZ21: =SUM(V21:Y21) -> 220.636 | BA21: =SUM(Z21:AC21) -> 227.874 | BB21: =SUM(AD21:AG21) -> 244.079 | BC21: =SUM(AH21:AK21) -> 259.522 | BD21: =SUM(AL21:AO21) -> 301.4391 | BE21: =SUM(AP21:AS21) -> 348.19029
A22: General and administrative | B22: =B111-B132-B141-B150 -> 4.486 | C22: =C111-C132-C141-C150 -> 5.248 | D22: =D111-D132-D141-D150 -> 5.431 | E22: =E111-E132-E141-E150 -> 6.571 | F22: =F111-F132-F141-F150 -> 5.615 | G22: =G111-G132-G141-G150 -> 6.048 | H22: =H111-H132-H141-H150 -> 6.533 | I22: =I111-I132-I141-I150 -> 7.489 | ... AK22: =AK111-AK132-AK141-AK150 -> 14.277 | AL22: =AL$8*AL67 -> 14.880498 | AM22: =AM$8*AM67 -> 15.831963 | AN22: =AN$8*AN67 -> 15.840715 | AO22: =AO$8*AO67 -> 16.789605 | AP22: =AP$8*AP67 -> 18.793751 | AQ22: =AQ$8*AQ67 -> 18.410415 | AR22: =AR$8*AR67 -> 18.025829 | AS22: =AS$8*AS67 -> 17.541313 | AU22: =SUM(B22:E22) -> 21.736 | AV22: =SUM(F22:I22) -> 25.685 | AW22: =SUM(J22:M22) -> 28.42 | AX22: =SUM(N22:Q22) -> 30.767 | AY22: =SUM(R22:U22) -> 35.195 | AZ22: =SUM(V22:Y22) -> 41.973 | BA22: =SUM(Z22:AC22) -> 46.512 | BB22: =SUM(AD22:AG22) -> 49.809 | BC22: =SUM(AH22:AK22) -> 55.721 | BD22: =SUM(AL22:AO22) -> 63.342781 | BE22: =SUM(AP22:AS22) -> 72.771309
A23: Total operating expenses | B23: =B20+B21+B22 -> 42.286 | C23: =C20+C21+C22 -> 45.484 | D23: =D20+D21+D22 -> 46.322 | E23: =E20+E21+E22 -> 54.179 | F23: =F20+F21+F22 -> 54.417 | G23: =G20+G21+G22 -> 57.32 | H23: =H20+H21+H22 -> 58.485 | I23: =I20+I21+I22 -> 64.702 | ... AS23: =AS20+AS21+AS22 -> 163.71892 | AU23: =SUM(B23:E23) -> 188.271 | AV23: =SUM(F23:I23) -> 234.924 | AW23: =SUM(J23:M23) -> 249.042 | AX23: =SUM(N23:Q23) -> 258.451 | AY23: =SUM(R23:U23) -> 317.073 | AZ23: =SUM(V23:Y23) -> 387.104 | BA23: =SUM(Z23:AC23) -> 407.817 | BB23: =SUM(AD23:AG23) -> 448.283 | BC23: =SUM(AH23:AK23) -> 502.6 | BD23: =SUM(AL23:AO23) -> 565.11313 | BE23: =SUM(AP23:AS23) -> 655.8858
A24: Operating Income | B24: =B16-B23 -> -7.126 | C24: =C16-C23 -> -0.649 | D24: =D16-D23 -> 1.928 | E24: =E16-E23 -> 13.421 | F24: =F16-F23 -> -6.702 | G24: =G16-G23 -> -1.024 | H24: =H16-H23 -> 1.996 | I24: =I16-I23 -> 15.531 | ... AS24: =AS16-AS23 -> 21.985113 | AU24: =SUM(B24:E24) -> 7.574 | AV24: =SUM(F24:I24) -> 9.801 | AW24: =SUM(J24:M24) -> -27.2 | AX24: =SUM(N24:Q24) -> -4.448 | AY24: =SUM(R24:U24) -> 25.241 | AZ24: =SUM(V24:Y24) -> 29.534 | BA24: =SUM(Z24:AC24) -> 28.743 | BB24: =SUM(AD24:AG24) -> 15.911 | BC24: =SUM(AH24:AK24) -> -3.646 | BD24: =SUM(AL24:AO24) -> 2.7751193 | BE24: =SUM(AP24:AS24) -> 43.932244 | BH24: =+BD24/BD8 -> 0.0038270345
A25: Consensus operating income | B25: ='[2]VA Consensus'!C36 -> -6.219 | C25: ='[2]VA Consensus'!D36 -> -1.8211362 | D25: ='[2]VA Consensus'!E36 -> 0.34439955 | E25: ='[2]VA Consensus'!F36 -> 9.5522178 | F25: ='[2]VA Consensus'!G36 -> -8.3391343 | G25: ='[2]VA Consensus'!H36 -> -0.98990951 | H25: ='[2]VA Consensus'!I36 -> 0.35928966 | I25: ='[2]VA Consensus'!J36 -> 11.506609 | ... AS25: ='[2]VA Consensus'!AT36 -> 17.412038 | AU25: ='[2]VA Consensus'!AV36 -> 5.2512178 | AV25: ='[2]VA Consensus'!AW36 -> 5.7860373 | AW25: ='[2]VA Consensus'!AX36 -> -27.555533 | AX25: ='[2]VA Consensus'!AY36 -> -13.076283 | AY25: ='[2]VA Consensus'!AZ36 -> 20.528773 | AZ25: ='[2]VA Consensus'!BA36 -> 26.351861 | BA25: ='[2]VA Consensus'!BB36 -> 27.732461 | BB25: ='[2]VA Consensus'!BC36 -> 22.14059 | ... BE25: ='[2]VA Consensus'!BF36 -> 43.650134 | BH25: =+BD25/BD9 -> 0.0025594523
A26: Management Guidance - Operating Income
A27: Low | N27: -17.6 | O27: -11 | P27: -3 | Q27: 5 | R27: -12 | S27: -2.5 | T27: 3.5 | U27: 16.5 | V27: -10.5 | W27: 0 | X27: 8.5 | Y27: 22 | Z27: -7 | AA27: 0.5 | AB27: 1 | AC27: 25 | AD27: -15 | AE27: -6 | AF27: 7 | AG27: 20 | AH27: -14 | AI27: -5 | AJ27: 1 | AK27: 0 | AL27: -11 | AY27: 19.5 | AZ27: 25.5 | BA27: 26.5 | BB27: 20.6 | BC27: -8.2 | BD27: 0
A28: Mid | N28: =AVERAGE(N27,N29) -> -17.45 | O28: =AVERAGE(O27,O29) -> -10.5 | P28: =AVERAGE(P27,P29) -> -2.5 | Q28: =AVERAGE(Q27,Q29) -> 5.5 | R28: =AVERAGE(R27,R29) -> -11.5 | S28: =AVERAGE(S27,S29) -> -2 | T28: =AVERAGE(T27,T29) -> 4 | U28: =AVERAGE(U27,U29) -> 17.5 | ... AB28: =AVERAGE(AB27,AB29) -> 1.5 | AC28: =IFERROR(AVERAGE(AC27,AC29),"") -> 26 | AD28: =IFERROR(AVERAGE(AD27,AD29),"") -> -14 | AE28: =IFERROR(AVERAGE(AE27,AE29),"") -> -5.5 | AF28: =IFERROR(AVERAGE(AF27,AF29),"") -> 7.5 | AG28: =IFERROR(AVERAGE(AG27,AG29),"") -> 21 | AH28: =IFERROR(AVERAGE(AH27,AH29),"") -> -12.5 | AI28: =IFERROR(AVERAGE(AI27,AI29),"") -> -3.5 | AJ28: =IFERROR(AVERAGE(AJ27,AJ29),"") -> 2.5 | ... AL28: =IFERROR(AVERAGE(AL27,AL29),"") -> -10.5 | AM28: =+'Income Statement'!AM$24-AM24 -> 0 | AN28: =+'Income Statement'!AN$24-AN24 -> 0 | AO28: =+'Income Statement'!AO$24-AO24 -> 0 | AP28: =+'Income Statement'!AP$24-AP24 -> 0 | AQ28: =+'Income Statement'!AQ$24-AQ24 -> 0 | AR28: =+'Income Statement'!AR$24-AR24 -> 0 | AS28: =+'Income Statement'!AS$24-AS24 -> 0 | AY28: =AVERAGE(AY27,AY29) -> 20.5 | AZ28: =AVERAGE(AZ27,AZ29) -> 26.5 | BA28: =AVERAGE(BA27,BA29) -> 27.5 | BB28: =IFERROR(AVERAGE(BB27,BB29),"") -> 21.6 | BC28: =IFERROR(AVERAGE(BC27,BC29),"") -> -6.7 | BD28: =IFERROR(AVERAGE(BD27,BD29),"") -> 2 | BE28: =IFERROR(AVERAGE(BE27,BE29),"")
A29: High | N29: -17.3 | O29: -10 | P29: -2 | Q29: 6 | R29: -11 | S29: -1.5 | T29: 4.5 | U29: 18.5 | V29: -9.5 | W29: 1 | X29: 10 | Y29: 24 | Z29: -6 | AA29: 1.5 | AB29: 2 | AC29: 27 | AD29: -13 | AE29: -5 | AF29: 8 | AG29: 22 | AH29: -11 | AI29: -2 | AJ29: 4 | AK29: 3 | AL29: -10 | AY29: 21.5 | AZ29: 27.5 | BA29: 28.5 | BB29: 22.6 | BC29: -5.2 | BD29: 4
A30: EBITDA | B30: =B24+'Cash Flow'!B7-'Income Statement'!B82 -> 15.04447 | C30: =C24+'Cash Flow'!C7-'Income Statement'!C82 -> -21.53547 | D30: =D24+'Cash Flow'!D7-'Income Statement'!D82 -> 2.614 | E30: =E24+'Cash Flow'!E7-'Income Statement'!E82 -> 14.779 | F30: =F24+'Cash Flow'!F7-'Income Statement'!F82 -> -5.905 | G30: =G24+'Cash Flow'!G7-'Income Statement'!G82 -> -0.195 | H30: =H24+'Cash Flow'!H7-'Income Statement'!H82 -> 2.85 | I30: =I24+'Cash Flow'!I7-'Income Statement'!I82 -> 17.207 | ... AC30: =AC24+'Cash Flow'!AC7-'Income Statement'!AC82 -> 29.703 | AD30: =AD24+'Cash Flow'!AT7-'Income Statement'!AD82 -> -10.953 | AE30: =AE24+'Cash Flow'!AU7-'Income Statement'!AE82 -> 5.015 | AF30: =AF24+'Cash Flow'!AV7-'Income Statement'!AF82 -> 12.848 | AG30: =AG24+'Cash Flow'!AW7-'Income Statement'!AG82 -> 21.544 | AH30: =AH24+'Cash Flow'!AX7-'Income Statement'!AH82 -> 1.459 | AI30: =AI24+'Cash Flow'!AY7-'Income Statement'!AI82 -> 8.454 | AJ30: =AJ24+'Cash Flow'!AZ7-'Income Statement'!AJ82 -> 8.27 | AK30: =AK24+'Cash Flow'!BA7-'Income Statement'!AK82 -> 14.195 | ... AN30: =AN24+'Cash Flow'!BD7-'Income Statement'!AN82 -> 18.721519 | AO30: =AO24+'Cash Flow'!BF7-'Income Statement'!AO82 -> 6.0375155 | AP30: =AP24+'Cash Flow'!BF7-'Income Statement'!AP82 -> -2.4786389 | AQ30: =AQ24+'Cash Flow'!BE7-'Income Statement'!AQ82 -> 29.85616 | AR30: =AR24+'Cash Flow'!BH7-'Income Statement'!AR82 -> 11.84108 | AS30: =AS24+'Cash Flow'!BJ7-'Income Statement'!AS82 -> 23.252113 | AU30: =SUM(B30:E30) -> 10.902 | AV30: =SUM(F30:I30) -> 13.957 | AW30: =SUM(J30:M30) -> -20.879 | AX30: =SUM(N30:Q30) -> 3.966 | AY30: =SUM(R30:U30) -> 29.335 | AZ30: =SUM(V30:Y30) -> 37.95 | BA30: =SUM(Z30:AC30) -> 37.558 | BB30: =SUM(AD30:AG30) -> 28.454 | BC30: =SUM(AH30:AK30) -> 32.378 | BD30: =SUM(AL30:AO30) -> 36.139579 | BE30: =SUM(AP30:AS30) -> 62.470715
A32: Financial income (expenses), net | B32: =B115+B155+B156 -> 0.469 | C32: =C115+C155+C156 -> 0.95 | D32: =D115+D155+D156 -> 0.622 | E32: =E115+E155+E156 -> 0.321 | F32: =F115+F155+F156 -> 0.253 | G32: =G115+G155+G156 -> 0.321 | H32: =H115+H155+H156 -> 0.436 | I32: =I115+I155+I156 -> 0.534 | ... AK32: =AK115+AK155+AK156 -> 9.572 | AL32: =AK32+0.5 -> 10.072 | AM32: =AL32 -> 10.072 | AN32: =AM32 -> 10.072 | AO32: =AN32 -> 10.072 | AP32: =AO32+0.5 -> 10.572 | AQ32: =AP32+0.5 -> 11.072 | AR32: =AQ32+0.5 -> 11.572 | AS32: =AR32+0.5 -> 12.072 | AU32: =SUM(B32:E32) -> 2.362 | AV32: =SUM(F32:I32) -> 1.544 | AW32: =SUM(J32:M32) -> 1.836 | AX32: =SUM(N32:Q32) -> -1.661 | AY32: =SUM(R32:U32) -> -3.577 | AZ32: =SUM(V32:Y32) -> 6.751 | BA32: =SUM(Z32:AC32) -> 30.903 | BB32: =SUM(AD32:AG32) -> 37.615 | BC32: =SUM(AH32:AK32) -> 40.317 | BD32: =SUM(AL32:AO32) -> 40.288 | BE32: =SUM(AP32:AS32) -> 45.288
A33: Pre-tax income | B33: =B24+B32 -> -6.657 | C33: =C24+C32 -> 0.301 | D33: =D24+D32 -> 2.55 | E33: =E24+E32 -> 13.742 | F33: =F24+F32 -> -6.449 | G33: =G24+G32 -> -0.703 | H33: =H24+H32 -> 2.432 | I33: =I24+I32 -> 16.065 | ... AS33: =AS24+AS32 -> 34.057113 | AU33: =AU24-AU32 -> 5.212 | AV33: =AV24-AV32 -> 8.257 | AW33: =AW24-AW32 -> -29.036 | AX33: =AX24-AX32 -> -2.787 | AY33: =AY24-AY32 -> 28.818 | AZ33: =AZ24-AZ32 -> 22.783 | BA33: =BA24-BA32 -> -2.16 | BB33: =SUM(AD33:AG33) -> 53.526 | BC33: =SUM(AH33:AK33) -> 36.671 | BD33: =SUM(AL33:AO33) -> 43.063119 | BE33: =SUM(AP33:AS33) -> 89.220244
A34: Provision for (benefit from) income taxes | B34: =B118-B157 -> 0.2 | C34: =C118-C157 -> 0.58 | D34: =D118-D157 -> 0.759 | E34: =E118-E157 -> 1.248 | F34: =F118-F157 -> 0.527 | G34: =G118-G157 -> 0.567 | H34: =H118-H157 -> 0.583 | I34: =I118-I157 -> -1.264 | ... AK34: =AK118-AK157 -> 2.983 | AL34: 7 | AM34: 7 | AN34: 9 | AO34: 10 | AP34: 9 | AQ34: 8 | AR34: 9 | AS34: 12 | AU34: =SUM(B34:E34) -> 2.787 | AV34: =SUM(F34:I34) -> 0.413 | AW34: =SUM(J34:M34) -> 2.388 | AX34: =SUM(N34:Q34) -> 1.546 | AY34: =SUM(R34:U34) -> 6.022 | AZ34: =SUM(V34:Y34) -> 13.703 | BA34: =SUM(Z34:AC34) -> 13.998 | BB34: =SUM(AD34:AG34) -> 12.758 | BC34: =SUM(AH34:AK34) -> 12.613 | BD34: =SUM(AL34:AO34) -> 33 | BE34: =SUM(AP34:AS34) -> 38
A35: Adjusted tax rate (non-GAAP) | B35: =+B34/B33 -> -0.030043563 | C35: =+C34/C33 -> 1.9269103 | D35: =+D34/D33 -> 0.29764706 | E35: =+E34/E33 -> 0.090816475 | F35: =+F34/F33 -> -0.081718096 | G35: =+G34/G33 -> -0.80654339 | H35: =+H34/H33 -> 0.23972039 | I35: =+I34/I33 -> -0.078680361 | ... S35: =+S34/S33 -> 6.3541667 | T35: =T34/T33 -> 0.21254355 | U35: =U34/U33 -> 0.14046745 | V35: =V34/V33 -> -0.16152616 | W35: =W34/W33 -> 1.0665829 | X35: =X34/X33 -> 0.45259392 | Y35: =Y34/Y33 -> 0.16132139 | Z35: =Z34/Z33 -> 1.026699 | AA35: =AA34/AA33 -> 0.87230553 | ... AK35: =AK34/AK33 -> 0.21118584 | AL35: NA | AM35: =AM34/AM33 -> 0.54320113 | AN35: =AN34/AN33 -> 0.70971991 | AO35: =AO34/AO33 -> 0.55034212 | AP35: NA | AQ35: =AQ34/AQ33 -> 0.38427009 | AR35: =AR34/AR33 -> 0.37205333 | AS35: =AS34/AS33 -> 0.35234931 | AU35: =SUM(B35:E35) -> 2.2853303 | AV35: =SUM(F35:I35) -> -0.72722145 | AW35: =+AW34/AW33 -> -0.082242733 | AX35: =+AX34/AX33 -> -0.55471834 | AY35: =+AY34/AY33 -> 0.20896662 | AZ35: =+AZ34/AZ33 -> 0.60145723 | BA35: =+BA34/BA33 -> -6.4805556 | BB35: =+BB34/BB33 -> 0.23835146 | BC35: =+BC34/BC33 -> 0.34395026 | BD35: =+BD34/BD33 -> 0.76631699 | BE35: =+BE34/BE33 -> 0.42591231
A36: Non-GAAP Net income | B36: =B33-B34 -> -6.857 | C36: =C33-C34 -> -0.279 | D36: =D33-D34 -> 1.791 | E36: =E33-E34 -> 12.494 | F36: =F33-F34 -> -6.976 | G36: =G33-G34 -> -1.27 | H36: =H33-H34 -> 1.849 | I36: =I33-I34 -> 17.329 | ... AS36: =AS33-AS34 -> 22.057113 | AU36: =SUM(B36:E36) -> 7.149 | AV36: =SUM(F36:I36) -> 10.932 | AW36: =SUM(J36:M36) -> -27.752 | AX36: =SUM(N36:Q36) -> -7.655 | AY36: =SUM(R36:U36) -> 15.642 | AZ36: =SUM(V36:Y36) -> 22.582 | BA36: =SUM(Z36:AC36) -> 45.648 | BB36: =SUM(AD36:AG36) -> 40.768 | BC36: =SUM(AH36:AK36) -> 24.058 | BD36: =SUM(AL36:AO36) -> 10.063119 | BE36: =SUM(AP36:AS36) -> 51.220244
A37: Consensus net income | B37: ='[2]VA Consensus'!C38 -> -6.073 | C37: ='[2]VA Consensus'!D38 -> -2.1934727 | D37: ='[2]VA Consensus'!E38 -> -0.18276962 | E37: ='[2]VA Consensus'!F38 -> 9.0058586 | F37: ='[2]VA Consensus'!G38 -> -8.7710332 | G37: ='[2]VA Consensus'!H38 -> -1.4526579 | H37: ='[2]VA Consensus'!I38 -> -0.0065381036 | I37: ='[2]VA Consensus'!J38 -> 10.895775 | ... AS37: ='[2]VA Consensus'!AT38 -> 19.194259 | AU37: ='[2]VA Consensus'!AV38 -> 5.0968586 | AV37: ='[2]VA Consensus'!AW38 -> 3.7547752 | AW37: ='[2]VA Consensus'!AX38 -> -28.186719 | AX37: ='[2]VA Consensus'!AY38 -> -15.724899 | AY37: ='[2]VA Consensus'!AZ38 -> 12.498401 | AZ37: ='[2]VA Consensus'!BA38 -> 17.97807 | BA37: ='[2]VA Consensus'!BB38 -> 40.2844 | BB37: ='[2]VA Consensus'!BC38 -> 35.368007 | ... BE37: ='[2]VA Consensus'!BF38 -> 53.635204
A39: Non-GAAP EPS | B39: =IF(B36<0,B36/B45,B36/B46) -> -0.25442276 | C39: =IF(C36<0,C36/C45,C36/C46) -> -0.010211612 | D39: =IF(D36<0,D36/D45,D36/D46) -> 0.058126419 | E39: =IF(E36<0,E36/E45,E36/E46) -> 0.40145485 | F39: =IF(F36<0,F36/F45,F36/F46) -> -0.24595875 | G39: =IF(G36<0,G36/G45,G36/G46) -> -0.043913769 | H39: =IF(H36<0,H36/H45,H36/H46) -> 0.056848473 | I39: =IF(I36<0,I36/I45,I36/I46) -> 0.53309466 | ... AS39: =IF(AS36<0,AS36/AS45,AS36/AS46) -> 0.14994853 | AU39: =IF(AU36<0,AU36/AU45,AU36/AU46) -> 0.23170088 | AV39: =IF(AV36<0,AV36/AV45,AV36/AV46) -> 0.33863562 | AW39: =IF(AW36<0,AW36/AW45,AW36/AW46) -> -0.91719681 | AX39: =IF(AX36<0,AX36/AX45,AX36/AX46) -> -0.081145348 | AY39: =IF(AY36<0,AY36/AY45,AY36/AY46) -> 0.13378442 | AZ39: =IF(AZ36<0,AZ36/AZ45,AZ36/AZ46) -> 0.17888503 | BA39: =IF(BA36<0,BA36/BA45,BA36/BA46) -> 0.36063612 | BB39: =IF(BB36<0,BB36/BB45,BB36/BB46) -> 0.3108822 | ... BE39: =IF(BE36<0,BE36/BE45,BE36/BE46) -> 0.34981037
A40: Consensus non-GAAP EPS | B40: ='[2]VA Consensus'!C40 -> - | C40: ='[2]VA Consensus'!D40 -> - | D40: ='[2]VA Consensus'!E40 -> - | E40: ='[2]VA Consensus'!F40 -> - | F40: ='[2]VA Consensus'!G40 -> - | G40: ='[2]VA Consensus'!H40 -> - | H40: ='[2]VA Consensus'!I40 -> - | I40: ='[2]VA Consensus'!J40 -> - | ... AS40: ='[2]VA Consensus'!AT40 -> 0.1372202 | AU40: ='[2]VA Consensus'!AV40 -> - | AV40: ='[2]VA Consensus'!AW40 -> - | AW40: ='[2]VA Consensus'!AX40 -> - | AX40: ='[2]VA Consensus'!AY40 -> - | AY40: ='[2]VA Consensus'!AZ40 -> 0.10804504 | AZ40: ='[2]VA Consensus'!BA40 -> 0.14261232 | BA40: ='[2]VA Consensus'!BB40 -> 0.32030295 | BB40: ='[2]VA Consensus'!BC40 -> 0.26695732 | ... BE40: ='[2]VA Consensus'!BF40 -> 0.38567577
A41: Management Guidance - Non-GAAP EPS
A42: Low | N42: -0.19 | O42: -0.12 | P42: -0.05 | Q42: 0.03 | R42: -0.14 | S42: -0.04 | T42: 0.01 | U42: 0.12 | V42: -0.11 | W42: -0.02 | X42: 0.05 | Y42: 0.17 | Z42: -0.05 | AA42: 0.01 | AB42: 0.02 | AC42: 0.22 | AD42: -0.1 | AE42: -0.03 | AF42: 0.07 | AG42: 0.13 | AH42: -0.06 | AI42: 0 | AJ42: 0.04 | AK42: 0.02 | AL42: -0.06 | AY42: 0.1 | AZ42: 0.14 | BA42: 0.31 | BB42: 0.26 | BC42: 0.12 | BD42: 0.06
A43: Mid | N43: =AVERAGE(N42,N44) -> -0.185 | O43: =AVERAGE(O42,O44) -> -0.115 | P43: =AVERAGE(P42,P44) -> -0.045 | Q43: =AVERAGE(Q42,Q44) -> 0.035 | R43: =AVERAGE(R42,R44) -> -0.135 | S43: =AVERAGE(S42,S44) -> -0.035 | T43: =AVERAGE(T42,T44) -> 0.015 | U43: =AVERAGE(U42,U44) -> 0.125 | ... AB43: =AVERAGE(AB42,AB44) -> 0.025 | AC43: =IFERROR(AVERAGE(AC42,AC44),"") -> 0.23 | AD43: =IFERROR(AVERAGE(AD42,AD44),"") -> -0.095 | AE43: =IFERROR(AVERAGE(AE42,AE44),"") -> -0.025 | AF43: =IFERROR(AVERAGE(AF42,AF44),"") -> 0.075 | AG43: =IFERROR(AVERAGE(AG42,AG44),"") -> 0.135 | AH43: =IFERROR(AVERAGE(AH42,AH44),"") -> -0.05 | AI43: =IFERROR(AVERAGE(AI42,AI44),"") -> 0.005 | AJ43: =IFERROR(AVERAGE(AJ42,AJ44),"") -> 0.05 | ... AS43: =IFERROR(AVERAGE(AS42,AS44),"") | AY43: =AVERAGE(AY42,AY44) -> 0.105 | AZ43: =AVERAGE(AZ42,AZ44) -> 0.145 | BA43: =AVERAGE(BA42,BA44) -> 0.32 | BB43: =IFERROR(AVERAGE(BB42,BB44),"") -> 0.265 | BC43: =IFERROR(AVERAGE(BC42,BC44),"") -> 0.125 | BD43: =IFERROR(AVERAGE(BD42,BD44),"") -> 0.08 | BE43: =IFERROR(AVERAGE(BE42,BE44),"")
A44: High | N44: -0.18 | O44: -0.11 | P44: -0.04 | Q44: 0.04 | R44: -0.13 | S44: -0.03 | T44: 0.02 | U44: 0.13 | V44: -0.1 | W44: -0.01 | X44: 0.06 | Y44: 0.18 | Z44: -0.04 | AA44: 0.02 | AB44: 0.03 | AC44: 0.24 | AD44: -0.09 | AE44: -0.02 | AF44: 0.08 | AG44: 0.14 | AH44: -0.04 | AI44: 0.01 | AJ44: 0.06 | AK44: 0.04 | AL44: -0.05 | AY44: 0.11 | AZ44: 0.15 | BA44: 0.33 | BB44: 0.27 | BC44: 0.13 | BD44: 0.1
...

Sheet Revenue Build
A1: =+'Income Statement'!A1 -> Varonis Systems, Inc. (VRNS)
A2: Revenue Build | B2: 2017/1F | C2: 2017/2F | D2: 2017/3F | E2: 2017/4F | F2: 2018/1F | G2: 2018/2F | H2: 2018/3F | I2: 2018/4F | J2: 2018/1F | K2: 2018/2F | L2: 2018/3F | M2: 2018/4F | N2: ='Income Statement'!N2 -> 2019/1F | O2: ='Income Statement'!O2 -> 2019/2F | P2: ='Income Statement'!P2 -> 2019/3F | Q2: ='Income Statement'!Q2 -> 2019/4F | R2: ='Income Statement'!R2 -> 2021/1F | S2: ='Income Statement'!S2 -> 2021/2F | T2: ='Income Statement'!T2 -> 2021/3F | U2: ='Income Statement'!U2 -> 2021/4F | ... AS2: ='Income Statement'!AS2 -> 2027/4F | AU2: 2017 | AV2: 2018 | AW2: 2019 | AX2: ='Income Statement'!AX2 -> 2020 | AY2: ='Income Statement'!AY2 -> 2021 | AZ2: ='Income Statement'!AZ2 -> 2022 | BA2: ='Income Statement'!BA2 -> 2023 | BB2: ='Income Statement'!BB2 -> 2024 | BC2: ='Income Statement'!BC2 -> 2025 | BD2: ='Income Statement'!BD2 -> 2026 | BE2: ='Income Statement'!BE2 -> 2027
B3: ='Income Statement'!B$3 -> 2017 | F3: ='Income Statement'!F$3 -> 2018 | J3: ='Income Statement'!J$3 -> 2019 | N3: ='Income Statement'!N$3 -> 2020 | R3: ='Income Statement'!R$3 -> 2021 | V3: ='Income Statement'!V$3 -> 2022 | Z3: ='Income Statement'!Z$3 -> 2023 | AD3: ='Income Statement'!AD$3 -> 2024 | AH3: ='Income Statement'!AH$3 -> 2025 | AL3: ='Income Statement'!AL$3 -> 2026 | AP3: ='Income Statement'!AP$3 -> 2027
A4: ='Income Statement'!A4 -> ($ in millions, unless otherwise stated) | B4: ='Income Statement'!B$4 -> 42825 | C4: ='Income Statement'!C$4 -> 42916 | D4: ='Income Statement'!D$4 -> 43008 | E4: ='Income Statement'!E$4 -> 43100 | F4: ='Income Statement'!F$4 -> 43190 | G4: ='Income Statement'!G$4 -> 43281 | H4: ='Income Statement'!H$4 -> 43373 | I4: ='Income Statement'!I$4 -> 43465 | ... AS4: ='Income Statement'!AS$4 -> Dec-27E | AU4: ='Income Statement'!AU$4 -> 2017 | AV4: ='Income Statement'!AV$4 -> 2018 | AW4: ='Income Statement'!AW$4 -> 2019 | AX4: ='Income Statement'!AX$4 -> 2020 | AY4: ='Income Statement'!AY$4 -> 2021 | AZ4: ='Income Statement'!AZ$4 -> 2022 | BA4: ='Income Statement'!BA$4 -> 2023 | BB4: ='Income Statement'!BB$4 -> 2024 | ... BE4: ='Income Statement'!BE$4 -> 2027E
A5: Total Revenue | B5: =B13+B28+B33 -> 39.593 | C5: =C13+C28+C33 -> 49.431 | D5: =D13+D28+D33 -> 53.365 | E5: =E13+E28+E33 -> 73.001 | F5: =F13+F28+F33 -> 53.528 | G5: =G13+G28+G33 -> 62.19 | H5: =H13+H28+H33 -> 67.052 | I5: =I13+I28+I33 -> 87.518 | ... U5: =U13+U28+U33 -> 126.578 | V5: =V13+V33 -> 96.261 | W5: =W13+W33 -> 111.448 | X5: =X13+X33 -> 123.308 | Y5: =Y13+Y33 -> 142.617 | Z5: =Z13+Z33 -> 107.335 | AA5: =AA13+AA33 -> 115.418 | AB5: =AB13+AB33 -> 122.308 | AC5: =AC13+AC33 -> 154.099 | ... AS5: =AS13+AS33 -> 233.88418 | AU5: =SUM(B5:E5) -> 215.39 | AV5: =SUM(F5:I5) -> 270.288 | AW5: =SUM(J5:M5) -> 254.19 | AX5: =SUM(N5:Q5) -> 292.689 | AY5: =SUM(R5:U5) -> 390.134 | AZ5: =SUM(V5:Y5) -> 473.634 | BA5: =SUM(Z5:AC5) -> 499.16 | BB5: =SUM(AD5:AG5) -> 550.95 | BC5: =SUM(AH5:AK5) -> 623.532 | BD5: =SUM(AL5:AO5) -> 725.13568 | BE5: =SUM(AP5:AS5) -> 884.61962
A6: Consensus revenue | B6: ='[2]VA Consensus'!C28 -> 40.38 | C6: ='[2]VA Consensus'!D28 -> 47.532444 | D6: ='[2]VA Consensus'!E28 -> 50.554272 | E6: ='[2]VA Consensus'!F28 -> 66.51052 | F6: ='[2]VA Consensus'!G28 -> 49.838929 | G6: ='[2]VA Consensus'!H28 -> 62.105238 | H6: ='[2]VA Consensus'!I28 -> 64.53161 | I6: ='[2]VA Consensus'!J28 -> 87.408971 | ... AS6: ='[2]VA Consensus'!AT28 -> 230.41508 | AU6: ='[2]VA Consensus'!AV28 -> 210.66552 | AV6: ='[2]VA Consensus'!AW28 -> 270.18211 | AW6: ='[2]VA Consensus'!AX28 -> 253.4685 | AX6: ='[2]VA Consensus'!AY28 -> 281.78387 | AY6: ='[2]VA Consensus'!AZ28 -> 385.55766 | AZ6: ='[2]VA Consensus'!BA28 -> 471.20837 | BA6: ='[2]VA Consensus'!BB28 -> 496.67471 | BB6: ='[2]VA Consensus'!BC28 -> 557.97652 | ... BE6: ='[2]VA Consensus'!BF28 -> 857.74118
A7: Y/Y % | B7: =IF(ISERROR(B5/#REF!-1),"NA",B5/#REF!-1) -> NA | C7: =IF(ISERROR(C5/#REF!-1),"NA",C5/#REF!-1) -> NA | D7: =IF(ISERROR(D5/#REF!-1),"NA",D5/#REF!-1) -> NA | E7: =IF(ISERROR(E5/#REF!-1),"NA",E5/#REF!-1) -> NA | F7: =IF(ISERROR(F5/B5-1),"NA",F5/B5-1) -> 0.35195615 | G7: =IF(ISERROR(G5/C5-1),"NA",G5/C5-1) -> 0.25811738 | H7: =IF(ISERROR(H5/D5-1),"NA",H5/D5-1) -> 0.25647897 | I7: =IF(ISERROR(I5/E5-1),"NA",I5/E5-1) -> 0.19886029 | J7: =IF(ISERROR(J5/F5-1),"NA",J5/F5-1) -> 0.05290689 | K7: =IF(ISERROR(K5/G5-1),"NA",K5/G5-1) -> -0.041308892 | L7: =IF(ISERROR(L5/H5-1),"NA",L5/H5-1) -> -0.020924059 | M7: =IF(ISERROR(M5/I5-1),"NA",M5/I5-1) -> -0.17091341 | ... AS7: =IF(ISERROR(AS5/AO5-1),"NA",AS5/AO5-1) -> 0.18407518 | AU7: =IF(ISERROR(AU5/#REF!-1),"NA",AU5/#REF!-1) -> NA | AV7: =IF(ISERROR(AV5/AU5-1),"NA",AV5/AU5-1) -> 0.2548772 | AW7: =IF(ISERROR(AW5/AV5-1),"NA",AW5/AV5-1) -> -0.059558693 | AX7: =IF(ISERROR(AX5/AW5-1),"NA",AX5/AW5-1) -> 0.15145757 | AY7: =IF(ISERROR(AY5/AX5-1),"NA",AY5/AX5-1) -> 0.33293018 | AZ7: =IF(ISERROR(AZ5/AY5-1),"NA",AZ5/AY5-1) -> 0.21402903 | BA7: =IF(ISERROR(BA5/AZ5-1),"NA",BA5/AZ5-1) -> 0.053893935 | BB7: =IF(ISERROR(BB5/BA5-1),"NA",BB5/BA5-1) -> 0.10375431 | BC7: =IF(ISERROR(BC5/BB5-1),"NA",BC5/BB5-1) -> 0.13173972 | ... BE7: =IF(ISERROR(BE5/BD5-1),"NA",BE5/BD5-1) -> 0.21993668
A8: Management Guidance - Total Revenue
A9: Low | N9: 53.9 | O9: 56 | P9: 68 | Q9: 82 | R9: 68 | S9: 82.5 | T9: 96 | U9: 120 | V9: 94.5 | W9: 110.5 | X9: 123 | Y9: 139 | Z9: 106 | AA9: 118 | AB9: 123.5 | AC9: 150 | AD9: 111 | AE9: 123 | AF9: 140 | AG9: 162 | AH9: 130 | AI9: 145 | AJ9: 163 | AK9: 165 | AL9: 164 | AY9: 383.5 | AZ9: 519 | BA9: 495 | BB9: 554.4 | BC9: 615.2 | BD9: 722
A10: Mid | N10: =AVERAGE(N9,N11) -> 54.1 | O10: =AVERAGE(O9,O11) -> 57 | P10: =AVERAGE(P9,P11) -> 69.5 | Q10: =AVERAGE(Q9,Q11) -> 83.5 | R10: =AVERAGE(R9,R11) -> 68.75 | S10: =AVERAGE(S9,S11) -> 83.25 | T10: =AVERAGE(T9,T11) -> 97 | U10: =AVERAGE(U9,U11) -> 121.5 | ... AB10: =AVERAGE(AB9,AB11) -> 125.25 | AC10: =IFERROR(AVERAGE(AC9,AC11),"") -> 152 | AD10: =IFERROR(AVERAGE(AD9,AD11),"") -> 113 | AE10: =IFERROR(AVERAGE(AE9,AE11),"") -> 124.5 | AF10: =IFERROR(AVERAGE(AF9,AF11),"") -> 141.5 | AG10: =IFERROR(AVERAGE(AG9,AG11),"") -> 164.5 | AH10: =IFERROR(AVERAGE(AH9,AH11),"") -> 132.5 | AI10: =IFERROR(AVERAGE(AI9,AI11),"") -> 147.5 | AJ10: =IFERROR(AVERAGE(AJ9,AJ11),"") -> 165.5 | ... AS10: =IFERROR(AVERAGE(AS9,AS11),"") | AY10: =AVERAGE(AY9,AY11) -> 385 | AZ10: =AVERAGE(AZ9,AZ11) -> 496 | BA10: =AVERAGE(BA9,BA11) -> 497 | BB10: =IFERROR(AVERAGE(BB9,BB11),"") -> 556.9 | BC10: =IFERROR(AVERAGE(BC9,BC11),"") -> 618.2 | BD10: =IFERROR(AVERAGE(BD9,BD11),"") -> 726 | BE10: =IFERROR(AVERAGE(BE9,BE11),"")
A11: High | N11: 54.3 | O11: 58 | P11: 71 | Q11: 85 | R11: 69.5 | S11: 84 | T11: 98 | U11: 123 | V11: 96.5 | W11: 112 | X11: 125.5 | Y11: 142 | Z11: 108 | AA11: 120 | AB11: 127 | AC11: 154 | AD11: 115 | AE11: 126 | AF11: 143 | AG11: 167 | AH11: 135 | AI11: 150 | AJ11: 168 | AK11: 171 | AL11: 166 | AY11: 386.5 | AZ11: 473 | BA11: 499 | BB11: 559.4 | BC11: 621.2 | BD11: 730
A12: Revenue by Type
A13: Subscription | B13: 0 | C13: 0 | D13: 0 | E13: 0 | F13: 1.071 | G13: 1.291 | H13: 2.539 | I13: 3.849 | J13: 7.005 | K13: 14.837 | L13: 23.327 | M13: 31.561 | N13: 20.365 | O13: 34.086 | P13: 44.084 | Q13: 62.653 | R13: 44.828 | S13: 58.063 | T13: 70.026 | U13: 96.025 | V13: 68.985 | W13: 84.38 | X13: 96.052 | Y13: 116.727 | Z13: 82.974 | AA13: 91.09 | AB13: 97.679 | AC13: 129.164 | AD13: =AD18+AD23 -> 89.965 | AE13: =AE18+AE23 -> 107.514 | AF13: =AF18+AF23 -> 126.556 | AG13: =AG18+AG23 -> 138.987 | AH13: =AH18+AH23 -> 120.048 | AI13: =AI18+AI23 -> 138.269 | AJ13: =+AJ18+AJ23 -> 150.636 | AK13: =+AK18+AK23 -> 163.277 | AL13: =+AL18+AL23 -> 159.38907 | AM13: =+AM18+AM23 -> 171.24836 | AN13: =+AN18+AN23 -> 183.01573 | AO13: =+AO18+AO23 -> 195.52477 | AP13: =+AP18+AP23 -> 206.81946 | AQ13: =+AQ18+AQ23 -> 214.59312 | ... AS13: =+AS18+AS23 -> 231.88418 | AU13: =SUM(B13:E13) -> 0 | AV13: =SUM(F13:I13) -> 8.75 | AW13: =SUM(J13:M13) -> 76.73 | AX13: =SUM(N13:Q13) -> 161.188 | AY13: =SUM(R13:U13) -> 268.942 | AZ13: =SUM(V13:Y13) -> 366.144 | BA13: =SUM(Z13:AC13) -> 400.907 | BB13: =SUM(AD13:AG13) -> 463.022 | BC13: =SUM(AH13:AK13) -> 572.23 | BD13: =SUM(AL13:AO13) -> 709.17794 | BE13: =SUM(AP13:AS13) -> 876.61962
A14: Consensus subscription revenue | B14: ='[2]VA Consensus'!C26 -> - | C14: ='[2]VA Consensus'!D26 -> - | D14: ='[2]VA Consensus'!E26 -> - | E14: ='[2]VA Consensus'!F26 -> - | F14: ='[2]VA Consensus'!G26 -> - | G14: ='[2]VA Consensus'!H26 -> - | H14: ='[2]VA Consensus'!I26 -> - | I14: ='[2]VA Consensus'!J26 -> - | ... AS14: ='[2]VA Consensus'!AT26 -> 228.46285 | AW14: ='[2]VA Consensus'!AX26 -> 73.711943 | AX14: ='[2]VA Consensus'!AY26 -> 150.05446 | AY14: ='[2]VA Consensus'!AZ26 -> 264.88894 | AZ14: ='[2]VA Consensus'!BA26 -> 363.06621 | BA14: ='[2]VA Consensus'!BB26 -> 400.16666 | BB14: ='[2]VA Consensus'!BC26 -> 468.82003 | BC14: ='[2]VA Consensus'!BD26 -> 567.84457 | BD14: ='[2]VA Consensus'!BE26 -> 705.6037 | BE14: ='[2]VA Consensus'!BF26 -> 848.64198
A15: Y/Y % | J15: =J13/F13-1 -> 5.5406162 | K15: =K13/G13-1 -> 10.492641 | L15: =L13/H13-1 -> 8.1874754 | M15: =M13/I13-1 -> 7.1997922 | N15: =N13/J13-1 -> 1.9072091 | O15: =O13/K13-1 -> 1.2973647 | P15: =P13/L13-1 -> 0.88982724 | Q15: =Q13/M13-1 -> 0.98513989 | ... AS15: =AS13/AO13-1 -> 0.18595807 | AU15: =IF(ISERROR(AU13/#REF!-1),"NA",AU13/#REF!-1) -> NA | AV15: =IF(ISERROR(AV13/AU13-1),"NA",AV13/AU13-1) -> NA | AW15: =IF(ISERROR(AW13/AV13-1),"NA",AW13/AV13-1) -> 7.7691429 | AX15: =IF(ISERROR(AX13/AW13-1),"NA",AX13/AW13-1) -> 1.1007168 | AY15: =IF(ISERROR(AY13/AX13-1),"NA",AY13/AX13-1) -> 0.6684989 | AZ15: =IF(ISERROR(AZ13/AY13-1),"NA",AZ13/AY13-1) -> 0.36142365 | BA15: =IF(ISERROR(BA13/AZ13-1),"NA",BA13/AZ13-1) -> 0.094943519 | BB15: =IF(ISERROR(BB13/BA13-1),"NA",BB13/BA13-1) -> 0.15493618 | BC15: =IF(ISERROR(BC13/BB13-1),"NA",BC13/BB13-1) -> 0.2358592 | ... BE15: =IF(ISERROR(BE13/BD13-1),"NA",BE13/BD13-1) -> 0.23610673
A16: % of total revenue | F16: =F13/F5 -> 0.02000822 | G16: =G13/G5 -> 0.020758964 | H16: =H13/H5 -> 0.037866134 | I16: =I13/I5 -> 0.043979524 | J16: =J13/J5 -> 0.12429028 | K16: =K13/K5 -> 0.24885527 | L16: =L13/L5 -> 0.3553291 | M16: =M13/M5 -> 0.43496417 | ... W16: =W13/W5 -> 0.7571244 | X16: 0 | Y16: =Y13/Y5 -> 0.81846484 | Z16: =Z13/Z5 -> 0.77303769 | AA16: =AA13/AA5 -> 0.78921832 | AB16: =AB13/AB5 -> 0.79863132 | AC16: =AC13/AC5 -> 0.83818844 | AD16: =AD13/AD5 -> 0.7890144 | AE16: =AE13/AE5 -> 0.82483544 | AF16: =AF13/AF5 -> 0.8547154 | ... AS16: =AS13/AS5 -> 0.99144876 | AX16: =AX13/AX$5 -> 0.55071424 | AY16: =AY13/AY$5 -> 0.68935802 | AZ16: =AZ13/AZ$5 -> 0.77305261 | BA16: =BA13/BA$5 -> 0.80316331 | BB16: =BB13/BB$5 -> 0.84040657 | BC16: =BC13/BC$5 -> 0.91772355 | BD16: =BD13/BD$5 -> 0.97799343 | BE16: =BE13/BE$5 -> 0.99095657
A18: Term license subscriptions | Z18: 80.906 | AA18: 85.437 | AB18: 83.963 | AC18: 106.2 | AD18: 55.98 | AE18: 62.729 | AF18: 68.751 | AG18: 66.781 | AH18: 31.488 | AI18: 32.374 | AJ18: 24.812 | AK18: 20.961 | BA18: =SUM(Z18:AC18) -> 356.506 | BB18: =SUM(AD18:AG18) -> 254.241 | BC18: =SUM(AH18:AK18) -> 109.635 | BD18: =SUM(AL18:AO18) -> 0
A19: Consensus term license revenue | AE19: ='[2]VA Consensus'!AF25 -> 58.733072 | AF19: ='[2]VA Consensus'!AG25 -> 64.108555 | AG19: ='[2]VA Consensus'!AH25 -> 74.418906 | AH19: ='[2]VA Consensus'!AI25 -> 36.888186 | AI19: ='[2]VA Consensus'!AJ25 -> 35.375066 | AJ19: ='[2]VA Consensus'!AK25 -> 33.219995 | AK19: ='[2]VA Consensus'!AL25 -> 19.857593 | AU19: ='[2]VA Consensus'!AV25 -> 118.22944 | BB19: ='[2]VA Consensus'!BC25 -> 262.44323 | BC19: ='[2]VA Consensus'!BD25 -> 108.53159 | BD19: ='[2]VA Consensus'!BE25 -> 21.360391
A20: Y/Y % | Z20: =IFERROR(Z18/V18-1,"NM") -> NM | AA20: =IFERROR(AA18/W18-1,"NM") -> NM | AB20: =IFERROR(AB18/X18-1,"NM") -> NM | AC20: =IFERROR(AC18/Y18-1,"NM") -> NM | AD20: =IFERROR(AD18/Z18-1,"NM") -> -0.30808593 | AE20: =IFERROR(AE18/AA18-1,"NM") -> -0.26578649 | AF20: =IFERROR(AF18/AB18-1,"NM") -> -0.18117504 | AG20: =IFERROR(AG18/AC18-1,"NM") -> -0.37117702 | ... AK20: =IFERROR(AK18/AG18-1,"NM") -> -0.6861233 | BB20: =BB18/BA18-1 -> -0.28685352 | BC20: =BC18/BB18-1 -> -0.5687753 | BD20: =BD18/BC18-1 -> -1
A21: % of total revenue | Z21: =Z18/Z$5 -> 0.7537709 | AA21: =AA18/AA$5 -> 0.74023982 | AB21: =AB18/AB$5 -> 0.68648821 | AC21: =AC18/AC$5 -> 0.68916735 | AD21: =AD18/AD$5 -> 0.49095789 | AE21: =AE18/AE$5 -> 0.4812499 | AF21: =AF18/AF$5 -> 0.46432045 | AG21: =AG18/AG$5 -> 0.42129402 | ... AK21: =AK18/AK$5 -> 0.12090397 | BA21: =BA18/BA5 -> 0.71421188 | BB21: =BB18/BB5 -> 0.4614593 | BC21: =BC18/BC5 -> 0.17582899 | BD21: =BD18/BD5 -> 0
A23: SaaS | Z23: 2.068 | AA23: 5.653 | AB23: 13.716 | AC23: 23 | AD23: 33.985 | AE23: 44.785 | AF23: 57.805 | AG23: 72.206 | AH23: 88.56 | AI23: 105.895 | AJ23: 125.824 | AK23: 142.316 | AL23: =AL152 -> 159.38907 | AM23: =AM152 -> 171.24836 | AN23: =AN152 -> 183.01573 | AO23: =AO152 -> 195.52477 | AP23: =AP152 -> 206.81946 | AQ23: =AQ152 -> 214.59312 | AR23: =AR152 -> 223.32286 | AS23: =AS152 -> 231.88418 | BA23: =SUM(Z23:AC23) -> 44.437 | BB23: =SUM(AD23:AG23) -> 208.781 | BC23: =SUM(AH23:AK23) -> 462.595 | BD23: =SUM(AL23:AO23) -> 709.17794 | BE23: =SUM(AP23:AS23) -> 876.61962
A24: Consensus SaaS revenue | AE24: ='[2]VA Consensus'!AF24 -> 42.775765 | AF24: ='[2]VA Consensus'!AG24 -> 55.331742 | AG24: ='[2]VA Consensus'!AH24 -> 69.114064 | AH24: ='[2]VA Consensus'!AI24 -> 78.121681 | AI24: ='[2]VA Consensus'!AJ24 -> 96.302924 | AJ24: ='[2]VA Consensus'!AK24 -> 119.18906 | AK24: ='[2]VA Consensus'!AL24 -> 139.88286 | AL24: ='[2]VA Consensus'!AM24 -> 150.40359 | ... AS24: ='[2]VA Consensus'!AT24 -> 226.36455 | AU24: ='[2]VA Consensus'!AV24 -> 118.32642 | BB24: ='[2]VA Consensus'!BC24 -> 205.01188 | BC24: ='[2]VA Consensus'!BD24 -> 460.16186 | BD24: ='[2]VA Consensus'!BE24 -> 684.49882 | BE24: ='[2]VA Consensus'!BF24 -> 843.38756
A25: Y/Y % | Z25: =IFERROR(Z23/V23-1,"NM") -> NM | AA25: =IFERROR(AA23/W23-1,"NM") -> NM | AB25: =IFERROR(AB23/X23-1,"NM") -> NM | AC25: =IFERROR(AC23/Y23-1,"NM") -> NM | AD25: =IFERROR(AD23/Z23-1,"NM") -> 15.433752 | AE25: =IFERROR(AE23/AA23-1,"NM") -> 6.9223421 | AF25: =IFERROR(AF23/AB23-1,"NM") -> 3.2144211 | AG25: =IFERROR(AG23/AC23-1,"NM") -> 2.1393913 | ... AS25: =IFERROR(AS23/AO23-1,"NM") -> 0.18595807 | BB25: =BB23/BA23-1 -> 3.6983595 | BC25: =BC23/BB23-1 -> 1.2156949 | BD25: =BD23/BC23-1 -> 0.53304281 | BE25: =BE23/BD23-1 -> 0.23610673
A26: % of total revenue | Z26: =Z23/Z$5 -> 0.019266782 | AA26: =AA23/AA$5 -> 0.048978496 | AB26: =AB23/AB$5 -> 0.11214311 | AC26: =AC23/AC$5 -> 0.1492547 | AD26: =AD23/AD$5 -> 0.29805652 | AE26: =AE23/AE$5 -> 0.34358553 | AF26: =AF23/AF$5 -> 0.39039495 | AG26: =AG23/AG$5 -> 0.45551812 | AH26: =AH23/AH$5 -> 0.6491574 | AI26: =AI23/AI5 -> 0.69593134 | AJ26: =AJ23/AJ$5 -> 0.77872469 | AK26: =AK23/AK5 -> 0.82088493 | AL26: =AL23/AL5 -> 0.96401456 | AM26: =AM23/AM5 -> 0.97349601 | AN26: =AN23/AN5 -> 0.98204767 | AO26: =AO23/AO5 -> 0.98987469 | AP26: =AP23/AP5 -> 0.99042235 | AQ26: =AQ23/AQ5 -> 0.9907661 | AR26: =AR23/AR5 -> 0.99112385 | AS26: =AS23/AS5 -> 0.99144876 | BA26: =BA23/BA5 -> 0.08902356 | BB26: =BB23/BB5 -> 0.37894727 | BC26: =BC23/BC5 -> 0.74189456 | BD26: =BD23/BD5 -> 0.97799343 | BE26: =BE23/BE5 -> 0.99095657
A28: Perpetual License | B28: 18.092 | C28: 27.31 | D28: 29 | E28: 45.939 | F28: 24.086 | G28: 32.27 | H28: 33.432 | I28: 49.79 | J28: 15.521 | K28: 11.514 | L28: 8.269 | M28: 6.789 | N28: 0.388 | O28: 0.24 | P28: 0.373 | Q28: 0.472 | R28: 0.286 | S28: 0.34 | T28: 0.324 | U28: 0.94 | AU28: =SUM(B28:E28) -> 120.341 | AV28: =SUM(F28:I28) -> 139.578 | AW28: =SUM(J28:M28) -> 42.093 | AX28: =SUM(N28:Q28) -> 1.473 | AY28: =SUM(R28:U28) -> 1.89
A29: Consensus perpetual license revenue | N29: 1.6 | O29: 0.6 | P29: 0.3 | Q29: 0.3 | R29: 0.3 | S29: 0.2 | T29: 0.3 | U29: 0.3 | AX29: 1.3 | AY29: 1.3
A30: Y/Y % | F30: =F28/B28-1 -> 0.33130665 | G30: =G28/C28-1 -> 0.18161845 | H30: =H28/D28-1 -> 0.15282759 | I30: =I28/E28-1 -> 0.083828555 | J30: =J28/F28-1 -> -0.35560076 | K30: =K28/G28-1 -> -0.64319802 | L30: =L28/H28-1 -> -0.75266212 | M30: =M28/I28-1 -> -0.86364732 | ... U30: =U28/Q28-1 -> 0.99152542 | AU30: =IF(ISERROR(AU28/#REF!-1),"NA",AU28/#REF!-1) -> NA | AV30: =IF(ISERROR(AV28/AU28-1),"NA",AV28/AU28-1) -> 0.15985408 | AW30: =IF(ISERROR(AW28/AV28-1),"NA",AW28/AV28-1) -> -0.69842669 | AX30: =IF(ISERROR(AX28/AW28-1),"NA",AX28/AW28-1) -> -0.96500606 | AY30: =IF(ISERROR(AY28/AX28-1),"NA",AY28/AX28-1) -> 0.28309572
A31: % of total revenue | B31: =B28/B5 -> 0.45694946 | C31: =C28/C5 -> 0.55248731 | D31: =D28/D5 -> 0.54342734 | E31: =E28/E5 -> 0.62929275 | F31: =F28/F5 -> 0.44997011 | G31: =G28/G5 -> 0.51889371 | H31: =H28/H5 -> 0.4985981 | I31: =I28/I5 -> 0.56891154 | ... U31: =U28/U5 -> 0.007426251 | AU31: =AU28/AU$5 -> 0.5587121 | AV31: =AV28/AV$5 -> 0.51640472 | AW31: =AW28/AW$5 -> 0.1655966 | AX31: =AX28/AX$5 -> 0.0050326456 | AY31: =AY28/AY$5 -> 0.0048444893
A33: Maintenance and Services | B33: 21.501 | C33: 22.121 | D33: 24.365 | E33: 27.062 | F33: 28.371 | G33: 28.629 | H33: 31.081 | I33: 33.879 | J33: 33.834 | K33: 33.27 | L33: 34.053 | M33: 34.21 | N33: 33.423 | O33: 32.239 | P33: 32.294 | Q33: 32.072 | R33: 29.671 | S33: 30.015 | T33: 30.003 | U33: 29.613 | V33: 27.276 | W33: 27.068 | X33: 27.256 | Y33: 25.89 | Z33: 24.361 | AA33: 24.328 | AB33: 24.629 | AC33: 24.935 | AD33: 24.057 | AE33: 22.832 | AF33: 21.512 | AG33: 19.527 | AH33: 16.375 | AI33: 13.894 | AJ33: 10.941 | AK33: 10.092 | AL33: =+AL164 -> 5.9497918 | AM33: =+AM164 -> 4.6623359 | AN33: =+AN164 -> 3.3456197 | AO33: =+AO164 -> 2 | AP33: =+AP164 -> 2 | AQ33: =+AQ164 -> 2 | AR33: =+AR164 -> 2 | AS33: =+AS164 -> 2 | AU33: =SUM(B33:E33) -> 95.049 | AV33: =SUM(F33:I33) -> 121.96 | AW33: =SUM(J33:M33) -> 135.367 | AX33: =SUM(N33:Q33) -> 130.028 | AY33: =SUM(R33:U33) -> 119.302 | AZ33: =SUM(V33:Y33) -> 107.49 | BA33: =SUM(Z33:AC33) -> 98.253 | BB33: =SUM(AD33:AG33) -> 87.928 | BC33: =SUM(AH33:AK33) -> 51.302 | BD33: =SUM(AL33:AO33) -> 15.957747 | BE33: =SUM(AP33:AS33) -> 8
A34: Consensus professional services revenue | B34: ='[2]VA Consensus'!C27 -> 21.225 | C34: ='[2]VA Consensus'!D27 -> 21.450574 | D34: ='[2]VA Consensus'!E27 -> 22.849497 | E34: ='[2]VA Consensus'!F27 -> 25.265076 | F34: ='[2]VA Consensus'!G27 -> 27.406415 | G34: ='[2]VA Consensus'!H27 -> 28.397139 | H34: ='[2]VA Consensus'!I27 -> 29.973594 | I34: ='[2]VA Consensus'!J27 -> 32.610856 | ... AS34: ='[2]VA Consensus'!AT27 -> 3.2537107 | AU34: ='[2]VA Consensus'!AV27 -> 92.436076 | AV34: ='[2]VA Consensus'!AW27 -> 121.03943 | AW34: ='[2]VA Consensus'!AX27 -> 134.97085 | AX34: ='[2]VA Consensus'!AY27 -> 130.41798 | AY34: ='[2]VA Consensus'!AZ27 -> 119.32442 | AZ34: ='[2]VA Consensus'!BA27 -> 108.09069 | BA34: ='[2]VA Consensus'!BB27 -> 96.918977 | BB34: ='[2]VA Consensus'!BC27 -> 89.156483 | ... BE34: ='[2]VA Consensus'!BF27 -> 15.165337
A35: Y/Y % | F35: =F33/B33-1 -> 0.31952002 | G35: =G33/C33-1 -> 0.29420008 | H35: =H33/D33-1 -> 0.27564129 | I35: =I33/E33-1 -> 0.25190304 | J35: =J33/F33-1 -> 0.19255578 | K35: =K33/G33-1 -> 0.16210835 | L35: =L33/H33-1 -> 0.095621119 | M35: =M33/I33-1 -> 0.0097700641 | ... AK35: =AK33/AG33-1 -> -0.48317714 | AL35: =AK35 -> -0.48317714 | AM35: =AL35 -> -0.48317714 | AN35: =AM35 -> -0.48317714 | AO35: =AN35 -> -0.48317714 | AP35: -0.5 | AQ35: =AP35 -> -0.5 | AR35: =AQ35 -> -0.5 | AS35: =AR35 -> -0.5 | AU35: =IF(ISERROR(AU33/#REF!-1),"NA",AU33/#REF!-1) -> NA | AV35: =IF(ISERROR(AV33/AU33-1),"NA",AV33/AU33-1) -> 0.28312765 | AW35: =IF(ISERROR(AW33/AV33-1),"NA",AW33/AV33-1) -> 0.10992949 | AX35: =IF(ISERROR(AX33/AW33-1),"NA",AX33/AW33-1) -> -0.039440927 | AY35: =IF(ISERROR(AY33/AX33-1),"NA",AY33/AX33-1) -> -0.082489925 | AZ35: =IF(ISERROR(AZ33/AY33-1),"NA",AZ33/AY33-1) -> -0.099009237 | BA35: =IF(ISERROR(BA33/AZ33-1),"NA",BA33/AZ33-1) -> -0.085933575 | BB35: =IF(ISERROR(BB33/BA33-1),"NA",BB33/BA33-1) -> -0.10508585 | BC35: =IF(ISERROR(BC33/BB33-1),"NA",BC33/BB33-1) -> -0.41654536 | ... BE35: =IF(ISERROR(BE33/BD33-1),"NA",BE33/BD33-1) -> -0.49867611
A36: % of total revenue | B36: =B33/B5 -> 0.54305054 | C36: =C33/C5 -> 0.44751269 | D36: =D33/D5 -> 0.45657266 | E36: =E33/E5 -> 0.37070725 | F36: =F33/F5 -> 0.53002167 | G36: =G33/G5 -> 0.46034732 | H36: =H33/H5 -> 0.46353576 | I36: =I33/I5 -> 0.38710894 | ... AS36: =AS33/AS5 -> 0.0085512412 | AU36: =AU33/AU$5 -> 0.4412879 | AV36: =AV33/AV$5 -> 0.4512224 | AW36: =AW33/AW$5 -> 0.53254259 | AX36: =AX33/AX$5 -> 0.44425312 | AY36: =AY33/AY$5 -> 0.3057975 | AZ36: =AZ33/AZ$5 -> 0.22694739 | BA36: =BA33/BA$5 -> 0.19683669 | BB36: =BB33/BB$5 -> 0.15959343 | ... BE36: =BE33/BE$5 -> 0.009043435
B38: ='Income Statement'!B$3 -> 2017 | F38: ='Income Statement'!F$3 -> 2018 | J38: ='Income Statement'!J$3 -> 2019 | N38: ='Income Statement'!N$3 -> 2020 | R38: ='Income Statement'!R$3 -> 2021 | V38: ='Income Statement'!V$3 -> 2022 | Z38: ='Income Statement'!Z$3 -> 2023 | AD38: ='Income Statement'!AD$3 -> 2024 | AH38: ='Income Statement'!AH$3 -> 2025 | AL38: ='Income Statement'!AL$3 -> 2026 | AP38: ='Income Statement'!AP$3 -> 2027
A39: Annual Recurring Revenue (ARR) | B39: ='Income Statement'!B$4 -> 42825 | C39: ='Income Statement'!C$4 -> 42916 | D39: ='Income Statement'!D$4 -> 43008 | E39: ='Income Statement'!E$4 -> 43100 | F39: ='Income Statement'!F$4 -> 43190 | G39: ='Income Statement'!G$4 -> 43281 | H39: ='Income Statement'!H$4 -> 43373 | I39: ='Income Statement'!I$4 -> 43465 | ... AS39: ='Income Statement'!AS$4 -> Dec-27E | AU39: ='Income Statement'!AU$4 -> 2017 | AV39: ='Income Statement'!AV$4 -> 2018 | AW39: ='Income Statement'!AW$4 -> 2019 | AX39: ='Income Statement'!AX$4 -> 2020 | AY39: ='Income Statement'!AY$4 -> 2021 | AZ39: ='Income Statement'!AZ$4 -> 2022 | BA39: ='Income Statement'!BA$4 -> 2023 | BB39: ='Income Statement'!BB$4 -> 2024 | ... BD39: ='Income Statement'!BD$4 -> 2026E | BE39: =BE4 -> 2027E
A40: Total ARR | F40: 103 | G40: 111.9 | H40: 117.9 | I40: 130.3 | J40: 138.7 | K40: 155.2 | L40: 178.9 | M40: 210.5 | N40: 220.5 | O40: 235.7 | P40: 261.1 | Q40: 287.3 | R40: 306.9 | S40: 328.2 | T40: 354.2 | U40: 387.1 | V40: 404.5 | W40: 426.3 | X40: 447.8 | Y40: 465.1 | Z40: 478.1 | AA40: 497 | AB40: 517.5 | AC40: 543 | AD40: 560.3 | AE40: 584.2 | AF40: 610 | AG40: 641.9 | AH40: 664.3 | AI40: 693.2 | AJ40: 718.6 | AK40: 745.4 | AL40: =AL143 -> 755.475 | AM40: =AM143 -> 774.785 | AN40: =AN143 -> 796.3475 | AO40: =AO143 -> 822.4625 | AP40: =AP143 -> 851.915 | AQ40: =AQ143 -> 887.126 | AR40: =AR143 -> 920.41475 | AS40: =AS143 -> 955.96125 | AV40: =I40 -> 130.3 | AW40: =M40 -> 210.5 | AX40: =Q40 -> 287.3 | AY40: =U40 -> 387.1 | AZ40: =Y40 -> 465.1 | BA40: =AC40 -> 543 | BB40: =AG40 -> 641.9 | BC40: =AK40 -> 745.4 | BD40: =AO40 -> 822.4625 | BE40: =AS40 -> 955.96125
A41: Consensus ARR | B41: ='[2]VA Consensus'!C17 -> - | C41: ='[2]VA Consensus'!D17 -> - | D41: ='[2]VA Consensus'!E17 -> - | E41: ='[2]VA Consensus'!F17 -> - | F41: ='[2]VA Consensus'!G17 -> - | G41: ='[2]VA Consensus'!H17 -> - | H41: ='[2]VA Consensus'!I17 -> - | I41: ='[2]VA Consensus'!J17 -> - | ... AS41: ='[2]VA Consensus'!AT17 -> 940.97822 | AW41: ='[2]VA Consensus'!AX17 -> 192.8007 | AX41: ='[2]VA Consensus'!AY17 -> 270.05942 | AY41: ='[2]VA Consensus'!AZ17 -> 380.49017 | AZ41: ='[2]VA Consensus'!BA17 -> 453.5074 | BA41: ='[2]VA Consensus'!BB17 -> 537.31447 | BB41: ='[2]VA Consensus'!BC17 -> 637.73931 | BC41: ='[2]VA Consensus'!BD17 -> 734.46679 | BD41: ='[2]VA Consensus'!BE17 -> 821.1766 | BE41: ='[2]VA Consensus'!BF17 -> 940.97822
A42: Y/Y % | J42: =J40/F40-1 -> 0.34660194 | K42: =K40/G40-1 -> 0.38695264 | L42: =L40/H40-1 -> 0.51738762 | M42: =M40/I40-1 -> 0.61550269 | N42: =N40/J40-1 -> 0.58976208 | O42: =O40/K40-1 -> 0.51868557 | P42: =P40/L40-1 -> 0.45947457 | Q42: =Q40/M40-1 -> 0.36484561 | ... AS42: =AS40/AO40-1 -> 0.16231591 | AW42: NA | AX42: =AX40/AW40-1 -> 0.36484561 | AY42: =AY40/AX40-1 -> 0.34737208 | AZ42: =AZ40/AY40-1 -> 0.20149832 | BA42: =BA40/AZ40-1 -> 0.16749086 | BB42: =BB40/BA40-1 -> 0.18213628 | BC42: =BC40/BB40-1 -> 0.16124007 | BD42: =BD40/BC40-1 -> 0.10338409 | BE42: =BE40/BD40-1 -> 0.16231591
A43: Management Guidance - FY ARR
A44: Low | AC44: 535 | AD44: 617 | AE44: 622 | AF44: 629 | AG44: =BB44 -> 635 | AH44: 737 | AI44: 748 | AJ44: 748 | AK44: =BC44 -> 730 | AO44: =BD44 -> 805 | AZ44: 460 | BA44: 535 | BB44: 635 | BC44: 730 | BD44: 805
A45: Mid | AC45: =AVERAGE(AC44,AC46) -> 537 | AD45: =AVERAGE(AD44,AD46) -> 621 | AE45: =AZ45 -> 461.5 | AF45: =BA45 -> 537 | AG45: =BB45 -> 637 | AH45: =BC45 -> 734 | AI45: =AVERAGE(AI44,AI46) -> 751 | AJ45: =AVERAGE(AJ44,AJ46) -> 751 | AK45: =AVERAGE(AK44,AK46) -> 734 | AO45: =AVERAGE(AO44,AO46) -> 822.5 | AZ45: =AVERAGE(AZ44,AZ46) -> 461.5 | BA45: =AVERAGE(BA44,BA46) -> 537 | BB45: =IFERROR(AVERAGE(BB44,BB46),"") -> 637 | BC45: =IFERROR(AVERAGE(BC44,BC46),"") -> 734 | BD45: =IFERROR(AVERAGE(BD44,BD46),"") -> 822.5 | BE45: =IFERROR(AVERAGE(BE44,BE46),"")
...

Sheet Balance Sheet
A1: =+'Income Statement'!A1 -> Varonis Systems, Inc. (VRNS)
A2: Balance Sheet | AU2: =+'Income Statement'!AU2 -> 2017 | AV2: =+'Income Statement'!AV2 -> 2018 | AW2: =+'Income Statement'!AW2 -> 2019 | AX2: =+'Income Statement'!AX2 -> 2020 | AY2: =+'Income Statement'!AY2 -> 2021 | AZ2: =+'Income Statement'!AZ2 -> 2022 | BA2: =+'Income Statement'!BA2 -> 2023 | BB2: =+'Income Statement'!BB2 -> 2024 | ... BE2: =+'Income Statement'!BE2 -> 2027
B3: ='Income Statement'!B$3 -> 2017 | F3: ='Income Statement'!F$3 -> 2018 | J3: ='Income Statement'!J$3 -> 2019 | N3: ='Income Statement'!N$3 -> 2020 | R3: ='Income Statement'!R$3 -> 2021 | V3: ='Income Statement'!V$3 -> 2022 | Z3: ='Income Statement'!Z$3 -> 2023 | AD3: ='Income Statement'!AD$3 -> 2024 | AH3: ='Income Statement'!AH$3 -> 2025 | AL3: ='Income Statement'!AL$3 -> 2026 | AP3: ='Income Statement'!AP$3 -> 2027
A4: ='Income Statement'!A4 -> ($ in millions, unless otherwise stated) | B4: ='Income Statement'!B$4 -> 42825 | C4: ='Income Statement'!C$4 -> 42916 | D4: ='Income Statement'!D$4 -> 43008 | E4: ='Income Statement'!E$4 -> 43100 | F4: ='Income Statement'!F$4 -> 43190 | G4: ='Income Statement'!G$4 -> 43281 | H4: ='Income Statement'!H$4 -> 43373 | I4: ='Income Statement'!I$4 -> 43465 | ... AS4: ='Income Statement'!AS$4 -> Dec-27E | AU4: ='Income Statement'!AU$4 -> 2017 | AV4: ='Income Statement'!AV$4 -> 2018 | AW4: ='Income Statement'!AW$4 -> 2019 | AX4: ='Income Statement'!AX$4 -> 2020 | AY4: ='Income Statement'!AY$4 -> 2021 | AZ4: ='Income Statement'!AZ$4 -> 2022 | BA4: ='Income Statement'!BA$4 -> 2023 | BB4: ='Income Statement'!BB$4 -> 2024 | ... BE4: ='Income Statement'!BE$4 -> 2027E
A5: Current assets
A6: Cash and Cash Equivalents | B6: 51.07 | C6: 53.539 | D6: 53.478 | E6: 56.689 | F6: 70.778 | G6: 73.636 | H6: 67.868 | I6: 48.707 | J6: 64.461 | K6: 69.159 | L6: 52.984 | M6: 68.929 | N6: 77.533 | O6: 239.979 | P6: 231.458 | Q6: 234.092 | R6: 753.606 | S6: 781.357 | T6: 803.144 | U6: 805.761 | V6: 775.719 | W6: 753.172 | X6: 754.245 | Y6: 367.8 | Z6: 248.585 | AA6: 399.196 | AB6: 111.196 | AC6: 230.74 | AD6: 147.051 | AE6: 155.403 | AF6: 282.218 | AG6: 185.585 | AH6: 153.107 | AI6: 199.231 | AJ6: 157.354 | AK6: 202.482 | AL6: =AK6+'Cash Flow'!AL46 -> 261.44757 | AM6: =AL6+'Cash Flow'!AM46 -> 270.9465 | AN6: =AM6+'Cash Flow'!AN46 -> 277.50712 | AO6: =AN6+'Cash Flow'!AO46 -> 249.81498 | AP6: =AO6+'Cash Flow'!AP46 -> 323.67462 | AQ6: =AP6+'Cash Flow'!AQ46 -> 332.05016 | AR6: =AQ6+'Cash Flow'!AR46 -> 347.71623 | AS6: =AR6+'Cash Flow'!AS46 -> 333.3823 | AU6: =E6 -> 56.689 | AV6: =I6 -> 48.707 | AW6: =M6 -> 68.929 | AX6: =Q6 -> 234.092 | AY6: =U6 -> 805.761 | AZ6: =Y6 -> 367.8 | BA6: =AC6 -> 230.74 | BB6: =AG6 -> 185.585 | BC6: =AK6 -> 202.482 | BD6: =AO6 -> 249.81498 | BE6: =AP6 -> 323.67462
A7: Marketable Securities | B7: 0 | C7: 0 | D7: 0 | E7: 0 | F7: 0 | G7: 0 | H7: 0 | I7: 39.77 | J7: 37.842 | K7: 35.845 | L7: 41.397 | M7: 41.531 | N7: 33.737 | O7: 26.116 | P7: 34.112 | Q7: 34.117 | R7: 28.08 | S7: 20.035 | T7: 8.01 | U7: 0 | V7: 28.372 | W7: 28.735 | X7: 25.235 | Y7: 236.338 | Z7: 280.835 | AA7: 277.419 | AB7: 337.705 | AC7: 253.175 | AD7: 355.743 | AE7: 427.065 | AF7: 562.568 | AG7: 343.383 | AH7: 414.524 | AI7: 571.63 | AJ7: 513.935 | AK7: 681.225 | AL7: =AK7 -> 681.225 | AM7: =AL7 -> 681.225 | AN7: =AM7 -> 681.225 | AO7: =AN7 -> 681.225 | AP7: =AO7 -> 681.225 | AQ7: =AP7 -> 681.225 | AR7: =AQ7 -> 681.225 | AS7: =AR7 -> 681.225 | AU7: =E7 -> 0 | AV7: =I7 -> 39.77 | AW7: =M7 -> 41.531 | AX7: =Q7 -> 34.117 | AY7: =U7 -> 0 | AZ7: =Y7 -> 236.338 | BA7: =AC7 -> 253.175 | BB7: =AG7 -> 343.383 | BC7: =AK7 -> 681.225 | BD7: =AO7 -> 681.225 | BE7: =AP7 -> 681.225
A8: Short-Term Bank Deposits | B8: 70.25 | C8: 68.039 | D8: 74.963 | E8: 79.868 | F8: 82.892 | G8: 85.045 | H8: 90.214 | I8: 70.438 | J8: 61.328 | K8: 41.328 | L8: 37 | M8: 10 | N8: 15 | O8: 60 | P8: 60 | Q8: 30.053 | R8: 42.284 | S8: 12.276 | T8: 2.276 | U8: 1.85 | V8: 0 | W8: 6.856 | X8: 10.871 | Y8: 128.35 | Z8: 226.85 | AA8: 77.139 | AB8: 76.186 | AC8: 49.8 | AD8: 45.28 | AE8: 44.846 | AF8: 34.174 | AG8: 39.45 | AH8: 41.588 | AI8: 36.587 | AJ8: 36.632 | AK8: 37.259 | AL8: =AK8 -> 37.259 | AM8: =AL8 -> 37.259 | AN8: =AM8 -> 37.259 | AO8: =AN8 -> 37.259 | AP8: =AO8 -> 37.259 | AQ8: =AP8 -> 37.259 | AR8: =AQ8 -> 37.259 | AS8: =AR8 -> 37.259 | AU8: =E8 -> 79.868 | AV8: =I8 -> 70.438 | AW8: =M8 -> 10 | AX8: =Q8 -> 30.053 | AY8: =U8 -> 1.85 | AZ8: =Y8 -> 128.35 | BA8: =AC8 -> 49.8 | BB8: =AG8 -> 39.45 | BC8: =AK8 -> 37.259 | BD8: =AO8 -> 37.259 | BE8: =AP8 -> 37.259
