Workbook
Name \P: #REF!
Name \P: #REF!
Name \P: #REF!
Name \P: #REF!
Name \Q: [1]TSFW!#REF!
Name \Q: [1]TSFW!#REF!
Name \Q: [1]TSFW!#REF!
Name \Q: [1]TSFW!#REF!
Name \S: '[2]US$'!#REF!
Name \S: '[2]US$'!#REF!
Name \X: [1]TSFW!#REF!
Name _1997: #REF!
Name _1997: #REF!
Name _1997: #REF!
Name _1997: #REF!
Name _1998: #REF!
Name _1998: #REF!
Name _1998: #REF!
Name _1999: #REF!
Name _1999: #REF!
Name _1999: #REF!
Name _1st_year: '[3]LINKS&INPUTS'!$D$52
Name _2000: #REF!
Name _2000: #REF!
Name _2000: #REF!
Name _2000: #REF!
Name _2000_EPS: #REF!
Name _2000_EPS: #REF!
Name _2000_EPS: #REF!
Name _2000_Rev: #REF!
Name _2000_Rev: #REF!
Name _2000_Rev: #REF!
Name _2001: #REF!
Name _2001_EPS: #REF!
Name _2001_Rev: #REF!
Name _2002: #REF!
Name _2002_EPS: #REF!
Name _2002_Rev: #REF!
Name _2003: #REF!
Name _2003_EPS: #REF!
Name _2003_Rev: #REF!
Name _2004: #REF!
Name _2004_EPS: #REF!
Name _2004_Rev: #REF!
Name _2005: #REF!
Name _2005_cfps: [4]NAV!#REF!
Name _2005_EPS: #REF!
Name _2005_EPS: #REF!
Name _2005_EPS: #REF!
Name _2005_EPS: #REF!
Name _2005_Rev: #REF!
Name _2005_Rev: #REF!
Name _2005_Rev: #REF!
Name _2006: #REF!
Name _2006: #REF!
Name _2006: #REF!
Name _2006_cfps: [4]NAV!#REF!
Name _2006_cfps: [4]NAV!#REF!
Name _2006_cfps: [4]NAV!#REF!
Name _2006_eps: [4]NAV!#REF!

Sheet __FDSCACHE__
B1: This sheet contains FactSet XML data for use with this workbook's =FDS codes. Modifying the worksheet's contents may damage the workbook's =FDS functionality.

Sheet Comparison
B2: =IS!B2 -> DocuSign, Inc (DOCU)
B4: Variance Analysis | D4: =IS!BO4 -> 3Q25 | E4: =K4 -> 3Q26 | F4: Y/Y Δ | G4: =IS!BS4 -> 2Q26 | H4: =K4 -> 3Q26 | I4: Q/Q Δ | J4: 3Q26E | K4: =IS!BT4 -> 3Q26 | L4: % Δ | N4: Variance | P4: 1Q Cons. | Q4: 2Q Guide | R4: 2Q Cons. | S4: FY G Prev | T4: FY G New | U4: Change | V4: FY Cons.
B5: Subscription Revenues | D5: =IS!BO5 -> 734693 | E5: =K5 -> 800958 | F5: =E5/D5-1 -> 0.090194136 | G5: =IS!BS5 -> 784388 | H5: =K5 -> 800958 | I5: =H5/G5-1 -> 0.021124749 | J5: 788325.59 | K5: =IS!BT5 -> 800958 | L5: =K5/J5-1 -> 0.016024357 | N5: =K5-J5 -> 12632.411 | P5: 564000 | Q5: =(583000+587000)/2 -> 585000 | R5: 581000 | S5: =(2394000+2406000)/2 -> 2400000 | T5: =(2394000+2406000)/2 -> 2400000 | U5: =IF(AND(ISNUMBER(T5), ISNUMBER(S5)), T5-S5, "-") -> 0 | V5: 2401000
B6: Professional Services | D6: =IS!BO9 -> 20127 | E6: =K6 -> 17392 | F6: =E6/D6-1 -> -0.13588712 | G6: =IS!BS9 -> 16248 | H6: =K6 -> 17392 | I6: =H6/G6-1 -> 0.070408666 | J6: 17913.03 | K6: =IS!BT9 -> 17392 | L6: =K6/J6-1 -> -0.029086648 | N6: =K6-J6 -> -521.03 | P6: 17000 | Q6: =Q7-Q5 -> 17000 | R6: 20000 | S6: =S7-S5 -> 76000 | T6: =T7-T5 -> 76000 | U6: =IF(AND(ISNUMBER(T6), ISNUMBER(S6)), T6-S6, "-") -> 0 | V6: 74000
B7: Total Revenue | D7: =D5+D6 -> 754820 | E7: =K7 -> 818350 | F7: =E7/D7-1 -> 0.084165761 | G7: =G5+G6 -> 800636 | H7: =K7 -> 818350 | I7: =H7/G7-1 -> 0.022124911 | J7: 806238.62 | K7: =K5+K6 -> 818350 | L7: =K7/J7-1 -> 0.01502208 | N7: =K7-J7 -> 12111.381 | P7: 583000 | Q7: =(600000+604000)/2 -> 602000 | R7: 601000 | S7: =(2470000+2482000)/2 -> 2476000 | T7: =(2470000+2482000)/2 -> 2476000 | U7: =IF(AND(ISNUMBER(T7), ISNUMBER(S7)), T7-S7, "-") -> 0 | V7: 2476000
B9: Cost of Revenue
B10: Subscription Revenues | D10: =IS!BO18 -> 115585 | E10: =K10 -> 132970 | F10: =E10/D10-1 -> 0.15040879 | G10: =IS!BS18 -> 126890 | H10: =K10 -> 132970 | I10: =H10/G10-1 -> 0.047915517 | J10: 137956.98 | K10: =IS!BT18 -> 132970 | L10: =K10/J10-1 -> -0.036148792
B11: Professional Services | D11: =IS!BO20 -> 16865 | E11: =K11 -> 15891 | F11: =E11/D11-1 -> -0.057752742 | G11: =IS!BS20 -> 16844 | H11: =K11 -> 15891 | I11: =H11/G11-1 -> -0.05657801 | J11: 16838.248 | K11: =IS!BT20 -> 15891 | L11: =K11/J11-1 -> -0.056255745
B12: Total Cost of Revenues | D12: =D10+D11 -> 132450 | E12: =K12 -> 148861 | F12: =E12/D12-1 -> 0.12390336 | G12: =G10+G11 -> 143734 | H12: =K12 -> 148861 | I12: =H12/G12-1 -> 0.035670057 | J12: 154795.23 | K12: =K10+K11 -> 148861 | L12: =K12/J12-1 -> -0.038335977
B14: Gross Profit | D14: =D7-D12 -> 622370 | E14: =K14 -> 669489 | F14: =E14/D14-1 -> 0.075708983 | G14: =G7-G12 -> 656902 | H14: =K14 -> 669489 | I14: =H14/G14-1 -> 0.019161153 | J14: 651443.39 | K14: =K7-K12 -> 669489 | L14: =K14/J14-1 -> 0.02770096 | N14: =K14-J14 -> 18045.607 | P14: 467000 | Q14: =Q15*Q7 -> 481600 | R14: 482000 | S14: =(1951000+2010000)/2 -> 1980500 | T14: =T15*T7 -> 1980800 | U14: =IF(AND(ISNUMBER(T14), ISNUMBER(S14)), T14-S14, "-") -> 300 | V14: 1971000
C15: Gross Margins | D15: =D14/D7 -> 0.8245277 | E15: =K15 -> 0.81809617 | G15: =G14/G7 -> 0.82047522 | H15: =K15 -> 0.81809617 | J15: 0.80800321 | K15: =K14/K7 -> 0.81809617 | N15: =K15-D15 -> -0.0064315328 | P15: =P14/P7 -> 0.80102916 | Q15: 0.8 | R15: =R14/R7 -> 0.80199667 | S15: =S14/S7 -> 0.79987884 | T15: 0.8 | V15: =V14/V7 -> 0.796042
B17: Operating Expenses
B18: S&M | D18: =IS!BO27 -> 236278 | E18: =K18 -> 242764 | F18: =E18/D18-1 -> 0.027450715 | G18: =IS!BS27 -> 250053 | H18: =K18 -> 242764 | I18: =H18/G18-1 -> -0.02914982 | J18: 253965.16 | K18: =IS!BT27 -> 242764 | L18: =K18/J18-1 -> -0.044105124 | N18: =K18-J18 -> -11201.165
B19: R&D | D19: =IS!BO29 -> 96644 | E19: =K19 -> 104902 | F19: =E19/D19-1 -> 0.085447622 | G19: =IS!BS29 -> 105165 | H19: =K19 -> 104902 | I19: =H19/G19-1 -> -0.002500832 | J19: 104811.02 | K19: =IS!BT29 -> 104902 | L19: =K19/J19-1 -> 0.00086803401 | N19: =K19-J19 -> 90.97953
B20: G&A | D20: =IS!BO31 -> 66372 | E20: =K20 -> 64771 | F20: =E20/D20-1 -> -0.024121618 | G20: =IS!BS31 -> 62955 | H20: =K20 -> 64771 | I20: =H20/G20-1 -> 0.028846001 | J20: 63692.851 | K20: =IS!BT31 -> 64771 | L20: =K20/J20-1 -> 0.016927317 | N20: =K20-J20 -> 1078.1491
B21: Total Operating Expenses | D21: =SUM(D18:D20) -> 399294 | E21: =K21 -> 412437 | F21: =E21/D21-1 -> 0.032915596 | G21: =SUM(G18:G20) -> 418173 | H21: =K21 -> 412437 | I21: =H21/G21-1 -> -0.013716811 | J21: 422469.04 | K21: =SUM(K18:K20) -> 412437 | L21: =K21/J21-1 -> -0.023746205 | N21: =K21-J21 -> -10032.036
B23: Non-GAAP Operating Income (Loss) | D23: =D14-D21 -> 223076 | E23: =K23 -> 257052 | F23: =E23/D23-1 -> 0.15230684 | G23: =G14-G21 -> 238729 | H23: =K23 -> 257052 | I23: =H23/G23-1 -> 0.076752301 | J23: 228974.36 | K23: =K14-K21 -> 257052 | L23: =K23/J23-1 -> 0.12262353 | N23: =K23-J23 -> 28077.644 | P23: 98000 | Q23: =Q24*Q7 -> 102340 | R23: 98000 | S23: =(395000+447000)/2 -> 421000 | T23: =T24*T7 -> 420920 | U23: =IF(AND(ISNUMBER(T23), ISNUMBER(S23)), T23-S23, "-") -> -80 | V23: 416000
C24: Non-GAAP Operating Margins | D24: =D23/D7 -> 0.29553536 | E24: =K24 -> 0.3141101 | G24: =G23/G7 -> 0.2981742 | H24: =K24 -> 0.3141101 | J24: 0.28400321 | K24: =K23/K7 -> 0.3141101 | P24: =P23/P7 -> 0.16809605 | Q24: 0.17 | R24: =R23/R7 -> 0.16306156 | S24: =S23/S7 -> 0.17003231 | T24: 0.17 | V24: =V23/V7 -> 0.16801292
B26: GAAP & Non-cash charges | D26: =IS!BO44 -> 164046 | E26: =K26 -> 171697 | F26: =E26/D26-1 -> 0.046639357 | G26: =IS!BS44 -> 173502 | H26: =K26 -> 171697 | I26: =H26/G26-1 -> -0.010403338 | J26: 160916 | K26: =IS!BT44 -> 171697 | L26: =K26/J26-1 -> 0.066997688
B28: GAAP Operating Income | D28: =D23-D26 -> 59030 | E28: =K28 -> 85355 | F28: =E28/D28-1 -> 0.44595968 | G28: =G23-G26 -> 65227 | H28: =K28 -> 85355 | I28: =H28/G28-1 -> 0.30858387 | J28: 68058.356 | K28: =K23-K26 -> 85355 | L28: =K28/J28-1 -> 0.2541443
C29: GAAP Operating Margins | D29: =D28/D7 -> 0.078204075 | E29: =K29 -> 0.10430134 | G29: =G28/G7 -> 0.081468982 | H29: =K29 -> 0.10430134 | J29: 0.084414657 | K29: =K28/K7 -> 0.10430134
B31: Non-GAAP Interest & Other Income (Expense) | D31: =IS!BO54 -> 12544 | E31: =K31 -> 10174 | F31: =E31/D31-1 -> -0.18893495 | G31: =IS!BS54 -> 11233 | H31: =K31 -> 10174 | I31: =H31/G31-1 -> -0.094275795 | J31: 11000 | K31: =IS!BT54 -> 10174 | L31: =K31/J31-1 -> -0.075090909
B32: GAAP Total Other Income (Expense) | D32: =IS!BO55 -> 12544 | E32: =K32 -> 10174 | F32: =E32/D32-1 -> -0.18893495 | G32: =IS!BS55 -> 11233 | H32: =K32 -> 10174 | I32: =H32/G32-1 -> -0.094275795 | J32: 11000 | K32: =IS!BT55 -> 10174 | L32: =K32/J32-1 -> -0.075090909
B34: Non-GAAP Income before Taxes | D34: =D23+D31 -> 235620 | E34: =K34 -> 267226 | F34: =E34/D34-1 -> 0.13413972 | G34: =G23+G31 -> 249962 | H34: =K34 -> 267226 | I34: =H34/G34-1 -> 0.069066498 | J34: 239974.36 | K34: =K23+K31 -> 267226 | L34: =K34/J34-1 -> 0.11356065
B35: Income Tax | D35: =IS!BO61 -> 47124 | E35: =K35 -> 56117 | G35: =IS!BS61 -> 54877 | H35: =K35 -> 56117 | J35: 47994.871 | K35: =IS!BT61 -> 56117 | S35: 6000 | T35: 9000
B36: Non-GAAP Net Income | D36: =D34-D35 -> 188496 | E36: =K36 -> 211109 | F36: =E36/D36-1 -> 0.11996541 | G36: =G34-G35 -> 195085 | H36: =K36 -> 211109 | I36: =H36/G36-1 -> 0.082138555 | J36: 191979.49 | K36: =K34-K35 -> 211109 | L36: =K36/J36-1 -> 0.099643537 | N36: =K36-J36 -> 19129.515
B38: GAAP Income before Taxes | D38: =IS!BO66 -> 71574 | E38: =K38 -> 95529 | F38: =E38/D38-1 -> 0.33468857 | G38: =IS!BS66 -> 76460 | H38: =K38 -> 95529 | I38: =H38/G38-1 -> 0.24939838 | J38: 79058.356 | K38: =IS!BT66 -> 95529 | L38: =K38/J38-1 -> 0.20833527
B39: Income Tax | D39: =IS!BO67 -> 9151 | E39: =K39 -> 11804 | G39: =IS!BS67 -> 13490 | H39: =K39 -> 11804 | J39: 6000 | K39: =IS!BT67 -> 11804
B40: GAAP Net Income | D40: =D38-D39 -> 62423 | E40: =K40 -> 83725 | F40: =E40/D40-1 -> 0.34125242 | G40: =G38-G39 -> 62970 | H40: =K40 -> 83725 | I40: =H40/G40-1 -> 0.3296014 | J40: 73058.356 | K40: =K38-K39 -> 83725 | L40: =K40/J40-1 -> 0.14600169
B42: Non-GAAP EPS | D42: =D36/D46 -> 0.90316522 | E42: =K42 -> 1.0146105 | F42: =E42/D42-1 -> 0.12339417 | G42: =G36/G46 -> 0.9247663 | H42: =K42 -> 1.0146105 | I42: =H42/G42-1 -> 0.097153449 | J42: 0.91047675 | K42: =K36/K46 -> 1.0146105 | L42: =K42/J42-1 -> 0.11437282 | N42: =K42-J42 -> 0.10413379 | P42: 0.46 | R42: 0.46 | V42: 0.54
B43: GAAP EPS | D43: =D40/D45 -> 0.30664597 | E43: =K43 -> 0.41457461 | G43: =G40/G45 -> 0.31074199 | H43: =K43 -> 0.41457461 | J43: 0.36070363 | K43: =K40/K45 -> 0.41457461
B45: Basic Shares Outstanding | D45: =IS!BO79 -> 203567 | E45: =K45 -> 201954 | G45: =IS!BS79 -> 202644 | H45: =K45 -> 201954 | J45: 202544 | K45: =IS!BT79 -> 201954
B46: Diluted Shares Outstanding | D46: =IS!BO80 -> 208706 | E46: =K46 -> 208069 | G46: =IS!BS80 -> 210956 | H46: =K46 -> 208069 | J46: 210856 | K46: =IS!BT80 -> 208069 | Q46: =(205000+210000)/2 -> 207500 | S46: =(205000+210000)/2 -> 207500 | T46: =(205000+210000)/2 -> 207500
X47: 1Q23 | Y47: FY23
B48: Source: Company reports and Needham & Co estimates | W48: Billings | X48: 573 - 583 | Y48: 2706 - 2726
B50: Billings | P50: 581400 | Q50: =(599000+609000)/2 -> 604000 | R50: 677300 | S50: =(2710000+2730000)/2 -> 2720000 | T50: =(2521000+2541000)/2 -> 2531000 | U50: =IF(AND(ISNUMBER(T50), ISNUMBER(S50)), T50-S50, "-") -> -189000 | V50: 2713900

Sheet G CHG
C5: FY26 Guidance | D5: Prior FY26 Guide | E5: Updated FY26 Guide | F5: Delta | G5: 3Q26 Guide | H5: 3Q26 Result | I5: 3Q26 Beat | J5: Rest of Year Raise / (Reduce)
C6: Revenue ($mm) | D6: =AVERAGE(3189,3201) -> 3195 | E6: =AVERAGE(3208,3212) -> 3210 | F6: =E6-D6 -> 15 | G6: =AVERAGE(804,808) -> 806 | H6: =Comparison!K7/1000 -> 818.35 | I6: =H6-G6 -> 12.35 | J6: =F6-I6 -> 2.65
C7: Growth | D7: =D6/(IS!BQ13/1000)-1 -> 0.073322182 | E7: =E6/(IS!BQ13/1000)-1 -> 0.078361254
C8: Subscription Revenue | D8: =AVERAGE(3121,3133) -> 3127 | E8: =AVERAGE(3140,3144) -> 3142 | F8: =E8-D8 -> 15 | G8: =AVERAGE(786,790) -> 788 | H8: =Comparison!K5/1000 -> 800.958 | I8: =H8-G8 -> 12.958 | J8: =F8-I8 -> 2.042
C9: Growth | D9: =D8/(IS!BQ5/1000)-1 -> 0.07778937 | E9: =E8/(IS!BQ5/1000)-1 -> 0.08295945
C10: Billings | D10: =AVERAGE(3325,3355) -> 3340 | E10: =AVERAGE(3379,3389) -> 3384 | F10: =E10-D10 -> 44 | G10: =AVERAGE(785,795) -> 790 | H10: =IS!BO108/1000 -> 752.307 | I10: =H10-G10 -> -37.693 | J10: =F10-I10 -> 81.693
C11: Growth | D11: =D10/(IS!BQ108/1000)-1 -> 0.074107293 | E11: =E10/(IS!BQ108/1000)-1 -> 0.088257209
C12: Non-GAAP Operating Margin | D12: =AVERAGE(28.6%,29.6%) -> 0.291 | E12: =AVERAGE(29.8%,29.9%) -> 0.2985 | F12: =E12-D12 -> 0.0075 | G12: =AVERAGE(28%,29%) -> 0.285 | H12: =Comparison!K24 -> 0.3141101
L14: Guidance History | M14: FY23 | N14: FY24 | O14: FY25 | P14: FY26E
L15: Revenue Growth - Initial Guide | M15: 0.175 | N15: 0.074 | O15: 0.058 | P15: 0.053
L16: Revenue Growth- Actual | M16: =IS!BG14 -> 0.19395381 | N16: =IS!BL14 -> 0.097764432 | O16: =IS!BQ14 -> 0.077793693 | P16: TBD
L17: Difference | M17: =M16-M15 -> 0.018953815 | N17: =N16-N15 -> 0.023764432 | O17: =O16-O15 -> 0.019793693 | P17: TBD
L19: NG Operating Margin - Initial Guide | M19: 0.17 | N19: 0.22 | O19: 0.2725 | P19: 0.283
L20: NG Operating Margin - Actual | M20: =IS!BG36 -> 0.20544812 | N20: =IS!BL36 -> 0.2575664 | O20: =IS!BQ36 -> 0.29764047 | P20: TBD
L21: Difference | M21: =M20-M19 -> 0.035448117 | N21: =N20-N19 -> 0.037566399 | O21: =O20-O19 -> 0.025140472 | P21: TBD

Sheet IS
B2: DocuSign, Inc (DOCU)
B4: Income Statement (FYE January 31) | D4: 2012 | E4: 1Q13 | F4: 2Q13 | G4: 3Q13 | H4: 4Q13 | I4: FY13 | J4: 1Q14 | K4: 2Q14 | L4: 3Q14 | M4: 4Q14 | N4: FY14 | O4: 1Q15 | P4: 2Q15 | Q4: 3Q15 | R4: 4Q15 | S4: FY15 | T4: 1Q16 | U4: 2Q16 | V4: 3Q16 | W4: 4Q16 | X4: FY16 | Y4: 1Q17 | Z4: 2Q17 | AA4: 3Q17 | AB4: 4Q17 | AC4: FY17 | AD4: 1Q18 | AE4: 2Q18 | AF4: 3Q18 | AG4: 4Q18 | AH4: FY18 | AI4: 1Q19 | AJ4: 2Q19 | AK4: 3Q19 | AL4: 4Q19 | AM4: FY19 | AN4: 1Q20 | AO4: 2Q20 | AP4: 3Q20 | AQ4: 4Q20 | AR4: FY20 | AS4: 1Q21 | AT4: 2Q21 | AU4: 3Q21 | AV4: 4Q21 | AW4: FY21 | AX4: 1Q22 | AY4: 2Q22 | AZ4: 3Q22 | BA4: 4Q22 | BB4: FY22 | BC4: 1Q23 | BD4: 2Q23 | BE4: 3Q23 | BF4: 4Q23 | BG4: FY23 | BH4: 1Q24 | BI4: 2Q24 | BJ4: 3Q24 | BK4: 4Q24 | BL4: FY24 | BM4: 1Q25 | BN4: 2Q25 | BO4: 3Q25 | BP4: 4Q25 | BQ4: FY25 | BR4: 1Q26 | BS4: 2Q26 | BT4: 3Q26 | BU4: 4Q26E | BV4: FY26E | BW4: 1Q27E | BX4: 2Q27E | BY4: 3Q27E | BZ4: 4Q27E | CA4: FY27E
B5: Subscription Revenue | X5: =229127 -> 229127 | AC5: =348563 -> 348563 | AD5: 106847 | AE5: 117553 | AF5: 122905 | AG5: 137276 | AH5: =SUM(AD5:AG5) -> 484581 | AI5: 148198 | AJ5: 158461 | AK5: 169426 | AL5: =187572 -> 187572 | AM5: =SUM(AI5:AL5) -> 663657 | AN5: =201458 -> 201458 | AO5: 220811 | AP5: =238072 -> 238072 | AQ5: 258122 | AR5: =SUM(AN5:AQ5) -> 918463 | AS5: 280922 | AT5: =323643 -> 323643 | AU5: =366617 -> 366617 | AV5: 410215 | AW5: =SUM(AS5:AV5) -> 1381397 | AX5: 451935 | AY5: 492758 | AZ5: 528573 | BA5: 564006 | BB5: =SUM(AX5:BA5) -> 2037272 | BC5: 569251 | BD5: 605194 | BE5: 624055 | BF5: 643677 | BG5: =SUM(BC5:BF5) -> 2442177 | BH5: 639307 | BI5: 669367 | BJ5: 682352 | BK5: 695682 | BL5: =SUM(BH5:BK5) -> 2686708 | BM5: 691483 | BN5: 717366 | BO5: 734693 | BP5: 757767 | BQ5: =SUM(BM5:BP5) -> 2901309 | BR5: 746202 | BS5: 784388 | BT5: 800958 | BU5: =BP5*(1+BU6) -> 810280.25 | BV5: =SUM(BR5:BU5) -> 3141828.3 | BW5: =BR5*(1+BW6) -> 790974.12 | BX5: =BS5*(1+BX6) -> 831451.28 | BY5: =BT5*(1+BY6) -> 849015.48 | BZ5: =BU5*(1+BZ6) -> 858897.07 | CA5: =SUM(BW5:BZ5) -> 3330337.9
C6: Y/Y Growth | O6: =O5/J5-1 -> #DIV/0! | P6: =P5/K5-1 -> #DIV/0! | Q6: =Q5/L5-1 -> #DIV/0! | R6: =R5/M5-1 -> #DIV/0! | V6: =V5/Q5-1 -> #DIV/0! | W6: =W5/R5-1 -> #DIV/0! | X6: =X5/S5-1 -> #DIV/0! | Y6: =Y5/T5-1 -> #DIV/0! | Z6: =Z5/U5-1 -> #DIV/0! | AA6: =AA5/V5-1 -> #DIV/0! | AB6: =AB5/W5-1 -> #DIV/0! | AC6: =AC5/X5-1 -> 0.5212655 | ... BT6: =BT5/BO5-1 -> 0.090194136 | BU6: 0.0693 | BV6: =BV5/BQ5-1 -> 0.082900254 | BW6: 0.06 | BX6: 0.06 | BY6: 0.06 | BZ6: 0.06 | CA6: =CA5/BV5-1 -> 0.06
C7: Q/Q Growth | F7: =F5/E5-1 -> #DIV/0! | G7: =G5/F5-1 -> #DIV/0! | H7: =H5/G5-1 -> #DIV/0! | O7: =O5/M5-1 -> #DIV/0! | P7: =P5/O5-1 -> #DIV/0! | Q7: =Q5/P5-1 -> #DIV/0! | R7: =R5/Q5-1 -> #DIV/0! | T7: =T5/R5-1 -> #DIV/0! | U7: =U5/T5-1 -> #DIV/0! | V7: =V5/U5-1 -> #DIV/0! | W7: =W5/V5-1 -> #DIV/0! | Y7: =Y5/W5-1 -> #DIV/0! | Z7: =Z5/Y5-1 -> #DIV/0! | AA7: =AA5/Z5-1 -> #DIV/0! | AB7: =AB5/AA5-1 -> #DIV/0! | AD7: =AD5/AB5-1 -> #DIV/0! | AE7: =AE5/AD5-1 -> 0.10019935 | AF7: =AF5/AE5-1 -> 0.0455284 | AG7: =AG5/AF5-1 -> 0.11692771 | AI7: =AI5/AG5-1 -> 0.079562342 | AJ7: =AJ5/AI5-1 -> 0.069251947 | AK7: =AK5/AJ5-1 -> 0.069196837 | AL7: =AL5/AK5-1 -> 0.10710281 | AN7: =AN5/AL5-1 -> 0.074030239 | AO7: =AO5/AN5-1 -> 0.096064688 | AP7: =AP5/AO5-1 -> 0.078170924 | AQ7: =AQ5/AP5-1 -> 0.08421822 | AS7: =AS5/AQ5-1 -> 0.088330324 | AT7: =AT5/AS5-1 -> 0.15207424 | AU7: =AU5/AT5-1 -> 0.13278211 | AV7: =AV5/AU5-1 -> 0.11891974 | AX7: =AX5/AV5-1 -> 0.10170277 | AY7: =AY5/AX5-1 -> 0.090329362 | AZ7: =AZ5/AY5-1 -> 0.072682737 | BA7: =BA5/AZ5-1 -> 0.067035206 | BC7: =BC5/BA5-1 -> 0.0092995465 | BD7: =BD5/BC5-1 -> 0.063140864 | BE7: =BE5/BD5-1 -> 0.031165213 | BF7: =BF5/BE5-1 -> 0.031442741 | BH7: =BH5/BF5-1 -> -0.0067891194 | BI7: =BI5/BH5-1 -> 0.047019663 | BJ7: =BJ5/BI5-1 -> 0.019398925 | BK7: =BK5/BJ5-1 -> 0.019535372 | BM7: =BM5/BK5-1 -> -0.0060358037 | BN7: =BN5/BM5-1 -> 0.037431144 | BO7: =BO5/BN5-1 -> 0.02415364 | BP7: =BP5/BO5-1 -> 0.031406315 | BR7: =BR5/BP5-1 -> -0.015261947 | BS7: =BS5/BR5-1 -> 0.051173811 | BT7: =BT5/BS5-1 -> 0.021124749 | BU7: =BU5/BT5-1 -> 0.011638879 | BW7: =BW5/BU5-1 -> -0.023826488 | BX7: =BX5/BW5-1 -> 0.051173811 | BY7: =BY5/BX5-1 -> 0.021124749 | BZ7: =BZ5/BY5-1 -> 0.011638879
C8: % of total revenues | D8: =D5/D13 -> #DIV/0! | E8: =E5/E13 -> #DIV/0! | F8: =F5/F13 -> #DIV/0! | G8: =G5/G13 -> #DIV/0! | H8: =H5/H13 -> #DIV/0! | O8: =O5/O13 -> #DIV/0! | P8: =P5/P13 -> #DIV/0! | Q8: =Q5/Q13 -> #DIV/0! | R8: =R5/R13 -> #DIV/0! | S8: =S5/S13 -> #DIV/0! | T8: =T5/T13 -> #DIV/0! | U8: =U5/U13 -> #DIV/0! | V8: =V5/V13 -> #DIV/0! | ... CA8: =CA5/CA13 -> 0.98234282
B9: Professional Services and Other | X9: =21354 -> 21354 | AC9: =32896 -> 32896 | AD9: 6651 | AE9: 7990 | AF9: 7684 | AG9: =11598 -> 11598 | AH9: =SUM(AD9:AG9) -> 33923 | AI9: 7610 | AJ9: 8583 | AK9: 8959 | AL9: =12160 -> 12160 | AM9: =SUM(AI9:AL9) -> 37312 | AN9: =12504 -> 12504 | AO9: 14801 | AP9: =11430 -> 11430 | AQ9: =16773 -> 16773 | AR9: =SUM(AN9:AQ9) -> 55508 | AS9: =16095 -> 16095 | AT9: =18566 -> 18566 | AU9: =16306 -> 16306 | AV9: 20683 | AW9: =SUM(AS9:AV9) -> 71650 | AX9: 17143 | AY9: 19086 | AZ9: 16890 | BA9: 16822 | BB9: =SUM(AX9:BA9) -> 69941 | BC9: 19441 | BD9: 16990 | BE9: 21408 | BF9: 15899 | BG9: =SUM(BC9:BF9) -> 73738 | BH9: 22081 | BI9: 18320 | BJ9: 18069 | BK9: 16704 | BL9: =SUM(BH9:BK9) -> 75174 | BM9: 18157 | BN9: 18661 | BO9: 20127 | BP9: 18485 | BQ9: =SUM(BM9:BP9) -> 75430 | BR9: 17452 | BS9: 16248 | BT9: 17392 | BU9: =BP9*(1+BU10) -> 16932.26 | BV9: =SUM(BR9:BU9) -> 68024.26 | BW9: =BR9*(1+BW10) -> 15357.76 | BX9: =BS9*(1+BX10) -> 14298.24 | BY9: =BT9*(1+BY10) -> 15304.96 | BZ9: =BU9*(1+BZ10) -> 14900.389 | CA9: =SUM(BW9:BZ9) -> 59861.349
C10: Y/Y Growth | O10: =O9/J9-1 -> #DIV/0! | P10: =P9/K9-1 -> #DIV/0! | Q10: =Q9/L9-1 -> #DIV/0! | R10: =R9/M9-1 -> #DIV/0! | V10: =V9/Q9-1 -> #DIV/0! | W10: =W9/R9-1 -> #DIV/0! | X10: =X9/S9-1 -> #DIV/0! | Y10: =Y9/T9-1 -> #DIV/0! | Z10: =Z9/U9-1 -> #DIV/0! | AA10: =AA9/V9-1 -> #DIV/0! | AB10: =AB9/W9-1 -> #DIV/0! | AC10: =AC9/X9-1 -> 0.54050763 | ... BT10: =BT9/BO9-1 -> -0.13588712 | BU10: -0.084 | BV10: =BV9/BQ9-1 -> -0.0981803 | BW10: -0.12 | BX10: -0.12 | BY10: -0.12 | BZ10: -0.12 | CA10: =CA9/BV9-1 -> -0.12
C11: Q/Q Growth | F11: =F9/E9-1 -> #DIV/0! | G11: =G9/F9-1 -> #DIV/0! | H11: =H9/G9-1 -> #DIV/0! | O11: =O9/M9-1 -> #DIV/0! | P11: =P9/O9-1 -> #DIV/0! | Q11: =Q9/P9-1 -> #DIV/0! | R11: =R9/Q9-1 -> #DIV/0! | T11: =T9/R9-1 -> #DIV/0! | U11: =U9/T9-1 -> #DIV/0! | V11: =V9/U9-1 -> #DIV/0! | W11: =W9/V9-1 -> #DIV/0! | Y11: =Y9/W9-1 -> #DIV/0! | Z11: =Z9/Y9-1 -> #DIV/0! | AA11: =AA9/Z9-1 -> #DIV/0! | AB11: =AB9/AA9-1 -> #DIV/0! | AD11: =AD9/AB9-1 -> #DIV/0! | AE11: =AE9/AD9-1 -> 0.20132311 | AF11: =AF9/AE9-1 -> -0.038297872 | AG11: =AG9/AF9-1 -> 0.50937012 | AI11: =AI9/AG9-1 -> -0.34385239 | AJ11: =AJ9/AI9-1 -> 0.12785808 | AK11: =AK9/AJ9-1 -> 0.043807527 | AL11: =AL9/AK9-1 -> 0.35729434 | AN11: =AN9/AL9-1 -> 0.028289474 | AO11: =AO9/AN9-1 -> 0.18370122 | AP11: =AP9/AO9-1 -> -0.22775488 | AQ11: =AQ9/AP9-1 -> 0.46745407 | AS11: =AS9/AQ9-1 -> -0.040422107 | AT11: =AT9/AS9-1 -> 0.15352594 | AU11: =AU9/AT9-1 -> -0.12172789 | AV11: =AV9/AU9-1 -> 0.2684288 | AX11: =AX9/AV9-1 -> -0.17115505 | AY11: =AY9/AX9-1 -> 0.11334072 | AZ11: =AZ9/AY9-1 -> -0.11505816 | BA11: =BA9/AZ9-1 -> -0.0040260509 | BC11: =BC9/BA9-1 -> 0.15568898 | BD11: =BD9/BC9-1 -> -0.12607376 | BE11: =BE9/BD9-1 -> 0.26003531 | BF11: =BF9/BE9-1 -> -0.25733371 | BH11: =BH9/BF9-1 -> 0.38882949 | BI11: =BI9/BH9-1 -> -0.17032743 | BJ11: =BJ9/BI9-1 -> -0.013700873 | BK11: =BK9/BJ9-1 -> -0.075543749 | BM11: =BM9/BK9-1 -> 0.086985153 | BN11: =BN9/BM9-1 -> 0.02775789 | BO11: =BO9/BN9-1 -> 0.078559563 | BP11: =BP9/BO9-1 -> -0.081581955 | BR11: =BR9/BP9-1 -> -0.055883148 | BS11: =BS9/BR9-1 -> -0.068989228 | BT11: =BT9/BS9-1 -> 0.070408666 | BU11: =BU9/BT9-1 -> -0.026433993 | BW11: =BW9/BU9-1 -> -0.092988178 | BX11: =BX9/BW9-1 -> -0.068989228 | BY11: =BY9/BX9-1 -> 0.070408666 | BZ11: =BZ9/BY9-1 -> -0.026433993
C12: % of total revenues | D12: =D9/D13 -> #DIV/0! | E12: =E9/E13 -> #DIV/0! | F12: =F9/F13 -> #DIV/0! | G12: =G9/G13 -> #DIV/0! | H12: =H9/H13 -> #DIV/0! | O12: =O9/O13 -> #DIV/0! | P12: =P9/P13 -> #DIV/0! | Q12: =Q9/Q13 -> #DIV/0! | R12: =R9/R13 -> #DIV/0! | S12: =S9/S13 -> #DIV/0! | T12: =T9/T13 -> #DIV/0! | U12: =U9/U13 -> #DIV/0! | V12: =V9/V13 -> #DIV/0! | ... CA12: =CA9/CA13 -> 0.017657177
B13: Total Revenues | D13: =D5+D9 -> 0 | E13: =E5+E9 -> 0 | F13: =F5+F9 -> 0 | G13: =G5+G9 -> 0 | H13: =H5+H9 -> 0 | O13: =O5+O9 -> 0 | P13: =P5+P9 -> 0 | Q13: =Q5+Q9 -> 0 | R13: =R5+R9 -> 0 | S13: =S5+S9 -> 0 | T13: =T5+T9 -> 0 | U13: =U5+U9 -> 0 | V13: =V5+V9 -> 0 | ... CA13: =CA5+CA9 -> 3390199.3
C14: Y/Y Growth | O14: =O13/J13-1 -> #DIV/0! | P14: =P13/K13-1 -> #DIV/0! | Q14: =Q13/L13-1 -> #DIV/0! | R14: =R13/M13-1 -> #DIV/0! | V14: =V13/Q13-1 -> #DIV/0! | W14: =W13/R13-1 -> #DIV/0! | X14: =X13/S13-1 -> #DIV/0! | Y14: =Y13/T13-1 -> #DIV/0! | Z14: =Z13/U13-1 -> #DIV/0! | AA14: =AA13/V13-1 -> #DIV/0! | AB14: =AB13/W13-1 -> #DIV/0! | AC14: =AC13/X13-1 -> 0.52290593 | ... CA14: =CA13/BV13-1 -> 0.05618538
C15: Q/Q Growth | F15: =F13/E13-1 -> #DIV/0! | G15: =G13/F13-1 -> #DIV/0! | H15: =H13/G13-1 -> #DIV/0! | O15: =O13/M13-1 -> #DIV/0! | P15: =P13/O13-1 -> #DIV/0! | Q15: =Q13/P13-1 -> #DIV/0! | R15: =R13/Q13-1 -> #DIV/0! | T15: =T13/R13-1 -> #DIV/0! | U15: =U13/T13-1 -> #DIV/0! | V15: =V13/U13-1 -> #DIV/0! | W15: =W13/V13-1 -> #DIV/0! | Y15: =Y13/W13-1 -> #DIV/0! | Z15: =Z13/Y13-1 -> #DIV/0! | AA15: =AA13/Z13-1 -> #DIV/0! | AB15: =AB13/AA13-1 -> #DIV/0! | AC15: =AC13-X13 -> 130978 | AD15: =AD13/AB13-1 -> #DIV/0! | AE15: =AE13/AD13-1 -> 0.10612522 | AF15: =AF13/AE13-1 -> 0.0401934 | AG15: =AG13/AF13-1 -> 0.14001945 | AI15: =AI13/AG13-1 -> 0.046576299 | AJ15: =AJ13/AI13-1 -> 0.072114397 | AK15: =AK13/AJ13-1 -> 0.067892292 | AL15: =AL13/AK13-1 -> 0.11966813 | AN15: =AN13/AL13-1 -> 0.071245469 | AO15: =AO13/AN13-1 -> 0.10118619 | AP15: =AP13/AO13-1 -> 0.058952855 | AQ15: =AQ13/AP13-1 -> 0.10177474 | AS15: =AS13/AQ13-1 -> 0.080474363 | AT15: =AT13/AS13-1 -> 0.15215291 | AU15: =AU13/AT13-1 -> 0.11897408 | AV15: =AV13/AU13-1 -> 0.12528628 | AX15: =AX13/AV13-1 -> 0.088605656 | AY15: =AY13/AX13-1 -> 0.091170338 | AZ15: =AZ13/AY13-1 -> 0.065682122 | BA15: =BA13/AZ13-1 -> 0.064834828 | BC15: =BC13/BA13-1 -> 0.013539292 | BD15: =BD13/BC13-1 -> 0.056892229 | BE15: =BE13/BD13-1 -> 0.037414977 | BF15: =BF13/BE13-1 -> 0.021864925 | BH15: =BH13/BF13-1 -> 0.0027472194 | BI15: =BI13/BH13-1 -> 0.039763346 | BJ15: =BJ13/BI13-1 -> 0.018517145 | BK15: =BK13/BJ13-1 -> 0.017082583 | BM15: =BM13/BK13-1 -> -0.0038546518 | BN15: =BN13/BM13-1 -> 0.037183642 | BO15: =BO13/BN13-1 -> 0.025533031 | BP15: =BP13/BO13-1 -> 0.028393524 | BR15: =BR13/BP13-1 -> -0.016229266 | BS15: =BS13/BR13-1 -> 0.048427691 | BT15: =BT13/BS13-1 -> 0.022124911 | BU15: =BU13/BT13-1 -> 0.010829734 | BW15: =BW13/BU13-1 -> -0.025242163 | BX15: =BX13/BW13-1 -> 0.048885132 | BY15: =BY13/BX13-1 -> 0.021957943 | BZ15: =BZ13/BY13-1 -> 0.010964703
B17: Cost of Revenue | AN17: =+((AN9+AO9-AN20-AO20)/(AN9+AO9)) -> -0.15663798
C18: Subscription Revenue | X18: =48656-1074-1965 -> 45617 | AC18: =73363-1190-6940 -> 65233 | AD18: =19293-238-1697 -> 17358 | AE18: =20040-231-1691 -> 18118 | AF18: =22335-228-1691 -> 20416 | AG18: =22166-214-1714 -> 20238 | AH18: =SUM(AD18:AG18) -> 76130 | AI18: =32438-9955-1668 -> 20815 | AJ18: =23057-1588-1003 -> 20466 | AK18: =28709-2398-1632 -> 24679 | AL18: =33560-2241-1778-830 -> 28711 | AM18: =SUM(AI18:AL18) -> 94671 | AN18: =33119-2282-1627-221 -> 28989 | AO18: =39472-3115-1381-211 -> 34765 | AP18: =43178-3534-1348-337 -> 37959 | AQ18: =48162-3951-1348-285 -> 42578 | AR18: =SUM(AN18:AQ18) -> 144291 | AS18: =52010-3864-1348-535 -> 46263 | AT18: =64730-5014-3132-926 -> 55658 | AU18: =69905-5777-3376-722 -> 60030 | AV18: =73347-6138-3196-1454+775 -> 63334 | AW18: =SUM(AS18:AV18) -> 225285 | AX18: =78071-6018-3171-1442 -> 67440 | AY18: =84455-7539-3328-971 -> 72617 | AZ18: =84579-8095-2766-873 -> 72845 | BA18: =96556-9500-2403-417 -> 84236 | BB18: =SUM(AX18:BA18) -> 297138 | BC18: =105159-10613-2403-508 -> 91635 | BD18: =107931-12994-2403-332-194 -> 92008 | BE18: =102524-11665-2425-310-127 -> 87997 | BF18: =110463-11644-2382-243-126 -> 96068 | BG18: =SUM(BC18:BF18) -> 367708 | BH18: =108942-11357-2403-466-299 -> 94417 | BI18: =116185-13081-2314-465-206 -> 100119 | BJ18: =114227-13705-2070-301 -> 98151 | BK18: =120551-13517-2070-232 -> 104732 | BL18: =SUM(BH18:BK18) -> 397419 | BM18: =126602-14181-2070-792 -> 109559 | BN18: =132372-15593-3067-595 -> 113117 | BO18: =134587-14862-3566-574 -> 115585 | BP18: =138884-13712-3564-921 -> 120687 | BQ18: =SUM(BM18:BP18) -> 458948 | BR18: =137343-12996-3565-1445 -> 119337 | BS18: =144097-14425-1220-1562 -> 126890 | BT18: =150372-15018-889-1495 -> 132970 | BU18: =BU5*(1-BU19) -> 140988.76 | BV18: =SUM(BR18:BU18) -> 520185.76 | BW18: =BW5*(1-BW19) -> 134465.6 | BX18: =BX5*(1-BX19) -> 139683.82 | BY18: =BY5*(1-BY19) -> 140087.55 | BZ18: =BZ5*(1-BZ19) -> 140000.22 | CA18: =SUM(BW18:BZ18) -> 554237.19
C19: Gross Margins | D19: =((D5-D18)/(D5)) -> #DIV/0! | E19: =((E5-E18)/(E5)) -> #DIV/0! | F19: =((F5-F18)/(F5)) -> #DIV/0! | G19: =((G5-G18)/(G5)) -> #DIV/0! | H19: =((H5-H18)/(H5)) -> #DIV/0! | O19: =((O5-O18)/(O5)) -> #DIV/0! | P19: =((P5-P18)/(P5)) -> #DIV/0! | Q19: =((Q5-Q18)/(Q5)) -> #DIV/0! | R19: =((R5-R18)/(R5)) -> #DIV/0! | S19: =((S5-S18)/(S5)) -> #DIV/0! | T19: =((T5-T18)/(T5)) -> #DIV/0! | U19: =((U5-U18)/(U5)) -> #DIV/0! | V19: =((V5-V18)/(V5)) -> #DIV/0! | ... BT19: =((BT5-BT18)/(BT5)) -> 0.8339863 | BU19: 0.826 | BV19: =((BV5-BV18)/(BV5)) -> 0.83443215 | BW19: 0.83 | BX19: 0.832 | BY19: 0.835 | BZ19: 0.837 | CA19: =((CA5-CA18)/(CA5)) -> 0.83357929
C20: Professional Services and Other | X20: =25199-1297 -> 23902 | AC20: =29114-1021 -> 28093 | AD20: =7831-235 -> 7596 | AE20: =8418-254 -> 8164 | AF20: =8881-253 -> 8628 | AG20: =9309-234 -> 9075 | AH20: =SUM(AD20:AG20) -> 33463 | AI20: =25856-16045 -> 9811 | AJ20: =13304-2822 -> 10482 | AK20: =16364-3578-108 -> 12678 | AL20: =19133-3413-1119 -> 14601 | AM20: =SUM(AI20:AL20) -> 47572 | AN20: =18900-3440-431 -> 15029 | AO20: =21704-4821-330 -> 16553 | AP20: =18786-3616-378 -> 14792 | AQ20: =19913-3826-383 -> 15704 | AR20: =SUM(AN20:AQ20) -> 62078 | AS20: =22022-4125-501 -> 17396 | AT20: =25885-5225-812 -> 19848 | AU20: =27926-6005-954 -> 20967 | AV20: =28233-6510-775 -> 20948 | AW20: =SUM(AS20:AV20) -> 79159 | AX20: =27171-5535-1332 -> 20304 | AY20: =29325-6446-1150 -> 21729 | AZ20: =31396-7270-927 -> 23199 | BA20: =34898-8096-412 -> 26390 | BB20: =SUM(AX20:BA20) -> 91622 | BC20: =27257-5082-283 -> 21892 | BD20: =28773-6478-198-71 -> 22026 | BE20: =27018-6767-161-286 -> 19804 | BF20: =26963-7431-149-286 -> 19097 | BG20: =SUM(BC20:BF20) -> 82819 | BH20: =27545-6730-209-130 -> 20476 | BI20: =29397-7286-248-86 -> 21777 | BJ20: =28418-7343-236 -> 20839 | BK20: =27356-6977-105 -> 20274 | BL20: =SUM(BH20:BK20) -> 83366 | BM20: =22844-4702-231 -> 17911 | BN20: =23093-4998-221 -> 17874 | BO20: =21950-4765-320 -> 16865 | BP20: =21327-4174-255 -> 16898 | BQ20: =SUM(BM20:BP20) -> 69548 | BR20: =19926-3908-428 -> 15590 | BS20: =21366-4167-355 -> 16844 | BT20: =20174-3992-291 -> 15891 | BU20: =BU9*(1-BU21) -> 16085.647 | BV20: =SUM(BR20:BU20) -> 64410.647 | BW20: =BW9*(1-BW21) -> 15050.605 | BX20: =BX9*(1-BX21) -> 14012.275 | BY20: =BY9*(1-BY21) -> 14845.811 | BZ20: =BZ9*(1-BZ21) -> 14602.381 | CA20: =SUM(BW20:BZ20) -> 58511.072
C21: Gross Margins | D21: =(D9-D20)/D9 -> #DIV/0! | E21: =(E9-E20)/E9 -> #DIV/0! | F21: =(F9-F20)/F9 -> #DIV/0! | G21: =(G9-G20)/G9 -> #DIV/0! | H21: =(H9-H20)/H9 -> #DIV/0! | O21: =(O9-O20)/O9 -> #DIV/0! | P21: =(P9-P20)/P9 -> #DIV/0! | Q21: =(Q9-Q20)/Q9 -> #DIV/0! | R21: =(R9-R20)/R9 -> #DIV/0! | S21: =(S9-S20)/S9 -> #DIV/0! | T21: =(T9-T20)/T9 -> #DIV/0! | U21: =(U9-U20)/U9 -> #DIV/0! | V21: =(V9-V20)/V9 -> #DIV/0! | ... BT21: =(BT9-BT20)/BT9 -> 0.086304048 | BU21: 0.05 | BV21: =(BV9-BV20)/BV9 -> 0.053122415 | BW21: 0.02 | BX21: 0.02 | BY21: 0.03 | BZ21: 0.02 | CA21: =(CA9-CA20)/CA9 -> 0.022556735
B22: Total Cost of Revenues | E22: =E20+E18 -> 0 | F22: =F20+F18 -> 0 | G22: =G20+G18 -> 0 | H22: =H20+H18 -> 0 | O22: =O18+O20 -> 0 | P22: =P18+P20 -> 0 | Q22: =Q18+Q20 -> 0 | R22: =R18+R20 -> 0 | S22: =S20+S18 -> 0 | T22: =T18+T20 -> 0 | U22: =U18+U20 -> 0 | V22: =V18+V20 -> 0 | W22: =W18+W20 -> 0 | X22: =X18+X20 -> 69519 | Y22: =Y18+Y20 -> 0 | Z22: =Z18+Z20 -> 0 | AA22: =AA18+AA20 -> 0 | ... AH22: =AH18+AH20 -> 109593 | AI22: =AI20+AI18 -> 30626 | AJ22: =AJ20+AJ18 -> 30948 | AK22: =AK20+AK18 -> 37357 | AL22: =AL20+AL18 -> 43312 | AM22: =SUM(AI22:AL22) -> 142243 | AN22: =AN20+AN18 -> 44018 | AO22: =AO20+AO18 -> 51318 | AP22: =AP20+AP18 -> 52751 | AQ22: =AQ20+AQ18 -> 58282 | AR22: =SUM(AN22:AQ22) -> 206369 | AS22: =AS20+AS18 -> 63659 | AT22: =AT20+AT18 -> 75506 | AU22: =AU20+AU18 -> 80997 | AV22: =AV20+AV18 -> 84282 | AW22: =SUM(AS22:AV22) -> 304444 | AX22: =AX20+AX18 -> 87744 | AY22: =AY20+AY18 -> 94346 | AZ22: =AZ20+AZ18 -> 96044 | BA22: =BA20+BA18 -> 110626 | BB22: =SUM(AX22:BA22) -> 388760 | BC22: =BC20+BC18 -> 113527 | BD22: =BD20+BD18 -> 114034 | BE22: =BE20+BE18 -> 107801 | BF22: =BF20+BF18 -> 115165 | BG22: =SUM(BC22:BF22) -> 450527 | BH22: =BH20+BH18 -> 114893 | BI22: =BI20+BI18 -> 121896 | BJ22: =BJ20+BJ18 -> 118990 | BK22: =BK20+BK18 -> 125006 | BL22: =SUM(BH22:BK22) -> 480785 | BM22: =BM20+BM18 -> 127470 | BN22: =BN20+BN18 -> 130991 | BO22: =BO20+BO18 -> 132450 | BP22: =BP20+BP18 -> 137585 | BQ22: =SUM(BM22:BP22) -> 528496 | BR22: =BR20+BR18 -> 134927 | BS22: =BS20+BS18 -> 143734 | BT22: =BT20+BT18 -> 148861 | BU22: =BU20+BU18 -> 157074.41 | BV22: =SUM(BR22:BU22) -> 584596.41 | BW22: =BW20+BW18 -> 149516.21 | BX22: =BX20+BX18 -> 153696.09 | BY22: =BY20+BY18 -> 154933.37 | BZ22: =BZ20+BZ18 -> 154602.6 | CA22: =SUM(BW22:BZ22) -> 612748.26
B23: Gross Profit | D23: =D13-D22 -> 0 | E23: =E13-E22 -> 0 | F23: =F13-F22 -> 0 | G23: =G13-G22 -> 0 | H23: =H13-H22 -> 0 | O23: =O13-O22 -> 0 | P23: =P13-P22 -> 0 | Q23: =Q13-Q22 -> 0 | R23: =R13-R22 -> 0 | S23: =S13-S22 -> 0 | T23: =T13-T22 -> 0 | U23: =U13-U22 -> 0 | V23: =V13-V22 -> 0 | ... CA23: =CA13-CA22 -> 2777451
C24: Gross Margin | D24: =D23/D13 -> #DIV/0! | E24: =E23/E13 -> #DIV/0! | F24: =F23/F13 -> #DIV/0! | G24: =G23/G13 -> #DIV/0! | H24: =H23/H13 -> #DIV/0! | O24: =O23/O13 -> #DIV/0! | P24: =P23/P13 -> #DIV/0! | Q24: =Q23/Q13 -> #DIV/0! | R24: =R23/R13 -> #DIV/0! | S24: =S23/S13 -> #DIV/0! | T24: =T23/T13 -> #DIV/0! | U24: =U23/U13 -> #DIV/0! | V24: =V23/V13 -> #DIV/0! | ... CA24: =CA23/CA13 -> 0.81925893
B26: Operating Expenses
C27: Sales and Marketing | X27: =170006-10617-1965 -> 157424 | AC27: =240787-11187-3385 -> 226215 | AD27: =64691-2705-840 -> 61146 | AE27: =68943-2883-665 -> 65395 | AF27: =69666-1959-1015 -> 66692 | AG27: =74630-1839-730 -> 72061 | AH27: =SUM(AD27:AG27) -> 265294 | AI27: =191085-112481-765 -> 77839 | AJ27: =103779-16791-765 -> 86223 | AK27: =117051-22338-2257-68 -> 92388 | AL27: =127691-20505-3234-8051 -> 95901 | AM27: =SUM(AI27:AL27) -> 352351 | AN27: =129936-18102-3106-2351 -> 106377 | AO27: =150886-25942-3039-1577 -> 120328 | AP27: =149231-24649-2957-1682 -> 119943 | AQ27: =161326-26170-2911-1413 -> 130832 | AR27: =SUM(AN27:AQ27) -> 477480 | AS27: =171793-24665-2911-2909 -> 141308 | AT27: =194992-32305-4284-186-3958 -> 154259 | AU27: =209944-36881-3981-4125 -> 164957 | AV27: 178118 | AW27: =SUM(AS27:AV27) -> 638642 | AX27: =239119-38135-3358-6778 -> 190848 | AY27: =262372-46921-3333-5706 -> 206412 | AZ27: =275619-49663-3205-5184 -> 217567 | BA27: =299417-52040-3205-1960 -> 242212 | BB27: =SUM(AX27:BA27) -> 857039 | BC27: =300697-47431-3205-2290 -> 247771 | BD27: =323582-61218-2630-1683-886 -> 257165 | BE27: =313783-57925-2688-1277-1467 -> 250426 | BF27: =304649-55760-2571-910-1467 -> 243941 | BG27: =SUM(BC27:BF27) -> 999303 | BH27: =280605-45326-2629-1670-1356 -> 229624 | BI27: =294838-51563-2630-1400-815 -> 238430 | BJ27: =292473-53715-2629-875 -> 235254 | BK27: =300221-53251-2631-1104 -> 243235 | BL27: =SUM(BH27:BK27) -> 946543 | BM27: =281644-46271-2629-2138 -> 230606 | BN27: 223978 | BO27: 236278 | BP27: =301288-48213-3354-2242 -> 247479 | BQ27: =SUM(BM27:BP27) -> 938341 | BR27: 243034 | BS27: =305450-49081-2962-3354 -> 250053 | BT27: =296516-48018-2356-3378 -> 242764 | BU27: =BU13*BU28 -> 259744.73 | BV27: =SUM(BR27:BU27) -> 995595.73 | BW27: =BW13*BW28 -> 253994.54 | BX27: =BX13*BX28 -> 266411.1 | BY27: =BY13*BY28 -> 267939.34 | BZ27: =BZ13*BZ28 -> 270877.21 | CA27: =SUM(BW27:BZ27) -> 1059222.2
C28: % of Revenue | D28: =D27/D13 -> #DIV/0! | E28: =E27/E13 -> #DIV/0! | F28: =F27/F13 -> #DIV/0! | G28: =G27/G13 -> #DIV/0! | H28: =H27/H13 -> #DIV/0! | O28: =O27/O13 -> #DIV/0! | P28: =P27/P13 -> #DIV/0! | Q28: =Q27/Q13 -> #DIV/0! | R28: =R27/R13 -> #DIV/0! | S28: =S27/S13 -> #DIV/0! | T28: =T27/T13 -> #DIV/0! | U28: =U27/U13 -> #DIV/0! | V28: =V27/V13 -> #DIV/0! | ... BT28: =BT27/BT13 -> 0.29665058 | BU28: 0.314 | BV28: =BV27/BV13 -> 0.31016868 | BW28: 0.315 | BX28: 0.315 | BY28: 0.31 | BZ28: 0.31 | CA28: =CA27/CA13 -> 0.31243655
C29: Research and Development | X29: =62255-8221 -> 54034 | AC29: =89652-10161 -> 79491 | AD29: =22708-1391 -> 21317 | AE29: =23767-1288 -> 22479 | AF29: =22522-1042 -> 21480 | AG29: =23431-1175 -> 22256 | AH29: =SUM(AD29:AG29) -> 87532 | AI29: =70870-47268 -> 23602 | AJ29: =33773-7359 -> 26414 | AK29: =38404-9919-302 -> 28183 | AL29: =42921-9562-2246 -> 31113 | AM29: =SUM(AI29:AL29) -> 109312 | AN29: =37183-7317-1150 -> 28716 | AO29: =47517-11963-1026 -> 34528 | AP29: =48758-11679-712 -> 36367 | AQ29: =52094-12252-636 -> 39206 | AR29: =SUM(AN29:AQ29) -> 138817 | AS29: =54234-11885-1546 -> 40803 | AT29: =63791-14781-2019 -> 46991 | AU29: =73362-18896-1752 -> 52714 | AV29: 57795 | AW29: =SUM(AS29:AV29) -> 198303 | AX29: =85416-20462-4176 -> 60778 | AY29: =94651-26275-2752 -> 65624 | AZ29: =102603-30074-2316 -> 70213 | BA29: =110692-31712-1097 -> 77883 | BB29: =SUM(AX29:BA29) -> 274498 | BC29: =112227-32205-1533 -> 78489 | BD29: =126532-40978-868-385 -> 84301 | BE29: =115934-35506-608-434 -> 79386 | BF29: =125891-41278-460-433 -> 83720 | BG29: =SUM(BC29:BF29) -> 325896 | BH29: =115364-35997-1408-492 -> 77467 | BI29: =135960-45151-1387-381 -> 89041 | BJ29: =136640-48310-876 -> 87454 | BK29: =151524-54753-605 -> 96166 | BL29: =SUM(BH29:BK29) -> 350128 | BM29: =134320-44202-2565 -> 87553 | BN29: 92387 | BO29: 96644 | BP29: =155463-53422-1421 -> 100620 | BQ29: =SUM(BM29:BP29) -> 377204 | BR29: 99935 | BS29: =169630-61865-2600 -> 105165 | BT29: =167626-60806-1918 -> 104902 | BU29: =BU13*BU30 -> 107537.63 | BV29: =SUM(BR29:BU29) -> 417539.63 | BW29: =BW13*BW30 -> 101597.82 | BX29: =BX13*BX30 -> 105718.69 | BY29: =BY13*BY30 -> 108040.06 | BZ29: =BZ13*BZ30 -> 110972.28 | CA29: =SUM(BW29:BZ29) -> 426328.84
C30: % of Revenue | D30: =D29/D13 -> #DIV/0! | E30: =E29/E13 -> #DIV/0! | F30: =F29/F13 -> #DIV/0! | G30: =G29/G13 -> #DIV/0! | H30: =H29/H13 -> #DIV/0! | O30: =O29/O13 -> #DIV/0! | P30: =P29/P13 -> #DIV/0! | Q30: =Q29/Q13 -> #DIV/0! | R30: =R29/R13 -> #DIV/0! | S30: =S29/S13 -> #DIV/0! | T30: =T29/T13 -> #DIV/0! | U30: =U29/U13 -> #DIV/0! | V30: =V29/V13 -> #DIV/0! | ... BT30: =BT29/BT13 -> 0.12818721 | BU30: 0.13 | BV30: =BV29/BV13 -> 0.13008063 | BW30: 0.126 | BX30: 0.125 | BY30: 0.125 | BZ30: 0.127 | CA30: =CA29/CA13 -> 0.12575333
C31: General and Administrative | X31: =63669-11455 -> 52214 | AC31: =64360-11884 -> 52476 | AD31: =18239-3837 -> 14402 | AE31: =18156-3856 -> 14300 | AF31: =19528-3113 -> 16415 | AG31: =25603-2772 -> 22831 | AH31: =SUM(AD31:AG31) -> 67948 | AI31: =103117-84045 -> 19072 | AJ31: =30851-11605 -> 19246 | AK31: =36274-13515-1290 -> 21469 | AL31: =39055-13550-3411 -> 22094 | AM31: =SUM(AI31:AL31) -> 81881 | AN31: =37261-11130-1602 -> 24529 | AO31: =40755-9951-720 -> 30084 | AP31: =33546-9258-735 -> 23553 | AQ31: =35753-9406-540 -> 25807 | AR31: =SUM(AN31:AQ31) -> 103973 | AS31: =38811-9012-1057-694 -> 28048 | AT31: =51446-11442-6746-1544 -> 31714 | AU31: =50256-13361-336-1406 -> 35153 | AV31: 36099 | AW31: =SUM(AS31:AV31) -> 131014 | AX31: =50038-10986-2555 -> 36497 | AY31: =63652-12778-1006-221-3892 -> 45755 | AZ31: =54624-14338-804 -> 39482 | BA31: =64443-16659-334-1207 -> 46243 | BB31: =SUM(AX31:BA31) -> 167977 | BC31: =62578-15392-485 -> 46701 | BD31: =76456-19539-304-1804-292 -> 54517 | BE31: =85553-23384-180-830-363 -> 60796 | BF31: =91641-29810-182-364 -> 61285 | BG31: =SUM(BC31:BF31) -> 223299 | BH31: =104811-40342-431-399 -> 63639 | BI31: =103884-34592-546-296 -> 68450 | BJ31: =108215-36337-564 -> 71314 | BK31: =102711-32502-554 -> 69655 | BL31: =SUM(BH31:BK31) -> 273058 | BM31: =92478-28520-678-1358 -> 61922 | BN31: 51515 | BO31: 66372 | BP31: =98821-30426-1504 -> 66891 | BQ31: =SUM(BM31:BP31) -> 246700 | BR31: 60729 | BS31: =94866-31000-911 -> 62955 | BT31: =98307-32808-728 -> 64771 | BU31: =BU13*BU32 -> 67004.214 | BV31: =SUM(BR31:BU31) -> 255459.21 | BW31: =BW13*BW32 -> 70957.205 | BX31: =BX13*BX32 -> 71042.96 | BY31: =BY13*BY32 -> 73467.237 | BZ31: =BZ13*BZ32 -> 74272.784 | CA31: =SUM(BW31:BZ31) -> 289740.19
C32: % of Revenue | D32: =D31/D13 -> #DIV/0! | E32: =E31/E13 -> #DIV/0! | F32: =F31/F13 -> #DIV/0! | G32: =G31/G13 -> #DIV/0! | H32: =H31/H13 -> #DIV/0! | O32: =O31/O13 -> #DIV/0! | P32: =P31/P13 -> #DIV/0! | Q32: =Q31/Q13 -> #DIV/0! | R32: =R31/R13 -> #DIV/0! | S32: =S31/S13 -> #DIV/0! | T32: =T31/T13 -> #DIV/0! | U32: =U31/U13 -> #DIV/0! | V32: =V31/V13 -> #DIV/0! | ... BT32: =BT31/BT13 -> 0.079148286 | BU32: 0.081 | BV32: =BV31/BV13 -> 0.079585966 | BW32: 0.088 | BX32: 0.084 | BY32: 0.085 | BZ32: 0.085 | CA32: =CA31/CA13 -> 0.085464057
B33: Total Operating Expense | D33: =D27+D29+D31 -> 0 | E33: =E27+E29+E31 -> 0 | F33: =F27+F29+F31 -> 0 | G33: =G27+G29+G31 -> 0 | H33: =H27+H29+H31 -> 0 | O33: =O27+O29+O31 -> 0 | P33: =P27+P29+P31 -> 0 | Q33: =Q27+Q29+Q31 -> 0 | R33: =R27+R29+R31 -> 0 | S33: =S27+S29+S31 -> 0 | T33: =T27+T29+T31 -> 0 | U33: =U27+U29+U31 -> 0 | V33: =V27+V29+V31 -> 0 | ... CA33: =CA27+CA29+CA31 -> 1775291.2
B35: Non-GAAP Operating Income | D35: =D23-D33 -> 0 | E35: =E23-E33 -> 0 | F35: =F23-F33 -> 0 | G35: =G23-G33 -> 0 | H35: =H23-H33 -> 0 | O35: =O23-O33 -> 0 | P35: =P23-P33 -> 0 | Q35: =Q23-Q33 -> 0 | R35: =R23-R33 -> 0 | S35: =S23-S33 -> 0 | T35: =T23-T33 -> 0 | U35: =U23-U33 -> 0 | V35: =V23-V33 -> 0 | ... AG35: =AG23-AG33 -> 2413 | AH35: =SUM(AD35:AG35) -> -11863 | AI35: =AI23-AI33 -> 4669 | AJ35: =AJ23-AJ33 -> 4213 | AK35: =AK23-AK33 -> -1012 | AL35: =AL23-AL33 -> 7312 | AM35: =AM23-AM33 -> 15182 | AN35: =AN23-AN33 -> 10322 | AO35: =AO23-AO33 -> -646 | AP35: =AP23-AP33 -> 16888 | ... CA35: =CA23-CA33 -> 1002159.8
C36: Non-GAAP Operating Margin | D36: =D35/D13 -> #DIV/0! | E36: =E35/E13 -> #DIV/0! | F36: =F35/F13 -> #DIV/0! | G36: =G35/G13 -> #DIV/0! | H36: =H35/H13 -> #DIV/0! | O36: =O35/O13 -> #DIV/0! | P36: =P35/P13 -> #DIV/0! | Q36: =Q35/Q13 -> #DIV/0! | R36: =R35/R13 -> #DIV/0! | S36: =S35/S13 -> #DIV/0! | T36: =T35/T13 -> #DIV/0! | U36: =U35/U13 -> #DIV/0! | V36: =V35/V13 -> #DIV/0! | ... CA36: =CA35/CA13 -> 0.29560499
B38: GAAP Adjustments
C39: Amortization of purchased intangibles | S39: =SUM(O39:R39) -> 0 | X39: =4030+1965 -> 5995 | AC39: =6940+3385 -> 10325 | AD39: 8406 | AE39: 2356 | AF39: 2706 | AG39: 2444 | AH39: =SUM(AD39:AG39) -> 15912 | AI39: 2433 | AJ39: 1768 | AK39: 3889 | AL39: 5012 | AM39: =SUM(AI39:AL39) -> 13102 | AN39: 4733 | AO39: 4420 | AP39: 4305 | AQ39: 4259 | AR39: =SUM(AN39:AQ39) -> 17717 | AS39: 4259 | AT39: 7416 | AU39: 7357 | AV39: 6586 | AW39: =SUM(AS39:AV39) -> 25618 | AX39: 6529 | AY39: 6661 | AZ39: 5971 | BA39: 5608 | BB39: =SUM(AX39:BA39) -> 24769 | BC39: 5608 | BD39: 5033 | BE39: 5113 | BF39: 4953 | BG39: =SUM(BC39:BF39) -> 20707 | BH39: 5032 | BI39: 4944 | BJ39: 4699 | BK39: 4701 | BL39: =SUM(BH39:BK39) -> 19376 | BM39: 4699 | BN39: 6180 | BO39: 6920 | BP39: 6918 | BQ39: =SUM(BM39:BP39) -> 24717 | BR39: 6919 | BS39: 4916 | BT39: 4873 | BU39: =BT39 -> 4873 | BV39: =SUM(BR39:BU39) -> 21581 | BW39: =BU39 -> 4873 | BX39: =BW39 -> 4873 | BY39: =BX39 -> 4873 | BZ39: =BY39 -> 4873 | CA39: =SUM(BW39:BZ39) -> 19492
C40: Stock based compensation | S40: =SUM(O40:R40) -> 0 | X40: =1074+1297+10617+8221+11455 -> 32664 | AC40: =1190+1021+11187+10161+11884 -> 35443 | AD40: 2537 | AE40: 8512 | AF40: 6595 | AG40: 6234 | AH40: =SUM(AD40:AG40) -> 23878 | AI40: 269794 | AJ40: 40165 | AK40: 51748 | AL40: 49271 | AM40: =SUM(AI40:AL40) -> 410978 | AN40: 42271 | AO40: 55792 | AP40: 52736 | AQ40: 55605 | AR40: =SUM(AN40:AQ40) -> 206404 | AS40: 53551 | AT40: 68767 | AU40: 80920 | AV40: =6138+6510+37190+20328+13473 -> 83639 | AW40: =SUM(AS40:AV40) -> 286877 | AX40: 81136 | AY40: 99959 | AZ40: =8095+7270+49663+30074+14338 -> 109440 | BA40: 118007 | BB40: =SUM(AX40:BA40) -> 408542 | BC40: 110723 | BD40: 141207 | BE40: 135247 | BF40: 145923 | BG40: =SUM(BC40:BF40) -> 533100 | BH40: 139752 | BI40: 151673 | BJ40: 159410 | BK40: 161000 | BL40: =SUM(BH40:BK40) -> 611835 | BM40: 137876 | BN40: 164448 | BO40: 153228 | BP40: 149947 | BQ40: =SUM(BM40:BP40) -> 605499 | BR40: 145596 | BS40: 160538 | BT40: 160642 | BU40: 150000 | BV40: =SUM(BR40:BU40) -> 616776 | BW40: 160000 | BX40: 160000 | BY40: 160000 | BZ40: 160000 | CA40: =SUM(BW40:BZ40) -> 640000
C41: Payroll tax on employee stock transactions | S41: =SUM(O41:R41) -> 0 | AC41: 0 | AH41: =SUM(AD41:AG41) -> 0 | AK41: 0 | AL41: 15657 | AM41: =SUM(AI41:AL41) -> 15657 | AN41: 5755 | AO41: 3864 | AP41: 3844 | AQ41: 3257 | AR41: =SUM(AN41:AQ41) -> 16720 | AS41: 6548 | AT41: 9259 | AU41: 8959 | AV41: 9276 | AW41: =SUM(AS41:AV41) -> 34042 | AX41: 16283 | AY41: 11585 | AZ41: 10104 | BA41: 4220 | BB41: =SUM(AX41:BA41) -> 42192 | BC41: 5099 | BD41: 3385 | BE41: 2536 | BF41: 1944 | BG41: =SUM(BC41:BF41) -> 12964 | BH41: 4184 | BI41: 4046 | BJ41: 2852 | BK41: 2600 | BL41: =SUM(BH41:BK41) -> 13682 | BM41: 6404 | BN41: 4772 | BO41: 4274 | BP41: 6343 | BQ41: =SUM(BM41:BP41) -> 21793 | BR41: 12259 | BS41: 8048 | BT41: 6182 | BU41: 6000 | BV41: =SUM(BR41:BU41) -> 32489 | BW41: 6000 | BX41: 6000 | BY41: 6000 | BZ41: 60000 | CA41: =SUM(BW41:BZ41) -> 78000
C42: Acquisition-related expense | S42: =SUM(O42:R42) -> 0 | AC42: 0 | AH42: =SUM(AD42:AG42) -> 0 | AK42: 1768 | AM42: =SUM(AI42:AL42) -> 1768 | AP42: 0 | AR42: =SUM(AN42:AQ42) -> 0 | AS42: 694 | AT42: 6932 | AU42: 336 | AW42: =SUM(AS42:AV42) -> 7962 | AY42: 221 | BB42: =SUM(AX42:BA42) -> 221 | BG42: =SUM(BC42:BF42) -> 0 | BL42: =SUM(BH42:BK42) -> 0 | BM42: 1358 | BN42: 3358 | BO42: -376 | BQ42: =SUM(BM42:BP42) -> 4340 | BV42: =SUM(BR42:BU42) -> 0 | CA42: =SUM(BW42:BZ42) -> 0
C43: Other | S43: =SUM(O43:R43) -> 0 | AC43: =SUM(Y43:AB43) -> 0 | AH43: =SUM(AD43:AG43) -> 0 | AM43: =SUM(AI43:AL43) -> 0 | AR43: =SUM(AN43:AQ43) -> 0 | AW43: =SUM(AS43:AV43) -> 0 | AY43: 3892 | BA43: 1207 | BB43: =SUM(AX43:BA43) -> 5099 | BD43: =1828+1804 -> 3632 | BE43: =28082+830+2677 -> 31589 | BF43: =253+2676 -> 2929 | BG43: =SUM(BC43:BF43) -> 38150 | BH43: =28772+2676 -> 31448 | BI43: =811+1784 -> 2595 | BJ43: =710 -> 710 | BK43: 88 | BL43: =SUM(BH43:BK43) -> 34841 | BM43: =29124 -> 29124 | BN43: 597 | BQ43: =SUM(BM43:BP43) -> 29721 | BV43: =SUM(BR43:BU43) -> 0 | CA43: =SUM(BW43:BZ43) -> 0
B44: Total GAAP and non-cash adjustments | D44: =SUM(D39:D43) -> 0 | E44: =SUM(E39:E43) -> 0 | F44: =SUM(F39:F43) -> 0 | G44: =SUM(G39:G43) -> 0 | H44: =SUM(H39:H43) -> 0 | O44: =SUM(O39:O43) -> 0 | P44: =SUM(P39:P43) -> 0 | Q44: =SUM(Q39:Q43) -> 0 | R44: =SUM(R39:R43) -> 0 | S44: =SUM(S39:S43) -> 0 | T44: =SUM(T39:T43) -> 0 | U44: =SUM(U39:U43) -> 0 | V44: =SUM(V39:V43) -> 0 | ... CA44: =SUM(CA39:CA43) -> 737492
B46: GAAP Operating Income | D46: =D35-D44 -> 0 | E46: =E35-E44 -> 0 | F46: =F35-F44 -> 0 | G46: =G35-G44 -> 0 | H46: =H35-H44 -> 0 | O46: =O35-O44 -> 0 | P46: =P35-P44 -> 0 | Q46: =Q35-Q44 -> 0 | R46: =R35-R44 -> 0 | S46: =S35-S44 -> 0 | T46: =T35-T44 -> 0 | U46: =U35-U44 -> 0 | V46: =V35-V44 -> 0 | ... CA46: =CA35-CA44 -> 264667.82
C47: GAAP Operating Margin | D47: =D46/D13 -> #DIV/0! | E47: =E46/E13 -> #DIV/0! | F47: =F46/F13 -> #DIV/0! | G47: =G46/G13 -> #DIV/0! | H47: =H46/H13 -> #DIV/0! | O47: =O46/O13 -> #DIV/0! | P47: =P46/P13 -> #DIV/0! | Q47: =Q46/Q13 -> #DIV/0! | R47: =R46/R13 -> #DIV/0! | S47: =S46/S13 -> #DIV/0! | T47: =T46/T13 -> #DIV/0! | U47: =U46/U13 -> #DIV/0! | V47: =V46/V13 -> #DIV/0! | ... CA47: =CA46/CA13 -> 0.078068513
...

Sheet BS
B2: =IS!B2 -> DocuSign, Inc (DOCU)
B4: Balance Sheet | D4: 2012 | E4: 1Q13 | F4: 2Q13 | G4: 3Q13 | H4: 4Q13 | I4: 2013 | J4: 1Q14 | K4: 2Q14 | L4: 3Q14 | M4: 4Q14 | N4: 2014 | O4: 1Q15 | P4: 2Q15 | Q4: 3Q15 | R4: 4Q15 | S4: 2015 | T4: 1Q16 | U4: 2Q16 | V4: 3Q16 | W4: 4Q16 | X4: 2016 | Y4: 1Q17 | Z4: 2Q17 | AA4: 3Q17 | AB4: 4Q17 | AC4: 2017 | AD4: 1Q18 | AE4: 2Q18 | AF4: 3Q18 | AG4: 4Q18 | AH4: 2018 | AI4: 1Q19 | AJ4: 2Q19 | AK4: 3Q19 | AL4: 4Q19 | AM4: 2019 | AN4: 1Q20 | AO4: 2Q20 | AP4: 3Q20 | AQ4: 4Q20 | AR4: 2020 | AS4: 1Q21 | AT4: 2Q21 | AU4: 3Q21 | AV4: 4Q21 | AW4: 2021 | AX4: 1Q22 | AY4: 2Q22 | AZ4: 3Q22 | BA4: 4Q22 | BB4: 2022 | BC4: 1Q23 | BD4: 2Q23 | BE4: 3Q23 | BF4: 4Q23 | BG4: 2023 | BH4: =IS!BH4 -> 1Q24 | BI4: =IS!BI4 -> 2Q24 | BJ4: =IS!BJ4 -> 3Q24 | BK4: =IS!BK4 -> 4Q24 | BL4: =IS!BL4 -> FY24 | BM4: =IS!BM4 -> 1Q25 | BN4: =IS!BN4 -> 2Q25 | BO4: =IS!BO4 -> 3Q25 | ... CA4: =IS!CA4 -> FY27E
B5: Assets: | BP5: 0
C6: Cash and cash equivalents | S6: =R6 -> 0 | X6: 228523 | AC6: 190556 | AG6: 256867 | AH6: =AG6 -> 256867 | AI6: 269429 | AJ6: 818795 | AK6: 1094133 | AL6: 517811 | AM6: =AL6 -> 517811 | AN6: 236476 | AO6: 224290 | AP6: 197697 | AQ6: 241203 | AR6: =AQ6 -> 241203 | AS6: 442237 | AT6: 404262 | AU6: 374984 | AV6: 566055 | AW6: =AV6 -> 566055 | AX6: 518972 | AY6: 518577 | AZ6: 503884 | BA6: 509059 | BB6: =BA6 -> 509059 | BC6: 638190 | BD6: 637186 | BE6: 632620 | BF6: 721895 | BG6: =BF6 -> 721895 | BH6: 940494 | BI6: 1017778 | BJ6: 1188578 | BK6: 797060 | BL6: =BK6 -> 797060 | BM6: 817388 | BN6: 619064 | BO6: 610870 | BP6: 648623 | BQ6: =BP6 -> 648623 | BR6: 657399 | BS6: 599986 | BT6: 583291 | BU6: =BT6+CF!BU70 -> 855072.33 | BV6: =BU6 -> 855072.33 | BW6: =BV6+CF!BW70 -> 1218625.6 | BX6: =BW6+CF!BX70 -> 1487879.3 | BY6: =BX6+CF!BY70 -> 1644676.1 | BZ6: =BY6+CF!BZ70 -> 1939958.5 | CA6: =BZ6 -> 1939958.5
C7: Investments—current | AG7: 0 | AH7: =AG7 -> 0 | AK7: 0 | AL7: 251203 | AM7: =AL7 -> 251203 | AN7: 515648 | AO7: 525963 | AP7: 456080 | AQ7: 414939 | AR7: =AQ7 -> 414939 | AS7: 315712 | AT7: 269777 | AU7: 223590 | AV7: 207450 | AW7: =AV7 -> 207450 | AX7: 261660 | AY7: 304292 | AZ7: 314574 | BA7: 293763 | BB7: =BA7 -> 293763 | BC7: 329425 | BD7: 357539 | BE7: 342730 | BF7: 309771 | BG7: =BF7 -> 309771 | BH7: 350763 | BI7: 426271 | BJ7: 401639 | BK7: 248402 | BL7: =BK7 -> 248402 | BM7: 269400 | BN7: 319289 | BO7: 331506 | BP7: 314924 | BQ7: =BP7 -> 314924 | BR7: 291293 | BS7: 244469 | BT7: 256580 | BU7: =BT7 -> 256580 | BV7: =BU7 -> 256580 | BW7: =BV7 -> 256580 | BX7: =BW7 -> 256580 | BY7: =BX7 -> 256580 | BZ7: =BY7 -> 256580 | CA7: =BZ7 -> 256580
C8: Accounts receivable | S8: =R8 -> 0 | X8: =W8 -> 0 | AG8: 123750 | AH8: =AG8 -> 123750 | AI8: 104128 | AJ8: 108365 | AK8: 130611 | AL8: 174548 | AM8: =AL8 -> 174548 | AN8: 117134 | AO8: 138652 | AP8: 159464 | AQ8: 237841 | AR8: =AQ8 -> 237841 | AS8: 220602 | AT8: 224502 | AU8: 261085 | AV8: 323570 | AW8: =AV8 -> 323570 | AX8: 250365 | AY8: 284730 | AZ8: 305599 | BA8: 440950 | BB8: =BA8 -> 440950 | BC8: 300872 | BD8: 339528 | BE8: 422612 | BF8: 516914 | BG8: =BF8 -> 516914 | BH8: 408632 | BI8: 414740 | BJ8: 360456 | BK8: 439299 | BL8: =BK8 -> 439299 | BM8: 306152 | BN8: 309885 | BO8: 300444 | BP8: 429582 | BQ8: =BP8 -> 429582 | BR8: 307597 | BS8: 356943 | BT8: 354978 | BU8: =BU54*IS!BU13 -> 488055.38 | BV8: =BU8 -> 488055.38 | BW8: =BW54*IS!BW13 -> 362849.35 | BX8: =BX54*IS!BX13 -> 380587.28 | BY8: =BY54*IS!BY13 -> 466733.04 | BZ8: =BZ54*IS!BZ13 -> 524278.47 | CA8: =BZ8 -> 524278.47
C9: Restricted cash | AG9: 569 | AH9: =AG9 -> 569 | AI9: 367 | AJ9: 367 | AK9: 367 | AL9: 367 | AM9: =AL9 -> 367 | AN9: 167 | AO9: 133 | AP9: 414 | AQ9: 280 | AR9: =AQ9 -> 280 | AS9: 280 | AT9: 280 | AU9: 281 | AV9: 0 | AW9: =AV9 -> 0 | AX9: =AW9 -> 0 | AY9: =AX9 -> 0 | AZ9: =AY9 -> 0 | BA9: =AZ9 -> 0 | BB9: =BA9 -> 0 | BC9: =BB9 -> 0 | BD9: =BC9 -> 0 | ... BM9: =BL9 -> 0 | BP9: =BO9 -> 0 | BQ9: =BP9 -> 0 | BS9: =BR9 -> 0 | BT9: =BS9 -> 0 | BU9: =BT9 -> 0 | BV9: =BU9 -> 0 | BW9: =BV9 -> 0 | BX9: =BW9 -> 0 | BY9: =BX9 -> 0 | BZ9: =BY9 -> 0 | CA9: =BZ9 -> 0
C10: Contract assets—current | AG10: 14260 | AH10: =AG10 -> 14260 | AI10: 12030 | AJ10: 13760 | AK10: 12056 | AL10: 10616 | AM10: =AL10 -> 10616 | AN10: 13360 | AO10: 15548 | AP10: 17921 | AQ10: 12502 | AR10: =AQ10 -> 12502 | AS10: 13236 | AT10: 17044 | AU10: 22477 | AV10: 16883 | AW10: =AV10 -> 16883 | AX10: 15267 | AY10: 13993 | AZ10: 14690 | BA10: 12588 | BB10: =BA10 -> 12588 | BC10: 13368 | BD10: 9387 | BE10: 13609 | BF10: 12437 | BG10: =BF10 -> 12437 | BH10: 17454 | BI10: 16188 | BJ10: 19381 | BK10: 15922 | BL10: =BK10 -> 15922 | BM10: 12319 | BN10: 13449 | BO10: 13645 | BP10: 13764 | BQ10: =BP10 -> 13764 | BR10: 9585 | BS10: 9892 | BT10: 8978 | BU10: =BU55*IS!BU13 -> 16544.25 | BV10: =BU10 -> 16544.25 | BW10: =BW55*IS!BW13 -> 16126.638 | BX10: =BX55*IS!BX13 -> 16914.99 | BY10: =BY55*IS!BY13 -> 17286.409 | BZ10: =BZ55*IS!BZ13 -> 17475.949 | CA10: =BZ10 -> 17475.949
C11: Prepaid and other | S11: =R11 -> 0 | X11: =W11 -> 0 | AG11: 23349 | AH11: =AG11 -> 23349 | AI11: 29779 | AJ11: 26776 | AK11: 28344 | AL11: 29976 | AM11: =AL11 -> 29976 | AN11: 39341 | AO11: 38907 | AP11: 37814 | AQ11: 37125 | AR11: =AQ11 -> 37125 | AS11: 51176 | AT11: 52158 | AU11: 47343 | AV11: 48390 | AW11: =AV11 -> 48390 | AX11: 65172 | AY11: 61197 | AZ11: 67842 | BA11: 63236 | BB11: =BA11 -> 63236 | BC11: 80669 | BD11: 79142 | BE11: 68814 | BF11: 69987 | BG11: =BF11 -> 69987 | BH11: 86719 | BI11: 81492 | BJ11: 72629 | BK11: 66984 | BL11: =BK11 -> 66984 | BM11: 84540 | BN11: 81693 | BO11: 75412 | BP11: 82368 | BQ11: =BP11 -> 82368 | BR11: 111204 | BS11: 107760 | BT11: 103328 | BU11: =BU56*IS!BU13 -> 107537.63 | BV11: =BU11 -> 107537.63 | BW11: =BW56*IS!BW13 -> 104823.14 | BX11: =BX56*IS!BX13 -> 101489.94 | BY11: =BY56*IS!BY13 -> 95075.248 | BZ11: =BZ56*IS!BZ13 -> 96117.72 | CA11: =BZ11 -> 96117.72
B12: Total Current Assets | D12: =SUM(D6:D11) -> 0 | E12: =SUM(E6:E11) -> 0 | F12: =SUM(F6:F11) -> 0 | G12: =SUM(G6:G11) -> 0 | H12: =SUM(H6:H11) -> 0 | I12: =SUM(I6:I11) -> 0 | J12: =SUM(J6:J11) -> 0 | K12: =SUM(K6:K11) -> 0 | ... CA12: =SUM(CA6:CA11) -> 2834410.6
C13: Investments—noncurrent | AG13: 0 | AH13: =AG13 -> 0 | AJ13: 0 | AK13: 0 | AL13: 164220 | AM13: =AL13 -> 164220 | AN13: 184683 | AO13: 180146 | AP13: 257783 | AQ13: 239729 | AR13: =AQ13 -> 239729 | AS13: 140117 | AT13: 66265 | AU13: 76782 | AV13: 92717 | AW13: =AV13 -> 92717 | AX13: 94930 | AY13: 64088 | AZ13: 89455 | BA13: 94938 | BB13: =BA13 -> 94938 | BC13: 94751 | BD13: 133238 | BE13: 129783 | BF13: 186049 | BG13: =BF13 -> 186049 | BH13: 206026 | BI13: 85202 | BJ13: 55448 | BK13: 121977 | BL13: =BK13 -> 121977 | BM13: 139108 | BN13: 102537 | BO13: 112805 | BP13: 134105 | BQ13: =BP13 -> 134105 | BR13: 160139 | BS13: 208864 | BT13: 208529 | BU13: =BT13 -> 208529 | BV13: =BU13 -> 208529 | BW13: =BV13 -> 208529 | BX13: =BW13 -> 208529 | BY13: =BX13 -> 208529 | BZ13: =BY13 -> 208529 | CA13: =BZ13 -> 208529
C14: Property and equipment, net | S14: =R14 -> 0 | X14: =W14 -> 0 | AG14: 63019 | AH14: =AG14 -> 63019 | AI14: 60095 | AJ14: 60415 | AK14: 73965 | AL14: 75832 | AM14: =AL14 -> 75832 | AN14: 84094 | AO14: 92078 | AP14: 105917 | AQ14: 128293 | AR14: =AQ14 -> 128293 | AS14: 134811 | AT14: 150646 | AU14: 159652 | AV14: 165039 | AW14: =AV14 -> 165039 | AX14: 164128 | AY14: 173983 | AZ14: 177832 | BA14: 184664 | BB14: =BA14 -> 184664 | BC14: 183704 | BD14: 186229 | BE14: 196127 | BF14: 199892 | BG14: =BF14 -> 199892 | BH14: 120803 | BI14: 220916 | BJ14: 230963 | BK14: 245173 | BL14: =BK14 -> 245173 | BM14: 255736 | BN14: 265544 | BO14: 278623 | BP14: 299370 | BQ14: =BP14 -> 299370 | BR14: 310150 | BS14: 327953 | BT14: 343636 | BU14: =BT14-CF!BU37-CF!BU8 -> 328416.06 | BV14: =BU14 -> 328416.06 | BW14: =BV14-CF!BW37-CF!BW8 -> 310684.45 | BX14: =BW14-CF!BX37-CF!BX8 -> 294152.78 | BY14: =BX14-CF!BY37-CF!BY8 -> 279796.23 | BZ14: =BY14-CF!BZ37-CF!BZ8 -> 271483.33 | CA14: =BZ14 -> 271483.33
C15: Deferred contract acquisition costs—noncurrent | AG15: 75535 | AH15: =AG15 -> 75535 | AI15: 78401 | AJ15: 86199 | AK15: 97091 | AL15: 112583 | AM15: =AL15 -> 112583 | AN15: 115924 | AO15: 124434 | AP15: 136248 | AQ15: 153333 | AR15: =AQ15 -> 153333 | AS15: 169686 | AT15: 198325 | AU15: 225115 | AV15: 260130 | AW15: =AV15 -> 260130 | AX15: 274039 | AY15: 289636 | AZ15: 300073 | BA15: 311835 | BB15: =BA15 -> 311835 | BC15: 313760 | BD15: 322695 | BE15: 329958 | BF15: 350899 | BG15: =BF15 -> 350899 | BH15: 135403 | BI15: 369749 | BJ15: 383205 | BK15: 409627 | BL15: =BK15 -> 409627 | BM15: 415739 | BN15: 427599 | BO15: 445987 | BP15: 467201 | BQ15: =BP15 -> 467201 | BR15: 461969 | BS15: 462928 | BT15: 462552 | BU15: =BU57*IS!BU13 -> 537688.13 | BV15: =BU15 -> 537688.13 | BW15: =BW57*IS!BW13 -> 483799.13 | BX15: =BX57*IS!BX13 -> 507449.71 | BY15: =BY57*IS!BY13 -> 535878.67 | BZ15: =BZ57*IS!BZ13 -> 567968.35 | CA15: =BZ15 -> 567968.35
C16: Operating lease right to use | AG16: 0 | AH16: =AG16 -> 0 | AI16: 0 | AJ16: 0 | AK16: 0 | AL16: 0 | AM16: =AL16 -> 0 | AN16: 143361 | AO16: 137292 | AP16: 136627 | AQ16: 149833 | AR16: =AQ16 -> 149833 | AS16: 161484 | AT16: 168313 | AU16: 160362 | AV16: 159352 | AW16: =AV16 -> 159352 | AX16: 152185 | AY16: 140589 | AZ16: 132608 | BA16: 126021 | BB16: =BA16 -> 126021 | BC16: 116589 | BD16: 100481 | BE16: 92155 | BF16: 141493 | BG16: =BF16 -> 141493 | BH16: 353308 | BI16: 131341 | BJ16: 126198 | BK16: 123188 | BL16: =BK16 -> 123188 | BM16: 119997 | BN16: 117877 | BO16: 113365 | BP16: 109630 | BQ16: =BP16 -> 109630 | BR16: 115412 | BS16: 109953 | BT16: 133183 | BU16: =BU58*IS!BU13 -> 132354 | BV16: =BU16 -> 132354 | BW16: =BW58*IS!BW13 -> 129013.1 | BX16: =BX58*IS!BX13 -> 135319.92 | BY16: =BY58*IS!BY13 -> 138291.27 | BZ16: =BZ58*IS!BZ13 -> 139807.59 | CA16: =BZ16 -> 139807.59
C17: Intangible assets, net | S17: =R17 -> 0 | X17: =W17 -> 0 | AG17: 14148 | AH17: =AG17 -> 14148 | AI17: 11278 | AJ17: 10139 | AK17: 79161 | AL17: 74203 | AM17: =AL17 -> 74203 | AN17: 69490 | AO17: 65070 | AP17: 60759 | AQ17: 56500 | AR17: =AQ17 -> 56500 | AS17: 52241 | AT17: 135825 | AU17: 128414 | AV17: 121828 | AW17: =AV17 -> 121828 | AX17: 115009 | AY17: 110327 | AZ17: 102802 | BA17: 98816 | BB17: =BA17 -> 98816 | BC17: 87277 | BD17: 81246 | BE17: 75232 | BF17: 70280 | BG17: =BF17 -> 70280 | BH17: 65247 | BI17: 60304 | BJ17: 55605 | BK17: 50905 | BL17: =BK17 -> 50905 | BM17: 46206 | BN17: 90227 | BO17: 83307 | BP17: 76388 | BQ17: =BP17 -> 76388 | BR17: 69469 | BS17: 64553 | BT17: 60816 | BU17: =BT17 -> 60816 | BV17: =BU17 -> 60816 | BW17: =BV17 -> 60816 | BX17: =BW17 -> 60816 | BY17: =BX17 -> 60816 | BZ17: =BY17 -> 60816 | CA17: =BZ17 -> 60816
C18: Goodwill | S18: =R18 -> 0 | X18: =W18 -> 0 | AG18: 37306 | AH18: =AG18 -> 37306 | AI18: 36074 | AJ18: 35369 | AK18: 194533 | AL18: 195225 | AM18: =AL18 -> 195225 | AN18: 194775 | AO18: 195427 | AP18: 195024 | AQ18: 194882 | AR18: =AQ18 -> 194882 | AS18: 193594 | AT18: 349254 | AU18: 348504 | AV18: 350151 | AW18: =AV18 -> 350151 | AX18: 351511 | AY18: 355595 | AZ18: 355353 | BA18: 355058 | BB18: =BA18 -> 355058 | BC18: 354056 | BD18: 353326 | BE18: 352423 | BF18: 353619 | BG18: =BF18 -> 353619 | BH18: 359255 | BI18: 353345 | BJ18: 351493 | BK18: 353138 | BL18: =BK18 -> 353138 | BM18: 352450 | BN18: 455519 | BO18: 455678 | BP18: 454477 | BQ18: =BP18 -> 454477 | BR18: 455276 | BS18: 456368 | BT18: 457247 | BU18: =BT18 -> 457247 | BV18: =BU18 -> 457247 | BW18: =BV18 -> 457247 | BX18: =BW18 -> 457247 | BY18: =BX18 -> 457247 | BZ18: =BY18 -> 457247 | CA18: =BZ18 -> 457247
C19: Deferred tax assets - noncurrent | BN19: 822026 | BO19: 816538 | BP19: 840470 | BQ19: =BP19 -> 840470 | BR19: 844837 | BS19: 836641 | BT19: 838694 | BU19: =BS19-IS!BU66*0.1 -> 828143.15 | BW19: =BU19-IS!BW66*0.1 -> 821253.84 | BX19: =BV19-IS!BX66*0.1 -> -8700.7681 | BY19: =BW19-IS!BY66*0.1 -> 811447.09 | BZ19: =BX19-IS!BZ66*0.1 -> -13420.726
C20: Other assets | S20: =R20 -> 0 | X20: =W20 -> 0 | AG20: 11170 | AH20: =AG20 -> 11170 | AI20: 12891 | AJ20: 9513 | AK20: 9175 | AL20: 8833 | AM20: =AL20 -> 8833 | AN20: 23947 | AO20: 23896 | AP20: 24617 | AQ20: 24678 | AR20: =AQ20 -> 24678 | AS20: 26312 | AT20: 16659 | AU20: 22530 | AV20: 24942 | AW20: =AV20 -> 24942 | AX20: 33882 | AY20: 38680 | AZ20: 45791 | BA20: 50337 | BB20: =BA20 -> 50337 | BC20: 61470 | BD20: 67349 | BE20: 75521 | BF20: 79484 | BG20: =BF20 -> 79484 | BH20: 85795 | BI20: 90079 | BJ20: 92032 | BK20: 99615 | BL20: =BK20 -> 99615 | BM20: 107654 | BN20: 129232 | BO20: 132028 | BP20: 141803 | BQ20: =BP20 -> 141803 | BR20: 153073 | BS20: 163613 | BT20: 170227 | BU20: =BU59*IS!BU13 -> 157170.38 | BV20: =BU20 -> 157170.38 | BW20: =BW59*IS!BW13 -> 161266.38 | BX20: =BX59*IS!BX13 -> 153080.66 | BY20: =BY59*IS!BY13 -> 155577.68 | BZ20: =BZ59*IS!BZ13 -> 157283.54 | CA20: =BZ20 -> 157283.54
B21: Total Assets | D21: =D12+SUM(D13:D20) -> 0 | E21: =E12+SUM(E13:E20) -> 0 | F21: =F12+SUM(F13:F20) -> 0 | G21: =G12+SUM(G13:G20) -> 0 | H21: =H12+SUM(H13:H20) -> 0 | I21: =I12+SUM(I13:I20) -> 0 | J21: =J12+SUM(J13:J20) -> 0 | K21: =K12+SUM(K13:K20) -> 0 | ... W21: =W12+SUM(W13:W20) -> 0 | X21: 486487 | Y21: =Y12+SUM(Y13:Y20) -> 0 | Z21: =Z12+SUM(Z13:Z20) -> 0 | AA21: =AA12+SUM(AA13:AA20) -> 0 | AB21: =AB12+SUM(AB13:AB20) -> 0 | AC21: 499638 | AD21: =AD12+SUM(AD13:AD20) -> 0 | AE21: =AE12+SUM(AE13:AE20) -> 0 | AF21: =AF12+SUM(AF13:AF20) -> 0 | AG21: =AG12+SUM(AG13:AG20) -> 619973 | AH21: =AH12+SUM(AH13:AH20) -> 619973 | AI21: =AI12+SUM(AI13:AI20) -> 614472 | AJ21: =AJ12+SUM(AJ13:AJ20) -> 1169698 | AK21: =AK12+SUM(AK13:AK20) -> 1719436 | ... CA21: =CA12+SUM(CA13:CA20) -> 4697545.4
B23: Liabilities:
C24: Accounts payable | S24: =R24 -> 0 | X24: =W24 -> 0 | AG24: 23713 | AH24: =AG24 -> 23713 | AI24: 13269 | AJ24: 16653 | AK24: 22059 | AL24: 19590 | AM24: =AL24 -> 19590 | AN24: 21436 | AO24: 23452 | AP24: 29099 | AQ24: 28144 | AR24: =AQ24 -> 28144 | AS24: 21504 | AT24: 33053 | AU24: 32309 | AV24: 37367 | AW24: =AV24 -> 37367 | AX24: 14870 | AY24: 33612 | AZ24: 47712 | BA24: 52804 | BB24: =BA24 -> 52804 | BC24: 26213 | BD24: 44449 | BE24: 47176 | BF24: 24393 | BG24: =BF24 -> 24393 | BH24: 14688 | BI24: 5803 | BJ24: 14787 | BK24: 19029 | BL24: =BK24 -> 19029 | BM24: 17700 | BN24: 8116 | BO24: 18144 | BP24: 30697 | BQ24: =BP24 -> 30697 | BR24: 24583 | BS24: 10643 | BT24: 22482 | BU24: =BU62*IS!BU13 -> 24816.375 | BV24: =BU24 -> 24816.375 | BW24: =BW62*IS!BW13 -> 24189.956 | BX24: =BX62*IS!BX13 -> 25372.486 | BY24: =BY62*IS!BY13 -> 25929.613 | BZ24: =BZ62*IS!BZ13 -> 26213.924 | CA24: =BZ24 -> 26213.924
