Workbook
Name _1994: #REF!
Name _1995: #REF!
Name _1996: #REF!
Name _1997: #REF!
Name _1998: #REF!
Name _1999: #REF!
Name _1Q94: #REF!
Name _1Q95: #REF!
Name _2007: #REF!
Name _2008: #REF!
Name _2Q94: #REF!
Name _2Q95: #REF!
Name _3Q94: #REF!
Name _3Q95: #REF!
Name _4Q94: #REF!
Name _4Q95: #REF!
Name _Key1: #REF!
Name _marketsource: #REF!
Name _Order1: 0
Name _Sort: #REF!
Name _strtyr: #REF!
Name a: #REF!
Name Acc_payable: #REF!
Name Acc_payable_growth_fore: #REF!
Name Acc_Rec: #REF!
Name Acc_Rec_growth_fore: #REF!
Name Acc_Rec_turns: #REF!
Name Accel_Ratio: #REF!
Name Accrued_compensation: #REF!
Name Accrued_compensation_growth_fore: #REF!
Name Accrued_expenses: #REF!
Name Accrued_expenses_growth_fore: #REF!
Name Accum_Cap_Expenses: #REF!
Name Accum_Cap_Expenses_growth_fore: #REF!
Name Accum_Goodwill_Amort: #REF!
Name Accum_Goodwill_Amort_growth_fore: #REF!
Name Accum_Other_Amort.: #REF!
Name Adj_net_oper_fore: #REF!
Name Adjusted_Common_Equity: #REF!
Name Adjusted_Income_Available_to_Common: #REF!
Name Adjusted_Net_Operating_Profit: #REF!
Name AEH_qtrly_results: #REF!
Name After_tax_charge: #REF!
Name After_Tax_charges_gains: #REF!
Name Ag: #REF!
Name AHC_CAPEX: #REF!
Name AHC_CAPEX_2004: #REF!
Name AHC_CAPEX_2005: #REF!
Name AHC_CAPEX_2006: #REF!
Name AHC_CAPEX_2007: #REF!
Name AHC_CAPEX_Chems: #REF!
Name AHC_CAPEX_EP: #REF!
Name AHC_CAPEX_EP_2004: #REF!
Name AHC_CAPEX_EP_2005: #REF!
Name AHC_CAPEX_EP_2006: #REF!
Name AHC_CAPEX_EP_2007: #REF!
Name AHC_CAPEX_Other: #REF!
Name AHC_CAPEX_Other_2004: #REF!
Name AHC_CAPEX_Other_2005: #REF!
Name AHC_CAPEX_Other_2006: #REF!

Sheet __FDSCACHE__
B1: This sheet contains FactSet XML data for use with this workbook's =FDS codes. Modifying the worksheet's contents may damage the workbook's =FDS functionality.

Sheet Disclaimer
C5: Equity Research
C7: Financial Model
C8: Life Science Tools & Diagnostics
C9: 46080
C12: Natera, Inc. (NTRA)
C19: Brandon Couillard | E19: Evan Stampler, PhD, CFA | G19: Chris Mercado, CFA
C20: Senior Analyst | E20: Vice President | G20: Vice President
C21: 212.214.5053 | E21: 212.214.5312 | G21: 212.214.8092
C22: brandon.couillard@wellsfargo.com | E22: evan.stampler@wellsfargo.com | G22: chistopher.mercado2@wellsfargo.com
C26: Important Disclaimers:
BN437: 33.6
BN438: 16.1
BN443: 0
BO513: 40 | BW513: 30
BN514: =0.9 -> 0.9 | BO514: 1 | BR514: =+BP514 -> 0

Sheet IS
A1: Natera Inc. (NASDAQ: NTRA)
A2: Income Statement
A3: $ millions except per share data, FY ending Dec
B5: Mar | C5: Jun | D5: Sep | E5: Dec | F5: 41974 | G5: Mar | H5: Jun | I5: Sep | J5: Dec | K5: =+DATE(YEAR(F5)+1,MONTH(F5),DAY(F5)) -> 42339 | L5: Mar | M5: Jun | N5: Sep | O5: Dec | P5: =+DATE(YEAR(K5)+1,MONTH(K5),DAY(K5)) -> 42705 | Q5: Mar | R5: Jun | S5: Sep | T5: Dec | U5: =+DATE(YEAR(P5)+1,MONTH(P5),DAY(P5)) -> 43070 | V5: Mar | W5: Jun | X5: Sep | Y5: Dec | Z5: =+DATE(YEAR(U5)+1,MONTH(U5),DAY(U5)) -> 43435 | AA5: Mar | AB5: Jun | AC5: Sep | AD5: Dec | AE5: =+DATE(YEAR(Z5)+1,MONTH(Z5),DAY(Z5)) -> 43800 | AF5: Mar | AG5: Jun | AH5: Sep | AI5: Dec | AJ5: =+DATE(YEAR(AE5)+1,MONTH(AE5),DAY(AE5)) -> 44166 | AK5: Mar | AL5: Jun | AM5: Sep | AN5: Dec | AO5: =+DATE(YEAR(AJ5)+1,MONTH(AJ5),DAY(AJ5)) -> 44531 | AP5: Mar | AQ5: Jun | AR5: Sep | AS5: Dec | AT5: =+DATE(YEAR(AO5)+1,MONTH(AO5),DAY(AO5)) -> 44896 | AU5: Mar | AV5: Jun | AW5: Sep | AX5: Dec | AY5: =+DATE(YEAR(AT5)+1,MONTH(AT5),DAY(AT5)) -> 45261 | AZ5: Mar | BA5: Jun | BB5: Sep | BC5: Dec | BD5: =+DATE(YEAR(AY5)+1,MONTH(AY5),DAY(AY5)) -> 45627 | BE5: Mar | BF5: Jun | BG5: Sep | BH5: Dec | BI5: =+DATE(YEAR(BD5)+1,MONTH(BD5),DAY(BD5)) -> 45992 | BJ5: Mar | BK5: Jun | BL5: Sep | BM5: Dec | BN5: =+DATE(YEAR(BI5)+1,MONTH(BI5),DAY(BI5)) -> 46357 | BO5: Mar | BP5: Jun | BQ5: Sep | BR5: Dec | BS5: =+DATE(YEAR(BN5)+1,MONTH(BN5),DAY(BN5)) -> 46722 | BT5: Mar | BU5: Jun | BV5: Sep | BW5: Dec | BX5: =+DATE(YEAR(BS5)+1,MONTH(BS5),DAY(BS5)) -> 47088 | BY5: Mar | BZ5: Jun | CA5: Sep | CB5: Dec | CC5: =+DATE(YEAR(BX5)+1,MONTH(BX5),DAY(BX5)) -> 47453 | CD5: Mar | CE5: Jun | CF5: Sep | CG5: Dec | CH5: =+DATE(YEAR(CC5)+1,MONTH(CC5),DAY(CC5)) -> 47818 | CI5: Mar | CJ5: Jun | CK5: Sep | CL5: Dec | CM5: =+DATE(YEAR(CH5)+1,MONTH(CH5),DAY(CH5)) -> 48183 | CN5: Mar | CO5: Jun | CP5: Sep | CQ5: Dec | CR5: =+DATE(YEAR(CM5)+1,MONTH(CM5),DAY(CM5)) -> 48549 | CS5: Mar | CT5: Jun | CU5: Sep | CV5: Dec | CW5: =+DATE(YEAR(CR5)+1,MONTH(CR5),DAY(CR5)) -> 48914 | CX5: Mar | CY5: Jun | CZ5: Sep | DA5: Dec | DB5: =+DATE(YEAR(CW5)+1,MONTH(CW5),DAY(CW5)) -> 49279
B6: 1Q14A | C6: 2Q14A | D6: 3Q14A | E6: 4Q14A | F6: FY14A | G6: 1Q15A | H6: 2Q15A | I6: 3Q15A | J6: 4Q15A | K6: FY15A | L6: 1Q16A | M6: 2Q16A | N6: 3Q16A | O6: 4Q16A | P6: FY16A | Q6: 1Q17A | R6: 2Q17A | S6: 3Q17A | T6: 4Q17A | U6: FY17A | V6: 1Q18A | W6: 2Q18A | X6: 3Q18A | Y6: 4Q18A | Z6: FY18A | AA6: 1Q19A | AB6: 2Q19A | AC6: 3Q19A | AD6: 4Q19A | AE6: FY19A | AF6: 1Q20A | AG6: 2Q20A | AH6: 3Q20A | AI6: 4Q20A | AJ6: FY20A | AK6: 1Q21A | AL6: 2Q21A | AM6: 3Q21A | AN6: 4Q21A | AO6: FY21A | AP6: 1Q22A | AQ6: 2Q22A | AR6: 3Q22A | AS6: 4Q22A | AT6: FY22A | AU6: 1Q23A | AV6: 2Q23A | AW6: 3Q23A | AX6: 4Q23A | AY6: FY23A | AZ6: 1Q24A | BA6: 2Q24A | BB6: 3Q24A | BC6: 4Q24A | BD6: FY24A | BE6: 1Q25A | BF6: 2Q25A | BG6: 3Q25A | BH6: 4Q25 | BI6: FY25 | BJ6: 1Q26E | BK6: 2Q26E | BL6: 3Q26E | BM6: 4Q26E | BN6: FY26E | BO6: 1Q27E | BP6: 2Q27E | BQ6: 3Q27E | BR6: 4Q27E | BS6: FY27E | BT6: 1Q28E | BU6: 2Q28E | BV6: 3Q28E | BW6: 4Q28E | BX6: FY28E | BY6: 1Q29E | BZ6: 2Q29E | CA6: 3Q29E | CB6: 4Q29E | CC6: FY29E | CD6: 1Q30E | CE6: 2Q30E | CF6: 3Q30E | CG6: 4Q30E | CH6: FY30E | CI6: 1Q31E | CJ6: 2Q31E | CK6: 3Q31E | CL6: 4Q31E | CM6: FY31E | CN6: 1Q32E | CO6: 2Q32E | CP6: 3Q32E | CQ6: 4Q32E | CR6: FY32E | CS6: 1Q33E | CT6: 2Q33E | CU6: 3Q33E | CV6: 4Q33E | CW6: FY33E | CX6: 1Q34E | CY6: 2Q34E | CZ6: 3Q34E | DA6: 4Q34E | DB6: FY34E | DD6: 5-yr CAGR | DE6: 3-yr CAGR
A7: Net Sales | B7: =27.209+0.086 -> 27.295 | C7: =35.736+0.1 -> 35.836 | D7: =45.804+0.47 -> 46.274 | E7: =F7-SUM(B7:D7) -> 49.884 | F7: 159.289 | G7: 47.435 | H7: 45.087 | I7: 44.921 | J7: =K7-SUM(G7:I7) -> 52.912 | K7: 190.355 | L7: 61.902 | M7: 51.984 | N7: 53.889 | O7: =P7-SUM(L7:N7) -> 49.299 | P7: 217.074 | Q7: 46.901 | R7: 53.617 | S7: 56.656 | T7: =U7-SUM(Q7:S7) -> 53.765 | U7: 210.939 | V7: 62.34 | W7: 63.069 | X7: 65.28 | Y7: =Z7-SUM(V7:X7) -> 66.965 | Z7: 257.654 | AA7: 66.824 | AB7: 74.355 | AC7: 77.909 | AD7: =AE7-SUM(AA7:AC7) -> 83.24 | AE7: 302.328 | AF7: 94.012 | AG7: 86.472 | AH7: 98.143 | AI7: =AJ7-SUM(AF7:AH7) -> 112.378 | AJ7: 391.005 | AK7: 152.316 | AL7: 142.026 | AM7: 158.116 | AN7: =AO7-SUM(AK7:AM7) -> 173.028 | AO7: 625.486 | AP7: 194.133 | AQ7: 198.2 | AR7: 210.637 | AS7: =AT7-SUM(AP7:AR7) -> 217.252 | AT7: 820.222 | AU7: 241.756 | AV7: 261.404 | AW7: 268.306 | AX7: =AY7-SUM(AU7:AW7) -> 311.105 | AY7: 1082.571 | AZ7: 367.741 | BA7: 413.351 | BB7: 439.758 | BC7: =BD7-SUM(AZ7:BB7) -> 476.061 | BD7: 1696.911 | BE7: 501.83 | BF7: =544.427+2.173 -> 546.6 | BG7: 592.183 | BH7: =2306.113-BE7-BF7-BG7 -> 665.5 | BI7: =SUM(BE7:BH7) -> 2306.113 | BJ7: =+Rev!BJ17 -> 616.53287 | BK7: =+Rev!BK17 -> 650.50782 | BL7: =+Rev!BL17 -> 676.58177 | BM7: =+Rev!BM17 -> 715.30687 | BN7: =SUM(BJ7:BM7) -> 2658.9293 | BO7: =+Rev!BO17 -> 762.14849 | BP7: =+Rev!BP17 -> 763.06913 | BQ7: =+Rev!BQ17 -> 790.7504 | BR7: =+Rev!BR17 -> 813.12422 | BS7: =SUM(BO7:BR7) -> 3129.0922 | BT7: =+Rev!BT17 -> 876.90033 | BU7: =+Rev!BU17 -> 886.05176 | BV7: =+Rev!BV17 -> 913.63859 | BW7: =+Rev!BW17 -> 940.58178 | BX7: =SUM(BT7:BW7) -> 3617.1725 | BY7: =+Rev!BY17 -> 1012.82 | BZ7: =+Rev!BZ17 -> 1016.8898 | CA7: =+Rev!CA17 -> 1051.5164 | CB7: =+Rev!CB17 -> 1076.6057 | CC7: =SUM(BY7:CB7) -> 4157.8319 | CD7: =+Rev!CD17 -> 1155.036 | CE7: =+Rev!CE17 -> 1161.815 | CF7: =+Rev!CF17 -> 1196.7164 | CG7: =+Rev!CG17 -> 1225.5048 | CH7: =SUM(CD7:CG7) -> 4739.0721 | CI7: =+Rev!CI17 -> 1298.4004 | CJ7: =+Rev!CJ17 -> 1301.0288 | CK7: =+Rev!CK17 -> 1332.8348 | CL7: =+Rev!CL17 -> 1358.4264 | CM7: =SUM(CI7:CL7) -> 5290.6903 | CN7: =+Rev!CN17 -> 1435.3246 | CO7: =+Rev!CO17 -> 1437.9537 | CP7: =+Rev!CP17 -> 1470.6387 | CQ7: =+Rev!CQ17 -> 1497.2106 | CR7: =SUM(CN7:CQ7) -> 5841.1277 | CS7: =+Rev!CS17 -> 1578.9497 | CT7: =+Rev!CT17 -> 1582.2801 | CU7: =+Rev!CU17 -> 1616.7881 | CV7: =+Rev!CV17 -> 1645.0622 | CW7: =SUM(CS7:CV7) -> 6423.0801 | CX7: =+Rev!CX17 -> 1717.5517 | CY7: =+Rev!CY17 -> 1717.0667 | CZ7: =+Rev!CZ17 -> 1748.7456 | DA7: =+Rev!DA17 -> 1774.2 | DB7: =SUM(CX7:DA7) -> 6957.564
A8: Cost of Revenues | B8: 15.9 | C8: 19.014 | D8: 20.82 | E8: =F8-SUM(B8:D8) -> 22.662 | F8: 78.396 | G8: 24.843 | H8: 25.732 | I8: 30.456 | J8: =K8-SUM(G8:I8) -> 31.814 | K8: 112.845 | L8: 32.34 | M8: 30.973 | N8: 34.261 | O8: =P8-SUM(L8:N8) -> 38 | P8: 135.574 | Q8: =33.088+0.612 -> 33.7 | R8: =33.709+0.85 -> 34.559 | S8: =33.558+1.054 -> 34.612 | T8: =U8-SUM(Q8:S8) -> 36.725 | U8: =135.508+4.088 -> 139.596 | V8: =39.055+1.537 -> 40.592 | W8: =39.204+1.791 -> 40.995 | X8: =39.477+2.202 -> 41.679 | Y8: =Z8-SUM(V8:X8) -> 42.789 | Z8: =158.081+7.974 -> 166.055 | AA8: =41.605+1.698 -> 43.303 | AB8: =41.382+2.443 -> 43.825 | AC8: =40.138+3.742 -> 43.88 | AD8: =AE8-SUM(AA8:AC8) -> 44.462 | AE8: =162.604+12.866 -> 175.47 | AF8: =41.52+3.458 -> 44.978 | AG8: =42.731+4.208 -> 46.939 | AH8: =46.873+4.948 -> 51.821 | AI8: =AJ8-SUM(AF8:AH8) -> 59.882 | AJ8: =185.865+17.755 -> 203.62 | AK8: =61.322+5.491 -> 66.813 | AL8: =73.227+2.885 -> 76.112 | AM8: =76.838+4.533 -> 81.371 | AN8: =AO8-SUM(AK8:AM8) -> 94.122 | AO8: =302.663+15.755 -> 318.418 | AP8: =102.67+0.545 -> 103.215 | AQ8: =108.756+0.481 -> 109.237 | AR8: =115.436+1.076 -> 116.512 | AS8: =AT8-SUM(AP8:AR8) -> 127.292 | AT8: =453.632+2.624 -> 456.256 | AU8: =147.754+0.37 -> 148.124 | AV8: =142.808+0.341 -> 143.149 | AW8: =146.962+0.349 -> 147.311 | AX8: =AY8-SUM(AU8:AW8) -> 151.247 | AY8: =588.564+1.267 -> 589.831 | AZ8: =158.833+0.307 -> 159.14 | BA8: =169.85+0.329 -> 170.179 | BB8: =167.657+0.354 -> 168.011 | BC8: =BD8-SUM(AZ8:BB8) -> 176.423 | BD8: =672.304+1.449 -> 673.753 | BE8: =184.613+0.452 -> 185.065 | BF8: =199.531+0.465 -> 199.996 | BG8: =207.253+0.548 -> 207.801 | BH8: =810.627+2.306-BE8-BF8-BG8 -> 220.071 | BI8: =SUM(BE8:BH8) -> 812.933 | BJ8: =+BJ7-BJ9 -> 230.4524 | BK8: =+BK7-BK9 -> 239.65354 | BL8: =+BL7-BL9 -> 237.52289 | BM8: =+BM7-BM9 -> 234.83095 | BN8: =SUM(BJ8:BM8) -> 942.45977 | BO8: =+BO7-BO9 -> 267.60622 | BP8: =+BP7-BP9 -> 269.58173 | BQ8: =+BQ7-BQ9 -> 270.51446 | BR8: =+BR7-BR9 -> 261.80974 | BS8: =SUM(BO8:BR8) -> 1069.5122 | BT8: =+BT7-BT9 -> 294.20707 | BU8: =+BU7-BU9 -> 299.97641 | BV8: =+BV7-BV9 -> 298.35836 | BW8: =+BW7-BW9 -> 289.00616 | BX8: =SUM(BT8:BW8) -> 1181.548 | BY8: =+BY7-BY9 -> 326.87003 | BZ8: =+BZ7-BZ9 -> 331.20942 | CA8: =+CA7-CA9 -> 331.20094 | CB8: =+CB7-CB9 -> 319.36444 | CC8: =SUM(BY8:CB8) -> 1308.6448 | CD8: =+CD7-CD9 -> 359.35482 | CE8: =+CE7-CE9 -> 365.13248 | CF8: =+CF7-CF9 -> 364.02375 | CG8: =+CG7-CG9 -> 351.26336 | CH8: =SUM(CD8:CG8) -> 1439.7744 | CI8: =+CI7-CI9 -> 392.38467 | CJ8: =+CJ7-CJ9 -> 398.34097 | CK8: =+CK7-CK9 -> 395.83634 | CL8: =+CL7-CL9 -> 381.01633 | CM8: =SUM(CI8:CL8) -> 1567.5783 | CN8: =+CN7-CN9 -> 424.05992 | CO8: =+CO7-CO9 -> 430.91641 | CP8: =+CP7-CP9 -> 427.59469 | CQ8: =+CQ7-CQ9 -> 411.43563 | CR8: =SUM(CN8:CQ8) -> 1694.0067 | CS8: =+CS7-CS9 -> 456.55124 | CT8: =+CT7-CT9 -> 464.4006 | CU8: =+CU7-CU9 -> 460.41948 | CV8: =+CV7-CV9 -> 442.93284 | CW8: =SUM(CS8:CV8) -> 1824.3042 | CX8: =+CX7-CX9 -> 489.53371 | CY8: =+CY7-CY9 -> 497.75608 | CZ8: =+CZ7-CZ9 -> 492.44631 | DA8: =+DA7-DA9 -> 473.08617 | DB8: =SUM(CX8:DA8) -> 1952.8223
A9: Gross Profit | B9: =B7-B8 -> 11.395 | C9: =C7-C8 -> 16.822 | D9: =D7-D8 -> 25.454 | E9: =E7-E8 -> 27.222 | F9: =F7-F8 -> 80.893 | G9: =G7-G8 -> 22.592 | H9: =H7-H8 -> 19.355 | I9: =I7-I8 -> 14.465 | ... AX9: =AX7-AX8 -> 159.858 | AY9: =SUM(AU9:AX9) -> 492.74 | AZ9: =AZ7-AZ8 -> 208.601 | BA9: =BA7-BA8 -> 243.172 | BB9: =BB7-BB8 -> 271.747 | BC9: =BC7-BC8 -> 299.638 | BD9: =SUM(AZ9:BC9) -> 1023.158 | BE9: =BE7-BE8 -> 316.765 | BF9: =BF7-BF8 -> 346.604 | BG9: =BG7-BG8 -> 384.382 | BH9: =BH7-BH8 -> 445.429 | BI9: =SUM(BE9:BH9) -> 1493.18 | BJ9: =+Rev!BJ479 -> 386.08047 | BK9: =+Rev!BK479 -> 410.85429 | BL9: =+Rev!BL479 -> 439.05889 | BM9: =+Rev!BM479 -> 480.47592 | BN9: =+Rev!BN479 -> 1716.4696 | BO9: =+Rev!BO479 -> 494.54227 | BP9: =+Rev!BP479 -> 493.48739 | BQ9: =+Rev!BQ479 -> 520.23595 | ... DB9: =+Rev!DB479 -> 5004.7417
A10: Research & Development | B10: 4.298 | C10: 4.122 | D10: 4.372 | E10: =F10-SUM(B10:D10) -> 4.5 | F10: 17.292 | G10: 5.63 | H10: 6.741 | I10: 7.336 | J10: =K10-SUM(G10:I10) -> 8.004 | K10: 27.711 | L10: 8.759 | M10: 10.299 | N10: 11.345 | O10: =P10-SUM(L10:N10) -> 11.459 | P10: 41.862 | Q10: 12.65 | R10: 11.786 | S10: 12.609 | T10: =U10-SUM(Q10:S10) -> 13.019 | U10: 50.064 | V10: 14.34 | W10: 11.852 | X10: 12.393 | Y10: =Z10-SUM(V10:X10) -> 12.77 | Z10: 51.355 | AA10: 11.435 | AB10: 12.124 | AC10: 12.796 | AD10: =AE10-SUM(AA10:AC10) -> 15.002 | AE10: 51.357 | AF10: 18.225 | AG10: 23.005 | AH10: 26.421 | AI10: =AJ10-SUM(AF10:AH10) -> 32.384 | AJ10: 100.035 | AK10: 40.188 | AL10: 53.752 | AM10: 98.457 | AN10: =AO10-SUM(AK10:AM10) -> 71.811 | AO10: 264.208 | AP10: 80.414 | AQ10: 82.58 | AR10: 65.51 | AS10: =AT10-SUM(AP10:AR10) -> 87.911 | AT10: 316.415 | AU10: 82.306 | AV10: 78.173 | AW10: 77.235 | AX10: =AY10-SUM(AU10:AW10) -> 82.964 | AY10: 320.678 | AZ10: 88.637 | BA10: 89.109 | BB10: 96.931 | BC10: =BD10-SUM(AZ10:BB10) -> 129.461 | BD10: 404.138 | BE10: 129.078 | BF10: =146.427 -> 146.427 | BG10: 173.412 | BH10: =624.11-BE10-BF10-BG10 -> 175.193 | BI10: =SUM(BE10:BH10) -> 624.11 | BJ10: 198 | BK10: 198 | BL10: 204 | BM10: 208 | BN10: =SUM(BJ10:BM10) -> 808 | BO10: =+BJ10*(1+BO36) -> 215.82 | BP10: =+BK10*(1+BP36) -> 215.82 | BQ10: =+BL10*(1+BQ36) -> 222.36 | BR10: =+BM10*(1+BR36) -> 226.72 | BS10: =SUM(BO10:BR10) -> 880.72 | BT10: =+BO10*(1+BT36) -> 233.0856 | BU10: =+BP10*(1+BU36) -> 233.0856 | BV10: =+BQ10*(1+BV36) -> 240.1488 | BW10: =+BR10*(1+BW36) -> 244.8576 | BX10: =SUM(BT10:BW10) -> 951.1776 | BY10: =+BT10*(1+BY36) -> 250.56702 | BZ10: =+BU10*(1+BZ36) -> 250.56702 | CA10: =+BV10*(1+CA36) -> 258.15996 | CB10: =+BW10*(1+CB36) -> 263.22192 | CC10: =SUM(BY10:CB10) -> 1022.5159 | CD10: =+BY10*(1+CD36) -> 268.10671 | CE10: =+BZ10*(1+CE36) -> 268.10671 | CF10: =+CA10*(1+CF36) -> 276.23116 | CG10: =+CB10*(1+CG36) -> 281.64745 | CH10: =SUM(CD10:CG10) -> 1094.092 | CI10: =+CD10*(1+CI36) -> 286.87418 | CJ10: =+CE10*(1+CJ36) -> 286.87418 | CK10: =+CF10*(1+CK36) -> 295.56734 | CL10: =+CG10*(1+CL36) -> 301.36278 | CM10: =SUM(CI10:CL10) -> 1170.6785 | CN10: =+CI10*(1+CN36) -> 306.95537 | CO10: =+CJ10*(1+CO36) -> 306.95537 | CP10: =+CK10*(1+CP36) -> 316.25705 | CQ10: =+CL10*(1+CQ36) -> 322.45817 | CR10: =SUM(CN10:CQ10) -> 1252.626 | CS10: =+CN10*(1+CS36) -> 328.44225 | CT10: =+CO10*(1+CT36) -> 328.44225 | CU10: =+CP10*(1+CU36) -> 338.39505 | CV10: =+CQ10*(1+CV36) -> 345.03024 | CW10: =SUM(CS10:CV10) -> 1340.3098 | CX10: =+CS10*(1+CX36) -> 351.43321 | CY10: =+CT10*(1+CY36) -> 351.43321 | CZ10: =+CU10*(1+CZ36) -> 362.0827 | DA10: =+CV10*(1+DA36) -> 369.18236 | DB10: =SUM(CX10:DA10) -> 1434.1315
A11: Selling, General & Administrative | B11: 14.379 | C11: 13.905 | D11: 16.303 | E11: =F11-SUM(B11:D11) -> 18.349 | F11: 62.936 | G11: 23.239 | H11: 28.086 | I11: 27.87 | J11: =K11-SUM(G11:I11) -> 30.442 | K11: 109.637 | L11: 30.408 | M11: 33.227 | N11: 34.938 | O11: =P11-SUM(L11:N11) -> 37.553 | P11: 136.126 | Q11: 37.582 | R11: 34.309 | S11: 34.478 | T11: =U11-SUM(Q11:S11) -> 48.937 | U11: 155.306 | V11: 37.925 | W11: 37.44 | X11: 38.374 | Y11: =Z11-SUM(V11:X11) -> 41.133 | Z11: 154.872 | AA11: 43.832 | AB11: 47.042 | AC11: 56.715 | AD11: =AE11-SUM(AA11:AC11) -> 58.587 | AE11: 206.176 | AF11: 65.681 | AG11: 68.188 | AH11: 75.678 | AI11: =AJ11-SUM(AF11:AH11) -> 94.08 | AJ11: 303.627 | AK11: 108.332 | AL11: 127.456 | AM11: 128.485 | AN11: =AO11-SUM(AK11:AM11) -> 146.761 | AO11: 511.034 | AP11: 147.634 | AQ11: 149.468 | AR11: 147.667 | AS11: =AT11-SUM(AP11:AR11) -> 143.822 | AT11: 588.591 | AU11: 149.627 | AV11: 152.508 | AW11: 154.742 | AX11: =AY11-SUM(AU11:AW11) -> 161.43 | AY11: 618.307 | AZ11: 194.278 | BA11: 197.965 | BB11: 214.154 | BC11: =BD11-SUM(AZ11:BB11) -> 234.917 | BD11: 841.314 | BE11: 266.864 | BF11: =310.549 -> 310.549 | BG11: 308.546 | BH11: =1177.261+1.72-BE11-BF11-BG11 -> 293.022 | BI11: =SUM(BE11:BH11) -> 1178.981 | BJ11: 280 | BK11: 290 | BL11: 300 | BM11: 310 | BN11: =SUM(BJ11:BM11) -> 1180 | BO11: =+BJ11*(1+BO37) -> 305.2 | BP11: =+BK11*(1+BP37) -> 316.1 | BQ11: =+BL11*(1+BQ37) -> 327 | BR11: =+BM11*(1+BR37) -> 337.9 | BS11: =SUM(BO11:BR11) -> 1286.2 | BT11: =+BO11*(1+BT37) -> 329.616 | BU11: =+BP11*(1+BU37) -> 341.388 | BV11: =+BQ11*(1+BV37) -> 353.16 | BW11: =+BR11*(1+BW37) -> 364.932 | BX11: =SUM(BT11:BW11) -> 1389.096 | BY11: =+BT11*(1+BY37) -> 354.3372 | BZ11: =+BU11*(1+BZ37) -> 366.9921 | CA11: =+BV11*(1+CA37) -> 379.647 | CB11: =+BW11*(1+CB37) -> 392.3019 | CC11: =SUM(BY11:CB11) -> 1493.2782 | CD11: =+BY11*(1+CD37) -> 379.1408 | CE11: =+BZ11*(1+CE37) -> 392.68155 | CF11: =+CA11*(1+CF37) -> 406.22229 | CG11: =+CB11*(1+CG37) -> 419.76303 | CH11: =SUM(CD11:CG11) -> 1597.8077 | CI11: =+CD11*(1+CI37) -> 401.88925 | CJ11: =+CE11*(1+CJ37) -> 416.24244 | CK11: =+CF11*(1+CK37) -> 430.59563 | CL11: =+CG11*(1+CL37) -> 444.94881 | CM11: =SUM(CI11:CL11) -> 1693.6761 | CN11: =+CI11*(1+CN37) -> 426.00261 | CO11: =+CJ11*(1+CO37) -> 441.21699 | CP11: =+CK11*(1+CP37) -> 456.43137 | CQ11: =+CL11*(1+CQ37) -> 471.64574 | CR11: =SUM(CN11:CQ11) -> 1795.2967 | CS11: =+CN11*(1+CS37) -> 451.56276 | CT11: =+CO11*(1+CT37) -> 467.69001 | CU11: =+CP11*(1+CU37) -> 483.81725 | CV11: =+CQ11*(1+CV37) -> 499.94449 | CW11: =SUM(CS11:CV11) -> 1903.0145 | CX11: =+CS11*(1+CX37) -> 478.65653 | CY11: =+CT11*(1+CY37) -> 495.75141 | CZ11: =+CU11*(1+CZ37) -> 512.84628 | DA11: =+CV11*(1+DA37) -> 529.94116 | DB11: =SUM(CX11:DA11) -> 2017.1954
A12: Gain from Disposal of Business | C12: 0 | D12: 0 | E12: =F12-SUM(C12:D12) -> 0 | F12: 0 | V12: 0 | W12: 0 | X12: 0 | Y12: =Z12-SUM(V12:X12) -> 0 | Z12: 0 | AA12: 0 | AB12: 0 | AC12: -14.388 | AD12: =AE12-SUM(AA12:AC12) -> 0 | AE12: -14.388 | AF12: 0 | AG12: 0 | AH12: 0 | AI12: =AJ12-SUM(AF12:AH12) -> 0 | AJ12: 0 | AK12: 0 | AL12: 0 | AM12: 0 | AN12: =AO12-SUM(AK12:AM12) -> 0 | AO12: 0 | AP12: 0 | AQ12: 0 | AR12: 0 | AS12: =AT12-SUM(AP12:AR12) -> 0 | AT12: 0 | AU12: 0 | AV12: 0 | AW12: 0 | AX12: =AY12-SUM(AU12:AW12) -> 0 | AY12: 0 | AZ12: 0 | BA12: 0 | BB12: 0
A13: Operating Expenses | B13: =+B10+B11 -> 18.677 | C13: =+C10+C11 -> 18.027 | D13: =+D10+D11 -> 20.675 | E13: =+E10+E11 -> 22.849 | F13: =+F10+F11 -> 80.228 | G13: =+G10+G11 -> 28.869 | H13: =+H10+H11 -> 34.827 | I13: =+I10+I11 -> 35.206 | ... DB13: =+DB10+DB11 -> 3451.3268
A14: Operating Income (EBIT) | B14: =+B9-B13 -> -7.282 | C14: =+C9-C13 -> -1.205 | D14: =+D9-D13 -> 4.779 | E14: =+E9-E13 -> 4.373 | F14: =+F9-F13 -> 0.665 | G14: =+G9-G13 -> -6.277 | H14: =+H9-H13 -> -15.472 | I14: =+I9-I13 -> -20.741 | ... DB14: =+DB9-DB13 -> 1553.4149
A15: Interest expense | B15: 0.809 | C15: 0.936 | D15: 1.202 | E15: =F15-SUM(B15:D15) -> 1.272 | F15: 4.219 | G15: 1.01 | H15: 1.203 | I15: 1.177 | J15: =K15-SUM(G15:I15) -> 0.115 | K15: 3.505 | L15: 0.115 | M15: 0.122 | N15: 0.146 | O15: =P15-SUM(L15:N15) -> 0.15 | P15: 0.533 | Q15: 0.183 | R15: 0.218 | S15: 1.477 | T15: =U15-SUM(Q15:S15) -> 2.335 | U15: 4.213 | V15: 2.389 | W15: 2.56 | X15: 2.781 | Y15: =Z15-SUM(V15:X15) -> 2.746 | Z15: 10.476 | AA15: 2.724 | AB15: 2.721 | AC15: 2.672 | AD15: =AE15-SUM(AA15:AC15) -> 2.576 | AE15: 10.693 | AF15: 2.464 | AG15: 4.038 | AH15: 4.27 | AI15: =AJ15-SUM(AF15:AH15) -> 4.31 | AJ15: 15.082 | AK15: 2.073 | AL15: 2.075 | AM15: 2.078 | AN15: =AO15-SUM(AK15:AM15) -> 2.079 | AO15: 8.305 | AP15: 2.087 | AQ15: 2.15 | AR15: 2.33 | AS15: =AT15-SUM(AP15:AR15) -> 2.752 | AT15: 9.319 | AU15: 3.061 | AV15: 3.177 | AW15: 3.252 | AX15: =AY15-SUM(AU15:AW15) -> 3.148 | AY15: 12.638 | AZ15: 3.124 | BA15: 3.127 | BB15: 3.142 | BC15: =BD15-SUM(AZ15:BB15) -> 1.292 | BD15: 10.685 | BE15: 1.005 | BF15: 1.029 | BG15: 1.045 | BH15: =4.069-BE15-BF15-BG15 -> 0.99 | BI15: =SUM(BE15:BH15) -> 4.069 | BJ15: =+'Other Accts'!BJ29 -> 0.963876 | BK15: =+'Other Accts'!BK29 -> 0.722907 | BL15: =+'Other Accts'!BL29 -> 0.48217897 | BM15: =+'Other Accts'!BM29 -> 0.24108948 | BN15: =SUM(BJ15:BM15) -> 2.4100515 | BO15: =+'Other Accts'!BO29 -> 0 | BP15: =+'Other Accts'!BP29 -> 0 | BQ15: =+'Other Accts'!BQ29 -> 0 | BR15: =+'Other Accts'!BR29 -> 0 | BS15: =SUM(BO15:BR15) -> 0 | BT15: =+'Other Accts'!BT29 -> 0 | BU15: =+'Other Accts'!BU29 -> 0 | BV15: =+'Other Accts'!BV29 -> 0 | BW15: =+'Other Accts'!BW29 -> 0 | BX15: =SUM(BT15:BW15) -> 0 | BY15: =+'Other Accts'!BY29 -> 0 | BZ15: =+'Other Accts'!BZ29 -> 0 | CA15: =+'Other Accts'!CA29 -> 0 | CB15: =+'Other Accts'!CB29 -> 0 | CC15: =SUM(BY15:CB15) -> 0 | CD15: =+'Other Accts'!CD29 -> 0 | CE15: =+'Other Accts'!CE29 -> 0 | CF15: =+'Other Accts'!CF29 -> 0 | CG15: =+'Other Accts'!CG29 -> 0 | CH15: =SUM(CD15:CG15) -> 0 | CI15: =+'Other Accts'!CI29 -> 0 | CJ15: =+'Other Accts'!CJ29 -> 0 | CK15: =+'Other Accts'!CK29 -> 0 | CL15: =+'Other Accts'!CL29 -> 0 | CM15: =SUM(CI15:CL15) -> 0 | CN15: =+'Other Accts'!CN29 -> 0 | CO15: =+'Other Accts'!CO29 -> 0 | CP15: =+'Other Accts'!CP29 -> 0 | CQ15: =+'Other Accts'!CQ29 -> 0 | CR15: =SUM(CN15:CQ15) -> 0 | CS15: =+'Other Accts'!CS29 -> 0 | CT15: =+'Other Accts'!CT29 -> 0 | CU15: =+'Other Accts'!CU29 -> 0 | CV15: =+'Other Accts'!CV29 -> 0 | CW15: =SUM(CS15:CV15) -> 0 | CX15: =+'Other Accts'!CX29 -> 0 | CY15: =+'Other Accts'!CY29 -> 0 | CZ15: =+'Other Accts'!CZ29 -> 0 | DA15: =+'Other Accts'!DA29 -> 0 | DB15: =SUM(CX15:DA15) -> 0
A16: Interest income | B16: 0.806 | C16: -1.34 | D16: -0.708 | E16: =F16-SUM(B16:D16) -> 1.124 | F16: -0.118 | G16: 1.8 | H16: 0.322 | I16: -1.81 | J16: =K16-SUM(G16:I16) -> -1.276 | K16: -0.964 | L16: 0 | M16: 0 | N16: 0 | O16: =P16-SUM(L16:N16) -> 0 | P16: 0 | Q16: -1.3 | R16: 0.413 | S16: 0.437 | T16: =U16-SUM(Q16:S16) -> -1.93 | U16: -2.38 | V16: -0.137 | W16: 3.933 | X16: -0.449 | Y16: =Z16-SUM(V16:X16) -> -0.618 | Z16: 2.729 | AA16: -0.453 | AB16: -0.836 | AC16: -0.673 | AD16: =AE16-SUM(AA16:AC16) -> -2.19 | AE16: -4.152 | AF16: -1.987 | AG16: -1.924 | AH16: -1.749 | AI16: =AJ16-SUM(AF16:AH16) -> -1.902 | AJ16: -7.562 | AK16: -1.371 | AL16: -1.585 | AM16: -1.274 | AN16: =AO16-SUM(AK16:AM16) -> -1.151 | AO16: -5.381 | AP16: -0.801 | AQ16: -0.277 | AR16: -0.087 | AS16: =AT16-SUM(AP16:AR16) -> -2.373 | AT16: -3.538 | AU16: -4.585 | AV16: -4.518 | AW16: -5.406 | AX16: =AY16-SUM(AU16:AW16) -> -9.844 | AY16: -24.353 | AZ16: -10.267 | BA16: -10.457 | BB16: -11.618 | BC16: =BD16-SUM(AZ16:BB16) -> -10.906 | BD16: -43.248 | BE16: -13.419 | BF16: -10.738 | BG16: -11.284 | BH16: =-45.891-BE16-BF16-BG16 -> -10.45 | BI16: =SUM(BE16:BH16) -> -45.891 | BJ16: =-'Other Accts'!BJ9 -> -10.22333 | BK16: =-'Other Accts'!BK9 -> -10.614898 | BL16: =-'Other Accts'!BL9 -> -10.033068 | BM16: =-'Other Accts'!BM9 -> -9.6184711 | BN16: =SUM(BJ16:BM16) -> -40.489767 | BO16: =-'Other Accts'!BO9 -> -6.3830883 | BP16: =-'Other Accts'!BP9 -> -5.2179704 | BQ16: =-'Other Accts'!BQ9 -> -5.1821643 | BR16: =-'Other Accts'!BR9 -> -5.2327732 | BS16: =SUM(BO16:BR16) -> -22.015996 | BT16: =-'Other Accts'!BT9 -> -5.3611132 | BU16: =-'Other Accts'!BU9 -> -5.7114312 | BV16: =-'Other Accts'!BV9 -> -5.9356431 | BW16: =-'Other Accts'!BW9 -> -6.2588073 | BX16: =SUM(BT16:BW16) -> -23.266995 | BY16: =-'Other Accts'!BY9 -> -6.6850077 | BZ16: =-'Other Accts'!BZ9 -> -7.3697465 | CA16: =-'Other Accts'!CA9 -> -7.890946 | CB16: =-'Other Accts'!CB9 -> -8.5408551 | CC16: =SUM(BY16:CB16) -> -30.486555 | CD16: =-'Other Accts'!CD9 -> -9.2911588 | CE16: =-'Other Accts'!CE9 -> -10.346495 | CF16: =-'Other Accts'!CF9 -> -11.228513 | CG16: =-'Other Accts'!CG9 -> -12.247067 | CH16: =SUM(CD16:CG16) -> -43.113233 | CI16: =-'Other Accts'!CI9 -> -13.385813 | CJ16: =-'Other Accts'!CJ9 -> -14.826104 | CK16: =-'Other Accts'!CK9 -> -16.051993 | CL16: =-'Other Accts'!CL9 -> -17.408031 | CM16: =SUM(CI16:CL16) -> -61.671941 | CN16: =-'Other Accts'!CN9 -> -18.872947 | CO16: =-'Other Accts'!CO9 -> -20.664821 | CP16: =-'Other Accts'!CP9 -> -22.221129 | CQ16: =-'Other Accts'!CQ9 -> -23.918632 | CR16: =SUM(CN16:CQ16) -> -85.67753 | CS16: =-'Other Accts'!CS9 -> -25.732807 | CT16: =-'Other Accts'!CT9 -> -27.901556 | CU16: =-'Other Accts'!CU9 -> -29.815495 | CV16: =-'Other Accts'!CV9 -> -31.884841 | CW16: =SUM(CS16:CV16) -> -115.3347 | CX16: =-'Other Accts'!CX9 -> -34.081299 | CY16: =-'Other Accts'!CY9 -> -36.590082 | CZ16: =-'Other Accts'!CZ9 -> -38.803301 | DA16: =-'Other Accts'!DA9 -> -41.164611 | DB16: =SUM(CX16:DA16) -> -150.63929
A17: Other expense, net | B17: 0.719 | C17: -0.287 | D17: 0.561 | E17: =F17-SUM(B17:D17) -> 0.723 | F17: 1.716 | G17: 0.917 | H17: 2.684 | I17: -2.478 | J17: =K17-SUM(G17:I17) -> 6.773 | K17: 7.896 | L17: -1.035 | M17: 0.519 | N17: -0.887 | O17: =P17-SUM(L17:N17) -> 0.005 | P17: -1.398 | Q17: 0 | R17: 0 | S17: 0 | T17: =U17-SUM(Q17:S17) -> 0 | U17: 0 | V17: 0 | W17: 0 | X17: 0 | Y17: =Z17-SUM(V17:X17) -> 0 | Z17: 0 | AA17: 0 | AB17: 0 | AC17: 0 | AD17: =AE17-SUM(AA17:AC17) -> 0 | AE17: 0 | AF17: 0 | AG17: 5.848 | AH17: 0 | AI17: =AJ17-SUM(AF17:AH17) -> 0 | AJ17: 5.848 | AK17: 0 | AL17: 0 | AM17: 0 | AN17: =AO17-SUM(AK17:AM17) -> 0 | AO17: 0 | AP17: 0 | AQ17: 0 | AR17: 0 | AS17: =AT17-SUM(AP17:AR17) -> 0 | AT17: 0 | AU17: 0 | AV17: 0 | AW17: 0 | AX17: =AY17-SUM(AU17:AW17) -> 0 | AY17: 0 | AZ17: 0 | BA17: 0 | BB17: 0 | BC17: =BD17-SUM(AZ17:BB17) -> 0 | BD17: 0 | BE17: 0 | BF17: 0 | BG17: 0 | BH17: =0-BE17-BF17-BG17 -> 0 | BI17: =SUM(BE17:BH17) -> 0 | BJ17: 0 | BK17: 0 | BL17: 0 | BM17: 0 | BN17: =SUM(BJ17:BM17) -> 0 | BO17: 0 | BP17: 0 | BQ17: 0 | BR17: 0 | BS17: =SUM(BO17:BR17) -> 0 | BT17: 0 | BU17: 0 | BV17: 0 | BW17: 0 | BX17: =SUM(BT17:BW17) -> 0 | BY17: 0 | BZ17: 0 | CA17: 0 | CB17: 0 | CC17: =SUM(BY17:CB17) -> 0 | CD17: 0 | CE17: 0 | CF17: 0 | CG17: 0 | CH17: =SUM(CD17:CG17) -> 0 | CI17: 0 | CJ17: 0 | CK17: 0 | CL17: 0 | CM17: =SUM(CI17:CL17) -> 0 | CN17: 0 | CO17: 0 | CP17: 0 | CQ17: 0 | CR17: =SUM(CN17:CQ17) -> 0 | CS17: 0 | CT17: 0 | CU17: 0 | CV17: 0 | CW17: =SUM(CS17:CV17) -> 0 | CX17: 0 | CY17: 0 | CZ17: 0 | DA17: 0 | DB17: =SUM(CX17:DA17) -> 0
A18: Income Before Taxes | B18: =+B14-B15-B16-B17 -> -9.616 | C18: =+C14-C15-C16-C17 -> -0.514 | D18: =+D14-D15-D16-D17 -> 3.724 | E18: =+E14-E15-E16-E17 -> 1.254 | F18: =+F14-F15-F16-F17 -> -5.152 | G18: =+G14-G15-G16-G17 -> -10.004 | H18: =+H14-H15-H16-H17 -> -19.681 | I18: =+I14-I15-I16-I17 -> -17.63 | ... DB18: =+DB14-DB15-DB16-DB17 -> 1704.0542
A19: Income Tax | B19: 0 | C19: 0 | D19: 0 | E19: =F19-SUM(B19:D19) -> 0 | F19: 0 | G19: 0 | H19: 0 | I19: 0 | J19: =K19-SUM(G19:I19) -> 0 | K19: 0 | L19: 0 | M19: 0 | N19: 0.103 | O19: =P19-SUM(L19:N19) -> 0.039 | P19: 0.142 | Q19: 0.047 | R19: 0.064 | S19: 0.162 | T19: =U19-SUM(Q19:S19) -> 0.181 | U19: 0.454 | V19: 0.104 | W19: 0.113 | X19: 0.118 | Y19: =Z19-SUM(V19:X19) -> -0.014 | Z19: 0.321 | AA19: 0.074 | AB19: 1.895 | AC19: 0.044 | AD19: =AE19-SUM(AA19:AC19) -> -0.014 | AE19: 1.999 | AF19: 0.023 | AG19: 0.015 | AH19: 0.025 | AI19: =AJ19-SUM(AF19:AH19) -> 0.035 | AJ19: 0.098 | AK19: 0.134 | AL19: 0.242 | AM19: 0.272 | AN19: =AO19-SUM(AK19:AM19) -> -0.03 | AO19: 0.618 | AP19: 0.179 | AQ19: 0.193 | AR19: 0.185 | AS19: =AT19-SUM(AP19:AR19) -> 0.421 | AT19: 0.978 | AU19: 0.16 | AV19: -0.282 | AW19: 0.202 | AX19: =AY19-SUM(AU19:AW19) -> 0.191 | AY19: 0.271 | AZ19: 0.428 | BA19: 0.892 | BB19: 0.73 | BC19: =BD19-SUM(AZ19:BB19) -> -1.355 | BD19: 0.695 | BE19: 0.173 | BF19: 0.275 | BG19: 0.207 | BH19: =-59.929-BE19-BF19-BG19 -> -60.584 | BI19: =SUM(BE19:BH19) -> -59.929 | BJ19: =+BJ20*BJ18 -> 0 | BK19: =+BK20*BK18 -> 0 | BL19: =+BL20*BL18 -> 0 | BM19: =+BM20*BM18 -> 0 | BN19: =SUM(BJ19:BM19) -> 0 | BO19: =+BO20*BO18 -> 0 | BP19: =+BP20*BP18 -> 0 | BQ19: =+BQ20*BQ18 -> 0 | BR19: =+BR20*BR18 -> 0 | BS19: =SUM(BO19:BR19) -> 0 | BT19: =+BT20*BT18 -> 0 | BU19: =+BU20*BU18 -> 0 | BV19: =+BV20*BV18 -> 0 | BW19: =+BW20*BW18 -> 0 | BX19: =SUM(BT19:BW19) -> 0 | BY19: =+BY20*BY18 -> 0 | BZ19: =+BZ20*BZ18 -> 0 | CA19: =+CA20*CA18 -> 0 | CB19: =+CB20*CB18 -> 0 | CC19: =SUM(BY19:CB19) -> 0 | CD19: =+CD20*CD18 -> 0 | CE19: =+CE20*CE18 -> 0 | CF19: =+CF20*CF18 -> 0 | CG19: =+CG20*CG18 -> 0 | CH19: =SUM(CD19:CG19) -> 0 | CI19: =+CI20*CI18 -> 0 | CJ19: =+CJ20*CJ18 -> 0 | CK19: =+CK20*CK18 -> 0 | CL19: =+CL20*CL18 -> 0 | CM19: =SUM(CI19:CL19) -> 0 | CN19: =+CN20*CN18 -> 0 | CO19: =+CO20*CO18 -> 0 | CP19: =+CP20*CP18 -> 0 | CQ19: =+CQ20*CQ18 -> 0 | CR19: =SUM(CN19:CQ19) -> 0 | CS19: =+CS20*CS18 -> 0 | CT19: =+CT20*CT18 -> 0 | CU19: =+CU20*CU18 -> 0 | CV19: =+CV20*CV18 -> 0 | CW19: =SUM(CS19:CV19) -> 0 | CX19: =+CX20*CX18 -> 0 | CY19: =+CY20*CY18 -> 0 | CZ19: =+CZ20*CZ18 -> 0 | DA19: =+DA20*DA18 -> 0 | DB19: =SUM(CX19:DA19) -> 0 | DD19: =SUM(BX19,CC19,CH19,CM19,CR19,CW19,DB19) -> 0
A20: Tax Rate | B20: =+B19/B18 -> 0 | C20: =+C19/C18 -> 0 | D20: =+D19/D18 -> 0 | E20: =+E19/E18 -> 0 | F20: =+F19/F18 -> 0 | G20: =+G19/G18 -> 0 | H20: =+H19/H18 -> 0 | I20: =+I19/I18 -> 0 | ... BI20: =+BI19/BI18 -> 0.22354144 | BJ20: 0 | BK20: 0 | BL20: 0 | BM20: 0 | BN20: =+BN19/BN18 -> 0 | BO20: 0 | BP20: 0 | BQ20: 0 | BR20: 0 | BS20: =+BS19/BS18 -> 0 | BT20: =BX20 -> 0 | BU20: =BX20 -> 0 | BV20: =BX20 -> 0 | BW20: =BX20 -> 0 | BX20: 0 | BY20: =CC20 -> 0 | BZ20: =CC20 -> 0 | CA20: =CC20 -> 0 | CB20: =CC20 -> 0 | CC20: 0 | CD20: =CH20 -> 0 | CE20: =CH20 -> 0 | CF20: =CH20 -> 0 | CG20: =CH20 -> 0 | CH20: 0 | CI20: =CM20 -> 0 | CJ20: =CM20 -> 0 | CK20: =CM20 -> 0 | CL20: =CM20 -> 0 | CM20: 0 | CN20: =CR20 -> 0 | CO20: =CR20 -> 0 | CP20: =CR20 -> 0 | CQ20: =CR20 -> 0 | CR20: 0 | CS20: =CW20 -> 0 | CT20: =CW20 -> 0 | CU20: =CW20 -> 0 | CV20: =CW20 -> 0 | CW20: 0 | CX20: =DB20 -> 0 | CY20: =DB20 -> 0 | CZ20: =DB20 -> 0 | DA20: =DB20 -> 0 | DB20: 0
A21: Net Loss | B21: =+B18-B19 -> -9.616 | C21: =+C18-C19 -> -0.514 | D21: =+D18-D19 -> 3.724 | E21: =+E18-E19 -> 1.254 | F21: =+F18-F19 -> -5.152 | G21: =+G18-G19 -> -10.004 | H21: =+H18-H19 -> -19.681 | I21: =+I18-I19 -> -17.63 | ... DB21: =+DB18-DB19 -> 1704.0542
A22: Unrealized Gain on AFS Securities | B22: 0 | C22: 0 | D22: =2.552+1 -> 3.552 | E22: =F22-SUM(B22:D22) -> -3.552 | F22: 0 | G22: 0 | H22: 0 | I22: -0.036 | J22: =1.416-G22-H22-I22 -> 1.452 | K22: =+G22+H22+I22+J22 -> 1.416 | L22: -1.811 | M22: -0.548 | N22: 0.609 | O22: =-0.691-L22-M22-N22 -> 1.059 | P22: =+L22+M22+N22+O22 -> -0.691 | Q22: -0.2 | R22: -0.062 | S22: -0.067 | T22: =U22-SUM(Q22:S22) -> 0.37 | U22: 0.041 | V22: 0.138 | W22: -0.046 | X22: 0.036 | Y22: =Z22-SUM(V22:X22) -> -0.342 | Z22: -0.214 | AA22: -0.286 | AB22: -1.061 | AC22: -0.063 | AD22: =AE22-SUM(AA22:AC22) -> -0.061 | AE22: -1.471 | AF22: -4.747 | AG22: -0.104 | AH22: 0.6 | AI22: =AJ22-SUM(AF22:AH22) -> 0.911 | AJ22: -3.34 | AK22: 1.062 | AL22: 0.756 | AM22: 0.95 | AN22: =AO22-SUM(AK22:AM22) -> 3.778 | AO22: 6.546 | AP22: 11.617 | AQ22: 2.493 | AR22: 3.212 | AS22: =AT22-SUM(AP22:AR22) -> -3.247 | AT22: =--14.075 -> 14.075 | AU22: -4.564 | AV22: -2.595 | AW22: -3.807 | AX22: =AY22-SUM(AU22:AW22) -> -2.311 | AY22: -13.277 | AZ22: -0.893 | BA22: -0.834 | BB22: -0.593 | BC22: =BD22-SUM(AZ22:BB22) -> -0.421 | BD22: -2.741 | BE22: -0.147 | BF22: 0.09 | BG22: -0.1 | BH22: =-0.086-BE22-BF22-BG22 -> 0.071 | BI22: =+BE22+BF22+BG22+BH22 -> -0.086 | BJ22: -0.1 | BK22: -0.1 | BL22: -0.1 | BM22: -0.1 | BN22: =+BJ22+BK22+BL22+BM22 -> -0.4 | BO22: -0.1 | BP22: -0.1 | BQ22: -0.1 | BR22: -0.1 | BS22: =+BO22+BP22+BQ22+BR22 -> -0.4 | BT22: -0.1 | BU22: -0.1 | BV22: -0.1 | BW22: -0.1 | BX22: =+BT22+BU22+BV22+BW22 -> -0.4 | BY22: -0.1 | BZ22: -0.1 | CA22: -0.1 | CB22: -0.1 | CC22: =+BY22+BZ22+CA22+CB22 -> -0.4 | CD22: -0.1 | CE22: -0.1 | CF22: -0.1 | CG22: -0.1 | CH22: =+CD22+CE22+CF22+CG22 -> -0.4 | CI22: -0.1 | CJ22: -0.1 | CK22: -0.1 | CL22: -0.1 | CM22: =+CI22+CJ22+CK22+CL22 -> -0.4 | CN22: -0.1 | CO22: -0.1 | CP22: -0.1 | CQ22: -0.1 | CR22: =+CN22+CO22+CP22+CQ22 -> -0.4 | CS22: -0.1 | CT22: -0.1 | CU22: -0.1 | CV22: -0.1 | CW22: =+CS22+CT22+CU22+CV22 -> -0.4 | CX22: -0.1 | CY22: -0.1 | CZ22: -0.1 | DA22: -0.1 | DB22: =+CX22+CY22+CZ22+DA22 -> -0.4
A23: Comprehensive Loss | B23: =+B21-B22 -> -9.616 | C23: =+C21-C22 -> -0.514 | D23: =+D21-D22 -> 0.172 | E23: =+E21-E22 -> 4.806 | F23: =+F21-F22 -> -5.152 | G23: =+G21-G22 -> -10.004 | H23: =+H21-H22 -> -19.681 | I23: =+I21-I22 -> -17.594 | ... DB23: =+DB21-DB22 -> 1704.4542
A25: Basic shares outstanding | B25: 4.591 | C25: 4.722 | D25: 4.866 | E25: =F25*4-SUM(B25:D25) -> 5.021 | F25: 4.8 | G25: 5.289 | H25: 5.494 | I25: 44.944 | J25: =K25*4-SUM(G25:I25) -> 49.089 | K25: 26.204 | L25: 50.439 | M25: 51.445 | N25: 52.012 | O25: =P25*4-SUM(L25:N25) -> 52.408 | P25: 51.576 | Q25: 52.758 | R25: 53.088 | S25: 53.447 | T25: =U25*4-SUM(Q25:S25) -> 53.955 | U25: 53.312 | V25: 54.132 | W25: 54.551 | X25: 60.57 | Y25: =Z25*4-SUM(V25:X25) -> 62.139 | Z25: 57.848 | AA25: 62.831 | AB25: 68.224 | AC25: 70.456 | AD25: =AE25*4-SUM(AA25:AC25) -> 76.709 | AE25: 69.555 | AF25: 78.287 | AG25: 79.069 | AH25: 80.908 | AI25: =AJ25*4-SUM(AF25:AH25) -> 85.78 | AJ25: 81.011 | AK25: 86.689 | AL25: 88.077 | AM25: 92.558 | AN25: =AO25*4-SUM(AK25:AM25) -> 94.908 | AO25: 90.558 | AP25: 95.578 | AQ25: 96.579 | AR25: 97.052 | AS25: =AT25*4-SUM(AP25:AR25) -> 104.423 | AT25: 98.408 | AU25: 111.767 | AV25: 113.69 | AW25: 115.171 | AX25: =AY25*4-SUM(AU25:AW25) -> 119.36 | AY25: 114.997 | AZ25: 120.814 | BA25: 122.853 | BB25: 123.775 | BC25: =BD25*4-SUM(AZ25:BB25) -> 131.43 | BD25: 124.718 | BE25: 134.75 | BF25: 136.388 | BG25: 137.187 | BH25: =BI25*4-SUM(BE25:BG25) -> 138.559 | BI25: 136.721 | BJ25: =BH25+BS!BJ55-BS!BJ56 -> 139.59819 | BK25: =BJ25+BS!BK55-BS!BK56 -> 140.63738 | BL25: =BK25+BS!BL55-BS!BL56 -> 141.67658 | BM25: =BL25+BS!BM55-BS!BM56 -> 142.71577 | BN25: =AVERAGE(BJ25:BM25) -> 141.15698 | BO25: =BM25+BS!BO55-BS!BO56 -> 143.78614 | BP25: =BO25+BS!BP55-BS!BP56 -> 144.85651 | BQ25: =BP25+BS!BQ55-BS!BQ56 -> 145.92687 | BR25: =BQ25+BS!BR55-BS!BR56 -> 146.99724 | BS25: =AVERAGE(BO25:BR25) -> 145.39169 | BT25: =BR25+BS!BT55-BS!BT56 -> 148.09972 | BU25: =BT25+BS!BU55-BS!BU56 -> 149.2022 | BV25: =BU25+BS!BV55-BS!BV56 -> 150.30468 | BW25: =BV25+BS!BW55-BS!BW56 -> 151.40716 | BX25: =AVERAGE(BT25:BW25) -> 149.75344 | BY25: =BW25+BS!BY55-BS!BY56 -> 152.54271 | BZ25: =BY25+BS!BZ55-BS!BZ56 -> 153.67827 | CA25: =BZ25+BS!CA55-BS!CA56 -> 154.81382 | CB25: =CA25+BS!CB55-BS!CB56 -> 155.94938 | CC25: =AVERAGE(BY25:CB25) -> 154.24604 | CD25: =CB25+BS!CD55-BS!CD56 -> 157.119 | CE25: =CD25+BS!CE55-BS!CE56 -> 158.28862 | CF25: =CE25+BS!CF55-BS!CF56 -> 159.45824 | CG25: =CF25+BS!CG55-BS!CG56 -> 160.62786 | CH25: =AVERAGE(CD25:CG25) -> 158.87343 | CI25: =CG25+BS!CI55-BS!CI56 -> 161.83257 | CJ25: =CI25+BS!CJ55-BS!CJ56 -> 163.03727 | CK25: =CJ25+BS!CK55-BS!CK56 -> 164.24198 | CL25: =CK25+BS!CL55-BS!CL56 -> 165.44669 | CM25: =AVERAGE(CI25:CL25) -> 163.63963 | CN25: =CL25+BS!CN55-BS!CN56 -> 166.68754 | CO25: =CN25+BS!CO55-BS!CO56 -> 167.92839 | CP25: =CO25+BS!CP55-BS!CP56 -> 169.16924 | CQ25: =CP25+BS!CQ55-BS!CQ56 -> 170.41009 | CR25: =AVERAGE(CN25:CQ25) -> 168.54882 | CS25: =CQ25+BS!CS55-BS!CS56 -> 171.68817 | CT25: =CS25+BS!CT55-BS!CT56 -> 172.96624 | CU25: =CT25+BS!CU55-BS!CU56 -> 174.24432 | CV25: =CU25+BS!CV55-BS!CV56 -> 175.5224 | CW25: =AVERAGE(CS25:CV25) -> 173.60528 | CX25: =CV25+BS!CX55-BS!CX56 -> 176.83881 | CY25: =CX25+BS!CY55-BS!CY56 -> 178.15523 | CZ25: =CY25+BS!CZ55-BS!CZ56 -> 179.47165 | DA25: =CZ25+BS!DA55-BS!DA56 -> 180.78807 | DB25: =AVERAGE(CX25:DA25) -> 178.81344 | DE25: 404 | DF25: 628 | DG25: 675 | DH25: 724 | DI25: 740 | DJ25: 752 | DK25: 801
A26: Diluted shares outstanding | B26: 4.591 | C26: 4.722 | D26: 36.931 | E26: =F26*4-SUM(B26:D26) -> -27.044 | F26: 4.8 | G26: 5.289 | H26: 5.494 | I26: 44.944 | J26: =K26*4-SUM(G26:I26) -> 49.089 | K26: 26.204 | L26: 50.439 | M26: 51.445 | N26: 52.012 | O26: =P26*4-SUM(L26:N26) -> 52.408 | P26: 51.576 | Q26: 53.043 | R26: 53.088 | S26: 53.447 | T26: =U26*4-SUM(Q26:S26) -> 54.838 | U26: 53.604 | V26: 54.132 | W26: 54.551 | X26: 60.57 | Y26: =Z26*4-SUM(V26:X26) -> 62.139 | Z26: 57.848 | AA26: 62.831 | AB26: 68.224 | AC26: 70.456 | AD26: =AE26*4-SUM(AA26:AC26) -> 76.709 | AE26: 69.555 | AF26: 78.287 | AG26: 79.069 | AH26: 80.908 | AI26: =AJ26*4-SUM(AF26:AH26) -> 85.78 | AJ26: 81.011 | AK26: 86.689 | AL26: 88.077 | AM26: 92.558 | AN26: =AO26*4-SUM(AK26:AM26) -> 94.908 | AO26: 90.558 | AP26: 95.578 | AQ26: 96.579 | AR26: 97.052 | AS26: =AT26*4-SUM(AP26:AR26) -> 104.423 | AT26: 98.408 | AU26: 111.767 | AV26: 113.69 | AW26: 115.171 | AX26: =AY26*4-SUM(AU26:AW26) -> 119.36 | AY26: 114.997 | AZ26: 120.814 | BA26: 122.853 | BB26: 123.775 | BC26: =BD26*4-SUM(AZ26:BB26) -> 131.43 | BD26: 124.718 | BE26: 134.75 | BF26: 136.388 | BG26: 137.187 | BH26: =BI26*4-SUM(BE26:BG26) -> 138.559 | BI26: 136.721 | BJ26: =BH26+BS!BJ55-BS!BJ56 -> 139.59819 | BK26: =BJ26+BS!BK55-BS!BK56 -> 140.63738 | BL26: =BK26+BS!BL55-BS!BL56 -> 141.67658 | BM26: =BL26+BS!BM55-BS!BM56 -> 142.71577 | BN26: =AVERAGE(BJ26:BM26) -> 141.15698 | BO26: =BM26+BS!BO55-BS!BO56 -> 143.78614 | BP26: =BO26+BS!BP55-BS!BP56 -> 144.85651 | BQ26: =BP26+BS!BQ55-BS!BQ56 -> 145.92687 | BR26: =BQ26+BS!BR55-BS!BR56 -> 146.99724 | BS26: =AVERAGE(BO26:BR26) -> 145.39169 | BT26: =BR26+BS!BT55-BS!BT56 -> 148.09972 | BU26: =BT26+BS!BU55-BS!BU56 -> 149.2022 | BV26: =BU26+BS!BV55-BS!BV56 -> 150.30468 | BW26: =BV26+BS!BW55-BS!BW56 -> 151.40716 | BX26: =AVERAGE(BT26:BW26) -> 149.75344 | BY26: =BW26+BS!BY55-BS!BY56 -> 152.54271 | BZ26: =BY26+BS!BZ55-BS!BZ56 -> 153.67827 | CA26: =BZ26+BS!CA55-BS!CA56 -> 154.81382 | CB26: =CA26+BS!CB55-BS!CB56 -> 155.94938 | CC26: =AVERAGE(BY26:CB26) -> 154.24604 | CD26: =CB26+BS!CD55-BS!CD56 -> 157.119 | CE26: =CD26+BS!CE55-BS!CE56 -> 158.28862 | CF26: =CE26+BS!CF55-BS!CF56 -> 159.45824 | CG26: =CF26+BS!CG55-BS!CG56 -> 160.62786 | CH26: =AVERAGE(CD26:CG26) -> 158.87343 | CI26: =CG26+BS!CI55-BS!CI56 -> 161.83257 | CJ26: =CI26+BS!CJ55-BS!CJ56 -> 163.03727 | CK26: =CJ26+BS!CK55-BS!CK56 -> 164.24198 | CL26: =CK26+BS!CL55-BS!CL56 -> 165.44669 | CM26: =AVERAGE(CI26:CL26) -> 163.63963 | CN26: =CL26+BS!CN55-BS!CN56 -> 166.68754 | CO26: =CN26+BS!CO55-BS!CO56 -> 167.92839 | CP26: =CO26+BS!CP55-BS!CP56 -> 169.16924 | CQ26: =CP26+BS!CQ55-BS!CQ56 -> 170.41009 | CR26: =AVERAGE(CN26:CQ26) -> 168.54882 | CS26: =CQ26+BS!CS55-BS!CS56 -> 171.68817 | CT26: =CS26+BS!CT55-BS!CT56 -> 172.96624 | CU26: =CT26+BS!CU55-BS!CU56 -> 174.24432 | CV26: =CU26+BS!CV55-BS!CV56 -> 175.5224 | CW26: =AVERAGE(CS26:CV26) -> 173.60528 | CX26: =CV26+BS!CX55-BS!CX56 -> 176.83881 | CY26: =CX26+BS!CY55-BS!CY56 -> 178.15523 | CZ26: =CY26+BS!CZ55-BS!CZ56 -> 179.47165 | DA26: =CZ26+BS!DA55-BS!DA56 -> 180.78807 | DB26: =AVERAGE(CX26:DA26) -> 178.81344 | DF26: =+DF25/DE25-1 -> 0.55445545 | DG26: =+DG25/DF25-1 -> 0.074840764 | DH26: =+DH25/DG25-1 -> 0.072592593 | DI26: =+DI25/DH25-1 -> 0.022099448 | DJ26: =+DJ25/DI25-1 -> 0.016216216 | DK26: =+DK25/DJ25-1 -> 0.065159574
DE27: 841 | DF27: 1105 | DG27: 1204 | DH27: 1278 | DI27: 1336 | DJ27: 1349 | DK27: 1490
A28: GAAP basic E.P.S. | B28: =B23/B25 -> -2.0945328 | C28: =C23/C25 -> -0.10885218 | D28: =D23/D25 -> 0.035347308 | E28: =E23/E25 -> 0.95717984 | F28: =F23/F25 -> -1.0733333 | G28: =G23/G25 -> -1.8914729 | H28: =H23/H25 -> -3.5822716 | I28: =I23/I25 -> -0.39146493 | ... K28: =K23/K25 -> -2.73588 | L28: =L21/L25 -> -0.17218819 | M28: =M21/M25 -> -0.45011177 | N28: =N21/N25 -> -0.50021149 | O28: =O23/O25 -> -0.74351244 | P28: =P21/P25 -> -1.8567745 | Q28: =Q23/Q25 -> -0.67783085 | R28: =R23/R25 -> -0.52121007 | S28: =S21/S25 -> -0.50739985 | T28: =T21/T25 -> -0.84333241 | U28: =U21/U25 -> -2.5569103 | V28: =V21/V25 -> -0.60727481 | W28: =W21/W25 -> -0.62004363 | X28: =X21/X25 -> -0.48895493 | Y28: =Y21/Y25 -> -0.51241571 | Z28: =Z21/Z25 -> -2.2153575 | ... DB28: =DB21/DB25 -> 9.5297881 | DF28: =+DF27/DE27-1 -> 0.31391201 | DG28: =+DG27/DF27-1 -> 0.08959276 | DH28: =+DH27/DG27-1 -> 0.061461794 | DI28: =+DI27/DH27-1 -> 0.045383412 | DJ28: =+DJ27/DI27-1 -> 0.0097305389 | DK28: =+DK27/DJ27-1 -> 0.10452187
A29: GAAP diluted E.P.S. | B29: =B23/B26 -> -2.0945328 | C29: =C23/C26 -> -0.10885218 | D29: =(D23+1)/D26 -> 0.031734857 | E29: =E23/E26 -> -0.1777104 | F29: =F23/F26 -> -1.0733333 | G29: =G23/G26 -> -1.8914729 | H29: =H23/H26 -> -3.5822716 | I29: =I23/I26 -> -0.39146493 | J29: =J23/J26 -> -0.49730082 | K29: =K23/K26 -> -2.73588 | L29: =L21/L26 -> -0.17218819 | M29: =M21/M26 -> -0.45011177 | N29: =N21/N26 -> -0.50021149 | O29: =O23/O26 -> -0.74351244 | P29: =P21/P26 -> -1.8567745 | Q29: =(Q21-1.042)/Q26 -> -0.69760383 | R29: =R23/R26 -> -0.52121007 | S29: =S21/S26 -> -0.50739985 | T29: =(T21-0.106)/T26 -> -0.83168606 | U29: =(U21-1.148)/U26 -> -2.5643982 | V29: =V21/V26 -> -0.60727481 | W29: =W21/W26 -> -0.62004363 | X29: =X21/X26 -> -0.48895493 | Y29: =Y21/Y26 -> -0.51241571 | Z29: =Z21/Z26 -> -2.2153575 | AA29: =AA21/AA26 -> -0.54258248 | AB29: =AB21/AB26 -> -0.47514071 | AC29: =AC21/AC26 -> -0.53260191 | ... DB29: =DB21/DB26 -> 9.5297881
A31: EBITDA | B31: =B14+CF!B9 -> -7.282 | C31: =C14+CF!C9 -> 1.103 | D31: =D14+CF!D9 -> 6.141 | E31: =E14+CF!E9 -> 5.851 | F31: =F14+CF!F9 -> 5.813 | G31: =G14+CF!G9 -> -4.636 | H31: =H14+CF!H9 -> -14.139 | I31: =I14+CF!I9 -> -19.352 | ... DB31: =DB14+CF!DB9 -> 1645.6514
A33: Year-Over-Year
A34: =A7 -> Net Sales | B34: -- | C34: -- | D34: -- | E34: -- | F34: -- | G34: =G7/B7-1 -> 0.73786408 | H34: =H7/C7-1 -> 0.25814823 | I34: =I7/D7-1 -> -0.029238881 | J34: =J7/E7-1 -> 0.060700826 | K34: =K7/F7-1 -> 0.19502916 | L34: =L7/G7-1 -> 0.30498577 | M34: =M7/H7-1 -> 0.15297092 | N34: =N7/I7-1 -> 0.19963937 | ... DB34: =DB7/CW7-1 -> 0.08321302
A35: Gross Profit | B35: -- | C35: -- | D35: -- | E35: -- | F35: -- | G35: =G9/B9-1 -> 0.98262396 | H35: =H9/C9-1 -> 0.15057663 | I35: =I9/D9-1 -> -0.43171997 | J35: =J9/E9-1 -> -0.2249651 | K35: =K9/F9-1 -> -0.041820677 | L35: =L9/G9-1 -> 0.30851629 | M35: =M9/H9-1 -> 0.085559287 | N35: =N9/I9-1 -> 0.35693052 | ... DB35: =DB9/CW9-1 -> 0.08827692
A36: =A10 -> Research & Development | B36: -- | C36: -- | D36: -- | E36: -- | F36: -- | G36: =G10/B10-1 -> 0.30991159 | H36: =H10/C10-1 -> 0.63537118 | I36: =I10/D10-1 -> 0.67795059 | J36: =J10/E10-1 -> 0.77866667 | K36: =K10/F10-1 -> 0.60253296 | L36: =L10/G10-1 -> 0.55577265 | M36: =M10/H10-1 -> 0.52781486 | N36: =N10/I10-1 -> 0.5464831 | ... BN36: =BN10/BI10-1 -> 0.29464357 | BO36: =BS36 -> 0.09 | BP36: =BS36 -> 0.09 | BQ36: =BS36 -> 0.09 | BR36: =BS36 -> 0.09 | BS36: 0.09 | BT36: =BX36 -> 0.08 | BU36: =BX36 -> 0.08 | BV36: =BX36 -> 0.08 | BW36: =BX36 -> 0.08 | BX36: 0.08 | BY36: =CC36 -> 0.075 | BZ36: =CC36 -> 0.075 | CA36: =CC36 -> 0.075 | CB36: =CC36 -> 0.075 | CC36: 0.075 | CD36: =CH36 -> 0.07 | CE36: =CH36 -> 0.07 | CF36: =CH36 -> 0.07 | CG36: =CH36 -> 0.07 | CH36: 0.07 | CI36: =CM36 -> 0.07 | CJ36: =CM36 -> 0.07 | CK36: =CM36 -> 0.07 | CL36: =CM36 -> 0.07 | CM36: 0.07 | CN36: =CR36 -> 0.07 | CO36: =CR36 -> 0.07 | CP36: =CR36 -> 0.07 | CQ36: =CR36 -> 0.07 | CR36: =CM36 -> 0.07 | CS36: =CW36 -> 0.07 | CT36: =CW36 -> 0.07 | CU36: =CW36 -> 0.07 | CV36: =CW36 -> 0.07 | CW36: =CR36 -> 0.07 | CX36: =DB36 -> 0.07 | CY36: =DB36 -> 0.07 | CZ36: =DB36 -> 0.07 | DA36: =DB36 -> 0.07 | DB36: =CW36 -> 0.07
A37: =A11 -> Selling, General & Administrative | B37: -- | C37: -- | D37: -- | E37: -- | F37: -- | G37: =G11/B11-1 -> 0.61617637 | H37: =H11/C11-1 -> 1.019849 | I37: =I11/D11-1 -> 0.70950132 | J37: =J11/E11-1 -> 0.65905499 | K37: =K11/F11-1 -> 0.74203953 | L37: =L11/G11-1 -> 0.30849004 | M37: =M11/H11-1 -> 0.18304493 | N37: =N11/I11-1 -> 0.25360603 | ... BN37: =BN11/BI11-1 -> 0.0008643057 | BO37: =BS37 -> 0.09 | BP37: =BS37 -> 0.09 | BQ37: =BS37 -> 0.09 | BR37: =BS37 -> 0.09 | BS37: 0.09 | BT37: =BX37 -> 0.08 | BU37: =BX37 -> 0.08 | BV37: =BX37 -> 0.08 | BW37: =BX37 -> 0.08 | BX37: 0.08 | BY37: =CC37 -> 0.075 | BZ37: =CC37 -> 0.075 | CA37: =CC37 -> 0.075 | CB37: =CC37 -> 0.075 | CC37: 0.075 | CD37: =CH37 -> 0.07 | CE37: =CH37 -> 0.07 | CF37: =CH37 -> 0.07 | CG37: =CH37 -> 0.07 | CH37: 0.07 | CI37: =CM37 -> 0.06 | CJ37: =CM37 -> 0.06 | CK37: =CM37 -> 0.06 | CL37: =CM37 -> 0.06 | CM37: 0.06 | CN37: =CR37 -> 0.06 | CO37: =CR37 -> 0.06 | CP37: =CR37 -> 0.06 | CQ37: =CR37 -> 0.06 | CR37: 0.06 | CS37: =CW37 -> 0.06 | CT37: =CW37 -> 0.06 | CU37: =CW37 -> 0.06 | CV37: =CW37 -> 0.06 | CW37: 0.06 | CX37: =DB37 -> 0.06 | CY37: =DB37 -> 0.06 | CZ37: =DB37 -> 0.06 | DA37: =DB37 -> 0.06 | DB37: 0.06
A38: Operating Expenses | B38: -- | C38: -- | D38: -- | E38: -- | F38: -- | G38: =G13/B13-1 -> 0.54569792 | H38: =H13/C13-1 -> 0.93193543 | I38: =I13/D13-1 -> 0.7028295 | J38: =J13/E13-1 -> 0.68261193 | K38: =K13/F13-1 -> 0.71197088 | L38: =L13/G13-1 -> 0.35671482 | M38: =M13/H13-1 -> 0.24977747 | N38: =N13/I13-1 -> 0.31463387 | ... DB38: =DB13/CW13-1 -> 0.064132519
A39: Operating Income (EBIT) | B39: -- | C39: -- | D39: -- | E39: -- | F39: -- | G39: =G14/B14-1 -> -0.13801154 | H39: =H14/C14-1 -> 11.839834 | I39: =I14/D14-1 -> -5.3400293 | J39: =J14/E14-1 -> -4.9670707 | K39: =K14/F14-1 -> -90.981955 | L39: =L14/G14-1 -> 0.53018958 | M39: =M14/H14-1 -> 0.45520941 | N39: =N14/I14-1 -> 0.28513572 | ... DB39: =DB14/CW14-1 -> 0.14604964
A40: EBITDA | B40: -- | C40: -- | D40: -- | E40: -- | F40: -- | G40: =G31/B31-1 -> -0.36336171 | H40: =H31/C31-1 -> -13.818676 | I40: =I31/D31-1 -> -4.1512783 | J40: =J31/E31-1 -> -3.7646556 | K40: =K31/F31-1 -> -10.341648 | L40: =L31/G31-1 -> 0.81427955 | M40: =M31/H31-1 -> 0.50512766 | N40: =N31/I31-1 -> 0.28699876 | ... DB40: =DB31/CW31-1 -> 0.14038395
A41: =A18 -> Income Before Taxes | B41: -- | C41: -- | D41: -- | E41: -- | F41: -- | G41: =G18/B18-1 -> 0.040349418 | H41: =H18/C18-1 -> 37.289883 | I41: =I18/D18-1 -> -5.7341568 | J41: =J18/E18-1 -> -19.30941 | K41: =K18/F18-1 -> 12.640334 | L41: =L18/G18-1 -> -0.13184726 | M41: =M18/H18-1 -> 0.17656623 | N41: =N18/I18-1 -> 0.46988088 | ... DB41: =DB18/CW18-1 -> 0.15860075
A42: Net Loss | B42: -- | C42: -- | D42: -- | E42: -- | F42: -- | G42: =G21/B21-1 -> 0.040349418 | H42: =H21/C21-1 -> 37.289883 | I42: =I21/D21-1 -> -5.7341568 | J42: =J21/E21-1 -> -19.30941 | K42: =K21/F21-1 -> 12.640334 | L42: =L21/G21-1 -> -0.13184726 | M42: =M21/H21-1 -> 0.17656623 | N42: =N21/I21-1 -> 0.4757232 | ... DB42: =DB21/CW21-1 -> 0.15860075
A43: Comprehesive Loss | B43: -- | C43: -- | D43: -- | E43: -- | F43: -- | G43: =G23/B23-1 -> 0.040349418 | H43: =H23/C23-1 -> 37.289883 | I43: =I23/D23-1 -> -103.2907 | J43: =J23/E23-1 -> -6.079484 | K43: =K23/F23-1 -> 12.915179 | L43: =L23/G23-1 -> -0.31287485 | M43: =M23/H23-1 -> 0.14872212 | N43: =N23/I23-1 -> 0.51335683 | ... DB43: =DB23/CW23-1 -> 0.15855762
A45: GAAP diluted EPS | B45: -- | C45: -- | D45: -- | E45: -- | F45: -- | G45: =G29/B29-1 -> -0.096947594 | H45: =H29/C29-1 -> 31.909507 | I45: =I29/D29-1 -> -13.335488 | J45: =J29/E29-1 -> 1.7983777 | K45: =K29/F29-1 -> 1.5489565 | L45: =L29/G29-1 -> -0.90896608 | M45: =M29/H29-1 -> -0.87435018 | N45: =N29/I29-1 -> 0.27779386 | ... DB45: =DB29/CW29-1 -> 0.12485509
...

Sheet Rev
A1: =+IS!A1 -> Natera Inc. (NASDAQ: NTRA)
A2: Revenue Build
A3: =+IS!A3 -> $ millions except per share data, FY ending Dec
B5: =+IS!B5 -> Mar | C5: =+IS!C5 -> Jun | D5: =+IS!D5 -> Sep | E5: =+IS!E5 -> Dec | F5: =+IS!F5 -> 41974 | G5: =+IS!G5 -> Mar | H5: =+IS!H5 -> Jun | I5: =+IS!I5 -> Sep | ... DB5: =+IS!DB5 -> 49279
B6: =+IS!B6 -> 1Q14A | C6: =+IS!C6 -> 2Q14A | D6: =+IS!D6 -> 3Q14A | E6: =+IS!E6 -> 4Q14A | F6: =+IS!F6 -> FY14A | G6: =+IS!G6 -> 1Q15A | H6: =+IS!H6 -> 2Q15A | I6: =+IS!I6 -> 3Q15A | ... DB6: =+IS!DB6 -> FY34E
A7: Revenue Build
A8: Consolidated
A9: Product Revenues | G9: =+G31 -> 46.899 | H9: =+H31 -> 44.519 | I9: =+I31 -> 44.423 | J9: =+J31 -> 52.327 | K9: =+G9+H9+I9+J9 -> 188.168 | L9: =+L31 -> 61.136 | M9: =+M31 -> 51.231 | N9: =+N31 -> 53.09 | O9: =+O31 -> 48.511 | P9: =+L9+M9+N9+O9 -> 213.968 | Q9: =+Q31 -> 45.913 | R9: =+R31 -> 52.276 | S9: =+S31 -> 55.331 | T9: =+T31 -> 51.969 | U9: =+Q9+R9+S9+T9 -> 205.489 | V9: =+V31 -> 54.269 | W9: =+W31 -> 60.353 | X9: =+X31 -> 62.662 | Y9: =+Y31 -> 63.082 | Z9: =+V9+W9+X9+Y9 -> 240.366 | AA9: =+AA31 -> 63.364 | AB9: =+AB31 -> 65.099 | AC9: =+AC31 -> 66.936 | AD9: =+AD31 -> 74.482 | AE9: =+AA9+AB9+AC9+AD9 -> 269.881 | AF9: =+AF31 -> 87.046 | AG9: =+AG31 -> 80.414 | AH9: =+AH31 -> 93.286 | AI9: =+AI31 -> 106.465 | AJ9: =+AF9+AG9+AH9+AI9 -> 367.211 | AK9: =+AK31 -> 118.382 | AL9: =+AL31 -> 137.232 | AM9: =+AM31 -> 150.651 | AN9: =+AN31 -> 160.884 | AO9: =+AK9+AL9+AM9+AN9 -> 567.149 | AP9: =+AP31 -> 190.002 | AQ9: =+AQ31 -> 194.582 | AR9: =+AR31 -> 199.831 | AS9: =+AS31 -> 212.892 | AT9: =+AP9+AQ9+AR9+AS9 -> 797.307 | AU9: =+AU31 -> 237.797 | AV9: =+AV31 -> 258.256 | AW9: =+AW31 -> 265.218 | AX9: =+AX31 -> 307.251 | AY9: =+AU9+AV9+AW9+AX9 -> 1068.522 | AZ9: =+AZ31 -> 364.672 | BA9: =+BA31 -> 411.364 | BB9: =+BB31 -> 436.127 | BC9: =+BC31 -> 472.911 | BD9: =+AZ9+BA9+BB9+BC9 -> 1685.074 | BE9: =+BE31 -> 500.036 | BF9: =+BF31 -> 544.427 | BG9: =+BG31 -> 590.197 | BH9: =+BH31 -> 661.16 | BI9: =+BE9+BF9+BG9+BH9 -> 2295.82 | BJ9: =+BJ31 -> 614.64917 | BK9: =+BK31 -> 648.22617 | BL9: =+BL31 -> 674.49647 | BM9: =+BM31 -> 710.74987 | BN9: =+BJ9+BK9+BL9+BM9 -> 2648.1217 | BO9: =+BO31 -> 760.17061 | BP9: =+BP31 -> 760.6734 | BQ9: =+BQ31 -> 788.56084 | BR9: =+BR31 -> 808.33937 | BS9: =+BO9+BP9+BQ9+BR9 -> 3117.7442 | BT9: =+BT31 -> 874.82355 | BU9: =+BU31 -> 883.53624 | BV9: =+BV31 -> 911.33955 | BW9: =+BW31 -> 935.55769 | BX9: =+BT9+BU9+BV9+BW9 -> 3605.257 | BY9: =+BY31 -> 1010.6394 | BZ9: =+BZ31 -> 1014.2485 | CA9: =+CA31 -> 1049.1024 | CB9: =+CB31 -> 1071.3304 | CC9: =+BY9+BZ9+CA9+CB9 -> 4145.3207 | CD9: =+CD31 -> 1152.7464 | CE9: =+CE31 -> 1159.0417 | CF9: =+CF31 -> 1194.1817 | CG9: =+CG31 -> 1219.9657 | CH9: =+CD9+CE9+CF9+CG9 -> 4725.9354 | CI9: =+CI31 -> 1295.9962 | CJ9: =+CJ31 -> 1298.1168 | CK9: =+CK31 -> 1330.1733 | CL9: =+CL31 -> 1352.6104 | CM9: =+CI9+CJ9+CK9+CL9 -> 5276.8967 | CN9: =+CN31 -> 1432.8003 | CO9: =+CO31 -> 1434.8961 | CP9: =+CP31 -> 1467.8442 | CQ9: =+CQ31 -> 1491.1037 | CR9: =+CN9+CO9+CP9+CQ9 -> 5826.6444 | CS9: =+CS31 -> 1576.2991 | CT9: =+CT31 -> 1579.0696 | CU9: =+CU31 -> 1613.8538 | CV9: =+CV31 -> 1638.6501 | CW9: =+CS9+CT9+CU9+CV9 -> 6407.8727 | CX9: =+CX31 -> 1714.7687 | CY9: =+CY31 -> 1713.6956 | CZ9: =+CZ31 -> 1745.6647 | DA9: =+DA31 -> 1767.4672 | DB9: =+CX9+CY9+CZ9+DA9 -> 6941.5962
A10: % yoy | G10: -- | H10: -- | I10: -- | J10: -- | K10: -- | L10: =+L9/G9-1 -> 0.30356724 | M10: =+M9/H9-1 -> 0.15076709 | N10: =+N9/I9-1 -> 0.19510164 | O10: =+O9/J9-1 -> -0.072926023 | P10: =+P9/K9-1 -> 0.13711152 | Q10: =+Q9/L9-1 -> -0.24900222 | R10: =+R9/M9-1 -> 0.020397806 | S10: =+S9/N9-1 -> 0.042211339 | ... DB10: =+DB9/CW9-1 -> 0.083291843
A11: % seq | G11: -- | H11: =+H9/G9-1 -> -0.050747351 | I11: =+I9/H9-1 -> -0.0021563827 | J11: =+J9/I9-1 -> 0.17792585 | K11: -- | L11: =+L9/J9-1 -> 0.16834521 | M11: =+M9/L9-1 -> -0.16201583 | N11: =+N9/M9-1 -> 0.036286623 | O11: =+O9/N9-1 -> -0.086249765 | P11: -- | Q11: =+Q9/O9-1 -> -0.053554864 | R11: =+R9/Q9-1 -> 0.1385882 | S11: =+S9/R9-1 -> 0.058439819 | T11: =+T9/S9-1 -> -0.060761598 | U11: -- | V11: =+V9/T9-1 -> 0.044257153 | W11: =+W9/V9-1 -> 0.1121082 | X11: =+X9/W9-1 -> 0.038258247 | Y11: =+Y9/X9-1 -> 0.0067026268 | Z11: -- | AA11: =+AA9/Y9-1 -> 0.0044703719 | AB11: =+AB9/AA9-1 -> 0.027381478 | AC11: =+AC9/AB9-1 -> 0.028218559 | AD11: =+AD9/AC9-1 -> 0.11273455 | AE11: -- | AF11: =+AF9/AD9-1 -> 0.16868505 | AG11: =+AG9/AF9-1 -> -0.076189601 | AH11: =+AH9/AG9-1 -> 0.16007163 | AI11: =+AI9/AH9-1 -> 0.14127522 | AJ11: -- | AK11: =+AK9/AI9-1 -> 0.1119335 | AL11: =+AL9/AK9-1 -> 0.15923029 | AM11: =+AM9/AL9-1 -> 0.097783316 | AN11: =+AN9/AM9-1 -> 0.067925205 | AO11: -- | AP11: =+AP9/AN9-1 -> 0.18098754 | AQ11: =+AQ9/AP9-1 -> 0.024105009 | AR11: =+AR9/AQ9-1 -> 0.026975774 | AS11: =+AS9/AR9-1 -> 0.065360229 | AT11: -- | AU11: =+AU9/AS9-1 -> 0.1169842 | AV11: =+AV9/AU9-1 -> 0.086035568 | AW11: =+AW9/AV9-1 -> 0.026957747 | AX11: =+AX9/AW9-1 -> 0.15848472 | AY11: -- | AZ11: =+AZ9/AX9-1 -> 0.18688629 | BA11: =+BA9/AZ9-1 -> 0.12803835 | BB11: =+BB9/BA9-1 -> 0.060197295 | BC11: =+BC9/BB9-1 -> 0.084342405 | BD11: -- | BE11: =+BE9/BC9-1 -> 0.057357515 | BF11: =+BF9/BE9-1 -> 0.088775608 | BG11: =+BG9/BF9-1 -> 0.084070041 | BH11: =+BH9/BG9-1 -> 0.12023612 | BI11: -- | BJ11: =+BJ9/BH9-1 -> -0.070347315 | BK11: =+BK9/BJ9-1 -> 0.054627917 | BL11: =+BL9/BK9-1 -> 0.040526439 | BM11: =+BM9/BL9-1 -> 0.05374883 | BN11: -- | BO11: =+BO9/BM9-1 -> 0.069533238 | BP11: =+BP9/BO9-1 -> 0.00066141344 | BQ11: =+BQ9/BP9-1 -> 0.03666152 | BR11: =+BR9/BQ9-1 -> 0.025081806 | BS11: -- | BT11: =+BT9/BR9-1 -> 0.082247863 | BU11: =+BU9/BT9-1 -> 0.0099593647 | BV11: =+BV9/BU9-1 -> 0.031468212 | BW11: =+BW9/BV9-1 -> 0.026574228 | BX11: -- | BY11: =+BY9/BW9-1 -> 0.080253458 | BZ11: =+BZ9/BY9-1 -> 0.0035710435 | CA11: =+CA9/BZ9-1 -> 0.034364266 | CB11: =+CB9/CA9-1 -> 0.021187683 | CC11: -- | CD11: =+CD9/CB9-1 -> 0.075995163 | CE11: =+CE9/CD9-1 -> 0.0054611374 | CF11: =+CF9/CE9-1 -> 0.03031815 | CG11: =+CG9/CF9-1 -> 0.021591392 | CH11: -- | CI11: =+CI9/CG9-1 -> 0.062321859 | CJ11: =+CJ9/CI9-1 -> 0.0016362308 | CK11: =+CK9/CJ9-1 -> 0.024694656 | CL11: =+CL9/CK9-1 -> 0.016867762 | CM11: -- | CN11: =+CN9/CL9-1 -> 0.059285304 | CO11: =+CO9/CN9-1 -> 0.0014627348 | CP11: =+CP9/CO9-1 -> 0.022962045 | CQ11: =+CQ9/CP9-1 -> 0.015846027 | CR11: -- | CS11: =+CS9/CQ9-1 -> 0.057135771 | CT11: =+CT9/CS9-1 -> 0.00175761 | CU11: =+CU9/CT9-1 -> 0.022028299 | CV11: =+CV9/CU9-1 -> 0.015364617 | CW11: -- | CX11: =+CX9/CV9-1 -> 0.046451995 | CY11: =+CY9/CX9-1 -> -0.00062575125 | CZ11: =+CZ9/CY9-1 -> 0.018655023 | DA11: =+DA9/CZ9-1 -> 0.012489547 | DB11: --
A13: Licensing and Other Revenues | G13: 0.536 | H13: 0.568 | I13: 0.498 | J13: 0.585 | K13: =+G13+H13+I13+J13 -> 2.187 | L13: 0.766 | M13: 0.753 | N13: 0.799 | O13: 0.788 | P13: =+L13+M13+N13+O13 -> 3.106 | Q13: 0.988 | R13: 1.341 | S13: 1.325 | T13: 1.796 | U13: =+Q13+R13+S13+T13 -> 5.45 | V13: 8.071 | W13: 2.716 | X13: 2.618 | Y13: 3.883 | Z13: =+V13+W13+X13+Y13 -> 17.288 | AA13: 3.46 | AB13: 9.256 | AC13: 10.973 | AD13: 8.758 | AE13: =+AA13+AB13+AC13+AD13 -> 32.447 | AF13: 6.966 | AG13: 6.058 | AH13: 4.857 | AI13: 5.913 | AJ13: =+AF13+AG13+AH13+AI13 -> 23.794 | AK13: 33.934 | AL13: 4.794 | AM13: 7.465 | AN13: 12.144 | AO13: =+AK13+AL13+AM13+AN13 -> 58.337 | AP13: 4.131 | AQ13: 3.618 | AR13: 10.806 | AS13: 4.36 | AT13: =+AP13+AQ13+AR13+AS13 -> 22.915 | AU13: 3.959 | AV13: 3.148 | AW13: 3.088 | AX13: 3.854 | AY13: =+AU13+AV13+AW13+AX13 -> 14.049 | AZ13: 3.069 | BA13: 1.987 | BB13: 3.631 | BC13: 3.15 | BD13: =+AZ13+BA13+BB13+BC13 -> 11.837 | BE13: 1.794 | BF13: 2.173 | BG13: 1.986 | BH13: =10.293-BE13-BF13-BG13 -> 4.34 | BI13: =+BE13+BF13+BG13+BH13 -> 10.293 | BJ13: =+BE13*(1+BJ14) -> 1.8837 | BK13: =+BF13*(1+BK14) -> 2.28165 | BL13: =+BG13*(1+BL14) -> 2.0853 | BM13: =+BH13*(1+BM14) -> 4.557 | BN13: =+BJ13+BK13+BL13+BM13 -> 10.80765 | BO13: =+BJ13*(1+BO14) -> 1.977885 | BP13: =+BK13*(1+BP14) -> 2.3957325 | BQ13: =+BL13*(1+BQ14) -> 2.189565 | BR13: =+BM13*(1+BR14) -> 4.78485 | BS13: =+BO13+BP13+BQ13+BR13 -> 11.348033 | BT13: =+BO13*(1+BT14) -> 2.0767793 | BU13: =+BP13*(1+BU14) -> 2.5155191 | BV13: =+BQ13*(1+BV14) -> 2.2990433 | BW13: =+BR13*(1+BW14) -> 5.0240925 | BX13: =+BT13+BU13+BV13+BW13 -> 11.915434 | BY13: =+BT13*(1+BY14) -> 2.1806182 | BZ13: =+BU13*(1+BZ14) -> 2.6412951 | CA13: =+BV13*(1+CA14) -> 2.4139954 | CB13: =+BW13*(1+CB14) -> 5.2752971 | CC13: =+BY13+BZ13+CA13+CB13 -> 12.511206 | CD13: =+BY13*(1+CD14) -> 2.2896491 | CE13: =+BZ13*(1+CE14) -> 2.7733598 | CF13: =+CA13*(1+CF14) -> 2.5346952 | CG13: =+CB13*(1+CG14) -> 5.539062 | CH13: =+CD13+CE13+CF13+CG13 -> 13.136766 | CI13: =+CD13*(1+CI14) -> 2.4041316 | CJ13: =+CE13*(1+CJ14) -> 2.9120278 | CK13: =+CF13*(1+CK14) -> 2.6614299 | CL13: =+CG13*(1+CL14) -> 5.8160151 | CM13: =+CI13+CJ13+CK13+CL13 -> 13.793604 | CN13: =+CI13*(1+CN14) -> 2.5243382 | CO13: =+CJ13*(1+CO14) -> 3.0576292 | CP13: =+CK13*(1+CP14) -> 2.7945014 | CQ13: =+CL13*(1+CQ14) -> 6.1068158 | CR13: =+CN13+CO13+CP13+CQ13 -> 14.483285 | CS13: =+CN13*(1+CS14) -> 2.6505551 | CT13: =+CO13*(1+CT14) -> 3.2105107 | CU13: =+CP13*(1+CU14) -> 2.9342265 | CV13: =+CQ13*(1+CV14) -> 6.4121566 | CW13: =+CS13+CT13+CU13+CV13 -> 15.207449 | CX13: =+CS13*(1+CX14) -> 2.7830828 | CY13: =+CT13*(1+CY14) -> 3.3710362 | CZ13: =+CU13*(1+CZ14) -> 3.0809378 | DA13: =+CV13*(1+DA14) -> 6.7327645 | DB13: =+CX13+CY13+CZ13+DA13 -> 15.967821
A14: % yoy | G14: -- | H14: -- | I14: -- | J14: -- | K14: -- | L14: =+L13/G13-1 -> 0.42910448 | M14: =+M13/H13-1 -> 0.32570423 | N14: =+N13/I13-1 -> 0.60441767 | O14: =+O13/J13-1 -> 0.34700855 | P14: =+P13/K13-1 -> 0.42021033 | Q14: =+Q13/L13-1 -> 0.28981723 | R14: =+R13/M13-1 -> 0.78087649 | S14: =+S13/N13-1 -> 0.6583229 | ... BI14: =+BI13/BD13-1 -> -0.13043846 | BJ14: 0.05 | BK14: 0.05 | BL14: 0.05 | BM14: 0.05 | BN14: =+BN13/BI13-1 -> 0.05 | BO14: 0.05 | BP14: 0.05 | BQ14: 0.05 | BR14: 0.05 | BS14: =+BS13/BN13-1 -> 0.05 | BT14: 0.05 | BU14: 0.05 | BV14: 0.05 | BW14: 0.05 | BX14: =+BX13/BS13-1 -> 0.05 | BY14: 0.05 | BZ14: 0.05 | CA14: 0.05 | CB14: 0.05 | CC14: =+CC13/BX13-1 -> 0.05 | CD14: 0.05 | CE14: 0.05 | CF14: 0.05 | CG14: 0.05 | CH14: =+CH13/CC13-1 -> 0.05 | CI14: 0.05 | CJ14: 0.05 | CK14: 0.05 | CL14: 0.05 | CM14: =+CM13/CH13-1 -> 0.05 | CN14: 0.05 | CO14: 0.05 | CP14: 0.05 | CQ14: 0.05 | CR14: =+CR13/CM13-1 -> 0.05 | CS14: 0.05 | CT14: 0.05 | CU14: 0.05 | CV14: 0.05 | CW14: =+CW13/CR13-1 -> 0.05 | CX14: 0.05 | CY14: 0.05 | CZ14: 0.05 | DA14: 0.05 | DB14: =+DB13/CW13-1 -> 0.05
