Workbook

Sheet Revenue Model
A1: Veracyte Inc. | BS1: Needham & Company, LLC
A2: Quarterly Revenue Model | BS2: Michael Matson ● (617) 457-0949
A3: ($ In Millions)
B5: 41699 | C5: 41791 | D5: 41883 | E5: 41974 | F5: 2014 | G5: 42064 | H5: 42156 | I5: 42248 | J5: 42339 | K5: 2015 | L5: 42430 | M5: 42522 | N5: 42614 | O5: 42705 | P5: 2016 | Q5: 42795 | R5: 42887 | S5: 42979 | T5: 43070 | U5: 2017 | V5: 43160 | W5: 43252 | X5: 43344 | Y5: 43435 | Z5: 2018 | AA5: 43525 | AB5: 43617 | AC5: 43709 | AD5: 43800 | AE5: 2019 | AF5: 43891 | AG5: 43983 | AH5: 44075 | AI5: 44166 | AJ5: 2020 | AK5: 44256 | AL5: 44348 | AM5: 44440 | AN5: 44531 | AO5: 2021 | AP5: 44621 | AQ5: 44713 | AR5: 44805 | AS5: 44896 | AT5: 2022 | AU5: 44986 | AV5: 45078 | AW5: 45170 | AX5: 45261 | AY5: 2023 | AZ5: 45352 | BA5: 45444 | BB5: 45536 | BC5: 45627 | BD5: 2024 | BE5: 45717 | BF5: 45809 | BG5: 45901 | BH5: 45992 | BI5: 2025 | BJ5: =DATE(YEAR(BE5)+1,MONTH(BE5),DAY(BE5)) -> 46082 | BK5: =DATE(YEAR(BF5)+1,MONTH(BF5),DAY(BF5)) -> 46174 | BL5: =DATE(YEAR(BG5)+1,MONTH(BG5),DAY(BG5)) -> 46266 | BM5: =DATE(YEAR(BH5)+1,MONTH(BH5),DAY(BH5)) -> 46357 | BN5: 2026E | BO5: =DATE(YEAR(BJ5)+1,MONTH(BJ5),DAY(BJ5)) -> 46447 | BP5: =DATE(YEAR(BK5)+1,MONTH(BK5),DAY(BK5)) -> 46539 | BQ5: =DATE(YEAR(BL5)+1,MONTH(BL5),DAY(BL5)) -> 46631 | BR5: =DATE(YEAR(BM5)+1,MONTH(BM5),DAY(BM5)) -> 46722 | BS5: 2027E
B6: Q114A | C6: Q214A | D6: Q314A | E6: Q414A | F6: Annual | G6: Q115A | H6: Q215A | I6: Q315A | J6: Q415A | K6: Annual | L6: Q116A | M6: Q216A | N6: Q316A | O6: Q416A | P6: Annual | Q6: Q117A | R6: Q217A | S6: Q317A | T6: Q417A | U6: Annual | V6: Q118A | W6: Q218A | X6: Q318A | Y6: Q418A | Z6: Annual | AA6: Q119A | AB6: Q219A | AC6: Q319A | AD6: Q419A | AE6: Annual | AF6: Q120A | AG6: Q220A | AH6: Q320A | AI6: Q420A | AJ6: Annual | AK6: Q121A | AL6: Q221A | AM6: Q321A | AN6: Q421A | AO6: Annual | AP6: Q122A | AQ6: Q222A | AR6: Q322A | AS6: Q422A | AT6: Annual | AU6: Q123A | AV6: Q223A | AW6: Q323A | AX6: Q423A | AY6: Annual | AZ6: Q124A | BA6: Q224A | BB6: Q324A | BC6: Q424A | BD6: Annual | BE6: Q125A | BF6: Q225A | BG6: Q325A | BH6: Q425A | BI6: Annual | BJ6: Q126E | BK6: Q226E | BL6: Q326E | BM6: Q426E | BN6: Annual | BO6: Q127E | BP6: Q227E | BQ6: Q327E | BR6: Q427E | BS6: Annual
A7: Revenue
A8: Testing Revenue | B8: 7.476 | C8: 8.677 | D8: 9.838 | E8: 12.199 | F8: =SUM(B8:E8) -> 38.19 | G8: 11.218 | H8: 11.908 | I8: 12.335 | J8: 14.042 | K8: =SUM(G8:J8) -> 49.503 | L8: 13.55 | M8: 14.675 | N8: 18.603 | O8: 18.257 | P8: =SUM(L8:O8) -> 65.085 | Q8: 16.432 | R8: 18.406 | S8: 17.519 | T8: 19.596 | U8: =SUM(Q8:T8) -> 71.953 | V8: 20.041 | W8: 22.301 | X8: 23.216 | Y8: 25.5 | Z8: =SUM(V8:Y8) -> 91.058 | AA8: 25.389 | AB8: 26.686 | AC8: 26.723 | AD8: 28.557 | AE8: =SUM(AA8:AD8) -> 107.355 | AF8: 26.991 | AG8: 15.212 | AH8: 28.27 | AI8: 31.497 | AJ8: =SUM(AF8:AI8) -> 101.97 | AK8: 33.078 | AL8: 50.793 | AM8: 50.897 | AN8: 53.414 | AO8: =SUM(AK8:AN8) -> 188.182 | AP8: 55.98 | AQ8: 59.718 | AR8: 64.577 | AS8: 70.269 | AT8: =SUM(AP8:AS8) -> 250.544 | AU8: 72.396 | AV8: 81.749 | AW8: 82.012 | AX8: 90.385 | AY8: =SUM(AU8:AX8) -> 326.542 | AZ8: 90.303 | BA8: 106.97 | BB8: 109.536 | BC8: 112.152 | BD8: =SUM(AZ8:BC8) -> 418.961 | BE8: 107.309 | BF8: 122.263 | BG8: 127.756 | BH8: 135.826 | BI8: =SUM(BE8:BH8) -> 493.154 | BJ8: =BJ28*BJ40/1000000 -> 126.5009 | BK8: =BK28*BK40/1000000 -> 143.52642 | BL8: =BL28*BL40/1000000 -> 142.9207 | BM8: =BM28*BM40/1000000 -> 149.698 | BN8: =SUM(BJ8:BM8) -> 562.64602 | BO8: =BO28*BO40/1000000 -> 140.28431 | BP8: =BP28*BP40/1000000 -> 159.27291 | BQ8: =BQ28*BQ40/1000000 -> 158.77311 | BR8: =BR28*BR40/1000000 -> 166.09808 | BS8: =SUM(BO8:BR8) -> 624.42842
A9: Product Revenue | B9: 0 | C9: 0 | D9: 0 | E9: 0 | F9: =SUM(B9:E9) -> 0 | G9: 0 | H9: 0 | I9: 0 | J9: 0 | K9: =SUM(G9:J9) -> 0 | L9: 0 | M9: 0 | N9: 0 | O9: 0 | P9: =SUM(L9:O9) -> 0 | Q9: 0 | R9: 0 | S9: 0 | T9: 0 | U9: =SUM(Q9:T9) -> 0 | V9: 0 | W9: 0 | X9: 0 | Y9: 0 | Z9: =SUM(V9:Y9) -> 0 | AA9: 0 | AB9: 0 | AC9: 0 | AD9: 0.923 | AE9: =SUM(AA9:AD9) -> 0.923 | AF9: 3.409 | AG9: 1.713 | AH9: 2.027 | AI9: 2.696 | AJ9: =SUM(AF9:AI9) -> 9.845 | AK9: 3.059 | AL9: 2.688 | AM9: 2.959 | AN9: 2.758 | AO9: =SUM(AK9:AN9) -> 11.464 | AP9: 2.979 | AQ9: 3.108 | AR9: 3.314 | AS9: 3.231 | AT9: =SUM(AP9:AS9) -> 12.632 | AU9: 3.892 | AV9: 4.011 | AW9: 4.02 | AX9: 3.665 | AY9: =SUM(AU9:AX9) -> 15.588 | AZ9: 3.537 | BA9: 3.906 | BB9: 3.188 | BC9: 3.019 | BD9: =SUM(AZ9:BC9) -> 13.65 | BE9: 3.58 | BF9: 3.598 | BG9: 3.301 | BH9: 3.848 | BI9: =SUM(BE9:BH9) -> 14.327 | BJ9: =BJ29*BJ41/1000000 -> 3.763765 | BK9: =BK29*BK41/1000000 -> 3.6978625 | BL9: =BL29*BL41/1000000 -> 3.204326 | BM9: =BM29*BM41/1000000 -> 3.6656435 | BN9: =SUM(BJ9:BM9) -> 14.331597 | BO9: =BO29*BO41/1000000 -> 3.8390403 | BP9: =BP29*BP41/1000000 -> 3.7718198 | BQ9: =BQ29*BQ41/1000000 -> 3.2684125 | BR9: =BR29*BR41/1000000 -> 3.7389564 | BS9: =SUM(BO9:BR9) -> 14.618229
A10: Biopharma and Other Revenue | B10: 0 | C10: 0 | D10: 0 | E10: 0 | F10: =SUM(B10:E10) -> 0 | G10: 0 | H10: 0 | I10: 0 | J10: 0 | K10: =SUM(G10:J10) -> 0 | L10: 0 | M10: 0 | N10: 0 | O10: 0 | P10: =SUM(L10:O10) -> 0 | Q10: 0 | R10: 0 | S10: 0 | T10: 0 | U10: =SUM(Q10:T10) -> 0 | V10: 0 | W10: 0.45 | X10: 0.25 | Y10: 0.25 | Z10: =SUM(V10:Y10) -> 0.95 | AA10: 4.14 | AB10: =1.45+2 -> 3.45 | AC10: =2.25+2 -> 4.25 | AD10: 0.25 | AE10: =SUM(AA10:AD10) -> 12.09 | AF10: 0.722 | AG10: 3.779 | AH10: 0.824 | AI10: 0.343 | AJ10: =SUM(AF10:AI10) -> 5.668 | AK10: 0.566 | AL10: 1.624 | AM10: 6.514 | AN10: 11.164 | AO10: =SUM(AK10:AN10) -> 19.868 | AP10: 8.824 | AQ10: 10.038 | AR10: 7.701 | AS10: 6.797 | AT10: =SUM(AP10:AS10) -> 33.36 | AU10: 6.134 | AV10: 4.562 | AW10: 4.076 | AX10: 4.149 | AY10: =SUM(AU10:AX10) -> 18.921 | AZ10: 3.004 | BA10: 3.552 | BB10: 3.136 | BC10: 3.461 | BD10: =SUM(AZ10:BC10) -> 13.153 | BE10: 3.584 | BF10: 4.303 | BG10: 0.815 | BH10: 0.962 | BI10: =SUM(BE10:BH10) -> 9.664 | BJ10: =BE10*(1+BJ16) -> 0 | BK10: =BF10*(1+BK16) -> 0 | BL10: =BG10*(1+BL16) -> 0 | BM10: =BH10*(1+BM16) -> 0 | BN10: =SUM(BJ10:BM10) -> 0 | BO10: =BJ10*(1+BO16) -> 0 | BP10: =BK10*(1+BP16) -> 0 | BQ10: =BL10*(1+BQ16) -> 0 | BR10: =BM10*(1+BR16) -> 0 | BS10: =SUM(BO10:BR10) -> 0
A11: Total Revenue | B11: =SUM(B8:B10) -> 7.476 | C11: =SUM(C8:C10) -> 8.677 | D11: =SUM(D8:D10) -> 9.838 | E11: =SUM(E8:E10) -> 12.199 | F11: =SUM(B11:E11) -> 38.19 | G11: =SUM(G8:G10) -> 11.218 | H11: =SUM(H8:H10) -> 11.908 | I11: =SUM(I8:I10) -> 12.335 | J11: =SUM(J8:J10) -> 14.042 | K11: =SUM(G11:J11) -> 49.503 | L11: =SUM(L8:L10) -> 13.55 | M11: =SUM(M8:M10) -> 14.675 | N11: =SUM(N8:N10) -> 18.603 | O11: =SUM(O8:O10) -> 18.257 | P11: =SUM(L11:O11) -> 65.085 | Q11: =SUM(Q8:Q10) -> 16.432 | R11: =SUM(R8:R10) -> 18.406 | S11: =SUM(S8:S10) -> 17.519 | T11: =SUM(T8:T10) -> 19.596 | U11: =SUM(Q11:T11) -> 71.953 | V11: =SUM(V8:V10) -> 20.041 | W11: =SUM(W8:W10) -> 22.751 | X11: =SUM(X8:X10) -> 23.466 | Y11: =SUM(Y8:Y10) -> 25.75 | Z11: =SUM(V11:Y11) -> 92.008 | AA11: =SUM(AA8:AA10) -> 29.529 | AB11: =SUM(AB8:AB10) -> 30.136 | AC11: =SUM(AC8:AC10) -> 30.973 | AD11: =SUM(AD8:AD10) -> 29.73 | AE11: =SUM(AA11:AD11) -> 120.368 | AF11: =SUM(AF8:AF10) -> 31.122 | AG11: =SUM(AG8:AG10) -> 20.704 | AH11: =SUM(AH8:AH10) -> 31.121 | AI11: =SUM(AI8:AI10) -> 34.536 | AJ11: =SUM(AF11:AI11) -> 117.483 | AK11: =SUM(AK8:AK10) -> 36.703 | AL11: =SUM(AL8:AL10) -> 55.105 | AM11: =SUM(AM8:AM10) -> 60.37 | AN11: =SUM(AN8:AN10) -> 67.336 | AO11: =SUM(AK11:AN11) -> 219.514 | AP11: =SUM(AP8:AP10) -> 67.783 | AQ11: =SUM(AQ8:AQ10) -> 72.864 | AR11: =SUM(AR8:AR10) -> 75.592 | AS11: =SUM(AS8:AS10) -> 80.297 | AT11: =SUM(AP11:AS11) -> 296.536 | AU11: =SUM(AU8:AU10) -> 82.422 | AV11: =SUM(AV8:AV10) -> 90.322 | AW11: =SUM(AW8:AW10) -> 90.108 | AX11: =SUM(AX8:AX10) -> 98.199 | AY11: =SUM(AU11:AX11) -> 361.051 | AZ11: =SUM(AZ8:AZ10) -> 96.844 | BA11: =SUM(BA8:BA10) -> 114.428 | BB11: =SUM(BB8:BB10) -> 115.86 | BC11: =SUM(BC8:BC10) -> 118.632 | BD11: =SUM(AZ11:BC11) -> 445.764 | BE11: =SUM(BE8:BE10) -> 114.473 | BF11: =SUM(BF8:BF10) -> 130.164 | BG11: =SUM(BG8:BG10) -> 131.872 | BH11: =SUM(BH8:BH10) -> 140.636 | BI11: =SUM(BE11:BH11) -> 517.145 | BJ11: =SUM(BJ8:BJ10) -> 130.26467 | BK11: =SUM(BK8:BK10) -> 147.22429 | BL11: =SUM(BL8:BL10) -> 146.12503 | BM11: =SUM(BM8:BM10) -> 153.36364 | BN11: =SUM(BJ11:BM11) -> 576.97762 | BO11: =SUM(BO8:BO10) -> 144.12335 | BP11: =SUM(BP8:BP10) -> 163.04473 | BQ11: =SUM(BQ8:BQ10) -> 162.04153 | BR11: =SUM(BR8:BR10) -> 169.83704 | BS11: =SUM(BO11:BR11) -> 639.04665
A13: Year/Year Changes
A14: Testing Revenue | B14: NA | C14: NA | D14: NA | E14: NA | F14: NA | G14: =IFERROR(G8/B8-1,"NA") -> 0.50053505 | H14: =IFERROR(H8/C8-1,"NA") -> 0.37236372 | I14: =IFERROR(I8/D8-1,"NA") -> 0.25381175 | J14: =IFERROR(J8/E8-1,"NA") -> 0.15107796 | K14: =IFERROR(K8/F8-1,"NA") -> 0.29622938 | L14: =IFERROR(L8/G8-1,"NA") -> 0.20788019 | M14: =IFERROR(M8/H8-1,"NA") -> 0.2323648 | N14: =IFERROR(N8/I8-1,"NA") -> 0.50814755 | ... BS14: =IFERROR(BS8/BN8-1,"NA") -> 0.10980687
A15: Product Revenue | B15: NA | C15: NA | D15: NA | E15: NA | F15: NA | G15: =IFERROR(G9/B9-1,"NA") -> NA | H15: =IFERROR(H9/C9-1,"NA") -> NA | I15: =IFERROR(I9/D9-1,"NA") -> NA | J15: =IFERROR(J9/E9-1,"NA") -> NA | K15: =IFERROR(K9/F9-1,"NA") -> NA | L15: =IFERROR(L9/G9-1,"NA") -> NA | M15: =IFERROR(M9/H9-1,"NA") -> NA | N15: =IFERROR(N9/I9-1,"NA") -> NA | ... BS15: =IFERROR(BS9/BN9-1,"NA") -> 0.02
A16: Biopharma and Other Revenue | B16: NA | C16: NA | D16: NA | E16: NA | F16: NA | G16: =IFERROR(G10/B10-1,"NA") -> NA | H16: =IFERROR(H10/C10-1,"NA") -> NA | I16: =IFERROR(I10/D10-1,"NA") -> NA | J16: =IFERROR(J10/E10-1,"NA") -> NA | K16: =IFERROR(K10/F10-1,"NA") -> NA | L16: =IFERROR(L10/G10-1,"NA") -> NA | M16: =IFERROR(M10/H10-1,"NA") -> NA | N16: =IFERROR(N10/I10-1,"NA") -> NA | ... BI16: =IFERROR(BI10/BD10-1,"NA") -> -0.26526268 | BJ16: -1 | BK16: -1 | BL16: -1 | BM16: -1 | BN16: =IFERROR(BN10/BI10-1,"NA") -> -1 | BO16: -0.1 | BP16: -0.1 | BQ16: -0.1 | BR16: -0.1 | BS16: =IFERROR(BS10/BN10-1,"NA") -> NA
A17: Total Revenue | B17: NA | C17: NA | D17: NA | E17: NA | F17: NA | G17: =IFERROR(G11/B11-1,"NA") -> 0.50053505 | H17: =IFERROR(H11/C11-1,"NA") -> 0.37236372 | I17: =IFERROR(I11/D11-1,"NA") -> 0.25381175 | J17: =IFERROR(J11/E11-1,"NA") -> 0.15107796 | K17: =IFERROR(K11/F11-1,"NA") -> 0.29622938 | L17: =IFERROR(L11/G11-1,"NA") -> 0.20788019 | M17: =IFERROR(M11/H11-1,"NA") -> 0.2323648 | N17: =IFERROR(N11/I11-1,"NA") -> 0.50814755 | ... BS17: =IFERROR(BS11/BN11-1,"NA") -> 0.10757615
A19: % of Revenue
A20: Testing Revenue | B20: =B8/B$11 -> 1 | C20: =C8/C$11 -> 1 | D20: =D8/D$11 -> 1 | E20: =E8/E$11 -> 1 | F20: =F8/F$11 -> 1 | G20: =G8/G$11 -> 1 | H20: =H8/H$11 -> 1 | I20: =I8/I$11 -> 1 | ... BS20: =BS8/BS$11 -> 0.97712494
A21: Product Revenue | B21: =B9/B$11 -> 0 | C21: =C9/C$11 -> 0 | D21: =D9/D$11 -> 0 | E21: =E9/E$11 -> 0 | F21: =F9/F$11 -> 0 | G21: =G9/G$11 -> 0 | H21: =H9/H$11 -> 0 | I21: =I9/I$11 -> 0 | ... BS21: =BS9/BS$11 -> 0.022875058
A22: Biopharma and Other Revenue | B22: =B10/B$11 -> 0 | C22: =C10/C$11 -> 0 | D22: =D10/D$11 -> 0 | E22: =E10/E$11 -> 0 | F22: =F10/F$11 -> 0 | G22: =G10/G$11 -> 0 | H22: =H10/H$11 -> 0 | I22: =I10/I$11 -> 0 | ... BS22: =BS10/BS$11 -> 0
A23: Total Revenue | B23: =B11/B$11 -> 1 | C23: =C11/C$11 -> 1 | D23: =D11/D$11 -> 1 | E23: =E11/E$11 -> 1 | F23: =F11/F$11 -> 1 | G23: =G11/G$11 -> 1 | H23: =H11/H$11 -> 1 | I23: =I11/I$11 -> 1 | ... BS23: =BS11/BS$11 -> 1
A25: Test Volume
A26: Afirma | B26: 3098 | C26: 3451 | D26: 3441 | E26: 4071 | F26: =SUM(B26:E26) -> 14061 | G26: 4020 | H26: 4758 | I26: 5034 | J26: 5609 | K26: =SUM(G26:J26) -> 19421 | L26: 5352 | M26: 5832 | N26: 5740 | O26: 6313 | P26: =SUM(L26:O26) -> 23237 | Q26: 5834 | R26: 6506 | S26: 6533 | T26: 7153 | U26: =SUM(Q26:T26) -> 26026 | V26: 6864 | W26: 7686 | X26: 8006 | Y26: 9154 | Z26: =SUM(V26:Y26) -> 31710 | AA26: 9162 | AB26: 9663 | AC26: 9941 | AD26: 10846 | AE26: =SUM(AA26:AD26) -> 39612 | AF26: 10559 | AG26: 5379 | AH26: 10242 | AI26: 11221 | AJ26: =SUM(AF26:AI26) -> 37401 | AK26: 10743 | AL26: 12013 | AM26: 11342 | AN26: 12622 | AO26: =SUM(AK26:AN26) -> 46720 | AP26: =AP28-AP27 -> 12239 | AQ26: =AQ28-AQ27 -> 12604 | AR26: =AR28-AR27 -> 12974 | AS26: =AS28-AS27 -> 13701 | AT26: =SUM(AP26:AS26) -> 51518 | AU26: =AU28-AU27 -> 13388 | AV26: =AV28-AV27 -> 14009 | AW26: =AW28-AW27 -> 14194 | AX26: =AX28-AX27 -> 15736 | AY26: =SUM(AU26:AX26) -> 57327 | AZ26: 14000 | BA26: 15700 | BB26: 15100 | BC26: 16300 | BD26: =SUM(AZ26:BC26) -> 61100 | BE26: 15500 | BF26: =42441-BF27 -> 16941 | BG26: 17000 | BH26: 18250 | BI26: =SUM(BE26:BH26) -> 67691 | BJ26: =BE26*(1+BJ33) -> 16275 | BK26: =BF26*(1+BK33) -> 18126.87 | BL26: =BG26*(1+BL33) -> 17510 | BM26: =BH26*(1+BM33) -> 18980 | BN26: =SUM(BJ26:BM26) -> 70891.87 | BO26: =BJ26*(1+BO33) -> 16926 | BP26: =BK26*(1+BP33) -> 18851.945 | BQ26: =BL26*(1+BQ33) -> 18210.4 | BR26: =BM26*(1+BR33) -> 19739.2 | BS26: =SUM(BO26:BR26) -> 73727.545
A27: Decipher | B27: 0 | C27: 0 | D27: 0 | E27: 0 | F27: =SUM(B27:E27) -> 0 | G27: 0 | H27: 0 | I27: 0 | J27: 0 | K27: =SUM(G27:J27) -> 0 | L27: 0 | M27: 0 | N27: 0 | O27: 0 | P27: =SUM(L27:O27) -> 0 | Q27: 0 | R27: 0 | S27: 0 | T27: 0 | U27: =SUM(Q27:T27) -> 0 | V27: 0 | W27: 0 | X27: 0 | Y27: 0 | Z27: =SUM(V27:Y27) -> 0 | AA27: 0 | AB27: 0 | AC27: 0 | AD27: 0 | AE27: =SUM(AA27:AD27) -> 0 | AF27: 0 | AG27: 0 | AH27: 0 | AI27: 0 | AJ27: =SUM(AF27:AI27) -> 0 | AK27: 1560 | AL27: 6967 | AM27: 7500 | AN27: 7700 | AO27: =SUM(AK27:AN27) -> 23727 | AP27: 8800 | AQ27: 10000 | AR27: 11000 | AS27: 12000 | AT27: =SUM(AP27:AS27) -> 41800 | AU27: 12500 | AV27: 15050 | AW27: 15500 | AX27: 15500 | AY27: =SUM(AU27:AX27) -> 58550 | AZ27: 16500 | BA27: 19900 | BB27: 21250 | BC27: 22400 | BD27: =SUM(AZ27:BC27) -> 80050 | BE27: 22600 | BF27: 25500 | BG27: 26700 | BH27: 27200 | BI27: =SUM(BE27:BH27) -> 102000 | BJ27: =BE27*(1+BJ34) -> 27346 | BK27: =BF27*(1+BK34) -> 31365 | BL27: =BG27*(1+BL34) -> 31773 | BM27: =BH27*(1+BM34) -> 32640 | BN27: =SUM(BJ27:BM27) -> 123124 | BO27: =BJ27*(1+BO34) -> 31447.9 | BP27: =BK27*(1+BP34) -> 36069.75 | BQ27: =BL27*(1+BQ34) -> 36538.95 | BR27: =BM27*(1+BR34) -> 37536 | BS27: =SUM(BO27:BR27) -> 141592.6
A28: Total Testing Volume | B28: =SUM(B26:B27) -> 3098 | C28: =SUM(C26:C27) -> 3451 | D28: =SUM(D26:D27) -> 3441 | E28: =SUM(E26:E27) -> 4071 | F28: =SUM(B28:E28) -> 14061 | G28: =SUM(G26:G27) -> 4020 | H28: =SUM(H26:H27) -> 4758 | I28: =SUM(I26:I27) -> 5034 | J28: =SUM(J26:J27) -> 5609 | K28: =SUM(G28:J28) -> 19421 | L28: =SUM(L26:L27) -> 5352 | M28: =SUM(M26:M27) -> 5832 | N28: =SUM(N26:N27) -> 5740 | O28: =SUM(O26:O27) -> 6313 | P28: =SUM(L28:O28) -> 23237 | Q28: =SUM(Q26:Q27) -> 5834 | R28: =SUM(R26:R27) -> 6506 | S28: =SUM(S26:S27) -> 6533 | T28: =SUM(T26:T27) -> 7153 | U28: =SUM(Q28:T28) -> 26026 | V28: =SUM(V26:V27) -> 6864 | W28: =SUM(W26:W27) -> 7686 | X28: =SUM(X26:X27) -> 8006 | Y28: =SUM(Y26:Y27) -> 9154 | Z28: =SUM(V28:Y28) -> 31710 | AA28: =SUM(AA26:AA27) -> 9162 | AB28: =SUM(AB26:AB27) -> 9663 | AC28: =SUM(AC26:AC27) -> 9941 | AD28: =SUM(AD26:AD27) -> 10846 | AE28: =SUM(AA28:AD28) -> 39612 | AF28: =SUM(AF26:AF27) -> 10559 | AG28: =SUM(AG26:AG27) -> 5379 | AH28: =SUM(AH26:AH27) -> 10242 | AI28: =SUM(AI26:AI27) -> 11221 | AJ28: =SUM(AF28:AI28) -> 37401 | AK28: =SUM(AK26:AK27) -> 12303 | AL28: =SUM(AL26:AL27) -> 18980 | AM28: =SUM(AM26:AM27) -> 18842 | AN28: =SUM(AN26:AN27) -> 20322 | AO28: =SUM(AK28:AN28) -> 70447 | AP28: =21039 -> 21039 | AQ28: 22604 | AR28: 23974 | AS28: 25701 | AT28: =SUM(AP28:AS28) -> 93318 | AU28: =28788-AU29 -> 25888 | AV28: =31809-AV29 -> 29059 | AW28: =32544-AW29 -> 29694 | AX28: 31236 | AY28: =SUM(AU28:AX28) -> 115877 | AZ28: 30924 | BA28: 36000 | BB28: 36792 | BC28: 39107 | BD28: =SUM(AZ28:BC28) -> 142823 | BE28: =SUM(BE26:BE27) -> 38100 | BF28: =SUM(BF26:BF27) -> 42441 | BG28: =SUM(BG26:BG27) -> 43700 | BH28: =SUM(BH26:BH27) -> 45450 | BI28: =SUM(BE28:BH28) -> 169691 | BJ28: =SUM(BJ26:BJ27) -> 43621 | BK28: =SUM(BK26:BK27) -> 49491.87 | BL28: =SUM(BL26:BL27) -> 49283 | BM28: =SUM(BM26:BM27) -> 51620 | BN28: =SUM(BJ28:BM28) -> 194015.87 | BO28: =SUM(BO26:BO27) -> 48373.9 | BP28: =SUM(BP26:BP27) -> 54921.695 | BQ28: =SUM(BQ26:BQ27) -> 54749.35 | BR28: =SUM(BR26:BR27) -> 57275.2 | BS28: =SUM(BO28:BR28) -> 215320.14
A29: Total Product Volume | B29: 0 | C29: 0 | D29: 0 | E29: 0 | F29: =SUM(B29:E29) -> 0 | G29: 0 | H29: 0 | I29: 0 | J29: 0 | K29: =SUM(G29:J29) -> 0 | L29: 0 | M29: 0 | N29: 0 | O29: 0 | P29: =SUM(L29:O29) -> 0 | Q29: 0 | R29: 0 | S29: 0 | T29: 0 | U29: =SUM(Q29:T29) -> 0 | V29: 0 | W29: 0 | X29: 0 | Y29: 0 | Z29: =SUM(V29:Y29) -> 0 | AA29: 0 | AB29: 0 | AC29: 0 | AD29: 680 | AE29: =SUM(AA29:AD29) -> 680 | AF29: 2482 | AG29: 1249 | AH29: 1448 | AI29: 1909 | AJ29: =SUM(AF29:AI29) -> 7088 | AK29: 2134 | AL29: 1876 | AM29: 2130 | AN29: 1978 | AO29: =SUM(AK29:AN29) -> 8118 | AP29: 2206 | AQ29: 2300 | AR29: 2400 | AS29: 2300 | AT29: =SUM(AP29:AS29) -> 9206 | AU29: 2900 | AV29: 2750 | AW29: 2850 | AX29: 2600 | AY29: =SUM(AU29:AX29) -> 11100 | AZ29: 2500 | BA29: 3023 | BB29: 2240 | BC29: 2200 | BD29: =SUM(AZ29:BC29) -> 9963 | BE29: 2570 | BF29: =44966-42441 -> 2525 | BG29: 2188 | BH29: =48019-45516 -> 2503 | BI29: =SUM(BE29:BH29) -> 9786 | BJ29: =BE29*(1+BJ36) -> 2595.7 | BK29: =BF29*(1+BK36) -> 2550.25 | BL29: =BG29*(1+BL36) -> 2209.88 | BM29: =BH29*(1+BM36) -> 2528.03 | BN29: =SUM(BJ29:BM29) -> 9883.86 | BO29: =BJ29*(1+BO36) -> 2647.614 | BP29: =BK29*(1+BP36) -> 2601.255 | BQ29: =BL29*(1+BQ36) -> 2254.0776 | BR29: =BM29*(1+BR36) -> 2578.5906 | BS29: =SUM(BO29:BR29) -> 10081.537
A30: Total Volume | B30: =SUM(B28:B29) -> 3098 | C30: =SUM(C28:C29) -> 3451 | D30: =SUM(D28:D29) -> 3441 | E30: =SUM(E28:E29) -> 4071 | F30: =SUM(B30:E30) -> 14061 | G30: =SUM(G28:G29) -> 4020 | H30: =SUM(H28:H29) -> 4758 | I30: =SUM(I28:I29) -> 5034 | J30: =SUM(J28:J29) -> 5609 | K30: =SUM(G30:J30) -> 19421 | L30: =SUM(L28:L29) -> 5352 | M30: =SUM(M28:M29) -> 5832 | N30: =SUM(N28:N29) -> 5740 | O30: =SUM(O28:O29) -> 6313 | P30: =SUM(L30:O30) -> 23237 | Q30: =SUM(Q28:Q29) -> 5834 | R30: =SUM(R28:R29) -> 6506 | S30: =SUM(S28:S29) -> 6533 | T30: =SUM(T28:T29) -> 7153 | U30: =SUM(Q30:T30) -> 26026 | V30: =SUM(V28:V29) -> 6864 | W30: =SUM(W28:W29) -> 7686 | X30: =SUM(X28:X29) -> 8006 | Y30: =SUM(Y28:Y29) -> 9154 | Z30: =SUM(V30:Y30) -> 31710 | AA30: =SUM(AA28:AA29) -> 9162 | AB30: =SUM(AB28:AB29) -> 9663 | AC30: =SUM(AC28:AC29) -> 9941 | AD30: =SUM(AD28:AD29) -> 11526 | AE30: =SUM(AA30:AD30) -> 40292 | AF30: =SUM(AF28:AF29) -> 13041 | AG30: =SUM(AG28:AG29) -> 6628 | AH30: =SUM(AH28:AH29) -> 11690 | AI30: =SUM(AI28:AI29) -> 13130 | AJ30: =SUM(AF30:AI30) -> 44489 | AK30: =SUM(AK28:AK29) -> 14437 | AL30: =SUM(AL28:AL29) -> 20856 | AM30: =SUM(AM28:AM29) -> 20972 | AN30: =SUM(AN28:AN29) -> 22300 | AO30: =SUM(AK30:AN30) -> 78565 | AP30: =SUM(AP28:AP29) -> 23245 | AQ30: =SUM(AQ28:AQ29) -> 24904 | AR30: =SUM(AR28:AR29) -> 26374 | AS30: =SUM(AS28:AS29) -> 28001 | AT30: =SUM(AP30:AS30) -> 102524 | AU30: =SUM(AU28:AU29) -> 28788 | AV30: =SUM(AV28:AV29) -> 31809 | AW30: =SUM(AW28:AW29) -> 32544 | AX30: =SUM(AX28:AX29) -> 33836 | AY30: =SUM(AU30:AX30) -> 126977 | AZ30: =SUM(AZ28:AZ29) -> 33424 | BA30: =SUM(BA28:BA29) -> 39023 | BB30: =SUM(BB28:BB29) -> 39032 | BC30: 41271 | BD30: =SUM(AZ30:BC30) -> 152750 | BE30: 40655 | BF30: =SUM(BF28:BF29) -> 44966 | BG30: =SUM(BG28:BG29) -> 45888 | BH30: =SUM(BH28:BH29) -> 47953 | BI30: =SUM(BE30:BH30) -> 179462 | BJ30: =SUM(BJ28:BJ29) -> 46216.7 | BK30: =SUM(BK28:BK29) -> 52042.12 | BL30: =SUM(BL28:BL29) -> 51492.88 | BM30: =SUM(BM28:BM29) -> 54148.03 | BN30: =SUM(BJ30:BM30) -> 203899.73 | BO30: =SUM(BO28:BO29) -> 51021.514 | BP30: =SUM(BP28:BP29) -> 57522.95 | BQ30: =SUM(BQ28:BQ29) -> 57003.428 | BR30: =SUM(BR28:BR29) -> 59853.791 | BS30: =SUM(BO30:BR30) -> 225401.68
A32: Year/Year Changes
A33: Afirma | B33: NA | C33: NA | D33: NA | E33: NA | F33: NA | G33: =IFERROR(G26/B26-1,"NA") -> 0.29761136 | H33: =IFERROR(H26/C26-1,"NA") -> 0.3787308 | I33: =IFERROR(I26/D26-1,"NA") -> 0.46294682 | J33: =IFERROR(J26/E26-1,"NA") -> 0.37779415 | K33: =IFERROR(K26/F26-1,"NA") -> 0.38119622 | L33: =IFERROR(L26/G26-1,"NA") -> 0.33134328 | M33: =IFERROR(M26/H26-1,"NA") -> 0.22572509 | N33: =IFERROR(N26/I26-1,"NA") -> 0.14024632 | ... AM33: =IFERROR(AM26/AH26-1,"NA") -> 0.1074009 | AN33: 0.1146912 | AO33: =IFERROR(AO26/AJ26-1,"NA") -> 0.24916446 | AP33: =IFERROR(AP26/AK26-1,"NA") -> 0.13925347 | AQ33: =IFERROR(AQ26/AL26-1,"NA") -> 0.049196704 | AR33: =IFERROR(AR26/AM26-1,"NA") -> 0.14388997 | AS33: =IFERROR(AS26/AN26-1,"NA") -> 0.08548566 | AT33: =IFERROR(AT26/AO26-1,"NA") -> 0.10269692 | AU33: =IFERROR(AU26/AP26-1,"NA") -> 0.093880219 | AV33: =IFERROR(AV26/AQ26-1,"NA") -> 0.11147255 | ... BI33: =IFERROR(BI26/BD26-1,"NA") -> 0.10787234 | BJ33: 0.05 | BK33: 0.07 | BL33: 0.03 | BM33: 0.04 | BN33: =IFERROR(BN26/BI26-1,"NA") -> 0.047286493 | BO33: 0.04 | BP33: 0.04 | BQ33: 0.04 | BR33: 0.04 | BS33: =IFERROR(BS26/BN26-1,"NA") -> 0.04
A34: Decipher | B34: NA | C34: NA | D34: NA | E34: NA | F34: NA | G34: =IFERROR(G27/B27-1,"NA") -> NA | H34: =IFERROR(H27/C27-1,"NA") -> NA | I34: =IFERROR(I27/D27-1,"NA") -> NA | J34: =IFERROR(J27/E27-1,"NA") -> NA | K34: =IFERROR(K27/F27-1,"NA") -> NA | L34: =IFERROR(L27/G27-1,"NA") -> NA | M34: =IFERROR(M27/H27-1,"NA") -> NA | N34: =IFERROR(N27/I27-1,"NA") -> NA | ... BI34: =IFERROR(BI27/BD27-1,"NA") -> 0.27420362 | BJ34: 0.21 | BK34: 0.23 | BL34: 0.19 | BM34: 0.2 | BN34: =IFERROR(BN27/BI27-1,"NA") -> 0.20709804 | BO34: 0.15 | BP34: 0.15 | BQ34: 0.15 | BR34: 0.15 | BS34: =IFERROR(BS27/BN27-1,"NA") -> 0.15
A35: Total Testing Volume | B35: NA | C35: NA | D35: NA | E35: NA | F35: NA | G35: =IFERROR(G28/B28-1,"NA") -> 0.29761136 | H35: =IFERROR(H28/C28-1,"NA") -> 0.3787308 | I35: =IFERROR(I28/D28-1,"NA") -> 0.46294682 | J35: =IFERROR(J28/E28-1,"NA") -> 0.37779415 | K35: =IFERROR(K28/F28-1,"NA") -> 0.38119622 | L35: =IFERROR(L28/G28-1,"NA") -> 0.33134328 | M35: =IFERROR(M28/H28-1,"NA") -> 0.22572509 | N35: =IFERROR(N28/I28-1,"NA") -> 0.14024632 | ... BS35: =IFERROR(BS28/BN28-1,"NA") -> 0.10980687
A36: Total Product Volume | B36: NA | C36: NA | D36: NA | E36: NA | F36: NA | G36: =IFERROR(G29/B29-1,"NA") -> NA | H36: =IFERROR(H29/C29-1,"NA") -> NA | I36: =IFERROR(I29/D29-1,"NA") -> NA | J36: =IFERROR(J29/E29-1,"NA") -> NA | K36: =IFERROR(K29/F29-1,"NA") -> NA | L36: =IFERROR(L29/G29-1,"NA") -> NA | M36: =IFERROR(M29/H29-1,"NA") -> NA | N36: =IFERROR(N29/I29-1,"NA") -> NA | ... AM36: =IFERROR(AM29/AH29-1,"NA") -> 0.47099448 | AN36: 0.3 | AO36: =IFERROR(AO29/AJ29-1,"NA") -> 0.14531603 | AP36: =IFERROR(AP29/AK29-1,"NA") -> 0.033739456 | AQ36: =IFERROR(AQ29/AL29-1,"NA") -> 0.22601279 | AR36: =IFERROR(AR29/AM29-1,"NA") -> 0.12676056 | AS36: =IFERROR(AS29/AN29-1,"NA") -> 0.1627907 | AT36: =IFERROR(AT29/AO29-1,"NA") -> 0.13402316 | AU36: =IFERROR(AU29/AP29-1,"NA") -> 0.31459655 | AV36: =IFERROR(AV29/AQ29-1,"NA") -> 0.19565217 | ... BI36: =IFERROR(BI29/BD29-1,"NA") -> -0.017765733 | BJ36: 0.01 | BK36: 0.01 | BL36: 0.01 | BM36: 0.01 | BN36: =IFERROR(BN29/BI29-1,"NA") -> 0.01 | BO36: 0.02 | BP36: 0.02 | BQ36: 0.02 | BR36: 0.02 | BS36: =IFERROR(BS29/BN29-1,"NA") -> 0.02
A37: Total Volume | B37: NA | C37: NA | D37: NA | E37: NA | F37: NA | G37: =IFERROR(G30/B30-1,"NA") -> 0.29761136 | H37: =IFERROR(H30/C30-1,"NA") -> 0.3787308 | I37: =IFERROR(I30/D30-1,"NA") -> 0.46294682 | J37: =IFERROR(J30/E30-1,"NA") -> 0.37779415 | K37: =IFERROR(K30/F30-1,"NA") -> 0.38119622 | L37: =IFERROR(L30/G30-1,"NA") -> 0.33134328 | M37: =IFERROR(M30/H30-1,"NA") -> 0.22572509 | N37: =IFERROR(N30/I30-1,"NA") -> 0.14024632 | ... BS37: =IFERROR(BS30/BN30-1,"NA") -> 0.10545356
A39: Revenue Per Test
A40: Testing | B40: =IFERROR(B8/(B26+B27)*1000000,"NA") -> 2413.1698 | C40: =IFERROR(C8/(C26+C27)*1000000,"NA") -> 2514.3437 | D40: =IFERROR(D8/(D26+D27)*1000000,"NA") -> 2859.0526 | E40: =IFERROR(E8/(E26+E27)*1000000,"NA") -> 2996.561 | F40: =IFERROR(F8/(F26+F27)*1000000,"NA") -> 2716.023 | G40: =IFERROR(G8/(G26+G27)*1000000,"NA") -> 2790.5473 | H40: =IFERROR(H8/(H26+H27)*1000000,"NA") -> 2502.7322 | I40: =IFERROR(I8/(I26+I27)*1000000,"NA") -> 2450.3377 | ... AJ40: =IFERROR(AJ8/(AJ26+AJ27)*1000000,"NA") -> 2726.3977 | AK40: =IFERROR(AK8/(AK28)*1000000,"NA") -> 2688.6125 | AL40: =IFERROR(AL8/(AL28)*1000000,"NA") -> 2676.1328 | AM40: =IFERROR(AM8/(AM28)*1000000,"NA") -> 2701.2525 | AN40: =IFERROR(AN8/(AN28)*1000000,"NA") -> 2628.383 | AO40: =IFERROR(AO8/(AO26+AO27)*1000000,"NA") -> 2671.2564 | AP40: =IFERROR(AP8/(AP28)*1000000,"NA") -> 2660.7729 | AQ40: =IFERROR(AQ8/(AQ28)*1000000,"NA") -> 2641.9218 | AR40: =IFERROR(AR8/(AR28)*1000000,"NA") -> 2693.6264 | AS40: =IFERROR(AS8/(AS28)*1000000,"NA") -> 2734.0959 | AT40: =IFERROR(AT8/(AT26+AT27)*1000000,"NA") -> 2684.8411 | AU40: =IFERROR(AU8/(AU28)*1000000,"NA") -> 2796.508 | AV40: =IFERROR(AV8/(AV28)*1000000,"NA") -> 2813.2076 | AW40: =IFERROR(AW8/(AW28)*1000000,"NA") -> 2761.9048 | AX40: =IFERROR(AX8/(AX28)*1000000,"NA") -> 2893.6163 | AY40: =IFERROR(AY8/(AY26+AY27)*1000000,"NA") -> 2818.0053 | AZ40: =IFERROR(AZ8/(AZ28)*1000000,"NA") -> 2920.1591 | BA40: =IFERROR(BA8/(BA28)*1000000,"NA") -> 2971.3889 | BB40: =IFERROR(BB8/(BB28)*1000000,"NA") -> 2977.1689 | BC40: =IFERROR(BC8/(BC28)*1000000,"NA") -> 2867.8242 | BD40: =IFERROR(BD8/(BD26+BD27)*1000000,"NA") -> 2968.197 | BE40: =IFERROR(BE8/(BE28)*1000000,"NA") -> 2816.5092 | BF40: =IFERROR(BF8/(BF28)*1000000,"NA") -> 2880.7757 | BG40: =IFERROR(BG8/(BG28)*1000000,"NA") -> 2923.4783 | BH40: =IFERROR(BH8/(BH28)*1000000,"NA") -> 2988.4708 | BI40: =IFERROR(BI8/(BI26+BI27)*1000000,"NA") -> 2906.1883 | BJ40: 2900 | BK40: =BJ40 -> 2900 | BL40: =BK40 -> 2900 | BM40: =BL40 -> 2900 | BN40: =IFERROR(BN8/(BN26+BN27)*1000000,"NA") -> 2900 | BO40: =BM40 -> 2900 | BP40: =BO40 -> 2900 | BQ40: =BP40 -> 2900 | BR40: =BQ40 -> 2900 | BS40: =IFERROR(BS8/(BS26+BS27)*1000000,"NA") -> 2900
A41: Products | B41: =IFERROR(B9/B29*1000000,"NA") -> NA | C41: =IFERROR(C9/C29*1000000,"NA") -> NA | D41: =IFERROR(D9/D29*1000000,"NA") -> NA | E41: =IFERROR(E9/E29*1000000,"NA") -> NA | F41: =IFERROR(F9/F29*1000000,"NA") -> NA | G41: =IFERROR(G9/G29*1000000,"NA") -> NA | H41: =IFERROR(H9/H29*1000000,"NA") -> NA | I41: =IFERROR(I9/I29*1000000,"NA") -> NA | ... BI41: =IFERROR(BI9/BI29*1000000,"NA") -> 1464.0302 | BJ41: 1450 | BK41: =BJ41 -> 1450 | BL41: =BK41 -> 1450 | BM41: =BL41 -> 1450 | BN41: =IFERROR(BN9/BN29*1000000,"NA") -> 1450 | BO41: =BM41 -> 1450 | BP41: =BO41 -> 1450 | BQ41: =BP41 -> 1450 | BR41: =BQ41 -> 1450 | BS41: =IFERROR(BS9/BS29*1000000,"NA") -> 1450
A42: Average Revenue Per Test | B42: =IFERROR((B8+B9)/B30*1000000,"NA") -> 2413.1698 | C42: =IFERROR((C8+C9)/C30*1000000,"NA") -> 2514.3437 | D42: =IFERROR((D8+D9)/D30*1000000,"NA") -> 2859.0526 | E42: =IFERROR((E8+E9)/E30*1000000,"NA") -> 2996.561 | F42: =IFERROR((F8+F9)/F30*1000000,"NA") -> 2716.023 | G42: =IFERROR((G8+G9)/G30*1000000,"NA") -> 2790.5473 | H42: =IFERROR((H8+H9)/H30*1000000,"NA") -> 2502.7322 | I42: =IFERROR((I8+I9)/I30*1000000,"NA") -> 2450.3377 | ... BS42: =IFERROR((BS8+BS9)/BS30*1000000,"NA") -> 2835.1459
A44: Year/Year Changes
A45: Testing | B45: NA | C45: NA | D45: NA | E45: NA | F45: NA | G45: =IFERROR(G40/B40-1,"NA") -> 0.15638248 | H45: =IFERROR(H40/C40-1,"NA") -> -0.0046180752 | I45: =IFERROR(I40/D40-1,"NA") -> -0.14295466 | J45: =IFERROR(J40/E40-1,"NA") -> -0.16455012 | K45: =IFERROR(K40/F40-1,"NA") -> -0.061516848 | L45: =IFERROR(L40/G40-1,"NA") -> -0.09273573 | M45: =IFERROR(M40/H40-1,"NA") -> 0.0054169587 | N45: =IFERROR(N40/I40-1,"NA") -> 0.32265065 | ... BS45: =IFERROR(BS40/BN40-1,"NA") -> -1.110223e-16
A46: Products | B46: NA | C46: NA | D46: NA | E46: NA | F46: NA | G46: =IFERROR(G41/B41-1,"NA") -> NA | H46: =IFERROR(H41/C41-1,"NA") -> NA | I46: =IFERROR(I41/D41-1,"NA") -> NA | J46: =IFERROR(J41/E41-1,"NA") -> NA | K46: =IFERROR(K41/F41-1,"NA") -> NA | L46: =IFERROR(L41/G41-1,"NA") -> NA | M46: =IFERROR(M41/H41-1,"NA") -> NA | N46: =IFERROR(N41/I41-1,"NA") -> NA | ... BS46: =IFERROR(BS41/BN41-1,"NA") -> 2.220446e-16
A47: Average Revenue Per Test | B47: NA | C47: NA | D47: NA | E47: NA | F47: NA | G47: =IFERROR(G42/B42-1,"NA") -> 0.15638248 | H47: =IFERROR(H42/C42-1,"NA") -> -0.0046180752 | I47: =IFERROR(I42/D42-1,"NA") -> -0.14295466 | J47: =IFERROR(J42/E42-1,"NA") -> -0.16455012 | K47: =IFERROR(K42/F42-1,"NA") -> -0.061516848 | L47: =IFERROR(L42/G42-1,"NA") -> -0.09273573 | M47: =IFERROR(M42/H42-1,"NA") -> 0.0054169587 | N47: =IFERROR(N42/I42-1,"NA") -> 0.32265065 | ... BS47: =IFERROR(BS42/BN42-1,"NA") -> 0.0019201063
...

Sheet Income Statement
A1: Veracyte Inc. | BS1: Needham & Company, LLC
A2: Quarterly Income Statement | BS2: Michael Matson ● (617) 457-0949
A3: ($ In Millions Except Per Share Data) | AH3: NG EPS | AI3: -0.11
B5: ='Revenue Model'!B5 -> 41699 | C5: ='Revenue Model'!C5 -> 41791 | D5: ='Revenue Model'!D5 -> 41883 | E5: ='Revenue Model'!E5 -> 41974 | F5: ='Revenue Model'!F5 -> 2014 | G5: ='Revenue Model'!G5 -> 42064 | H5: ='Revenue Model'!H5 -> 42156 | I5: ='Revenue Model'!I5 -> 42248 | ... BS5: ='Revenue Model'!BS5 -> 2027E
B6: ='Revenue Model'!B6 -> Q114A | C6: ='Revenue Model'!C6 -> Q214A | D6: ='Revenue Model'!D6 -> Q314A | E6: ='Revenue Model'!E6 -> Q414A | F6: ='Revenue Model'!F6 -> Annual | G6: ='Revenue Model'!G6 -> Q115A | H6: ='Revenue Model'!H6 -> Q215A | I6: ='Revenue Model'!I6 -> Q315A | ... BS6: ='Revenue Model'!BS6 -> Annual
A7: Testing Revenue | B7: ='Revenue Model'!B8 -> 7.476 | C7: ='Revenue Model'!C8 -> 8.677 | D7: ='Revenue Model'!D8 -> 9.838 | E7: ='Revenue Model'!E8 -> 12.199 | F7: =SUM(B7:E7) -> 38.19 | G7: ='Revenue Model'!G8 -> 11.218 | H7: ='Revenue Model'!H8 -> 11.908 | I7: ='Revenue Model'!I8 -> 12.335 | J7: ='Revenue Model'!J8 -> 14.042 | K7: =SUM(G7:J7) -> 49.503 | L7: ='Revenue Model'!L8 -> 13.55 | M7: ='Revenue Model'!M8 -> 14.675 | N7: ='Revenue Model'!N8 -> 18.603 | O7: ='Revenue Model'!O8 -> 18.257 | P7: =SUM(L7:O7) -> 65.085 | Q7: ='Revenue Model'!Q8 -> 16.432 | R7: ='Revenue Model'!R8 -> 18.406 | S7: ='Revenue Model'!S8 -> 17.519 | T7: ='Revenue Model'!T8 -> 19.596 | U7: =SUM(Q7:T7) -> 71.953 | V7: ='Revenue Model'!V8 -> 20.041 | W7: ='Revenue Model'!W8 -> 22.301 | X7: ='Revenue Model'!X8 -> 23.216 | Y7: ='Revenue Model'!Y8 -> 25.5 | Z7: =SUM(V7:Y7) -> 91.058 | AA7: ='Revenue Model'!AA8 -> 25.389 | AB7: ='Revenue Model'!AB8 -> 26.686 | AC7: ='Revenue Model'!AC8 -> 26.723 | AD7: ='Revenue Model'!AD8 -> 28.557 | AE7: =SUM(AA7:AD7) -> 107.355 | AF7: ='Revenue Model'!AF8 -> 26.991 | AG7: ='Revenue Model'!AG8 -> 15.212 | AH7: ='Revenue Model'!AH8 -> 28.27 | AI7: ='Revenue Model'!AI8 -> 31.497 | AJ7: =SUM(AF7:AI7) -> 101.97 | AK7: ='Revenue Model'!AK8 -> 33.078 | AL7: ='Revenue Model'!AL8 -> 50.793 | AM7: ='Revenue Model'!AM8 -> 50.897 | AN7: ='Revenue Model'!AN8 -> 53.414 | AO7: =SUM(AK7:AN7) -> 188.182 | AP7: ='Revenue Model'!AP8 -> 55.98 | AQ7: ='Revenue Model'!AQ8 -> 59.718 | AR7: ='Revenue Model'!AR8 -> 64.577 | AS7: ='Revenue Model'!AS8 -> 70.269 | AT7: =SUM(AP7:AS7) -> 250.544 | AU7: ='Revenue Model'!AU8 -> 72.396 | AV7: ='Revenue Model'!AV8 -> 81.749 | AW7: ='Revenue Model'!AW8 -> 82.012 | AX7: ='Revenue Model'!AX8 -> 90.385 | AY7: =SUM(AU7:AX7) -> 326.542 | AZ7: ='Revenue Model'!AZ8 -> 90.303 | BA7: ='Revenue Model'!BA8 -> 106.97 | BB7: ='Revenue Model'!BB8 -> 109.536 | BC7: ='Revenue Model'!BC8 -> 112.152 | BD7: =SUM(AZ7:BC7) -> 418.961 | BE7: ='Revenue Model'!BE8 -> 107.309 | BF7: ='Revenue Model'!BF8 -> 122.263 | BG7: ='Revenue Model'!BG8 -> 127.756 | BH7: ='Revenue Model'!BH8 -> 135.826 | BI7: =SUM(BE7:BH7) -> 493.154 | BJ7: ='Revenue Model'!BJ8 -> 126.5009 | BK7: ='Revenue Model'!BK8 -> 143.52642 | BL7: ='Revenue Model'!BL8 -> 142.9207 | BM7: ='Revenue Model'!BM8 -> 149.698 | BN7: =SUM(BJ7:BM7) -> 562.64602 | BO7: ='Revenue Model'!BO8 -> 140.28431 | BP7: ='Revenue Model'!BP8 -> 159.27291 | BQ7: ='Revenue Model'!BQ8 -> 158.77311 | BR7: ='Revenue Model'!BR8 -> 166.09808 | BS7: =SUM(BO7:BR7) -> 624.42842
A8: Product Revenue | B8: ='Revenue Model'!B9 -> 0 | C8: ='Revenue Model'!C9 -> 0 | D8: ='Revenue Model'!D9 -> 0 | E8: ='Revenue Model'!E9 -> 0 | F8: =SUM(B8:E8) -> 0 | G8: ='Revenue Model'!G9 -> 0 | H8: ='Revenue Model'!H9 -> 0 | I8: ='Revenue Model'!I9 -> 0 | J8: ='Revenue Model'!J9 -> 0 | K8: =SUM(G8:J8) -> 0 | L8: ='Revenue Model'!L9 -> 0 | M8: ='Revenue Model'!M9 -> 0 | N8: ='Revenue Model'!N9 -> 0 | O8: ='Revenue Model'!O9 -> 0 | P8: =SUM(L8:O8) -> 0 | Q8: ='Revenue Model'!Q9 -> 0 | R8: ='Revenue Model'!R9 -> 0 | S8: ='Revenue Model'!S9 -> 0 | T8: ='Revenue Model'!T9 -> 0 | U8: =SUM(Q8:T8) -> 0 | V8: ='Revenue Model'!V9 -> 0 | W8: ='Revenue Model'!W9 -> 0 | X8: ='Revenue Model'!X9 -> 0 | Y8: ='Revenue Model'!Y9 -> 0 | Z8: =SUM(V8:Y8) -> 0 | AA8: ='Revenue Model'!AA9 -> 0 | AB8: ='Revenue Model'!AB9 -> 0 | AC8: ='Revenue Model'!AC9 -> 0 | AD8: ='Revenue Model'!AD9 -> 0.923 | AE8: =SUM(AA8:AD8) -> 0.923 | AF8: ='Revenue Model'!AF9 -> 3.409 | AG8: ='Revenue Model'!AG9 -> 1.713 | AH8: ='Revenue Model'!AH9 -> 2.027 | AI8: ='Revenue Model'!AI9 -> 2.696 | AJ8: =SUM(AF8:AI8) -> 9.845 | AK8: ='Revenue Model'!AK9 -> 3.059 | AL8: ='Revenue Model'!AL9 -> 2.688 | AM8: ='Revenue Model'!AM9 -> 2.959 | AN8: ='Revenue Model'!AN9 -> 2.758 | AO8: =SUM(AK8:AN8) -> 11.464 | AP8: ='Revenue Model'!AP9 -> 2.979 | AQ8: ='Revenue Model'!AQ9 -> 3.108 | AR8: ='Revenue Model'!AR9 -> 3.314 | AS8: ='Revenue Model'!AS9 -> 3.231 | AT8: =SUM(AP8:AS8) -> 12.632 | AU8: ='Revenue Model'!AU9 -> 3.892 | AV8: ='Revenue Model'!AV9 -> 4.011 | AW8: ='Revenue Model'!AW9 -> 4.02 | AX8: ='Revenue Model'!AX9 -> 3.665 | AY8: =SUM(AU8:AX8) -> 15.588 | AZ8: ='Revenue Model'!AZ9 -> 3.537 | BA8: ='Revenue Model'!BA9 -> 3.906 | BB8: ='Revenue Model'!BB9 -> 3.188 | BC8: ='Revenue Model'!BC9 -> 3.019 | BD8: =SUM(AZ8:BC8) -> 13.65 | BE8: ='Revenue Model'!BE9 -> 3.58 | BF8: ='Revenue Model'!BF9 -> 3.598 | BG8: ='Revenue Model'!BG9 -> 3.301 | BH8: ='Revenue Model'!BH9 -> 3.848 | BI8: =SUM(BE8:BH8) -> 14.327 | BJ8: ='Revenue Model'!BJ9 -> 3.763765 | BK8: ='Revenue Model'!BK9 -> 3.6978625 | BL8: ='Revenue Model'!BL9 -> 3.204326 | BM8: ='Revenue Model'!BM9 -> 3.6656435 | BN8: =SUM(BJ8:BM8) -> 14.331597 | BO8: ='Revenue Model'!BO9 -> 3.8390403 | BP8: ='Revenue Model'!BP9 -> 3.7718198 | BQ8: ='Revenue Model'!BQ9 -> 3.2684125 | BR8: ='Revenue Model'!BR9 -> 3.7389564 | BS8: =SUM(BO8:BR8) -> 14.618229
A9: Biopharma and Other Revenue | B9: ='Revenue Model'!B10 -> 0 | C9: ='Revenue Model'!C10 -> 0 | D9: ='Revenue Model'!D10 -> 0 | E9: ='Revenue Model'!E10 -> 0 | F9: =SUM(B9:E9) -> 0 | G9: ='Revenue Model'!G10 -> 0 | H9: ='Revenue Model'!H10 -> 0 | I9: ='Revenue Model'!I10 -> 0 | J9: ='Revenue Model'!J10 -> 0 | K9: =SUM(G9:J9) -> 0 | L9: ='Revenue Model'!L10 -> 0 | M9: ='Revenue Model'!M10 -> 0 | N9: ='Revenue Model'!N10 -> 0 | O9: ='Revenue Model'!O10 -> 0 | P9: =SUM(L9:O9) -> 0 | Q9: ='Revenue Model'!Q10 -> 0 | R9: ='Revenue Model'!R10 -> 0 | S9: ='Revenue Model'!S10 -> 0 | T9: ='Revenue Model'!T10 -> 0 | U9: =SUM(Q9:T9) -> 0 | V9: ='Revenue Model'!V10 -> 0 | W9: ='Revenue Model'!W10 -> 0.45 | X9: ='Revenue Model'!X10 -> 0.25 | Y9: ='Revenue Model'!Y10 -> 0.25 | Z9: =SUM(V9:Y9) -> 0.95 | AA9: ='Revenue Model'!AA10 -> 4.14 | AB9: ='Revenue Model'!AB10 -> 3.45 | AC9: ='Revenue Model'!AC10 -> 4.25 | AD9: ='Revenue Model'!AD10 -> 0.25 | AE9: =SUM(AA9:AD9) -> 12.09 | AF9: ='Revenue Model'!AF10 -> 0.722 | AG9: ='Revenue Model'!AG10 -> 3.779 | AH9: ='Revenue Model'!AH10 -> 0.824 | AI9: ='Revenue Model'!AI10 -> 0.343 | AJ9: =SUM(AF9:AI9) -> 5.668 | AK9: ='Revenue Model'!AK10 -> 0.566 | AL9: ='Revenue Model'!AL10 -> 1.624 | AM9: ='Revenue Model'!AM10 -> 6.514 | AN9: ='Revenue Model'!AN10 -> 11.164 | AO9: =SUM(AK9:AN9) -> 19.868 | AP9: ='Revenue Model'!AP10 -> 8.824 | AQ9: ='Revenue Model'!AQ10 -> 10.038 | AR9: ='Revenue Model'!AR10 -> 7.701 | AS9: ='Revenue Model'!AS10 -> 6.797 | AT9: =SUM(AP9:AS9) -> 33.36 | AU9: ='Revenue Model'!AU10 -> 6.134 | AV9: ='Revenue Model'!AV10 -> 4.562 | AW9: ='Revenue Model'!AW10 -> 4.076 | AX9: ='Revenue Model'!AX10 -> 4.149 | AY9: =SUM(AU9:AX9) -> 18.921 | AZ9: ='Revenue Model'!AZ10 -> 3.004 | BA9: ='Revenue Model'!BA10 -> 3.552 | BB9: ='Revenue Model'!BB10 -> 3.136 | BC9: ='Revenue Model'!BC10 -> 3.461 | BD9: =SUM(AZ9:BC9) -> 13.153 | BE9: ='Revenue Model'!BE10 -> 3.584 | BF9: ='Revenue Model'!BF10 -> 4.303 | BG9: ='Revenue Model'!BG10 -> 0.815 | BH9: ='Revenue Model'!BH10 -> 0.962 | BI9: =SUM(BE9:BH9) -> 9.664 | BJ9: ='Revenue Model'!BJ10 -> 0 | BK9: ='Revenue Model'!BK10 -> 0 | BL9: ='Revenue Model'!BL10 -> 0 | BM9: ='Revenue Model'!BM10 -> 0 | BN9: =SUM(BJ9:BM9) -> 0 | BO9: ='Revenue Model'!BO10 -> 0 | BP9: ='Revenue Model'!BP10 -> 0 | BQ9: ='Revenue Model'!BQ10 -> 0 | BR9: ='Revenue Model'!BR10 -> 0 | BS9: =SUM(BO9:BR9) -> 0
A10: Total Revenue | B10: =SUM(B7:B9) -> 7.476 | C10: =SUM(C7:C9) -> 8.677 | D10: =SUM(D7:D9) -> 9.838 | E10: =SUM(E7:E9) -> 12.199 | F10: =SUM(B10:E10) -> 38.19 | G10: =SUM(G7:G9) -> 11.218 | H10: =SUM(H7:H9) -> 11.908 | I10: =SUM(I7:I9) -> 12.335 | J10: =SUM(J7:J9) -> 14.042 | K10: =SUM(G10:J10) -> 49.503 | L10: =SUM(L7:L9) -> 13.55 | M10: =SUM(M7:M9) -> 14.675 | N10: =SUM(N7:N9) -> 18.603 | O10: =SUM(O7:O9) -> 18.257 | P10: =SUM(L10:O10) -> 65.085 | Q10: =SUM(Q7:Q9) -> 16.432 | R10: =SUM(R7:R9) -> 18.406 | S10: =SUM(S7:S9) -> 17.519 | T10: =SUM(T7:T9) -> 19.596 | U10: =SUM(Q10:T10) -> 71.953 | V10: =SUM(V7:V9) -> 20.041 | W10: =SUM(W7:W9) -> 22.751 | X10: =SUM(X7:X9) -> 23.466 | Y10: =SUM(Y7:Y9) -> 25.75 | Z10: =SUM(V10:Y10) -> 92.008 | AA10: =SUM(AA7:AA9) -> 29.529 | AB10: =SUM(AB7:AB9) -> 30.136 | AC10: =SUM(AC7:AC9) -> 30.973 | AD10: =SUM(AD7:AD9) -> 29.73 | AE10: =SUM(AA10:AD10) -> 120.368 | AF10: =SUM(AF7:AF9) -> 31.122 | AG10: =SUM(AG7:AG9) -> 20.704 | AH10: =SUM(AH7:AH9) -> 31.121 | AI10: =SUM(AI7:AI9) -> 34.536 | AJ10: =SUM(AF10:AI10) -> 117.483 | AK10: =SUM(AK7:AK9) -> 36.703 | AL10: =SUM(AL7:AL9) -> 55.105 | AM10: =SUM(AM7:AM9) -> 60.37 | AN10: =SUM(AN7:AN9) -> 67.336 | AO10: =SUM(AK10:AN10) -> 219.514 | AP10: =SUM(AP7:AP9) -> 67.783 | AQ10: =SUM(AQ7:AQ9) -> 72.864 | AR10: =SUM(AR7:AR9) -> 75.592 | AS10: =SUM(AS7:AS9) -> 80.297 | AT10: =SUM(AP10:AS10) -> 296.536 | AU10: =SUM(AU7:AU9) -> 82.422 | AV10: =SUM(AV7:AV9) -> 90.322 | AW10: =SUM(AW7:AW9) -> 90.108 | AX10: =SUM(AX7:AX9) -> 98.199 | AY10: =SUM(AU10:AX10) -> 361.051 | AZ10: =SUM(AZ7:AZ9) -> 96.844 | BA10: =SUM(BA7:BA9) -> 114.428 | BB10: =SUM(BB7:BB9) -> 115.86 | BC10: =SUM(BC7:BC9) -> 118.632 | BD10: =SUM(AZ10:BC10) -> 445.764 | BE10: =SUM(BE7:BE9) -> 114.473 | BF10: =SUM(BF7:BF9) -> 130.164 | BG10: =SUM(BG7:BG9) -> 131.872 | BH10: =SUM(BH7:BH9) -> 140.636 | BI10: =SUM(BE10:BH10) -> 517.145 | BJ10: =SUM(BJ7:BJ9) -> 130.26467 | BK10: =SUM(BK7:BK9) -> 147.22429 | BL10: =SUM(BL7:BL9) -> 146.12503 | BM10: =SUM(BM7:BM9) -> 153.36364 | BN10: =SUM(BJ10:BM10) -> 576.97762 | BO10: =SUM(BO7:BO9) -> 144.12335 | BP10: =SUM(BP7:BP9) -> 163.04473 | BQ10: =SUM(BQ7:BQ9) -> 162.04153 | BR10: =SUM(BR7:BR9) -> 169.83704 | BS10: =SUM(BO10:BR10) -> 639.04665
A11: Cost of Testing Revenue | B11: 3.607 | C11: 3.966 | D11: 4.168 | E11: 4.865 | F11: =+B11+C11+D11+E11 -> 16.606 | G11: 4.566 | H11: 5.139 | I11: 5.618 | J11: 6.175 | K11: =+G11+H11+I11+J11 -> 21.498 | L11: 6.279 | M11: 6.301 | N11: 6.367 | O11: 6.515 | P11: =+L11+M11+N11+O11 -> 25.462 | Q11: 6.297 | R11: 6.96 | S11: 7.169 | T11: 7.769 | U11: =+Q11+R11+S11+T11 -> 28.195 | V11: 7.867 | W11: 8.246 | X11: 8.261 | Y11: 8.704 | Z11: =+V11+W11+X11+Y11 -> 33.078 | AA11: 8.513 | AB11: 8.777 | AC11: 9.114 | AD11: =9.673 -> 9.673 | AE11: =+AA11+AB11+AC11+AD11 -> 36.077 | AF11: =10.568-1.088 -> 9.48 | AG11: 6.471 | AH11: 9.118 | AI11: 9.756 | AJ11: =+AF11+AG11+AH11+AI11 -> 34.825 | AK11: 10.832 | AL11: 15.589 | AM11: 16.073 | AN11: 16.366 | AO11: =+AK11+AL11+AM11+AN11 -> 58.86 | AP11: 17.47 | AQ11: 18.533 | AR11: 19.749 | AS11: 19.394 | AT11: =+AP11+AQ11+AR11+AS11 -> 75.146 | AY11: =+AU11+AV11+AW11+AX11 -> 0 | BD11: =+AZ11+BA11+BB11+BC11 -> 0 | BI11: =+BE11+BF11+BG11+BH11 -> 0 | BN11: =+BJ11+BK11+BL11+BM11 -> 0 | BS11: =+BO11+BP11+BQ11+BR11 -> 0
A12: Cost of Product Revenue | B12: 0 | C12: 0 | D12: 0 | E12: 0 | F12: =+B12+C12+D12+E12 -> 0 | G12: 0 | H12: 0 | I12: 0 | J12: 0 | K12: =+G12+H12+I12+J12 -> 0 | L12: 0 | M12: 0 | N12: 0 | O12: 0 | P12: =+L12+M12+N12+O12 -> 0 | Q12: 0 | R12: 0 | S12: 0 | T12: 0 | U12: =+Q12+R12+S12+T12 -> 0 | V12: 0 | W12: 0 | X12: 0 | Y12: 0 | Z12: =+V12+W12+X12+Y12 -> 0 | AA12: 0 | AB12: 0 | AC12: 0 | AD12: 0.466 | AE12: =+AA12+AB12+AC12+AD12 -> 0.466 | AF12: 1.559 | AG12: 0.932 | AH12: 1.048 | AI12: 1.382 | AJ12: =+AF12+AG12+AH12+AI12 -> 4.921 | AK12: 1.49 | AL12: 1.323 | AM12: 1.491 | AN12: 1.583 | AO12: =+AK12+AL12+AM12+AN12 -> 5.887 | AP12: 1.575 | AQ12: 1.646 | AR12: 1.978 | AS12: 2.618 | AT12: =+AP12+AQ12+AR12+AS12 -> 7.817 | AY12: =+AU12+AV12+AW12+AX12 -> 0 | BD12: =+AZ12+BA12+BB12+BC12 -> 0 | BI12: =+BE12+BF12+BG12+BH12 -> 0 | BN12: =+BJ12+BK12+BL12+BM12 -> 0 | BS12: =+BO12+BP12+BQ12+BR12 -> 0
A13: Cost of Biopharma Revenue | B13: 0 | C13: 0 | D13: 0 | E13: 0 | F13: =SUM(B13:E13) -> 0 | G13: 0 | H13: 0 | I13: 0 | J13: 0 | K13: =SUM(G13:J13) -> 0 | L13: 0 | M13: 0 | N13: 0 | O13: 0 | P13: =SUM(L13:O13) -> 0 | Q13: 0 | R13: 0 | S13: 0 | T13: 0 | U13: =SUM(Q13:T13) -> 0 | V13: 0 | W13: 0 | X13: 0 | Y13: 0 | Z13: =SUM(V13:Y13) -> 0 | AA13: 0 | AB13: 0 | AC13: 0 | AD13: 0 | AE13: =+AA13+AB13+AC13+AD13 -> 0 | AF13: 0.116 | AG13: 0.252 | AH13: 0.204 | AI13: 0.049 | AJ13: =+AF13+AG13+AH13+AI13 -> 0.621 | AK13: 0.081 | AL13: 0.56 | AM13: 4.079 | AN13: 4.933 | AO13: =+AK13+AL13+AM13+AN13 -> 9.653 | AP13: 4.482 | AQ13: 4.735 | AR13: 4.149 | AS13: 4.755 | AT13: =+AP13+AQ13+AR13+AS13 -> 18.121 | AY13: =+AU13+AV13+AW13+AX13 -> 0 | BD13: =+AZ13+BA13+BB13+BC13 -> 0 | BI13: =+BE13+BF13+BG13+BH13 -> 0 | BN13: =+BJ13+BK13+BL13+BM13 -> 0 | BS13: =+BO13+BP13+BQ13+BR13 -> 0
A14: Total Cost of Sales | B14: =SUM(B11:B13) -> 3.607 | C14: =SUM(C11:C13) -> 3.966 | D14: =SUM(D11:D13) -> 4.168 | E14: =SUM(E11:E13) -> 4.865 | F14: =+B14+C14+D14+E14 -> 16.606 | G14: =SUM(G11:G13) -> 4.566 | H14: =SUM(H11:H13) -> 5.139 | I14: =SUM(I11:I13) -> 5.618 | J14: =SUM(J11:J13) -> 6.175 | K14: =+G14+H14+I14+J14 -> 21.498 | L14: =SUM(L11:L13) -> 6.279 | M14: =SUM(M11:M13) -> 6.301 | N14: =SUM(N11:N13) -> 6.367 | O14: =SUM(O11:O13) -> 6.515 | P14: =+L14+M14+N14+O14 -> 25.462 | Q14: =SUM(Q11:Q13) -> 6.297 | R14: =SUM(R11:R13) -> 6.96 | S14: =SUM(S11:S13) -> 7.169 | T14: =SUM(T11:T13) -> 7.769 | U14: =+Q14+R14+S14+T14 -> 28.195 | V14: =SUM(V11:V13) -> 7.867 | W14: =SUM(W11:W13) -> 8.246 | X14: =SUM(X11:X13) -> 8.261 | Y14: =SUM(Y11:Y13) -> 8.704 | Z14: =+V14+W14+X14+Y14 -> 33.078 | AA14: =SUM(AA11:AA13) -> 8.513 | AB14: =SUM(AB11:AB13) -> 8.777 | AC14: =SUM(AC11:AC13) -> 9.114 | AD14: =SUM(AD11:AD13) -> 10.139 | AE14: =+AA14+AB14+AC14+AD14 -> 36.543 | AF14: =SUM(AF11:AF13) -> 11.155 | AG14: =SUM(AG11:AG13) -> 7.655 | AH14: =SUM(AH11:AH13) -> 10.37 | AI14: =SUM(AI11:AI13) -> 11.187 | AJ14: =+AF14+AG14+AH14+AI14 -> 40.367 | AK14: =SUM(AK11:AK13) -> 12.403 | AL14: =SUM(AL11:AL13) -> 17.472 | AM14: =SUM(AM11:AM13) -> 21.643 | AN14: =SUM(AN11:AN13) -> 22.882 | AO14: =+AK14+AL14+AM14+AN14 -> 74.4 | AP14: =SUM(AP11:AP13) -> 23.527 | AQ14: =SUM(AQ11:AQ13) -> 24.914 | AR14: =SUM(AR11:AR13) -> 25.876 | AS14: =SUM(AS11:AS13) -> 26.767 | AT14: =+AP14+AQ14+AR14+AS14 -> 101.084 | AU14: 25.768 | AV14: 29.191 | AW14: 27.108 | AX14: 28.904 | AY14: =+AU14+AV14+AW14+AX14 -> 110.971 | AZ14: 30.908 | BA14: 33.002 | BB14: 33.346 | BC14: 36.426 | BD14: =+AZ14+BA14+BB14+BC14 -> 133.682 | BE14: 31.86 | BF14: =31.865+1.716+3.507 -> 37.088 | BG14: =33.222+1.597+1.106 -> 35.925 | BH14: =32.502+2.34+0.215 -> 35.057 | BI14: =+BE14+BF14+BG14+BH14 -> 139.93 | BJ14: =(1-BJ61)*BJ10 -> 35.822783 | BK14: =(1-BK61)*BK10 -> 40.486679 | BL14: =(1-BL61)*BL10 -> 39.453757 | BM14: =(1-BM61)*BM10 -> 40.641366 | BN14: =+BJ14+BK14+BL14+BM14 -> 156.40458 | BO14: =(1-BO61)*BO10 -> 39.633921 | BP14: =(1-BP61)*BP10 -> 44.837302 | BQ14: =(1-BQ61)*BQ10 -> 43.751212 | BR14: =(1-BR61)*BR10 -> 45.006815 | BS14: =+BO14+BP14+BQ14+BR14 -> 173.22925
A15: Gross Profit | B15: =+B10-B14 -> 3.869 | C15: =+C10-C14 -> 4.711 | D15: =+D10-D14 -> 5.67 | E15: =+E10-E14 -> 7.334 | F15: =+F10-F14 -> 21.584 | G15: =+G10-G14 -> 6.652 | H15: =+H10-H14 -> 6.769 | I15: =+I10-I14 -> 6.717 | ... BS15: =+BS10-BS14 -> 465.8174
A16: Research & Development | B16: 2.126 | C16: 2.243 | D16: 2.233 | E16: 3.202 | F16: =SUM(B16:E16) -> 9.804 | G16: 2.787 | H16: 3.103 | I16: 3.563 | J16: 3.343 | K16: =SUM(G16:J16) -> 12.796 | L16: 3.461 | M16: 4.267 | N16: 4.006 | O16: 3.59 | P16: =SUM(L16:O16) -> 15.324 | Q16: 4.03 | R16: 3.603 | S16: 3.046 | T16: 3.202 | U16: =SUM(Q16:T16) -> 13.881 | V16: 3.675 | W16: 4.601 | X16: 3.419 | Y16: 3.125 | Z16: =SUM(V16:Y16) -> 14.82 | AA16: 3.435 | AB16: 3.33 | AC16: 3.643 | AD16: 4.443 | AE16: =SUM(AA16:AD16) -> 14.851 | AF16: 4.407 | AG16: 4.169 | AH16: 4.042 | AI16: 4.586 | AJ16: =SUM(AF16:AI16) -> 17.204 | AK16: 5.336 | AL16: 6.249 | AM16: 8.006 | AN16: 10.252 | AO16: =SUM(AK16:AN16) -> 29.843 | AP16: 8.524 | AQ16: 9.084 | AR16: 10.522 | AS16: 11.055 | AT16: =SUM(AP16:AS16) -> 39.185 | AU16: 11.513 | AV16: 11.102 | AW16: 12.187 | AX16: 17.178 | AY16: =SUM(AU16:AX16) -> 51.98 | AZ16: 13.504 | BA16: 14.595 | BB16: 16.081 | BC16: 17.394 | BD16: =SUM(AZ16:BC16) -> 61.574 | BE16: 15.654 | BF16: 14.256 | BG16: 14.032 | BH16: 18.954 | BI16: =SUM(BE16:BH16) -> 62.896 | BJ16: =BJ62*BJ$10 -> 17.194936 | BK16: =BK62*BK$10 -> 19.58083 | BL16: =BL62*BL$10 -> 19.288503 | BM16: =BM62*BM$10 -> 18.863728 | BN16: =SUM(BJ16:BM16) -> 74.927997 | BO16: =BO62*BO$10 -> 18.880159 | BP16: =BP62*BP$10 -> 21.521905 | BQ16: =BQ62*BQ$10 -> 21.22744 | BR16: =BR62*BR$10 -> 20.720118 | BS16: =SUM(BO16:BR16) -> 82.349622
A17: Selling & Marketing | B17: 4.336 | C17: 5.101 | D17: 5.533 | E17: 6.962 | F17: =SUM(B17:E17) -> 21.932 | G17: 5.62 | H17: 6.937 | I17: 6.048 | J17: 6.687 | K17: =SUM(G17:J17) -> 25.292 | L17: 7.066 | M17: 8.263 | N17: 7.087 | O17: 5.832 | P17: =SUM(L17:O17) -> 28.248 | Q17: 7.336 | R17: 7.994 | S17: 7.885 | T17: 9.045 | U17: =SUM(Q17:T17) -> 32.26 | V17: 11.543 | W17: 9.623 | X17: 10.081 | Y17: 10.066 | Z17: =SUM(V17:Y17) -> 41.313 | AA17: 12.477 | AB17: 13.943 | AC17: 13.088 | AD17: 14.183 | AE17: =SUM(AA17:AD17) -> 53.691 | AF17: 17.584 | AG17: 10.701 | AH17: 10.955 | AI17: 13.149 | AJ17: =SUM(AF17:AI17) -> 52.389 | AK17: 16.296 | AL17: 19.662 | AM17: 21.67 | AN17: 22.212 | AO17: =SUM(AK17:AN17) -> 79.84 | AP17: 22.538 | AQ17: 23.143 | AR17: 24.262 | AS17: 23.21 | AT17: =SUM(AP17:AS17) -> 93.153 | AU17: 23.428 | AV17: 22.695 | AW17: 21.614 | AX17: 22.762 | AY17: =SUM(AU17:AX17) -> 90.499 | AZ17: 21.665 | BA17: 21.88 | BB17: 20.829 | BC17: 22.952 | BD17: =SUM(AZ17:BC17) -> 87.326 | BE17: 22.496 | BF17: 23.118 | BG17: 22.353 | BH17: 23.88 | BI17: =SUM(BE17:BH17) -> 91.847 | BJ17: =BJ63*BJ$10 -> 24.098963 | BK17: =BK63*BK$10 -> 26.647596 | BL17: =BL63*BL$10 -> 27.179255 | BM17: =BM63*BM$10 -> 29.139092 | BN17: =SUM(BJ17:BM17) -> 107.06491 | BO17: =BO63*BO$10 -> 26.374573 | BP17: =BP63*BP$10 -> 29.185008 | BQ17: =BQ63*BQ$10 -> 29.815641 | BR17: =BR63*BR$10 -> 31.929363 | BS17: =SUM(BO17:BR17) -> 117.30458
A18: General & Administrative | B18: 3.982 | C18: 3.928 | D18: 5.715 | E18: 5.229 | F18: =SUM(B18:E18) -> 18.854 | G18: 5.798 | H18: 5.536 | I18: 5.728 | J18: 5.521 | K18: =SUM(G18:J18) -> 22.583 | L18: 6.228 | M18: 6.071 | N18: 5.763 | O18: 5.725 | P18: =SUM(L18:O18) -> 23.787 | Q18: 6.019 | R18: 6.192 | S18: 5.52 | T18: 5.357 | U18: =SUM(Q18:T18) -> 23.088 | V18: 5.644 | W18: 5.932 | X18: 5.742 | Y18: 6.645 | Z18: =SUM(V18:Y18) -> 23.963 | AA18: 6.904 | AB18: 6.92 | AC18: 6.624 | AD18: 8.581 | AE18: =SUM(AA18:AD18) -> 29.029 | AF18: 7.813 | AG18: 7.957 | AH18: 8.546 | AI18: 12.413 | AJ18: =SUM(AF18:AI18) -> 36.729 | AK18: =46.282-35.1 -> 11.182 | AL18: =15.473 -> 15.473 | AM18: 20.749 | AN18: 18.849 | AO18: =SUM(AK18:AN18) -> 66.253 | AP18: 18.022 | AQ18: 16.765 | AR18: 16.328 | AS18: 16.84 | AT18: =SUM(AP18:AS18) -> 67.955 | AU18: 16.281 | AV18: 17.894 | AW18: 17.95 | AX18: 17.935 | AY18: =SUM(AU18:AX18) -> 70.06 | AZ18: 17.799 | BA18: 22.562 | BB18: 20.732 | BC18: 17.569 | BD18: =SUM(AZ18:BC18) -> 78.662 | BE18: 22.348 | BF18: 22.941 | BG18: 22.254 | BH18: 22.294 | BI18: =SUM(BE18:BH18) -> 89.837 | BJ18: =BJ64*BJ$10 -> 23.44764 | BK18: =BK64*BK$10 -> 25.911474 | BL18: =BL64*BL$10 -> 25.718005 | BM18: =BM64*BM$10 -> 26.838638 | BN18: =SUM(BJ18:BM18) -> 101.91576 | BO18: =BO64*BO$10 -> 25.653956 | BP18: =BP64*BP$10 -> 28.369784 | BQ18: =BQ64*BQ$10 -> 28.195226 | BR18: =BR64*BR$10 -> 29.381807 | BS18: =SUM(BO18:BR18) -> 111.60077
A19: Total Operating Expenses | B19: =SUM(B16:B18) -> 10.444 | C19: =SUM(C16:C18) -> 11.272 | D19: =SUM(D16:D18) -> 13.481 | E19: =SUM(E16:E18) -> 15.393 | F19: =SUM(F16:F18) -> 50.59 | G19: =SUM(G16:G18) -> 14.205 | H19: =SUM(H16:H18) -> 15.576 | I19: =SUM(I16:I18) -> 15.339 | ... BS19: =SUM(BS16:BS18) -> 311.25498
A20: Operating Income | B20: =+B15-B19 -> -6.575 | C20: =+C15-C19 -> -6.561 | D20: =+D15-D19 -> -7.811 | E20: =+E15-E19 -> -8.059 | F20: =+F15-F19 -> -29.006 | G20: =+G15-G19 -> -7.553 | H20: =+H15-H19 -> -8.807 | I20: =+I15-I19 -> -8.622 | ... BS20: =+BS15-BS19 -> 154.56242
A21: Interest Expense | B21: -0.111 | C21: -0.113 | D21: -0.114 | E21: -0.101 | F21: =SUM(B21:E21) -> -0.439 | G21: -0.089 | H21: -0.09 | I21: -0.092 | J21: -0.096 | K21: =SUM(G21:J21) -> -0.367 | L21: -0.367 | M21: -0.785 | N21: -0.799 | O21: -0.806 | P21: =SUM(L21:O21) -> -2.757 | Q21: -0.8 | R21: -0.808 | S21: -0.815 | T21: -2.518 | U21: =SUM(Q21:T21) -> -4.941 | V21: -0.448 | W21: -0.481 | X21: -0.498 | Y21: -0.536 | Z21: =SUM(V21:Y21) -> -1.963 | AA21: -0.303 | AB21: -0.235 | AC21: -0.058 | AD21: -0.081 | AE21: =SUM(AA21:AD21) -> -0.677 | AF21: -0.055 | AG21: -0.065 | AH21: -0.055 | AI21: -0.054 | AJ21: =SUM(AF21:AI21) -> -0.229 | AK21: -0.053 | AL21: -0.063 | AM21: 1.202 | AN21: 1.016 | AO21: =SUM(AK21:AN21) -> 2.102 | AP21: 0 | AQ21: 0 | AR21: 0 | AS21: 0 | AT21: =SUM(AP21:AS21) -> 0 | AU21: 0 | AW21: 0 | AX21: 0 | AY21: =SUM(AU21:AX21) -> 0 | AZ21: 0 | BB21: 0 | BC21: 0 | BD21: =SUM(AZ21:BC21) -> 0 | BE21: 0 | BG21: 0 | BH21: 0 | BI21: =SUM(BE21:BH21) -> 0 | BJ21: 0 | BK21: 0 | BL21: 0 | BM21: 0 | BN21: =SUM(BJ21:BM21) -> 0 | BO21: 0 | BP21: 0 | BQ21: 0 | BR21: 0 | BS21: =SUM(BO21:BR21) -> 0
A22: Other Income (Expense) | B22: 0.012 | C22: 0.019 | D22: 0.023 | E22: 0.018 | F22: =SUM(B22:E22) -> 0.072 | G22: 0.032 | H22: 0.028 | I22: 0.035 | J22: 0.034 | K22: =SUM(G22:J22) -> 0.129 | L22: 0.043 | M22: 0.036 | N22: 0.048 | O22: 0.075 | P22: =SUM(L22:O22) -> 0.202 | Q22: 0.1 | R22: 0.119 | S22: 0.134 | T22: 0.123 | U22: =SUM(Q22:T22) -> 0.476 | V22: 0.226 | W22: 0.15 | X22: 0.333 | Y22: 0.488 | Z22: =SUM(V22:Y22) -> 1.197 | AA22: 0.453 | AB22: 0.841 | AC22: 1.091 | AD22: 0.82 | AE22: =SUM(AA22:AD22) -> 3.205 | AF22: 0.539 | AG22: 0.091 | AH22: -0.003 | AI22: 0.082 | AJ22: =SUM(AF22:AI22) -> 0.709 | AK22: -0.195 | AL22: -1.653 | AM22: 0 | AN22: 0 | AO22: =SUM(AK22:AN22) -> -1.848 | AP22: 0.784 | AQ22: 1.086 | AR22: 0.805 | AS22: 1.979 | AT22: =SUM(AP22:AS22) -> 4.654 | AU22: 2.407 | AV22: -0.226 | AW22: 1.967 | AX22: 5.035 | AY22: =SUM(AU22:AX22) -> 9.183 | AZ22: 2.748 | BA22: 2.755 | BB22: 3.042 | BC22: =-0.732+1.89 -> 1.158 | BD22: =SUM(AZ22:BC22) -> 9.703 | BE22: 3.421 | BF22: 3.984 | BG22: =-4.057+8.138-1.308 -> 2.773 | BH22: =3.439 -> 3.439 | BI22: =SUM(BE22:BH22) -> 13.617 | BJ22: 0.1 | BK22: 0.1 | BL22: 0.1 | BM22: 0.1 | BN22: =SUM(BJ22:BM22) -> 0.4 | BO22: 0.1 | BP22: 0.1 | BQ22: 0.1 | BR22: 0.1 | BS22: =SUM(BO22:BR22) -> 0.4
A23: Pretax Income | B23: =B20+B22+B21 -> -6.674 | C23: =C20+C22+C21 -> -6.655 | D23: =D20+D22+D21 -> -7.902 | E23: =E20+E22+E21 -> -8.142 | F23: =F20+F22+F21 -> -29.373 | G23: =G20+G22+G21 -> -7.61 | H23: =H20+H22+H21 -> -8.869 | I23: =I20+I22+I21 -> -8.679 | ... BS23: =BS20+BS22+BS21 -> 154.96242
A24: Provision for Income Taxes | B24: 0 | C24: 0 | D24: 0 | E24: 0 | F24: =SUM(B24:E24) -> 0 | G24: 0 | H24: 0 | I24: 0 | J24: 0 | K24: =SUM(G24:J24) -> 0 | L24: 0 | M24: 0 | N24: 0 | O24: 0 | P24: =SUM(L24:O24) -> 0 | Q24: 0 | R24: 0 | S24: 0 | T24: 0 | U24: =SUM(Q24:T24) -> 0 | V24: 0 | W24: 0 | X24: 0 | Y24: 0 | Z24: =SUM(V24:Y24) -> 0 | AA24: 0 | AB24: 0 | AC24: 0 | AD24: 0 | AE24: =SUM(AA24:AD24) -> 0 | AF24: 0 | AG24: 0 | AH24: 0 | AI24: 0 | AJ24: =SUM(AF24:AI24) -> 0 | AK24: =-3.795+0.27 -> -3.525 | AL24: -0.152 | AM24: -1.35 | AN24: -0.789 | AO24: =SUM(AK24:AN24) -> -5.816 | AP24: =-0.003 -> -0.003 | AQ24: -0.115 | AR24: -0.152 | AS24: 0.403 | AT24: =SUM(AP24:AS24) -> 0.133 | AU24: 0.576 | AV24: 0.676 | AW24: 0.97 | AX24: 1.208 | AY24: =SUM(AU24:AX24) -> 3.43 | AZ24: 1.088 | BA24: 1.741 | BB24: =BB25*BB23 -> 1.926066 | BC24: =-1.67-1.83 -> -3.5 | BD24: =SUM(AZ24:BC24) -> 1.255066 | BE24: 1.06 | BF24: =2.23-0.437 -> 1.793 | BG24: =-0.248-0.565 -> -0.813 | BH24: =-0.515+1.59 -> 1.075 | BI24: =SUM(BE24:BH24) -> 3.115 | BJ24: =BJ25*BJ23 -> 1.4900172 | BK24: =BK25*BK23 -> 1.7348854 | BL24: =BL25*BL23 -> 1.7292753 | BM24: =BM25*BM23 -> 1.899041 | BN24: =SUM(BJ24:BM24) -> 6.8532188 | BO24: =BO25*BO23 -> 1.684037 | BP24: =BP25*BP23 -> 1.9615368 | BQ24: =BQ25*BQ23 -> 1.9576004 | BR24: =BR25*BR23 -> 2.1449467 | BS24: =SUM(BO24:BR24) -> 7.7481209
A25: Tax Rate | B25: =B24/B23 -> 0 | C25: =C24/C23 -> 0 | D25: =D24/D23 -> 0 | E25: =E24/E23 -> 0 | F25: =F24/F23 -> 0 | G25: =G24/G23 -> 0 | H25: =H24/H23 -> 0 | I25: =I24/I23 -> 0 | ... BA25: =BA24/BA23 -> 0.069241171 | BB25: 0.069 | BC25: =BC24/BC23 -> -0.13752996 | BD25: =BD24/BD23 -> 0.013320166 | BE25: =BE24/BE23 -> 0.041510025 | BF25: =BF24/BF23 -> 0.048795755 | BG25: 0.069 | BH25: =BH24/BH23 -> 0.024493051 | BI25: =BI24/BI23 -> 0.021298854 | BJ25: 0.05 | BK25: 0.05 | BL25: 0.05 | BM25: 0.05 | BN25: =BN24/BN23 -> 0.05 | BO25: 0.05 | BP25: 0.05 | BQ25: 0.05 | BR25: 0.05 | BS25: =BS24/BS23 -> 0.05
A26: Income Before Non-Recurring | B26: =+B23-B24 -> -6.674 | C26: =+C23-C24 -> -6.655 | D26: =+D23-D24 -> -7.902 | E26: =+E23-E24 -> -8.142 | F26: =+F23-F24 -> -29.373 | G26: =+G23-G24 -> -7.61 | H26: =+H23-H24 -> -8.869 | I26: =+I23-I24 -> -8.679 | ... BS26: =+BS23-BS24 -> 147.2143
A27: Intangible Asset Amortization | B27: 0 | C27: 0 | D27: 0 | E27: 0 | F27: =SUM(B27:E27) -> 0 | G27: 0 | H27: -0.267 | I27: -0.266 | J27: -0.267 | K27: =SUM(G27:J27) -> -0.8 | L27: -0.267 | M27: -0.267 | N27: -0.266 | O27: -0.267 | P27: =SUM(L27:O27) -> -1.067 | Q27: -0.267 | R27: -0.266 | S27: -0.267 | T27: -0.267 | U27: =SUM(Q27:T27) -> -1.067 | V27: -0.267 | W27: -0.266 | X27: -0.267 | Y27: -0.267 | Z27: =SUM(V27:Y27) -> -1.067 | AA27: -0.267 | AB27: -0.266 | AC27: -0.267 | AD27: -0.601 | AE27: =SUM(AA27:AD27) -> -1.401 | AF27: -1.275 | AG27: -1.273 | AH27: -1.274 | AI27: -1.273 | AJ27: =SUM(AF27:AI27) -> -5.095 | AK27: -1.801 | AL27: -3.723 | AM27: -4.983 | AN27: -5.474 | AO27: =SUM(AK27:AN27) -> -15.981 | AP27: -5.486 | AQ27: -5.391 | AR27: -5.213 | AS27: -5.264 | AT27: =SUM(AP27:AS27) -> -21.354 | AY27: =SUM(AU27:AX27) -> 0 | BD27: =SUM(AZ27:BC27) -> 0 | BI27: =SUM(BE27:BH27) -> 0 | BN27: =SUM(BJ27:BM27) -> 0 | BS27: =SUM(BO27:BR27) -> 0
A28: Net Other Items | B28: 0 | C28: 0 | D28: 0 | E28: 0 | F28: =SUM(B28:E28) -> 0 | G28: 0 | H28: 0 | I28: 0 | J28: 0 | K28: =SUM(G28:J28) -> 0 | L28: 0 | M28: 0 | N28: 0 | O28: 0 | P28: =SUM(L28:O28) -> 0 | Q28: 0 | R28: 0 | S28: 0 | T28: 0 | U28: =SUM(Q28:T28) -> 0 | V28: 0 | W28: 0 | X28: 0 | Y28: 0 | Z28: =SUM(V28:Y28) -> 0 | AA28: 0 | AB28: 0 | AC28: 0 | AD28: 0 | AE28: =SUM(AA28:AD28) -> 0 | AF28: -1.088 | AG28: 0 | AH28: 0 | AI28: 0 | AJ28: =SUM(AF28:AI28) -> -1.088 | AK28: -34.83 | AL28: 0 | AM28: 0 | AN28: 0 | AO28: =SUM(AK28:AN28) -> -34.83 | AP28: =-4.934 -> -4.934 | AQ28: =-0.982-3.318 -> -4.3 | AR28: =-2.557-0.514 -> -3.071 | AS28: -2.631 | AT28: =SUM(AP28:AS28) -> -14.936 | AY28: =SUM(AU28:AX28) -> 0 | BD28: =SUM(AZ28:BC28) -> 0 | BI28: =SUM(BE28:BH28) -> 0 | BN28: =SUM(BJ28:BM28) -> 0 | BS28: =SUM(BO28:BR28) -> 0
A29: Non-GAAP Net Income | B29: =SUM(B26:B28) -> -6.674 | C29: =SUM(C26:C28) -> -6.655 | D29: =SUM(D26:D28) -> -7.902 | E29: =SUM(E26:E28) -> -8.142 | F29: =SUM(F26:F28) -> -29.373 | G29: =SUM(G26:G28) -> -7.61 | H29: =SUM(H26:H28) -> -9.136 | I29: =SUM(I26:I28) -> -8.945 | ... AT29: =SUM(AT26:AT28) -> -36.61 | AU29: =+AU23-AU24 -> 7.263 | AV29: =+AV23-AV24 -> 8.538 | AW29: =+AW23-AW24 -> 12.246 | AX29: =+AX23-AX24 -> 15.247 | AY29: =+AY23-AY24 -> 43.294 | AZ29: =+AZ23-AZ24 -> 14.628 | BA29: =+BA23-BA24 -> 23.403 | BB29: =+BB23-BB24 -> 25.987934 | ... BS29: =+BS23-BS24 -> 147.2143
A31: Weighted Average Shares (Basic) | B31: 21.148342 | C31: 21.237196 | D31: 21.64866 | E31: 22.50825 | F31: 21.639374 | G31: 22.539723 | H31: 26.048934 | I31: 27.640806 | J31: 27.672806 | K31: 25.944193 | L31: 27.817993 | M31: 27.859918 | N31: 27.916819 | O31: 31.705603 | P31: 28.830472 | Q31: 33.823889 | R31: 33.873128 | S31: 33.946748 | T31: 34.055524 | U31: 33.925617 | V31: 34.271254 | W31: 34.314234 | X31: 38.620036 | Y31: 40.731334 | Z31: 37.020246 | AA31: 41.168593 | AB31: 45.586081 | AC31: 48.588296 | AD31: 49.095703 | AE31: 46.138177 | AF31: 49.792631 | AG31: 50.212123 | AH31: 54.858052 | AI31: 58.023753 | AJ31: =AVERAGE(AF31:AI31) -> 53.22164 | AK31: 63.331702 | AL31: 67.316065 | AM31: 69.743733 | AN31: 71.064467 | AO31: =AVERAGE(AK31:AN31) -> 67.863992 | AP31: 71.229672 | AQ31: 71.476966 | AR31: 71.656694 | AS31: 71.825754 | AT31: =AVERAGE(AP31:AS31) -> 71.547272 | AU31: 72.175457 | AV31: 72.478662 | AW31: 72.80477 | AX31: 73.107059 | AY31: =AVERAGE(AU31:AX31) -> 72.641487 | AZ31: 74.759789 | BA31: 77.163149 | BB31: 78.464654 | BC31: 77.608924 | BD31: =AVERAGE(AZ31:BC31) -> 76.999129 | BE31: 80.056024 | BF31: 78.391502 | BG31: 78.725139 | BH31: 79.178087 | BI31: =AVERAGE(BE31:BH31) -> 79.087688 | BJ31: =+BH31+0.4 -> 79.578087 | BK31: =+BJ31+0.4 -> 79.978087 | BL31: =+BK31+0.4 -> 80.378087 | BM31: =+BL31+0.4 -> 80.778087 | BN31: =AVERAGE(BJ31:BM31) -> 80.178087 | BO31: =+BM31+0.4 -> 81.178087 | BP31: =+BO31+0.4 -> 81.578087 | BQ31: =+BP31+0.4 -> 81.978087 | BR31: =+BQ31+0.4 -> 82.378087 | BS31: =AVERAGE(BO31:BR31) -> 81.778087
A32: Effect of Dilutive Securities | B32: =+B33-B31 -> 0 | C32: =+C33-C31 -> 0 | D32: =+D33-D31 -> 0 | E32: =+E33-E31 -> 0 | F32: =+F33-F31 -> 0 | G32: =+G33-G31 -> 0 | H32: =+H33-H31 -> 0 | I32: =+I33-I31 -> 0 | ... R32: =+R33-R31 -> 0 | S32: 0.9 | T32: =+T33-T31 -> 0 | U32: =+U33-U31 -> 0 | V32: =+V33-V31 -> 0 | W32: =+W33-W31 -> 0 | X32: =+X33-X31 -> 0 | Y32: 0 | Z32: =+Z33-Z31 -> 0 | AA32: 0 | AB32: 0 | AC32: 0 | AD32: 0 | AE32: =+AE33-AE31 -> 0 | AF32: =+AF33-AF31 -> 0 | AG32: =+AG33-AG31 -> 0 | AH32: =+AH33-AH31 -> 0 | AI32: 0 | AJ32: =+AJ33-AJ31 -> 0 | AK32: 0 | AL32: 0 | AM32: 0 | AN32: 0 | AO32: =+AO33-AO31 -> 0 | AP32: 0 | AQ32: 0 | AR32: 0 | AS32: 0 | AT32: =+AT33-AT31 -> 0 | AU32: 0 | AV32: 0 | AW32: 0 | AX32: 0 | AY32: =+AX32 -> 0 | AZ32: 0 | BA32: 0 | BB32: 0 | BC32: 0 | BD32: =+BC32 -> 0 | BE32: 0 | BF32: 0 | BG32: 0 | BH32: 0 | BI32: =+BH32 -> 0 | BJ32: 0 | BK32: 0 | BL32: 0 | BM32: 0 | BN32: =+BM32 -> 0 | BO32: 0 | BP32: 0 | BQ32: 0 | BR32: 0 | BS32: =+BR32 -> 0
