Workbook

Sheet __FDSCACHE__
B1: This sheet contains FactSet XML data for use with this workbook's =FDS codes. Modifying the worksheet's contents may damage the workbook's =FDS functionality.

Sheet Comparison
B2: Bill.com, Inc. (BILL)
B4: Variance Analysis | D4: =IS!AN4 -> 2Q25 | E4: =K4 -> 2Q26 | F4: Y/Y Change | G4: =IS!AR4 -> 1Q26 | H4: =K4 -> 2Q26 | I4: Q/Q Change | J4: 2Q26E | K4: =IS!AS4 -> 2Q26 | L4: % Difference
B5: Subscription and transaction fees | C5: Subscription Revenue | D5: =IS!AN5 -> 67721 | E5: =K5 -> 72100 | F5: =E5/D5-1 -> 0.064662365 | G5: =IS!AR5 -> 70823 | H5: =K5 -> 72100 | I5: =H5/G5-1 -> 0.018030866 | J5: 73051.39 | K5: =IS!AS5 -> 72100 | L5: =K5/J5-1 -> -0.013023566
C6: Transaction Revenue | D6: =IS!AN8 -> 251895 | E6: =K6 -> 303028 | F6: =E6/D6-1 -> 0.20299331 | G6: =IS!AR8 -> 287182 | H6: =K6 -> 303028 | I6: =H6/G6-1 -> 0.055177553 | J6: 290999.86 | K6: =IS!AS8 -> 303028 | L6: =K6/J6-1 -> 0.041333831
C7: Float Revenue | D7: =IS!AN14 -> 42938 | E7: =K7 -> 39543 | F7: =E7/D7-1 -> -0.079067493 | G7: =IS!AR14 -> 37736 | H7: =K7 -> 39543 | I7: =H7/G7-1 -> 0.047885308 | J7: 33802.488 | K7: =IS!AS14 -> 39543 | L7: =K7/J7-1 -> 0.16982514
B8: Total Revenue | D8: =IS!AN17 -> 362554 | E8: =K8 -> 414671 | F8: =E8/D8-1 -> 0.14374962 | G8: =IS!AR17 -> 395741 | H8: =K8 -> 414671 | I8: =H8/G8-1 -> 0.047834316 | J8: 397853.74 | K8: =IS!AS17 -> 414671 | L8: =K8/J8-1 -> 0.04226996
B10: Cost of Revenue | D10: =IS!AN21 -> 53644 | E10: =K10 -> 66892 | F10: =E10/D10-1 -> 0.24696145 | G10: =IS!AR21 -> 63661 | H10: =K10 -> 66892 | I10: =H10/G10-1 -> 0.050753208 | J10: 61547.973 | K10: =IS!AS21 -> 66892 | L10: =K10/J10-1 -> 0.086827013
B11: Gross Profit | D11: =D8-D10 -> 308910 | E11: =K11 -> 347779 | F11: =E11/D11-1 -> 0.12582629 | G11: =G8-G10 -> 332080 | H11: =K11 -> 347779 | I11: =H11/G11-1 -> 0.047274753 | J11: 336305.77 | K11: =K8-K10 -> 347779 | L11: =K11/J11-1 -> 0.034115487
C12: Gross Margin | D12: =D11/D8 -> 0.85203859 | E12: =K12 -> 0.83868657 | G12: =G11/G8 -> 0.83913469 | H12: =K12 -> 0.83868657 | J12: 0.8453 | K12: =K11/K8 -> 0.83868657
B14: Operating Expenses
C15: =IS!C26 -> Research & Development | D15: =IS!AN26 -> 55010 | E15: =K15 -> 53256 | F15: =E15/D15-1 -> -0.031885112 | G15: =IS!AR26 -> 53860 | H15: =K15 -> 53256 | I15: =H15/G15-1 -> -0.011214259 | J15: 65248.013 | K15: =IS!AS26 -> 53256 | L15: =K15/J15-1 -> -0.18379124
C16: =IS!C32 -> Sales & Marketing | D16: =IS!AN32 -> 121878 | E16: =K16 -> 145251 | F16: =E16/D16-1 -> 0.19177374 | G16: =IS!AR32 -> 139415 | H16: =K16 -> 145251 | I16: =H16/G16-1 -> 0.041860632 | J16: 135270.27 | K16: =IS!AS32 -> 145251 | L16: =K16/J16-1 -> 0.07378361
C17: =IS!C38 -> General & Administrative | D17: =IS!AN38 -> 69216 | E17: =K17 -> 75187 | F17: =E17/D17-1 -> 0.086266181 | G17: =IS!AR38 -> 70569 | H17: =K17 -> 75187 | I17: =H17/G17-1 -> 0.065439499 | J17: 70817.965 | K17: =IS!AS38 -> 75187 | L17: =K17/J17-1 -> 0.061693873
B18: Total Operating Expenses | D18: =SUM(D15:D17) -> 246104 | E18: =K18 -> 273694 | F18: =E18/D18-1 -> 0.11210708 | G18: =SUM(G15:G17) -> 263844 | H18: =K18 -> 273694 | I18: =H18/G18-1 -> 0.037332666 | J18: 271336.25 | K18: =SUM(K15:K17) -> 273694 | L18: =K18/J18-1 -> 0.0086894043
B20: Non-GAAP Operating Income | D20: =D11-D18 -> 62806 | E20: =K20 -> 74085 | F20: =E20/D20-1 -> 0.17958475 | G20: =G11-G18 -> 68236 | H20: =K20 -> 74085 | I20: =H20/G20-1 -> 0.085717217 | J20: 64969.515 | K20: =K11-K18 -> 74085 | L20: =K20/J20-1 -> 0.14030402
C21: Non-GAAP Operating Margin | D21: =D20/D8 -> 0.17323213 | E21: =K21 -> 0.17865971 | G21: =G20/G8 -> 0.1724259 | H21: =K21 -> 0.17865971 | J21: 0.1633 | K21: =K20/K8 -> 0.17865971
B23: GAAP Adjustments | D23: =IS!AN52 -> 84516 | E23: =K23 -> 92161 | F23: =E23/D23-1 -> 0.090456245 | G23: =IS!AR52 -> 88955 | H23: =K23 -> 92161 | I23: =H23/G23-1 -> 0.036040695 | J23: 89000 | K23: =IS!AS52 -> 92161 | L23: =K23/J23-1 -> 0.035516854
B25: GAAP Operating Income | D25: =D20-D23 -> -21710 | E25: =K25 -> -18076 | F25: =E25/D25-1 -> -0.1673883 | G25: =G20-G23 -> -20719 | H25: =K25 -> -18076 | I25: =H25/G25-1 -> -0.12756407 | J25: -24030.485 | K25: =K20-K23 -> -18076 | L25: =K25/J25-1 -> -0.24778878
C26: GAAP Operating Margin | D26: =D25/D8 -> -0.059880735 | E26: =K26 -> -0.043591184 | G26: =G25/G8 -> -0.052354949 | H26: =K26 -> -0.043591184 | J26: -0.060400298 | K26: =K25/K8 -> -0.043591184
B28: Non-GAAP Other Income | D28: =IS!AN61 -> 15832 | E28: =K28 -> 17635 | F28: =E28/D28-1 -> 0.11388327 | G28: =IS!AR61 -> 19516 | H28: =K28 -> 17635 | I28: =H28/G28-1 -> -0.096382455 | J28: 15650 | K28: =IS!AS61 -> 17635 | L28: =K28/J28-1 -> 0.12683706
B30: Non-GAAP Income before Taxes | D30: =IS!AN66 -> 78638 | E30: =K30 -> 91720 | F30: =E30/D30-1 -> 0.16635723 | G30: =IS!AR66 -> 87752 | H30: =K30 -> 91720 | I30: =H30/G30-1 -> 0.045218343 | J30: 80619.515 | K30: =IS!AS66 -> 91720 | L30: =K30/J30-1 -> 0.13768979
B31: Income Tax | D31: =IS!AN67 -> 15728 | E31: =K31 -> 18344 | G31: =IS!AR67 -> 17550 | H31: =K31 -> 18344 | J31: 16123.903 | K31: =IS!AS67 -> 18344
B32: Non-GAAP Net Income | D32: =D30-D31 -> 62910 | E32: =K32 -> 73376 | F32: =E32/D32-1 -> 0.16636465 | G32: =G30-G31 -> 70202 | H32: =K32 -> 73376 | I32: =H32/G32-1 -> 0.045212387 | J32: 64495.612 | K32: =K30-K31 -> 73376 | L32: =K32/J32-1 -> 0.13768979
B34: GAAP Income before Taxes | D34: =D25+D28 -> -5878 | E34: =K34 -> -441 | F34: =E34/D34-1 -> -0.92497448 | G34: =G25+G28 -> -1203 | H34: =K34 -> -441 | I34: =H34/G34-1 -> -0.63341646 | J34: -8380.4845 | K34: =K25+K28 -> -441 | L34: =K34/J34-1 -> -0.94737774
B35: Income Tax | D35: =IS!AN73 -> 45 | E35: =K35 -> 522 | F35: =E35/D35-1 -> 10.6 | G35: =IS!AR73 -> 149 | H35: =K35 -> 522 | I35: =H35/G35-1 -> 2.5033557 | J35: 500 | K35: =IS!AS73 -> 522 | L35: =K35/J35-1 -> 0.044
B36: GAAP Net Income | D36: =D34-D35 -> -5923 | E36: =K36 -> -963 | F36: =E36/D36-1 -> -0.83741347 | G36: =G34-G35 -> -1352 | H36: =K36 -> -963 | I36: =H36/G36-1 -> -0.28772189 | J36: -8880.4845 | K36: =K34-K35 -> -963 | L36: =K36/J36-1 -> -0.89155997
B38: Non- GAAP EPS | D38: =IS!AN79 -> 0.56210295 | E38: =K38 -> 0.64031276 | G38: =IS!AR79 -> 0.60787794 | H38: =K38 -> 0.64031276 | J38: 0.55513561 | K38: =IS!AS79 -> 0.64031276
B39: GAAP EPS | D39: =IS!AN81 -> 0.2997525 | E39: =K39 -> -0.025743047 | G39: =IS!AR81 -> -0.029061439 | H39: =K39 -> -0.025743047 | J39: -0.1024265 | K39: =IS!AS81 -> -0.025743047
B41: Basic Shares Outstanding | D41: =IS!AN84 -> 104480 | E41: =K41 -> 100532 | G41: =IS!AR84 -> 101922 | H41: =K41 -> 100532 | J41: 102322 | K41: =IS!AS84 -> 100532
B42: Diluted Shares Outstanding | D42: =IS!AN85 -> 111919 | E42: =K42 -> 114594 | G42: =IS!AR85 -> 115487 | H42: =K42 -> 114594 | J42: 116179.92 | K42: =IS!AS85 -> 114594
B44: AP/AR Variance Analysis | D44: =IS!AN$4 -> 2Q25 | E44: =K44 -> 2Q26 | F44: Y/Y Change | G44: =IS!AR$4 -> 1Q26 | H44: =K44 -> 2Q26 | I44: Q/Q Change | J44: 2Q26E | K44: =IS!AS$4 -> 2Q26 | L44: % Difference
B45: Customer Count | D45: ='Revenue Build'!AN4 -> 160600 | E45: =K45 -> 177500 | F45: =E45/D45-1 -> 0.10523039 | G45: ='Revenue Build'!AR4 -> 173500 | H45: =K45 -> 177500 | I45: =H45/G45-1 -> 0.023054755 | J45: 177500 | K45: ='Revenue Build'!AS4 -> 177500 | L45: =K45/J45-1 -> 0
C46: Quarterly Adds | D46: ='Revenue Build'!AN5 -> 4500 | E46: =K46 -> 4000 | F46: =E46/D46-1 -> -0.11111111 | G46: ='Revenue Build'!AR5 -> 4000 | H46: =K46 -> 4000 | I46: =H46/G46-1 -> 0 | J46: 4000 | K46: ='Revenue Build'!AS5 -> 4000 | L46: =K46/J46-1 -> 0
C47: Sub. Revenue/Customer | D47: ='Revenue Build'!AN8 -> 339.35243 | E47: =K47 -> 325.07042 | F47: =E47/D47-1 -> -0.042086058 | G47: ='Revenue Build'!AR8 -> 323.34294 | H47: =K47 -> 325.07042 | I47: =H47/G47-1 -> 0.0053425724 | J47: 335.9589 | K47: ='Revenue Build'!AS8 -> 325.07042 | L47: =K47/J47-1 -> -0.032410159
B49: Total Payment Volume | D49: ='Revenue Build'!AN20*1000 -> 71900 | E49: =K49 -> 79900 | F49: =E49/D49-1 -> 0.11126565 | G49: ='Revenue Build'!AR20*1000 -> 74700 | H49: =K49 -> 79900 | I49: =H49/G49-1 -> 0.06961178 | J49: 76933 | K49: ='Revenue Build'!AS20*1000 -> 79900 | L49: =K49/J49-1 -> 0.038566025
C50: Transactions | D50: ='Revenue Build'!AN14 -> 12.2 | E50: =K50 -> 12.8 | F50: =E50/D50-1 -> 0.049180328 | G50: ='Revenue Build'!AR14 -> 12.5 | H50: =K50 -> 12.8 | I50: =H50/G50-1 -> 0.024 | J50: 13.054 | K50: ='Revenue Build'!AS14 -> 12.8 | L50: =K50/J50-1 -> -0.019457638
C51: Average Transaction Size | D51: ='Revenue Build'!AN17 -> 5893.4426 | E51: =K51 -> 6242.1875 | F51: =E51/D51-1 -> 0.05917507 | G51: ='Revenue Build'!AR17 -> 5976 | H51: =K51 -> 6242.1875 | I51: =H51/G51-1 -> 0.044542754 | J51: 5893.4426 | K51: ='Revenue Build'!AS17 -> 6242.1875 | L51: =K51/J51-1 -> 0.05917507
B53: Take Rate (BPs) | D53: ='Revenue Build'!AN23 -> 15.624757 | E53: =K53 -> 16.036045 | F53: =E53/D53-1 -> 0.026322871 | G53: ='Revenue Build'!AR23 -> 16.398394 | H53: =K53 -> 16.036045 | I53: =H53/G53-1 -> -0.022096586 | J53: 16.2 | K53: ='Revenue Build'!AS23 -> 16.036045 | L53: =K53/J53-1 -> -0.010120676
B55: Segment Revenue | D55: ='Revenue Build'!AN29 -> 166842 | E55: =K55 -> 185828 | F55: =E55/D55-1 -> 0.11379629 | G55: ='Revenue Build'!AR29 -> 178596 | H55: =K55 -> 185828 | I55: =H55/G55-1 -> 0.040493628 | J55: 184264.17 | K55: ='Revenue Build'!AS29 -> 185828 | L55: =K55/J55-1 -> 0.0084869161
C56: Subscription Revenue | D56: ='Revenue Build'!AN11 -> 54500 | E56: =K56 -> 57700 | F56: =E56/D56-1 -> 0.058715596 | G56: ='Revenue Build'!AR11 -> 56100 | H56: =K56 -> 57700 | I56: =H56/G56-1 -> 0.028520499 | J56: 59632.705 | K56: ='Revenue Build'!AS11 -> 57700 | L56: =K56/J56-1 -> -0.032410159
...

Sheet Guide
C4: FY26 Guide Midpoint | D4: FY26 Prior Guide | E4: FY26 Updated Guidance | F4: Upside/ Downside | G4: 2Q Results | H4: 2Q Guide | I4: 2Q Beat | J4: Rest of Year Raise / (Reduce)
C5: Total Revenue | D5: 1612 | E5: 1641 | F5: =E5-D5 -> 29 | G5: =Comparison!K8/1000 -> 414.671 | H5: 399.5 | I5: =G5-H5 -> 15.171 | J5: =F5-I5 -> 13.829
C6: Growth | D6: =1000*D5/IS!AQ17-1 -> 0.10216947 | E6: =1000*E5/IS!AQ17-1 -> 0.12199758
C7: Non-GAAP Operating Income | D7: 267 | E7: 280.25 | F7: =E7-D7 -> 13.25 | G7: =Comparison!K20/1000 -> 74.085 | H7: 65 | I7: =G7-H7 -> 9.085 | J7: =F7-I7 -> 4.165
C8: Margin | D8: =D7/D5 -> 0.16563275 | E8: =E7/E5 -> 0.17078001
C9: Non-GAAP EPS | D9: 2.18 | E9: 2.37 | F9: =E9-D9 -> 0.19 | G9: =Comparison!K38 -> 0.64031276 | H9: 0.555 | I9: =G9-H9 -> 0.085312756 | J9: =F9-I9 -> 0.10468724
C17: FY26 Guide Midpoint | D17: FY26 Guide | E17: FY26E Street | F17: Upside/Downside
C18: Total Revenue | D18: =AVERAGE(1589.5,1629.5) -> 1609.5 | E18: 1634.2 | F18: =D18-E18 -> -24.7
C19: Growth | D19: =D18/(IS!AQ17/1000)-1 -> 0.10046015 | E19: =1000*E18/IS!AQ17-1 -> 0.11734823
C20: Non-GAAP Net Income | D20: 255 | E20: 259 | F20: =D20-E20 -> -4
C21: Margin | D21: =D20/D18 -> 0.1584343 | E21: =E20/E18 -> 0.15848733
C22: Non-GAAP EPS | D22: 2.1 | E22: 2.18 | F22: =D22-E22 -> -0.08
E24: =AVERAGE(1450.5,1490.5) -> 1470.5
E25: =E18-E24 -> 163.7

Sheet IS
B2: Bill.com, Inc. (BILL) | D2: ="Sep. " &C4 -> Sep. | E2: ="Dec. " &C4 -> Dec. | F2: ="Mar. " &H4 -> Mar. 2018 | G2: ="Jun. " &H4 -> Jun. 2018 | I2: ="Sep. " &H4 -> Sep. 2018 | J2: ="Dec. " &H4 -> Dec. 2018 | K2: ="Mar. " &M4 -> Mar. 2019 | L2: ="Jun. " &M4 -> Jun. 2019 | N2: ="Sep. " &M4 -> Sep. 2019 | O2: ="Dec. " &M4 -> Dec. 2019 | P2: ="Mar. " &R4 -> Mar. 2020 | Q2: ="Jun. " &R4 -> Jun. 2020 | S2: ="Sep. " &R4 -> Sep. 2020 | T2: ="Dec. " &R4 -> Dec. 2020 | U2: ="Mar. " &W4 -> Mar. 2021 | V2: ="Jun. " &W4 -> Jun. 2021 | X2: ="Sep. " &W4 -> Sep. 2021 | Y2: ="Dec. " &W4 -> Dec. 2021 | Z2: ="Mar. " &AB4 -> Mar. 2022 | AA2: ="Jun. " &AB4 -> Jun. 2022 | AC2: ="Sep. " &AB4 -> Sep. 2022 | AD2: ="Dec. " &AB4 -> Dec. 2022 | AE2: ="Mar. " &AG4 -> Mar. 2023 | AF2: ="Jun. " &AG4 -> Jun. 2023 | AH2: ="Sep. " &AG4 -> Sep. 2023 | AI2: ="Dec. " &AG4 -> Dec. 2023 | AJ2: ="Mar. " &AL4 -> Mar. 2024 | AK2: ="Jun. " &AL4 -> Jun. 2024 | AM2: ="Sep. " &AL4 -> Sep. 2024 | AN2: ="Dec. " &AL4 -> Dec. 2024 | AO2: ="Mar. " &AQ4 -> Mar. 2025 | AP2: ="Jun. " &AQ4 -> Jun. 2025 | AR2: ="Sep. " &AQ4 -> Sep. 2025 | AS2: ="Dec. " &AQ4 -> Dec. 2025 | AT2: ="Mar. " &AV4 -> Mar. 2026E | AU2: ="Jun. " &AV4 -> Jun. 2026E | AW2: ="Sep. " &AV4 -> Sep. 2026E | AX2: ="Dec. " &AV4 -> Dec. 2026E | AY2: ="Mar. " &BA4 -> Mar. 2027E | AZ2: ="Jun. " &BA4 -> Jun. 2027E
B4: Income Statement | D4: 1Q18 | E4: 2Q18 | F4: 3Q18 | G4: 4Q18 | H4: 2018 | I4: 1Q19 | J4: 2Q19 | K4: 3Q19 | L4: 4Q19 | M4: 2019 | N4: 1Q20 | O4: 2Q20 | P4: 3Q20 | Q4: 4Q20 | R4: 2020 | S4: 1Q21 | T4: 2Q21 | U4: 3Q21 | V4: 4Q21 | W4: 2021 | X4: 1Q22 | Y4: 2Q22 | Z4: 3Q22 | AA4: 4Q22 | AB4: 2022 | AC4: 1Q23 | AD4: 2Q23 | AE4: 3Q23 | AF4: 4Q23 | AG4: 2023 | AH4: 1Q24 | AI4: 2Q24 | AJ4: 3Q24 | AK4: 4Q24 | AL4: 2024 | AM4: 1Q25 | AN4: 2Q25 | AO4: 3Q25 | AP4: 4Q25 | AQ4: 2025 | AR4: 1Q26 | AS4: 2Q26 | AT4: 3Q26E | AU4: 4Q26E | AV4: 2026E | AW4: 1Q27E | AX4: 2Q27E | AY4: 3Q27E | AZ4: 4Q27E | BA4: 2027E
B5: Subscription Revenue | H5: 42000 | I5: 13070.323 | J5: 14316.547 | K5: 15400 | L5: 16813.13 | M5: =SUM(I5:L5) -> 59600 | N5: 18047.775 | O5: 19900 | P5: 22292 | Q5: 23600 | R5: =SUM(N5:Q5) -> 83839.775 | S5: 24600 | T5: 26600 | U5: 29300 | V5: 31200 | W5: =SUM(S5:V5) -> 111700 | X5: 36900 | Y5: 49200 | Z5: 52200 | AA5: ='Revenue Build'!AA143 -> 55300 | AB5: =SUM(X5:AA5) -> 193600 | AC5: 58100 | AD5: ='Revenue Build'!AD143 -> 61500 | AE5: ='Revenue Build'!AE143 -> 66700 | AF5: ='Revenue Build'!AF143 -> 66900 | AG5: =SUM(AC5:AF5) -> 253200 | AH5: ='Revenue Build'!AH143 -> 62400 | AI5: ='Revenue Build'!AI143 -> 63400 | AJ5: ='Revenue Build'!AJ143 -> 65600 | AK5: ='Revenue Build'!AK143 -> 65800 | AL5: =SUM(AH5:AK5) -> 257200 | AM5: ='Revenue Build'!AM143 -> 67383 | AN5: ='Revenue Build'!AN143 -> 67721 | AO5: ='Revenue Build'!AO143 -> 68115 | AP5: ='Revenue Build'!AP143 -> 68787 | AQ5: =SUM(AM5:AP5) -> 272006 | AR5: ='Revenue Build'!AR143 -> 70823 | AS5: ='Revenue Build'!AS143 -> 72100 | AT5: ='Revenue Build'!AT143 -> 72361.685 | AU5: ='Revenue Build'!AU143 -> 73465.459 | AV5: =SUM(AR5:AU5) -> 288750.14 | AW5: ='Revenue Build'!AW143 -> 76928.96 | AX5: ='Revenue Build'!AX143 -> 78464.912 | AY5: ='Revenue Build'!AY143 -> 78779.436 | AZ5: ='Revenue Build'!AZ143 -> 80148.65 | BA5: =SUM(AW5:AZ5) -> 314321.96
C6: Y/Y Growth | M6: =M5/H5-1 -> 0.41904762 | N6: =N5/I5-1 -> 0.38082086 | O6: =O5/J5-1 -> 0.39 | P6: =P5/K5-1 -> 0.44753247 | Q6: =Q5/L5-1 -> 0.40366485 | R6: =R5/M5-1 -> 0.40670763 | S6: =S5/N5-1 -> 0.36304894 | T6: =T5/O5-1 -> 0.33668342 | ... BA6: =BA5/AV5-1 -> 0.088560354
C7: Q/Q Growth | J7: =J5/I5-1 -> 0.095347595 | K7: =K5/J5-1 -> 0.075678392 | L7: =L5/K5-1 -> 0.09176171 | N7: =N5/L5-1 -> 0.073433335 | O7: =O5/N5-1 -> 0.10262902 | P7: =P5/O5-1 -> 0.12020101 | Q7: =Q5/P5-1 -> 0.058675758 | S7: =S5/Q5-1 -> 0.042372881 | T7: =T5/S5-1 -> 0.081300813 | U7: =U5/T5-1 -> 0.10150376 | V7: =V5/U5-1 -> 0.064846416 | X7: =X5/V5-1 -> 0.18269231 | Y7: =Y5/X5-1 -> 0.33333333 | Z7: =Z5/Y5-1 -> 0.06097561 | AA7: =AA5/Z5-1 -> 0.059386973 | AC7: =AC5/AA5-1 -> 0.050632911 | AD7: =AD5/AC5-1 -> 0.058519793 | AE7: =AE5/AD5-1 -> 0.084552846 | AF7: =AF5/AE5-1 -> 0.0029985007 | AH7: =AH5/AF5-1 -> -0.067264574 | AI7: =AI5/AH5-1 -> 0.016025641 | AJ7: =AJ5/AI5-1 -> 0.034700315 | AK7: =AK5/AJ5-1 -> 0.0030487805 | AM7: =AM5/AK5-1 -> 0.024057751 | AN7: =AN5/AM5-1 -> 0.005016102 | AO7: =AO5/AN5-1 -> 0.0058179885 | AP7: =AP5/AO5-1 -> 0.0098656684 | AR7: =AR5/AP5-1 -> 0.029598616 | AS7: =AS5/AR5-1 -> 0.018030866 | AT7: =AT5/AS5-1 -> 0.0036294789 | AU7: =AU5/AT5-1 -> 0.01525356 | AW7: =AW5/AU5-1 -> 0.047144624 | AX7: =AX5/AW5-1 -> 0.019965851 | AY7: =AY5/AX5-1 -> 0.0040084665 | AZ7: =AZ5/AY5-1 -> 0.017380346
B8: Transaction Revenue | I8: 5100 | J8: 6040 | K8: 6700 | L8: 8560 | M8: =SUM(I8:L8) -> 26400 | N8: 10500 | O8: 13100 | P8: 13800 | Q8: 15200 | R8: =SUM(N8:Q8) -> 52600 | S8: 19200 | T8: 25700 | U8: 29300 | V8: 46300 | W8: =SUM(S8:V8) -> 120500 | X8: 80600 | Y8: 106300 | Z8: 113300 | AA8: ='Revenue Build'!AA139 -> 139600 | AB8: =SUM(X8:AA8) -> 439800 | AC8: 156500 | AD8: ='Revenue Build'!AD139 -> 169600 | AE8: ='Revenue Build'!AE139 -> 172700 | AF8: ='Revenue Build'!AF139 -> 192600 | AG8: =SUM(AC8:AF8) -> 691400 | AH8: ='Revenue Build'!AH139 -> 202800 | AI8: ='Revenue Build'!AI139 -> 211600 | AJ8: ='Revenue Build'!AJ139-6 -> 215694 | AK8: ='Revenue Build'!AK139+6 -> 235506 | AL8: =SUM(AH8:AK8) -> 865600 | AM8: ='Revenue Build'!AM139 -> 247560 | AN8: ='Revenue Build'!AN139 -> 251895 | AO8: ='Revenue Build'!AO139 -> 252183 | AP8: ='Revenue Build'!AP139 -> 277160 | AQ8: =SUM(AM8:AP8) -> 1028798 | AR8: ='Revenue Build'!AR139 -> 287182 | AS8: ='Revenue Build'!AS139 -> 303028 | AT8: ='Revenue Build'!AT139 -> 296693.21 | AU8: ='Revenue Build'!AU139 -> 324479.68 | AV8: =SUM(AR8:AU8) -> 1211382.9 | AW8: ='Revenue Build'!AW139 -> 329854.59 | AX8: ='Revenue Build'!AX139 -> 345160.53 | AY8: ='Revenue Build'!AY139 -> 340465.02 | AZ8: ='Revenue Build'!AZ139 -> 370738.9 | BA8: =SUM(AW8:AZ8) -> 1386219
C9: Y/Y Growth | N9: =N8/I8-1 -> 1.0588235 | O9: =O8/J8-1 -> 1.1688742 | P9: =P8/K8-1 -> 1.0597015 | Q9: =Q8/L8-1 -> 0.77570093 | R9: =R8/M8-1 -> 0.99242424 | S9: =S8/N8-1 -> 0.82857143 | T9: =T8/O8-1 -> 0.96183206 | U9: =U8/P8-1 -> 1.1231884 | ... BA9: =BA8/AV8-1 -> 0.14432773
C10: Q/Q Growth | J10: =J8/I8-1 -> 0.18431373 | K10: =K8/J8-1 -> 0.10927152 | L10: =L8/K8-1 -> 0.27761194 | N10: =N8/L8-1 -> 0.22663551 | O10: =O8/N8-1 -> 0.24761905 | P10: =P8/O8-1 -> 0.053435115 | Q10: =Q8/P8-1 -> 0.10144928 | S10: =S8/Q8-1 -> 0.26315789 | T10: =T8/S8-1 -> 0.33854167 | U10: =U8/T8-1 -> 0.14007782 | V10: =V8/U8-1 -> 0.58020478 | X10: =X8/V8-1 -> 0.74082073 | Y10: =Y8/X8-1 -> 0.31885856 | Z10: =Z8/Y8-1 -> 0.065851364 | AA10: =AA8/Z8-1 -> 0.2321271 | AC10: =AC8/AA8-1 -> 0.12106017 | AD10: =AD8/AC8-1 -> 0.08370607 | AE10: =AE8/AD8-1 -> 0.018278302 | AF10: =AF8/AE8-1 -> 0.11522872 | AH10: =AH8/AF8-1 -> 0.052959502 | AI10: =AI8/AH8-1 -> 0.043392505 | AJ10: =AJ8/AI8-1 -> 0.019347826 | AK10: =AK8/AJ8-1 -> 0.091852346 | AM10: =AM8/AK8-1 -> 0.051183409 | AN10: =AN8/AM8-1 -> 0.017510906 | AO10: =AO8/AN8-1 -> 0.0011433335 | AP10: =AP8/AO8-1 -> 0.099043155 | AR10: =AR8/AP8-1 -> 0.036159619 | AS10: =AS8/AR8-1 -> 0.055177553 | AT10: =AT8/AS8-1 -> -0.020904953 | AU10: =AU8/AT8-1 -> 0.093653857 | AW10: =AW8/AU8-1 -> 0.0165647 | AX10: =AX8/AW8-1 -> 0.046402082 | AY10: =AY8/AX8-1 -> -0.01360383 | AZ10: =AZ8/AY8-1 -> 0.0889192
B11: Subscription & Transaction Fee Revenue | D11: 12365.458 | E11: 13337.97 | F11: 14920.695 | G11: 16367.558 | H11: =SUM(D11:G11) -> 56991.681 | I11: 18170.323 | J11: 20443.823 | K11: 22111.762 | L11: 25224.916 | M11: =SUM(I11:L11) -> 85950.823 | N11: 28547.775 | O11: 32964 | P11: 36092 | Q11: 38801 | R11: =SUM(N11:Q11) -> 136404.77 | S11: 43788 | T11: 52333 | U11: 58622 | V11: 77512 | W11: =SUM(S11:V11) -> 232255 | X11: =115600+1946 -> 117546 | Y11: =Y8+Y5 -> 155500 | Z11: =Z8+Z5 -> 165500 | AA11: 194820 | AB11: =AB8+AB5 -> 633400 | AC11: =AC8+AC5 -> 214600 | AD11: =AD8+AD5 -> 231100 | AE11: =AE8+AE5 -> 239400 | AF11: 259510 | AG11: 944710 | AH11: 265142 | AI11: 274992 | AJ11: =AJ8+AJ5 -> 281294 | AK11: =AK8+AK5 -> 301306 | AL11: =SUM(AH11:AK11) -> 1122734 | AM11: =AM5+AM8 -> 314943 | AN11: =AN8+AN5 -> 319616 | AO11: =AO8+AO5 -> 320298 | AP11: =AP8+AP5 -> 345947 | AQ11: =SUM(AM11:AP11) -> 1300804 | AR11: =AR5+AR8 -> 358005 | AS11: =AS8+AS5 -> 375128 | AT11: =AT8+AT5 -> 369054.9 | AU11: =AU8+AU5 -> 397945.14 | AV11: =SUM(AR11:AU11) -> 1500133 | AW11: =AW8+AW5 -> 406783.55 | AX11: =AX8+AX5 -> 423625.44 | AY11: =AY8+AY5 -> 419244.46 | AZ11: =AZ8+AZ5 -> 450887.55 | BA11: =SUM(AW11:AZ11) -> 1700541
C12: Y/Y Growth | I12: =I11/D11-1 -> 0.46944192 | J12: =J11/E11-1 -> 0.53275369 | K12: =K11/F11-1 -> 0.48195254 | L12: =L11/G11-1 -> 0.54115331 | M12: =M11/H11-1 -> 0.50812929 | N12: =N11/I11-1 -> 0.57112093 | O12: =O11/J11-1 -> 0.61241861 | P12: =P11/K11-1 -> 0.63225349 | ... BA12: =BA11/AV11-1 -> 0.13359345
C13: Q/Q Growth | J13: =J11/I11-1 -> 0.12512159 | K13: =K11/J11-1 -> 0.081586452 | L13: =L11/K11-1 -> 0.14079177 | N13: =N11/L11-1 -> 0.13172924 | O13: =O11/N11-1 -> 0.15469596 | P13: =P11/O11-1 -> 0.094891397 | Q13: =Q11/P11-1 -> 0.075058185 | S13: =S11/Q11-1 -> 0.12852762 | T13: =T11/S11-1 -> 0.19514479 | U13: =U11/T11-1 -> 0.12017274 | V13: =V11/U11-1 -> 0.32223397 | X13: =X11/V11-1 -> 0.51648777 | Y13: =Y11/X11-1 -> 0.32288636 | Z13: =Z11/Y11-1 -> 0.064308682 | AA13: =AA11/Z11-1 -> 0.17716012 | AC13: =AC11/AA11-1 -> 0.10152962 | AD13: =AD11/AC11-1 -> 0.076887232 | AE13: =AE11/AD11-1 -> 0.035915188 | AF13: =AF11/AE11-1 -> 0.084001671 | AH13: =AH11/AF11-1 -> 0.021702439 | AI13: =AI11/AH11-1 -> 0.037149905 | AJ13: =AJ11/AI11-1 -> 0.02291703 | AK13: =AK11/AJ11-1 -> 0.071142648 | AM13: =AM11/AK11-1 -> 0.045259636 | AN13: =AN11/AM11-1 -> 0.014837606 | AO13: =AO11/AN11-1 -> 0.0021338106 | AP13: =AP11/AO11-1 -> 0.080078552 | AR13: =AR11/AP11-1 -> 0.03485505 | AS13: =AS11/AR11-1 -> 0.047828941 | AT13: =AT11/AS11-1 -> -0.016189409 | AU13: =AU11/AT11-1 -> 0.078281679 | AW13: =AW11/AU11-1 -> 0.022210122 | AX13: =AX11/AW11-1 -> 0.041402588 | AY13: =AY11/AX11-1 -> -0.010341639 | AZ13: =AZ11/AY11-1 -> 0.075476469
B14: Interest on Client Funds Held | D14: 737.17115 | E14: 1825.148 | F14: 2177.0098 | G14: 3133.1164 | H14: =SUM(D14:G14) -> 7872.4454 | I14: ='Revenue Build'!I150 -> 4253.8067 | J14: ='Revenue Build'!J150 -> 5554.8275 | K14: ='Revenue Build'!K150 -> 6131.9238 | L14: ='Revenue Build'!L150 -> 6459.412 | M14: =SUM(I14:L14) -> 22399.97 | N14: ='Revenue Build'!N150 -> 6631.7051 | O14: ='Revenue Build'!O150 -> 6116 | P14: ='Revenue Build'!P150 -> 5138 | Q14: ='Revenue Build'!Q150 -> 3309 | R14: =SUM(N14:Q14) -> 21194.705 | S14: ='Revenue Build'!S150 -> 2421 | T14: ='Revenue Build'!T150 -> 1712 | U14: ='Revenue Build'!U150 -> 1116 | V14: ='Revenue Build'!V150 -> 761 | W14: =SUM(S14:V14) -> 6010 | X14: ='Revenue Build'!X150 -> 803 | Y14: ='Revenue Build'!Y150 -> 978 | Z14: ='Revenue Build'!Z150 -> 1411 | AA14: ='Revenue Build'!AA150 -> 5401 | AB14: =SUM(X14:AA14) -> 8593 | AC14: ='Revenue Build'!AC150 -> 15324 | AD14: ='Revenue Build'!AD150 -> 28900 | AE14: ='Revenue Build'!AE150 -> 33100 | AF14: ='Revenue Build'!AF150 -> 36473 | AG14: =SUM(AC14:AF14) -> 113797 | AH14: ='Revenue Build'!AH150 -> 39843 | AI14: ='Revenue Build'!AI150 -> 43503 | AJ14: ='Revenue Build'!AJ150 -> 41734 | AK14: ='Revenue Build'!AK150 -> 42359 | AL14: =SUM(AH14:AK14) -> 167439 | AM14: ='Revenue Build'!AM150 -> 43507 | AN14: 42938 | AO14: ='Revenue Build'!AO150 -> 37919 | AP14: ='Revenue Build'!AP150 -> 37402 | AQ14: =SUM(AM14:AP14) -> 161766 | AR14: ='Revenue Build'!AR150 -> 37736 | AS14: ='Revenue Build'!AS150 -> 39543 | AT14: ='Revenue Build'!AT150 -> 33804.176 | AU14: ='Revenue Build'!AU150 -> 31902.473 | AV14: =SUM(AR14:AU14) -> 142985.65 | AW14: ='Revenue Build'!AW150 -> 32443.469 | AX14: ='Revenue Build'!AX150 -> 31564.844 | AY14: ='Revenue Build'!AY150 -> 30314.432 | AZ14: ='Revenue Build'!AZ150 -> 32126.365 | BA14: =SUM(AW14:AZ14) -> 126449.11
C15: Y/Y Growth | I15: =I14/D14-1 -> 4.7704465 | J15: =J14/E14-1 -> 2.0434943 | K15: =K14/F14-1 -> 1.8166725 | L15: =L14/G14-1 -> 1.0616572 | M15: =M14/H14-1 -> 1.8453637 | N15: =N14/I14-1 -> 0.55900481 | O15: =O14/J14-1 -> 0.10102428 | P15: =P14/K14-1 -> -0.16209005 | ... BA15: =BA14/AV14-1 -> -0.11565173
C16: Q/Q Growth | E16: =E14/D14-1 -> 1.4758809 | F16: =F14/E14-1 -> 0.19278538 | G16: =G14/F14-1 -> 0.43918339 | I16: =I14/G14-1 -> 0.35769187 | J16: =J14/I14-1 -> 0.30584862 | K16: =K14/J14-1 -> 0.10389094 | L16: =L14/K14-1 -> 0.053407084 | N16: =N14/L14-1 -> 0.02667318 | O16: =O14/N14-1 -> -0.07776357 | P16: =P14/O14-1 -> -0.15990844 | Q16: =Q14/P14-1 -> -0.35597509 | S16: =S14/Q14-1 -> -0.26835902 | T16: =T14/S14-1 -> -0.29285419 | U16: =U14/T14-1 -> -0.34813084 | V16: =V14/U14-1 -> -0.31810036 | X16: =X14/V14-1 -> 0.055190539 | Y16: =Y14/X14-1 -> 0.21793275 | Z16: =Z14/Y14-1 -> 0.44274029 | AA16: =AA14/Z14-1 -> 2.8277817 | AC16: =AC14/AA14-1 -> 1.8372524 | AD16: =AD14/AC14-1 -> 0.88593057 | AE16: =AE14/AD14-1 -> 0.14532872 | AF16: =AF14/AE14-1 -> 0.10190332 | AH16: =AH14/AF14-1 -> 0.092397116 | AI16: =AI14/AH14-1 -> 0.091860553 | AJ16: =AJ14/AI14-1 -> -0.040663862 | AK16: =AK14/AJ14-1 -> 0.014975799 | AM16: =AM14/AK14-1 -> 0.027101679 | AN16: =AN14/AM14-1 -> -0.013078355 | AO16: =AO14/AN14-1 -> -0.11688947 | AP16: =AP14/AO14-1 -> -0.013634326 | AR16: =AR14/AP14-1 -> 0.0089300037 | AS16: =AS14/AR14-1 -> 0.047885308 | AT16: =AT14/AS14-1 -> -0.14512869 | AU16: =AU14/AT14-1 -> -0.056256468 | AW16: =AW14/AU14-1 -> 0.016957828 | AX16: =AX14/AW14-1 -> -0.027081721 | AY16: =AY14/AX14-1 -> -0.039614085 | AZ16: =AZ14/AY14-1 -> 0.059771303
B17: Total Revenues | D17: =D11+D14 -> 13102.63 | E17: =E11+E14 -> 15163.118 | F17: =F11+F14 -> 17097.705 | G17: =G11+G14 -> 19500.674 | H17: =H11+H14 -> 64864.126 | I17: =I11+I14 -> 22424.13 | J17: =J11+J14 -> 25998.65 | K17: =K11+K14 -> 28243.685 | ... X17: =X11+X14 -> 118349 | Y17: 156478 | Z17: 166911 | AA17: 200221 | AB17: =SUM(X17:AA17) -> 641959 | AC17: =AC11+AC14 -> 229924 | AD17: 260006 | AE17: 272555 | AF17: 295983 | AG17: =SUM(AC17:AF17) -> 1058468 | AH17: =AH11+AH14 -> 304985 | AI17: =AI11+AI14 -> 318495 | AJ17: =AJ11+AJ14 -> 323028 | AK17: =AK11+AK14 -> 343665 | AL17: =SUM(AH17:AK17) -> 1290173 | AM17: =AM11+AM14 -> 358450 | AN17: =AN11+AN14 -> 362554 | AO17: =AO11+AO14 -> 358217 | AP17: =AP11+AP14 -> 383349 | AQ17: =SUM(AM17:AP17) -> 1462570 | AR17: =AR11+AR14 -> 395741 | AS17: =AS11+AS14 -> 414671 | AT17: =AT11+AT14 -> 402859.08 | AU17: =AU11+AU14 -> 429847.61 | AV17: =SUM(AR17:AU17) -> 1643118.7 | AW17: =AW11+AW14 -> 439227.02 | AX17: =AX11+AX14 -> 455190.28 | AY17: =AY11+AY14 -> 449558.89 | AZ17: =AZ11+AZ14 -> 483013.91 | BA17: =SUM(AW17:AZ17) -> 1826990.1
C18: Y/Y Growth | I18: =I17/D17-1 -> 0.71142209 | J18: =J17/E17-1 -> 0.71459791 | K18: =K17/F17-1 -> 0.65189924 | L18: =L17/G17-1 -> 0.62478115 | M18: =M17/H17-1 -> 0.67042708 | N18: =N17/I17-1 -> 0.56882253 | O18: =O17/J17-1 -> 0.50315496 | P18: =P17/K17-1 -> 0.45979533 | ... BA18: =BA17/AV17-1 -> 0.11190392
C19: Q/Q Growth | E19: =E17/D17-1 -> 0.15725762 | F19: =F17/E17-1 -> 0.12758503 | G19: =G17/F17-1 -> 0.14054339 | I19: =I17/G17-1 -> 0.14991562 | J19: =J17/I17-1 -> 0.1594051 | K19: =K17/J17-1 -> 0.086351992 | L19: =L17/K17-1 -> 0.12181987 | N19: =N17/L17-1 -> 0.1103117 | O19: =O17/N17-1 -> 0.11087487 | P19: =P17/O17-1 -> 0.055015353 | Q19: =Q17/P17-1 -> 0.021343682 | S19: =S17/Q17-1 -> 0.097340299 | T19: =T17/S17-1 -> 0.16957736 | U19: =U17/T17-1 -> 0.10533814 | V19: =V17/U17-1 -> 0.31027152 | X19: =X17/V17-1 -> 0.51200286 | Y19: =Y17/X17-1 -> 0.32217425 | Z19: =Z17/Y17-1 -> 0.066673909 | AA19: =AA17/Z17-1 -> 0.19956743 | AC19: =AC17/AA17-1 -> 0.14835107 | AD19: =AD17/AC17-1 -> 0.13083454 | AE19: =AE17/AD17-1 -> 0.048264271 | AF19: =AF17/AE17-1 -> 0.085956963 | AH19: =AH17/AF17-1 -> 0.030413909 | AI19: =AI17/AH17-1 -> 0.044297261 | AJ19: =AJ17/AI17-1 -> 0.014232563 | AK19: =AK17/AJ17-1 -> 0.063886103 | AM19: =AM17/AK17-1 -> 0.043021547 | AN19: =AN17/AM17-1 -> 0.011449296 | AO19: =AO17/AN17-1 -> -0.011962356 | AP19: =AP17/AO17-1 -> 0.070158591 | AR19: =AR17/AP17-1 -> 0.032325635 | AS19: =AS17/AR17-1 -> 0.047834316 | AT19: =AT17/AS17-1 -> -0.028485051 | AU19: =AU17/AT17-1 -> 0.066992492 | AW19: =AW17/AU17-1 -> 0.021820307 | AX19: =AX17/AW17-1 -> 0.036344 | AY19: =AY17/AX17-1 -> -0.012371515 | AZ19: =AZ17/AY17-1 -> 0.074417446
B21: Cost of Revenue | D21: 3903.0364 | E21: 4027.9458 | F21: 4565.125 | G21: 4973.4755 | H21: =SUM(D21:G21) -> 17469.583 | I21: 5577 | J21: 6289 | K21: 6770.564 | L21: 7560 | M21: =SUM(I21:L21) -> 26196.564 | N21: 8010.4169 | O21: =9787-211-982 -> 8594 | P21: =10110-422-956 -> 8732 | Q21: =10100-476-608 -> 9016 | R21: =SUM(N21:Q21) -> 34352.417 | S21: =10605+400 -> 11005 | T21: =12246+400 -> 12646 | U21: =15434-728-119-800 -> 13787 | V21: =20293-967-2653-108-709 -> 15856 | W21: =SUM(S21:V21) -> 53294 | X21: =29835-1127-8401-163-721 -> 19423 | Y21: =34386-9285-1285-89-763 -> 22964 | Z21: =37342-1401-9285-881 -> 25775 | AA21: =43441-10172-1534 -> 31735 | AB21: =SUM(X21:AA21) -> 99897 | AC21: =34820-2066 -> 32754 | AD21: =47467-10502-2353 -> 34612 | AE21: =37897-2514 -> 35383 | AF21: =52552-11225-2495 -> 38832 | AG21: =SUM(AC21:AF21) -> 141581 | AH21: =44904-2628 -> 42276 | AI21: =47239-2446 -> 44793 | AJ21: =43845-2277 -> 41568 | AK21: =53905+11295-11295-2243 -> 51662 | AL21: =SUM(AH21:AK21) -> 180299 | AM21: =53602+11094-11094-2183 -> 51419 | AN21: =56298+10310-10310-2654 -> 53644 | AO21: =56733-2530 -> 54203 | AP21: =63172-2553 -> 60619 | AQ21: =SUM(AM21:AP21) -> 219885 | AR21: =66066-2405 -> 63661 | AS21: =69190-2298 -> 66892 | AT21: =AT17*(1-AT23) -> 65666.029 | AU21: =AU17*(1-AU23) -> 72644.246 | AV21: =SUM(AR21:AU21) -> 268863.28 | AW21: =AW17*(1-AW23) -> 67640.96 | AX21: =AX17*(1-AX23) -> 70099.303 | AY21: =AY17*(1-AY23) -> 71929.422 | AZ21: =AZ17*(1-AZ23) -> 81146.337 | BA21: =SUM(AW21:AZ21) -> 290816.02
B22: Gross Profit | D22: =D17-D21 -> 9199.5931 | E22: =E17-E21 -> 11135.172 | F22: =F17-F21 -> 12532.58 | G22: =G17-G21 -> 14527.198 | H22: =H17-H21 -> 47394.543 | I22: =I17-I21 -> 16847.13 | J22: =J17-J21 -> 19709.65 | K22: =K17-K21 -> 21473.121 | ... BA22: =BA17-BA21 -> 1536174.1
C23: Gross Margin | D23: =D22/D17 -> 0.70211808 | E23: =E22/E17 -> 0.734359 | F23: =F22/F17 -> 0.73299779 | G23: =G22/G17 -> 0.74495879 | H23: =H22/H17 -> 0.7306742 | I23: =I22/I17 -> 0.75129469 | J23: =J22/J17 -> 0.75810283 | K23: =K22/K17 -> 0.76028043 | ... AS23: =AS22/AS17 -> 0.83868657 | AT23: 0.837 | AU23: 0.831 | AV23: =AV22/AV17 -> 0.83637014 | AW23: 0.846 | AX23: 0.846 | AY23: 0.84 | AZ23: 0.832 | BA23: =BA22/BA17 -> 0.84082233
B25: Operating Expenses
C26: Research & Development | D26: 4598.3355 | E26: 4806.1979 | F26: 5245.8858 | G26: 5549.8605 | H26: =SUM(D26:G26) -> 20200.28 | I26: 6159.1792 | J26: 6542 | K26: 8050 | L26: 9102 | M26: =SUM(I26:L26) -> 29853.179 | N26: 10942.971 | O26: =12992-1084+74 -> 11982 | P26: =13969-1466+280 -> 12783 | Q26: =14929-2274+67 -> 12722 | R26: =SUM(N26:Q26) -> 48429.971 | S26: =15484-700 -> 14784 | T26: =17848-500 -> 17348 | U26: 18031 | V26: 22792 | W26: =SUM(S26:V26) -> 72955 | X26: =42472-10560-582-588 -> 30742 | Y26: =51954-14280-659-577 -> 36438 | Z26: =60230-14998-581 -> 44651 | AA26: =66908-16681 -> 50227 | AB26: =SUM(X26:AA26) -> 162058 | AC26: 53764 | AD26: =78910-27310 -> 51600 | AE26: =78761-23274 -> 55487 | AF26: =81841-23935 -> 57906 | AG26: =SUM(AC26:AF26) -> 218757 | AH26: =89065-27887 -> 61178 | AI26: =86489-26550 -> 59939 | AJ26: 55532 | AK26: 54348 | AL26: =SUM(AH26:AK26) -> 230997 | AM26: 54709 | AN26: =84784-29774 -> 55010 | AO26: 57987 | AP26: 62098 | AQ26: =SUM(AM26:AP26) -> 229804 | AR26: 53860 | AS26: 53256 | AT26: =AT17*AT27 -> 53983.116 | AU26: =AU17*AU27 -> 55880.189 | AV26: =SUM(AR26:AU26) -> 216979.31 | AW26: =AW17*AW27 -> 60613.328 | AX26: =AX17*AX27 -> 61905.878 | AY26: =AY17*AY27 -> 61140.009 | AZ26: =AZ17*AZ27 -> 65689.892 | BA26: =SUM(AW26:AZ26) -> 249349.11
C27: % of Revenue | D27: =D26/D17 -> 0.35094753 | E27: =E26/E17 -> 0.31696633 | F27: =F26/F17 -> 0.30681813 | G27: =G26/G17 -> 0.2845984 | H27: =H26/H17 -> 0.31142453 | I27: =I26/I17 -> 0.27466748 | J27: =J26/J17 -> 0.25162845 | K27: =K26/K17 -> 0.28501946 | ... AS27: =AS26/AS17 -> 0.12842953 | AT27: 0.134 | AU27: 0.13 | AV27: =AV26/AV17 -> 0.13205334 | AW27: 0.138 | AX27: 0.136 | AY27: 0.136 | AZ27: 0.136 | BA27: =BA26/BA17 -> 0.13648082
C28: Rewards Expense | X28: =AC28-23400 -> 15600 | Y28: =AE28-21500 -> 21500 | Z28: =AE28-18400 -> 24600 | AA28: ='Revenue Build'!AA54 -> 34400 | AB28: =AG28-78700 -> 96000 | AC28: ='Revenue Build'!AC54 -> 39000 | AD28: ='Revenue Build'!AD54 -> 44000 | AE28: ='Revenue Build'!AE54 -> 43000 | AF28: ='Revenue Build'!AF54 -> 48700 | AG28: =SUM(AC28:AF28) -> 174700 | AH28: ='Revenue Build'!AH54 -> 51800 | AI28: ='Revenue Build'!AI54 -> 53700 | AJ28: ='Revenue Build'!AJ54 -> 53800 | AK28: ='Revenue Build'!AK54 -> 60500 | AL28: =SUM(AH28:AK28) -> 219800 | AM28: ='Revenue Build'!AM54 -> 62100 | AN28: ='Revenue Build'!AN54 -> 64700 | AO28: ='Revenue Build'!AO54 -> 68400 | AP28: ='Revenue Build'!AP54 -> 76800 | AQ28: =SUM(AM28:AP28) -> 272000 | AR28: ='Revenue Build'!AR54 -> 81300 | AS28: ='Revenue Build'!AS54 -> 87000
C29: % of Revenue | X29: =X28/X17 -> 0.13181353 | Y29: =Y28/Y17 -> 0.13739951 | Z29: =Z28/Z17 -> 0.14738394 | AA29: =AA28/AA17 -> 0.17181015 | AB29: =AB28/AB17 -> 0.14954226 | AC29: =AC28/AC17 -> 0.16962127 | AD29: =AD28/AD17 -> 0.16922686 | AE29: =AE28/AE17 -> 0.15776632 | ... AS29: =AS28/AS17 -> 0.20980488
C30: Other S&M | X30: =X32-X28 -> 29719 | Y30: =Y32-Y28 -> 37070 | Z30: =Z32-Z28 -> 38363 | AA30: =AA32-AA28 -> 44533 | AB30: =SUM(X30:AA30) -> 149685 | AC30: =AC32-AC28 -> 49441 | AD30: =AD32-AD28 -> 50865 | AE30: =AE32-AE28 -> 53748 | AF30: =AF32-AF28 -> 54697 | AG30: =SUM(AC30:AF30) -> 208751 | AH30: =AH32-AH28 -> 52516 | AI30: =AI32-AI28 -> 51596 | AJ30: =AJ32-AJ28 -> 52888 | AK30: =AK32-AK28 -> 51667 | AL30: =SUM(AH30:AK30) -> 208667 | AM30: =AM32-AM28 -> 53328 | AN30: =AN32-AN28 -> 57178 | AO30: =AO32-AO28 -> 58489 | AP30: =AP32-AP28 -> 61916 | AQ30: =SUM(AM30:AP30) -> 230911 | AR30: =AR32-AR28 -> 58115 | AS30: =AS32-AS28 -> 58251
C31: % of Revenue | X31: =X30/X17 -> 0.25111323 | Y31: =Y30/Y17 -> 0.23690231 | Z31: =Z30/Z17 -> 0.22984105 | AA31: =AA30/AA17 -> 0.22241923 | AB31: =AB30/AB17 -> 0.2331691 | AC31: =AC30/AC17 -> 0.21503192 | AD31: =AD30/AD17 -> 0.1956301 | AE31: =AE30/AE17 -> 0.19720057 | ... AS31: =AS30/AS17 -> 0.14047522 | BA31: =BA30/BA15 -> 0
C32: Sales & Marketing | D32: 4279.077 | E32: 4654.7802 | F32: 4808.867 | G32: 6245.3872 | H32: =SUM(D32:G32) -> 19988.111 | I32: 5763.5565 | J32: 7226.2048 | K32: 7414 | L32: 10155.767 | M32: =SUM(I32:L32) -> 30559.528 | N32: 10344.749 | O32: =11491-494+682 -> 11679 | P32: =11802-767+506 -> 11541 | Q32: =11796-1134+1306 -> 11968 | R32: =SUM(N32:Q32) -> 45532.749 | S32: =11940-1100 -> 10840 | T32: =12592-1000 -> 11592 | U32: 13156 | V32: 22254 | W32: =SUM(S32:V32) -> 57842 | X32: =62312-8114-195-8271-413 -> 45319 | Y32: =80817-10483-11039-288-437 -> 58570 | Z32: =92065-18179-10484-439 -> 62963 | AA32: =102484-23551 -> 78933 | AB32: =SUM(X32:AA32) -> 245785 | AC32: 88441 | AD32: =164683-69818 -> 94865 | AE32: =115350-18602 -> 96748 | AF32: =117199-13802 -> 103397 | AG32: =SUM(AC32:AF32) -> 383451 | AH32: =118398-14082 -> 104316 | AI32: =118305-13009 -> 105296 | AJ32: 106688 | AK32: 112167 | AL32: =SUM(AH32:AK32) -> 428467 | AM32: 115428 | AN32: =132534-10656 -> 121878 | AO32: 126889 | AP32: 138716 | AQ32: =SUM(AM32:AP32) -> 502911 | AR32: 139415 | AS32: 145251 | AT32: =AT17*AT33 -> 144827.84 | AU32: =AU17*AU33 -> 153756.49 | AV32: =SUM(AR32:AU32) -> 583250.33 | AW32: =AW17*AW33 -> 155925.59 | AX32: =AX17*AX33 -> 160226.98 | AY32: =AY17*AY33 -> 159143.85 | AZ32: =AZ17*AZ33 -> 170503.91 | BA32: =SUM(AW32:AZ32) -> 645800.33
C33: % of Revenue | D33: =D32/D17 -> 0.32658155 | E33: =E32/E17 -> 0.30698042 | F33: =F32/F17 -> 0.28125804 | G33: =G32/G17 -> 0.3202652 | H33: =H32/H17 -> 0.30815356 | I33: =I32/I17 -> 0.25702476 | J33: =J32/J17 -> 0.27794539 | K33: =K32/K17 -> 0.26250115 | ... AS33: =AS32/AS17 -> 0.3502801 | AT33: 0.3595 | AU33: 0.3577 | AV33: =AV32/AV17 -> 0.35496543 | AW33: 0.355 | AX33: 0.352 | AY33: 0.354 | AZ33: 0.353 | BA33: =BA32/BA17 -> 0.35347774
C34: Provision for expected credit losses | X34: 4035 | Y34: 5190 | Z34: 6085 | AA34: =19566-SUM(X34:Z34) -> 4256 | AB34: =SUM(X34:AA34) -> 19566 | AC34: 6583 | AD34: 8520 | AE34: 8425 | AF34: =32224-SUM(AC34:AE34) -> 8696 | AG34: =SUM(AC34:AF34) -> 32224 | AH34: 11975 | AI34: 14354 | AJ34: 15104 | AK34: =60105-SUM(AH34:AJ34) -> 18672 | AL34: =SUM(AH34:AK34) -> 60105 | AM34: 20661 | AN34: 21358 | AO34: 14945 | AP34: 15785 | AQ34: =SUM(AM34:AP34) -> 72749 | AR34: 16096 | AS34: 22624
C35: % of Revenue | X35: =X34/X17 -> 0.034094078 | Y35: =Y34/Y17 -> 0.033167602 | Z35: =Z34/Z17 -> 0.036456555 | AA35: =AA34/AA17 -> 0.021256512 | AB35: =AB34/AB17 -> 0.030478582 | AC35: =AC34/AC17 -> 0.0286312 | AD35: =AD34/AD17 -> 0.032768475 | AE35: =AE34/AE17 -> 0.030911192 | ... AS35: =AS34/AS17 -> 0.054558915
C36: Other G&A | X36: =X38-X34 -> 28028 | Y36: =Y38-Y34 -> 29934 | Z36: =Z38-Z34 -> 33115 | AA36: =AA38-AA34 -> 38239 | AB36: =SUM(X36:AA36) -> 129316 | AC36: =AC38-AC34 -> 39237 | AD36: =AD38-AD34 -> 39657 | AE36: =AE38-AE34 -> 41671 | AF36: =AF38-AF34 -> 44804 | AG36: =SUM(AC36:AF36) -> 165369 | AH36: =AH38-AH34 -> 51867 | AI36: =AI38-AI34 -> 49810 | AJ36: =AJ38-AJ34 -> 45603 | AK36: =AK38-AK34 -> 46845 | AL36: =SUM(AH36:AK36) -> 194125 | AM36: =AM38-AM34 -> 49145 | AN36: =AN38-AN34 -> 47858 | AO36: =AO38-AO34 -> 50894 | AP36: =AP38-AP34 -> 49779 | AQ36: =SUM(AM36:AP36) -> 197676 | AR36: =AR38-AR34 -> 54473 | AS36: =AS38-AS34 -> 52563
C37: % of Revenue | X37: =X36/X17 -> 0.23682498 | Y37: =Y36/Y17 -> 0.19129846 | Z37: =Z36/Z17 -> 0.19839915 | AA37: =AA36/AA17 -> 0.19098396 | AB37: =AB36/AB17 -> 0.20143966 | AC37: =AC36/AC17 -> 0.17065204 | AD37: =AD36/AD17 -> 0.1525234 | AE37: =AE36/AE17 -> 0.15289024 | ... AS37: =AS36/AS17 -> 0.12675832
C38: General & Administrative | D38: 3199.584 | E38: 3278.035 | F38: 4268.4498 | G38: 4436.5703 | H38: =SUM(D38:G38) -> 15182.639 | I38: 5698.7928 | J38: 6010 | K38: 7117 | L38: 8048 | M38: =SUM(I38:L38) -> 26873.793 | N38: 9395.2055 | O38: =12748-1286-127 -> 11335 | P38: =15064-2430-133 -> 12501 | Q38: =15546-3744-789 -> 11013 | R38: =SUM(N38:Q38) -> 44244.205 | S38: 11857 | T38: 14017 | U38: 16894 | V38: 23569 | W38: =SUM(S38:V38) -> 66337 | X38: =57935-18086-1042-6325-419 -> 32063 | Y38: =65396-23080-2343-432-4417 -> 35124 | Z38: =60457-20565-243-449 -> 39200 | AA38: =58686-16191 -> 42495 | AB38: =SUM(X38:AA38) -> 148882 | AC38: 45820 | AD38: =69381-20989-215 -> 48177 | AE38: =71719-21334-289 -> 50096 | AF38: =73441-18937-1004 -> 53500 | AG38: =SUM(AC38:AF38) -> 197593 | AH38: =85326-21387-97 -> 63842 | AI38: =85583-20547-872 -> 64164 | AJ38: 60707 | AK38: =50732+14785 -> 65517 | AL38: =SUM(AH38:AK38) -> 254230 | AM38: =49145+20661 -> 69806 | AN38: =71122+21358-23264 -> 69216 | AO38: =50894+14945 -> 65839 | AP38: =49779+15785 -> 65564 | AQ38: =SUM(AM38:AP38) -> 270425 | AR38: =54473+16096 -> 70569 | AS38: =52563+22624 -> 75187 | AT38: =AT17*AT39 -> 73320.352 | AU38: =AU17*AU39 -> 74363.636 | AV38: =SUM(AR38:AU38) -> 293439.99 | AW38: =AW17*AW39 -> 79500.09 | AX38: =AX17*AX39 -> 81479.061 | AY38: =AY17*AY39 -> 81370.159 | AZ38: =AZ17*AZ39 -> 84044.421 | BA38: =SUM(AW38:AZ38) -> 326393.73
C39: % of Revenue | D39: =D38/D17 -> 0.24419404 | E39: =E38/E17 -> 0.21618476 | F39: =F38/F17 -> 0.24965046 | G39: =G38/G17 -> 0.22750856 | H39: =H38/H17 -> 0.23406835 | I39: =I38/I17 -> 0.25413663 | J39: =J38/J17 -> 0.23116585 | K39: =K38/K17 -> 0.25198553 | ... AS39: =AS38/AS17 -> 0.18131724 | AT39: 0.182 | AU39: 0.173 | AV39: =AV38/AV17 -> 0.17858721 | AW39: 0.181 | AX39: 0.179 | AY39: 0.181 | AZ39: 0.174 | BA39: =BA38/BA17 -> 0.17865107
B40: Total Operating Expense | D40: =D26+D32+D38 -> 12076.996 | E40: =E26+E32+E38 -> 12739.013 | F40: =F26+F32+F38 -> 14323.203 | G40: =G26+G32+G38 -> 16231.818 | H40: =H26+H32+H38 -> 55371.03 | I40: =I26+I32+I38 -> 17621.528 | J40: =J26+J32+J38 -> 19778.205 | K40: =K26+K32+K38 -> 22581 | ... BA40: =BA26+BA32+BA38 -> 1221543.2
B42: Non-GAAP Operating Income | D42: =D22-D40 -> -2877.4033 | E42: =E22-E40 -> -1603.841 | F42: =F22-F40 -> -1790.623 | G42: =G22-G40 -> -1704.6195 | H42: =H22-H40 -> -7976.4868 | I42: =I22-I40 -> -774.39889 | J42: =J22-J40 -> -68.55468 | K42: =K22-K40 -> -1107.8786 | ... BA42: =BA22-BA40 -> 314630.91
C43: Non-GAAP Operating Margin | D43: =D42/D17 -> -0.21960503 | E43: =E42/E17 -> -0.1057725 | F43: =F42/F17 -> -0.10472885 | G43: =G42/G17 -> -0.087413365 | H43: =H42/H17 -> -0.12297224 | I43: =I42/I17 -> -0.034534178 | J43: =J42/J17 -> -0.0026368554 | K43: =K42/K17 -> -0.03922571 | ... BA43: =BA42/BA17 -> 0.17221271
B45: GAAP Adjustments
C46: Amortization of intangibles | V46: 5659 | W46: =SUM(S46:V46) -> 5659 | X46: =8401+8271 -> 16672 | Y46: 19768 | Z46: =9285+10484 -> 19769 | AA46: 19769 | AB46: =SUM(X46:AA46) -> 75978 | AC46: 19769 | AD46: 19994 | AE46: 20220 | AF46: 20221 | AG46: =SUM(AC46:AF46) -> 80204 | AH46: =23939-AH47 -> 20221 | AI46: =23462-AI47 -> 20222 | AJ46: 23429 | AK46: 22965 | AL46: =SUM(AH46:AK46) -> 86837 | AM46: 20107 | AN46: 18168 | AO46: 18336 | AP46: 18325 | AQ46: =SUM(AM46:AP46) -> 74936 | AR46: 19004 | AS46: 22779 | AT46: 20000 | AU46: 20000 | AV46: =SUM(AR46:AU46) -> 81783 | AW46: 20000 | AX46: 20000 | AY46: 20000 | AZ46: 20000 | BA46: =SUM(AW46:AZ46) -> 80000
...

Sheet BS
B2: Bill.com, Inc. (BILL)
B4: Balance Sheet | D4: 1Q18 | E4: 2Q18 | F4: 3Q18 | G4: 4Q18 | H4: 2018 | I4: 1Q19 | J4: 2Q19 | K4: 3Q19 | L4: 4Q19 | M4: 2019 | N4: 1Q20 | O4: 2Q20 | P4: 3Q20 | Q4: 4Q20 | R4: 2020 | S4: 1Q21 | T4: 2Q21 | U4: 3Q21 | V4: 4Q21 | W4: 2021 | X4: 1Q22 | Y4: 2Q22 | Z4: 3Q22 | AA4: 4Q22 | AB4: 2022 | AC4: 1Q23 | AD4: 2Q23 | AE4: 3Q23 | AF4: 4Q23 | AG4: 2023 | AH4: =IS!AH4 -> 1Q24 | AI4: =IS!AI4 -> 2Q24 | AJ4: =IS!AJ4 -> 3Q24 | AK4: 4Q24 | AL4: =IS!AL4 -> 2024 | AM4: =IS!AM4 -> 1Q25 | AN4: =IS!AN4 -> 2Q25 | AO4: =IS!AO4 -> 3Q25 | AP4: =IS!AP4 -> 4Q25 | AQ4: =IS!AQ4 -> 2025 | AR4: =IS!AR4 -> 1Q26 | AS4: =IS!AS4 -> 2Q26 | ... BA4: =IS!BA4 -> 2027E
B5: Assets:
C6: Cash and Cash Equivalents | D6: 89333 | E6: 56616 | F6: 22642 | G6: 22401 | H6: =G6 -> 22401 | I6: 15308 | J6: 84134 | K6: 100727 | L6: 90306.147 | M6: =L6 -> 90306.147 | N6: 86249.027 | O6: 314894 | P6: 228585 | Q6: 573643 | R6: =Q6 -> 573643 | S6: 564153 | T6: 1568684 | U6: 1223724 | V6: 509615 | W6: =V6 -> 509615 | X6: 2013433 | Y6: 1672166 | Z6: 1639371 | AA6: 1596542 | AB6: =AA6 -> 1596542 | AC6: 1608966 | AD6: 1616758 | AE6: 1590560 | AF6: 1617151 | AG6: =AF6 -> 1617151 | AH6: 1527182 | AI6: 1579633 | AJ6: 952474 | AK6: 985941 | AL6: =AK6 -> 985941 | AM6: 853470 | AN6: 1566271 | AO6: 1047737 | AP6: 1038346 | AQ6: =AP6 -> 1038346 | AR6: 1099628 | AS6: 1094530 | AT6: =AS6+CF!AT76 -> 1066357.3 | AU6: =AT6+CF!AU76 -> 1158573.3 | AV6: =AU6 -> 1158573.3 | AW6: =AV6+CF!AW76 -> 1218031.2 | AX6: =AW6+CF!AX76 -> 1309480.7 | AY6: =AX6+CF!AY76 -> 1384554.1 | AZ6: =AY6+CF!AZ76 -> 1485378 | BA6: =AZ6 -> 1485378
C7: Short Term Investments | D7: 0 | E7: 38675 | F7: 69156 | G7: 69867 | H7: =G7 -> 69867 | I7: 74095 | J7: 74378 | K7: 74641.964 | L7: 71968.59 | M7: =L7 -> 71968.59 | N7: 71392.815 | O7: 68135 | P7: 153838 | Q7: 123974 | R7: =Q7 -> 123974 | S7: 136171 | T7: 165588 | U7: 512520 | V7: 655314 | W7: =V7 -> 655314 | X7: 821544 | Y7: 1117170 | Z7: 1143408 | AA7: 1108493 | AB7: =AA7 -> 1108493 | AC7: 1034537 | AD7: 1066538 | AE7: 1073013 | AF7: 1043110 | AG7: =AF7 -> 1043110 | AH7: 1119456 | AI7: 972621 | AJ7: 837140 | AK7: 601535 | AL7: =AK7 -> 601535 | AM7: 619596 | AN7: 644672 | AO7: 1125349 | AP7: 1180110 | AQ7: =AP7 -> 1180110 | AR7: 1215339 | AS7: 1146970 | AT7: =AS7 -> 1146970 | AU7: =AT7 -> 1146970 | AV7: =AU7 -> 1146970 | AW7: =AV7 -> 1146970 | AX7: =AW7 -> 1146970 | AY7: =AX7 -> 1146970 | AZ7: =AY7 -> 1146970 | BA7: =AZ7 -> 1146970
C8: Restricted Cash | D8: 246.15925 | E8: 246.15925 | F8: 256.19744 | G8: 256.20246 | H8: =G8 -> 256.20246 | I8: 256.20753 | J8: 256.2126 | K8: 256.22012 | L8: 256.23266 | M8: =L8 -> 256.23266 | N8: 256.24536 | P8: =O8 -> 0 | Q8: =P8 -> 0 | R8: =Q8 -> 0 | S8: =R8 -> 0 | T8: =S8 -> 0 | U8: =T8 -> 0 | V8: =U8 -> 0 | W8: =V8 -> 0 | ... AC8: =AB8 -> 0 | AD8: 0 | AE8: =AD8 -> 0 | AF8: =AE8 -> 0 | AG8: =AF8 -> 0 | AH8: =AG8 -> 0 | AI8: 0 | AJ8: =AI8 -> 0 | AL8: =AK8 -> 0 | AQ8: =AP8 -> 0 | AT8: =AS8 -> 0 | AU8: =AT8 -> 0 | AV8: =AU8 -> 0 | AW8: =AV8 -> 0 | AX8: 0 | AY8: =AX8 -> 0 | AZ8: =AY8 -> 0 | BA8: =AZ8 -> 0
C9: Accounts Receivable, net | D9: 1818 | E9: 1687 | F9: 1605 | G9: 2300 | H9: =G9 -> 2300 | I9: 3396 | J9: 4672 | K9: 4004.4258 | L9: 4397.6445 | M9: =L9 -> 4397.6445 | N9: 3690.5937 | O9: 4791 | P9: 3440 | Q9: 4252 | R9: =Q9 -> 4252 | S9: 5042 | T9: 7037 | U9: 9584 | V9: 18222 | W9: =V9 -> 18222 | X9: 19815 | Y9: 24433 | Z9: 26859 | AA9: 24045 | AB9: =AA9 -> 24045 | AC9: 29060 | AD9: 31261 | AE9: 34065 | AF9: 28233 | AG9: =AF9 -> 28233 | AH9: 24100 | AI9: 26652 | AJ9: 29891 | AK9: 28049 | AL9: =AK9 -> 28049 | AM9: 31934 | AN9: 28911 | AO9: 26663 | AP9: 32341 | AQ9: =AP9 -> 32341 | AR9: 32113 | AS9: 41163 | AT9: =AT60*IS!AT$17 -> 42300.203 | AU9: =AU60*IS!AU$17 -> 45133.999 | AV9: =AU9 -> 45133.999 | AW9: =AW60*IS!AW$17 -> 46118.837 | AX9: =AX60*IS!AX$17 -> 47794.98 | AY9: =AY60*IS!AY$17 -> 47203.683 | AZ9: =AZ60*IS!AZ$17 -> 50716.461 | BA9: =AZ9 -> 50716.461
C10: Acquired card receivables | V10: 147093 | W10: =V10 -> 147093 | X10: 174338 | Y10: 213414 | Z10: 237511 | AA10: 256392 | AB10: =AA10 -> 256392 | AC10: 357741 | AD10: 380895 | AE10: 431114 | AF10: 458650 | AG10: =AF10 -> 458650 | AH10: 552827 | AI10: 516980 | AJ10: 641861 | AK10: 697216 | AL10: =AK10 -> 697216 | AM10: 628274 | AN10: 581661 | AO10: 705535 | AP10: 685108 | AQ10: =AP10 -> 685108 | AR10: 738765 | AS10: 732084 | AT10: =AS10 -> 732084 | AU10: =AT10 -> 732084 | AV10: =AU10 -> 732084 | AW10: =AV10 -> 732084 | AX10: =AW10 -> 732084 | AY10: =AX10 -> 732084 | AZ10: =AY10 -> 732084 | BA10: =AZ10 -> 732084
C11: Unbilled Revenue | D11: 2327 | E11: 2538 | F11: 2908 | G11: 3047.1751 | H11: =G11 -> 3047.1751 | I11: 3565 | J11: 3929.8569 | K11: 4431.7575 | L11: 4795.0972 | M11: =L11 -> 4795.0972 | N11: 5415.5627 | O11: 5909 | P11: 6151 | Q11: 6549 | R11: =Q11 -> 6549 | S11: 6925 | T11: 7370 | U11: 7865 | V11: 8118 | W11: =V11 -> 8118 | X11: 0 | Y11: 0 | AA11: 0 | AB11: =AA11 -> 0 | AD11: 0 | AE11: 0 | AF11: 0 | AG11: =AF11 -> 0 | AH11: 0 | AI11: 0 | AJ11: 0 | AL11: =AK11 -> 0 | AQ11: =AP11 -> 0 | AT11: 0 | AU11: 0 | AV11: =AU11 -> 0 | AW11: 0 | AX11: 0 | AY11: 0 | AZ11: 0 | BA11: =AZ11 -> 0
C12: Prepaid Expenses and Other Current Assets | D12: 2616.7855 | E12: 4624.1662 | F12: 5205.0669 | G12: 5825.6531 | H12: =G12 -> 5825.6531 | I12: 7066.4629 | J12: 8957.9617 | K12: 10544.122 | L12: 12070.415 | M12: =L12 -> 12070.415 | N12: 13654.68 | O12: 15768 | P12: 25137 | Q12: 26781 | R12: =Q12 -> 26781 | S12: 15421 | T12: 18748 | U12: 18268 | V12: 59077 | W12: =V12 -> 59077 | X12: 71551 | Y12: 84718 | Z12: 91865 | AA12: 151258 | AB12: =AA12 -> 151258 | AC12: 140019 | AD12: 178688 | AE12: 170120 | AF12: 170111 | AG12: =AF12 -> 170111 | AH12: 195027 | AI12: 204726 | AJ12: 256199 | AK12: 297169 | AL12: =AK12 -> 297169 | AM12: 283756 | AN12: 251877 | AO12: 241332 | AP12: 258418 | AQ12: =AP12 -> 258418 | AR12: 269326 | AS12: 278473 | AT12: =AT62*IS!AT$17 -> 261858.4 | AU12: =AU62*IS!AU$17 -> 279400.95 | AV12: =AU12 -> 279400.95 | AW12: =AW62*IS!AW$17 -> 285497.56 | AX12: =AX62*IS!AX$17 -> 295873.68 | AY12: =AY62*IS!AY$17 -> 292213.28 | AZ12: =AZ62*IS!AZ$17 -> 313959.04 | BA12: =AZ12 -> 313959.04
C13: Funds Held for Customers | D13: 709298 | E13: 902871 | F13: 786615 | G13: 915013.13 | H13: =G13 -> 915013.13 | I13: 1013736 | J13: 1212826 | K13: 1179910 | L13: 1329306.1 | M13: =L13 -> 1329306.1 | N13: 1466491.8 | O13: 1481763 | P13: 1353552 | Q13: 1644250 | R13: =Q13 -> 1644250 | S13: 1668903 | T13: 2217680 | U13: 1929840 | V13: 2208598 | W13: =V13 -> 2208598 | X13: 2432521 | Y13: 3380395 | Z13: 3043540 | AA13: 3142660 | AB13: =AA13 -> 3142660 | AC13: 3121654 | AD13: 3474048 | AE13: 3106360 | AF13: 3355909 | AG13: =AF13 -> 3355909 | AH13: 3263528 | AI13: 3655435 | AJ13: 3510918 | AK13: 3704907 | AL13: =AK13 -> 3704907 | AM13: 3787171 | AN13: 3766541 | AO13: 3657218 | AP13: 4044470 | AQ13: =AP13 -> 4044470 | AR13: 3974674 | AS13: 4032211 | AT13: ='Revenue Build'!AT94*1000 -> 4147751.7 | AU13: ='Revenue Build'!AU94*1000 -> 4218508.8 | AV13: =AU13 -> 4218508.8 | AW13: ='Revenue Build'!AW94*1000 -> 4399114.5 | AX13: ='Revenue Build'!AX94*1000 -> 4676273.2 | AY13: ='Revenue Build'!AY94*1000 -> 4491027 | AZ13: ='Revenue Build'!AZ94*1000 -> 4759461.5 | BA13: =AZ13 -> 4759461.5
B14: Total Current Assets | D14: =SUM(D6:D13) -> 805638.94 | E14: =SUM(E6:E13) -> 1007257.3 | F14: =SUM(F6:F13) -> 888387.26 | G14: =SUM(G6:G13) -> 1018710.2 | H14: =SUM(H6:H13) -> 1018710.2 | I14: =SUM(I6:I13) -> 1117422.7 | J14: =SUM(J6:J13) -> 1389154 | K14: =SUM(K6:K13) -> 1374515.5 | ... BA14: =SUM(BA6:BA13) -> 8488569
C15: Operating lease right of use | S15: 43400 | T15: 44771 | U15: 44125 | V15: 71925 | W15: =V15 -> 71925 | X15: 78930 | Y15: 76807 | Z15: 78739 | AA15: 76445 | AB15: =AA15 -> 76445 | AC15: 75106 | AD15: 72725 | AE15: 70331 | AF15: 68988 | AG15: =AF15 -> 68988 | AH15: 66600 | AI15: 63505 | AJ15: 61466 | AK15: 59414 | AL15: =AK15 -> 59414 | AM15: 57370 | AN15: 60144 | AO15: 58076 | AP15: 56086 | AQ15: =AP15 -> 56086 | AR15: 54066 | AS15: 52017 | AT15: =AS15 -> 52017 | AU15: =AT15 -> 52017 | AV15: =AU15 -> 52017 | AW15: =AV15 -> 52017 | AX15: =AW15 -> 52017 | AY15: =AX15 -> 52017 | AZ15: =AY15 -> 52017 | BA15: =AZ15 -> 52017
C16: PP&E | D16: 4269.6683 | E16: 4532 | F16: 4109 | G16: 5948.2619 | H16: =G16 -> 5948.2619 | I16: 6315 | J16: 6449.8386 | K16: 6649.5243 | L16: 6556.5475 | M16: =L16 -> 6556.5475 | N16: 7607.4852 | O16: 7511 | P16: 12317 | Q16: 13866 | R16: =Q16 -> 13866 | S16: 21709 | T16: 30572 | U16: 31740 | V16: 48902 | W16: =V16 -> 48902 | X16: 51142 | Y16: 52691 | Z16: 53279 | AA16: 56985 | AB16: =AA16 -> 56985 | AC16: 62025 | AD16: 69383 | AE16: 77465 | AF16: 81564 | AG16: =AF16 -> 81564 | AH16: 85294 | AI16: 86577 | AJ16: 87300 | AK16: 88034 | AL16: =AK16 -> 88034 | AM16: 90016 | AN16: 94467 | AO16: 104837 | AP16: 116611 | AQ16: =AP16 -> 116611 | AR16: 128957 | AS16: 127028 | AT16: =AS16-CF!AT45-CF!AT11 -> 128228 | AU16: =AT16-CF!AU45-CF!AU11 -> 129428 | AV16: =AU16 -> 129428 | AW16: =AV16-CF!AW45-CF!AW11 -> 130628 | AX16: =AW16-CF!AX45-CF!AX11 -> 131828 | AY16: =AX16-CF!AY45-CF!AY11 -> 133028 | AZ16: =AY16-CF!AZ45-CF!AZ11 -> 134228 | BA16: =AZ16 -> 134228
C17: Intangible assets | V17: 417341 | W17: =V17 -> 417341 | X17: 491888 | Y17: 472120 | Z17: 452351 | AA17: 432583 | AB17: =AA17 -> 432583 | AC17: 412814 | AD17: 401869 | AE17: 381648 | AF17: 361427 | AG17: =AF17 -> 361427 | AH17: 341206 | AI17: 320985 | AJ17: 300764 | AK17: 281471 | AL17: =AK17 -> 281471 | AM17: 264914 | AN17: 253134 | AO17: 237970 | AP17: 222805 | AQ17: =AP17 -> 222805 | AR17: 207640 | AS17: 192475 | AT17: =AS17 -> 192475 | AU17: =AT17 -> 192475 | AV17: =AU17 -> 192475 | AW17: =AV17 -> 192475 | AX17: =AW17 -> 192475 | AY17: =AX17 -> 192475 | AZ17: =AY17 -> 192475 | BA17: =AZ17 -> 192475
C18: Goodwill | V18: 1772043 | W18: =V18 -> 1772043 | X18: 2354812 | Y18: 2363109 | Z18: 2363109 | AA18: 2362893 | AB18: =AA18 -> 2362893 | AC18: 2362330 | AD18: 2396509 | AE18: 2396509 | AF18: 2396509 | AG18: =AF18 -> 2396509 | AH18: 2396509 | AI18: 2396509 | AJ18: 2396509 | AK18: 2396509 | AL18: =AK18 -> 2396509 | AM18: 2396509 | AN18: 2396509 | AO18: 2396509 | AP18: 2396509 | AQ18: =AP18 -> 2396509 | AR18: 2396509 | AS18: 2396509 | AT18: =AS18 -> 2396509 | AU18: =AT18 -> 2396509 | AV18: =AU18 -> 2396509 | AW18: =AV18 -> 2396509 | AX18: =AW18 -> 2396509 | AY18: =AX18 -> 2396509 | AZ18: =AY18 -> 2396509 | BA18: =AZ18 -> 2396509
C19: Other assets | D19: 2552.1855 | E19: 2802 | F19: 3691 | G19: 4626.4705 | H19: =G19 -> 4626.4705 | I19: 5476 | J19: 5227.0558 | K19: 5979.866 | L19: 6640.8056 | M19: =L19 -> 6640.8056 | N19: 7398.4897 | O19: 6353 | P19: 6819 | Q19: 10700 | R19: =Q19 -> 10700 | S19: 17484 | T19: 21967 | U19: 22499 | V19: 52925 | W19: =V19 -> 52925 | X19: 54221 | Y19: 53935 | Z19: 53804 | AA19: 47730 | AB19: =AA19 -> 47730 | AC19: 48847 | AD19: 49600 | AE19: 49700 | AF19: 54366 | AG19: =AF19 -> 54366 | AH19: 48654 | AI19: 48788 | AJ19: 47736 | AK19: 38568 | AL19: =AK19 -> 38568 | AM19: 32051 | AN19: 30019 | AO19: 31410 | AP19: 33178 | AQ19: =AP19 -> 33178 | AR19: 34228 | AS19: 32974 | AT19: =AT64*IS!AT$17 -> 98249.206 | AU19: =AU64*IS!AU$17 -> 94987.657 | AV19: =AU19 -> 94987.657 | AW19: =AW64*IS!AW$17 -> 107118.61 | AX19: =AX64*IS!AX$17 -> 111011.73 | AY19: =AY64*IS!AY$17 -> 109638.35 | AZ19: =AZ64*IS!AZ$17 -> 106736.34 | BA19: =AZ19 -> 106736.34
B20: Total Assets | D20: =D14+SUM(D16:D19) -> 812460.8 | E20: =E14+SUM(E16:E19) -> 1014591.3 | F20: =F14+SUM(F16:F19) -> 896187.26 | G20: =G14+SUM(G16:G19) -> 1029284.9 | H20: =H14+SUM(H16:H19) -> 1029284.9 | I20: =I14+SUM(I16:I19) -> 1129213.7 | J20: =J14+SUM(J16:J19) -> 1400830.9 | K20: =K14+SUM(K16:K19) -> 1387144.9 | ... R20: =R14+SUM(R16:R19) -> 2404015 | S20: =S14+SUM(S16:S19)+S15 -> 2479208 | T20: =T14+SUM(T16:T19)+T15 -> 4082417 | U20: =U14+SUM(U16:U19)+U15 -> 3800165 | V20: =V14+SUM(V16:V19)+V15 -> 5969173 | W20: =W14+SUM(W16:W19)+W15 -> 5969173 | X20: =X14+SUM(X16:X19)+X15 -> 8564195 | Y20: =Y14+SUM(Y16:Y19)+Y15 -> 9510958 | Z20: =Z14+SUM(Z16:Z19)+Z15 -> 9183836 | ... BA20: =BA14+SUM(BA16:BA19)+BA15 -> 11370534
B22: Liabilities:
C23: Accounts Payable | D23: 1467 | E23: 2420 | F23: 1319 | G23: 1532 | H23: =G23 -> 1532 | I23: 2580 | J23: 3791 | K23: 4672.2937 | L23: 5063.3075 | M23: =L23 -> 5063.3075 | N23: 5686.3045 | O23: 6018 | P23: 6477 | Q23: 3478 | R23: =Q23 -> 3478 | S23: 6566 | T23: 5076 | U23: 4320 | V23: 11904 | W23: =V23 -> 11904 | X23: 13142 | Y23: 11770 | Z23: 9433 | AA23: 9948 | AB23: =AA23 -> 9948 | AC23: 11508 | AD23: 14262 | AE23: 9144 | AF23: 8519 | AG23: =AF23 -> 8519 | AH23: 6491 | AI23: 8772 | AJ23: 6824 | AK23: 7447 | AL23: =AK23 -> 7447 | AM23: 11181 | AN23: 5723 | AO23: 9302 | AP23: 16293 | AQ23: =AP23 -> 16293 | AR23: 6999 | AS23: 5044 | AT23: =AT67*IS!AT$17 -> 14100.068 | AU23: =AU67*IS!AU$17 -> 15044.666 | AV23: =AU23 -> 15044.666 | AW23: =AW67*IS!AW$17 -> 15372.946 | AX23: =AX67*IS!AX$17 -> 15931.66 | AY23: =AY67*IS!AY$17 -> 15734.561 | AZ23: =AZ67*IS!AZ$17 -> 16905.487 | BA23: =AZ23 -> 16905.487
C24: Accrued Compensation and Benefits | D24: 2245 | E24: 2625 | F24: 2541 | G24: 3425 | H24: =G24 -> 3425 | I24: 2872 | J24: 3304 | K24: 3487.386 | L24: 4333.4786 | M24: =L24 -> 4333.4786 | N24: 4408.9414 | O24: 6379 | P24: 6723 | Q24: 12387 | R24: =Q24 -> 12387 | S24: 7605 | T24: 14304 | U24: 11632 | V24: 20287 | W24: =V24 -> 20287 | X24: 18176 | Y24: 21146 | Z24: 18478 | AA24: 29004 | AB24: =AA24 -> 29004 | AC24: 20649 | AD24: 31021 | AE24: 20639 | AF24: 32901 | AG24: =AF24 -> 32901 | AH24: 23030 | AI24: 33228 | AJ24: 27619 | AK24: 34158 | AL24: =AK24 -> 34158 | AM24: 23305 | AN24: 29249 | AO24: 32998 | AP24: 39581 | AQ24: =AP24 -> 39581 | AR24: 35950 | AS24: 33081 | AT24: =AT68*IS!AT$17 -> 34243.021 | AU24: =AU68*IS!AU$17 -> 42984.761 | AV24: =AU24 -> 42984.761 | AW24: =AW68*IS!AW$17 -> 37334.296 | AX24: =AX68*IS!AX$17 -> 45519.028 | AY24: =AY68*IS!AY$17 -> 38212.506 | AZ24: =AZ68*IS!AZ$17 -> 48301.391 | BA24: =AZ24 -> 48301.391
C25: Deferred Revenue, current portion | D25: 2655 | E25: 2662 | F25: 2745 | G25: 3277 | H25: =G25 -> 3277 | I25: 2846 | J25: 3801 | K25: 3341.1347 | L25: 3468.5765 | M25: =L25 -> 3468.5765 | N25: 3706.4395 | O25: 4274 | P25: 6101 | Q25: 5891 | R25: =Q25 -> 5891 | S25: 6166 | T25: 5379 | U25: 8371 | V25: 12848 | W25: =V25 -> 12848 | X25: 21328 | Y25: 30487 | Z25: 30370 | AA25: 31868 | AB25: =AA25 -> 31868 | AC25: 30401 | AD25: 30358 | AE25: 28084 | AF25: 26328 | AG25: =AF25 -> 26328 | AH25: 19489 | AI25: 17327 | AJ25: 17547 | AK25: 17006 | AL25: =AK25 -> 17006 | AM25: 21730 | AN25: 21775 | AO25: 21740 | AP25: 22435 | AQ25: =AP25 -> 22435 | AR25: 20782 | AS25: 20887 | AT25: =AT70*IS!AT$17 -> 28200.135 | AU25: =AU70*IS!AU$17 -> 30089.333 | AV25: =AU25 -> 30089.333 | AW25: =AW70*IS!AW$17 -> 30745.891 | AX25: =AX70*IS!AX$17 -> 31863.32 | AY25: =AY70*IS!AY$17 -> 31469.122 | AZ25: =AZ70*IS!AZ$17 -> 33810.974 | BA25: =AZ25 -> 33810.974
C26: Other Accrued Liabilities | D26: 1511 | E26: 1454 | F26: 1789 | G26: 3001 | H26: =G26 -> 3001 | I26: 3793 | J26: 6683 | K26: 7462 | L26: 6550.8679 | M26: =L26 -> 6550.8679 | N26: 7730.7311 | O26: 9872 | P26: 10894 | Q26: 8541 | R26: =Q26 -> 8541 | S26: 8335 | T26: 6600 | U26: 9281 | V26: 72022 | W26: =V26 -> 72022 | X26: 79296 | Y26: 87578 | Z26: 155127 | AA26: 120080 | AB26: =AA26 -> 120080 | AC26: 141806 | AD26: 181551 | AE26: 171234 | AF26: 194733 | AG26: =AF26 -> 194733 | AH26: 252932 | AI26: 268409 | AJ26: 263603 | AK26: 299506 | AL26: =AK26 -> 299506 | AM26: 212327 | AN26: 265548 | AO26: 262921 | AP26: 252455 | AQ26: =AP26 -> 252455 | AR26: 306405 | AS26: 339017 | AT26: =AT69*IS!AT$17 -> 261858.4 | AU26: =AU69*IS!AU$17 -> 279400.95 | AV26: =AU26 -> 279400.95 | AW26: =AW69*IS!AW$17 -> 285497.56 | AX26: =AX69*IS!AX$17 -> 295873.68 | AY26: =AY69*IS!AY$17 -> 292213.28 | AZ26: =AZ69*IS!AZ$17 -> 313959.04 | BA26: =AZ26 -> 313959.04
C27: Convertible Preferred Stock Warrant Liabilities | D27: 490 | E27: 492 | F27: 496 | G27: 663 | H27: =G27 -> 663 | I27: 652 | J27: 358 | K27: 523.62413 | L27: 688.36132 | M27: =L27 -> 688.36132 | N27: 853.41269 | P27: =O27 -> 0 | Q27: =P27 -> 0 | R27: =Q27 -> 0 | S27: =R27 -> 0 | T27: =S27 -> 0 | U27: =T27 -> 0 | V27: =U27 -> 0 | W27: =V27 -> 0 | ... AJ27: =AI27 -> 0 | AL27: =AK27 -> 0 | AQ27: =AP27 -> 0 | AT27: =AS27 -> 0 | AU27: =AT27 -> 0 | AV27: =AU27 -> 0 | AW27: =AV27 -> 0 | AX27: =AW27 -> 0 | AY27: =AX27 -> 0 | AZ27: =AY27 -> 0 | BA27: =AZ27 -> 0
C28: Bank Borrowings, current portion | D28: 3044 | E28: 2417 | F28: 3042 | G28: 3667 | H28: =G28 -> 3667 | I28: 4292 | J28: 4500 | K28: 4500 | L28: 9.3132257e-13 | M28: =L28 -> 9.3132257e-13 | N28: 0 | O28: 0 | P28: 2300 | Q28: 2300 | R28: =Q28 -> 2300 | S28: 2300 | T28: 2300 | U28: 0 | V28: =U28 -> 0 | W28: =V28 -> 0 | Y28: =X28 -> 0 | Z28: =Y28 -> 0 | AA28: =Z28 -> 0 | AB28: =AA28 -> 0 | AD28: =AC28 -> 0 | AE28: =AD28 -> 0 | AF28: 135046 | AG28: =AF28 -> 135046 | AH28: 135033 | AI28: 135021 | AJ28: 0 | AL28: =AK28 -> 0 | AP28: 180005 | AQ28: =AP28 -> 180005 | AT28: =AS28 -> 0 | AU28: =AT28 -> 0 | AV28: =AU28 -> 0 | AW28: =AV28 -> 0 | AX28: =AW28 -> 0 | AY28: =AX28 -> 0 | AZ28: =AY28 -> 0 | BA28: =AZ28 -> 0
C29: Operating lease liabilities | S29: 2485 | T29: 4727 | U29: 6388
C30: Convertible notes | X30: 1132793 | Y30: 1133825 | Z30: 1134835 | AA30: 75097 | AB30: =AA30 -> 75097 | AN30: 33373 | AO30: 33397 | AP30: 33421 | AQ30: =AP30 -> 33421 | AR30: 33446 | AS30: 0 | AT30: =AS30 -> 0 | AU30: =AT30 -> 0 | AV30: =AU30 -> 0 | AW30: =AV30 -> 0 | AX30: =AW30 -> 0 | AY30: =AX30 -> 0 | AZ30: =AY30 -> 0 | BA30: =AZ30 -> 0
C31: Customer Fund Deposits | D31: 709298 | E31: 902871 | F31: 786615 | G31: 915013 | H31: =G31 -> 915013 | I31: 1013736 | J31: 1212826 | K31: 1179910 | L31: 1329310 | M31: =L31 -> 1329310 | N31: 1466491.8 | O31: 1491763 | P31: 1353552 | Q31: 1644250 | R31: =Q31 -> 1644250 | S31: 1668903 | T31: 2217680 | U31: 1929840 | V31: 2208598 | W31: =V31 -> 2208598 | X31: 2432521 | Y31: 3380395 | Z31: 3043540 | AA31: 3142660 | AB31: =AA31 -> 3142660 | AC31: 3121654 | AD31: 3474048 | AE31: 3106630 | AF31: 3355909 | AG31: =AF31 -> 3355909 | AH31: 3263528 | AI31: 3655435 | AJ31: 3510918 | AK31: 3704907 | AL31: =AK31 -> 3704907 | AM31: 3787171 | AN31: 3766541 | AO31: 3657218 | AP31: 4044470 | AQ31: =AP31 -> 4044470 | AR31: 3974674 | AS31: 4032211 | AT31: =AT13 -> 4147751.7 | AU31: =AU13 -> 4218508.8 | AV31: =AU31 -> 4218508.8 | AW31: =AW13 -> 4399114.5 | AX31: =AX13 -> 4676273.2 | AY31: =AY13 -> 4491027 | AZ31: =AZ13 -> 4759461.5 | BA31: =AZ31 -> 4759461.5
B32: Total Current Liabilities | D32: =SUM(D23:D31) -> 720710 | E32: =SUM(E23:E31) -> 914941 | F32: =SUM(F23:F31) -> 798547 | G32: =SUM(G23:G31) -> 930578 | H32: =SUM(H23:H31) -> 930578 | I32: =SUM(I23:I31) -> 1030771 | J32: =SUM(J23:J31) -> 1235263 | K32: =SUM(K23:K31) -> 1203896.4 | ... BA32: =SUM(BA23:BA31) -> 5172438.4
