Workbook
Name blank: #REF!
Name Current_Q: #REF!
Name export: #REF!
Name FY_92: #REF!
Name FY_93: #REF!
Name FY_94: #REF!
Name N_A: #REF!
Name N_M: #REF!
Name Next_Actual_Period_Range: '[1]Income Statement'!$D$3:$BE$6
Name NM_T: #REF!
Name Prior_Q: #REF!
Name Same_Q_Last_Yr: #REF!
Name source: #REF!
Name WIZARD_3YRATCF: #REF!
Name WIZARD_3YREBITDA: #REF!
Name WIZARD_3YRSECGROWTH: #REF!
Name WIZARD_AVGTRADINGVOLUME: #REF!
Name WIZARD_BKVALSHR: #REF!
Name WIZARD_BURNRATE: #REF!
Name WIZARD_CASH: #REF!
Name WIZARD_DIVYIELD: #REF!
Name WIZARD_EARNINGS: #REF!
Name WIZARD_EBITDABYSHROO: #REF!
Name WIZARD_EVBYEBITDAOO: #REF!
Name WIZARD_EVINVCAP: #REF!
Name WIZARD_LTDEBT: #REF!
Name WIZARD_MARKETCAP: #REF!
Name WIZARD_NETDEBTCAP: #REF!
Name WIZARD_OPERMARGIN: #REF!
Name WIZARD_PRICEESTNAV: #REF!
Name WIZARD_REVENUES: #REF!
Name WIZARD_ROAA: #REF!
Name WIZARD_ROAE: #REF!
Name WIZARD_ROE: #REF!
Name WIZARD_ROIC: #REF!
Name WIZARD_SHARESOUT: #REF!
Name WIZARD_STATIONREV: #REF!
Name WIZARD_TICKER: #REF!
Name WIZARD_TOTDEBTCAP: #REF!
Name WIZARD_Y1CAPREVR: [2]AMAT_FC!#REF!
Name WIZARD_Y1CAPREVS2: #REF!
Name WIZARD_Y1CASHCYEPSS1: #REF!
Name WIZARD_Y1CASHCYPES1: #REF!
Name WIZARD_Y1CYE: [2]AMAT_FC!#REF!
Name WIZARD_Y1CYPEE: [2]AMAT_FC!#REF!
Name WIZARD_Y1CYPES1: #REF!
Name WIZARD_Y1CYREVS2: #REF!
Name WIZARD_Y1CYS1: #REF!
Name WIZARD_Y1E: [2]AMAT_FC!#REF!
Name WIZARD_Y1EBITDAYRS2: #REF!
Name WIZARD_Y1EMVBYREV: #REF!
Name WIZARD_Y1EVEBITDAS2: #REF!
Name WIZARD_Y1PEE: [2]AMAT_FC!#REF!
Name WIZARD_Y1PES1: #REF!
Name WIZARD_Y1Q1E: [2]AMAT_FC!#REF!
Name WIZARD_Y1Q1R: [2]AMAT_FC!#REF!
Name WIZARD_Y1Q1S1: #REF!
Name WIZARD_Y1Q1S2: #REF!
Name WIZARD_Y1Q2E: [2]AMAT_FC!#REF!
Name WIZARD_Y1Q2R: [2]AMAT_FC!#REF!

Sheet Comparison
B2: ='Income Statement'!B2 -> Tyler Technologies (TYL) | N2: Guidance / Consensus Estimates
B4: Variance Analysis | D4: ='Income Statement'!CJ4 -> 4Q24 | E4: =K4 -> 4Q25 | F4: % Change | G4: ='Income Statement'!CN4 -> 3Q25 | H4: =K4 -> 4Q25 | I4: % Change | J4: 4Q25E | K4: ='Income Statement'!CO4 -> 4Q25 | L4: % Change | N4: 3Q Cons. | O4: 4Q Guide | P4: 4Q Cons. | Q4: FY21 G Prev | R4: FY21 G New | S4: FY21 Cons.
B5: Software License Revenue | D5: ='Income Statement'!CJ5 -> 6106 | E5: =K5 -> 5300 | F5: =E5/D5-1 -> -0.13200131 | G5: ='Income Statement'!CN5 -> 5100 | H5: =K5 -> 5300 | I5: =H5/G5-1 -> 0.039215686 | J5: 5300 | K5: ='Income Statement'!CO5 -> 5300 | L5: =K5/J5-1 -> 0
B6: Subscription Revenue | D6: ='Income Statement'!CJ8 -> 348836 | E6: =K6 -> 404858.03 | F6: =E6/D6-1 -> 0.16059705 | G6: ='Income Statement'!CN8 -> 401094 | H6: =K6 -> 404858.03 | I6: =H6/G6-1 -> 0.0093844186 | J6: 404858.03 | K6: ='Income Statement'!CO8 -> 404858.03 | L6: =K6/J6-1 -> 0
B7: Software Services Revenue | D7: ='Income Statement'!CJ11 -> 62795 | E7: =K7 -> 64000 | F7: =E7/D7-1 -> 0.019189426 | G7: ='Income Statement'!CN11 -> 64728 | H7: =K7 -> 64000 | I7: =H7/G7-1 -> -0.011247065 | J7: 64000 | K7: ='Income Statement'!CO11 -> 64000 | L7: =K7/J7-1 -> 0
B8: Maintenance Revenue | D8: ='Income Statement'!CJ14 -> 115018 | E8: =K8 -> 109500 | F8: =E8/D8-1 -> -0.0479751 | G8: ='Income Statement'!CN14 -> 111312 | H8: =K8 -> 109500 | I8: =H8/G8-1 -> -0.016278568 | J8: 109500 | K8: ='Income Statement'!CO14 -> 109500 | L8: =K8/J8-1 -> 0
B9: Appraisal Services Revenue | D9: ='Income Statement'!CJ17 -> 0 | E9: =K9 -> 0 | F9: =E9/D9-1 -> #DIV/0! | G9: ='Income Statement'!CN17 -> 0 | H9: =K9 -> 0 | I9: =H9/G9-1 -> #DIV/0! | J9: 0 | K9: ='Income Statement'!CO17 -> 0 | L9: =K9/J9-1 -> #DIV/0!
B10: Hardware & Other Revenue | D10: ='Income Statement'!CJ20 -> 8376 | E10: =K10 -> 6500 | F10: =E10/D10-1 -> -0.22397326 | G10: ='Income Statement'!CN20 -> 13645 | H10: =K10 -> 6500 | I10: =H10/G10-1 -> -0.52363503 | J10: 6500 | K10: ='Income Statement'!CO20 -> 6500 | L10: =K10/J10-1 -> 0
B11: Total Revenue | D11: =SUM(D5:D10) -> 541131 | E11: =K11 -> 590158.03 | F11: =E11/D11-1 -> 0.090601045 | G11: =SUM(G5:G10) -> 595879 | H11: =K11 -> 590158.03 | I11: =H11/G11-1 -> -0.0096008854 | J11: 590158.03 | K11: =SUM(K5:K10) -> 590158.03 | L11: =K11/J11-1 -> 0
B13: Cost of Revenue
B14: Software Licenses | D14: ='Income Statement'!CJ28 -> 1282 | E14: =K14 -> 2588 | F14: =E14/D14-1 -> 1.0187207 | G14: ='Income Statement'!CN28 -> 1669 | H14: =K14 -> 2588 | I14: =H14/G14-1 -> 0.55062912 | J14: 1855 | K14: ='Income Statement'!CO28 -> 2588 | L14: =K14/J14-1 -> 0.39514825
B15: Acquired software | D15: ='Income Statement'!BP30 -> 0 | E15: =K15 -> 0 | G15: ='Income Statement'!BS30 -> 0 | H15: =K15 -> 0 | J15: 0 | K15: ='Income Statement'!BU30 -> 0
B16: Software Services, Maint, & Subscrip. | D16: ='Income Statement'!CJ32 -> 279671 | E16: =K16 -> 285538 | F16: =E16/D16-1 -> 0.020978221 | G16: ='Income Statement'!CN32 -> 285958 | H16: =K16 -> 285538 | I16: =H16/G16-1 -> -0.0014687472 | J16: 286287.23 | K16: ='Income Statement'!CO32 -> 285538 | L16: =K16/J16-1 -> -0.002617046
B17: Appraisal Services | D17: ='Income Statement'!CJ34 -> 0 | E17: =K17 -> 0 | F17: =E17/D17-1 -> #DIV/0! | G17: ='Income Statement'!CN34 -> 0 | H17: =K17 -> 0 | I17: =H17/G17-1 -> #DIV/0! | J17: 0 | K17: ='Income Statement'!CO34 -> 0 | L17: =K17/J17-1 -> #DIV/0!
B18: Hardware & Other | D18: ='Income Statement'!CJ36 -> 5778 | E18: =K18 -> 6407 | F18: =E18/D18-1 -> 0.1088612 | G18: ='Income Statement'!CN36 -> 8117 | H18: =K18 -> 6407 | I18: =H18/G18-1 -> -0.21066897 | J18: 4875 | K18: ='Income Statement'!CO36 -> 6407 | L18: =K18/J18-1 -> 0.31425641
B19: Total Cost of Revenue | D19: =SUM(D14:D18) -> 286731 | E19: =K19 -> 294533 | F19: =E19/D19-1 -> 0.027210173 | G19: =SUM(G14:G18) -> 295744 | H19: =K19 -> 294533 | I19: =H19/G19-1 -> -0.0040947576 | J19: 293017.23 | K19: =SUM(K14:K18) -> 294533 | L19: =K19/J19-1 -> 0.0051729831
AC20: Feature | AD20: Traditional Payment Processor | AE20: Tyler Technologies (PayFac)
B21: Gross Profit | D21: =D11-D19 -> 254400 | E21: =K21 -> 295625.03 | F21: =E21/D21-1 -> 0.16204809 | G21: =G11-G19 -> 300135 | H21: =K21 -> 295625.03 | I21: =H21/G21-1 -> -0.015026458 | J21: 297140.81 | K21: =K11-K19 -> 295625.03 | L21: =K21/J21-1 -> -0.0051011949 | AC21: Merchant ID (MID) | AD21: Every single city or court needs its own unique MID from a bank. | AE21: Tyler has a Master MID. Agencies are "sub-merchants" under Tyler.
B22: Gross Margins | D22: =D21/D11 -> 0.47012646 | E22: =K22 -> 0.5009252 | F22: =E22-D22 -> 0.030798747 | G22: =G21/G11 -> 0.50368447 | H22: =K22 -> 0.5009252 | J22: 0.50349362 | K22: =K21/K11 -> 0.5009252 | AC22: Onboarding | AD22: Slow (2–4 weeks). Requires the city to pass bank credit checks. | AE22: Instant (Minutes/Hours). Tyler performs the "underwriting" itself.
AC23: Contracting | AD23: City must sign with a Bank, a Gateway, and a Software vendor. | AE23: Single Vendor. The city only signs a contract with Tyler.
B24: Operating Expenses | AC24: Risk & Liability | AD24: The bank/processor holds the fraud risk. | AE24: Tyler assumes the risk. If a sub-merchant (city) defaults, Tyler is liable.
B25: SG&A | D25: ='Income Statement'!CJ44+'Income Statement'!CJ46 -> 93194 | E25: =K25 -> 91755 | F25: =E25/D25-1 -> -0.015440908 | G25: ='Income Statement'!CN44+'Income Statement'!CN46 -> 93489 | H25: =K25 -> 91755 | I25: =H25/G25-1 -> -0.018547637 | J25: 98556.392 | K25: ='Income Statement'!CO44+'Income Statement'!CO46 -> 91755 | L25: =K25/J25-1 -> -0.069010153
B26: R&D | D26: ='Income Statement'!CJ48 -> 29435 | E26: =K26 -> 50364 | F26: =E26/D26-1 -> 0.71102429 | G26: ='Income Statement'!CN48 -> 48038 | H26: =K26 -> 50364 | I26: =H26/G26-1 -> 0.048420001 | J26: 50163.433 | K26: ='Income Statement'!CO48 -> 50364 | L26: =K26/J26-1 -> 0.0039982732
B27: Other | D27: ='Income Statement'!BP50 -> 0 | E27: =K27 -> 0 | G27: ='Income Statement'!BS50 -> 0 | H27: =K27 -> 0 | J27: 0 | K27: ='Income Statement'!AU50 -> 0
B28: Total Operating Expenses | D28: =SUM(D25:D27) -> 122629 | E28: =K28 -> 142119 | F28: =E28/D28-1 -> 0.15893467 | G28: =SUM(G25:G27) -> 141527 | H28: =K28 -> 142119 | I28: =H28/G28-1 -> 0.0041829474 | J28: 148719.82 | K28: =SUM(K25:K27) -> 142119 | L28: =K28/J28-1 -> -0.044384295
B30: Non-GAAP Operating Income (Loss) | D30: =D21-D28 -> 131771 | E30: =K30 -> 153506.03 | F30: =E30/D30-1 -> 0.1649455 | G30: =G21-G28 -> 158608 | H30: =K30 -> 153506.03 | I30: =H30/G30-1 -> -0.032167142 | J30: 148420.98 | K30: =K21-K28 -> 153506.03 | L30: =K30/J30-1 -> 0.034261001
B31: Non-GAAP Operating Margins | D31: =D30/D11 -> 0.24351035 | E31: =K31 -> 0.26011005 | F31: =E31-D31 -> 0.016599696 | G31: =G30/G11 -> 0.26617484 | H31: =K31 -> 0.26011005 | J31: 0.25149362 | K31: =K30/K11 -> 0.26011005
B33: GAAP & Non-cash charges | D33: ='Income Statement'!CJ64 -> 60085 | E33: =K33 -> 63552 | F33: =E33/D33-1 -> 0.057701589 | G33: ='Income Statement'!CN64 -> 60676 | H33: =K33 -> 63552 | I33: =H33/G33-1 -> 0.047399301 | J33: 62000 | K33: ='Income Statement'!CO64 -> 63552 | L33: =K33/J33-1 -> 0.025032258
B35: GAAP Operating Income | D35: =D30-D33 -> 71686 | E35: =K35 -> 89954.034 | F35: =E35/D35-1 -> 0.25483405 | G35: =G30-G33 -> 97932 | H35: =K35 -> 89954.034 | I35: =H35/G35-1 -> -0.081464343 | J35: 86420.983 | K35: =K30-K33 -> 89954.034 | L35: =K35/J35-1 -> 0.04088187
B36: GAAP Operating Margins | D36: =D35/D11 -> 0.13247439 | E36: =K36 -> 0.15242364 | G36: =G35/G11 -> 0.1643488 | H36: =K36 -> 0.15242364 | J36: 0.14643702 | K36: =K35/K11 -> 0.15242364
B38: Interest & Other Income (Expense) | D38: ='Income Statement'!CJ71 -> 5081 | E38: =K38 -> 9988 | F38: =E38/D38-1 -> 0.96575477 | G38: ='Income Statement'!CN71 -> 9620 | H38: =K38 -> 9988 | I38: =H38/G38-1 -> 0.038253638 | J38: 5765 | K38: ='Income Statement'!CO71 -> 9988 | L38: =K38/J38-1 -> 0.73252385
E39: =K39 -> 0 | H39: =K39 -> 0
B40: Non-GAAP Income before Taxes | D40: =D30+D38 -> 136852 | E40: =K40 -> 163494.03 | F40: =E40/D40-1 -> 0.19467771 | G40: =G30+G38 -> 168228 | H40: =K40 -> 163494.03 | I40: =H40/G40-1 -> -0.028140179 | J40: 154185.98 | K40: =K30+K38 -> 163494.03 | L40: =K40/J40-1 -> 0.060368986
B41: Income Tax | D41: ='Income Statement'!CJ79 -> 30107 | E41: =K41 -> 33416 | F41: =E41/D41-1 -> 0.10990799 | G41: ='Income Statement'!CN79 -> 37851 | H41: =K41 -> 33416 | I41: =H41/G41-1 -> -0.11716996 | J41: 34691.846 | K41: ='Income Statement'!CO79 -> 33416 | L41: =K41/J41-1 -> -0.036776541
B42: Non-GAAP Net Income | D42: =D40-D41 -> 106745 | E42: =K42 -> 130078.03 | F42: =E42/D42-1 -> 0.21858667 | G42: =G40-G41 -> 130377 | H42: =K42 -> 130078.03 | I42: =H42/G42-1 -> -0.0022930885 | J42: 119494.14 | K42: =K40-K41 -> 130078.03 | L42: =K42/J42-1 -> 0.088572526
B44: GAAP Income before Taxes | D44: =D35+D38 -> 76767 | E44: =K44 -> 99942.034 | F44: =E44/D44-1 -> 0.30188797 | G44: =G35+G38 -> 107552 | H44: =K44 -> 99942.034 | I44: =H44/G44-1 -> -0.070756155 | J44: 92185.983 | K44: =K35+K38 -> 99942.034 | L44: =K44/J44-1 -> 0.084134824
B45: Income Tax | D45: ='Income Statement'!CJ85 -> 11546 | E45: =K45 -> 19432 | F45: =E45/D45-1 -> 0.6830071 | G45: ='Income Statement'!CN85 -> 23159 | H45: =K45 -> 19432 | I45: =H45/G45-1 -> -0.16093096 | J45: 19819.986 | K45: ='Income Statement'!CO85 -> 19432 | L45: =K45/J45-1 -> -0.019575506
B46: GAAP Net Income | D46: =D44-D45 -> 65221 | E46: =K46 -> 80510.034 | F46: =E46/D46-1 -> 0.23441888 | G46: =G44-G45 -> 84393 | H46: =K46 -> 80510.034 | I46: =H46/G46-1 -> -0.046010522 | J46: 72365.996 | K46: =K44-K45 -> 80510.034 | L46: =K46/J46-1 -> 0.11253956
B48: Non-GAAP EPS | D48: =D42/D52 -> 2.4308845 | E48: =K48 -> 2.9873466 | F48: =E48/D48-1 -> 0.22891344 | G48: =G42/G52 -> 2.974335 | H48: =K48 -> 2.9873466 | I48: =H48/G48-1 -> 0.0043746356 | J48: 2.7322938 | K48: =K42/K52 -> 2.9873466 | L48: =K48/J48-1 -> 0.093347515
B49: GAAP EPS | D49: =D46/D52 -> 1.485266 | E49: =K49 -> 1.8489777 | G49: =G46/G52 -> 1.9252863 | H49: =K49 -> 1.8489777 | J49: 1.6546851 | K49: =K46/K52 -> 1.8489777
...

Sheet Income Statement
CM1: =(CM8+CM14)/CM23 -> 0.86761156 | CN1: =(CN8+CN14)/CN23 -> 0.85991619 | CO1: =(CO8+CO14)/CO23 -> 0.87155983 | CP1: =(CP8+CP14)/CP23 -> 0.8655628 | CQ1: =(CQ8+CQ14)/CQ23 -> 0.87346491 | CR1: =(CR8+CR14)/CR23 -> 0.87133137 | CS1: =(CS8+CS14)/CS23 -> 0.88022056 | CT1: =(CT8+CT14)/CT23 -> 0.88311691 | CU1: =(CU8+CU14)/CU23 -> 0.87704759
B2: Tyler Technologies (TYL) | CL2: =15000/4 -> 3750 | CO2: =CP60/CP96 -> 3.4528243 | CP2: =(+CP58+CP59)/CP96 -> 2.1421863 | CT2: =CU60/CU96 -> 3.2227133 | CU2: =(+CU58+CU59)/CU96 -> 1.929089 | CW2: 40000 | CX2: =CP8-40000 -> 1546016 | CY2: =CP8+CP11+CP14 -> 2283142
B4: Income Statement | D4: 2007 | E4: 1Q08 | F4: 2Q08 | G4: 3Q08 | H4: 4Q08 | I4: 2008 | J4: 1Q09 | K4: 2Q09 | L4: 3Q09 | M4: 4Q09 | N4: 2009 | O4: 1Q10 | P4: 2Q10 | Q4: 3Q10 | R4: 4Q10 | S4: 2010 | T4: 1Q11 | U4: 2Q11 | V4: 3Q11 | W4: 4Q11 | X4: 2011 | Y4: 1Q12 | Z4: 2Q12 | AA4: 3Q12 | AB4: 4Q12 | AC4: 2012 | AD4: 1Q13 | AE4: 2Q13 | AF4: 3Q13 | AG4: 4Q13 | AH4: 2013 | AI4: 1Q14 | AJ4: 2Q14 | AK4: 3Q14 | AL4: 4Q14 | AM4: 2014 | AN4: 1Q15 | AO4: 2Q15 | AP4: 3Q15 | AQ4: 4Q15 | AR4: 2015 | AS4: 1Q16 | AT4: 2Q16 | AU4: 3Q16 | AV4: 4Q16 | AW4: 2016 | AX4: 1Q17 | AY4: 2Q17 | AZ4: 3Q17 | BA4: 4Q17 | BB4: 2017 | BC4: 1Q18 | BD4: 2Q18 | BE4: 3Q18 | BF4: 4Q18 | BG4: 2018 | BH4: 1Q19 | BI4: 2Q19 | BJ4: 3Q19 | BK4: 4Q19 | BL4: 2019 | BM4: 1Q20 | BN4: 2Q20 | BO4: 3Q20 | BP4: 4Q20 | BQ4: 2020 | BR4: 1Q21 | BS4: 2Q21 | BT4: 3Q21 | BU4: 4Q21 | BV4: 2021 | BW4: 1Q22 | BX4: 2Q22 | BY4: 3Q22 | BZ4: 4Q22 | CA4: 2022 | CB4: 1Q23 | CC4: 2Q23 | CD4: 3Q23 | CE4: 4Q23 | CF4: 2023 | CG4: 1Q24 | CH4: 2Q24 | CI4: 3Q24 | CJ4: 4Q24 | CK4: 2024 | CL4: 1Q25 | CM4: 2Q25 | CN4: 3Q25 | CO4: 4Q25 | CP4: 2025 | CQ4: 1Q26E | CR4: 2Q26E | CS4: 3Q26E | CT4: 4Q26E | CU4: 2026E | CY4: =CP32 -> 1135423
B5: Software License Revenue | D5: 35063 | E5: 8369 | F5: 11905 | G5: 11372 | H5: =I5-G5-F5-E5 -> 9844 | I5: 41490 | J5: 10756 | K5: 9912 | L5: 10167 | M5: =N5-L5-K5-J5 -> 11296 | N5: 42131 | O5: 8449 | P5: 8735 | Q5: 9260 | R5: 8469 | S5: =SUM(O5:R5) -> 34913 | T5: 6822 | U5: 8308 | V5: 7631 | W5: 9833 | X5: =SUM(T5:W5) -> 32594 | Y5: 7563 | Z5: 8422 | AA5: 8973 | AB5: 8970 | AC5: =SUM(Y5:AB5) -> 33928 | AD5: 8830 | AE5: 10090 | AF5: 10495 | AG5: 11426 | AH5: =SUM(AD5:AG5) -> 40841 | AI5: 11232 | AJ5: 12083 | AK5: 13226 | AL5: 12524 | AM5: =SUM(AI5:AL5) -> 49065 | AN5: 14300 | AO5: 14586 | AP5: 15690 | AQ5: 14432 | AR5: =SUM(AN5:AQ5) -> 59008 | AS5: 16850 | AT5: 17551 | AU5: 19930 | AV5: 19975 | AW5: =SUM(AS5:AV5) -> 74306 | AX5: 18223 | AY5: 17107 | AZ5: 19842 | BA5: 20522 | BB5: =SUM(AX5:BA5) -> 75694 | BC5: 22776 | BD5: 22400 | BE5: 22444 | BF5: 25821 | BG5: =SUM(BC5:BF5) -> 93441 | BH5: 21793 | BI5: 20675 | BJ5: 25379 | BK5: =32358 -> 32358 | BL5: =SUM(BH5:BK5) -> 100205 | BM5: 18737 | BN5: =17025 -> 17025 | BO5: 19937 | BP5: 17465 | BQ5: =SUM(BM5:BP5) -> 73164 | BR5: 14933 | BS5: 17604 | BT5: 22673 | BU5: 19242 | BV5: =SUM(BR5:BU5) -> 74452 | BW5: 16506 | BX5: 15009 | BY5: 20269 | BZ5: 7622 | CA5: =SUM(BW5:BZ5) -> 59406 | CB5: 10130 | CC5: 9779 | CD5: 10554 | CE5: 7633 | CF5: =SUM(CB5:CE5) -> 38096 | CG5: 8734 | CH5: 5329 | CI5: 6188 | CJ5: 6106 | CK5: =SUM(CG5:CJ5) -> 26357 | CL5: 6994 | CM5: 3663 | CN5: 5100 | CO5: ='Revenue Build'!AF63 -> 5300 | CP5: =SUM(CL5:CO5) -> 21057 | CQ5: ='Revenue Build'!AH63 -> 3000 | CR5: ='Revenue Build'!AI63 -> 3000 | CS5: ='Revenue Build'!AJ63 -> 4000 | CT5: ='Revenue Build'!AK63 -> 4500 | CU5: =SUM(CQ5:CT5) -> 14500 | CV5: 0
C6: Y/Y Growth | I6: =I5/D5-1 -> 0.18329863 | J6: =J5/E5-1 -> 0.28521926 | K6: =K5/F5-1 -> -0.16740865 | L6: =L5/G5-1 -> -0.10596201 | M6: =M5/H5-1 -> 0.14750102 | N6: =N5/I5-1 -> 0.015449506 | O6: =O5/J5-1 -> -0.21448494 | P6: =P5/K5-1 -> -0.11874496 | ... CU6: =CU5/CP5-1 -> -0.31139289 | CX6: Recrruing, SaaS, Maintenace and Transactions Combined | DA6: Price | DB6: 215
C7: Q/Q Growth | F7: =F5/E5-1 -> 0.42251165 | G7: =G5/F5-1 -> -0.044771105 | H7: =H5/G5-1 -> -0.13436511 | J7: =J5/H5-1 -> 0.092645266 | K7: =K5/J5-1 -> -0.078467832 | L7: =L5/K5-1 -> 0.025726392 | M7: =M5/L5-1 -> 0.11104554 | O7: =O5/M5-1 -> -0.25203612 | P7: =P5/O5-1 -> 0.03385016 | Q7: =Q5/P5-1 -> 0.060103034 | R7: =R5/Q5-1 -> -0.085421166 | T7: =T5/R5-1 -> -0.19447396 | U7: =U5/T5-1 -> 0.21782468 | V7: =V5/U5-1 -> -0.081487723 | W7: =W5/V5-1 -> 0.28855982 | Y7: =Y5/W5-1 -> -0.23085528 | Z7: =Z5/Y5-1 -> 0.11357927 | AA7: =AA5/Z5-1 -> 0.06542389 | AB7: =AB5/AA5-1 -> -0.00033433634 | AD7: =AD5/AB5-1 -> -0.015607581 | AE7: =AE5/AD5-1 -> 0.14269536 | AF7: =AF5/AE5-1 -> 0.040138751 | AG7: =AG5/AF5-1 -> 0.088708909 | AI7: =AI5/AG5-1 -> -0.01697882 | AJ7: =AJ5/AI5-1 -> 0.07576567 | AK7: =AK5/AJ5-1 -> 0.094595713 | AL7: =AL5/AK5-1 -> -0.053077272 | AN7: =AN5/AL5-1 -> 0.14180773 | AO7: =AO5/AN5-1 -> 0.02 | AP7: =AP5/AO5-1 -> 0.075689017 | AQ7: =AQ5/AP5-1 -> -0.080178458 | AS7: =AS5/AQ5-1 -> 0.16754435 | AT7: =AT5/AS5-1 -> 0.041602374 | AU7: =AU5/AT5-1 -> 0.13554783 | AV7: =AV5/AU5-1 -> 0.0022579027 | AX7: =AX5/AV5-1 -> -0.087709637 | AY7: =AY5/AX5-1 -> -0.061241288 | AZ7: =AZ5/AY5-1 -> 0.15987607 | BA7: =BA5/AZ5-1 -> 0.034270739 | BC7: =BC5/BA5-1 -> 0.10983335 | BD7: =BD5/BC5-1 -> -0.016508606 | BE7: =BE5/BD5-1 -> 0.0019642857 | BF7: =BF5/BE5-1 -> 0.15046338 | BH7: =BH5/BF5-1 -> -0.15599706 | BI7: =BI5/BH5-1 -> -0.051300876 | BJ7: =BJ5/BI5-1 -> 0.22752116 | BK7: =BK5/BJ5-1 -> 0.27499113 | BM7: =BM5/BK5-1 -> -0.42094691 | BN7: =BN5/BM5-1 -> -0.091370017 | BO7: =BO5/BN5-1 -> 0.17104258 | BP7: =BP5/BO5-1 -> -0.12399057 | BR7: =BR5/BP5-1 -> -0.14497567 | BS7: =BS5/BR5-1 -> 0.1788656 | BT7: =BT5/BS5-1 -> 0.28794592 | BU7: =BU5/BT5-1 -> -0.15132536 | BW7: =BW5/BV5-1 -> -0.77830011 | BX7: =BX5/BW5-1 -> -0.090694293 | BY7: =BY5/BX5-1 -> 0.35045639 | BZ7: =BZ5/BY5-1 -> -0.62395777 | CB7: =CB5/BZ5-1 -> 0.32904749 | CC7: =CC5/CB5-1 -> -0.034649556 | CD7: =CD5/CC5-1 -> 0.079251457 | CE7: =CE5/CD5-1 -> -0.2767671 | CG7: =CG5/CE5-1 -> 0.14424211 | CH7: =CH5/CG5-1 -> -0.38985574 | CI7: =CI5/CH5-1 -> 0.16119347 | CJ7: =CJ5/CI5-1 -> -0.013251454 | CL7: =CL5/CJ5-1 -> 0.14543072 | CM7: =CM5/CL5-1 -> -0.47626537 | CN7: =CN5/CM5-1 -> 0.39230139 | CO7: =CO5/CN5-1 -> 0.039215686 | CQ7: =CQ5/CO5-1 -> -0.43396226 | CR7: =CR5/CQ5-1 -> 0 | CS7: =CS5/CR5-1 -> 0.33333333 | CT7: =CT5/CS5-1 -> 0.125 | DA7: Shares | DB7: 42200
B8: Subscription Revenue | D8: 10406 | E8: 3265 | F8: 3712 | G8: 3526 | H8: =I8-G8-F8-E8 -> 3871 | I8: 14374 | J8: 3976 | K8: 4160 | L8: 4558 | M8: =N8-L8-K8-J8 -> 4487 | N8: 17181 | O8: 5253 | P8: 5807 | Q8: 6020 | R8: 6218 | S8: =SUM(O8:R8) -> 23298 | T8: 6964 | U8: 7277 | V8: 7989 | W8: 8930 | X8: =SUM(T8:W8) -> 31160 | Y8: 9968 | Z8: 10553 | AA8: 11335 | AB8: 12762 | AC8: =SUM(Y8:AB8) -> 44618 | AD8: 13473 | AE8: 13863 | AF8: 15214 | AG8: 19314 | AH8: =SUM(AD8:AG8) -> 61864 | AI8: 20507 | AJ8: 20934 | AK8: 22694 | AL8: 23713 | AM8: =SUM(AI8:AL8) -> 87848 | AN8: 25288 | AO8: 26949 | AP8: 29036 | AQ8: 30660 | AR8: =SUM(AN8:AQ8) -> 111933 | AS8: 34089 | AT8: 33968 | AU8: 36869 | AV8: 37778 | AW8: =SUM(AS8:AV8) -> 142704 | AX8: 40102 | AY8: 40947 | AZ8: 44840 | BA8: 47621 | BB8: =SUM(AX8:BA8) -> 173510 | BC8: 49028 | BD8: =53009+1551+111 -> 54671 | BE8: =58699+1397+104 -> 60200 | BF8: =59811+952+100 -> 60863 | BG8: =SUM(BC8:BF8) -> 224762 | BH8: 67275 | BI8: 73475 | BJ8: 75272 | BK8: =80330 -> 80330 | BL8: =SUM(BH8:BK8) -> 296352 | BM8: 81723 | BN8: =85638 -> 85638 | BO8: 89290 | BP8: 93997 | BQ8: =SUM(BM8:BP8) -> 350648 | BR8: 102479 | BS8: =199558+1288 -> 200846 | BT8: =252942+751 -> 253693 | BU8: =229456+639 -> 230095 | BV8: =SUM(BR8:BU8) -> 787113 | BW8: 245443 | BX8: 255816 | BY8: 254346 | BZ8: 256699 | CA8: =SUM(BW8:BZ8) -> 1012304 | CB8: 280465 | CC8: 297789 | CD8: 295190 | CE8: 286068 | CF8: =SUM(CB8:CE8) -> 1159512 | CG8: 313243 | CH8: 333682 | CI8: 347170 | CJ8: 348836 | CK8: =SUM(CG8:CJ8) -> 1342931 | CL8: 374989 | CM8: 405075 | CN8: 401094 | CO8: ='Revenue Build'!AF65 -> 404858.03 | CP8: =SUM(CL8:CO8) -> 1586016 | CQ8: ='Revenue Build'!AH65 -> 424526.87 | CR8: ='Revenue Build'!AI65 -> 458453.83 | CS8: ='Revenue Build'!AJ65 -> 456704.14 | CT8: ='Revenue Build'!AK65 -> 461889.01 | CU8: =SUM(CQ8:CT8) -> 1801573.8 | CV8: =2095+2135 -> 4230 | CX8: =CF8+CF14 -> 1626173 | CY8: =CK8+CK14 -> 1806063 | DA8: Mkt | DB8: =DB7*DB6 -> 9073000
C9: Y/Y Growth | I9: =I8/D8-1 -> 0.38131847 | J9: =J8/E8-1 -> 0.21776417 | K9: =K8/F8-1 -> 0.12068966 | L9: =L8/G8-1 -> 0.29268293 | M9: =M8/H8-1 -> 0.15913201 | N9: =N8/I8-1 -> 0.19528315 | O9: =O8/J8-1 -> 0.32117706 | P9: =P8/K8-1 -> 0.39591346 | ... CU9: =CU8/CP8-1 -> 0.1359115 | CV9: =CV8/2 -> 2115 | CY9: =CY8/CX8-1 -> 0.11062169 | DA9: Net cash | DB9: =BS100 -> -1332692
C10: Q/Q Growth | F10: =F8/E8-1 -> 0.13690658 | G10: =G8/F8-1 -> -0.050107759 | H10: =H8/G8-1 -> 0.097844583 | J10: =J8/H8-1 -> 0.027124774 | K10: =K8/J8-1 -> 0.046277666 | L10: =L8/K8-1 -> 0.095673077 | M10: =M8/L8-1 -> -0.015577007 | O10: =O8/M8-1 -> 0.1707154 | P10: =P8/O8-1 -> 0.10546354 | Q10: =Q8/P8-1 -> 0.036679869 | R10: =R8/Q8-1 -> 0.032890365 | T10: =T8/R8-1 -> 0.11997427 | U10: =U8/T8-1 -> 0.044945434 | V10: =V8/U8-1 -> 0.097842518 | W10: =W8/V8-1 -> 0.11778696 | Y10: =Y8/W8-1 -> 0.1162374 | Z10: =Z8/Y8-1 -> 0.058687801 | AA10: =AA8/Z8-1 -> 0.074102151 | AB10: =AB8/AA8-1 -> 0.12589325 | AD10: =AD8/AB8-1 -> 0.055712271 | AE10: =AE8/AD8-1 -> 0.028946782 | AF10: =AF8/AE8-1 -> 0.097453654 | AG10: =AG8/AF8-1 -> 0.26948863 | AI10: =AI8/AG8-1 -> 0.061768665 | AJ10: =AJ8/AI8-1 -> 0.020822158 | AK10: =AK8/AJ8-1 -> 0.084073756 | AL10: =AL8/AK8-1 -> 0.044901736 | AN10: =AN8/AL8-1 -> 0.066419264 | AO10: =AO8/AN8-1 -> 0.065683328 | AP10: =AP8/AO8-1 -> 0.077442577 | AQ10: =AQ8/AP8-1 -> 0.055930569 | AS10: =AS8/AQ8-1 -> 0.11183953 | AT10: =AT8/AS8-1 -> -0.0035495321 | AU10: =AU8/AT8-1 -> 0.08540391 | AV10: =AV8/AU8-1 -> 0.024654859 | AX10: =AX8/AV8-1 -> 0.061517285 | AY10: =AY8/AX8-1 -> 0.021071268 | AZ10: =AZ8/AY8-1 -> 0.09507412 | BA10: =BA8/AZ8-1 -> 0.062020517 | BC10: =BC8/BA8-1 -> 0.029545789 | BD10: =BD8/BC8-1 -> 0.1150975 | BE10: =BE8/BD8-1 -> 0.10113223 | BF10: =BF8/BE8-1 -> 0.011013289 | BH10: =BH8/BF8-1 -> 0.10535136 | BI10: =BI8/BH8-1 -> 0.092159049 | BJ10: =BJ8/BI8-1 -> 0.024457298 | BK10: =BK8/BJ8-1 -> 0.067196301 | BM10: =BM8/BK8-1 -> 0.017340969 | BN10: =BN8/BM8-1 -> 0.04790573 | BO10: =BO8/BN8-1 -> 0.04264462 | BP10: =BP8/BO8-1 -> 0.05271587 | BR10: =BR8/BP8-1 -> 0.090236922 | BS10: =BS8/BR8-1 -> 0.95987471 | BT10: =BT8/BS8-1 -> 0.26312199 | BU10: =BU8/BT8-1 -> -0.093017939 | BW10: =BW8/BV8-1 -> -0.68817311 | BX10: =BX8/BW8-1 -> 0.042262358 | BY10: =BY8/BX8-1 -> -0.0057463177 | BZ10: =BZ8/BY8-1 -> 0.0092511775 | CB10: =CB8/BZ8-1 -> 0.092583142 | CC10: =CC8/CB8-1 -> 0.061768848 | CD10: =CD8/CC8-1 -> -0.0087276562 | CE10: =CE8/CD8-1 -> -0.030902131 | CG10: =CG8/CE8-1 -> 0.094994896 | CH10: =CH8/CG8-1 -> 0.065249662 | CI10: =CI8/CH8-1 -> 0.040421719 | CJ10: =CJ8/CI8-1 -> 0.0047988017 | CL10: =CL8/CJ8-1 -> 0.074972193 | CM10: =CM8/CL8-1 -> 0.080231687 | CN10: =CN8/CM8-1 -> -0.0098278097 | CO10: =CO8/CN8-1 -> 0.0093844186 | CQ10: =CQ8/CO8-1 -> 0.048582057 | CR10: =CR8/CQ8-1 -> 0.079917109 | CS10: =CS8/CR8-1 -> -0.0038165021 | CT10: =CT8/CS8-1 -> 0.011352797 | CX10: =2500+2550 -> 5050 | DA10: EV | DB10: =DB8-DB9 -> 10405692
B11: Software Services Revenue | D11: 60283 | E11: 16525 | F11: 19848 | G11: 18600 | H11: =I11-G11-F11-E11 -> 20024 | I11: 74997 | J11: 19232 | K11: 21330 | L11: 20383 | M11: =N11-L11-K11-J11 -> 19460 | N11: 80405 | O11: 17056 | P11: 18506 | Q11: 16718 | R11: 16060 | S11: =SUM(O11:R11) -> 68340 | T11: 16764 | U11: 17992 | V11: 17644 | W11: 17217 | X11: =SUM(T11:W11) -> 69617 | Y11: 18530 | Z11: 21737 | AA11: 22099 | AB11: 21042 | AC11: =SUM(Y11:AB11) -> 83408 | AD11: 20461 | AE11: 24085 | AF11: 24860 | AG11: 23861 | AH11: =SUM(AD11:AG11) -> 93267 | AI11: 24307 | AJ11: 30128 | AK11: 31159 | AL11: 28227 | AM11: =SUM(AI11:AL11) -> 113821 | AN11: 30804 | AO11: 34563 | AP11: 36398 | AQ11: 38087 | AR11: =SUM(AN11:AQ11) -> 139852 | AS11: 42430 | AT11: 46040 | AU11: 44738 | AV11: 41595 | AW11: =SUM(AS11:AV11) -> 174803 | AX11: 45018 | AY11: 47372 | AZ11: 47479 | BA11: 47280 | BB11: =SUM(AX11:BA11) -> 187149 | BC11: 45939 | BD11: 50674 | BE11: 48199 | BF11: 46457 | BG11: =SUM(BC11:BF11) -> 191269 | BH11: 48443 | BI11: 57401 | BJ11: =54997 -> 54997 | BK11: =52220 -> 52220 | BL11: =SUM(BH11:BK11) -> 213061 | BM11: 52133 | BN11: =43654 -> 43654 | BO11: 47946 | BP11: 42676 | BQ11: =SUM(BM11:BP11) -> 186409 | BR11: 47640 | BS11: =53337 -> 53337 | BT11: 54624 | BU11: 53790 | BV11: =SUM(BR11:BU11) -> 209391 | BW11: 61497 | BX11: 63125 | BY11: 63180 | BZ11: 55315 | CA11: =SUM(BW11:BZ11) -> 243117 | CB11: 60929 | CC11: 66420 | CD11: 61126 | CE11: 61501 | CF11: =SUM(CB11:CE11) -> 249976 | CG11: 64806 | CH11: 71928 | CI11: 64462 | CJ11: =62795 -> 62795 | CK11: =SUM(CG11:CJ11) -> 263991 | CL11: 64050 | CM11: 58612 | CN11: 64728 | CO11: ='Revenue Build'!AF67 -> 64000 | CP11: =SUM(CL11:CO11) -> 251390 | CQ11: ='Revenue Build'!AH67 -> 66000 | CR11: ='Revenue Build'!AI67 -> 66000 | CS11: ='Revenue Build'!AJ67 -> 65500 | CT11: ='Revenue Build'!AK67 -> 64000 | CU11: =SUM(CQ11:CT11) -> 261500 | CX11: =CX10/2 -> 2525 | DA11: NY Rev | DB11: =BL23 -> 1091356
C12: Y/Y Growth | I12: =I11/D11-1 -> 0.24408208 | J12: =J11/E11-1 -> 0.16381241 | K12: =K11/F11-1 -> 0.074667473 | L12: =L11/G11-1 -> 0.095860215 | M12: =M11/H11-1 -> -0.028166201 | N12: =N11/I11-1 -> 0.072109551 | O12: =O11/J11-1 -> -0.11314476 | P12: =P11/K11-1 -> -0.13239569 | ... CU12: =CU11/CP11-1 -> 0.040216397 | CW12: =BL8/BL23 -> 0.27154476 | DA12: EV/REV | DB12: =DB10/DB11 -> 9.534645
C13: Q/Q Growth | F13: =F11/E11-1 -> 0.20108926 | G13: =G11/F11-1 -> -0.062877872 | H13: =H11/G11-1 -> 0.07655914 | J13: =J11/H11-1 -> -0.039552537 | K13: =K11/J11-1 -> 0.10908902 | L13: =L11/K11-1 -> -0.044397562 | M13: =M11/L11-1 -> -0.045282834 | O13: =O11/M11-1 -> -0.12353546 | P13: =P11/O11-1 -> 0.085014071 | Q13: =Q11/P11-1 -> -0.096617313 | R13: =R11/Q11-1 -> -0.039358775 | T13: =T11/R11-1 -> 0.043835616 | U13: =U11/T11-1 -> 0.073252207 | V13: =V11/U11-1 -> -0.01934193 | W13: =W11/V11-1 -> -0.024200861 | Y13: =Y11/W11-1 -> 0.076261834 | Z13: =Z11/Y11-1 -> 0.1730707 | AA13: =AA11/Z11-1 -> 0.016653632 | AB13: =AB11/AA11-1 -> -0.047830219 | AD13: =AD11/AB11-1 -> -0.027611444 | AE13: =AE11/AD11-1 -> 0.17711744 | AF13: =AF11/AE11-1 -> 0.032177704 | AG13: =AG11/AF11-1 -> -0.040185036 | AI13: =AI11/AG11-1 -> 0.018691589 | AJ13: =AJ11/AI11-1 -> 0.23947834 | AK13: =AK11/AJ11-1 -> 0.034220659 | AL13: =AL11/AK11-1 -> -0.094098013 | AN13: =AN11/AL11-1 -> 0.091295568 | AO13: =AO11/AN11-1 -> 0.12202961 | AP13: =AP11/AO11-1 -> 0.053091456 | AQ13: =AQ11/AP11-1 -> 0.046403649 | AS13: =AS11/AQ11-1 -> 0.11402841 | AT13: =AT11/AS11-1 -> 0.08508131 | AU13: =AU11/AT11-1 -> -0.028279757 | AV13: =AV11/AU11-1 -> -0.070253476 | AX13: =AX11/AV11-1 -> 0.082293545 | AY13: =AY11/AX11-1 -> 0.052290195 | AZ13: =AZ11/AY11-1 -> 0.0022587182 | BA13: =BA11/AZ11-1 -> -0.0041913267 | BC13: =BC11/BA11-1 -> -0.028362944 | BD13: =BD11/BC11-1 -> 0.10307146 | BE13: =BE11/BD11-1 -> -0.048841615 | BF13: =BF11/BE11-1 -> -0.036141829 | BH13: =BH11/BF11-1 -> 0.042749209 | BI13: =BI11/BH11-1 -> 0.18491836 | BJ13: =BJ11/BI11-1 -> -0.041880803 | BK13: =BK11/BJ11-1 -> -0.050493663 | BM13: =BM11/BK11-1 -> -0.0016660283 | BN13: =BN11/BM11-1 -> -0.1626417 | BO13: =BO11/BN11-1 -> 0.098318596 | BP13: =BP11/BO11-1 -> -0.10991532 | BR13: =BR11/BP11-1 -> 0.11631831 | BS13: =BS11/BR11-1 -> 0.11958438 | BT13: =BT11/BS11-1 -> 0.024129591 | BU13: =BU11/BT11-1 -> -0.015268014 | BW13: =BW11/BV11-1 -> -0.70630543 | BX13: =BX11/BW11-1 -> 0.026472836 | BY13: =BY11/BX11-1 -> 0.00087128713 | BZ13: =BZ11/BY11-1 -> -0.1244856 | CB13: =CB11/BZ11-1 -> 0.10149146 | CC13: =CC11/CB11-1 -> 0.090121289 | CD13: =CD11/CC11-1 -> -0.079704908 | CE13: =CE11/CD11-1 -> 0.006134869 | CG13: =CG11/CE11-1 -> 0.053738964 | CH13: =CH11/CG11-1 -> 0.10989723 | CI13: =CI11/CH11-1 -> -0.10379824 | CJ13: =CJ11/CI11-1 -> -0.025860197 | CL13: =CL11/CJ11-1 -> 0.019985668 | CM13: =CM11/CL11-1 -> -0.08490242 | CN13: =CN11/CM11-1 -> 0.10434723 | CO13: =CO11/CN11-1 -> -0.011247065 | CQ13: =CQ11/CO11-1 -> 0.03125 | CR13: =CR11/CQ11-1 -> 0 | CS13: =CS11/CR11-1 -> -0.0075757576 | CT13: =CT11/CS11-1 -> -0.022900763 | CW13: =BL14/BL23 -> 0.39881304
B14: Maintenance Revenue | D14: 85411 | E14: 24849 | F14: 25900 | G14: 28353 | H14: =I14-G14-F14-E14 -> 28356 | I14: 107458 | J14: 29138 | K14: 30224 | L14: 32744 | M14: =N14-L14-K14-J14 -> 32406 | N14: 124512 | O14: 33416 | P14: 33212 | Q14: 34729 | R14: 34298 | S14: =SUM(O14:R14) -> 135655 | T14: 35512 | U14: 35056 | V14: 37011 | W14: 38919 | X14: =SUM(T14:W14) -> 146498 | Y14: 39850 | Z14: 42060 | AA14: 44452 | AB14: 45489 | AC14: =SUM(Y14:AB14) -> 171851 | AD14: 46050 | AE14: 46639 | AF14: 49291 | AG14: 49740 | AH14: =SUM(AD14:AG14) -> 191720 | AI14: 50240 | AJ14: 51951 | AK14: 54713 | AL14: 55792 | AM14: =SUM(AI14:AL14) -> 212696 | AN14: 57348 | AO14: 59463 | AP14: 61018 | AQ14: =67708+3186+37 -> 70931 | AR14: =SUM(AN14:AQ14) -> 248760 | AS14: =76032+5584+111 -> 81727 | AT14: =78743+4666+111 -> 83520 | AU14: =83000+3149+111 -> 86260 | AV14: =85194+1664+111 -> 86969 | AW14: =SUM(AS14:AV14) -> 338476 | AX14: =86859+204+111 -> 87174 | AY14: =89412+184+111 -> 89707 | AZ14: =92285+151+111 -> 92547 | BA14: =93013+124+111 -> 93248 | BB14: =SUM(AX14:BA14) -> 362676 | BC14: =93897+100+111 -> 94108 | BD14: 96076 | BE14: 96215 | BF14: 98333 | BG14: =SUM(BC14:BF14) -> 384732 | BH14: =100152+1597+100 -> 101849 | BI14: =106689+2757+100 -> 109546 | BJ14: =109833+1698+89 -> 111620 | BK14: =113644-1495+83 -> 112232 | BL14: =SUM(BH14:BK14) -> 435247 | BM14: =114365+160+79 -> 114604 | BN14: =116760+160+78 -> 116998 | BO14: =117979+113+78 -> 118170 | BP14: =118409+45+78 -> 118532 | BQ14: =SUM(BM14:BP14) -> 468304 | BR14: 119112 | BS14: 119621 | BT14: 117833 | BU14: 117721 | BV14: =SUM(BR14:BU14) -> 474287 | BW14: 117029 | BX14: 116815 | BY14: 117338 | BZ14: 117273 | CA14: =SUM(BW14:BZ14) -> 468455 | CB14: 115130 | CC14: 116539 | CD14: 117484 | CE14: 117508 | CF14: =SUM(CB14:CE14) -> 466661 | CG14: 117218 | CH14: 115309 | CI14: 115587 | CJ14: 115018 | CK14: =SUM(CG14:CJ14) -> 463132 | CL14: 112801 | CM14: 112123 | CN14: 111312 | CO14: ='Revenue Build'!AF69 -> 109500 | CP14: =SUM(CL14:CO14) -> 445736 | CQ14: ='Revenue Build'!AH69 -> 107000 | CR14: ='Revenue Build'!AI69 -> 107000 | CS14: ='Revenue Build'!AJ69 -> 104000 | CT14: ='Revenue Build'!AK69 -> 101000 | CU14: =SUM(CQ14:CT14) -> 419000 | CV14: 900 | DA14: EV/Rev | DB14: 14.5
C15: Y/Y Growth | I15: =I14/D14-1 -> 0.25812834 | J15: =J14/E14-1 -> 0.17260252 | K15: =K14/F14-1 -> 0.16694981 | L15: =L14/G14-1 -> 0.15486897 | M15: =M14/H14-1 -> 0.14282691 | N15: =N14/I14-1 -> 0.15870387 | O15: =O14/J14-1 -> 0.14681859 | P15: =P14/K14-1 -> 0.098861832 | ... CU15: =CU14/CP14-1 -> -0.059981693 | DA15: EV | DB15: =DB14*1800000 -> 26100000
C16: Q/Q Growth | F16: =F14/E14-1 -> 0.042295465 | G16: =G14/F14-1 -> 0.094710425 | H16: =H14/G14-1 -> 0.00010580891 | J16: =J14/H14-1 -> 0.027577938 | K16: =K14/J14-1 -> 0.037270918 | L16: =L14/K14-1 -> 0.083377448 | M16: =M14/L14-1 -> -0.010322502 | O16: =O14/M14-1 -> 0.031167068 | P16: =P14/O14-1 -> -0.0061048599 | Q16: =Q14/P14-1 -> 0.045676262 | R16: =R14/Q14-1 -> -0.012410377 | T16: =T14/R14-1 -> 0.03539565 | U16: =U14/T14-1 -> -0.01284073 | V16: =V14/U14-1 -> 0.055767914 | W16: =W14/V14-1 -> 0.051552241 | Y16: =Y14/W14-1 -> 0.023921478 | Z16: =Z14/Y14-1 -> 0.055457967 | AA16: =AA14/Z14-1 -> 0.056871136 | AB16: =AB14/AA14-1 -> 0.023328534 | AD16: =AD14/AB14-1 -> 0.012332652 | AE16: =AE14/AD14-1 -> 0.012790445 | AF16: =AF14/AE14-1 -> 0.056862283 | AG16: =AG14/AF14-1 -> 0.009109168 | AI16: =AI14/AG14-1 -> 0.010052272 | AJ16: =AJ14/AI14-1 -> 0.034056529 | AK16: =AK14/AJ14-1 -> 0.053165483 | AL16: =AL14/AK14-1 -> 0.01972109 | AN16: =AN14/AL14-1 -> 0.027889303 | AO16: =AO14/AN14-1 -> 0.0368801 | AP16: =AP14/AO14-1 -> 0.026150716 | AQ16: =AQ14/AP14-1 -> 0.16246026 | AS16: =AS14/AQ14-1 -> 0.15220425 | AT16: =AT14/AS14-1 -> 0.021938894 | AU16: =AU14/AT14-1 -> 0.032806513 | AV16: =AV14/AU14-1 -> 0.0082193369 | AX16: =AX14/AV14-1 -> 0.0023571617 | AY16: =AY14/AX14-1 -> 0.029056829 | AZ16: =AZ14/AY14-1 -> 0.031658622 | BA16: =BA14/AZ14-1 -> 0.0075745297 | BC16: =BC14/BA14-1 -> 0.0092227179 | BD16: =BD14/BC14-1 -> 0.020912143 | BE16: =BE14/BD14-1 -> 0.0014467713 | BF16: =BF14/BE14-1 -> 0.0220132 | BH16: =BH14/BF14-1 -> 0.035756053 | BI16: =BI14/BH14-1 -> 0.075572661 | BJ16: =BJ14/BI14-1 -> 0.018932686 | BK16: =BK14/BJ14-1 -> 0.0054828884 | BM16: =BM14/BK14-1 -> 0.021134792 | BN16: =BN14/BM14-1 -> 0.020889323 | BO16: =BO14/BN14-1 -> 0.010017265 | BP16: =BP14/BO14-1 -> 0.0030633833 | BR16: =BR14/BP14-1 -> 0.0048931934 | BS16: =BS14/BR14-1 -> 0.004273289 | BT16: =BT14/BS14-1 -> -0.014947208 | BU16: =BU14/BT14-1 -> -0.00095049774 | BW16: =BW14/BV14-1 -> -0.75325278 | BX16: =BX14/BW14-1 -> -0.0018286066 | BY16: =BY14/BX14-1 -> 0.0044771647 | BZ16: =BZ14/BY14-1 -> -0.00055395524 | CB16: =CB14/BZ14-1 -> -0.018273601 | CC16: =CC14/CB14-1 -> 0.012238339 | CD16: =CD14/CC14-1 -> 0.0081088734 | CE16: =CE14/CD14-1 -> 0.00020428314 | CG16: =CG14/CE14-1 -> -0.0024679171 | CH16: =CH14/CG14-1 -> -0.016285895 | CI16: =CI14/CH14-1 -> 0.0024109133 | CJ16: =CJ14/CI14-1 -> -0.0049226989 | CL16: =CL14/CJ14-1 -> -0.019275244 | CM16: =CM14/CL14-1 -> -0.006010585 | CN16: =CN14/CM14-1 -> -0.0072331279 | CO16: =CO14/CN14-1 -> -0.016278568 | CQ16: =CQ14/CO14-1 -> -0.02283105 | CR16: =CR14/CQ14-1 -> 0 | CS16: =CS14/CR14-1 -> -0.028037383 | CT16: =CT14/CS14-1 -> -0.028846154 | CX16: =0.22*CA23 -> 407044.88 | DA16: Net Cash | DB16: =DB9 -> -1332692
B17: Appraisal Service Revenue | D17: 21318 | E17: 4582 | F17: 4378 | G17: 5289 | H17: =I17-G17-F17-E17 -> 4849 | I17: 19098 | J17: 4892 | K17: 5054 | L17: 4692 | M17: =N17-L17-K17-J17 -> 4102 | N17: 18740 | O17: 4275 | P17: 4925 | Q17: 5612 | R17: 5742 | S17: =SUM(O17:R17) -> 20554 | T17: 6197 | U17: 5987 | V17: 5761 | W17: 5283 | X17: =SUM(T17:W17) -> 23228 | Y17: 5682 | Z17: 5771 | AA17: 5594 | AB17: 5496 | AC17: =SUM(Y17:AB17) -> 22543 | AD17: 5591 | AE17: 5056 | AF17: 5207 | AG17: 4971 | AH17: =SUM(AD17:AG17) -> 20825 | AI17: 4851 | AJ17: 5444 | AK17: 5802 | AL17: 5705 | AM17: =SUM(AI17:AL17) -> 21802 | AN17: 6089 | AO17: 6691 | AP17: 6557 | AQ17: 5728 | AR17: =SUM(AN17:AQ17) -> 25065 | AS17: 6558 | AT17: 6984 | AU17: 6541 | AV17: 6204 | AW17: =SUM(AS17:AV17) -> 26287 | AX17: 6612 | AY17: 6366 | AZ17: 6290 | BA17: 5755 | BB17: =SUM(AX17:BA17) -> 25023 | BC17: 5394 | BD17: 5532 | BE17: 5544 | BF17: 5376 | BG17: =SUM(BC17:BF17) -> 21846 | BH17: 5214 | BI17: 6233 | BJ17: =6008 -> 6008 | BK17: =6024 -> 6024 | BL17: =SUM(BH17:BK17) -> 23479 | BM17: 5763 | BN17: =4696 -> 4696 | BO17: 5394 | BP17: 5274 | BQ17: =SUM(BM17:BP17) -> 21127 | BR17: 6465 | BS17: 6265 | BT17: 7146 | BU17: 7912 | BV17: =SUM(BR17:BU17) -> 27788 | BW17: 8518 | BX17: 8812 | BY17: 8638 | BZ17: 8540 | CA17: =SUM(BW17:BZ17) -> 34508 | CW17: 1952 | CX17: =CW17*1.1 -> 2147.2 | CY17: =CX17*1.1 -> 2361.92 | DA17: Mkt | DB17: =DB16+DB15 -> 24767308
C18: Y/Y Growth | I18: =I17/D17-1 -> -0.10413735 | J18: =J17/E17-1 -> 0.067656045 | K18: =K17/F17-1 -> 0.15440841 | L18: =L17/G17-1 -> -0.11287578 | M18: =M17/H17-1 -> -0.15405238 | N18: =N17/I17-1 -> -0.018745418 | O18: =O17/J17-1 -> -0.12612428 | P18: =P17/K17-1 -> -0.025524337 | ... CA18: =CA17/BV17-1 -> 0.24183101 | DA18: Share | DB18: =DB7 -> 42200
C19: Q/Q Growth | F19: =F17/E17-1 -> -0.044522043 | G19: =G17/F17-1 -> 0.20808588 | H19: =H17/G17-1 -> -0.08319153 | J19: =J17/H17-1 -> 0.0088678078 | K19: =K17/J17-1 -> 0.03311529 | L19: =L17/K17-1 -> -0.071626435 | M19: =M17/L17-1 -> -0.12574595 | O19: =O17/M17-1 -> 0.042174549 | P19: =P17/O17-1 -> 0.15204678 | Q19: =Q17/P17-1 -> 0.13949239 | R19: =R17/Q17-1 -> 0.023164647 | T19: =T17/R17-1 -> 0.079240683 | U19: =U17/T17-1 -> -0.033887365 | V19: =V17/U17-1 -> -0.037748455 | W19: =W17/V17-1 -> -0.082971706 | Y19: =Y17/W17-1 -> 0.07552527 | Z19: =Z17/Y17-1 -> 0.015663499 | AA19: =AA17/Z17-1 -> -0.030670594 | AB19: =AB17/AA17-1 -> -0.01751877 | AD19: =AD17/AB17-1 -> 0.017285298 | AE19: =AE17/AD17-1 -> -0.095689501 | AF19: =AF17/AE17-1 -> 0.029865506 | AG19: =AG17/AF17-1 -> -0.045323603 | AI19: =AI17/AG17-1 -> -0.024140012 | AJ19: =AJ17/AI17-1 -> 0.12224284 | AK19: =AK17/AJ17-1 -> 0.06576047 | AL19: =AL17/AK17-1 -> -0.016718373 | AN19: =AN17/AL17-1 -> 0.067309378 | AO19: =AO17/AN17-1 -> 0.098866809 | AP19: =AP17/AO17-1 -> -0.020026902 | AQ19: =AQ17/AP17-1 -> -0.12642977 | AS19: =AS17/AQ17-1 -> 0.14490223 | AT19: =AT17/AS17-1 -> 0.064958829 | AU19: =AU17/AT17-1 -> -0.063430699 | AV19: =AV17/AU17-1 -> -0.051521174 | AX19: =AX17/AV17-1 -> 0.065764023 | AY19: =AY17/AX17-1 -> -0.037205082 | AZ19: =AZ17/AY17-1 -> -0.011938423 | BA19: =BA17/AZ17-1 -> -0.085055644 | BC19: =BC17/BA17-1 -> -0.062728063 | BD19: =BD17/BC17-1 -> 0.025583982 | BE19: =BE17/BD17-1 -> 0.0021691974 | BF19: =BF17/BE17-1 -> -0.03030303 | BH19: =BH17/BF17-1 -> -0.030133929 | BI19: =BI17/BH17-1 -> 0.19543537 | BJ19: =BJ17/BI17-1 -> -0.036098187 | BK19: =BK17/BJ17-1 -> 0.0026631158 | BM19: =BM17/BK17-1 -> -0.043326693 | BN19: =BN17/BM17-1 -> -0.18514663 | BO19: =BO17/BN17-1 -> 0.14863714 | BP19: =BP17/BO17-1 -> -0.022246941 | BR19: =BR17/BP17-1 -> 0.2258248 | BS19: =BS17/BR17-1 -> -0.030935808 | BT19: =BT17/BS17-1 -> 0.14062251 | BU19: =BU17/BT17-1 -> 0.10719284 | BW19: =BW17/BV17-1 -> -0.6934648 | BX19: =BX17/BW17-1 -> 0.034515144 | BY19: =BY17/BX17-1 -> -0.019745801 | BZ19: =BZ17/BY17-1 -> -0.011345219 | DA19: Price | DB19: =DB17/DB18 -> 586.90303
B20: Hardware & Other Revenue | D20: 7315 | E20: 1761 | F20: 1826 | G20: 1497 | H20: =I20-G20-F20-E20 -> 2600 | I20: 7684 | J20: 1571 | K20: 1492 | L20: 1788 | M20: =N20-L20-K20-J20 -> 2466 | N20: 7317 | O20: 1371 | P20: 1415 | Q20: 1430 | R20: 1652 | S20: =SUM(O20:R20) -> 5868 | T20: 1134 | U20: 2115 | V20: 1148 | W20: 1897 | X20: =SUM(T20:W20) -> 6294 | Y20: =1251-121 -> 1130 | Z20: 2825 | AA20: 1392 | AB20: 1609 | AC20: =SUM(Y20:AB20) -> 6956 | AD20: 1394 | AE20: 3355 | AF20: 1954 | AG20: 1423 | AH20: =SUM(AD20:AG20) -> 8126 | AI20: 1489 | AJ20: 3831 | AK20: 1070 | AL20: 1479 | AM20: =SUM(AI20:AL20) -> 7869 | AN20: 1137 | AO20: 4043 | AP20: 2146 | AQ20: 2301 | AR20: =SUM(AN20:AQ20) -> 9627 | AS20: 3334 | AT20: 5686 | AU20: 3419 | AV20: 2535 | AW20: =SUM(AS20:AV20) -> 14974 | AX20: 2728 | AY20: 7919 | AZ20: 3410 | BA20: 3660 | BB20: =SUM(AX20:BA20) -> 17717 | BC20: 4140 | BD20: 8369 | BE20: 4966 | BF20: 6183 | BG20: =SUM(BC20:BF20) -> 23658 | BH20: 4189 | BI20: 10651 | BJ20: =3911 -> 3911 | BK20: =4261 -> 4261 | BL20: =SUM(BH20:BK20) -> 23012 | BM20: 3820 | BN20: =3318 -> 3318 | BO20: 5200 | BP20: 5464 | BQ20: =SUM(BM20:BP20) -> 17802 | BR20: 4173 | BS20: =7690 -> 7690 | BT20: 4655 | BU20: 5416 | BV20: =SUM(BR20:BU20) -> 21934 | BW20: 7115 | BX20: 9108 | BY20: 9420 | BZ20: 6771 | CA20: =SUM(BW20:BZ20) -> 32414 | CB20: 5199 | CC20: 13752 | CD20: 10330 | CE20: 8225 | CF20: =SUM(CB20:CE20) -> 37506 | CG20: 8358 | CH20: 14728 | CI20: 9930 | CJ20: 8376 | CK20: =SUM(CG20:CJ20) -> 41392 | CL20: 6331 | CM20: 16644 | CN20: 13645 | CO20: ='Revenue Build'!AF73 -> 6500 | CP20: =SUM(CL20:CO20) -> 43120 | CQ20: ='Revenue Build'!AH73 -> 8000 | CR20: ='Revenue Build'!AI73 -> 14500 | CS20: ='Revenue Build'!AJ73 -> 6800 | CT20: ='Revenue Build'!AK73 -> 6000 | CU20: =SUM(CQ20:CT20) -> 35300 | CV20: 38
C21: Y/Y Growth | F21: =F20/E20-1 -> 0.036910846 | G21: =G20/F20-1 -> -0.18017525 | H21: =H20/G20-1 -> 0.73680695 | I21: =I20/D20-1 -> 0.050444293 | J21: =J20/E20-1 -> -0.10789324 | K21: =K20/F20-1 -> -0.18291347 | L21: =L20/G20-1 -> 0.19438878 | M21: =M20/H20-1 -> -0.051538462 | N21: =N20/I20-1 -> -0.047761583 | O21: =O20/J20-1 -> -0.12730745 | P21: =P20/K20-1 -> -0.051608579 | ... CU21: =CU20/CP20-1 -> -0.18135436 | CX21: =CF23 -> 1951751 | CY21: =CF23*1.1^7 -> 3803410.5 | DA21: Upside | DB21: =DB19/DB6-1 -> 1.7297815
C22: Q/Q Growth | J22: =J20/H20-1 -> -0.39576923 | K22: =K20/J20-1 -> -0.050286442 | L22: =L20/K20-1 -> 0.19839142 | M22: =M20/L20-1 -> 0.37919463 | O22: =O20/M20-1 -> -0.44403893 | P22: =P20/O20-1 -> 0.032093363 | Q22: =Q20/P20-1 -> 0.010600707 | R22: =R20/Q20-1 -> 0.15524476 | T22: =T20/R20-1 -> -0.31355932 | U22: =U20/T20-1 -> 0.86507937 | V22: =V20/U20-1 -> -0.4572104 | W22: =W20/V20-1 -> 0.65243902 | Y22: =Y20/W20-1 -> -0.40432261 | Z22: =Z20/Y20-1 -> 1.5 | AA22: =AA20/Z20-1 -> -0.50725664 | AB22: =AB20/AA20-1 -> 0.1558908 | AD22: =AD20/AB20-1 -> -0.13362337 | AE22: =AE20/AD20-1 -> 1.4067432 | AF22: =AF20/AE20-1 -> -0.41758569 | AG22: =AG20/AF20-1 -> -0.27175026 | AI22: =AI20/AG20-1 -> 0.046380885 | AJ22: =AJ20/AI20-1 -> 1.5728677 | AK22: =AK20/AJ20-1 -> -0.72069956 | AL22: =AL20/AK20-1 -> 0.38224299 | AN22: =AN20/AL20-1 -> -0.23123732 | AO22: =AO20/AN20-1 -> 2.5558487 | AP22: =AP20/AO20-1 -> -0.46920604 | AQ22: =AQ20/AP20-1 -> 0.0722274 | AS22: =AS20/AQ20-1 -> 0.44893525 | AT22: =AT20/AS20-1 -> 0.70545891 | AU22: =AU20/AT20-1 -> -0.39869856 | AV22: =AV20/AU20-1 -> -0.25855513 | AX22: =AX20/AV20-1 -> 0.076134122 | AY22: =AY20/AX20-1 -> 1.9028592 | AZ22: =AZ20/AY20-1 -> -0.56939007 | BA22: =BA20/AZ20-1 -> 0.073313783 | BC22: =BC20/BA20-1 -> 0.13114754 | BD22: =BD20/BC20-1 -> 1.0214976 | BE22: =BE20/BD20-1 -> -0.40661967 | BF22: =BF20/BE20-1 -> 0.24506645 | BH22: =BH20/BF20-1 -> -0.32249717 | BI22: =BI20/BH20-1 -> 1.5426116 | BJ22: =BJ20/BI20-1 -> -0.63280443 | BK22: =BK20/BJ20-1 -> 0.089491179 | BM22: =BM20/BK20-1 -> -0.10349683 | BN22: =BN20/BM20-1 -> -0.13141361 | BO22: =BO20/BN20-1 -> 0.56720916 | BP22: =BP20/BO20-1 -> 0.050769231 | BR22: =BR20/BP20-1 -> -0.23627379 | BS22: =BS20/BR20-1 -> 0.84279895 | BT22: =BT20/BS20-1 -> -0.3946684 | BU22: =BU20/BT20-1 -> 0.16348013 | BW22: =BW20/BV20-1 -> -0.67561776 | BX22: =BX20/BW20-1 -> 0.28011244 | BY22: =BY20/BX20-1 -> 0.034255599 | BZ22: =BZ20/BY20-1 -> -0.28121019 | CB22: =CB20/BZ20-1 -> -0.23216659 | CC22: =CC20/CB20-1 -> 1.6451241 | CD22: =CD20/CC20-1 -> -0.24883653 | CE22: =CE20/CD20-1 -> -0.20377541 | CG22: =CG20/CE20-1 -> 0.016170213 | CH22: =CH20/CG20-1 -> 0.76214405 | CI22: =CI20/CH20-1 -> -0.32577404 | CJ22: =CJ20/CI20-1 -> -0.15649547 | CL22: =CL20/CJ20-1 -> -0.24414995 | CM22: =CM20/CL20-1 -> 1.6289686 | CN22: =CN20/CM20-1 -> -0.18018505 | CO22: =CO20/CN20-1 -> -0.52363503 | CQ22: =CQ20/CO20-1 -> 0.23076923 | CR22: =CR20/CQ20-1 -> 0.8125 | CS22: =CS20/CR20-1 -> -0.53103448 | CT22: =CT20/CS20-1 -> -0.11764706 | CX22: =CF54 -> 448071 | CY22: =CY21*0.35 -> 1331193.7
B23: Total Revenues | D23: =SUM(D5,D8,D11,D14,D17,D20) -> 219796 | E23: =SUM(E5,E8,E11,E14,E17,E20) -> 59351 | F23: =SUM(F5,F8,F11,F14,F17,F20) -> 67569 | G23: =SUM(G5,G8,G11,G14,G17,G20) -> 68637 | H23: =SUM(H5,H8,H11,H14,H17,H20) -> 69544 | I23: =SUM(I5,I8,I11,I14,I17,I20) -> 265101 | J23: =SUM(J5,J8,J11,J14,J17,J20) -> 69565 | K23: =SUM(K5,K8,K11,K14,K17,K20) -> 72172 | ... CU23: =SUM(CU5,CU8,CU11,CU14,CU17,CU20) -> 2531873.8 | CV23: =+BV23+460000 -> 2054965 | CW23: =+CV23*0.3 -> 616489.5 | CY23: =CY21*0.3 -> 1141023.2 | DC23: =450*1.15 -> 517.5
C24: Y/Y Growth | I24: =I23/D23-1 -> 0.20612295 | J24: =J23/E23-1 -> 0.17209483 | K24: =K23/F23-1 -> 0.068122956 | L24: =L23/G23-1 -> 0.082972741 | M24: =M23/H23-1 -> 0.067194869 | N24: =N23/I23-1 -> 0.095001528 | O24: =O23/J23-1 -> 0.0036656365 | P24: =P23/K23-1 -> 0.0059302777 | ... CU24: =CU23/CP23-1 -> 0.078623661 | CV24: =CF23*1.093 -> 2133263.8 | CY24: 45000
C25: Q/Q Growth | F25: =F23/E23-1 -> 0.13846439 | G25: =G23/F23-1 -> 0.015806065 | H25: =H23/G23-1 -> 0.013214447 | J25: =J23/H23-1 -> 0.0003019671 | K25: =K23/J23-1 -> 0.037475742 | L25: =L23/K23-1 -> 0.029928504 | M25: =M23/L23-1 -> -0.001547113 | O25: =O23/M23-1 -> -0.059245186 | P25: =P23/O23-1 -> 0.039816671 | Q25: =Q23/P23-1 -> 0.016101928 | R25: =R23/Q23-1 -> -0.018029253 | T25: =T23/R23-1 -> 0.013169701 | U25: =U23/T23-1 -> 0.045535678 | V25: =V23/U23-1 -> 0.0058513064 | W25: =W23/V23-1 -> 0.06341988 | Y25: =Y23/W23-1 -> 0.0078460995 | Z25: =Z23/Y23-1 -> 0.1045054 | AA25: =AA23/Z23-1 -> 0.027110148 | AB25: =AB23/AA23-1 -> 0.016228888 | AD25: =AD23/AB23-1 -> 0.0045193356 | AE25: =AE23/AD23-1 -> 0.076086389 | AF25: =AF23/AE23-1 -> 0.03815187 | AG25: =AG23/AF23-1 -> 0.034703469 | AI25: =AI23/AG23-1 -> 0.017076805 | AJ25: =AJ23/AI23-1 -> 0.1042832 | AK25: =AK23/AJ23-1 -> 0.034517693 | AL25: =AL23/AK23-1 -> -0.0095131505 | AN25: =AN23/AL23-1 -> 0.059055242 | AO25: =AO23/AN23-1 -> 0.083939659 | AP25: =AP23/AO23-1 -> 0.031101541 | AQ25: =AQ23/AP23-1 -> 0.074871557 | AS25: =AS23/AQ23-1 -> 0.1409223 | AT25: =AT23/AS23-1 -> 0.047359829 | AU25: =AU23/AT23-1 -> 0.020686558 | AV25: =AV23/AU23-1 -> -0.013658176 | AX25: =AX23/AV23-1 -> 0.024613444 | AY25: =AY23/AX23-1 -> 0.047839205 | AZ25: =AZ23/AY23-1 -> 0.023827942 | BA25: =BA23/AZ23-1 -> 0.017154211 | BC25: =BC23/BA23-1 -> 0.01512706 | BD25: =BD23/BC23-1 -> 0.073794521 | BE25: =BE23/BD23-1 -> -0.00064781552 | BF25: =BF23/BE23-1 -> 0.02300394 | BH25: =BH23/BF23-1 -> 0.023577045 | BI25: =BI23/BH23-1 -> 0.11745316 | BJ25: =BJ23/BI23-1 -> -0.0028563103 | BK25: =BK23/BJ23-1 -> 0.036935354 | BM25: =BM23/BK23-1 -> -0.037035748 | BN25: =BN23/BM23-1 -> -0.019694342 | BO25: =BO23/BN23-1 -> 0.053838698 | BP25: =BP23/BO23-1 -> -0.0088446056 | BR25: =BR23/BP23-1 -> 0.040203523 | BS25: =BS23/BR23-1 -> 0.37503477 | BT25: =BT23/BS23-1 -> 0.13632473 | BU25: =BU23/BT23-1 -> -0.057417764 | BW25: =BW23/BV23-1 -> -0.7140326 | BX25: =BX23/BW23-1 -> 0.02757461 | BY25: =BY23/BX23-1 -> 0.0096141332 | BZ25: =BZ23/BY23-1 -> -0.044318256 | CB25: =CB23/CA23-1 -> -0.74497245 | CC25: =CC23/CB23-1 -> 0.068720555 | CD25: =CD23/CC23-1 -> -0.019027166 | CE25: =CE23/CD23-1 -> -0.0277935 | CG25: =CG23/CF23-1 -> -0.73748752 | CH25: =CH23/CG23-1 -> 0.055853415 | CI25: =CI23/CH23-1 -> 0.0043643341 | CJ25: =CJ23/CI23-1 -> -0.0040600953 | CL25: =CL23/CK23-1 -> -0.7356328 | CM25: =CM23/CL23-1 -> 0.054766307 | CN25: =CN23/CM23-1 -> -0.00039925048 | CO25: =CO23/CN23-1 -> -0.0096008854 | CQ25: =CQ23/CP23-1 -> -0.74075664 | CR25: =CR23/CQ23-1 -> 0.066434141 | CS25: =CS23/CR23-1 -> -0.018413775 | CT25: =CT23/CS23-1 -> 0.0006041864 | CY25: =CY23/CY24 -> 25.35607
CW26: =BV23 -> 1594965 | CX26: 352 | CY26: =CY25*30 -> 760.68211
B27: Cost of Revenue | CW27: 313000 | CY27: =((CY26/CX26)^0.14)-1 -> 0.11391609
B28: Software Licenses | D28: 7953 | E28: 2203 | F28: 2564 | G28: 2071 | H28: =I28-G28-F28-E28 -> 2386 | I28: 9224 | J28: 1276 | K28: 1433 | L28: 1366 | M28: =N28-L28-K28-J28 -> 1365 | N28: 5440 | O28: 707 | P28: 852 | Q28: 912 | R28: 985 | S28: =SUM(O28:R28) -> 3456 | T28: =795 -> 795 | U28: =989 -> 989 | V28: =536 -> 536 | W28: =714 -> 714 | X28: =SUM(T28:W28) -> 3034 | Y28: 566 | Z28: 484 | AA28: 458 | AB28: 475 | AC28: =SUM(Y28:AB28) -> 1983 | AD28: 426 | AE28: 692 | AF28: 583 | AG28: 676 | AH28: =SUM(AD28:AG28) -> 2377 | AI28: 531 | AJ28: 343 | AK28: 565 | AL28: 461 | AM28: =SUM(AI28:AL28) -> 1900 | AN28: 553 | AO28: 483 | AP28: 147 | AQ28: 449 | AR28: =SUM(AN28:AQ28) -> 1632 | AS28: 638 | AT28: 666 | AU28: 623 | AV28: 1037 | AW28: =SUM(AS28:AV28) -> 2964 | AX28: 731 | AY28: 647 | AZ28: 826 | BA28: 1117 | BB28: =SUM(AX28:BA28) -> 3321 | BC28: 778 | BD28: 1204 | BE28: =957 -> 957 | BF28: =863 -> 863 | BG28: =SUM(BC28:BF28) -> 3802 | BH28: 818 | BI28: =891 -> 891 | BJ28: =971 -> 971 | BK28: =1258 -> 1258 | BL28: =SUM(BH28:BK28) -> 3938 | BM28: 740 | BN28: =1130 -> 1130 | BO28: =1177 -> 1177 | BP28: =292 -> 292 | BQ28: =SUM(BM28:BP28) -> 3339 | BR28: =1236 -> 1236 | BS28: 1368 | BT28: =1547 -> 1547 | BU28: =1726 -> 1726 | BV28: =SUM(BR28:BU28) -> 5877 | BW28: =2609 -> 2609 | BX28: =2869 -> 2869 | BY28: =3162 -> 3162 | BZ28: =1436 -> 1436 | CA28: =SUM(BW28:BZ28) -> 10076 | CB28: =2313 -> 2313 | CC28: 2432 | CD28: =3120 -> 3120 | CE28: =2956 -> 2956 | CF28: =SUM(CB28:CE28) -> 10821 | CG28: 1565 | CH28: 1560 | CI28: =1870 -> 1870 | CJ28: =1282 -> 1282 | CK28: =SUM(CG28:CJ28) -> 6277 | CL28: =1910 -> 1910 | CM28: =1839 -> 1839 | CN28: 1669 | CO28: 2588 | CP28: =SUM(CL28:CO28) -> 8006 | CQ28: =(1-CQ29)*CQ5 -> 1500 | CR28: =(1-CR29)*CR5 -> 1500 | CS28: =(1-CS29)*CS5 -> 2000 | CT28: =(1-CT29)*CT5 -> 2250 | CU28: =SUM(CQ28:CT28) -> 7250 | CW28: =CW27+CW26 -> 1907965
C29: Gross Margins | D29: =(D5-D28)/D5 -> 0.77317971 | E29: =(E5-E28)/E5 -> 0.73676664 | F29: =(F5-F28)/F5 -> 0.78462831 | G29: =(G5-G28)/G5 -> 0.81788604 | H29: =(H5-H28)/H5 -> 0.75761885 | I29: =(I5-I28)/I5 -> 0.77768137 | J29: =(J5-J28)/J5 -> 0.88136854 | K29: =(K5-K28)/K5 -> 0.85542776 | ... CP29: =(CP5-CP28)/CP5 -> 0.61979389 | CQ29: 0.5 | CR29: 0.5 | CS29: 0.5 | CT29: 0.5 | CU29: =(CU5-CU28)/CU5 -> 0.5 | CW29: =1537-1507 -> 30
B30: Acquired Software | D30: 2279 | E30: 436 | F30: 461 | G30: 472 | H30: =I30-G30-F30-E30 -> 430 | I30: 1799 | J30: 315 | K30: 358 | L30: 369 | M30: =N30-L30-K30-J30 -> 369 | N30: 1411 | O30: 398 | P30: 398 | Q30: 398 | R30: 398 | S30: =SUM(O30:R30) -> 1592 | T30: 0 | U30: 0 | V30: 0 | W30: 0 | X30: =SUM(T30:W30) -> 0 | Y30: 0 | Z30: 0 | AA30: 0 | AB30: 0 | AC30: =SUM(Y30:AB30) -> 0 | AD30: 0 | AE30: =523-523 -> 0 | AF30: 0 | AH30: =SUM(AD30:AG30) -> 0 | AJ30: 0 | AK30: 0 | AL30: 0 | AM30: =SUM(AI30:AL30) -> 0 | AO30: 0 | AP30: 0 | AR30: =SUM(AN30:AQ30) -> 0 | AS30: 0 | AT30: 0 | AU30: 0 | AV30: 0 | AW30: =SUM(AS30:AV30) -> 0 | AX30: 0 | AY30: 0 | AZ30: 0 | BA30: 0 | BB30: =SUM(AX30:BA30) -> 0 | BC30: 0 | BD30: 0 | BE30: 0 | BF30: 0 | BG30: =SUM(BC30:BF30) -> 0 | BH30: 0 | BI30: 0 | BJ30: 0 | BK30: 0 | BL30: =SUM(BH30:BK30) -> 0 | BM30: 0 | BN30: 0 | BO30: 0 | BP30: 0 | BQ30: =SUM(BM30:BP30) -> 0 | BS30: 0 | BU30: 0 | BV30: =SUM(BR30:BU30) -> 0 | BW30: 0 | BX30: 0 | BY30: 0 | BZ30: 0 | CA30: =SUM(BW30:BZ30) -> 0 | CB30: 0 | CC30: 0 | CD30: 0 | CE30: 0 | CF30: =SUM(CB30:CE30) -> 0 | CG30: 0 | CH30: 0 | CI30: 0 | CJ30: 0 | CK30: =SUM(CG30:CJ30) -> 0 | CL30: 0 | CM30: 0 | CN30: 0 | CO30: 0 | CP30: =SUM(CL30:CO30) -> 0 | CQ30: 0 | CR30: 0 | CS30: 0 | CT30: 0 | CU30: =SUM(CQ30:CT30) -> 0
C31: Gross Margins
B32: Software Services, Maintenance & Subsc. | D32: 104993 | E32: 30444 | F32: 31123 | G32: 31988 | H32: =I32-G32-F32-E32 -> 32692 | I32: 126247 | J32: 33087 | K32: 34174 | L32: 35259 | M32: =N32-L32-K32-J32 -> 34679 | N32: 137199 | O32: 34881 | P32: 34595 | Q32: 34708 | R32: 33901 | S32: =SUM(O32:R32) -> 138085 | T32: =35180-196 -> 34984 | U32: =35502-214 -> 35288 | V32: =35689-239 -> 35450 | W32: =37405-222 -> 37183 | X32: =SUM(T32:W32) -> 142905 | Y32: =39813-248 -> 39565 | Z32: =43118-257 -> 42861 | AA32: =43485-286 -> 43199 | AB32: =45168-293 -> 44875 | AC32: =SUM(Y32:AB32) -> 170500 | AD32: =46382-336 -> 46046 | AE32: =48833-343 -> 48490 | AF32: =51786-408 -> 51378 | AG32: =52616-422 -> 52194 | AH32: =SUM(AD32:AG32) -> 198108 | AI32: =54999-513 -> 54486 | AJ32: =58274-513 -> 57761 | AK32: =61428-569 -> 60859 | AL32: =61662-582 -> 61080 | AM32: =SUM(AI32:AL32) -> 234186 | AN32: =65377-701 -> 64676 | AO32: =69678-746 -> 68932 | AP32: =72764-902 -> 71862 | AQ32: =77521-1031 -> 76490 | AR32: =SUM(AN32:AQ32) -> 281960 | AS32: =85270-1317 -> 83953 | AT32: =86717-1571 -> 85146 | AU32: =88623-1779 -> 86844 | AV32: =88329-1881 -> 86448 | AW32: =SUM(AS32:AV32) -> 342391 | AX32: =93540-2097 -> 91443 | AY32: =96172-2253 -> 93919 | AZ32: =98036-2524 -> 95512 | BA32: =99886-2541 -> 97345 | BB32: =SUM(AX32:BA32) -> 378219 | BC32: =106085-2776 -> 103309 | BD32: =109487-2955 -> 106532 | BE32: =111508-3909 -> 107599 | BF32: =111843-3948 -> 107895 | BG32: =SUM(BC32:BF32) -> 425335 | BH32: =117160-3798 -> 113362 | BI32: =125759-3756 -> 122003 | BJ32: =128545-3612 -> 124933 | BK32: =130674-3836 -> 126838 | BL32: =SUM(BH32:BK32) -> 487136 | BM32: =131779-4252 -> 127527 | BN32: =124287-4369 -> 119918 | BO32: =125881-4555 -> 121326 | BP32: =128557-4949 -> 123608 | BQ32: =SUM(BM32:BP32) -> 492379 | BR32: =134320-5000 -> 129320 | BS32: =199771-5909 -> 193862 | BT32: =241944-6303 -> 235641 | BU32: =223123-6493 -> 216630 | BV32: =SUM(BR32:BU32) -> 775453 | BW32: =236896-6772 -> 230124 | BX32: =244192-6867 -> 237325 | BY32: =239928-7181 -> 232747 | BZ32: =232880-6667+2514 -> 228727 | CA32: =SUM(BW32:BZ32) -> 928923 | CB32: =252415-6342+2588 -> 248661 | CC32: =255789-6437+2896 -> 252248 | CD32: =247781-6847+3083 -> 244017 | CE32: =245236-6981+4058 -> 242313 | CF32: =SUM(CB32:CE32) -> 987239 | CG32: =268870+4363-7390 -> 265843 | CH32: =277145+4484-7620 -> 274009 | CI32: =283750+4961-7972 -> 280739 | CJ32: =283013+4998-8340 -> 279671 | CK32: =SUM(CG32:CJ32) -> 1100262 | CL32: =278053+5379-8714 -> 274718 | CM32: =292595+5505-8891 -> 289209 | CN32: =289070+6195-9307 -> 285958 | CO32: =289171+5584-9217 -> 285538 | CP32: =SUM(CL32:CO32) -> 1135423 | CQ32: =(1-CQ33)*(CQ8+CQ11+CQ14) -> 286812.9 | CR32: =(1-CR33)*(CR8+CR11+CR14) -> 306255.11 | CS32: =(1-CS33)*(CS8+CS11+CS14) -> 300577.99 | CT32: =(1-CT33)*(CT8+CT11+CT14) -> 297772.28 | CU32: =SUM(CQ32:CT32) -> 1191418.3 | CW32: =1510+15 -> 1525
C33: Gross Margins | D33: =(D11+D14+D8-D32)/(D11+D14+D8) -> 0.3273991 | E33: =(E11+E14+E8-E32)/(E11+E14+E8) -> 0.31799547 | F33: =(F11+F14+F8-F32)/(F11+F14+F8) -> 0.37074404 | G33: =(G11+G14+G8-G32)/(G11+G14+G8) -> 0.36631074 | H33: =(H11+H14+H8-H32)/(H11+H14+H8) -> 0.37432776 | I33: =(I11+I14+I8-I32)/(I11+I14+I8) -> 0.35859553 | J33: =(J11+J14+J8-J32)/(J11+J14+J8) -> 0.36791732 | K33: =(K11+K14+K8-K32)/(K11+K14+K8) -> 0.38661737 | ... CP33: =(CP11+CP14+CP8-CP32)/(CP11+CP14+CP8) -> 0.50269279 | CQ33: 0.52 | CR33: 0.515 | CS33: 0.52 | CT33: 0.525 | CU33: =(CU11+CU14+CU8-CU32)/(CU11+CU14+CU8) -> 0.5199908 | CW33: =1540-1510 -> 30
B34: Appraisal Services | D34: 14467 | E34: 3167 | F34: 3004 | G34: 3098 | H34: =I34-G34-F34-E34 -> 2982 | I34: 12251 | J34: 3363 | K34: 2997 | L34: 2851 | M34: =N34-L34-K34-J34 -> 2307 | N34: 11518 | O34: 2877 | P34: 3131 | Q34: 3434 | R34: 3468 | S34: =SUM(O34:R34) -> 12910 | T34: 3824 | U34: 3702 | V34: 3776 | W34: 3248 | X34: =SUM(T34:W34) -> 14550 | Y34: 3796 | Z34: 3876 | AA34: 3598 | AB34: 3619 | AC34: =SUM(Y34:AB34) -> 14889 | AD34: 3799 | AE34: 3418 | AF34: 3360 | AG34: 3232 | AH34: =SUM(AD34:AG34) -> 13809 | AI34: 3311 | AJ34: 3665 | AK34: 3764 | AL34: 3544 | AM34: =SUM(AI34:AL34) -> 14284 | AN34: 4135 | AO34: 4278 | AP34: 3984 | AQ34: 3525 | AR34: =SUM(AN34:AQ34) -> 15922 | AS34: 3962 | AT34: 4458 | AU34: 4053 | AV34: 3938 | AW34: =SUM(AS34:AV34) -> 16411 | AX34: 4197 | AY34: 4282 | AZ34: 4089 | BA34: 3718 | BB34: =SUM(AX34:BA34) -> 16286 | BC34: 3781 | BD34: 3568 | BE34: =3505 -> 3505 | BF34: =3445 -> 3445 | BG34: =SUM(BC34:BF34) -> 14299 | BH34: 3452 | BI34: =3758 -> 3758 | BJ34: =4096 -> 4096 | BK34: =4031 -> 4031 | BL34: =SUM(BH34:BK34) -> 15337 | BM34: 4385 | BN34: =3976 -> 3976 | BO34: =3434 -> 3434 | BP34: =4150 -> 4150 | BQ34: =SUM(BM34:BP34) -> 15945 | BR34: =4617 -> 4617 | BS34: 4429 | BT34: =4506 -> 4506 | BU34: =5509 -> 5509 | BV34: =SUM(BR34:BU34) -> 19061 | BW34: =5936 -> 5936 | BX34: =5976 -> 5976 | BY34: 5783 | BZ34: =6293 -> 6293 | CA34: =SUM(BW34:BZ34) -> 23988 | CW34: =1510+15 -> 1525 | CY34: =2335+2360 -> 4695
C35: Gross Margins | D35: =(D17-D34)/D17 -> 0.32137161 | E35: =(E17-E34)/E17 -> 0.30881711 | F35: =(F17-F34)/F17 -> 0.31384194 | G35: =(G17-G34)/G17 -> 0.414256 | H35: =(H17-H34)/H17 -> 0.38502784 | I35: =(I17-I34)/I17 -> 0.35851922 | J35: =(J17-J34)/J17 -> 0.3125511 | K35: =(K17-K34)/K17 -> 0.40700435 | ... CA35: =(CA17-CA34)/CA17 -> 0.30485684 | CY35: =CY34/2 -> 2347.5
B36: Hardware and Other | D36: 5679 | E36: 1298 | F36: 1328 | G36: 1058 | H36: =I36-G36-F36-E36 -> 2109 | I36: 5793 | J36: 1232 | K36: 1213 | L36: 1252 | M36: =N36-L36-K36-J36 -> 2258 | N36: 5955 | O36: 938 | P36: 1149 | Q36: 1110 | R36: 1071 | S36: =SUM(O36:R36) -> 4268 | T36: 676 | U36: 2161 | V36: 808 | W36: 1349 | X36: =SUM(T36:W36) -> 4994 | Y36: 719 | Z36: 2709 | AA36: 882 | AB36: 948 | AC36: =SUM(Y36:AB36) -> 5258 | AD36: 798 | AE36: 2580 | AF36: 1230 | AG36: 951 | AH36: =SUM(AD36:AG36) -> 5559 | AI36: 774 | AJ36: 3087 | AK36: 667 | AL36: 797 | AM36: =SUM(AI36:AL36) -> 5325 | AN36: 566 | AO36: 3147 | AP36: 1565 | AQ36: 1223 | AR36: =SUM(AN36:AQ36) -> 6501 | AS36: 1846 | AT36: 4515 | AU36: 2120 | AV36: 1662 | AW36: =SUM(AS36:AV36) -> 10143 | AX36: 1316 | AY36: 6799 | AZ36: 2293 | BA36: 2187 | BB36: =SUM(AX36:BA36) -> 12595 | BC36: 2343 | BD36: 6801 | BE36: =2574 -> 2574 | BF36: =3990 -> 3990 | BG36: =SUM(BC36:BF36) -> 15708 | BH36: 2906 | BI36: =8868 -> 8868 | BJ36: =3096 -> 3096 | BK36: =2602 -> 2602 | BL36: =SUM(BH36:BK36) -> 17472 | BM36: 2479 | BN36: =2489 -> 2489 | BO36: =3780 -> 3780 | BP36: =3653 -> 3653 | BQ36: =SUM(BM36:BP36) -> 12401 | BR36: =2458 -> 2458 | BS36: 4623 | BT36: =2764 -> 2764 | BU36: =3101 -> 3101 | BV36: =SUM(BR36:BU36) -> 12946 | BW36: =5028 -> 5028 | BX36: =8161 -> 8161 | BY36: =6033 -> 6033 | BZ36: =4453 -> 4453 | CA36: =SUM(BW36:BZ36) -> 23675 | CB36: =5780 -> 5780 | CC36: 11061 | CD36: =6505 -> 6505 | CE36: =6577 -> 6577 | CF36: =SUM(CB36:CE36) -> 29923 | CG36: 4656 | CH36: 10731 | CI36: 6052 | CJ36: =5778 -> 5778 | CK36: =SUM(CG36:CJ36) -> 27217 | CL36: =3448 -> 3448 | CM36: =13675 -> 13675 | CN36: =8117 -> 8117 | CO36: =6407 -> 6407 | CP36: =SUM(CL36:CO36) -> 31647 | CQ36: =(1-CQ37)*CQ20 -> 6000 | CR36: =(1-CR37)*CR20 -> 10875 | CS36: =(1-CS37)*CS20 -> 5100 | CT36: =(1-CT37)*CT20 -> 4500 | CU36: =SUM(CQ36:CT36) -> 26475
C37: Gross Margins | D37: =(D20-D36)/D20 -> 0.22365003 | E37: =(E20-E36)/E20 -> 0.2629188 | F37: =(F20-F36)/F20 -> 0.27272727 | G37: =(G20-G36)/G20 -> 0.29325317 | H37: =(H20-H36)/H20 -> 0.18884615 | I37: =(I20-I36)/I20 -> 0.24609578 | J37: =(J20-J36)/J20 -> 0.21578612 | K37: =(K20-K36)/K20 -> 0.18699732 | ... CP37: =(CP20-CP36)/CP20 -> 0.26607143 | CQ37: 0.25 | CR37: 0.25 | CS37: 0.25 | CT37: 0.25 | CU37: =(CU20-CU36)/CU20 -> 0.25 | CX37: =0.05*157 -> 7.85
B38: Total Cost of Revenues | D38: =SUM(D28,D30,D32,D34,D36) -> 135371 | E38: =SUM(E28,E30,E32,E34,E36) -> 37548 | F38: =SUM(F28,F30,F32,F34,F36) -> 38480 | G38: =SUM(G28,G30,G32,G34,G36) -> 38687 | H38: =SUM(H28,H30,H32,H34,H36) -> 40599 | I38: =SUM(I28,I30,I32,I34,I36) -> 155314 | J38: =SUM(J28,J30,J32,J34,J36) -> 39273 | K38: =SUM(K28,K30,K32,K34,K36) -> 40175 | ... CU38: =SUM(CU28,CU30,CU32,CU34,CU36) -> 1225143.3
B40: Gross Profit | D40: =D23-D38 -> 84425 | E40: =E23-E38 -> 21803 | F40: =F23-F38 -> 29089 | G40: =G23-G38 -> 29950 | H40: =H23-H38 -> 28945 | I40: =I23-I38 -> 109787 | J40: =J23-J38 -> 30292 | K40: =K23-K38 -> 31997 | ... CU40: =CU23-CU38 -> 1306730.6 | CV40: less than 50 bps, more improvement at OM line
C41: Gross Margin | D41: =D40/D23 -> 0.38410617 | E41: =E40/E23 -> 0.36735691 | F41: =F40/F23 -> 0.43050807 | G41: =G40/G23 -> 0.43635357 | H41: =H40/H23 -> 0.41621132 | I41: =I40/I23 -> 0.41413273 | J41: =J40/J23 -> 0.43544886 | K41: =K40/K23 -> 0.44334368 | ... CU41: =CU40/CU23 -> 0.51611204
B43: Operating Expenses | CV43: G&A up LSD
...

Sheet Balance Sheet
B2: ='Income Statement'!B2 -> Tyler Technologies (TYL)
B4: Balance Sheet | D4: 2007 | E4: 1Q08 | F4: 2Q08 | G4: 3Q08 | H4: 4Q08 | I4: 2008 | J4: 1Q09 | K4: 2Q09 | L4: 3Q09 | M4: 4Q09 | N4: 2009 | O4: 1Q10 | P4: 2Q10 | Q4: 3Q10 | R4: 4Q10 | S4: 2010 | T4: 1Q11 | U4: 2Q11 | V4: 3Q11 | W4: 4Q11 | X4: 2011 | Y4: 1Q12 | Z4: 2Q12 | AA4: 3Q12 | AB4: 4Q12 | AC4: 2012 | AD4: 1Q13 | AE4: 2Q13 | AF4: 3Q13 | AG4: 4Q13 | AH4: 2013 | AI4: 1Q14 | AJ4: 2Q14 | AK4: 3Q14 | AL4: 4Q14 | AM4: 2014 | AN4: 1Q15 | AO4: 2Q15 | AP4: 3Q15 | AQ4: 4Q15 | AR4: 2015 | AS4: 1Q16 | AT4: 2Q16 | AU4: 3Q16 | AV4: 4Q16 | AW4: 2016 | AX4: 1Q17 | AY4: 2Q17 | AZ4: 3Q17 | BA4: 4Q17 | BB4: 2017 | BC4: 1Q18 | BD4: 2Q18 | BE4: 3Q18 | BF4: 4Q18 | BG4: 2018 | BH4: 1Q19 | BI4: 2Q19 | BJ4: 3Q19 | BK4: 4Q19 | BL4: 2019 | BM4: 1Q20 | BN4: 2Q20 | BO4: 3Q20 | BP4: 4Q20 | BQ4: 2020 | BR4: 1Q21 | BS4: 2Q21 | BT4: 3Q21 | BU4: 4Q21 | BV4: 2021 | BW4: 1Q22 | BX4: 2Q22 | BY4: 3Q22 | BZ4: 4Q22 | CA4: 2022 | CB4: ='Income Statement'!CB4 -> 1Q23 | CC4: ='Income Statement'!CC4 -> 2Q23 | CD4: ='Income Statement'!CD4 -> 3Q23 | CE4: ='Income Statement'!CE4 -> 4Q23 | CF4: ='Income Statement'!CF4 -> 2023 | CG4: ='Income Statement'!CG4 -> 1Q24 | CH4: ='Income Statement'!CH4 -> 2Q24 | CI4: ='Income Statement'!CI4 -> 3Q24 | ... CU4: ='Income Statement'!CU4 -> 2026E
B5: Assets:
