Workbook
Name \P: #REF!
Name \P: #REF!
Name \P: #REF!
Name \P: #REF!
Name \Q: [1]TSFW!#REF!
Name \Q: [1]TSFW!#REF!
Name \Q: [1]TSFW!#REF!
Name \Q: [1]TSFW!#REF!
Name \S: '[2]US$'!#REF!
Name \S: '[2]US$'!#REF!
Name \X: [1]TSFW!#REF!
Name \X: [1]TSFW!#REF!
Name _1997: #REF!
Name _1997: #REF!
Name _1997: #REF!
Name _1997: #REF!
Name _1998: #REF!
Name _1998: #REF!
Name _1998: #REF!
Name _1999: #REF!
Name _1999: #REF!
Name _1999: #REF!
Name _1st_year: '[3]LINKS&INPUTS'!$D$52
Name _2000: #REF!
Name _2000: #REF!
Name _2000: #REF!
Name _2000: #REF!
Name _2000_EPS: #REF!
Name _2000_EPS: #REF!
Name _2000_EPS: #REF!
Name _2000_Rev: #REF!
Name _2000_Rev: #REF!
Name _2000_Rev: #REF!
Name _2001: #REF!
Name _2001_EPS: #REF!
Name _2001_Rev: #REF!
Name _2002: #REF!
Name _2002_EPS: #REF!
Name _2002_Rev: #REF!
Name _2003: #REF!
Name _2003_EPS: #REF!
Name _2003_Rev: #REF!
Name _2004: #REF!
Name _2004_EPS: #REF!
Name _2004_Rev: #REF!
Name _2005: #REF!
Name _2005_cfps: [4]NAV!#REF!
Name _2005_EPS: #REF!
Name _2005_EPS: #REF!
Name _2005_EPS: #REF!
Name _2005_EPS: #REF!
Name _2005_Rev: #REF!
Name _2005_Rev: #REF!
Name _2005_Rev: #REF!
Name _2006: #REF!
Name _2006: #REF!
Name _2006: #REF!
Name _2006_cfps: [4]NAV!#REF!
Name _2006_cfps: [4]NAV!#REF!
Name _2006_cfps: [4]NAV!#REF!

Sheet __FDSCACHE__
B1: This sheet contains FactSet XML data for use with this workbook's =FDS codes. Modifying the worksheet's contents may damage the workbook's =FDS functionality.

Sheet Comparison
B2: =IS!B2 -> CS DISCO (LAW)
B4: Variance Analysis | D4: =IS!AF4 -> 4Q24 | E4: =K4 -> 4Q25 | F4: Y/Y Chg. | G4: =IS!AJ4 -> 3Q25 | H4: =K4 -> 4Q25 | I4: Q/Q Chg. | J4: 4Q25E | K4: =IS!AK4 -> 4Q25 | L4: % Delta
B5: Software Revenue | D5: =IS!AF5 -> 30764 | E5: =K5 -> 35136 | F5: =E5/D5-1 -> 0.14211416 | G5: =IS!AJ5 -> 35233 | H5: =K5 -> 35136 | I5: =H5/G5-1 -> -0.0027531008 | J5: 34240.332 | K5: =IS!AK5 -> 35136 | L5: =K5/J5-1 -> 0.026158274
B6: Services Revenue | D6: =IS!AF8 -> 6235 | E6: =K6 -> 6035 | F6: =E6/D6-1 -> -0.032076985 | G6: =IS!AJ8 -> 5686 | H6: =K6 -> 6035 | I6: =H6/G6-1 -> 0.061378825 | J6: 5511.74 | K6: =IS!AK8 -> 6035 | L6: =K6/J6-1 -> 0.094935538
B7: Total Revenue | D7: =IS!AF11 -> 36999 | E7: =K7 -> 41171 | F7: =E7/D7-1 -> 0.1127598 | G7: =IS!AJ11 -> 40919 | H7: =K7 -> 41171 | I7: =H7/G7-1 -> 0.0061585083 | J7: 39752.072 | K7: =IS!AK11 -> 41171 | L7: =K7/J7-1 -> 0.035694441
B8: Cost of Revenue | D8: =IS!AF14 -> 9092 | E8: =K8 -> 9661 | F8: =E8/D8-1 -> 0.06258249 | G8: =IS!AJ14 -> 9447 | H8: =K8 -> 9661 | I8: =H8/G8-1 -> 0.022652694 | J8: 9540.4973 | K8: =IS!AK14 -> 9661 | L8: =K8/J8-1 -> 0.012630654
B9: Gross Profit | D9: =D7-D8 -> 27907 | E9: =K9 -> 31510 | F9: =E9/D9-1 -> 0.12910739 | G9: =G7-G8 -> 31472 | H9: =K9 -> 31510 | I9: =H9/G9-1 -> 0.0012074225 | J9: 30211.575 | K9: =K7-K8 -> 31510 | L9: =K9/J9-1 -> 0.042977743
B10: Gross Margins | D10: =D9/D7 -> 0.75426363 | E10: =K10 -> 0.76534454 | G10: =G9/G7 -> 0.76912926 | H10: =K10 -> 0.76534454 | J10: 0.76 | K10: =K9/K7 -> 0.76534454
B12: Operating Expenses
B13: S&M | D13: =IS!AF19 -> 13871 | E13: =K13 -> 13891 | F13: =E13/D13-1 -> 0.0014418571 | G13: =IS!AJ19 -> 13612 | H13: =K13 -> 13891 | I13: =H13/G13-1 -> 0.020496621 | J13: 13793.969 | K13: =IS!AK19 -> 13891 | L13: =K13/J13-1 -> 0.0070343072
B14: R&D | D14: =IS!AF21 -> 11934 | E14: =K14 -> 12965 | F14: =E14/D14-1 -> 0.086391822 | G14: =IS!AJ21 -> 11461 | H14: =K14 -> 12965 | I14: =H14/G14-1 -> 0.13122764 | J14: 12323.142 | K14: =IS!AK21 -> 12965 | L14: =K14/J14-1 -> 0.052085553
B15: G&A | D15: =IS!AF23 -> 7294 | E15: =K15 -> 7879 | F15: =E15/D15-1 -> 0.080202906 | G15: =IS!AJ23 -> 7748 | H15: =K15 -> 7879 | I15: =H15/G15-1 -> 0.016907589 | J15: 7473.3895 | K15: =IS!AK23 -> 7879 | L15: =K15/J15-1 -> 0.054273963
B16: Total Operating Expenses | D16: =SUM(D13:D15) -> 33099 | E16: =K16 -> 34735 | F16: =E16/D16-1 -> 0.049427475 | G16: =SUM(G13:G15) -> 32821 | H16: =K16 -> 34735 | I16: =H16/G16-1 -> 0.058316322 | J16: 33590.501 | K16: =SUM(K13:K15) -> 34735 | L16: =K16/J16-1 -> 0.034072108 | N16: =K16-J16 -> 1144.4992
B18: Non-GAAP Operating Income | D18: =D9-D16 -> -5192 | E18: =K18 -> -3225 | F18: =E18/D18-1 -> -0.37885208 | G18: =G9-G16 -> -1349 | H18: =K18 -> -3225 | I18: =H18/G18-1 -> 1.3906597 | J18: -3378.9261 | K18: =K9-K16 -> -3225 | L18: =K18/J18-1 -> -0.045554746
B19: Non-GAAP Operating Margin | D19: =D18/D7 -> -0.14032812 | E19: =K19 -> -0.078331836 | G19: =G18/G7 -> -0.03296757 | H19: =K19 -> -0.078331836 | J19: -0.085 | K19: =K18/K7 -> -0.078331836
B21: GAAP & Non-cash charges | D21: =IS!AF33 -> 20938 | E21: =K21 -> 6017 | F21: =E21/D21-1 -> -0.71262776 | G21: =IS!AJ33 -> 13113 | H21: =K21 -> 6017 | I21: =H21/G21-1 -> -0.54114238 | J21: 6000 | K21: =IS!AK33 -> 6017 | L21: =K21/J21-1 -> 0.0028333333
B23: GAAP Operating Income | D23: =D18-D21 -> -26130 | E23: =K23 -> -9242 | F23: =E23/D23-1 -> -0.64630693 | G23: =G18-G21 -> -14462 | H23: =K23 -> -9242 | I23: =H23/G23-1 -> -0.36094593 | J23: -9378.9261 | K23: =K18-K21 -> -9242 | L23: =K23/J23-1 -> -0.014599339
B24: GAAP Operating Margin | D24: =D23/D7 -> -0.7062353 | E24: =K24 -> -0.22447839 | G24: =G23/G7 -> -0.35342995 | H24: =K24 -> -0.22447839 | J24: -0.23593553 | K24: =K23/K7 -> -0.22447839
B26: Interest & Other Income (Expense) | D26: =IS!AF40 -> 953 | E26: =K26 -> 996 | F26: =E26/D26-1 -> 0.045120672 | G26: =IS!AJ40 -> 937 | H26: =K26 -> 996 | I26: =H26/G26-1 -> 0.062966916 | J26: 850 | K26: =IS!AK40 -> 996 | L26: =K26/J26-1 -> 0.17176471
B28: Adjusted EBITDA | D28: =IS!AF50 -> -4287 | E28: =K28 -> -2159 | F28: =E28/D28-1 -> -0.49638442 | G28: =IS!AJ50 -> -297 | H28: =K28 -> -2159 | I28: =H28/G28-1 -> 6.2693603 | J28: -2455.4761 | K28: =IS!AK50 -> -2159 | L28: =K28/J28-1 -> -0.12074079
B29: EBITDA Margin | D29: =D28/D7 -> -0.115868 | E29: =K29 -> -0.052439824 | G29: =G28/G7 -> -0.0072582419 | H29: =K29 -> -0.052439824 | J29: -0.061769764 | K29: =K28/K7 -> -0.052439824
B31: Non-GAAP Income before Taxes | D31: =D18+D26 -> -4239 | E31: =K31 -> -2229 | F31: =E31/D31-1 -> -0.47416844 | G31: =G18+G26 -> -412 | H31: =K31 -> -2229 | I31: =H31/G31-1 -> 4.4101942 | J31: -2528.9261 | K31: =K18+K26 -> -2229 | L31: =K31/J31-1 -> -0.11859821
B32: Income Tax | D32: =IS!AF54 -> 23 | E32: =K32 -> 256 | F32: =E32/D32-1 -> 10.130435 | G32: =IS!AJ54 -> 140 | H32: =K32 -> 256 | I32: =H32/G32-1 -> 0.82857143 | J32: 100 | K32: =IS!AK54 -> 256 | L32: =K32/J32-1 -> 1.56
B33: Non-GAAP Net Income | D33: =D31-D32 -> -4262 | E33: =K33 -> -2485 | F33: =E33/D33-1 -> -0.4169404 | G33: =G31-G32 -> -552 | H33: =K33 -> -2485 | I33: =H33/G33-1 -> 3.5018116 | J33: -2628.9261 | K33: =K31-K32 -> -2485 | L33: =K33/J33-1 -> -0.054747115
B35: GAAP Income before Taxes | D35: =D23+D26 -> -25177 | E35: =K35 -> -8246 | F35: =E35/D35-1 -> -0.67247885 | G35: =G23+G26 -> -13525 | H35: =K35 -> -8246 | I35: =H35/G35-1 -> -0.39031423 | J35: -8528.9261 | K35: =K23+K26 -> -8246 | L35: =K35/J35-1 -> -0.033172537
B36: Income Tax | D36: =IS!AF60 -> 23 | E36: =K36 -> 256 | F36: =E36/D36-1 -> 10.130435 | G36: =IS!AJ60 -> 140 | H36: =K36 -> 256 | I36: =H36/G36-1 -> 0.82857143 | J36: 100 | K36: =IS!AK60 -> 256 | L36: =K36/J36-1 -> 1.56
B37: GAAP Net Income | D37: =D35-D36 -> -25200 | E37: =K37 -> -8502 | F37: =E37/D37-1 -> -0.66261905 | G37: =G35-G36 -> -13665 | H37: =K37 -> -8502 | I37: =H37/G37-1 -> -0.37782656 | J37: -8628.9261 | K37: =K35-K36 -> -8502 | L37: =K37/J37-1 -> -0.014709376
B39: Non-GAAP EPS | D39: =IS!AF65 -> -0.070912782 | E39: =K39 -> -0.03952412 | F39: =E39/D39-1 -> -0.44263757 | G39: =IS!AJ65 -> -0.0088897478 | H39: =K39 -> -0.03952412 | I39: =H39/G39-1 -> 3.4460339 | J39: -0.041918658 | K39: =IS!AK65 -> -0.03952412 | L39: =K39/J39-1 -> -0.05712344
B40: GAAP EPS | D40: =IS!AF67 -> -0.41928721 | E40: =K40 -> -0.13522498 | G40: =IS!AJ67 -> -0.22006957 | H40: =K40 -> -0.13522498 | J40: -0.13758964 | K40: =IS!AK67 -> -0.13522498
B42: Basic Shares Outstanding | D42: =IS!Z70 -> 60350 | E42: =K42 -> 59815 | G42: =IS!AC70 -> 61188 | H42: =K42 -> 59815 | J42: 59815 | K42: =IS!AD70 -> 59815
B43: Diluted Shares Outstanding | D43: =IS!Z71 -> 60350 | E43: =K43 -> 59815 | G43: =IS!AC71 -> 61188 | H43: =K43 -> 59815 | J43: 59815 | K43: =IS!AD71 -> 59815
B46: Source: Company reports and Needham & Co estimates

Sheet G Chg
C5: FY26 Guidance ($mm) | D5: FY26 Street Estimate | E5: Initial FY26 Guidance | F5: Delta | G5: 3Q26 Guide | H5: =LEFT(G5,4)& " Result" -> 3Q26 Result | I5: =LEFT(G5,4)& " Beat" -> 3Q26 Beat | J5: Rest of Year Raise / (Reduce)
C6: Revenue | D6: 170.4 | E6: =AVERAGE(167,177) -> 172 | F6: =E6-D6 -> 1.6 | G6: 38.5 | H6: =Comparison!K7/1000 -> 41.171 | I6: =H6-G6 -> 2.671 | J6: =F6-I6 -> -1.071
C7: Growth | D7: =D6/(IS!AL11/1000)-1 -> 0.086395195 | E7: =E6/(IS!AL11/1000)-1 -> 0.096596089
C8: Software Revenue | D8: 148.1 | E8: =AVERAGE(145.5,152.5) -> 149 | F8: =E8-D8 -> 0.9 | G8: 33.25 | H8: =Comparison!K5/1000 -> 35.136 | I8: =H8-G8 -> 1.886 | J8: =F8-I8 -> -0.986
C9: Growth | D9: =D8*1000/IS!AL5-1 -> 0.10522388 | E9: =E8*1000/IS!AL5-1 -> 0.1119403
C10: Services Revenue | D10: =D6-D8 -> 22.3 | E10: =E6-E8 -> 23 | F10: =E10-D10 -> 0.7 | G10: =G6-G8 -> 5.25 | H10: =Comparison!K6/1000 -> 6.035 | I10: =H10-G10 -> 0.785 | J10: =F10-I10 -> -0.085
C11: Growth | D11: =D10*1000/IS!AL8-1 -> -0.02402731 | E11: =E10*1000/IS!AL8-1 -> 0.0066086043
C12: Adjusted EBITDA | D12: -2.9 | E12: =AVERAGE(-8.5,-4.5) -> -6.5 | F12: =E12-D12 -> -3.6 | G12: -4 | H12: =Comparison!K28/1000 -> -2.159 | I12: =H12-G12 -> 1.841 | J12: =F12-I12 -> -5.441
C13: Margin | D13: =D12/D6 -> -0.017018779 | E13: =E12/E6 -> -0.037790698
L14: Guidance History | M14: FY22 | N14: FY23 | O14: FY24 | P14: FY25E | Q14: FY26E
H15: Manually update Software/Services Result | L15: Revenue Growth - Initial Guide | M15: 0.3 | N15: 0.036 | O15: 0.079 | P15: =AVERAGE(145500,157500)/IS!AG11-1 -> 0.045974551 | Q15: TBD
L16: Revenue Growth- Actual | M16: =IS!W12 -> 0.1823302 | N16: =IS!AB12 -> 0.021451291 | O16: =IS!AG12 -> 0.048888406 | P16: =IS!AL12 -> 0.082904702
L17: Difference | M17: =M16-M15 -> -0.1176698 | N17: =N16-N15 -> -0.014548709 | O17: =O16-O15 -> -0.030111594 | P17: =P16-P15 -> 0.036930151
L19: Adj. EBITDA Margin - Initial Guide | M19: -0.319 | N19: -0.286 | O19: -0.151 | P19: =-17/AVERAGE(145.5,157.5) -> -0.11221122 | Q19: TBD
L20: Adj. EBITDA Margin - Actual | M20: =IS!W51 -> -0.32934389 | N20: =IS!AB51 -> -0.18751539 | O20: =IS!AG51 -> -0.12923136 | P20: =IS!AL51 -> -0.065241092
L21: Difference | M21: =M20-M19 -> -0.010343886 | N21: =N20-N19 -> 0.098484611 | O21: =O20-O19 -> 0.021768636 | P21: =P20-P19 -> 0.046970129
L23: Needham & Company Research

Sheet IS
B2: CS DISCO (LAW)
B4: Income Statement | D4: 1Q19 | E4: 2Q19 | F4: 3Q19 | G4: 4Q19 | H4: 2019 | I4: 1Q20 | J4: 2Q20 | K4: 3Q20 | L4: 4Q20 | M4: 2020 | N4: 1Q21 | O4: 2Q21 | P4: 3Q21 | Q4: 4Q21 | R4: 2021 | S4: 1Q22 | T4: 2Q22 | U4: 3Q22 | V4: 4Q22 | W4: 2022 | X4: 1Q23 | Y4: 2Q23 | Z4: 3Q23 | AA4: 4Q23 | AB4: 2023 | AC4: 1Q24 | AD4: 2Q24 | AE4: 3Q24 | AF4: 4Q24 | AG4: 2024 | AH4: 1Q25 | AI4: 2Q25 | AJ4: 3Q25 | AK4: 4Q25 | AL4: 2025 | AM4: 1Q26E | AN4: 2Q26E | AO4: 3Q26E | AP4: 4Q26E | AQ4: 2026E
B5: Software Revenue | X5: 27560 | Y5: 27012 | Z5: 28413 | AA5: 29282 | AB5: =SUM(X5:AA5) -> 112267 | AC5: 29909 | AD5: 29278 | AE5: 30181 | AF5: =120132-SUM(AC5:AE5) -> 30764 | AG5: =SUM(AC5:AF5) -> 120132 | AH5: 30887 | AI5: 32744 | AJ5: 35233 | AK5: =134000-SUM(AH5:AJ5) -> 35136 | AL5: =SUM(AH5:AK5) -> 134000 | AM5: =AH5*(1+AM6) -> 34531.666 | AN5: =AI5*(1+AN6) -> 36673.28 | AO5: =AJ5*(1+AO6) -> 38185.026 | AP5: =AK5*(1+AP6) -> 39633.408 | AQ5: =SUM(AM5:AP5) -> 149023.38
C6: Y/Y Growth | X6: - | Y6: - | Z6: - | AA6: - | AB6: - | AC6: =AC5/X5-1 -> 0.085232221 | AD6: =AD5/Y5-1 -> 0.083888642 | AE6: =AE5/Z5-1 -> 0.062225038 | AF6: =AF5/AA5-1 -> 0.050611297 | AG6: =AG5/AB5-1 -> 0.070056205 | AH6: =AH5/AC5-1 -> 0.032699188 | AI6: =AI5/AD5-1 -> 0.1183824 | AJ6: =AJ5/AE5-1 -> 0.16739008 | ... AL6: =AL5/AG5-1 -> 0.11543968 | AM6: 0.118 | AN6: 0.12 | AO6: =1.122*(AJ5-1200)/AJ5-1 -> 0.083785826 | AP6: 0.128 | AQ6: =AQ5/AL5-1 -> 0.11211478
C7: Q/Q Growth | X7: - | Y7: =Y5/X5-1 -> -0.01988389 | Z7: =Z5/Y5-1 -> 0.051865837 | AA7: =AA5/Z5-1 -> 0.030584592 | AC7: =AC5/AA5-1 -> 0.021412472 | AD7: =AD5/AC5-1 -> -0.021097329 | AE7: =AE5/AD5-1 -> 0.030842271 | AF7: =AF5/AE5-1 -> 0.019316789 | AH7: =AH5/AF5-1 -> 0.0039981797 | AI7: =AI5/AH5-1 -> 0.060122382 | AJ7: =AJ5/AI5-1 -> 0.076013926 | AK7: =AK5/AJ5-1 -> -0.0027531008 | AM7: =AM5/AK5-1 -> -0.017199852 | AN7: =AN5/AM5-1 -> 0.062018844 | AO7: =AO5/AN5-1 -> 0.041222001 | AP7: =AP5/AO5-1 -> 0.037930628
B8: Services Revenue | X8: 5569 | Y8: 7264 | Z8: 6530 | AA8: 6460 | AB8: =SUM(X8:AA8) -> 25823 | AC8: =AC11-AC5 -> 5662 | AD8: =AD11-AD5 -> 6727 | AE8: =AE11-AE5 -> 6085 | AF8: =36999-AF5 -> 6235 | AG8: =SUM(AC8:AF8) -> 24709 | AH8: =AH11-AH5 -> 5766 | AI8: =AI11-AI5 -> 5362 | AJ8: =AJ11-AJ5 -> 5686 | AK8: =22849-SUM(AH8:AJ8) -> 6035 | AL8: =SUM(AH8:AK8) -> 22849 | AM8: =AH8*(1+AM9) -> 5218.23 | AN8: =AI8*(1+AN9) -> 5630.1 | AO8: =AJ8*(1+AO9) -> 5856.58 | AP8: =AK8*(1+AP9) -> 6276.4 | AQ8: =SUM(AM8:AP8) -> 22981.31
C9: Y/Y Growth | X9: - | Y9: - | Z9: - | AA9: - | AB9: - | AC9: =AC8/X8-1 -> 0.016699587 | AD9: =AD8/Y8-1 -> -0.073926211 | AE9: =AE8/Z8-1 -> -0.068147014 | AF9: =AF8/AA8-1 -> -0.034829721 | AG9: =AG8/AB8-1 -> -0.043139837 | AH9: =AH8/AC8-1 -> 0.018368068 | AI9: =AI8/AD8-1 -> -0.20291363 | AJ9: =AJ8/AE8-1 -> -0.065571076 | ... AL9: =AL8/AG8-1 -> -0.075276215 | AM9: -0.095 | AN9: 0.05 | AO9: 0.03 | AP9: 0.04 | AQ9: =AQ8/AL8-1 -> 0.0057906254
C10: Q/Q Growth | X10: - | Y10: =Y8/X8-1 -> 0.30436344 | Z10: =Z8/Y8-1 -> -0.10104626 | AA10: =AA8/Z8-1 -> -0.010719755 | AC10: =AC8/AA8-1 -> -0.12352941 | AD10: =AD8/AC8-1 -> 0.18809608 | AE10: =AE8/AD8-1 -> -0.095436301 | AF10: =AF8/AE8-1 -> 0.024650781 | AH10: =AH8/AF8-1 -> -0.075220529 | AI10: =AI8/AH8-1 -> -0.070065904 | AJ10: =AJ8/AI8-1 -> 0.060425214 | AK10: =AK8/AJ8-1 -> 0.061378825 | AM10: =AM8/AK8-1 -> -0.13533886 | AN10: =AN8/AM8-1 -> 0.078929062 | AO10: =AO8/AN8-1 -> 0.040226639 | AP10: =AP8/AO8-1 -> 0.071683474
B11: Total Revenue | D11: =+D116 -> 10378 | E11: =+E116 -> 11305 | F11: =+F116 -> 12652 | G11: =+G116 -> 14221 | H11: =H116 -> 48556 | I11: =+I116 -> 15668 | J11: =+J116 -> 15727 | K11: =+K116 -> 17863 | L11: =+L116 -> 19186 | M11: =M116 -> 68444 | N11: =+N116 -> 21131 | O11: 29547 | P11: 29854 | Q11: 33810 | R11: =SUM(N11:Q11) -> 114342 | S11: 34468 | T11: 33710 | U11: =34475 -> 34475 | V11: 32537 | W11: =SUM(S11:V11) -> 135190 | X11: =+X5+X8 -> 33129 | Y11: =+Y5+Y8 -> 34276 | Z11: =+Z5+Z8 -> 34943 | AA11: =+AA5+AA8 -> 35742 | AB11: =+AB5+AB8 -> 138090 | AC11: 35571 | AD11: 36005 | AE11: =36266 -> 36266 | AF11: =+AF5+AF8 -> 36999 | AG11: =+AG5+AG8 -> 144841 | AH11: 36653 | AI11: 38106 | AJ11: 40919 | AK11: =+AK5+AK8 -> 41171 | AL11: =+AL5+AL8 -> 156849 | AM11: =+AM5+AM8 -> 39749.896 | AN11: =+AN5+AN8 -> 42303.38 | AO11: =+AO5+AO8 -> 44041.606 | AP11: =+AP5+AP8 -> 45909.808 | AQ11: =+AQ5+AQ8 -> 172004.69
C12: Y/Y Growth | I12: =I11/D11-1 -> 0.50973213 | J12: =J11/E11-1 -> 0.39115436 | K12: =K11/F11-1 -> 0.41187164 | L12: =L11/G11-1 -> 0.34913157 | M12: =M11/H11-1 -> 0.40958893 | N12: =N11/I11-1 -> 0.34867245 | O12: =O11/J11-1 -> 0.87874356 | P12: =P11/K11-1 -> 0.67127582 | ... AQ12: =AQ11/AL11-1 -> 0.096625991
C13: Q/Q Growth | E13: =E11/D11-1 -> 0.089323569 | F13: =F11/E11-1 -> 0.11915082 | G13: =G11/F11-1 -> 0.12401201 | I13: =I11/G11-1 -> 0.10175093 | J13: =J11/I11-1 -> 0.003765637 | K13: =K11/J11-1 -> 0.13581738 | L13: =L11/K11-1 -> 0.074063707 | N13: =N11/L11-1 -> 0.101376 | O13: =O11/N11-1 -> 0.39827741 | P13: =P11/O11-1 -> 0.010390226 | Q13: =Q11/P11-1 -> 0.13251156 | S13: =S11/Q11-1 -> 0.019461698 | T13: =T11/S11-1 -> -0.021991412 | U13: =U11/T11-1 -> 0.022693563 | V13: =V11/U11-1 -> -0.056214648 | X13: =X11/V11-1 -> 0.018194671 | Y13: =Y11/X11-1 -> 0.034622234 | Z13: =Z11/Y11-1 -> 0.01945968 | AA13: =AA11/Z11-1 -> 0.02286581 | AC13: =AC11/AA11-1 -> -0.0047842874 | AD13: =AD11/AC11-1 -> 0.01220095 | AE13: =AE11/AD11-1 -> 0.0072489932 | AF13: =AF11/AE11-1 -> 0.020211769 | AH13: =AH11/AF11-1 -> -0.0093516041 | AI13: =AI11/AH11-1 -> 0.039642048 | AJ13: =AJ11/AI11-1 -> 0.073820396 | AK13: =AK11/AJ11-1 -> 0.0061585083 | AM13: =AM11/AK11-1 -> -0.034517112 | AN13: =AN11/AM11-1 -> 0.064238759 | AO13: =AO11/AN11-1 -> 0.04108953 | AP13: =AP11/AO11-1 -> 0.042419025
B14: Cost of Revenue | D14: =D118-D137 -> 2902 | E14: =E118-E137 -> 3304 | F14: =F118-F137 -> 3618 | G14: =G118-G137 -> 4626 | H14: =H118-H137 -> 14450 | I14: =I118-I137 -> 5065 | J14: =J118-J137 -> 4502 | K14: =K118-K137 -> 5515 | ... N14: =N118-N137 -> 5780 | O14: =8695-10 -> 8685 | P14: =7829-10 -> 7819 | Q14: =8786-29 -> 8757 | R14: =SUM(N14:Q14) -> 31041 | S14: =8969-160 -> 8809 | T14: =8489-234 -> 8255 | U14: =8634-274 -> 8360 | V14: =8071-270 -> 7801 | W14: =SUM(S14:V14) -> 33225 | X14: =8277-231 -> 8046 | Y14: =9039-271 -> 8768 | Z14: =8939-270 -> 8669 | AA14: =8693-264 -> 8429 | AB14: =SUM(X14:AA14) -> 33912 | AC14: =8852-385 -> 8467 | AD14: =9288-432 -> 8856 | AE14: =9740-456 -> 9284 | AF14: =9534-442 -> 9092 | AG14: =SUM(AC14:AF14) -> 35699 | AH14: 9004 | AI14: =9683-562 -> 9121 | AJ14: 9447 | AK14: 9661 | AL14: =SUM(AH14:AK14) -> 37233 | AM14: =AM11*(1-AM16) -> 9818.2243 | AN14: =AN11*(1-AN16) -> 10068.204 | AO14: =AO11*(1-AO16) -> 10481.902 | AP14: =AP11*(1-AP16) -> 10834.715 | AQ14: =SUM(AM14:AP14) -> 41203.046
B15: Gross Profit | D15: =D11-D14 -> 7476 | E15: =E11-E14 -> 8001 | F15: =F11-F14 -> 9034 | G15: =G11-G14 -> 9595 | H15: =H11-H14 -> 34106 | I15: =I11-I14 -> 10603 | J15: =J11-J14 -> 11225 | K15: =K11-K14 -> 12348 | ... AQ15: =AQ11-AQ14 -> 130801.64
C16: Gross Margin | D16: =D15/D11 -> 0.72037001 | E16: =E15/E11 -> 0.70773994 | F16: =F15/F11 -> 0.71403731 | G16: =G15/G11 -> 0.67470642 | H16: =H15/H11 -> 0.70240547 | I16: =I15/I11 -> 0.67672964 | J16: =J15/J11 -> 0.7137407 | K16: =K15/K11 -> 0.69126127 | ... AL16: =AL15/AL11 -> 0.76261882 | AM16: 0.753 | AN16: 0.762 | AO16: 0.762 | AP16: 0.764 | AQ16: =AQ15/AQ11 -> 0.76045394
B18: Operating Expenses
C19: Sales & marketing | D19: =D122-D138 -> 5256 | E19: =E122-E138 -> 5821 | F19: =F122-F138 -> 6946 | G19: =G122-G138 -> 7798 | H19: =H122-H138 -> 25821 | I19: =I122-I138 -> 9252 | J19: =J122-J138 -> 7082 | K19: =K122-K138 -> 7093 | ... N19: =N122-N138 -> 7793 | O19: =10832-235 -> 10597 | P19: =13168-245 -> 12923 | Q19: =15169-695 -> 14474 | R19: =SUM(N19:Q19) -> 45787 | S19: =16419-821 -> 15598 | T19: =18931-1380 -> 17551 | U19: =19311-753 -> 18558 | V19: =18178-1232 -> 16946 | W19: =SUM(S19:V19) -> 68653 | X19: =19060-1391-177 -> 17492 | Y19: =18053-1360-471 -> 16222 | Z19: =16708-1277 -> 15431 | AA19: =14311-1338 -> 12973 | AB19: =SUM(X19:AA19) -> 62118 | AC19: =15808-1080 -> 14728 | AD19: =15498-1171 -> 14327 | AE19: =14988-1213 -> 13775 | AF19: 13871 | AG19: =SUM(AC19:AF19) -> 56701 | AH19: 13183 | AI19: 13763 | AJ19: 13612 | AK19: 13891 | AL19: =SUM(AH19:AK19) -> 54449 | AM19: =AM11*AM20 -> 14150.963 | AN19: =AN11*AN20 -> 14002.419 | AO19: =AO11*AO20 -> 14049.272 | AP19: =AP11*AP20 -> 14691.139 | AQ19: =SUM(AM19:AP19) -> 56893.793
C20: % of Revenue | D20: =D19/D11 -> 0.50645596 | E20: =E19/E11 -> 0.51490491 | F20: =F19/F11 -> 0.54900411 | G20: =G19/G11 -> 0.548344 | H20: =H19/H11 -> 0.53177774 | I20: =I19/I11 -> 0.59050294 | J20: =J19/J11 -> 0.45030839 | K20: =K19/K11 -> 0.39707776 | ... AL20: =AL19/AL11 -> 0.34714279 | AM20: 0.356 | AN20: 0.331 | AO20: 0.319 | AP20: 0.32 | AQ20: =AQ19/AQ11 -> 0.33076884
C21: Research & Development | D21: =D123-D139 -> 4761 | E21: =E123-E139 -> 6243 | F21: =F123-F139 -> 6968 | G21: =G123-G139 -> 6653 | H21: =H123-H139 -> 24625 | I21: =I123-I139 -> 7981 | J21: =J123-J139 -> 5998 | K21: =K123-K139 -> 6010 | ... N21: =N123-N139 -> 6061 | O21: =7861-285 -> 7576 | P21: =9652-301 -> 9351 | Q21: =10639-1294 -> 9345 | R21: =SUM(N21:Q21) -> 32333 | S21: =12318-1427 -> 10891 | T21: =15181-2073 -> 13108 | U21: =15694-1916 -> 13778 | V21: =16065-2652 -> 13413 | W21: =SUM(S21:V21) -> 51190 | X21: =15772-2190-509 -> 13073 | Y21: =13258-1729-1001 -> 10528 | Z21: =12065-2001 -> 10064 | AA21: =10528-1847 -> 8681 | AB21: =SUM(X21:AA21) -> 42346 | AC21: =12079-2092 -> 9987 | AD21: =12888-2084 -> 10804 | AE21: =12757-1680 -> 11077 | AF21: 11934 | AG21: =SUM(AC21:AF21) -> 43802 | AH21: 12214 | AI21: 11724 | AJ21: 11461 | AK21: 12965 | AL21: =SUM(AH21:AK21) -> 48364 | AM21: =AM11*AM22 -> 12918.716 | AN21: =AN11*AN22 -> 12648.711 | AO21: =AO11*AO22 -> 12816.107 | AP21: =AP11*AP22 -> 13130.205 | AQ21: =SUM(AM21:AP21) -> 51513.739
C22: % of Revenue | D22: =D21/D11 -> 0.45875891 | E22: =E21/E11 -> 0.55223352 | F22: =F21/F11 -> 0.55074297 | G22: =G21/G11 -> 0.46782927 | H22: =H21/H11 -> 0.50714639 | I22: =I21/I11 -> 0.50938218 | J22: =J21/J11 -> 0.38138234 | K22: =K21/K11 -> 0.33644964 | ... AL22: =AL21/AL11 -> 0.30834752 | AM22: 0.325 | AN22: 0.299 | AO22: 0.291 | AP22: 0.286 | AQ22: =AQ21/AQ11 -> 0.29949032
C23: General & Administrative | D23: =D124-D140 -> 1923 | E23: =E124-E140 -> 2632 | F23: =F124-F140 -> 2454 | G23: =G124-G140 -> 2881 | H23: =H124-H140 -> 9890 | I23: =I124-I140 -> 4068 | J23: =J124-J140 -> 2952 | K23: =K124-K140 -> 2837 | ... N23: =N124-N140 -> 3857 | O23: =5128-436 -> 4692 | P23: =8270-498 -> 7772 | Q23: =8163-1077 -> 7086 | R23: =SUM(N23:Q23) -> 23407 | S23: =8519-798 -> 7721 | T23: =11065-1835-386-798 -> 8046 | U23: =10906-2722-329 -> 7855 | V23: =10248-3190-540 -> 6518 | W23: =SUM(S23:V23) -> 30140 | X23: =12300-3412-330 -> 8558 | Y23: =10917-3508-102 -> 7307 | Z23: =128+6429 -> 6557 | AA23: =9887-1498-500-74 -> 7815 | AB23: =SUM(X23:AA23) -> 30237 | AC23: =11164-2116-199 -> 8849 | AD23: =10715-2371-384 -> 7960 | AE23: =9658-1798-143 -> 7717 | AF23: 7294 | AG23: =SUM(AC23:AF23) -> 31820 | AH23: 8418 | AI23: 7249 | AJ23: 7748 | AK23: 7879 | AL23: =SUM(AH23:AK23) -> 31294 | AM23: =AM11*AM24 -> 8744.9771 | AN23: =AN11*AN24 -> 7699.2152 | AO23: =AO11*AO24 -> 7883.4475 | AP23: =AP11*AP24 -> 8080.1262 | AQ23: =SUM(AM23:AP23) -> 32407.766
C24: % of Revenue | D24: =D23/D11 -> 0.18529582 | E24: =E23/E11 -> 0.23281734 | F24: =F23/F11 -> 0.19396143 | G24: =G23/G11 -> 0.20258772 | H24: =H23/H11 -> 0.20368235 | I24: =I23/I11 -> 0.25963748 | J24: =J23/J11 -> 0.18770268 | K24: =K23/K11 -> 0.15881991 | ... AL24: =AL23/AL11 -> 0.19951673 | AM24: 0.22 | AN24: 0.182 | AO24: 0.179 | AP24: 0.176 | AQ24: =AQ23/AQ11 -> 0.18841211
B25: Total Operating Expense | D25: =D19+D21+D23 -> 11940 | E25: =E19+E21+E23 -> 14696 | F25: =F19+F21+F23 -> 16368 | G25: =G19+G21+G23 -> 17332 | H25: =H19+H21+H23 -> 60336 | I25: =I19+I21+I23 -> 21301 | J25: =J19+J21+J23 -> 16032 | K25: =K19+K21+K23 -> 15940 | ... AQ25: =AQ19+AQ21+AQ23 -> 140815.3
B27: Non-GAAP Operating Income | D27: =D15-D25 -> -4464 | E27: =E15-E25 -> -6695 | F27: =F15-F25 -> -7334 | G27: =G15-G25 -> -7737 | H27: =H15-H25 -> -26230 | I27: =I15-I25 -> -10698 | J27: =J15-J25 -> -4807 | K27: =K15-K25 -> -3592 | ... AQ27: =AQ15-AQ25 -> -10013.654
C28: Non-GAAP Operating Margin | D28: =D27/D11 -> -0.43014068 | E28: =E27/E11 -> -0.59221583 | F28: =F27/F11 -> -0.5796712 | G28: =G27/G11 -> -0.54405457 | H28: =H27/H11 -> -0.54020101 | I28: =I27/I11 -> -0.68279295 | J28: =J27/J11 -> -0.3056527 | K28: =K27/K11 -> -0.20108604 | ... AQ28: =AQ27/AQ11 -> -0.058217328
B30: GAAP Adjustments
C31: Stock base compensation | D31: =D141 -> 2632 | E31: =+E141 -> 534 | F31: =+F141 -> 453 | G31: =+G141 -> 501 | H31: =SUM(D31:G31) -> 4120 | I31: =+I141 -> 488 | J31: =+J141 -> 504 | K31: =+K141 -> 506 | L31: =+L141 -> 495 | M31: =SUM(I31:L31) -> 1993 | N31: =+N141 -> 488 | O31: 966 | P31: 1054 | Q31: 3095 | R31: =SUM(N31:Q31) -> 5603 | S31: 3206 | T31: 5522 | U31: 5665 | V31: 7344 | W31: =SUM(S31:V31) -> 21737 | X31: 7224 | Y31: 6868 | Z31: -2881 | AA31: 4947 | AB31: =SUM(X31:AA31) -> 16158 | AC31: 5673 | AD31: 6058 | AE31: 5147 | AF31: 5391 | AG31: =SUM(AC31:AF31) -> 22269 | AH31: 5879 | AI31: 6478 | AJ31: 6090 | AK31: 6017 | AL31: =SUM(AH31:AK31) -> 24464 | AM31: 6000 | AN31: 6000 | AO31: 6000 | AP31: 6000 | AQ31: =SUM(AM31:AP31) -> 24000
C32: Other | H32: =SUM(D32:G32) -> 0 | K32: -1057 | M32: =SUM(I32:L32) -> -1057 | R32: =SUM(N32:Q32) -> 0 | T32: =386+798 -> 1184 | U32: 329 | V32: 540 | W32: =SUM(S32:V32) -> 2053 | X32: 1016 | Y32: 1574 | Z32: 0 | AA32: =500+74 -> 574 | AB32: =SUM(X32:AA32) -> 3164 | AC32: 199 | AD32: 384 | AE32: 143 | AF32: =303+31+15213 -> 15547 | AG32: =SUM(AC32:AF32) -> 16273 | AH32: 565 | AI32: 1581 | AJ32: 7023 | AK32: 0 | AL32: =SUM(AH32:AK32) -> 9169 | AQ32: =SUM(AM32:AP32) -> 0
B33: GAAP Adjustments | D33: =SUM(D31:D32) -> 2632 | E33: =SUM(E31:E32) -> 534 | F33: =SUM(F31:F32) -> 453 | G33: =SUM(G31:G32) -> 501 | H33: =SUM(H31:H32) -> 4120 | I33: =SUM(I31:I32) -> 488 | J33: =SUM(J31:J32) -> 504 | K33: =SUM(K31:K32) -> -551 | ... AQ33: =SUM(AQ31:AQ32) -> 24000
B35: GAAP Operating Income | D35: =D27-D33 -> -7096 | E35: =E27-E33 -> -7229 | F35: =F27-F33 -> -7787 | G35: =G27-G33 -> -8238 | H35: =H27-H33 -> -30350 | I35: =I27-I33 -> -11186 | J35: =J27-J33 -> -5311 | K35: =K27-K33 -> -3041 | ... AQ35: =AQ27-AQ33 -> -34013.654
C36: GAAP Operating Margin | D36: =D35/D11 -> -0.6837541 | E36: =E35/E11 -> -0.63945157 | F36: =F35/F11 -> -0.61547581 | G36: =G35/G11 -> -0.57928416 | H36: =H35/H11 -> -0.62505149 | I36: =I35/I11 -> -0.71393924 | J36: =J35/J11 -> -0.3376995 | K36: =K35/K11 -> -0.17024016 | ... AQ36: =AQ35/AQ11 -> -0.19774841
B38: Interest and Other Income | D38: =D129 -> 180 | E38: =E129 -> 144 | F38: =F129 -> 215 | G38: =G129 -> 113 | H38: =H129 -> 652 | I38: =I129 -> 63 | J38: =J129 -> 15 | K38: =K129 -> 55 | ... N38: =N129 -> 13 | O38: 21 | P38: 40 | Q38: 32 | R38: =SUM(N38:Q38) -> 106 | S38: 30 | T38: 29 | U38: 364 | V38: 1279 | W38: =SUM(S38:V38) -> 1702 | X38: 1947 | Y38: 2129 | Z38: 2191 | AA38: 2039 | AB38: =SUM(X38:AA38) -> 8306 | AC38: 1986 | AD38: 1735 | AE38: 1652 | AF38: 1464 | AG38: =SUM(AC38:AF38) -> 6837 | AH38: 1354 | AI38: 1208 | AJ38: 937 | AK38: 996 | AL38: =SUM(AH38:AK38) -> 4495 | AM38: =AK38-25 -> 971 | AN38: =AM38-25 -> 946 | AO38: =AN38-30 -> 916 | AP38: =AO38-50 -> 866 | AQ38: =SUM(AM38:AP38) -> 3699
B39: Interest and Other Expense | D39: =+D130 -> -33 | E39: =+E130 -> 36 | F39: =+F130 -> -87 | G39: =+G130 -> -40 | H39: =+H130 -> -124 | I39: =+I130 -> -88 | J39: =+J130 -> -161 | K39: =+K130 -> -170 | ... N39: =+N130 -> -57 | O39: -92 | P39: -169 | Q39: -222 | R39: =SUM(N39:Q39) -> -540 | S39: -93 | T39: -200 | U39: -314 | V39: 134 | W39: =SUM(S39:V39) -> -473 | X39: 8 | Y39: 4 | Z39: -260 | AA39: 80 | AB39: =SUM(X39:AA39) -> -168 | AC39: -150 | AD39: -80 | AE39: 185 | AF39: -511 | AG39: =SUM(AC39:AF39) -> -556 | AL39: =SUM(AH39:AK39) -> 0 | AQ39: =SUM(AM39:AP39) -> 0
B40: Total Other Income (Expense) | D40: =SUM(D38:D39) -> 147 | E40: =SUM(E38:E39) -> 180 | F40: =SUM(F38:F39) -> 128 | G40: =SUM(G38:G39) -> 73 | H40: =SUM(D40:G40) -> 528 | I40: =SUM(I38:I39) -> -25 | J40: =SUM(J38:J39) -> -146 | K40: =SUM(K38:K39) -> -115 | L40: =SUM(L38:L39) -> -15 | M40: =SUM(I40:L40) -> -301 | N40: =SUM(N38:N39) -> -44 | O40: =SUM(O38:O39) -> -71 | P40: =SUM(P38:P39) -> -129 | Q40: =SUM(Q38:Q39) -> -190 | R40: =SUM(N40:Q40) -> -434 | S40: =SUM(S38:S39) -> -63 | T40: =SUM(T38:T39) -> -171 | U40: =SUM(U38:U39) -> 50 | V40: =SUM(V38:V39) -> 1413 | W40: =SUM(S40:V40) -> 1229 | X40: =SUM(X38:X39) -> 1955 | Y40: =SUM(Y38:Y39) -> 2133 | Z40: =SUM(Z38:Z39) -> 1931 | AA40: =SUM(AA38:AA39) -> 2119 | AB40: =SUM(X40:AA40) -> 8138 | AC40: =SUM(AC38:AC39) -> 1836 | AD40: =SUM(AD38:AD39) -> 1655 | AE40: =SUM(AE38:AE39) -> 1837 | AF40: =SUM(AF38:AF39) -> 953 | AG40: =SUM(AC40:AF40) -> 6281 | AH40: =SUM(AH38:AH39) -> 1354 | AI40: =SUM(AI38:AI39) -> 1208 | AJ40: =SUM(AJ38:AJ39) -> 937 | AK40: =SUM(AK38:AK39) -> 996 | AL40: =SUM(AH40:AK40) -> 4495 | AM40: =SUM(AM38:AM39) -> 971 | AN40: =SUM(AN38:AN39) -> 946 | AO40: =SUM(AO38:AO39) -> 916 | AP40: =SUM(AP38:AP39) -> 866 | AQ40: =SUM(AM40:AP40) -> 3699
B42: EBITDA Reconciliation
C43: GAAP Net Loss | D43: =D62 -> -6952 | E43: =E62 -> -7051 | F43: =F62 -> -7661 | G43: =G62 -> -8168 | H43: =SUM(D43:G43) -> -29832 | I43: =I62 -> -11236 | J43: =J62 -> -5477 | K43: =K62 -> -3169 | L43: =L62 -> -2991 | M43: =SUM(I43:L43) -> -22873 | N43: =N62 -> -2928 | O43: =O62 -> -3083 | P43: =P62 -> -9225 | Q43: =Q62 -> -9108 | R43: =SUM(N43:Q43) -> -24344 | S43: =S62 -> -11849 | T43: =T62 -> -20171 | U43: =U62 -> -20058 | V43: =V62 -> -18687 | W43: =SUM(S43:V43) -> -70765 | X43: =X62 -> -20365 | Y43: =Y62 -> -14915 | Z43: =Z62 -> -1030 | AA43: =AA62 -> -5840 | AB43: =SUM(X43:AA43) -> -42150 | AC43: =AC62 -> -10582 | AD43: =AD62 -> -10834 | AE43: =AE62 -> -9158 | AF43: =AF62 -> -25200 | AG43: =SUM(AC43:AF43) -> -55774 | AH43: =AH62 -> -11393 | AI43: =AI62 -> -10812 | AJ43: =AJ62 -> -13665 | AK43: =AK62 -> -8502 | AL43: =SUM(AH43:AK43) -> -44372 | AM43: =AM62 -> -11061.985 | AN43: =AN62 -> -7319.169 | AO43: =AO62 -> -6423.1234 | AP43: =AP62 -> -6160.3765 | AQ43: =SUM(AM43:AP43) -> -30964.654
C44: Dep & Amortization | D44: =D143 -> 120 | E44: =E143 -> 176 | F44: =F143 -> 247 | G44: =G143 -> 260 | H44: =SUM(D44:G44) -> 803 | I44: =I143 -> 378 | J44: =J143 -> 421 | K44: =K143 -> 415 | L44: =L143 -> 410 | M44: =SUM(I44:L44) -> 1624 | N44: =N143 -> 424 | O44: 406 | P44: 424 | Q44: 420 | R44: =SUM(N44:Q44) -> 1674 | S44: =CF!S10 -> 455 | T44: =CF!T10 -> 700 | U44: =CF!U10 -> 924 | V44: =CF!V10 -> 895 | W44: =SUM(S44:V44) -> 2974 | X44: =CF!X10 -> 952 | Y44: =CF!Y10 -> 1005 | Z44: =CF!Z10 -> 1054 | AA44: =CF!AA10 -> 1148 | AB44: =SUM(X44:AA44) -> 4159 | AC44: =CF!AC10 -> 1075 | AD44: =CF!AD10 -> 1028 | AE44: =CF!AE10 -> 989 | AF44: =CF!AF10 -> 834 | AG44: =SUM(AC44:AF44) -> 3926 | AH44: =CF!AH10 -> 927 | AI44: =CF!AI10 -> 902 | AJ44: =CF!AJ10 -> 902 | AK44: =CF!AK10 -> 927 | AL44: =SUM(AH44:AK44) -> 3658 | AM44: =CF!AM10 -> 872.045 | AN44: =CF!AN10 -> 869.50982 | AO44: =CF!AO10 -> 878.7662 | AP44: =CF!AP10 -> 886.95808 | AQ44: =SUM(AM44:AP44) -> 3507.2791
C45: Provision for Income Taxes | D45: =D54 -> 3 | E45: =E54 -> 2 | F45: =F54 -> 2 | G45: =G54 -> 2 | H45: =SUM(D45:G45) -> 9 | I45: =I54 -> 25 | J45: =J54 -> 20 | K45: =K54 -> 13 | L45: =L54 -> 13 | M45: =SUM(I45:L45) -> 71 | N45: =N54 -> 36 | O45: =O54 -> 43 | P45: =P54 -> 31 | Q45: =Q54 -> -29 | R45: =SUM(N45:Q45) -> 81 | S45: =S54 -> 29 | T45: =T54 -> 44 | U45: =U54 -> 38 | V45: =V54 -> 75 | W45: =SUM(S45:V45) -> 186 | X45: =X54 -> 40 | Y45: =Y54 -> 57 | Z45: =Z54 -> 64 | AA45: 282 | AB45: =SUM(X45:AA45) -> 443 | AC45: =AC54 -> 86 | AD45: =AD54 -> 105 | AE45: =AE54 -> 118 | AF45: =AF54 -> 23 | AG45: =SUM(AC45:AF45) -> 332 | AH45: =AH54 -> 137 | AI45: =AI54 -> 210 | AJ45: =AJ54 -> 140 | AK45: =AK54 -> 256 | AL45: =SUM(AH45:AK45) -> 743 | AM45: =AM54 -> 150 | AN45: =AN54 -> 150 | AO45: =AO54 -> 150 | AP45: =AP54 -> 200 | AQ45: =SUM(AM45:AP45) -> 650
C46: Interest and Other, Net | D46: =-D40 -> -147 | E46: =-E40 -> -180 | F46: =-F40 -> -128 | G46: =-G40 -> -73 | H46: =SUM(D46:G46) -> -528 | I46: =-I40 -> 25 | J46: =-J40 -> 146 | K46: =-K40 -> 115 | L46: =-L40 -> 15 | M46: =SUM(I46:L46) -> 301 | N46: =-N40 -> 44 | O46: =-O40 -> 71 | P46: =-P40 -> 129 | Q46: =-Q40 -> 190 | R46: =SUM(N46:Q46) -> 434 | S46: =-S40 -> 63 | T46: =-T40 -> 171 | U46: =-U40 -> -50 | V46: =-V40 -> -1413 | W46: =SUM(S46:V46) -> -1229 | X46: =-X40 -> -1955 | Y46: =-Y40 -> -2133 | Z46: =-Z40 -> -1931 | AA46: =-AA40 -> -2119 | AB46: =SUM(X46:AA46) -> -8138 | AC46: =-AC40 -> -1836 | AD46: =-AD40 -> -1655 | AE46: =-AE40 -> -1837 | AF46: =-AF40 -> -953 | AG46: =SUM(AC46:AF46) -> -6281 | AH46: =-AH40 -> -1354 | AI46: =-AI40 -> -1208 | AJ46: =-AJ40 -> -937 | AK46: =-AK40 -> -996 | AL46: =SUM(AH46:AK46) -> -4495 | AM46: =-AM40 -> -971 | AN46: =-AN40 -> -946 | AO46: =-AO40 -> -916 | AP46: =-AP40 -> -866 | AQ46: =SUM(AM46:AP46) -> -3699
C47: Stock-based Compensation | D47: =D141 -> 2632 | E47: =E141 -> 534 | F47: =F141 -> 453 | G47: =G141 -> 501 | H47: =SUM(D47:G47) -> 4120 | I47: =I141 -> 488 | J47: =J141 -> 504 | K47: =K141 -> 506 | L47: =L141 -> 495 | M47: =SUM(I47:L47) -> 1993 | N47: =N141 -> 488 | O47: =O31 -> 966 | P47: =P31 -> 1054 | Q47: =Q31 -> 3095 | R47: =SUM(N47:Q47) -> 5603 | S47: =S31 -> 3206 | T47: =T31 -> 5522 | U47: =U31 -> 5665 | V47: =V31 -> 7344 | W47: =SUM(S47:V47) -> 21737 | X47: =X31 -> 7224 | Y47: =Y31 -> 6868 | Z47: =Z31 -> -2881 | AA47: =AA31 -> 4947 | AB47: =SUM(X47:AA47) -> 16158 | AC47: =AC31 -> 5673 | AD47: =AD31 -> 6058 | AE47: =AE31 -> 5147 | AF47: =AF31 -> 5391 | AG47: =SUM(AC47:AF47) -> 22269 | AH47: =AH31 -> 5879 | AI47: =AI31 -> 6478 | AJ47: =AJ31 -> 6090 | AK47: =AK31 -> 6017 | AL47: =SUM(AH47:AK47) -> 24464 | AM47: =AM31 -> 6000 | AN47: =AN31 -> 6000 | AO47: =AO31 -> 6000 | AP47: =AP31 -> 6000 | AQ47: =SUM(AM47:AP47) -> 24000
C48: Other | D48: =D125 -> 0 | E48: =E125 -> 0 | F48: =F125 -> 0 | G48: =G125 -> 0 | H48: =SUM(D48:G48) -> 0 | I48: =I125 -> 0 | J48: =J125 -> 0 | K48: =K125 -> -1057 | L48: =L125 -> 0 | M48: =SUM(I48:L48) -> -1057 | N48: =N125 -> 0 | Q48: 160 | R48: =SUM(N48:Q48) -> 160 | S48: 275 | T48: =+T32+135 -> 1319 | U48: =87+329 -> 416 | V48: =23+540 -> 563 | W48: =SUM(S48:V48) -> 2573 | X48: =1016+110 -> 1126 | Y48: =134+1574 -> 1708 | Z48: 175 | AA48: =51+500+74 -> 625 | AB48: =SUM(X48:AA48) -> 3634 | AC48: =193+199 -> 392 | AD48: =178+384 -> 562 | AE48: =95+143 -> 238 | AF48: =71+303+31+15213 -> 15618 | AG48: =SUM(AC48:AF48) -> 16810 | AH48: =150+565 -> 715 | AI48: =161+1581 -> 1742 | AJ48: =150+AJ32 -> 7173 | AK48: 139 | AL48: =SUM(AH48:AK48) -> 9769 | AQ48: =SUM(AM48:AP48) -> 0
...

Sheet BS
B2: =IS!B2 -> CS DISCO (LAW)
B4: Balance Sheet | D4: 1Q19 | E4: 2Q19 | F4: 3Q19 | G4: 4Q19 | H4: 2019 | I4: 1Q20 | J4: 2Q20 | K4: 3Q20 | L4: 4Q20 | M4: 2020 | N4: 1Q21 | O4: 2Q21 | P4: 3Q21 | Q4: 4Q21 | R4: 2021 | S4: 1Q22 | T4: 2Q22 | U4: 3Q22 | V4: 4Q22 | W4: 2022 | X4: =IS!X4 -> 1Q23 | Y4: =IS!Y4 -> 2Q23 | Z4: =IS!Z4 -> 3Q23 | AA4: =IS!AA4 -> 4Q23 | AB4: =IS!AB4 -> 2023 | AC4: =IS!AC4 -> 1Q24 | AD4: =IS!AD4 -> 2Q24 | AE4: =IS!AE4 -> 3Q24 | ... AQ4: =IS!AQ4 -> 2026E
B5: Assets:
C6: Cash & Cash Equivalents | D6: 43786 | E6: 40307 | F6: 33348 | G6: 23224 | H6: =G6 -> 23224 | I6: 29398 | J6: 24022 | K6: 78188 | L6: 58569 | M6: =L6 -> 58569 | N6: 53632 | O6: 47026 | P6: 258478 | Q6: 255477 | R6: =Q6 -> 255477 | S6: 238576 | T6: 228187 | U6: 213122 | V6: 203244 | W6: =V6 -> 203244 | X6: 187635 | Y6: 178919 | Z6: 157652 | AA6: 159551 | AB6: =AA6 -> 159551 | AC6: 148679 | AD6: 130005 | AE6: =76549+50245 -> 126794 | AF6: =52771+76356 -> 129127 | AG6: =AF6 -> 129127 | AH6: =34533+84278 -> 118811 | AI6: =21672+92672 -> 114344 | AJ6: =28804+84682 -> 113486 | AK6: =19655+94942 -> 114597 | AL6: =AK6 -> 114597 | AM6: =AL6+CF!AM51 -> 100786.59 | AN6: =AM6+CF!AN51 -> 99653.353 | AO6: =AN6+CF!AO51 -> 97358.69 | AP6: =AO6+CF!AP51 -> 97706.938 | AQ6: =AP6 -> 97706.938
C7: Accounts Receivable, Net | D7: 4592 | E7: 4926 | F7: 5026 | G7: 7362 | H7: =G7 -> 7362 | I7: 8114 | J7: 8631 | K7: 9942 | L7: 12912 | M7: =L7 -> 12912 | N7: 14952 | O7: 21195 | P7: 23180 | Q7: 20740 | R7: =Q7 -> 20740 | S7: 24930 | T7: 24309 | U7: 22204 | V7: 22720 | W7: =V7 -> 22720 | X7: 23851 | Y7: 24577 | Z7: 27103 | AA7: 26993 | AB7: =AA7 -> 26993 | AC7: 24501 | AD7: 25334 | AE7: 23988 | AF7: 23117 | AG7: =AF7 -> 23117 | AH7: 22326 | AI7: 23861 | AJ7: 24233 | AK7: 25622 | AL7: =AK7 -> 25622 | AM7: =AM50*IS!AM11 -> 29017.424 | AN7: =AN50*IS!AN11 -> 30881.467 | AO7: =AO50*IS!AO11 -> 32150.372 | AP7: =AP50*IS!AP11 -> 33973.258 | AQ7: =AP7 -> 33973.258
C8: Insurance Recovery Receivable | AJ8: 9240 | AK8: 8039 | AL8: =AK8 -> 8039 | AM8: =AL8 -> 8039 | AN8: =AM8 -> 8039 | AO8: =AN8 -> 8039 | AP8: =AO8 -> 8039 | AQ8: =AP8 -> 8039
C9: Other Current Assets | D9: 1736 | E9: 1354 | F9: 939 | G9: 1341 | H9: =G9 -> 1341 | I9: 1118 | J9: 1030 | K9: 1240 | L9: 1364 | M9: =L9 -> 1364 | N9: 1439 | O9: 4329 | P9: 6558 | Q9: 4634 | R9: =Q9 -> 4634 | S9: 3662 | T9: 2950 | U9: 6437 | V9: 5576 | W9: =V9 -> 5576 | X9: 4880 | Y9: 3717 | Z9: 6292 | AA9: 5795 | AB9: =AA9 -> 5795 | AC9: 5388 | AD9: 4812 | AE9: 6318 | AF9: 4692 | AG9: =AF9 -> 4692 | AH9: 4459 | AI9: 4566 | AJ9: 6103 | AK9: 4736 | AL9: =AK9 -> 4736 | AM9: =AM51*IS!AM$11 -> 5962.4844 | AN9: =AN51*IS!AN$11 -> 5499.4394 | AO9: =AO51*IS!AO$11 -> 7046.657 | AP9: =AP51*IS!AP$11 -> 6886.4712 | AQ9: =AP9 -> 6886.4712
B10: Total Current Assets | D10: =SUM(D6:D9) -> 50114 | E10: =SUM(E6:E9) -> 46587 | F10: =SUM(F6:F9) -> 39313 | G10: =SUM(G6:G9) -> 31927 | H10: =SUM(H6:H9) -> 31927 | I10: =SUM(I6:I9) -> 38630 | J10: =SUM(J6:J9) -> 33683 | K10: =SUM(K6:K9) -> 89370 | ... Q10: =SUM(Q6:Q9) -> 280851 | R10: =Q10 -> 280851 | S10: =SUM(S6:S9) -> 267168 | T10: =SUM(T6:T9) -> 255446 | U10: =SUM(U6:U9) -> 241763 | V10: =SUM(V6:V9) -> 231540 | W10: =V10 -> 231540 | X10: =SUM(X6:X9) -> 216366 | Y10: =SUM(Y6:Y9) -> 207213 | Z10: =SUM(Z6:Z9) -> 191047 | AA10: =SUM(AA6:AA9) -> 192339 | AB10: =AA10 -> 192339 | AC10: =SUM(AC6:AC9) -> 178568 | AD10: =SUM(AD6:AD9) -> 160151 | AE10: =SUM(AE6:AE9) -> 157100 | AF10: =SUM(AF6:AF9) -> 156936 | AG10: =AF10 -> 156936 | AH10: =SUM(AH6:AH9) -> 145596 | AI10: =SUM(AI6:AI9) -> 142771 | AJ10: =SUM(AJ6:AJ9) -> 153062 | AK10: =SUM(AK6:AK9) -> 152994 | AL10: =AK10 -> 152994 | AM10: =SUM(AM6:AM9) -> 143805.5 | AN10: =SUM(AN6:AN9) -> 144073.26 | AO10: =SUM(AO6:AO9) -> 144594.72 | AP10: =SUM(AP6:AP9) -> 146605.67 | AQ10: =AP10 -> 146605.67
C11: Property and Equipment, Net | D11: 1290 | E11: 2106 | F11: 2720 | G11: 3589 | H11: =G11 -> 3589 | I11: 3877 | J11: 3785 | K11: 3763 | L11: 3873 | M11: =L11 -> 3873 | N11: 4022 | O11: 4494 | P11: 4947 | Q11: 5335 | R11: =Q11 -> 5335 | S11: 5848 | T11: 7229 | U11: 7491 | V11: 7507 | W11: =V11 -> 7507 | X11: 7795 | Y11: 8638 | Z11: 9182 | AA11: 9663 | AB11: =AA11 -> 9663 | AC11: 9518 | AD11: 9232 | AE11: 9239 | AF11: 7878 | AG11: =AF11 -> 7878 | AH11: 7538 | AI11: 7665 | AJ11: 8030 | AK11: 7583 | AL11: =AK11 -> 7583 | AM11: =AL11-CF!AM29-CF!AM10 -> 7560.955 | AN11: =AM11-CF!AN29-CF!AN10 -> 7641.4452 | AO11: =AN11-CF!AO29-CF!AO10 -> 7712.679 | AP11: =AO11-CF!AP29-CF!AP10 -> 7775.7209 | AQ11: =AP11 -> 7775.7209
C12: Operating Lease Right-of-Use Assets | D12: 0 | E12: 0 | F12: 0 | G12: 0 | H12: =G12 -> 0 | I12: 2813 | J12: 2468 | K12: 2100 | L12: 1850 | M12: =L12 -> 1850 | N12: 1608 | O12: 1364 | P12: 1115 | Q12: 864 | R12: =Q12 -> 864 | S12: 609 | T12: 10937 | U12: 10293 | V12: 9824 | W12: =V12 -> 9824 | X12: 9606 | Y12: 9124 | Z12: 8637 | AA12: 8143 | AB12: =AA12 -> 8143 | AC12: 7878 | AD12: 7372 | AE12: 6859 | AF12: 8388 | AG12: =AF12 -> 8388 | AH12: 7832 | AI12: 7270 | AJ12: 6700 | AK12: 6121 | AL12: =AK12 -> 6121 | AM12: =AK12-500 -> 5621 | AN12: =AM12-500 -> 5121 | AO12: =AN12-500 -> 4621 | AP12: =AO12-500 -> 4121 | AQ12: =AP12 -> 4121
C13: Primary law intangible asset, net | Z13: 14000 | AA13: 14000 | AB13: =AA13 -> 14000 | AC13: 14000 | AD13: 14000 | AE13: 14000 | AF13: 0 | AG13: =AF13 -> 0 | AK13: 0 | AL13: =AK13 -> 0 | AM13: =AL13 -> 0 | AN13: =AM13 -> 0 | AO13: =AN13 -> 0 | AP13: =AO13 -> 0 | AQ13: =AP13 -> 0
C14: Intangible assets, net | H14: =G14 -> 0 | M14: =L14 -> 0 | R14: =Q14 -> 0 | S14: 1173 | T14: 1101 | U14: 1031 | V14: 962 | W14: =V14 -> 962 | X14: 891 | Y14: 821 | Z14: 751 | AA14: 681 | AB14: =AA14 -> 681 | AC14: 610 | AD14: 540 | AE14: 470 | AF14: 400 | AG14: =AF14 -> 400 | AH14: 341 | AI14: 296 | AJ14: 251 | AK14: 206 | AL14: =AK14 -> 206 | AM14: =AK14-70 -> 136 | AN14: =AL14-70 -> 136 | AO14: =AM14-70 -> 66 | AP14: =AN14-70 -> 66 | AQ14: =AP14 -> 66
C15: Goodwill | H15: =G15 -> 0 | M15: =L15 -> 0 | R15: =Q15 -> 0 | S15: 5898 | T15: 5898 | U15: 5898 | V15: 5898 | W15: =V15 -> 5898 | X15: 5898 | Y15: 5898 | Z15: 5898 | AA15: 5898 | AB15: =AA15 -> 5898 | AC15: 5898 | AD15: 5898 | AE15: 5898 | AF15: 5898 | AG15: =AF15 -> 5898 | AH15: 5898 | AI15: 5898 | AJ15: 5898 | AK15: 5898 | AL15: =AK15 -> 5898 | AM15: =AL15 -> 5898 | AN15: =AM15 -> 5898 | AO15: =AN15 -> 5898 | AP15: =AO15 -> 5898 | AQ15: =AP15 -> 5898
C16: Other Assets | D16: 224 | E16: 291 | F16: 278 | G16: 382 | H16: =G16 -> 382 | I16: 377 | J16: 341 | K16: 326 | L16: 539 | M16: =L16 -> 539 | N16: 535 | O16: 501 | P16: 534 | Q16: 351 | R16: =Q16 -> 351 | S16: 384 | T16: 737 | U16: 736 | V16: 591 | W16: =V16 -> 591 | X16: 721 | Y16: 721 | Z16: 730 | AA16: 823 | AB16: =AA16 -> 823 | AC16: 804 | AD16: 808 | AE16: 816 | AF16: 820 | AG16: =AF16 -> 820 | AH16: 825 | AI16: 827 | AJ16: 820 | AK16: 837 | AL16: =AK16 -> 837 | AM16: 535 | AN16: 535 | AO16: 535 | AP16: 535 | AQ16: =AP16 -> 535
B17: Total Assets | D17: =D10+SUM(D11:D16) -> 51628 | E17: =E10+SUM(E11:E16) -> 48984 | F17: =F10+SUM(F11:F16) -> 42311 | G17: =G10+SUM(G11:G16) -> 35898 | H17: =H10+SUM(H11:H16) -> 35898 | I17: =I10+SUM(I11:I16) -> 45697 | J17: =J10+SUM(J11:J16) -> 40277 | K17: =K10+SUM(K11:K16) -> 95559 | ... Q17: =Q10+SUM(Q11:Q16) -> 287401 | R17: =Q17 -> 287401 | S17: =S10+SUM(S11:S16) -> 281080 | T17: =T10+SUM(T11:T16) -> 281348 | U17: =U10+SUM(U11:U16) -> 267212 | V17: =V10+SUM(V11:V16) -> 256322 | W17: =V17 -> 256322 | X17: =X10+SUM(X11:X16) -> 241277 | Y17: =Y10+SUM(Y11:Y16) -> 232415 | Z17: =Z10+SUM(Z11:Z16) -> 230245 | AA17: =AA10+SUM(AA11:AA16) -> 231547 | AB17: =AA17 -> 231547 | AC17: =AC10+SUM(AC11:AC16) -> 217276 | AD17: =AD10+SUM(AD11:AD16) -> 198001 | AE17: =AE10+SUM(AE11:AE16) -> 194382 | AF17: =AF10+SUM(AF11:AF16) -> 180320 | AG17: =AF17 -> 180320 | AH17: =AH10+SUM(AH11:AH16) -> 168030 | AI17: =AI10+SUM(AI11:AI16) -> 164727 | AJ17: =AJ10+SUM(AJ11:AJ16) -> 174761 | AK17: =AK10+SUM(AK11:AK16) -> 173639 | AL17: =AK17 -> 173639 | AM17: =AM10+SUM(AM11:AM16) -> 163556.46 | AN17: =AN10+SUM(AN11:AN16) -> 163404.71 | AO17: =AO10+SUM(AO11:AO16) -> 163427.4 | AP17: =AP10+SUM(AP11:AP16) -> 165001.39 | AQ17: =AP17 -> 165001.39
B19: Liabilities:
C20: Accounts Payable | D20: 1240 | E20: 2479 | F20: 2432 | G20: 3986 | H20: =G20 -> 3986 | I20: 4170 | J20: 4878 | K20: 5269 | L20: 3588 | M20: =L20 -> 3588 | N20: 4267 | O20: 6144 | P20: 7953 | Q20: 4686 | R20: =Q20 -> 4686 | S20: 7545 | T20: 8565 | U20: 6843 | V20: 8485 | W20: =V20 -> 8485 | X20: 6545 | Y20: 5122 | Z20: 6485 | AA20: 5234 | AB20: =AA20 -> 5234 | AC20: 1995 | AD20: 4040 | AE20: 3410 | AF20: 3994 | AG20: =AF20 -> 3994 | AH20: 5409 | AI20: 3122 | AJ20: 2464 | AK20: 3888 | AL20: =AK20 -> 3888 | AM20: =AM56*IS!AM$11 -> 5564.9854 | AN20: =AN56*IS!AN$11 -> 5922.4732 | AO20: =AO56*IS!AO$11 -> 6165.8248 | AP20: =AP56*IS!AP$11 -> 6427.3731 | AQ20: =AP20 -> 6427.3731
C21: Accrued Expenses | D21: 567 | E21: 713 | F21: 798 | G21: 1080 | H21: =G21 -> 1080 | I21: 1654 | J21: 762 | K21: 660 | L21: 641 | M21: =L21 -> 641 | N21: 771 | O21: 2800 | P21: 3244 | Q21: 2844 | R21: =Q21 -> 2844 | S21: 3816 | T21: 4609 | U21: 4728 | V21: 4705 | W21: =V21 -> 4705 | X21: 3696 | Y21: 4386 | Z21: 4161 | AA21: 5502 | AB21: =AA21 -> 5502 | AC21: 6341 | AD21: 5457 | AE21: 5847 | AF21: 5947 | AG21: =AF21 -> 5947 | AH21: 3901 | AI21: 6187 | AJ21: 5189 | AK21: 6533 | AL21: =AK21 -> 6533 | AM21: =AM57*IS!AM$11 -> 5564.9854 | AN21: =AN57*IS!AN$11 -> 5922.4732 | AO21: =AO57*IS!AO$11 -> 6165.8248 | AP21: =AP57*IS!AP$11 -> 6656.9222 | AQ21: =AP21 -> 6656.9222
C22: Accrued legal loss contingency | AJ22: 15500 | AK22: 11500 | AL22: =AK22 -> 11500 | AM22: =AL22 -> 11500 | AN22: =AM22 -> 11500 | AO22: =AN22 -> 11500 | AP22: =AO22 -> 11500 | AQ22: =AP22 -> 11500
C23: Accrued Salary and Benefits | D23: 1174 | E23: 3549 | F23: 4002 | G23: 2723 | H23: =G23 -> 2723 | I23: 2465 | J23: 2810 | K23: 3959 | L23: 5240 | M23: =L23 -> 5240 | N23: 2945 | O23: 4858 | P23: 6775 | Q23: 7955 | R23: =Q23 -> 7955 | S23: 4503 | T23: 5817 | U23: 6337 | V23: 3536 | W23: =V23 -> 3536 | X23: 3952 | Y23: 5124 | Z23: 5526 | AA23: 6230 | AB23: =AA23 -> 6230 | AC23: 3134 | AD23: 5513 | AE23: 6816 | AF23: 9127 | AG23: =AF23 -> 9127 | AH23: 3692 | AI23: 5809 | AJ23: 7955 | AK23: 10457 | AL23: =AK23 -> 10457 | AM23: =AM58*IS!AM$11 -> 6757.4823 | AN23: =AN58*IS!AN$11 -> 7191.5746 | AO23: =AO58*IS!AO$11 -> 7266.865 | AP23: =AP58*IS!AP$11 -> 7804.6674 | AQ23: =AP23 -> 7804.6674
C24: Current Portion of Revolving Line of Credit | D24: 0 | E24: 0 | F24: 0 | G24: 0 | I24: 0 | J24: 17000 | K24: 17000 | L24: 0 | N24: 0 | O24: 0 | P24: 0 | Q24: 0 | S24: 0 | T24: 0 | U24: 0 | V24: 0 | X24: 0 | Z24: 0 | AA24: 0 | AC24: 0 | AM24: 0 | AN24: 0 | AO24: 0 | AP24: 0
C25: Deferred Revenue | D25: 801 | E25: 681 | F25: 646 | G25: 1418 | H25: =G25 -> 1418 | I25: 1537 | J25: 1339 | K25: 1101 | L25: 1642 | M25: =L25 -> 1642 | N25: 2752 | O25: 1489 | P25: 1575 | Q25: 2175 | R25: =Q25 -> 2175 | S25: 3035 | T25: 2690 | U25: 2741 | V25: 4100 | W25: =V25 -> 4100 | X25: 4169 | Y25: 3310 | Z25: 2966 | AA25: 4285 | AB25: =AA25 -> 4285 | AC25: 3501 | AD25: 3518 | AE25: 3042 | AF25: 4296 | AG25: =AF25 -> 4296 | AH25: 3905 | AI25: 3493 | AJ25: 4272 | AK25: 5382 | AL25: =AK25 -> 5382 | AM25: =AM59*IS!AM$11 -> 3974.9896 | AN25: =AN59*IS!AN$11 -> 4230.338 | AO25: =AO59*IS!AO$11 -> 4404.1606 | AP25: =AP59*IS!AP$11 -> 5050.0789 | AQ25: =AP25 -> 5050.0789
C26: Operating Leases | D26: 0 | E26: 0 | F26: 0 | G26: 0 | I26: 1271 | J26: 1158 | K26: 1016 | L26: 1018 | N26: 1031 | O26: 1045 | P26: 1059 | Q26: 890 | R26: =Q26 -> 890 | S26: 627 | T26: 1229 | U26: 1599 | V26: 1902 | W26: =V26 -> 1902 | X26: 1981 | Y26: 1982 | Z26: 1905 | AA26: 1826 | AB26: =AA26 -> 1826 | AC26: 1983 | AD26: 1905 | AE26: 1823 | AF26: 2288 | AG26: =AF26 -> 2288 | AH26: 2460 | AI26: 2514 | AJ26: 2569 | AK26: 2624 | AL26: =AK26 -> 2624 | AM26: =AK26-80 -> 2544 | AN26: =AM26-80 -> 2464 | AO26: =AN26-80 -> 2384 | AP26: =AO26-80 -> 2304 | AQ26: =AP26 -> 2304
C27: Finance Leases | D27: 0 | E27: 0 | F27: 0 | G27: 0 | H27: =G27 -> 0 | I27: 107 | J27: 109 | K27: 111 | L27: 112 | M27: =L27 -> 112 | N27: 114 | O27: 116 | P27: 117 | Q27: 99 | R27: =Q27 -> 99 | S27: 70 | T27: 39 | U27: 31 | V27: 39 | W27: =V27 -> 39 | X27: 40 | Y27: 40 | Z27: =Y27 -> 40 | AA27: 41 | AB27: =AA27 -> 41 | AC27: 41 | AD27: 41 | AE27: 42 | AF27: 42 | AG27: =AF27 -> 42 | AH27: 43 | AI27: 43 | AJ27: 43 | AK27: 44 | AL27: =AK27 -> 44 | AM27: =AL27 -> 44 | AN27: =AM27 -> 44 | AO27: =AN27 -> 44 | AP27: =AO27 -> 44 | AQ27: =AP27 -> 44
B28: Total Current Liabilities | D28: =SUM(D20:D27) -> 3782 | E28: =SUM(E20:E27) -> 7422 | F28: =SUM(F20:F27) -> 7878 | G28: =SUM(G20:G27) -> 9207 | H28: =SUM(H20:H27) -> 9207 | I28: =SUM(I20:I27) -> 11204 | J28: =SUM(J20:J27) -> 28056 | K28: =SUM(K20:K27) -> 29116 | ... AQ28: =SUM(AQ20:AQ27) -> 39787.042
C29: Long-term Debt | D29: 0 | E29: 0 | F29: 0 | G29: 0 | H29: =G29 -> 0 | I29: 17000 | J29: 0 | K29: 0 | L29: 0 | M29: =L29 -> 0 | N29: 0 | O29: =N29 -> 0 | P29: =O29 -> 0 | Q29: =P29 -> 0 | R29: =Q29 -> 0 | S29: =R29 -> 0 | T29: =S29 -> 0 | U29: =T29 -> 0 | V29: =U29 -> 0 | ... AD29: =AC29 -> 0 | AE29: 0 | AF29: =AE29 -> 0 | AG29: =AF29 -> 0 | AH29: =AG29 -> 0 | AK29: =AJ29 -> 0 | AL29: =AK29 -> 0 | AM29: =AL29 -> 0 | AN29: =AM29 -> 0 | AO29: =AN29 -> 0 | AP29: =AO29 -> 0 | AQ29: =AP29 -> 0
C30: Debt Issuance Costs | D30: 0 | E30: 0 | F30: 0 | G30: 0 | H30: =G30 -> 0 | I30: 0 | J30: 0 | K30: 0 | L30: 0 | M30: =L30 -> 0 | N30: 0 | O30: =N30 -> 0 | P30: =O30 -> 0 | Q30: =P30 -> 0 | R30: =Q30 -> 0 | S30: =R30 -> 0 | T30: =S30 -> 0 | U30: =T30 -> 0 | V30: =U30 -> 0 | ... AD30: =AC30 -> 0 | AE30: 0 | AF30: =AE30 -> 0 | AG30: =AF30 -> 0 | AH30: =AG30 -> 0 | AK30: =AJ30 -> 0 | AL30: =AK30 -> 0 | AM30: =AL30 -> 0 | AN30: =AM30 -> 0 | AO30: =AN30 -> 0 | AP30: =AO30 -> 0 | AQ30: =AP30 -> 0
C31: Operating Lease, Noncurrent | D31: 0 | E31: 0 | F31: 0 | G31: 0 | H31: =G31 -> 0 | I31: 1658 | J31: 1405 | K31: 1149 | L31: 890 | M31: =L31 -> 890 | N31: 627 | O31: 361 | P31: 91 | Q31: 0 | R31: =Q31 -> 0 | S31: 0 | T31: 9711 | U31: 9219 | V31: 8770 | W31: =V31 -> 8770 | X31: 8449 | Y31: 7969 | Z31: 7560 | AA31: 7136 | AB31: =AA31 -> 7136 | AC31: 6702 | AD31: 6262 | AE31: 5817 | AF31: 6855 | AG31: =AF31 -> 6855 | AH31: 6216 | AI31: 5566 | AJ31: 4908 | AK31: 4231 | AL31: =AK31 -> 4231 | AM31: =AK31-440 -> 3791 | AN31: =AM31-440 -> 3351 | AO31: =AN31-440 -> 2911 | AP31: =AO31-440 -> 2471 | AQ31: =AP31 -> 2471
C32: Financing Lease, Noncurrent | D32: 0 | E32: 0 | F32: 0 | G32: 0 | I32: 183 | J32: 156 | K32: 127 | L32: 99 | N32: 70 | O32: 40 | P32: 10 | Q32: 0 | R32: =Q32 -> 0 | S32: =R32 -> 0 | T32: 219 | U32: 209 | V32: 199 | W32: =V32 -> 199 | X32: 189 | Y32: 179 | Z32: 169 | AA32: 158 | AB32: =AA32 -> 158 | AC32: 148 | AD32: 137 | AE32: 127 | AF32: 116 | AG32: =AF32 -> 116 | AH32: 105 | AI32: 94 | AJ32: 83 | AK32: 72 | AL32: =AK32 -> 72 | AM32: =AL32 -> 72 | AN32: =AM32 -> 72 | AO32: =AN32 -> 72 | AP32: =AO32 -> 72 | AQ32: =AP32 -> 72
C33: Other Liabilities | D33: 121 | E33: 336 | F33: 361 | G33: 270 | H33: =G33 -> 270 | I33: 0 | J33: 0 | K33: 1 | L33: 0 | M33: =L33 -> 0 | N33: 0 | O33: =N33 -> 0 | P33: =O33 -> 0 | Q33: 75 | R33: =Q33 -> 75 | S33: 653 | T33: 631 | U33: 723 | V33: 950 | W33: =V33 -> 950 | X33: 458 | Y33: 424 | Z33: 389 | AA33: 800 | AB33: =AA33 -> 800 | AC33: 278 | AD33: 238 | AE33: 199 | AF33: 141 | AG33: =AF33 -> 141 | AH33: 127 | AI33: 149 | AJ33: 148 | AK33: 601 | AL33: =AK33 -> 601 | AM33: =AL33 -> 601 | AN33: =AM33 -> 601 | AO33: =AN33 -> 601 | AP33: =AO33 -> 601 | AQ33: =AP33 -> 601
B34: Total Liabilities | D34: =D28+SUM(D29:D33) -> 3903 | E34: =E28+SUM(E29:E33) -> 7758 | F34: =F28+SUM(F29:F33) -> 8239 | G34: =G28+SUM(G29:G33) -> 9477 | H34: =H28+SUM(H29:H33) -> 9477 | I34: =I28+SUM(I29:I33) -> 30045 | J34: =J28+SUM(J29:J33) -> 29617 | K34: =K28+SUM(K29:K33) -> 30393 | ... AQ34: =AQ28+SUM(AQ29:AQ33) -> 42931.042
B36: Shareholders Equity:
C37: Total Shareholder Equity | D37: =D17-D34 -> 47725 | E37: =E17-E34 -> 41226 | F37: =F17-F34 -> 34072 | G37: =G17-G34 -> 26421 | H37: =G37 -> 26421 | I37: =I17-I34 -> 15652 | J37: =J17-J34 -> 10660 | K37: =K17-K34 -> 65166 | L37: =L17-L34 -> 65877 | M37: =L37 -> 65877 | N37: =N17-N34 -> 63611 | O37: =O17-O34 -> 62056 | P37: =P17-P34 -> 273988 | Q37: =Q17-Q34 -> 268677 | R37: =Q37 -> 268677 | S37: =S17-S34 -> 260831 | T37: =T17-T34 -> 247838 | U37: =U17-U34 -> 234782 | V37: =V17-V34 -> 223636 | W37: =V37 -> 223636 | X37: =X17-X34 -> 211798 | Y37: =Y17-Y34 -> 203879 | Z37: =Z17-Z34 -> 201044 | AA37: =AA17-AA34 -> 200335 | AB37: =AA37 -> 200335 | AC37: =AC17-AC34 -> 193153 | AD37: =AD17-AD34 -> 170890 | AE37: =AE17-AE34 -> 167259 | AF37: =AF17-AF34 -> 147514 | AG37: =AF37 -> 147514 | AH37: =AH17-AH34 -> 142172 | AI37: =AI17-AI34 -> 137750 | AJ37: =AJ17-AJ34 -> 131630 | AK37: =AK17-AK34 -> 128307 | AL37: =AK37 -> 128307 | AM37: =AM17-AM34 -> 123142.02 | AN37: =AN17-AN34 -> 122105.85 | AO37: =AO17-AO34 -> 121912.72 | AP37: =AP17-AP34 -> 122070.35 | AQ37: =AP37 -> 122070.35
B38: Total Liabilities & Shareholders Equity | D38: =D37+D34 -> 51628 | E38: =E37+E34 -> 48984 | F38: =F37+F34 -> 42311 | G38: =G37+G34 -> 35898 | H38: =G38 -> 35898 | I38: =I37+I34 -> 45697 | J38: =J37+J34 -> 40277 | K38: =K37+K34 -> 95559 | L38: =L37+L34 -> 79107 | M38: =L38 -> 79107 | N38: =N37+N34 -> 76188 | O38: =O37+O34 -> 78909 | P38: =P37+P34 -> 294812 | Q38: =Q37+Q34 -> 287401 | R38: =Q38 -> 287401 | S38: =S37+S34 -> 281080 | T38: =T37+T34 -> 281348 | U38: =U37+U34 -> 267212 | V38: =V37+V34 -> 256322 | W38: =V38 -> 256322 | X38: =X37+X34 -> 241277 | Y38: =Y37+Y34 -> 232415 | Z38: =Z37+Z34 -> 230245 | AA38: =AA37+AA34 -> 231547 | AB38: =AA38 -> 231547 | AC38: =AC37+AC34 -> 217276 | AD38: =AD37+AD34 -> 198001 | AE38: =AE37+AE34 -> 194382 | AF38: =AF37+AF34 -> 180320 | AG38: =AF38 -> 180320 | AH38: =AH37+AH34 -> 168030 | AI38: =AI37+AI34 -> 164727 | AJ38: =AJ37+AJ34 -> 174761 | AK38: =AK37+AK34 -> 173639 | AL38: =AK38 -> 173639 | AM38: =AM37+AM34 -> 163556.46 | AN38: =AN37+AN34 -> 163404.71 | AO38: =AO37+AO34 -> 163427.4 | AP38: =AP37+AP34 -> 165001.39 | AQ38: =AP38 -> 165001.39
B39: Scott Berg, sberg@needhamco.com | AB39: Source: Company Reports and Needham & Company, LLC Estimates | AG39: Source: Company Reports and Needham & Company, LLC Estimates | AL39: Source: Company Reports and Needham & Company, LLC Estimates | AQ39: Source: Company Reports and Needham & Company, LLC Estimates
B40: 763.350.4027 | AB40: $ in thousands, except per share data | AG40: $ in thousands, except per share data | AL40: $ in thousands, except per share data | AQ40: $ in thousands, except per share data
C41: check | D41: =D17-D38 -> 0 | E41: =E17-E38 -> 0 | F41: =F17-F38 -> 0 | G41: =G17-G38 -> 0 | H41: =H17-H38 -> 0 | I41: =I17-I38 -> 0 | J41: =J17-J38 -> 0 | K41: =K17-K38 -> 0 | ... AQ41: =AQ17-AQ38 -> 0
C43: DSO | D43: =((D7+#REF!)/2)/IS!D11*91 -> #REF! | E43: =((E7+D7)/2)/IS!E11*91 -> 38.30774 | F43: =((F7+E7)/2)/IS!F11*91 -> 35.790073 | G43: =((G7+F7)/2)/IS!G11*91 -> 39.635328 | I43: =((I7+H7)/2)/IS!I11*91 -> 44.94243 | J43: =((J7+I7)/2)/IS!J11*91 -> 48.44519 | K43: =((K7+J7)/2)/IS!K11*91 -> 47.308487 | L43: =((L7+K7)/2)/IS!L11*91 -> 54.198739 | N43: =((N7+M7)/2)/IS!N11*91 -> 59.997728 | O43: =((O7+N7)/2)/IS!O11*91 -> 55.663468 | P43: =((P7+O7)/2)/IS!P11*91 -> 67.631222 | Q43: =((Q7+P7)/2)/IS!Q11*91 -> 59.10559 | S43: =((S7+R7)/2)/IS!S11*91 -> 60.287368 | T43: =((T7+S7)/2)/IS!T11*91 -> 66.460234 | U43: =((U7+T7)/2)/IS!U11*91 -> 61.387716 | V43: =((V7+U7)/2)/IS!V11*91 -> 62.822079 | X43: =((X7+W7)/2)/IS!X11*91 -> 63.961499 | Y43: =((Y7+X7)/2)/IS!Y11*91 -> 64.286206 | Z43: =((Z7+Y7)/2)/IS!Z11*91 -> 67.293592 | AA43: =((AA7+Z7)/2)/IS!AA11*91 -> 68.864865 | AC43: =((AC7+AB7)/2)/IS!AC11*91 -> 65.867617 | AD43: =((AD7+AC7)/2)/IS!AD11*91 -> 62.977156 | AE43: =((AE7+AD7)/2)/IS!AE11*91 -> 61.880301 | AF43: =((AF7+AE7)/2)/IS!AF11*91 -> 57.927985 | AH43: =((AH7+AG7)/2)/IS!AH11*91 -> 56.411658 | AI43: =((AI7+AH7)/2)/IS!AI11*91 -> 55.149019 | AJ43: =((AJ7+AI7)/2)/IS!AJ11*91 -> 53.478262 | AK43: =((AK7+AJ7)/2)/IS!AK11*91 -> 55.097095 | AM43: =((AM7+AL7)/2)/IS!AM11*91 -> 62.543404 | AN43: =((AN7+AM7)/2)/IS!AN11*91 -> 64.425102 | AO43: =((AO7+AN7)/2)/IS!AO11*91 -> 65.119076 | AP43: =((AP7+AO7)/2)/IS!AP11*91 -> 65.533386
B45: Deferred Revs | D45: =D25 -> 801 | E45: =E25 -> 681 | F45: =F25 -> 646 | G45: =G25 -> 1418 | I45: =I25 -> 1537 | J45: =J25 -> 1339 | K45: =K25 -> 1101 | L45: =L25 -> 1642 | N45: =N25 -> 2752 | O45: =O25 -> 1489 | P45: =P25 -> 1575 | Q45: =Q25 -> 2175 | S45: =S25 -> 3035 | T45: =T25 -> 2690 | U45: =U25 -> 2741 | V45: =V25 -> 4100 | X45: =X25 -> 4169 | Y45: =Y25 -> 3310 | Z45: =Z25 -> 2966 | AA45: =AA25 -> 4285 | AC45: =AC25 -> 3501 | AD45: =AD25 -> 3518 | AE45: =AE25 -> 3042 | AF45: =AF25 -> 4296 | AH45: =AH25 -> 3905 | AI45: =AI25 -> 3493 | AJ45: =AJ25 -> 4272 | AK45: =AK25 -> 5382 | AM45: =AM25 -> 3974.9896 | AN45: =AN25 -> 4230.338 | AO45: =AO25 -> 4404.1606 | AP45: =AP25 -> 5050.0789
C46: % y/y change | I46: =I45/D45-1 -> 0.91885144 | J46: =J45/E45-1 -> 0.96622614 | K46: =K45/F45-1 -> 0.70433437 | L46: =L45/G45-1 -> 0.15796897 | N46: =N45/I45-1 -> 0.79050098 | O46: =O45/J45-1 -> 0.1120239 | P46: =P45/K45-1 -> 0.43051771 | Q46: =Q45/L45-1 -> 0.32460414 | S46: =S45/N45-1 -> 0.1028343 | T46: =T45/O45-1 -> 0.8065816 | U46: =U45/P45-1 -> 0.74031746 | V46: =V45/Q45-1 -> 0.88505747 | X46: =X45/S45-1 -> 0.37364086 | Y46: =Y45/T45-1 -> 0.23048327 | Z46: =Z45/U45-1 -> 0.08208683 | AA46: =AA45/V45-1 -> 0.045121951 | AC46: =AC45/X45-1 -> -0.16023027 | AD46: =AD45/Y45-1 -> 0.062839879 | AE46: =AE45/Z45-1 -> 0.025623736 | AF46: =AF45/AA45-1 -> 0.0025670945 | AH46: =AH45/AC45-1 -> 0.1153956 | AI46: =AI45/AD45-1 -> -0.0071063104 | AJ46: =AJ45/AE45-1 -> 0.40433925 | AK46: =AK45/AF45-1 -> 0.2527933 | AM46: =AM45/AH45-1 -> 0.017923073 | AN46: =AN45/AI45-1 -> 0.21109018 | AO46: =AO45/AJ45-1 -> 0.03093647 | AP46: =AP45/AK45-1 -> -0.061672449
...

Sheet CF
B2: =IS!B2 -> CS DISCO (LAW) | T2: =+T25-S25 -> 590 | U2: =U25-P25 -> -5856 | AJ2: =AJ25-AE25 -> 1878 | AK2: =AK25-AF25 -> -1326
B4: Cash Flow Statement | D4: 1Q19 | E4: 2Q19 | F4: 3Q19 | G4: 4Q19 | H4: 2019 | I4: 1Q20 | J4: 2Q20 | K4: 3Q20 | L4: 4Q20 | M4: =IS!M4 -> 2020 | N4: =IS!N4 -> 1Q21 | O4: =IS!O4 -> 2Q21 | P4: =IS!P4 -> 3Q21 | Q4: =IS!Q4 -> 4Q21 | R4: =IS!R4 -> 2021 | S4: =IS!S4 -> 1Q22 | T4: =IS!T4 -> 2Q22 | ... AQ4: =IS!AQ4 -> 2026E
B5: Operating Activities
B7: Net loss | D7: =IS!D62 -> -6952 | E7: =IS!E62 -> -7051 | F7: =IS!F62 -> -7661 | G7: =IS!G62 -> -8168 | H7: =IS!H62 -> -29832 | I7: =IS!I62 -> -11236 | J7: =IS!J62 -> -5477 | K7: =IS!K62 -> -3169 | ... Q7: =IS!Q62 -> -9108 | R7: =SUM(N7:Q7) -> -24344 | S7: =IS!S62 -> -11849 | T7: =+-32020-S7 -> -20171 | U7: =-52077-T7-S7 -> -20057 | V7: =-70765-U7-T7-S7 -> -18688 | W7: =SUM(S7:V7) -> -70765 | X7: -20365 | Y7: =+-35280-X7 -> -14915 | Z7: =+-36310-Y7-X7 -> -1030 | AA7: =+-42150-Z7-Y7-X7 -> -5840 | AB7: =SUM(X7:AA7) -> -42150 | AC7: =IS!AC62 -> -10582 | AD7: =IS!AD62 -> -10834 | AE7: =IS!AE62 -> -9158 | AF7: =IS!AF62 -> -25200 | AG7: -55774 | AH7: =IS!AH62 -> -11393 | AI7: =IS!AI62 -> -10812 | AJ7: =IS!AJ62 -> -13665 | AK7: =IS!AK62 -> -8502 | AL7: =SUM(AH7:AK7) -> -44372 | AM7: =IS!AM62 -> -11061.985 | AN7: =IS!AN62 -> -7319.169 | AO7: =IS!AO62 -> -6423.1234 | AP7: =IS!AP62 -> -6160.3765 | AQ7: =SUM(AM7:AP7) -> -30964.654
R8: =SUM(N8:Q8) -> 0 | W8: =SUM(S8:V8) -> 0 | AB8: =SUM(X8:AA8) -> 0 | AQ8: =SUM(AM8:AP8) -> 0
B9: Adjustments to reconcile net cash
C10: Depreciation & Amortization | D10: 120 | E10: 176 | F10: 247 | G10: 260 | H10: =SUM(D10:G10) -> 803 | I10: 378 | J10: 421 | K10: 415 | L10: 410 | M10: =SUM(I10:L10) -> 1624 | N10: 424 | O10: =830-N10 -> 406 | P10: =1254-O10-N10 -> 424 | Q10: =1674-P10-O10-N10 -> 420 | R10: =SUM(N10:Q10) -> 1674 | S10: 455 | T10: =1155-S10 -> 700 | U10: =2079-T10-S10 -> 924 | V10: =2974-U10-T10-S10 -> 895 | W10: =SUM(S10:V10) -> 2974 | X10: 952 | Y10: =1957-X10 -> 1005 | Z10: =3011-Y10-X10 -> 1054 | AA10: =4159-Z10-Y10-X10 -> 1148 | AB10: =SUM(X10:AA10) -> 4159 | AC10: 1075 | AD10: =2103-AC10 -> 1028 | AE10: 989 | AF10: =AG10-SUM(AC10:AE10) -> 834 | AG10: 3926 | AH10: 927 | AI10: 902 | AJ10: 902 | AK10: =AL10-SUM(AH10:AJ10) -> 927 | AL10: 3658 | AM10: =AM58 -> 872.045 | AN10: =AN58 -> 869.50982 | AO10: =AO58 -> 878.7662 | AP10: =AP58 -> 886.95808 | AQ10: =SUM(AM10:AP10) -> 3507.2791
C11: Stock-based compensation | D11: 2638 | E11: 531 | F11: 456 | G11: 495 | H11: =SUM(D11:G11) -> 4120 | I11: 488 | J11: 500 | K11: 502 | L11: 503 | M11: =SUM(I11:L11) -> 1993 | N11: 488 | O11: =1454-N11 -> 966 | P11: =2508-O11-N11 -> 1054 | Q11: =5603-P11-O11-N11 -> 3095 | R11: =SUM(N11:Q11) -> 5603 | S11: 3206 | T11: =8728-S11 -> 5522 | U11: =14393-T11-S11 -> 5665 | V11: =21737-U11-T11-S11 -> 7344 | W11: =SUM(S11:V11) -> 21737 | X11: 7224 | Y11: =14092-X11 -> 6868 | Z11: =11211-Y11-X11 -> -2881 | AA11: =16158-Z11-Y11-X11 -> 4947 | AB11: =SUM(X11:AA11) -> 16158 | AC11: 5673 | AD11: =11731-AC11 -> 6058 | AE11: 5147 | AF11: =AG11-SUM(AC11:AE11) -> 5391 | AG11: 22269 | AH11: 5879 | AI11: 6478 | AJ11: 6090 | AK11: =AL11-SUM(AH11:AJ11) -> 6017 | AL11: 24464 | AM11: =IS!AM31 -> 6000 | AN11: =IS!AN31 -> 6000 | AO11: =IS!AO31 -> 6000 | AP11: =IS!AP31 -> 6000 | AQ11: =SUM(AM11:AP11) -> 24000
C12: Charge to Allowance for Credit Losses | D12: 89 | E12: 89 | F12: 89 | G12: 89 | H12: =SUM(D12:G12) -> 356 | I12: 135 | J12: 115 | K12: 77 | L12: 124 | M12: =SUM(I12:L12) -> 451 | N12: 130 | O12: =251-N12 -> 121 | P12: =517-O12-N12 -> 266 | Q12: =833-P12-O12-N12 -> 316 | R12: =SUM(N12:Q12) -> 833 | S12: 180 | T12: =367-S12 -> 187 | U12: =853-T12-S12 -> 486 | V12: =1294-U12-T12-S12 -> 441 | W12: =SUM(S12:V12) -> 1294 | X12: 831 | Y12: =1356-X12 -> 525 | Z12: =1801-Y12-X12 -> 445 | AA12: =2432-Z12-Y12-X12 -> 631 | AB12: =SUM(X12:AA12) -> 2432 | AC12: 564 | AD12: =1126-AC12 -> 562 | AE12: 933 | AF12: =AG12-SUM(AC12:AE12) -> 53 | AG12: 2112 | AH12: 534 | AI12: 563 | AJ12: 577 | AK12: =AL12-SUM(AH12:AJ12) -> 213 | AL12: 1887 | AM12: 257 | AN12: 271 | AO12: 288 | AP12: 306 | AQ12: =SUM(AM12:AP12) -> 1122
