Workbook
Name _15__xlnm.Print_Area: #N/A
Name _1994: #REF!
Name _1994: #REF!
Name _1995: #REF!
Name _1995: #REF!
Name _1996: #REF!
Name _1996: #REF!
Name _1997: #REF!
Name _1997: #REF!
Name _1998: #REF!
Name _1998: #REF!
Name _1999: #REF!
Name _1999: #REF!
Name _1Q94: #REF!
Name _1Q94: #REF!
Name _1Q95: #REF!
Name _1Q95: #REF!
Name _2007: [1]BalanceSheet!#REF!
Name _2007: [1]BalanceSheet!#REF!
Name _2008: [1]BalanceSheet!#REF!
Name _2008: [1]BalanceSheet!#REF!
Name _2Q94: #REF!
Name _2Q94: #REF!
Name _2Q95: #REF!
Name _2Q95: #REF!
Name _3Q94: #REF!
Name _3Q94: #REF!
Name _3Q95: #REF!
Name _3Q95: #REF!
Name _4Q94: #REF!
Name _4Q94: #REF!
Name _4Q95: #REF!
Name _4Q95: #REF!
Name _dcf2: [2]Sheet15!#REF!
Name _Key1: [3]BMY!#REF!
Name _Key1: [3]BMY!#REF!
Name _Order1: 0
Name _Sort: [3]BMY!#REF!
Name _Sort: [3]BMY!#REF!
Name _top4: #REF!
Name a: [4]NOPAT_VDF!$C$90:$AE$90
Name a: [5]NOPAT_VDF!$C$90:$AE$90
Name a: [6]NOPAT_VDF!$C$90:$AE$90
Name abit: 0.000000001
Name Acc_payable: '[7]Invested capital_VDF'!$C$17:$AE$17
Name Acc_payable: '[6]Invested capital_VDF'!$C$17:$AE$17
Name Acc_payable_growth_fore: [4]Forecasts_VDF!$H$150:$K$150
Name Acc_payable_growth_fore: [5]Forecasts_VDF!$H$150:$K$150
Name Acc_payable_growth_fore: [6]Forecasts_VDF!$H$150:$K$150
Name Acc_Rec: '[7]Invested capital_VDF'!$C$7:$AE$7
Name Acc_Rec: '[5]Invested capital_VDF'!$C$7:$AE$7
Name Acc_Rec: '[6]Invested capital_VDF'!$C$7:$AE$7
Name Acc_Rec_growth_fore: [4]Forecasts_VDF!$H$147:$K$147
Name Acc_Rec_growth_fore: [5]Forecasts_VDF!$H$147:$K$147
Name Acc_Rec_growth_fore: [6]Forecasts_VDF!$H$147:$K$147
Name Acc_Rec_turns: '[7]Invested capital_VDF'!$C$95:$Q$95
Name Acc_Rec_turns: '[5]Invested capital_VDF'!$C$95:$Q$95
Name Acc_Rec_turns: '[6]Invested capital_VDF'!$C$95:$Q$95
Name Accel_Ratio: '[7]Summary Page_VDF'!$E$9
Name Accel_Ratio: '[5]Summary Page_VDF'!$E$9

Sheet __FDSCACHE__
B1: This sheet contains FactSet XML data for use with this workbook's =FDS codes. Modifying the worksheet's contents may damage the workbook's =FDS functionality.

Sheet Intro
A1: 46070
C5: NeoGenomics
C6: Nasdaq: NEO
C8: Tycho Peterson
C9: Life Science Tools & Diagnostics
C10: 212.738.5583
C11: tpeterson2@jefferies.com
C13: Matt Stanton
C14: 615.963.8397
C15: mstanton@jefferies.com
C17: Jack Melick
C18: 617.345.8671
C19: jmelick@jefferies.com
... C31: ppatel5@jefferies.com

Sheet IS
EY2: =Intro!C5 -> NeoGenomics
EY3: Historical and Projected Statements of Income
EY4: Dollars in millions, except per share amounts
D5: Historical results | J5: Historical results | P5: Historical results | V5: Historical results | AB5: Historical results | AH5: Historical results | AN5: Historical results | AT5: Historical results | AZ5: Historical results | BF5: Historical results | BL5: Historical results | BR5: Historical results | BX5: Historical results | CD5: Historical results | CJ5: Historical results | CP5: Historical results | CV5: Historical results | DB5: Historical results | DH5: Historical results | DN5: Historical results | DT5: Historical results | DZ5: Historical results | EF5: Historical results | EL5: Historical results | ER5: Historical results | EX5: Historical results | FD5: Projections | FJ5: Projections | FP5: Projections | FV5: Projections | GB5: Projections | GH5: Projections | GN5: Projections | GT5: Projections | GZ5: Projections | HF5: Projections
D6: 2000 | J6: 2001 | P6: 2002 | V6: 2003 | AB6: 2004 | AH6: 2005 | AN6: 2006 | AT6: 2007 | AZ6: 2008 | BF6: 2009 | BL6: 2010 | BR6: 2011 | BX6: 2012 | CD6: 2013 | CJ6: 2014 | CP6: 2015 | CV6: 2016 | DB6: 2017 | DH6: 2018 | DN6: 2019 | DT6: 2020 | DZ6: 2021 | EF6: 2022 | EL6: 2023 | ER6: =EL6+1 -> 2024 | EX6: =ER6+1 -> 2025 | FD6: =EX6+1 -> 2026 | FJ6: =FD6+1 -> 2027 | FP6: =FJ6+1 -> 2028 | FV6: =FP6+1 -> 2029 | GB6: =FV6+1 -> 2030 | GH6: =GB6+1 -> 2031 | GN6: =GH6+1 -> 2032 | GT6: =GN6+1 -> 2033 | GZ6: =GT6+1 -> 2034 | HF6: =GZ6+1 -> 2035
D7: 36616 | E7: 36707 | F7: 36799 | G7: 36891 | H7: Total | J7: 36981 | K7: 37072 | L7: 37164 | M7: 37256 | N7: Total | P7: 37346 | Q7: 37437 | R7: 37529 | S7: 37621 | T7: Total | V7: 37711 | W7: 37802 | X7: 37894 | Y7: 37986 | Z7: Total | AB7: 38077 | AC7: 38168 | AD7: 38260 | AE7: 38352 | AF7: Total | AH7: 38442 | AI7: 38533 | AJ7: 38625 | AK7: 38717 | AL7: Total | AN7: =AH7+365 -> 38807 | AO7: =AI7+365 -> 38898 | AP7: =AJ7+365 -> 38990 | AQ7: =AK7+365 -> 39082 | AR7: Total | AT7: =AN7+365 -> 39172 | AU7: =AO7+365 -> 39263 | AV7: =AP7+365 -> 39355 | AW7: =AQ7+365 -> 39447 | AX7: Total | AZ7: =AT7+365 -> 39537 | BA7: =AU7+365 -> 39628 | BB7: =AV7+365 -> 39720 | BC7: =AW7+365 -> 39812 | BD7: Total | BF7: =AZ7+365 -> 39902 | BG7: =BA7+365 -> 39993 | BH7: =BB7+365 -> 40085 | BI7: =BC7+365 -> 40177 | BJ7: Total | BL7: =BF7+365 -> 40267 | BM7: =BG7+365 -> 40358 | BN7: =BH7+365 -> 40450 | BO7: =BI7+365 -> 40542 | BP7: Total | BR7: =BL7+365 -> 40632 | BS7: =BM7+365 -> 40723 | BT7: =BN7+365 -> 40815 | BU7: =BO7+365 -> 40907 | BV7: Total | BX7: =BR7+365 -> 40997 | BY7: =BS7+365 -> 41088 | BZ7: =BT7+365 -> 41180 | CA7: =BU7+365 -> 41272 | CB7: Total | CD7: =BX7+365 -> 41362 | CE7: =BY7+365 -> 41453 | CF7: =BZ7+365 -> 41545 | CG7: =CA7+365 -> 41637 | CH7: Total | CJ7: =CD7+365 -> 41727 | CK7: =CE7+365 -> 41818 | CL7: =CF7+365 -> 41910 | CM7: =CG7+365 -> 42002 | CN7: Total | CP7: =CJ7+365 -> 42092 | CQ7: =CK7+365 -> 42183 | CR7: =CL7+365 -> 42275 | CS7: =CM7+365 -> 42367 | CT7: Total | CV7: =CP7+365 -> 42457 | CW7: =CQ7+365 -> 42548 | CX7: =CR7+365 -> 42640 | CY7: =CS7+365 -> 42732 | CZ7: Total | DB7: =CV7+365 -> 42822 | DC7: =CW7+365 -> 42913 | DD7: =CX7+365 -> 43005 | DE7: =CY7+365 -> 43097 | DF7: Total | DH7: 43190 | DI7: 43281 | DJ7: 43373 | DK7: 43465 | DL7: Total | DN7: =DH7+365 -> 43555 | DO7: =DI7+365 -> 43646 | DP7: =DJ7+365 -> 43738 | DQ7: =DK7+365 -> 43830 | DR7: Total | DT7: =DN7+365 -> 43920 | DU7: =DO7+365 -> 44011 | DV7: =DP7+365 -> 44103 | DW7: =DQ7+365 -> 44195 | DX7: Total | DZ7: =DT7+365 -> 44285 | EA7: =DU7+365 -> 44376 | EB7: =DV7+365 -> 44468 | EC7: =DW7+365 -> 44560 | ED7: Total | EF7: =DZ7+365 -> 44650 | EG7: =EA7+365 -> 44741 | EH7: =EB7+365 -> 44833 | EI7: =EC7+365 -> 44925 | EJ7: Total | EL7: =EF7+365 -> 45015 | EM7: =EG7+365 -> 45106 | EN7: =EH7+365 -> 45198 | EO7: =EI7+365 -> 45290 | EP7: Total | ER7: =EOMONTH(EL7+365,0) -> 45382 | ES7: =EOMONTH(EM7+365,0) -> 45473 | ET7: =EOMONTH(EN7+365,0) -> 45565 | EU7: =EOMONTH(EO7+365,0) -> 45657 | EV7: Total | EX7: =EOMONTH(ER7+365,0) -> 45747 | EY7: =EOMONTH(ES7+365,0) -> 45838 | EZ7: =EOMONTH(ET7+365,0) -> 45930 | FA7: =EOMONTH(EU7+365,0) -> 46022 | FB7: Total | FD7: =EOMONTH(EX7+365,0) -> 46112 | FE7: =EOMONTH(EY7+365,0) -> 46203 | FF7: =EOMONTH(EZ7+365,0) -> 46295 | FG7: =EOMONTH(FA7+365,0) -> 46387 | FH7: Total | FJ7: =EOMONTH(FD7+365,0) -> 46477 | FK7: =EOMONTH(FE7+365,0) -> 46568 | FL7: =EOMONTH(FF7+365,0) -> 46660 | FM7: =EOMONTH(FG7+365,0) -> 46752 | FN7: Total | FP7: =EOMONTH(FJ7+365,0) -> 46843 | FQ7: =EOMONTH(FK7+365,0) -> 46934 | FR7: =EOMONTH(FL7+365,0) -> 47026 | FS7: =EOMONTH(FM7+365,0) -> 47118 | FT7: Total | FV7: =EOMONTH(FP7+365,0) -> 47208 | FW7: =EOMONTH(FQ7+365,0) -> 47299 | FX7: =EOMONTH(FR7+365,0) -> 47391 | FY7: =EOMONTH(FS7+365,0) -> 47483 | FZ7: Total | GB7: =EOMONTH(FV7+365,0) -> 47573 | GC7: =EOMONTH(FW7+365,0) -> 47664 | GD7: =EOMONTH(FX7+365,0) -> 47756 | GE7: =EOMONTH(FY7+365,0) -> 47848 | GF7: Total | GH7: =EOMONTH(GB7+365,0) -> 47938 | GI7: =EOMONTH(GC7+365,0) -> 48029 | GJ7: =EOMONTH(GD7+365,0) -> 48121 | GK7: =EOMONTH(GE7+365,0) -> 48213 | GL7: Total | GN7: =EOMONTH(GH7+365,0) -> 48304 | GO7: =EOMONTH(GI7+365,0) -> 48395 | GP7: =EOMONTH(GJ7+365,0) -> 48487 | GQ7: =EOMONTH(GK7+365,0) -> 48579 | GR7: Total | GT7: =EOMONTH(GN7+365,0) -> 48669 | GU7: =EOMONTH(GO7+365,0) -> 48760 | GV7: =EOMONTH(GP7+365,0) -> 48852 | GW7: =EOMONTH(GQ7+365,0) -> 48944 | GX7: Total | GZ7: =EOMONTH(GT7+365,0) -> 49034 | HA7: =EOMONTH(GU7+365,0) -> 49125 | HB7: =EOMONTH(GV7+365,0) -> 49217 | HC7: =EOMONTH(GW7+365,0) -> 49309 | HD7: Total | HF7: =EOMONTH(GZ7+365,0) -> 49399 | HG7: =EOMONTH(HA7+365,0) -> 49490 | HH7: =EOMONTH(HB7+365,0) -> 49582 | HI7: =EOMONTH(HC7+365,0) -> 49674 | HJ7: Total
B9: Net sales | DH9: 63.423 | DI9: 67.746 | DJ9: 69.096 | DK9: 76.475 | DL9: =SUM(DH9:DK9) -> 276.74 | DN9: 95.577 | DO9: 101.713 | DP9: 104.672 | DQ9: 106.868 | DR9: =SUM(DN9:DQ9) -> 408.83 | DT9: 106.03 | DU9: 86.977 | DV9: 125.444 | DW9: 125.997 | DX9: =SUM(DT9:DW9) -> 444.448 | DZ9: 115.533 | EA9: 121.724 | EB9: 121.34 | EC9: 125.732 | ED9: =SUM(DZ9:EC9) -> 484.329 | EF9: 117.169 | EG9: 125.072 | EH9: 128.782 | EI9: 138.705 | EJ9: =SUM(EF9:EI9) -> 509.728 | EL9: 137.22 | EM9: 146.917 | EN9: 151.954 | EO9: 155.552 | EP9: =SUM(EL9:EO9) -> 591.643 | ER9: 156.24 | ES9: 164.502 | ET9: 167.824 | EU9: 172 | EV9: =SUM(ER9:EU9) -> 660.566 | EX9: 168.035 | EY9: 181.33 | EZ9: 187.797 | FA9: 190.17 | FB9: =SUM(EX9:FA9) -> 727.332
C10: Cost of products sold | DH10: 36.12 | DI10: 37.216 | DJ10: 36.775 | DK10: 39.364 | DL10: =DL9-DL11 -> 149.475 | DN10: 48.462 | DO10: 52.747 | DP10: 53.84 | DQ10: 56.945 | DR10: =DR9-DR11 -> 211.994 | DT10: 59.661 | DU10: 58.971 | DV10: 71.379 | DW10: 68.544 | DX10: =DX9-DX11 -> 258.555 | DZ10: 73.959 | EA10: 68.734 | EB10: 74.101 | EC10: 80.475 | ED10: =ED9-ED11 -> 297.269 | EF10: 78.937 | EG10: 81.126 | EH10: 79.889 | EI10: 81.88 | EJ10: =EJ9-EJ11 -> 321.832 | EL10: 82.406 | EM10: 87.026 | EN10: 89.643 | EO10: 87.964 | EP10: =EP9-EP11 -> 347.039 | ER10: 90.771 | ES10: 92.008 | ET10: 92.944 | EU10: 94.743 | EV10: =SUM(ER10:EU10) -> 370.466 | EX10: 94.789 | EY10: 104.072 | EZ10: 107.351 | FA10: 106.827 | FB10: =SUM(EX10:FA10) -> 413.039
B11: Gross profit | DH11: =DH9-DH10 -> 27.303 | DI11: =DI9-DI10 -> 30.53 | DJ11: =DJ9-DJ10 -> 32.321 | DK11: =DK9-DK10 -> 37.111 | DL11: =SUM(DH11:DK11) -> 127.265 | DN11: =DN9-DN10 -> 47.115 | DO11: =DO9-DO10 -> 48.966 | DP11: =DP9-DP10 -> 50.832 | DQ11: =DQ9-DQ10 -> 49.923 | DR11: =SUM(DN11:DQ11) -> 196.836 | DT11: =DT9-DT10 -> 46.369 | DU11: =DU9-DU10 -> 28.006 | DV11: =DV9-DV10 -> 54.065 | DW11: =DW9-DW10 -> 57.453 | DX11: =SUM(DT11:DW11) -> 185.893 | DZ11: =DZ9-DZ10 -> 41.574 | EA11: =EA9-EA10 -> 52.99 | EB11: =EB9-EB10 -> 47.239 | EC11: =EC9-EC10 -> 45.257 | ED11: =SUM(DZ11:EC11) -> 187.06 | EF11: =EF9-EF10 -> 38.232 | EG11: =EG9-EG10 -> 43.946 | EH11: =EH9-EH10 -> 48.893 | EI11: =EI9-EI10 -> 56.825 | EJ11: =SUM(EF11:EI11) -> 187.896 | EL11: =EL9-EL10 -> 54.814 | EM11: =EM9-EM10 -> 59.891 | EN11: =EN9-EN10 -> 62.311 | EO11: =EO9-EO10 -> 67.588 | EP11: =SUM(EL11:EO11) -> 244.604 | ER11: =ER9-ER10 -> 65.469 | ES11: =ES9-ES10 -> 72.494 | ET11: =ET9-ET10 -> 74.88 | EU11: =EU9-EU10 -> 77.257 | EV11: =EV9-EV10 -> 290.1 | EX11: =EX9-EX10 -> 73.246 | EY11: =EY9-EY10 -> 77.258 | EZ11: =EZ9-EZ10 -> 80.446 | FA11: =FA9-FA10 -> 83.343 | FB11: =FB9-FB10 -> 314.293
C12: G&A | DH12: 17.067 | DI12: 20.983 | DJ12: 21.055 | DK12: 25.717 | DL12: =SUM(DH12:DK12) -> 84.822 | DN12: 32.142 | DO12: 29.577 | DP12: 33.054 | DQ12: 33.22 | DR12: =SUM(DN12:DQ12) -> 127.993 | DT12: 36.344 | DU12: 34.613 | DV12: 36.128 | DW12: 36.709 | DX12: =SUM(DT12:DW12) -> 143.794 | DZ12: 40.476 | EA12: 54.638 | EB12: 63.839 | EC12: 62.394 | ED12: =SUM(DZ12:EC12) -> 221.347 | EF12: 66.248 | EG12: 57.951 | EH12: 64.282 | EI12: 57.855 | EJ12: =SUM(EF12:EI12) -> 246.336 | EL12: 61.549 | EM12: 60.308 | EN12: 61.486 | EO12: 59.758 | EP12: =SUM(EL12:EO12) -> 243.101 | ER12: 65.797 | ES12: 63.328 | ET12: 66.969 | EU12: 63.643 | EV12: =SUM(ER12:EU12) -> 259.737 | EX12: 68.207 | EY12: 71.747 | EZ12: 69.874 | FA12: 63.509 | FB12: =SUM(EX12:FA12) -> 273.337
C13: Sales and Marketing | DH13: 6.775 | DI13: 7.68 | DJ13: 6.9 | DK13: 8.047 | DL13: =SUM(DH13:DK13) -> 29.402 | DN13: 11.216 | DO13: 12.324 | DP13: 11.508 | DQ13: 12.302 | DR13: =SUM(DN13:DQ13) -> 47.35 | DT13: 13.258 | DU13: 10.195 | DV13: 11.304 | DW13: 13.105 | DX13: =SUM(DT13:DW13) -> 47.862 | DZ13: 13.749 | EA13: 17.224 | EB13: 15.704 | EC13: 15.917 | ED13: =SUM(DZ13:EC13) -> 62.594 | EF13: 16.299 | EG13: 17.071 | EH13: 16.809 | EI13: 17.142 | EJ13: =SUM(EF13:EI13) -> 67.321 | EL13: 16.259 | EM13: 18.901 | EN13: 17.61 | EO13: 18.072 | EP13: =SUM(EL13:EO13) -> 70.842 | ER13: 20.221 | ES13: 21.677 | ET13: 20.415 | EU13: 22.339 | EV13: =SUM(ER13:EU13) -> 84.652 | EX13: 22.683 | EY13: 24.075 | EZ13: 21.806 | FA13: 23.443 | FB13: =SUM(EX13:FA13) -> 92.007
C14: Research & Development | DH14: 0.956 | DI14: 1.073 | DJ14: 0.446 | DK14: 0.526 | DL14: =SUM(DH14:DK14) -> 3.001 | DN14: 1.209 | DO14: 2.587 | DP14: 2.611 | DQ14: 2.08 | DR14: =SUM(DN14:DQ14) -> 8.487 | DT14: 2.06 | DU14: 2.105 | DV14: 1.964 | DW14: 2.1 | DX14: =SUM(DT14:DW14) -> 8.229 | DZ14: 2.456 | EA14: 3.495 | EB14: 7.409 | EC14: 8.513 | ED14: =SUM(DZ14:EC14) -> 21.873 | EF14: 7.713 | EG14: 8.626 | EH14: 7.312 | EI14: 6.675 | EJ14: =SUM(EF14:EI14) -> 30.326 | EL14: 7.395 | EM14: 7.502 | EN14: 5.285 | EO14: 7.127 | EP14: =SUM(EL14:EO14) -> 27.309 | ER14: 7.62 | ES14: 7.886 | ET14: 7.684 | EU14: 7.969 | EV14: =SUM(ER14:EU14) -> 31.159 | EX14: 10.181 | EY14: 9.023 | EZ14: 8.694 | FA14: 9.179 | FB14: =SUM(EX14:FA14) -> 37.077
C15: Other expenses | DH15: 0 | DI15: 0 | DJ15: 0 | DK15: 0 | DL15: =SUM(DH15:DK15) -> 0 | DN15: 0 | DO15: 0 | DP15: 0 | DQ15: 0 | DR15: =SUM(DN15:DQ15) -> 0 | DT15: 0 | DU15: 0 | DV15: 0 | DW15: 0 | DX15: =SUM(DT15:DW15) -> 0 | DZ15: 0 | EA15: 0 | EB15: 0 | EC15: 0 | ED15: =SUM(DZ15:EC15) -> 0 | EF15: 0 | EG15: 0 | EH15: 0 | EI15: 1.536 | EJ15: =SUM(EF15:EI15) -> 1.536 | EL15: 4.684 | EM15: 3.074 | EN15: 2.125 | EO15: 1.205 | EP15: =SUM(EL15:EO15) -> 11.088 | ER15: 2.398 | ES15: 1.544 | ET15: 1.009 | EU15: 1.707 | EV15: =SUM(ER15:EU15) -> 6.658 | EX15: 0 | EY15: 20.041 | EZ15: 7.086 | FA15: 0.626 | FB15: =SUM(EX15:FA15) -> 27.753
B16: Operating income | DH16: =DH11-SUM(DH12:DH15) -> 2.505 | DI16: =DI11-SUM(DI12:DI15) -> 0.794 | DJ16: =DJ11-SUM(DJ12:DJ15) -> 3.92 | DK16: =DK11-SUM(DK12:DK15) -> 2.821 | DL16: =DL11-SUM(DL12:DL15) -> 10.04 | DN16: =DN11-SUM(DN12:DN15) -> 2.548 | DO16: =DO11-SUM(DO12:DO15) -> 4.478 | DP16: =DP11-SUM(DP12:DP15) -> 3.659 | DQ16: =DQ11-SUM(DQ12:DQ15) -> 2.321 | DR16: =DR11-SUM(DR12:DR15) -> 13.006 | DT16: =DT11-SUM(DT12:DT15) -> -5.293 | DU16: =DU11-SUM(DU12:DU15) -> -18.907 | DV16: =DV11-SUM(DV12:DV15) -> 4.669 | DW16: =DW11-SUM(DW12:DW15) -> 5.539 | DX16: =DX11-SUM(DX12:DX15) -> -13.992 | DZ16: =DZ11-SUM(DZ12:DZ15) -> -15.107 | EA16: =EA11-SUM(EA12:EA15) -> -22.367 | EB16: =EB11-SUM(EB12:EB15) -> -39.713 | EC16: =EC11-SUM(EC12:EC15) -> -41.567 | ED16: =ED11-SUM(ED12:ED15) -> -118.754 | EF16: =EF11-SUM(EF12:EF15) -> -52.028 | EG16: =EG11-SUM(EG12:EG15) -> -39.702 | EH16: =EH11-SUM(EH12:EH15) -> -39.51 | EI16: =EI11-SUM(EI12:EI15) -> -26.383 | EJ16: =EJ11-SUM(EJ12:EJ15) -> -157.623 | EL16: =EL11-SUM(EL12:EL15) -> -35.073 | EM16: =EM11-SUM(EM12:EM15) -> -29.894 | EN16: =EN11-SUM(EN12:EN15) -> -24.195 | EO16: =EO11-SUM(EO12:EO15) -> -18.574 | EP16: =EP11-SUM(EP12:EP15) -> -107.736 | ER16: =ER11-SUM(ER12:ER15) -> -30.567 | ES16: =ES11-SUM(ES12:ES15) -> -21.941 | ET16: -21.197 | EU16: -18.401 | EV16: =EV11-SUM(EV12:EV15) -> -92.106 | EX16: =EX11-SUM(EX12:EX15) -> -27.825 | EY16: =EY11-SUM(EY12:EY15) -> -47.628 | EZ16: =EZ11-SUM(EZ12:EZ15) -> -27.014 | FA16: =FA11-SUM(FA12:FA15) -> -13.414 | FB16: =FB11-SUM(FB12:FB15) -> -115.881
C17: Interest expense | DH17: 1.486 | DI17: 1.407 | DJ17: 1.873 | DK17: 1.464 | DL17: =SUM(DH17:DK17) -> 6.23 | DN17: 1.826 | DO17: 1.304 | DP17: 0.203 | DQ17: 0.38 | DR17: =SUM(DN17:DQ17) -> 3.713 | DT17: 0.819 | DU17: 1.548 | DV17: 2.458 | DW17: 2.194 | DX17: =SUM(DT17:DW17) -> 7.019 | DZ17: 1.177 | EA17: 0.902 | EB17: 1.296 | EC17: 1.707 | ED17: =SUM(DZ17:EC17) -> 5.082 | EF17: 1.301 | EG17: 0.926 | EH17: 0.139 | EI17: 0 | EJ17: =SUM(EF17:EI17) -> 2.366 | EL17: 0 | EM17: 0 | EN17: 0 | EO17: 1.681 | EP17: =SUM(EL17:EO17) -> 1.681 | ER17: 1.685 | ES17: 1.666 | ET17: 1.642 | EU17: 1.624 | EV17: =SUM(ER17:EU17) -> 6.617 | EX17: 1.618 | EY17: 0.933 | EZ17: 0.603 | FA17: 0.599 | FB17: =SUM(EX17:FA17) -> 3.753
C18: Interest income | DH18: 0 | DI18: 0 | DJ18: 0 | DK18: 0 | DL18: =SUM(DH18:DK18) -> 0 | DN18: 0 | DO18: 0 | DP18: 0 | DQ18: 0 | DR18: =SUM(DN18:DQ18) -> 0 | DT18: 0 | DU18: 0 | DV18: 0 | DW18: 0 | DX18: =SUM(DT18:DW18) -> 0 | DZ18: 0 | EA18: 0 | EB18: 0 | EC18: 0 | ED18: =SUM(DZ18:EC18) -> 0 | EF18: 0 | EG18: 0 | EH18: 0 | EI18: -0.86 | EJ18: =SUM(EF18:EI18) -> -0.86 | EL18: -1.467 | EM18: -2.524 | EN18: -2.84 | EO18: -4.845 | EP18: =SUM(EL18:EO18) -> -11.676 | ER18: -4.834 | ES18: -4.592 | ET18: -4.673 | EU18: -4.328 | EV18: =SUM(ER18:EU18) -> -18.427 | EX18: -3.721 | EY18: =-2.263 -> -2.263 | EZ18: -1.563 | FA18: -1.523 | FB18: =SUM(EX18:FA18) -> -9.07
C19: Other expense, net | DH19: =-0.063 -> -0.063 | DI19: 0.124 | DJ19: -0.03 | DK19: -0.046 | DL19: =SUM(DH19:DK19) -> -0.015 | DN19: 5.169 | DO19: =1.018-0.01 -> 1.008 | DP19: -0.035 | DQ19: -0.494 | DR19: =SUM(DN19:DQ19) -> 5.648 | DT19: -0.223 | DU19: =-7.405+1.4+3.506 -> -2.499 | DV19: -0.011 | DW19: -4.222 | DX19: =SUM(DT19:DW19) -> -6.955 | DZ19: 4.854 | EA19: =-0.171-96.534 -> -96.705 | EB19: =-17.75-0.089 -> -17.839 | EC19: 0.93 | ED19: =SUM(DZ19:EC19) -> -108.76 | EF19: -0.168 | EG19: 0.405 | EH19: -0.025 | EI19: 0.001 | EJ19: =SUM(EF19:EI19) -> 0.213 | EL19: 0.114 | EM19: -0.73 | EN19: 0.096 | EO19: -0.124 | EP19: =SUM(EL19:EO19) -> -0.644 | ER19: 0.263 | ES19: 0.002 | ET19: -0.317 | EU19: 0.431 | EV19: =SUM(ER19:EU19) -> 0.379 | EX19: -0.065 | EY19: -0.482 | EZ19: 0.335 | FA19: -0.084 | FB19: =SUM(EX19:FA19) -> -0.296
B20: Income before taxes | DH20: =DH16-SUM(DH17:DH19) -> 1.082 | DI20: =DI16-SUM(DI17:DI19) -> -0.737 | DJ20: =DJ16-SUM(DJ17:DJ19) -> 2.077 | DK20: =DK16-SUM(DK17:DK19) -> 1.403 | DL20: =DL16-SUM(DL17:DL19) -> 3.825 | DN20: =DN16-SUM(DN17:DN19) -> -4.447 | DO20: =DO16-SUM(DO17:DO19) -> 2.166 | DP20: =DP16-SUM(DP17:DP19) -> 3.491 | DQ20: =DQ16-SUM(DQ17:DQ19) -> 2.435 | DR20: =DR16-SUM(DR17:DR19) -> 3.645 | DT20: =DT16-SUM(DT17:DT19) -> -5.889 | DU20: =DU16-SUM(DU17:DU19) -> -17.956 | DV20: =DV16-SUM(DV17:DV19) -> 2.222 | DW20: =DW16-SUM(DW17:DW19) -> 7.567 | DX20: =DX16-SUM(DX17:DX19) -> -14.056 | DZ20: =DZ16-SUM(DZ17:DZ19) -> -21.138 | EA20: =EA16-SUM(EA17:EA19) -> 73.436 | EB20: =EB16-SUM(EB17:EB19) -> -23.17 | EC20: =EC16-SUM(EC17:EC19) -> -44.204 | ED20: =ED16-SUM(ED17:ED19) -> -15.076 | EF20: =EF16-SUM(EF17:EF19) -> -53.161 | EG20: =EG16-SUM(EG17:EG19) -> -41.033 | EH20: =EH16-SUM(EH17:EH19) -> -39.624 | EI20: =EI16-SUM(EI17:EI19) -> -25.524 | EJ20: =EJ16-SUM(EJ17:EJ19) -> -159.342 | EL20: =EL16-SUM(EL17:EL19) -> -33.72 | EM20: =EM16-SUM(EM17:EM19) -> -26.64 | EN20: =EN16-SUM(EN17:EN19) -> -21.451 | EO20: =EO16-SUM(EO17:EO19) -> -15.286 | EP20: =EP16-SUM(EP17:EP19) -> -97.097 | ER20: =ER16-SUM(ER17:ER19) -> -27.681 | ES20: =ES16-SUM(ES17:ES19) -> -19.017 | ET20: -17.849 | EU20: -16.128 | EV20: =EV16-SUM(EV17:EV19) -> -80.675 | EX20: =EX16-SUM(EX17:EX19) -> -25.657 | EY20: =EY16-SUM(EY17:EY19) -> -45.816 | EZ20: =EZ16-SUM(EZ17:EZ19) -> -26.389 | FA20: =FA16-SUM(FA17:FA19) -> -12.406 | FB20: =FB16-SUM(FB17:FB19) -> -110.268
C21: Income tax | DH21: 0.438 | DI21: -0.357 | DJ21: 0.054 | DK21: 1.05 | DL21: =SUM(DH21:DK21) -> 1.185 | DN21: -2.023 | DO21: 0.175 | DP21: 1.348 | DQ21: -3.861 | DR21: =SUM(DN21:DQ21) -> -4.361 | DT21: 1.089 | DU21: -11.132 | DV21: -0.335 | DW21: -7.85 | DX21: =SUM(DT21:DW21) -> -18.228 | DZ21: 0.976 | EA21: -2.437 | EB21: -2.822 | EC21: -2.445 | ED21: =SUM(DZ21:EC21) -> -6.728 | EF21: -3.753 | EG21: -5.73 | EH21: -2.772 | EI21: -2.837 | EJ21: =SUM(EF21:EI21) -> -15.092 | EL21: -2.925 | EM21: -2.309 | EN21: -2.935 | EO21: -0.96 | EP21: =SUM(EL21:EO21) -> -9.129 | ER21: -0.62 | ES21: -0.375 | ET21: -0.15 | EU21: -0.804 | EV21: =SUM(ER21:EU21) -> -1.949 | EX21: 0.266 | EY21: -0.724 | EZ21: 0.74 | FA21: -2.525 | FB21: =SUM(EX21:FA21) -> -2.243
B22: GAAP Net income | DH22: =DH20-DH21 -> 0.644 | DI22: =DI20-DI21 -> -0.38 | DJ22: =DJ20-DJ21 -> 2.023 | DK22: =DK20-DK21 -> 0.353 | DL22: =DL20-DL21 -> 2.64 | DN22: =DN20-DN21 -> -2.424 | DO22: =DO20-DO21 -> 1.991 | DP22: =DP20-DP21 -> 2.143 | DQ22: =DQ20-DQ21 -> 6.296 | DR22: =DR20-DR21 -> 8.006 | DT22: =DT20-DT21 -> -6.978 | DU22: =DU20-DU21 -> -6.824 | DV22: =DV20-DV21 -> 2.557 | DW22: =DW20-DW21 -> 15.417 | DX22: =DX20-DX21 -> 4.172 | DZ22: =DZ20-DZ21 -> -22.114 | EA22: =EA20-EA21 -> 75.873 | EB22: =EB20-EB21 -> -20.348 | EC22: =EC20-EC21 -> -41.759 | ED22: =ED20-ED21 -> -8.348 | EF22: =EF20-EF21 -> -49.408 | EG22: =EG20-EG21 -> -35.303 | EH22: =EH20-EH21 -> -36.852 | EI22: =EI20-EI21 -> -22.687 | EJ22: =EJ20-EJ21 -> -144.25 | EL22: =EL20-EL21 -> -30.795 | EM22: =EM20-EM21 -> -24.331 | EN22: =EN20-EN21 -> -18.516 | EO22: =EO20-EO21 -> -14.326 | EP22: =EP20-EP21 -> -87.968 | ER22: =ER20-ER21 -> -27.061 | ES22: =ES20-ES21 -> -18.642 | ET22: -17.699 | EU22: -15.324 | EV22: =EV20-EV21 -> -78.726 | EX22: =EX20-EX21 -> -25.923 | EY22: =EY20-EY21 -> -45.092 | EZ22: =EZ20-EZ21 -> -27.129 | FA22: =FA20-FA21 -> -9.881 | FB22: =FB20-FB21 -> -108.025
B24: Basic average shares | DH24: 80.507 | DI24: 81.017 | DJ24: 87.253 | DK24: 93.27 | DL24: 85.618 | DN24: 94.74 | DO24: 98.297 | DP24: 103.899 | DQ24: 104.393 | DR24: 100.47 | DT24: 104.484 | DU24: 107.887 | DV24: 110.461 | DW24: 111.2 | DX24: 100.47 | DZ24: 116.199 | EA24: 118.287 | EB24: 122.559 | EC24: 123.082 | ED24: 119.962 | EF24: 123.63 | EG24: 124.068 | EH24: 124.425 | EI24: 124.714 | EJ24: 124.217 | EL24: 125.026 | EM24: 125.356 | EN24: 125.687 | EO24: 125.929 | EP24: 124.217 | ER24: 126.111 | ES24: 126.405 | ET24: 126.953 | EU24: 127.16 | EV24: =AVERAGE(ER24:EU24) -> 126.65725 | EX24: 127.376 | EY24: 127.949 | EZ24: 128.415 | FA24: 128.648 | FB24: =AVERAGE(EX24:FA24) -> 128.097
B25: Diluted average shares | DH25: 80.507 | DI25: 90.168 | DJ25: 90.927 | DK25: 96.874 | DL25: 91.568 | DN25: 94.74 | DO25: 102.336 | DP25: 107.88 | DQ25: 107.816 | DR25: 103.615 | DT25: 104.484 | DU25: 107.887 | DV25: 119.191 | DW25: 114.236 | DX25: 103.615 | DZ25: 116.199 | EA25: 131.237 | EB25: 122.559 | EC25: 123.082 | ED25: 119.962 | EF25: 123.63 | EG25: 124.068 | EH25: 124.425 | EI25: 124.714 | EJ25: 124.217 | EL25: 125.026 | EM25: 125.356 | EN25: 125.687 | EO25: 125.929 | EP25: 124.217 | ER25: 126.111 | ES25: 126.405 | ET25: 126.953 | EU25: 127.16 | EV25: =AVERAGE(ER25:EU25) -> 126.65725 | EX25: 127.376 | EY25: 127.949 | EZ25: 128.415 | FA25: 128.648 | FB25: =AVERAGE(EX25:FA25) -> 128.097
B27: COGS Adjustments
B28: Amortization of intangible assets | DZ28: 5.299 | EA28: 0.729 | EB28: 4.824 | EC28: 4.853 | ED28: =SUM(DZ28:EC28) -> 15.705 | EF28: 4.853 | EG28: 4.853 | EH28: 4.853 | EI28: 4.854 | EJ28: =SUM(EF28:EI28) -> 19.413 | EL28: 4.853 | EM28: 4.853 | EN28: 4.853 | EO28: 5.079 | EP28: =SUM(EL28:EO28) -> 19.638 | ER28: 4.9 | ES28: 4.9 | ET28: 4.9 | EU28: 4.9 | EV28: =SUM(ER28:EU28) -> 19.6 | EX28: 4.9 | EY28: 4.8 | EZ28: 4.613 | FA28: 4.615 | FB28: =SUM(EX28:FA28) -> 18.928
B29: SBC | DZ29: 0 | EA29: 0 | EB29: 0 | EC29: 0 | ED29: =SUM(DZ29:EC29) -> 0 | EF29: 0 | EG29: 0 | EH29: 0 | EI29: 0 | EJ29: =SUM(EF29:EI29) -> 0 | EL29: 0 | EM29: 0 | EN29: 0 | EO29: 0 | EP29: =SUM(EL29:EO29) -> 0 | ER29: 0.405 | ES29: 0.367 | ET29: 0.3 | EU29: 0.3 | EV29: =SUM(ER29:EU29) -> 1.372 | EX29: 0.405 | EY29: =5.114-EY28 -> 0.314 | EZ29: 0.337 | FA29: =4.964-FA28 -> 0.349 | FB29: =SUM(EX29:FA29) -> 1.405
B30: Other | DZ30: 0 | EA30: 0 | EB30: 0 | EC30: 0 | ED30: =SUM(DZ30:EC30) -> 0 | EF30: 0 | EG30: 0 | EH30: 0 | EI30: 0 | EJ30: =SUM(EF30:EI30) -> 0 | EL30: 0 | EM30: 0 | EN30: 0 | EO30: 0 | EP30: =SUM(EL30:EO30) -> 0 | ER30: 0 | ES30: 0 | ET30: 0 | EU30: 0 | EV30: =SUM(ER30:EU30) -> 0 | EX30: 0 | EY30: 0 | EZ30: 0 | FA30: 0 | FB30: =SUM(EX30:FA30) -> 0
B32: EBITDA Adjustments
B33: Depreciation | DH33: =CF!DH11 -> 3.633 | DI33: =CF!DI11 -> 3.811 | DJ33: =CF!DJ11 -> 4.033 | DK33: =CF!DK11 -> 4.327 | DL33: =SUM(DH33:DK33) -> 15.804 | DN33: =CF!DN11 -> 5.271 | DO33: =CF!DO11 -> 5.081 | DP33: =CF!DP11 -> 4.848 | DQ33: =CF!DQ11 -> 5.146 | DR33: =SUM(DN33:DQ33) -> 20.346 | DT33: =CF!DT11 -> 6.24 | DU33: =CF!DU11 -> 5.937 | DV33: =CF!DV11 -> 6.528 | DW33: =CF!DW11 -> 7.199 | DX33: =SUM(DT33:DW33) -> 25.904 | DZ33: =CF!DZ11 -> 6.68 | EA33: =CF!EA11 -> 6.949 | EB33: =CF!EB11 -> 8.178 | EC33: =CF!EC11 -> 8.385 | ED33: =SUM(DZ33:EC33) -> 30.192 | EF33: =CF!EF11 -> 8.395 | EG33: =CF!EG11 -> 8.526 | EH33: =CF!EH11 -> 8.973 | EI33: =CF!EI11 -> 9.478 | EJ33: =SUM(EF33:EI33) -> 35.372 | EL33: =CF!EL11 -> 9.048 | EM33: =CF!EM11 -> 9.475 | EN33: =CF!EN11 -> 9.349 | EO33: =CF!EO11 -> 9.578 | EP33: =SUM(EL33:EO33) -> 37.45 | ER33: =CF!ER11 -> 9.905 | ES33: =CF!ES11 -> 9.746 | ET33: =CF!ET11 -> 9.623 | EU33: =CF!EU11 -> 9.827 | EV33: =SUM(ER33:EU33) -> 39.101 | EX33: 9.366 | EY33: 9.14 | EZ33: 8.803 | FA33: 8.763 | FB33: =SUM(EX33:FA33) -> 36.072 | FD33: =CF!FD11 -> 9.835095 | FE33: =CF!FE11 -> 9.7467105 | FF33: =CF!FF11 -> 9.6671644 | FG33: =CF!FG11 -> 9.595573 | FH33: =SUM(FD33:FG33) -> 38.844543 | FJ33: =CF!FJ11 -> 9.6072263 | FK33: =CF!FK11 -> 9.6177143 | FL33: =CF!FL11 -> 9.6271535 | FM33: =CF!FM11 -> 9.6356488 | FN33: =SUM(FJ33:FM33) -> 38.487743 | FP33: =CF!FP11 -> 9.7258474 | FQ33: =CF!FQ11 -> 9.8070262 | FR33: =CF!FR11 -> 9.8800871 | FS33: =CF!FS11 -> 9.9458419 | FT33: =SUM(FP33:FS33) -> 39.358803 | FV33: =CF!FV11 -> 10.094591 | FW33: =CF!FW11 -> 10.228465 | FX33: =CF!FX11 -> 10.348952 | FY33: =CF!FY11 -> 10.457391 | FZ33: =SUM(FV33:FY33) -> 41.1294 | GB33: =CF!GB11 -> 11.096009 | GC33: =CF!GC11 -> 11.232379 | GD33: =CF!GD11 -> 11.354545 | GE33: =CF!GE11 -> 11.463985 | GF33: =SUM(GB33:GE33) -> 45.146917 | GH33: =CF!GH11 -> 11.671862 | GI33: =CF!GI11 -> 11.858085 | GJ33: =CF!GJ11 -> 12.024911 | GK33: =CF!GK11 -> 12.174358 | GL33: =SUM(GH33:GK33) -> 47.729216 | GN33: =CF!GN11 -> 12.967734 | GO33: =CF!GO11 -> 13.145554 | GP33: =CF!GP11 -> 13.304045 | GQ33: =CF!GQ11 -> 13.445309 | GR33: =SUM(GN33:GQ33) -> 52.862641 | GT33: =CF!GT11 -> 13.706143 | GU33: =CF!GU11 -> 13.938626 | GV33: =CF!GV11 -> 14.145839 | GW33: =CF!GW11 -> 14.330529 | GX33: =SUM(GT33:GW33) -> 56.121138 | GZ33: =CF!GZ11 -> 14.641538 | HA33: =CF!HA11 -> 14.918741 | HB33: =CF!HB11 -> 15.165814 | HC33: =CF!HC11 -> 15.386031 | HD33: =SUM(GZ33:HC33) -> 60.112124
B34: Amortization of intangible assets | DH34: =CF!DH12 -> 1.413 | DI34: =CF!DI12 -> 1.421 | DJ34: =CF!DJ12 -> 1.421 | DK34: =CF!DK12 -> 1.673 | DL34: =SUM(DH34:DK34) -> 5.928 | DN34: =CF!DN12 -> 2.559 | DO34: =CF!DO12 -> 2.543 | DP34: =CF!DP12 -> 2.38 | DQ34: =CF!DQ12 -> 2.443 | DR34: =SUM(DN34:DQ34) -> 9.925 | DT34: =CF!DT12 -> 2.452 | DU34: =CF!DU12 -> 2.467 | DV34: =CF!DV12 -> 2.468 | DW34: =CF!DW12 -> 2.43 | DX34: =SUM(DT34:DW34) -> 9.817 | DZ34: =CF!DZ12 -> 2.458 | EA34: =CF!EA12 -> 3.751 | EB34: =CF!EB12 -> 8.474 | EC34: =CF!EC12 -> 8.477 | ED34: =SUM(DZ34:EC34) -> 23.16 | EF34: =CF!EF12 -> 8.49 | EG34: =CF!EG12 -> 8.489 | EH34: =CF!EH12 -> 8.491 | EI34: =CF!EI12 -> 8.588 | EJ34: =SUM(EF34:EI34) -> 34.058 | EL34: =CF!EL12 -> 8.783 | EM34: =CF!EM12 -> 8.783 | EN34: =CF!EN12 -> 8.784 | EO34: =CF!EO12 -> 8.783 | EP34: =SUM(EL34:EO34) -> 35.133 | ER34: =CF!ER12 -> 8.362 | ES34: =CF!ES12 -> 8.361 | ET34: =CF!ET12 -> 8.362 | EU34: =CF!EU12 -> 8.361 | EV34: =SUM(ER34:EU34) -> 33.446 | EX34: 8.362 | EY34: 8.124 | EZ34: 7.634 | FA34: 7.632 | FB34: =SUM(EX34:FA34) -> 31.752 | FD34: =CF!FD12 -> 0 | FE34: =CF!FE12 -> 0 | FF34: =CF!FF12 -> 0 | FG34: =CF!FG12 -> 0 | FH34: =SUM(FD34:FG34) -> 0 | FJ34: =CF!FJ12 -> 0 | FK34: =CF!FK12 -> 0 | FL34: =CF!FL12 -> 0 | FM34: =CF!FM12 -> 0 | FN34: =SUM(FJ34:FM34) -> 0 | FP34: =CF!FP12 -> 0 | FQ34: =CF!FQ12 -> 0 | FR34: =CF!FR12 -> 0 | FS34: =CF!FS12 -> 0 | FT34: =SUM(FP34:FS34) -> 0 | FV34: =CF!FV12 -> 0 | FW34: =CF!FW12 -> 0 | FX34: =CF!FX12 -> 0 | FY34: =CF!FY12 -> 0 | FZ34: =SUM(FV34:FY34) -> 0 | GB34: =CF!GB12 -> 0 | GC34: =CF!GC12 -> 0 | GD34: =CF!GD12 -> 0 | GE34: =CF!GE12 -> 0 | GF34: =SUM(GB34:GE34) -> 0 | GH34: =CF!GH12 -> 0 | GI34: =CF!GI12 -> 0 | GJ34: =CF!GJ12 -> 0 | GK34: =CF!GK12 -> 0 | GL34: =SUM(GH34:GK34) -> 0 | GN34: =CF!GN12 -> 0 | GO34: =CF!GO12 -> 0 | GP34: =CF!GP12 -> 0 | GQ34: =CF!GQ12 -> 0 | GR34: =SUM(GN34:GQ34) -> 0 | GT34: =CF!GT12 -> 0 | GU34: =CF!GU12 -> 0 | GV34: =CF!GV12 -> 0 | GW34: =CF!GW12 -> 0 | GX34: =SUM(GT34:GW34) -> 0 | GZ34: =CF!GZ12 -> 0 | HA34: =CF!HA12 -> 0 | HB34: =CF!HB12 -> 0 | HC34: =CF!HC12 -> 0 | HD34: =SUM(GZ34:HC34) -> 0
B35: SBC | DH35: =CF!DH13 -> 1.624 | DI35: =CF!DI13 -> 2.333 | DJ35: =CF!DJ13 -> 1.191 | DK35: =CF!DK13 -> 1.807 | DL35: =SUM(DH35:DK35) -> 6.955 | DN35: =CF!DN13 -> 2.139 | DO35: =CF!DO13 -> 2.313 | DP35: =CF!DP13 -> 3.275 | DQ35: =CF!DQ13 -> 2.273 | DR35: =SUM(DN35:DQ35) -> 10 | DT35: =CF!DT13 -> 2.186 | DU35: =CF!DU13 -> 2.635 | DV35: =CF!DV13 -> 2.715 | DW35: =CF!DW13 -> 2.676 | DX35: =SUM(DT35:DW35) -> 10.212 | DZ35: =CF!DZ13 -> 2.653 | EA35: =CF!EA13 -> 4.506 | EB35: =CF!EB13 -> 5.237 | EC35: =CF!EC13 -> 10.062 | ED35: =SUM(DZ35:EC35) -> 22.458 | EF35: =CF!EF13 -> 12.103 | EG35: =CF!EG13 -> 3.626 | EH35: =CF!EH13 -> 4.28 | EI35: =CF!EI13 -> 4.663 | EJ35: =SUM(EF35:EI35) -> 24.672 | EL35: =CF!EL13 -> 4.758 | EM35: =CF!EM13 -> 5.705 | EN35: =CF!EN13 -> 7.18 | EO35: =CF!EO13 -> 6.99 | EP35: =SUM(EL35:EO35) -> 24.633 | ER35: =CF!ER13 -> 7.774 | ES35: =CF!ES13 -> 8.841 | ET35: =CF!ET13 -> 8.47 | EU35: =CF!EU13 -> 8.328 | EV35: =SUM(ER35:EU35) -> 33.413 | EX35: 10.754 | EY35: 12.215 | EZ35: 10.305 | FA35: 8.042 | FB35: =SUM(EX35:FA35) -> 41.316 | FD35: =CF!FD13 -> 0 | FE35: =CF!FE13 -> 0 | FF35: =CF!FF13 -> 0 | FG35: =CF!FG13 -> 0 | FH35: =SUM(FD35:FG35) -> 0 | FJ35: =CF!FJ13 -> 0 | FK35: =CF!FK13 -> 0 | FL35: =CF!FL13 -> 0 | FM35: =CF!FM13 -> 0 | FN35: =SUM(FJ35:FM35) -> 0 | FP35: =CF!FP13 -> 0 | FQ35: =CF!FQ13 -> 0 | FR35: =CF!FR13 -> 0 | FS35: =CF!FS13 -> 0 | FT35: =SUM(FP35:FS35) -> 0 | FV35: =CF!FV13 -> 0 | FW35: =CF!FW13 -> 0 | FX35: =CF!FX13 -> 0 | FY35: =CF!FY13 -> 0 | FZ35: =SUM(FV35:FY35) -> 0 | GB35: =CF!GB13 -> 0 | GC35: =CF!GC13 -> 0 | GD35: =CF!GD13 -> 0 | GE35: =CF!GE13 -> 0 | GF35: =SUM(GB35:GE35) -> 0 | GH35: =CF!GH13 -> 0 | GI35: =CF!GI13 -> 0 | GJ35: =CF!GJ13 -> 0 | GK35: =CF!GK13 -> 0 | GL35: =SUM(GH35:GK35) -> 0 | GN35: =CF!GN13 -> 0 | GO35: =CF!GO13 -> 0 | GP35: =CF!GP13 -> 0 | GQ35: =CF!GQ13 -> 0 | GR35: =SUM(GN35:GQ35) -> 0 | GT35: =CF!GT13 -> 0 | GU35: =CF!GU13 -> 0 | GV35: =CF!GV13 -> 0 | GW35: =CF!GW13 -> 0 | GX35: =SUM(GT35:GW35) -> 0 | GZ35: =CF!GZ13 -> 0 | HA35: =CF!HA13 -> 0 | HB35: =CF!HB13 -> 0 | HC35: =CF!HC13 -> 0 | HD35: =SUM(GZ35:HC35) -> 0
B36: Transition/restructuring | DH36: 0 | DI36: 1.822 | DJ36: 0.67 | DK36: 0 | DL36: =SUM(DH36:DK36) -> 2.492 | DN36: 0 | DO36: 0 | DP36: 0 | DQ36: 0 | DR36: =SUM(DN36:DQ36) -> 0 | DT36: 0 | DU36: 0 | DV36: 0 | DW36: 0 | DX36: =SUM(DT36:DW36) -> 0 | DZ36: =6.061+0.46 -> 6.521 | EA36: =0.368 -> 0.368 | EB36: 0.775 | EC36: 0.378 | ED36: =SUM(DZ36:EC36) -> 8.042 | EF36: 0 | EG36: 0 | EH36: 2.792 | EI36: 1.536 | EJ36: =SUM(EF36:EI36) -> 4.328 | EL36: 4.684 | EM36: 3.074 | EN36: 2.125 | EO36: 1.205 | EP36: =SUM(EL36:EO36) -> 11.088 | ER36: 2.398 | ES36: 1.544 | ET36: 1.009 | EU36: 1.707 | EV36: =SUM(ER36:EU36) -> 6.658 | EX36: 0 | EY36: 0.637 | EZ36: =0.319 -> 0.319 | FA36: 0.351 | FB36: =SUM(EX36:FA36) -> 1.307 | FH36: =SUM(FD36:FG36) -> 0 | FN36: =SUM(FJ36:FM36) -> 0 | FT36: =SUM(FP36:FS36) -> 0 | FZ36: =SUM(FV36:FY36) -> 0 | GF36: =SUM(GB36:GE36) -> 0 | GL36: =SUM(GH36:GK36) -> 0 | GR36: =SUM(GN36:GQ36) -> 0 | GX36: =SUM(GT36:GW36) -> 0 | HD36: =SUM(GZ36:HC36) -> 0
B37: Acquisition related charges | DH37: 0 | DI37: 0 | DJ37: 0 | DK37: 2.325 | DL37: =SUM(DH37:DK37) -> 2.325 | DN37: 1.266 | DO37: 0.512 | DP37: 0.334 | DQ37: 1.052 | DR37: =SUM(DN37:DQ37) -> 3.164 | DT37: 1.296 | DU37: 0.11 | DV37: 0.446 | DW37: 0.22 | DX37: =SUM(DT37:DW37) -> 2.072 | DZ37: 0.814 | EA37: 10.998 | EB37: 1.533 | EC37: 2.338 | ED37: =SUM(DZ37:EC37) -> 15.683 | EF37: 1.03 | EG37: 1.252 | EH37: 0.197 | EI37: 0 | EJ37: =SUM(EF37:EI37) -> 2.479 | EL37: 0 | EM37: 0 | EN37: 0 | EO37: 0 | EP37: =SUM(EL37:EO37) -> 0 | ER37: 0 | ES37: 0 | ET37: 0 | EU37: 0 | EV37: =SUM(ER37:EU37) -> 0 | EX37: 0 | EY37: 3.204 | EZ37: 1.8 | FA37: 1.09 | FB37: =SUM(EX37:FA37) -> 6.094 | FH37: =SUM(FD37:FG37) -> 0 | FN37: =SUM(FJ37:FM37) -> 0 | FT37: =SUM(FP37:FS37) -> 0 | FZ37: =SUM(FV37:FY37) -> 0 | GF37: =SUM(GB37:GE37) -> 0 | GL37: =SUM(GH37:GK37) -> 0 | GR37: =SUM(GN37:GQ37) -> 0 | GX37: =SUM(GT37:GW37) -> 0 | HD37: =SUM(GZ37:HC37) -> 0
B38: Other | DH38: 0 | DI38: 0 | DJ38: 0 | DK38: 0 | DL38: =SUM(DH38:DK38) -> 0 | DN38: 5.145 | DO38: 1.018 | DP38: 0.364 | DQ38: -0.134 | DR38: =SUM(DN38:DQ38) -> 6.393 | DT38: -0.03 | DU38: -1.965 | DV38: -0.105 | DW38: -4.026 | DX38: =SUM(DT38:DW38) -> -6.126 | DZ38: 5.021 | EA38: 0.174 | EB38: =10.5+1.814 -> 12.314 | EC38: =0.7+2.372 -> 3.072 | ED38: =SUM(DZ38:EC38) -> 20.581 | EF38: 2.831 | EG38: 1.94 | EH38: 3.195 | EI38: 0.952 | EJ38: =SUM(EF38:EI38) -> 8.918 | EL38: 0.789 | EM38: 0.076 | EN38: 0.158 | EO38: 1.242 | EP38: =SUM(EL38:EO38) -> 2.265 | ER38: 5.883 | ES38: =2.358+1.962 -> 4.32 | ET38: =0.677+6.113 -> 6.79 | EU38: =1.085+1.397 -> 2.482 | EV38: =SUM(ER38:EU38) -> 19.475 | EX38: =2.983+1.172+2.193 -> 6.348 | EY38: =4.46+20.041 -> 24.501 | EZ38: =3.634+7.086 -> 10.72 | FA38: =0.626+0.206 -> 0.832 | FB38: =SUM(EX38:FA38) -> 42.401 | FH38: =SUM(FD38:FG38) -> 0 | FN38: =SUM(FJ38:FM38) -> 0 | FT38: =SUM(FP38:FS38) -> 0 | FZ38: =SUM(FV38:FY38) -> 0 | GF38: =SUM(GB38:GE38) -> 0 | GL38: =SUM(GH38:GK38) -> 0 | GR38: =SUM(GN38:GQ38) -> 0 | GX38: =SUM(GT38:GW38) -> 0 | HD38: =SUM(GZ38:HC38) -> 0
B39: Financing | DH39: 0 | DI39: 0 | DJ39: 0 | DK39: 0 | DL39: =SUM(DH39:DK39) -> 0 | DN39: 0 | DO39: 0 | DP39: 0 | DQ39: 0 | DR39: =SUM(DN39:DQ39) -> 0 | DT39: 0 | DU39: 0 | DV39: 0 | DW39: 0 | DX39: =SUM(DT39:DW39) -> 0 | DZ39: 0 | EA39: -96.534 | EB39: -17.75 | EC39: 0 | ED39: =SUM(DZ39:EC39) -> -114.284 | EF39: 0 | EG39: 0 | EH39: 0 | EI39: 0 | EJ39: =SUM(EF39:EI39) -> 0 | EL39: 0 | EM39: 0 | EN39: 0 | EO39: 0 | EP39: =SUM(EL39:EO39) -> 0 | ER39: 0 | ES39: 0 | ET39: 0 | EU39: 0 | EV39: =SUM(ER39:EU39) -> 0 | EX39: 0 | EY39: 0 | EZ39: 0 | FA39: 0 | FB39: =SUM(EX39:FA39) -> 0
FH40: =SUM(FD40:FG40) -> 0 | FN40: =SUM(FJ40:FM40) -> 0 | FT40: =SUM(FP40:FS40) -> 0 | FZ40: =SUM(FV40:FY40) -> 0 | GF40: =SUM(GB40:GE40) -> 0 | GL40: =SUM(GH40:GK40) -> 0 | GR40: =SUM(GN40:GQ40) -> 0 | GX40: =SUM(GT40:GW40) -> 0 | HD40: =SUM(GZ40:HC40) -> 0
B41: EPS Adjustments
B42: Amortization of intangible assets | DH42: 1.413 | DI42: 1.123 | DJ42: 1.123 | DK42: 1.321 | DL42: =SUM(DH42:DK42) -> 4.98 | DN42: 2.559 | DO42: 2.009 | DP42: 1.88 | DQ42: 1.93 | DR42: =SUM(DN42:DQ42) -> 8.378 | DT42: 1.937 | DU42: 1.949 | DV42: 1.949 | DW42: 1.92 | DX42: =SUM(DT42:DW42) -> 7.755 | DZ42: 2.458 | EA42: 3.751 | EB42: 8.474 | EC42: 8.477 | ED42: =SUM(DZ42:EC42) -> 23.16 | EF42: 8.49 | EG42: 8.49 | EH42: 8.49 | EI42: 8.588 | EJ42: =SUM(EF42:EI42) -> 34.058 | EL42: 8.783 | EM42: 8.783 | EN42: 8.784 | EO42: 8.783 | EP42: =SUM(EL42:EO42) -> 35.133 | ER42: 8.362 | ES42: 8.361 | ET42: 8.362 | EU42: 8.362 | EV42: =SUM(ER42:EU42) -> 33.447 | EX42: 8.362 | EY42: 8.124 | EZ42: 7.634 | FA42: 7.632 | FB42: =SUM(EX42:FA42) -> 31.752
B43: SBC | DH43: 1.624 | DI43: 2.284 | DJ43: 0.941 | DK43: 1.695 | DL43: =SUM(DH43:DK43) -> 6.544 | DN43: 1.959 | DO43: 2.019 | DP43: 2.96 | DQ43: 1.971 | DR43: =SUM(DN43:DQ43) -> 8.909 | DT43: 1.847 | DU43: 2.202 | DV43: 2.185 | DW43: 2.215 | DX43: =SUM(DT43:DW43) -> 8.449 | DZ43: 2.653 | EA43: 4.506 | EB43: 5.237 | EC43: 10.062 | ED43: =SUM(DZ43:EC43) -> 22.458 | EF43: 12.103 | EG43: 3.626 | EH43: 4.28 | EI43: 4.662 | EJ43: =SUM(EF43:EI43) -> 24.671 | EL43: 4.758 | EM43: 5.705 | EN43: 7.18 | EO43: 6.99 | EP43: =SUM(EL43:EO43) -> 24.633 | ER43: 7.774 | ES43: 8.841 | ET43: 8.47 | EU43: 8.328 | EV43: =SUM(ER43:EU43) -> 33.413 | EX43: 10.754 | EY43: 12.215 | EZ43: 10.305 | FA43: 8.042 | FB43: =SUM(EX43:FA43) -> 41.316
B44: Transition/restructuring | DH44: 0 | DI44: 1.439 | DJ44: 0.53 | DK44: 0 | DL44: =SUM(DH44:DK44) -> 1.969 | DN44: 0 | DO44: 0 | DP44: 0 | DQ44: 0 | DR44: =SUM(DN44:DQ44) -> 0 | DT44: 0 | DU44: 0 | DV44: 0 | DW44: 0 | DX44: =SUM(DT44:DW44) -> 0 | DZ44: =0.46+6.061 -> 6.521 | EA44: 0.368 | EB44: 0.775 | EC44: 0.378 | ED44: =SUM(DZ44:EC44) -> 8.042 | EF44: 0 | EG44: 0 | EH44: 2.792 | EI44: 1.536 | EJ44: =SUM(EF44:EI44) -> 4.328 | EL44: 4.684 | EM44: 3.074 | EN44: 2.125 | EO44: 1.205 | EP44: =SUM(EL44:EO44) -> 11.088 | ER44: 2.398 | ES44: 1.544 | ET44: 1.009 | EU44: 1.707 | EV44: =SUM(ER44:EU44) -> 6.658 | EX44: 0 | EY44: 0.637 | EZ44: =0.319+7.086 -> 7.405 | FA44: 0.351 | FB44: =SUM(EX44:FA44) -> 8.393
B45: Acquisition related charges | DH45: 0 | DI45: 0 | DJ45: 0 | DK45: 2.116 | DL45: =SUM(DH45:DK45) -> 2.116 | DN45: 1 | DO45: 0.405 | DP45: 0.264 | DQ45: 0.831 | DR45: =SUM(DN45:DQ45) -> 2.5 | DT45: 1.024 | DU45: 0.087 | DV45: 0.353 | DW45: 0.174 | DX45: =SUM(DT45:DW45) -> 1.638 | DZ45: 0.814 | EA45: 10.998 | EB45: 1.533 | EC45: 2.338 | ED45: =SUM(DZ45:EC45) -> 15.683 | EF45: 1.03 | EG45: 1.252 | EH45: 0.197 | EI45: 0 | EJ45: =SUM(EF45:EI45) -> 2.479 | EL45: 0 | EM45: 0 | EN45: 0 | EO45: 0 | EP45: =SUM(EL45:EO45) -> 0 | ER45: 0 | ES45: 0 | ET45: 0 | EU45: 0 | EV45: =SUM(ER45:EU45) -> 0 | EX45: 0 | EY45: 3.204 | EZ45: 1.8 | FA45: 1.09 | FB45: =SUM(EX45:FA45) -> 6.094
...

Sheet Rev
B1: =IS!EY2 -> NeoGenomics
B2: Historical and Projected Revenue Statement
B3: =[44]IS!B3 -> Dollars in millions, except per share amounts
ER4: Historical results
D5: Historical results | J5: Historical results | P5: Historical results | V5: Historical results | AB5: Historical results | AH5: Historical results | AN5: Historical results | AT5: Historical results | AZ5: Historical results | BF5: Historical results | BL5: Historical results | BR5: Historical results | BX5: Historical results | CD5: Historical results | CJ5: Historical results | CP5: Historical results | CV5: Historical results | DB5: Historical results | DH5: Historical results | DN5: Historical results | DT5: Historical results | DZ5: Historical results | EF5: Historical results | EL5: Historical results | EX5: Historical results | FD5: Projections | FJ5: Projections | FP5: Projections
D6: 2000 | J6: 2001 | P6: 2002 | V6: 2003 | AB6: 2004 | AH6: 2005 | AN6: 2006 | AT6: 2007 | AZ6: 2008 | BF6: 2009 | BL6: 2010 | BR6: 2011 | BX6: 2012 | CD6: 2013 | CJ6: 2014 | CP6: 2015 | CV6: 2016 | DB6: 2017 | DH6: 2018 | DN6: 2019 | DT6: 2020 | DZ6: 2021 | EF6: =DZ6+1 -> 2022 | EL6: =EF6+1 -> 2023 | ER6: =EL6+1 -> 2024 | EX6: =ER6+1 -> 2025 | FD6: =EX6+1 -> 2026 | FJ6: =FD6+1 -> 2027 | FP6: =FJ6+1 -> 2028
D7: =[44]IS!D7 -> 36616 | E7: =[44]IS!E7 -> 36707 | F7: =[44]IS!F7 -> 36799 | G7: =[44]IS!G7 -> 36891 | H7: Total | J7: =[44]IS!J7 -> 36981 | K7: =[44]IS!K7 -> 37072 | L7: =[44]IS!L7 -> 37164 | M7: =[44]IS!M7 -> 37256 | N7: Total | P7: =[44]IS!P7 -> 37346 | Q7: =[44]IS!Q7 -> 37437 | R7: =[44]IS!R7 -> 37529 | S7: =[44]IS!S7 -> 37621 | T7: Total | V7: =[44]IS!V7 -> 37711 | W7: =[44]IS!W7 -> 37802 | X7: =[44]IS!X7 -> 37894 | Y7: =[44]IS!Y7 -> 37986 | Z7: Total | AB7: =[44]IS!AB7 -> 38077 | AC7: =[44]IS!AC7 -> 38168 | AD7: =[44]IS!AD7 -> 38260 | AE7: =[44]IS!AE7 -> 38352 | AF7: Total | AH7: =[44]IS!AH7 -> 38442 | AI7: =[44]IS!AI7 -> 38533 | AJ7: =[44]IS!AJ7 -> 38625 | AK7: =[44]IS!AK7 -> 38717 | AL7: Total | AN7: =[44]IS!AN7 -> 38807 | AO7: =[44]IS!AO7 -> 38898 | AP7: =[44]IS!AP7 -> 38990 | AQ7: =[44]IS!AQ7 -> 39082 | AR7: Total | AT7: =[44]IS!AT7 -> 39172 | AU7: =[44]IS!AU7 -> 39263 | AV7: =[44]IS!AV7 -> 39355 | AW7: =[44]IS!AW7 -> 39447 | AX7: Total | AZ7: =[44]IS!AZ7 -> 39537 | BA7: =[44]IS!BA7 -> 39628 | BB7: =[44]IS!BB7 -> 39720 | BC7: =[44]IS!BC7 -> 39812 | BD7: Total | BF7: =[44]IS!BF7 -> 39902 | BG7: =[44]IS!BG7 -> 39993 | BH7: =[44]IS!BH7 -> 40085 | BI7: =[44]IS!BI7 -> 40177 | BJ7: Total | BL7: =[44]IS!BL7 -> 40267 | BM7: =[44]IS!BM7 -> 40358 | BN7: =[44]IS!BN7 -> 40450 | BO7: =[44]IS!BO7 -> 40542 | BP7: Total | BR7: =[44]IS!BR7 -> 40632 | BS7: =[44]IS!BS7 -> 40723 | BT7: =[44]IS!BT7 -> 40815 | BU7: =[44]IS!BU7 -> 40907 | BV7: Total | BX7: =[44]IS!BX7 -> 40997 | BY7: =[44]IS!BY7 -> 41088 | BZ7: =[44]IS!BZ7 -> 41180 | CA7: =[44]IS!CA7 -> 41272 | CB7: Total | CD7: =[44]IS!CD7 -> 41362 | CE7: =[44]IS!CE7 -> 41453 | CF7: =[44]IS!CF7 -> 41545 | CG7: =[44]IS!CG7 -> 41637 | CH7: Total | CJ7: =[44]IS!CJ7 -> 41727 | CK7: =[44]IS!CK7 -> 41818 | CL7: =[44]IS!CL7 -> 41910 | CM7: =[44]IS!CM7 -> 42002 | CN7: Total | CP7: =[44]IS!CP7 -> 42092 | CQ7: =[44]IS!CQ7 -> 42183 | CR7: =[44]IS!CR7 -> 42275 | CS7: =[44]IS!CS7 -> 42367 | CT7: Total | CV7: =[44]IS!CV7 -> 42457 | CW7: =[44]IS!CW7 -> 42548 | CX7: =[44]IS!CX7 -> 42640 | CY7: =[44]IS!CY7 -> 42732 | CZ7: Total | DB7: =[44]IS!DB7 -> 42822 | DC7: =[44]IS!DC7 -> 42913 | DD7: =[44]IS!DD7 -> 43005 | DE7: =[44]IS!DE7 -> 43097 | DF7: Total | DH7: =[44]IS!DH7 -> 43187 | DI7: =[44]IS!DI7 -> 43278 | DJ7: =[44]IS!DJ7 -> 43370 | DK7: =[44]IS!DK7 -> 43462 | DL7: Total | DN7: =[44]IS!DN7 -> 43552 | DO7: =[44]IS!DO7 -> 43643 | DP7: =[44]IS!DP7 -> 43735 | DQ7: =[44]IS!DQ7 -> 43827 | DR7: Total | DT7: =[44]IS!DT7 -> 43917 | DU7: =[44]IS!DU7 -> 44008 | DV7: =[44]IS!DV7 -> 44100 | DW7: =[44]IS!DW7 -> 44192 | DX7: Total | DZ7: =IS!DZ7 -> 44285 | EA7: =IS!EA7 -> 44376 | EB7: =IS!EB7 -> 44468 | EC7: =IS!EC7 -> 44560 | ED7: Total | EF7: =IS!EF7 -> 44650 | EG7: =IS!EG7 -> 44741 | EH7: =IS!EH7 -> 44833 | EI7: =IS!EI7 -> 44925 | EJ7: Total | EL7: =IS!EL7 -> 45015 | EM7: =IS!EM7 -> 45106 | EN7: =IS!EN7 -> 45198 | EO7: =IS!EO7 -> 45290 | EP7: Total | ER7: =IS!ER7 -> 45382 | ES7: =IS!ES7 -> 45473 | ET7: =IS!ET7 -> 45565 | EU7: =IS!EU7 -> 45657 | EV7: Total | EX7: =IS!EX7 -> 45747 | EY7: =IS!EY7 -> 45838 | EZ7: =IS!EZ7 -> 45930 | FA7: =IS!FA7 -> 46022 | FB7: Total | FD7: =IS!FD7 -> 46112 | FE7: =IS!FE7 -> 46203 | FF7: =IS!FF7 -> 46295 | FG7: =IS!FG7 -> 46387 | FH7: Total | FJ7: =IS!FJ7 -> 46477 | FK7: =IS!FK7 -> 46568 | FL7: =IS!FL7 -> 46660 | FM7: =IS!FM7 -> 46752 | FN7: Total | FP7: =IS!FP7 -> 46843 | FQ7: =IS!FQ7 -> 46934 | FR7: =IS!FR7 -> 47026 | FS7: =IS!FS7 -> 47118 | FT7: Total
EB8: =EB9/DZ9 -> 1.0423868 | EH8: =EH9/EF9 -> 1.0484381 | EN8: =EN9/EL9 -> 1.0822855
DZ9: =SUM(DZ10:EA10) -> 197.892 | EB9: =SUM(EB10:EC10) -> 206.28 | EF9: =SUM(EF10:EG10) -> 204.426 | EH9: =SUM(EH10:EI10) -> 214.328 | EL9: =SUM(EL10:EM10) -> 238.025 | EN9: =SUM(EN10:EO10) -> 257.611
B10: Clinical Services (ex. Pathline) | DB10: 51.329 | DC10: 53.978 | DD10: 50.74 | DE10: 53.456 | DF10: =SUM(DB10:DE10) -> 209.503 | DH10: 56.971 | DI10: 59.54 | DJ10: 59.449 | DK10: 65.913 | DL10: =SUM(DH10:DK10) -> 241.873 | DN10: 86.21 | DO10: 88.982 | DP10: 92.565 | DQ10: 93.405 | DR10: =SUM(DN10:DQ10) -> 361.162 | DT10: 92.982 | DU10: 73.884 | DV10: 108.733 | DW10: 106.738 | DX10: =SUM(DT10:DW10) -> 382.337 | DZ10: 96.487 | EA10: 101.405 | EB10: 102.227 | EC10: 104.053 | ED10: =SUM(DZ10:EC10) -> 404.172 | EF10: 98.791 | EG10: 105.635 | EH10: 106.162 | EI10: 108.166 | EJ10: =SUM(EF10:EI10) -> 418.754 | EL10: 114.869 | EM10: 123.156 | EN10: 127.553 | EO10: 130.058 | EP10: =SUM(EL10:EO10) -> 495.636 | ER10: 134.535 | ES10: 141.388 | ET10: 145.783 | EU10: =(EU19*EU25)/1000000 -> 149.58074 | EV10: =SUM(ER10:EU10) -> 571.28674 | EX10: =(EX19*EX25)/1000000 -> 149.70882 | EY10: =(EY19*EY25)/1000000 -> 159.49732 | EZ10: =(EZ19*EZ25)/1000000 -> 167.01041 | FA10: =(FA19*FA25)/1000000 -> 169.92266 | FB10: =SUM(EX10:FA10) -> 646.13921 | FD10: =(FD19*FD25)/1000000 -> 164.22309 | FE10: =(FE19*FE25)/1000000 -> 175.44706 | FF10: =(FF19*FF25)/1000000 -> 183.97867 | FG10: =(FG19*FG25)/1000000 -> 189.12392 | FH10: =SUM(FD10:FG10) -> 712.77273 | FJ10: =(FJ19*FJ25)/1000000 -> 180.99026 | FK10: =(FK19*FK25)/1000000 -> 193.3602 | FL10: =(FL19*FL25)/1000000 -> 202.7629 | FM10: =(FM19*FM25)/1000000 -> 208.43347 | FN10: =SUM(FJ10:FM10) -> 785.54683 | FP10: =(FP19*FP25)/1000000 -> 199.46937 | FQ10: =(FQ19*FQ25)/1000000 -> 213.10228 | FR10: =(FR19*FR25)/1000000 -> 223.46499 | FS10: =(FS19*FS25)/1000000 -> 229.71453 | FT10: =SUM(FP10:FS10) -> 865.75116
C11: growth y/y | DH11: =DH10/DB10-1 -> 0.10991837 | DI11: =DI10/DC10-1 -> 0.10304198 | DJ11: =DJ10/DD10-1 -> 0.17163973 | DK11: =DK10/DE10-1 -> 0.23303277 | DL11: =DL10/DF10-1 -> 0.15450853 | DN11: =DN10/DH10-1 -> 0.51322603 | DO11: =DO10/DI10-1 -> 0.4944911 | DP11: =DP10/DJ10-1 -> 0.5570489 | DQ11: =DQ10/DK10-1 -> 0.41709526 | DR11: =DR10/DL10-1 -> 0.49318857 | DT11: =DT10/DN10-1 -> 0.078552372 | DU11: =DU10/DO10-1 -> -0.16967477 | DV11: =DV10/DP10-1 -> 0.17466645 | DW11: =DW10/DQ10-1 -> 0.14274396 | DX11: =DX10/DR10-1 -> 0.058630199 | DZ11: =DZ10/DT10-1 -> 0.037695468 | EA11: =EA10/DU10-1 -> 0.37248931 | EB11: =EB10/DV10-1 -> -0.059834641 | EC11: =EC10/DW10-1 -> -0.025155053 | ED11: =ED10/DX10-1 -> 0.057109304 | EF11: =EF10/DZ10-1 -> 0.023878865 | EG11: =EG10/EA10-1 -> 0.041713919 | EH11: =EH10/EB10-1 -> 0.038492766 | EI11: =EI10/EC10-1 -> 0.039527933 | EJ11: =EJ10/ED10-1 -> 0.036078699 | EL11: =EL10/EF10-1 -> 0.16274762 | EM11: =EM10/EG10-1 -> 0.16586359 | EN11: =EN10/EH10-1 -> 0.20149394 | EO11: =EO10/EI10-1 -> 0.20239262 | EP11: =EP10/EJ10-1 -> 0.18359705 | ER11: =ER10/EL10-1 -> 0.17120372 | ES11: =ES10/EM10-1 -> 0.14803988 | ET11: =ET10/EN10-1 -> 0.14292098 | EU11: =EU10/EO10-1 -> 0.15010791 | EV11: =EV10/EP10-1 -> 0.15263366 | EX11: =EX10/ER10-1 -> 0.11278713 | EY11: =EY10/ES10-1 -> 0.12808248 | EZ11: =EZ10/ET10-1 -> 0.14560967 | FA11: =FA10/EU10-1 -> 0.13599292 | FB11: =FB10/EV10-1 -> 0.13102436 | FD11: =FD10/EX10-1 -> 0.09695 | FE11: =FE10/EY10-1 -> 0.1 | FF11: =FF10/EZ10-1 -> 0.1016 | FG11: =FG10/FA10-1 -> 0.113 | FH11: =FH10/FB10-1 -> 0.10312564 | FJ11: =FJ10/FD10-1 -> 0.1021 | FK11: =FK10/FE10-1 -> 0.1021 | FL11: =FL10/FF10-1 -> 0.1021 | FM11: =FM10/FG10-1 -> 0.1021 | FN11: =FN10/FH10-1 -> 0.1021 | FP11: =FP10/FJ10-1 -> 0.1021 | FQ11: =FQ10/FK10-1 -> 0.1021 | FR11: =FR10/FL10-1 -> 0.1021 | FS11: =FS10/FM10-1 -> 0.1021 | FT11: =FT10/FN10-1 -> 0.1021
C12: growth q/q (%) | DC12: =DC10/DB10-1 -> 0.051608253 | DD12: =DD10/DC10-1 -> -0.059987402 | DE12: =DE10/DD10-1 -> 0.053527789 | DH12: =DH10/DE10-1 -> 0.065755013 | DI12: =DI10/DH10-1 -> 0.045093118 | DJ12: =DJ10/DI10-1 -> -0.0015283843 | DK12: =DK10/DJ10-1 -> 0.10873185 | DN12: =DN10/DK10-1 -> 0.30793622 | DO12: =DO10/DN10-1 -> 0.032154042 | DP12: =DP10/DO10-1 -> 0.040266571 | DQ12: =DQ10/DP10-1 -> 0.0090747043 | DT12: =DT10/DQ10-1 -> -0.0045286655 | DU12: =DU10/DT10-1 -> -0.20539459 | DV12: =DV10/DU10-1 -> 0.47167181 | DW12: =DW10/DV10-1 -> -0.018347696 | DZ12: =DZ10/DW10-1 -> -0.096038899 | EA12: =EA10/DZ10-1 -> 0.050970597 | EB12: =EB10/EA10-1 -> 0.0081061092 | EC12: =EC10/EB10-1 -> 0.017862209 | EF12: =EF10/EC10-1 -> -0.050570382 | EG12: =EG10/EF10-1 -> 0.069277566 | EH12: =EH10/EG10-1 -> 0.0049888768 | EI12: =EI10/EH10-1 -> 0.018876811 | EL12: =EL10/EI10-1 -> 0.061969565 | EM12: =EM10/EL10-1 -> 0.07214305 | EN12: =EN10/EM10-1 -> 0.035702686 | EO12: =EO10/EN10-1 -> 0.019638895 | ER12: =ER10/EO10-1 -> 0.034423104 | ES12: =ES10/ER10-1 -> 0.050938418 | ET12: =ET10/ES10-1 -> 0.031084675 | EU12: =EU10/ET10-1 -> 0.026050603 | EX12: =EX10/EU10-1 -> 0.00085627337 | EY12: =EY10/EX10-1 -> 0.065383644 | EZ12: =EZ10/EY10-1 -> 0.047104803 | FA12: =FA10/EZ10-1 -> 0.017437481
C13: growth q/q ($) | DC13: =DC10-DB10 -> 2.649 | DD13: =DD10-DC10 -> -3.238 | DE13: =DE10-DD10 -> 2.716 | DH13: =DH10-DE10 -> 3.515 | DI13: =DI10-DH10 -> 2.569 | DJ13: =DJ10-DI10 -> -0.091 | DK13: =DK10-DJ10 -> 6.464 | DN13: =DN10-DK10 -> 20.297 | DO13: =DO10-DN10 -> 2.772 | DP13: =DP10-DO10 -> 3.583 | DQ13: =DQ10-DP10 -> 0.84 | DT13: =DT10-DQ10 -> -0.423 | DU13: =DU10-DT10 -> -19.098 | DV13: =DV10-DU10 -> 34.849 | DW13: =DW10-DV10 -> -1.995 | DZ13: =DZ10-DW10 -> -10.251 | EA13: =EA10-DZ10 -> 4.918 | EB13: =EB10-EA10 -> 0.822 | EC13: =EC10-EB10 -> 1.826 | EF13: =EF10-EC10 -> -5.262 | EG13: =EG10-EF10 -> 6.844 | EH13: =EH10-EG10 -> 0.527 | EI13: =EI10-EH10 -> 2.004 | EL13: =EL10-EI10 -> 6.703 | EM13: =EM10-EL10 -> 8.287 | EN13: =EN10-EM10 -> 4.397 | EO13: =EO10-EN10 -> 2.505 | ER13: =ER10-EO10 -> 4.477 | ES13: =ES10-ER10 -> 6.853 | ET13: =ET10-ES10 -> 4.395 | EU13: =EU10-ET10 -> 3.797735 | EX13: =EX10-EU10 -> 0.128082 | EY13: =EY10-EX10 -> 9.788508 | EZ13: =EZ10-EY10 -> 7.51309 | FA13: =FA10-EZ10 -> 2.912241
C14: % of revenue | DB14: =DB10/DB90 -> 0.91905103 | DC14: =DC10/DC90 -> 0.88933191 | DD14: =DD10/DD90 -> 0.86454251 | DE14: =DE10/DE90 -> 0.87030706 | DF14: =DF10/DF90 -> 0.8852601 | DH14: =DH10/DH90 -> 0.89827034 | DI14: =DI10/DI90 -> 0.87887108 | DJ14: =DJ10/DJ90 -> 0.86038266 | DK14: =DK10/DK90 -> 0.86188951 | DL14: =DL10/DL90 -> 0.87400809 | DN14: =DN10/DN90 -> 0.90199525 | DO14: =DO10/DO90 -> 0.87483409 | DP14: =DP10/DP90 -> 0.88433392 | DQ14: =DQ10/DQ90 -> 0.87402216 | DR14: =DR10/DR90 -> 0.88340386 | DT14: =DT10/DT90 -> 0.87694049 | DU14: =DU10/DU90 -> 0.84946595 | DV14: =DV10/DV90 -> 0.86678518 | DW14: =DW10/DW90 -> 0.84714715 | DX14: =DX10/DX90 -> 0.86025137 | DZ14: =DZ10/DZ90 -> 0.83514667 | EA14: =EA10/EA90 -> 0.83307318 | EB14: =EB10/EB90 -> 0.84248393 | EC14: =EC10/EC90 -> 0.8275777 | ED14: =ED10/ED90 -> 0.83449886 | EF14: =EF10/EF90 -> 0.84314964 | EG14: =EG10/EG90 -> 0.84459351 | EH14: =EH10/EH90 -> 0.82435434 | EI14: =EI10/EI90 -> 0.77982769 | EJ14: =EJ10/EJ90 -> 0.82152442 | EL14: =EL10/EL90 -> 0.83711558 | EM14: =EM10/EM90 -> 0.83826923 | EN14: =EN10/EN90 -> 0.83941851 | EO14: =EO10/EO90 -> 0.83610625 | EP14: =EP10/EP90 -> 0.83772816 | ER14: =ER10/ER90 -> 0.86107911 | ES14: =ES10/ES90 -> 0.85949107 | ET14: =ET10/ET90 -> 0.86866598 | EU14: =EU10/EU90 -> 0.86965544 | EX14: =EX10/EX90 -> 0.8909383 | EY14: =EY10/EY90 -> 0.87959701 | EZ14: =EZ10/EZ90 -> 0.88931354 | FA14: =FA10/FA90 -> 0.89353029
C16: Requisitions | DB16: 94528 | DC16: 99247 | DD16: 98031 | DE16: 102714 | DF16: =SUM(DB16:DE16) -> 394520 | DH16: 105229 | DI16: 109986 | DJ16: 108467 | DK16: 115915 | DL16: =SUM(DH16:DK16) -> 439597 | DN16: 137111 | DO16: 144983 | DP16: 143312 | DQ16: 145679 | DR16: =SUM(DN16:DQ16) -> 571085 | DT16: 144319 | DU16: 114413 | DV16: 147518 | DW16: 153170 | DX16: =SUM(DT16:DW16) -> 559420 | DZ16: 151145 | EA16: 163128 | EB16: 159625 | EC16: 159553 | ED16: =SUM(DZ16:EC16) -> 633451
C17: growth y/y | DH17: =DH16/DB16-1 -> 0.11320455 | DI17: =DI16/DC16-1 -> 0.10820478 | DJ17: =DJ16/DD16-1 -> 0.10645612 | DK17: =DK16/DE16-1 -> 0.12852192 | DL17: =DL16/DF16-1 -> 0.11425783 | DN17: =DN16/DH16-1 -> 0.30297732 | DO17: =DO16/DI16-1 -> 0.31819504 | DP17: =DP16/DJ16-1 -> 0.32124978 | DQ17: =DQ16/DK16-1 -> 0.25677436 | DR17: =DR16/DL16-1 -> 0.29911032 | DT17: =DT16/DN16-1 -> 0.052570545 | DU17: =DU16/DO16-1 -> -0.21085231 | DV17: =DV16/DP16-1 -> 0.029348554 | DW17: =DW16/DQ16-1 -> 0.051421276 | DX17: =DX16/DR16-1 -> -0.020426031 | DZ17: =DZ16/DT16-1 -> 0.047298 | EA17: =EA16/DU16-1 -> 0.42578204 | EB17: =EB16/DV16-1 -> 0.08207134 | EC17: =EC16/DW16-1 -> 0.041672651 | ED17: =ED16/DX16-1 -> 0.13233528
C19: Volume | DB19: 155567 | DC19: 163620 | DD19: 163289 | DE19: 174918 | DF19: =SUM(DB19:DE19) -> 657394 | DH19: 178794 | DI19: 187189 | DJ19: 185738 | DK19: 198181 | DL19: =SUM(DH19:DK19) -> 749902 | DN19: 234317 | DO19: 250330 | DP19: 250518 | DQ19: 252374 | DR19: =SUM(DN19:DQ19) -> 987539 | DT19: 250376 | DU19: 204844 | DV19: 255458 | DW19: 265391 | DX19: =SUM(DT19:DW19) -> 976069 | DZ19: 260941 | EA19: 281335 | EB19: 272732 | EC19: 271760 | ED19: =SUM(DZ19:EC19) -> 1086768 | EF19: 266035 | EG19: 272982 | EH19: 270899 | EI19: 278089 | EJ19: =SUM(EF19:EI19) -> 1088005 | EL19: 285476 | EM19: 295116 | EN19: 289637 | EO19: 294850 | EP19: =SUM(EL19:EO19) -> 1165079 | ER19: 300827 | ES19: 311670 | ET19: 314564 | EU19: 321679 | EV19: =SUM(ER19:EU19) -> 1248740 | EX19: 326163 | EY19: 343005 | EZ19: 347215 | FA19: 342586 | FB19: =SUM(EX19:FA19) -> 1358969 | FD19: =EX19*(1+FD20) -> 335947.89 | FE19: =EY19*(1+FE20) -> 343005 | FF19: =EZ19*(1+FF20) -> 354159.3 | FG19: =FA19*(1+FG20) -> 359715.3 | FH19: =SUM(FD19:FG19) -> 1392827.5 | FJ19: =FD19*(1+FJ20) -> 346026.33 | FK19: =FE19*(1+FK20) -> 353295.15 | FL19: =FF19*(1+FL20) -> 364784.08 | FM19: =FG19*(1+FM20) -> 370506.76 | FN19: =SUM(FJ19:FM19) -> 1434612.3 | FP19: =FJ19*(1+FP20) -> 356407.12 | FQ19: =FK19*(1+FQ20) -> 363894 | FR19: =FL19*(1+FR20) -> 375727.6 | FS19: =FM19*(1+FS20) -> 381621.96 | FT19: =SUM(FP19:FS19) -> 1477650.7
C20: growth y/y | DH20: =DH19/DB19-1 -> 0.14930544 | DI20: =DI19/DC19-1 -> 0.14404718 | DJ20: =DJ19/DD19-1 -> 0.13748017 | DK20: =DK19/DE19-1 -> 0.13299375 | DL20: =DL19/DF19-1 -> 0.14071926 | DN20: =DN19/DH19-1 -> 0.31054174 | DO20: =DO19/DI19-1 -> 0.33731149 | DP20: =DP19/DJ19-1 -> 0.34877085 | DQ20: =DQ19/DK19-1 -> 0.27345205 | DR20: =DR19/DL19-1 -> 0.31689074 | DT20: =DT19/DN19-1 -> 0.06853536 | DU20: =DU19/DO19-1 -> -0.18170415 | DV20: =DV19/DP19-1 -> 0.019719142 | DW20: =DW19/DQ19-1 -> 0.051578213 | DX20: =DX19/DR19-1 -> -0.011614731 | DZ20: =DZ19/DT19-1 -> 0.042196536 | EA20: =EA19/DU19-1 -> 0.37341099 | EB20: =EB19/DV19-1 -> 0.067619726 | EC20: =EC19/DW19-1 -> 0.023998553 | ED20: =ED19/DX19-1 -> 0.11341309 | EF20: =EF19/DZ19-1 -> 0.019521654 | EG20: =EG19/EA19-1 -> -0.029690582 | EH20: =EH19/EB19-1 -> -0.0067208835 | EI20: =EI19/EC19-1 -> 0.023288931 | EJ20: =EJ19/ED19-1 -> 0.0011382374 | EL20: =EL19/EF19-1 -> 0.073076851 | EM20: =EM19/EG19-1 -> 0.081082269 | EN20: =EN19/EH19-1 -> 0.069169691 | EO20: =EO19/EI19-1 -> 0.060272071 | EP20: =EP19/EJ19-1 -> 0.070839748 | ER20: =ER19/EL19-1 -> 0.053773347 | ES20: =ES19/EM19-1 -> 0.056093197 | ET20: =ET19/EN19-1 -> 0.086062899 | EU20: =EU19/EO19-1 -> 0.09099203 | EV20: =EV19/EP19-1 -> 0.071807148 | EX20: =EX19/ER19-1 -> 0.084221164 | EY20: =EY19/ES19-1 -> 0.10053903 | EZ20: =EZ19/ET19-1 -> 0.10379764 | FA20: =FA19/EU19-1 -> 0.064993363 | FB20: =FB19/EV19-1 -> 0.088272178 | FD20: 0.03 | FE20: 0 | FF20: 0.02 | FG20: 0.05 | FH20: =FH19/FB19-1 -> 0.024914836 | FJ20: 0.03 | FK20: 0.03 | FL20: 0.03 | FM20: 0.03 | FN20: =FN19/FH19-1 -> 0.03 | FP20: 0.03 | FQ20: 0.03 | FR20: 0.03 | FS20: 0.03 | FT20: =FT19/FN19-1 -> 0.03
C22: Tests per case | DB22: =DB19/DB16 -> 1.645724 | DC22: =DC19/DC16 -> 1.6486141 | DD22: =DD19/DD16 -> 1.6656874 | DE22: =DE19/DE16 -> 1.7029616 | DF22: =DF19/DF16 -> 1.6663135 | DH22: =DH19/DH16 -> 1.6990944 | DI22: =DI19/DI16 -> 1.7019348 | DJ22: =DJ19/DJ16 -> 1.7123918 | DK22: =DK19/DK16 -> 1.7097097 | DL22: =DL19/DL16 -> 1.7058852 | DN22: =DN19/DN16 -> 1.7089584 | DO22: =DO19/DO16 -> 1.7266162 | DP22: =DP19/DP16 -> 1.7480602 | DQ22: =DQ19/DQ16 -> 1.7323979 | DR22: =DR19/DR16 -> 1.729233 | DT22: =DT19/DT16 -> 1.734879 | DU22: =DU19/DU16 -> 1.790391 | DV22: =DV19/DV16 -> 1.7317073 | DW22: =DW19/DW16 -> 1.7326565 | DX22: =DX19/DX16 -> 1.7447875 | DZ22: =DZ19/DZ16 -> 1.7264283 | EA22: =EA19/EA16 -> 1.7246273 | EB22: =EB19/EB16 -> 1.7085795 | EC22: =EC19/EC16 -> 1.7032585 | ED22: =ED19/ED16 -> 1.7156307
C23: growth y/y | DH23: =DH22/DB22-1 -> 0.032429701 | DI23: =DI22/DC22-1 -> 0.032342759 | DJ23: =DJ22/DD22-1 -> 0.028039117 | DK23: =DK22/DE22-1 -> 0.0039625552 | DL23: =DL22/DF22-1 -> 0.023748033 | DN23: =DN22/DH22-1 -> 0.0058054922 | DO23: =DO22/DI22-1 -> 0.014501985 | DP23: =DP22/DJ22-1 -> 0.020829573 | DQ23: =DQ22/DK22-1 -> 0.013270231 | DR23: =DR22/DL22-1 -> 0.013686612 | DT23: =DT22/DN22-1 -> 0.015167454 | DU23: =DU22/DO22-1 -> 0.03693625 | DV23: =DV22/DP22-1 -> -0.0093548606 | DW23: =DW22/DQ22-1 -> 0.00014926248 | DX23: =DX22/DR22-1 -> 0.0089950328 | DZ23: =DZ22/DT22-1 -> -0.0048710712 | EA23: =EA22/DU22-1 -> -0.036731455 | EB23: =EB22/DV22-1 -> -0.01335551 | EC23: =EC22/DW22-1 -> -0.016967037 | ED23: =ED22/DX22-1 -> -0.016710764
C25: ASP/test | DB25: =DB10/DB19*1000000 -> 329.94787 | DC25: =DC10/DC19*1000000 -> 329.89855 | DD25: =DD10/DD19*1000000 -> 310.7374 | DE25: =DE10/DE19*1000000 -> 305.60606 | DF25: =DF10/DF19*1000000 -> 318.68712 | DH25: =DH10/DH19*1000000 -> 318.64045 | DI25: =DI10/DI19*1000000 -> 318.07425 | DJ25: =DJ10/DJ19*1000000 -> 320.06913 | DK25: =DK10/DK19*1000000 -> 332.58991 | DL25: =DL10/DL19*1000000 -> 322.53948 | DN25: =DN10/DN19*1000000 -> 367.92038 | DO25: =DO10/DO19*1000000 -> 355.45879 | DP25: =DP10/DP19*1000000 -> 369.49441 | DQ25: =DQ10/DQ19*1000000 -> 370.10548 | DR25: =DR10/DR19*1000000 -> 365.71923 | DT25: =DT10/DT19*1000000 -> 371.36946 | DU25: =DU10/DU19*1000000 -> 360.68423 | DV25: =DV10/DV19*1000000 -> 425.63944 | DW25: =DW10/DW19*1000000 -> 402.19148 | DX25: =DX10/DX19*1000000 -> 391.71104 | DZ25: =DZ10/DZ19*1000000 -> 369.76558 | EA25: =EA10/EA19*1000000 -> 360.44218 | EB25: =EB10/EB19*1000000 -> 374.82584 | EC25: =EC10/EC19*1000000 -> 382.88563 | ED25: =ED10/ED19*1000000 -> 371.90274 | EF25: =EF10/EF19*1000000 -> 371.34588 | EG25: =EG10/EG19*1000000 -> 386.96691 | EH25: =EH10/EH19*1000000 -> 391.88775 | EI25: =EI10/EI19*1000000 -> 388.96181 | EJ25: =EJ10/EJ19*1000000 -> 384.88242 | EL25: =EL10/EL19*1000000 -> 402.37708 | EM25: =EM10/EM19*1000000 -> 417.31387 | EN25: =EN10/EN19*1000000 -> 440.38918 | EO25: =EO10/EO19*1000000 -> 441.09886 | EP25: =EP10/EP19*1000000 -> 425.40978 | ER25: =ER10/ER19*1000000 -> 447.21717 | ES25: =ES10/ES19*1000000 -> 453.64649 | ET25: =ET10/ET19*1000000 -> 463.44464 | EU25: 465 | EV25: =EV10/EV19*1000000 -> 457.49054 | EX25: 459 | EY25: 465 | EZ25: 481 | FA25: 496 | FB25: =FB10/FB19*1000000 -> 475.46281 | FD25: =EX25*(1+FD26) -> 488.835 | FE25: =EY25*(1+FE26) -> 511.5 | FF25: =EZ25*(1+FF26) -> 519.48 | FG25: =FA25*(1+FG26) -> 525.76 | FH25: =FH10/FH19*1000000 -> 511.74516 | FJ25: =FD25*(1+FJ26) -> 523.05345 | FK25: =FE25*(1+FK26) -> 547.305 | FL25: =FF25*(1+FL26) -> 555.8436 | FM25: =FG25*(1+FM26) -> 562.5632 | FN25: =FN10/FN19*1000000 -> 547.56733 | FP25: =FJ25*(1+FP26) -> 559.66719 | FQ25: =FK25*(1+FQ26) -> 585.61635 | FR25: =FL25*(1+FR26) -> 594.75265 | FS25: =FM25*(1+FS26) -> 601.94262 | FT25: =FT10/FT19*1000000 -> 585.89704
C26: growth y/y | DH26: =DH25/DB25-1 -> -0.034270328 | DI26: =DI25/DC25-1 -> -0.03584223 | DJ26: =DJ25/DD25-1 -> 0.030030905 | DK26: =DK25/DE25-1 -> 0.088296188 | DL26: =DL25/DF25-1 -> 0.012088218 | DN26: =DN25/DH25-1 -> 0.15465687 | DO26: =DO25/DI25-1 -> 0.11753403 | DP26: =DP25/DJ25-1 -> 0.15442063 | DQ26: =DQ25/DK25-1 -> 0.11279829 | DR26: =DR25/DL25-1 -> 0.13387431 | DT26: =DT25/DN25-1 -> 0.0093745254 | DU26: =DU25/DO25-1 -> 0.014700533 | DV26: =DV25/DP25-1 -> 0.15195097 | DW26: =DW25/DQ25-1 -> 0.086694218 | DX26: =DX25/DR25-1 -> 0.071070394 | DZ26: =DZ25/DT25-1 -> -0.0043188289 | EA26: =EA25/DU25-1 -> -0.00067108707 | EB26: =EB25/DV25-1 -> -0.1193818 | EC26: =EC25/DW25-1 -> -0.048001636 | ED26: =ED25/DX25-1 -> -0.050568639 | EF26: =EF25/DZ25-1 -> 0.004273779 | EG26: =EG25/EA25-1 -> 0.073589414 | EH26: =EH25/EB25-1 -> 0.045519581 | EI26: =EI25/EC25-1 -> 0.01586942 | EJ26: =EJ25/ED25-1 -> 0.034900736 | EL26: =EL25/EF25-1 -> 0.083564162 | EM26: =EM25/EG25-1 -> 0.078422633 | EN26: =EN25/EH25-1 -> 0.12376357 | EO26: =EO25/EI25-1 -> 0.13404158 | EP26: =EP25/EJ25-1 -> 0.10529802 | ER26: =ER25/EL25-1 -> 0.11143798 | ES26: =ES25/EM25-1 -> 0.087063043 | ET26: =ET25/EN25-1 -> 0.052352477 | EU26: =EU25/EO25-1 -> 0.05418544 | EV26: =EV25/EP25-1 -> 0.075411429 | EX26: =EX25/ER25-1 -> 0.026346995 | EY26: =EY25/ES25-1 -> 0.02502723 | EZ26: =EZ25/ET25-1 -> 0.037880164 | FA26: =FA25/EU25-1 -> 0.066666667 | FB26: =FB25/EV25-1 -> 0.039284456 | FD26: 0.065 | FE26: 0.1 | FF26: 0.08 | FG26: 0.06 | FH26: =FH25/FB25-1 -> 0.076309565 | FJ26: 0.07 | FK26: 0.07 | FL26: 0.07 | FM26: 0.07 | FN26: =FN25/FH25-1 -> 0.07 | FP26: 0.07 | FQ26: 0.07 | FR26: 0.07 | FS26: 0.07 | FT26: =FT25/FN25-1 -> 0.07
C28: Core ASP | DU28: 351 | DV28: 359 | DW28: 369 | DX28: 363 | DZ28: 355 | EA28: 360
C29: growth y/y | DU29: =DU28/DO25-1 -> -0.012543773 | DV29: =DV28/DP25-1 -> -0.028402074 | DW29: =DW28/DQ25-1 -> -0.0029869279 | DX29: =DX28/DR25-1 -> -0.0074352867 | DZ29: =DZ28/DT25-1 -> -0.044078639 | EA29: =EA28/DU25-1 -> -0.0018970278
C31: COVID revenues | DU31: =((DU25-DU28)*DU19)/1000000 -> 1.983756 | DV31: =((DV25-DV28)*DV19)/1000000 -> 17.023578 | DW31: =((DW25-DW28)*DW19)/1000000 -> 8.808721 | DX31: =((DX25-DX28)*DX19)/1000000 -> 28.023953 | DZ31: =((DZ25-DZ28)*DZ19)/1000000 -> 3.852945 | EA31: =((EA25-EA28)*EA19)/1000000 -> 0.1244
