Workbook
Name \A: #REF!
Name \B: #REF!
Name \C: #REF!
Name \D: #REF!
Name \E: #REF!
Name \F: #REF!
Name \G: #REF!
Name \H: #REF!
Name \I: #REF!
Name \P: #REF!
Name \S: [1]Model!#REF!
Name \X: [1]Model!#REF!
Name _1A_FUND: [3]Funding!#REF!
Name _2A_FUND: [3]Funding!#REF!
Name _2H_COV: [3]Worksheet!#REF!
Name _4H_COV: [3]Worksheet!#REF!
Name _5MKT_REL: #REF!
Name _6P_COV: [3]Worksheet!#REF!
Name _7MKT_REL: #REF!
Name _9P_COV: [3]Worksheet!#REF!
Name _GRM1: [1]Model!#REF!
Name _GRM2: [1]Model!#REF!
Name _GRM3: [1]Model!#REF!
Name _NM1: [1]Model!#REF!
Name _NM2: [1]Model!#REF!
Name _NM3: [1]Model!#REF!
Name _OM1: [1]Model!#REF!
Name _OM2: [1]Model!#REF!
Name _OM3: [1]Model!#REF!
Name _ROA1: [1]Model!#REF!
Name _ROA2: [1]Model!#REF!
Name _ROA3: [1]Model!#REF!
Name _ROE1: [1]Model!#REF!
Name _ROE2: [1]Model!#REF!
Name _ROE3: [1]Model!#REF!
Name a: [4]Q!#REF!
Name ab: [5]Q!$AB$15
Name ac: [5]Q!$AB$18
Name Acquisition_Y_or_N: [6]IS!#REF!
Name ad: [5]Q!$AB$28
Name ADJ: #REF!
Name ae: [4]Q!#REF!
Name af: [4]Q!#REF!
Name ag: [5]Q!$AB$29
Name ah: [5]Q!$AB$32
Name ai: [5]Q!$AB$42
Name aj: [5]Q!$AB$43
Name ak: [4]Q!#REF!
Name AMV: [1]Model!#REF!
Name AMVL12MOCF: [1]Model!#REF!
Name AMVL12MOPPR: [1]Model!#REF!
Name AMVL12MSAL: [1]Model!#REF!
Name AMVOCF: [1]Model!#REF!
Name AMVOI: [1]Model!#REF!
Name AMVSALES: [1]Model!#REF!
Name ARMINE: #REF!
Name Assets: [7]UNPEARN_IS!#REF!
Name ASSUMPT1: #REF!
Name ASSUMPT2: #REF!
Name Average_Tax_Rate__LTM: [7]UNPEARN_IS!#REF!

Sheet __FDSCACHE__
B1: This sheet contains FactSet XML data for use with this workbook's =FDS codes. Modifying the worksheet's contents may damage the workbook's =FDS functionality.

Sheet Disclaimer
C5: Equity Research
C7: Financial Model
C8: Airfreight & Surface Transportation - Railroads
C9: 46044
C12: CSX Corporation (NYSE: CSX)
C17: Wells Fargo Airfreight & Surface Transportation Team
C19: Christian Wetherbee
C20: Senior Analyst
C21: 212-214-8053
C22: Christian.Wetherbee@wellsfargo.com
C25: Robert Salmon, CFA | E25: Ryan Deveikis | G25: Matthew Hortopan
C26: Research Analyst | E26: Research Analyst | G26: Research Analyst
C27: 212-214-5016 | E27: 212-214-8040 | G27: 212-214-5009
C28: Robert.H.Salmon@wellsfargo.com | E28: Ryan.Deveikis@wellsfargo.com | G28: Matthew.F.Hortopan@wellsfargo.com
C32: Important Disclaimers:
C58: red font = assumption input

Sheet CSX
B1: Wells Fargo Securities, LLC
B2: =Disclaimer!$C$9 -> 46044 | KV2: =KV24*100 -> 60.955208 | KW2: =KW24*100 -> 60.367667 | KX2: =KX24*100 -> 64.427693 | KY2: =KY24*100 -> 64.266304 | LC2: =LC24*100 -> 63.678348 | LD2: =LD24*100 -> 60.875439 | LE2: =LE24*100 -> 62.58635 | LF2: =LF24*100 -> 65.696524 | LJ2: =LJ24*100 -> 69.588081 | LK2: =LK24*100 -> 64.101847 | LL2: =LL24*100 -> 64.148313 | LM2: =LM24*100 -> 66.875713 | LQ2: =LQ24*100 -> 66.217103 | LR2: =LR24*100 -> 62.419645 | LS2: =LS24*100 -> 62.015227 | LT2: =LT24*100 -> 63.843661
GG3: 38807 | JW3: 2019/4f | KA3: 2020/1f | KB3: 2020/2f | KC3: 2020/3f | KD3: 2020/4f | KE3: 2020 | KH3: 2021/1f | KI3: 2021/2f | KJ3: 2021/3f | KK3: 2021/4f | KL3: 2021 | KO3: 2021/1f | KP3: 2021/2f | KQ3: 2022/3f | KR3: 2022/4f | KS3: 2021 | KV3: 2023/1f | KW3: 2023/2f | KX3: 2023/3f | KY3: 2023/4f | KZ3: 2023 | LC3: 2024/1f | LD3: 2024/2f | LE3: 2024/3f | LF3: 2024/4f | LG3: 2024 | LJ3: 2025/1f | LK3: 2025/2f | LL3: 2025/3f | LM3: 2025/4f | LN3: 2025 | LQ3: 2025/1f | LR3: 2025/2f | LS3: 2025/3f | LT3: 2025/4f | LU3: 2026 | LX3: 2025/1f | LY3: 2025/2f | LZ3: 2025/3f | MA3: 2025/4f | MB3: 2027 | ME3: 2025/1f | MF3: 2025/2f | MG3: 2025/3f | MH3: 2025/4f | MI3: 208
B4: CSX - Summary | C4: =D4-1 -> 1978 | D4: =E4-1 -> 1979 | E4: =F4-1 -> 1980 | F4: =G4-1 -> 1981 | G4: =H4-1 -> 1982 | H4: =I4-1 -> 1983 | I4: =J4-1 -> 1984 | J4: =K4-1 -> 1985 | ... L4: =M4-1 -> 1987 | M4: =BV4-1 -> 1988 | N4: =BV4 -> 1989 | O4: =CC4 -> 1990 | P4: =CJ4 -> 1991 | Q4: =CQ4 -> 1992 | R4: =CX4 -> 1993 | S4: =DE4 -> 1994 | T4: =DL4 -> 1995 | U4: =DS4 -> 1996 | V4: =DZ4 -> 1997 | W4: =EG4 -> 1998 | X4: =EN4 -> 1999 | Y4: =EU4 -> 2000 | Z4: =FB4 -> 2001 | AA4: =FI4 -> 2002 | AB4: =FP4 -> 2003 | AC4: =FW4 -> 2004 | AD4: =GD4 -> 2005 | AE4: =GK4 -> 2006 | AF4: =GR4 -> 2007 | AG4: =GY4 -> 2008 | AH4: =HF4 -> 2009 | AI4: =HM4 -> 2010 | AJ4: =HT4 -> 2011 | AK4: =IA4 -> 2012 | AL4: =IH4 -> 2013 | AM4: =IO4 -> 2014 | AN4: =IV4 -> 2015 | AO4: =JC4 -> 2016 | AP4: =JJ4 -> 2017 | AQ4: =JQ4 -> 2018 | AR4: =JX4 -> 2019 | AS4: =KE4 -> 2020 | AT4: =KL4 -> 2021 | AU4: =KS4 -> 2022 | AV4: =KZ4 -> 2023 | AW4: =LG4 -> 2024 | AX4: =LN4 -> 2025 | AY4: =LU4 -> 2026E | AZ4: =MB4 -> 2027E | BA4: =MI4 -> 2028E | BQ4: CSX - Summary | BR4: 1Q89 | BS4: 2Q89 | BT4: 3Q89 | BU4: 4Q89 | BV4: 1989 | BX4: CSX - Summary | BY4: =LEFT(BR4,2)&RIGHT(CC4,2) -> 1Q90 | BZ4: =LEFT(BS4,2)&RIGHT(CC4,2) -> 2Q90 | CA4: =LEFT(BT4,2)&RIGHT(CC4,2) -> 3Q90 | CB4: =LEFT(BU4,2)&RIGHT(CC4,2) -> 4Q90 | CC4: =BV4+1 -> 1990 | CE4: CSX - Summary | CF4: =LEFT(BY4,2)&RIGHT(CJ4,2) -> 1Q91 | CG4: =LEFT(BZ4,2)&RIGHT(CJ4,2) -> 2Q91 | CH4: =LEFT(CA4,2)&RIGHT(CJ4,2) -> 3Q91 | CI4: =LEFT(CB4,2)&RIGHT(CJ4,2) -> 4Q91 | CJ4: =CC4+1 -> 1991 | CL4: CSX - Summary | CM4: =LEFT(CF4,2)&RIGHT(CQ4,2) -> 1Q92 | CN4: =LEFT(CG4,2)&RIGHT(CQ4,2) -> 2Q92 | CO4: =LEFT(CH4,2)&RIGHT(CQ4,2) -> 3Q92 | CP4: =LEFT(CI4,2)&RIGHT(CQ4,2) -> 4Q92 | CQ4: =CJ4+1 -> 1992 | CS4: CSX - Summary | CT4: =LEFT(CM4,2)&RIGHT(CX4,2) -> 1Q93 | CU4: =LEFT(CN4,2)&RIGHT(CX4,2) -> 2Q93 | CV4: =LEFT(CO4,2)&RIGHT(CX4,2) -> 3Q93 | CW4: =LEFT(CP4,2)&RIGHT(CX4,2) -> 4Q93 | CX4: =CQ4+1 -> 1993 | CZ4: CSX - Summary | DA4: =LEFT(CT4,2)&RIGHT(DE4,2) -> 1Q94 | DB4: =LEFT(CU4,2)&RIGHT(DE4,2) -> 2Q94 | DC4: =LEFT(CV4,2)&RIGHT(DE4,2) -> 3Q94 | DD4: =LEFT(CW4,2)&RIGHT(DE4,2) -> 4Q94 | DE4: =CX4+1 -> 1994 | DG4: CSX - Summary | DH4: =LEFT(DA4,2)&RIGHT(DL4,2) -> 1Q95 | DI4: =LEFT(DB4,2)&RIGHT(DL4,2) -> 2Q95 | DJ4: =LEFT(DC4,2)&RIGHT(DL4,2) -> 3Q95 | DK4: =LEFT(DD4,2)&RIGHT(DL4,2) -> 4Q95 | DL4: =DE4+1 -> 1995 | DN4: CSX - Summary | DO4: =LEFT(DH4,2)&RIGHT(DS4,2) -> 1Q96 | DP4: =LEFT(DI4,2)&RIGHT(DS4,2) -> 2Q96 | DQ4: =LEFT(DJ4,2)&RIGHT(DS4,2) -> 3Q96 | DR4: =LEFT(DK4,2)&RIGHT(DS4,2) -> 4Q96 | DS4: =DL4+1 -> 1996 | DU4: CSX - Summary | DV4: =LEFT(DO4,2)&RIGHT(DZ4,2) -> 1Q97 | DW4: =LEFT(DP4,2)&RIGHT(DZ4,2) -> 2Q97 | DX4: =LEFT(DQ4,2)&RIGHT(DZ4,2) -> 3Q97 | DY4: =LEFT(DR4,2)&RIGHT(DZ4,2) -> 4Q97 | DZ4: =DS4+1 -> 1997 | EB4: CSX - Summary | EC4: =LEFT(DV4,2)&RIGHT(EG4,2) -> 1Q98 | ED4: =LEFT(DW4,2)&RIGHT(EG4,2) -> 2Q98 | EE4: =LEFT(DX4,2)&RIGHT(EG4,2) -> 3Q98 | EF4: =LEFT(DY4,2)&RIGHT(EG4,2) -> 4Q98 | EG4: =DZ4+1 -> 1998 | EI4: CSX - Summary | EJ4: =LEFT(EC4,2)&RIGHT(EN4,2) -> 1Q99 | EK4: =LEFT(ED4,2)&RIGHT(EN4,2) -> 2Q99 | EL4: =LEFT(EE4,2)&RIGHT(EN4,2) -> 3Q99 | EM4: =LEFT(EF4,2)&RIGHT(EN4,2) -> 4Q99 | EN4: =EG4+1 -> 1999 | EP4: CSX - Summary | EQ4: =LEFT(EJ4,2)&RIGHT(EU4,2) -> 1Q00 | ER4: =LEFT(EK4,2)&RIGHT(EU4,2) -> 2Q00 | ES4: =LEFT(EL4,2)&RIGHT(EU4,2) -> 3Q00 | ET4: =LEFT(EM4,2)&RIGHT(EU4,2) -> 4Q00 | EU4: =EN4+1 -> 2000 | EW4: CSX - Summary | EX4: =LEFT(EQ4,2)&RIGHT(FB4,2) -> 1Q01 | EY4: =LEFT(ER4,2)&RIGHT(FB4,2) -> 2Q01 | EZ4: =LEFT(ES4,2)&RIGHT(FB4,2) -> 3Q01 | FA4: =LEFT(ET4,2)&RIGHT(FB4,2) -> 4Q01 | FB4: =EU4+1 -> 2001 | FD4: CSX - Summary | FE4: =LEFT(EX4,2)&RIGHT(FI4,2) -> 1Q02 | FF4: =LEFT(EY4,2)&RIGHT(FI4,2) -> 2Q02 | FG4: =LEFT(EZ4,2)&RIGHT(FI4,2) -> 3Q02 | FH4: =LEFT(FA4,2)&RIGHT(FI4,2) -> 4Q02 | FI4: =FB4+1 -> 2002 | FK4: CSX - Summary | FL4: =LEFT(FE4,2)&RIGHT(FP4,2) -> 1Q03 | FM4: =LEFT(FF4,2)&RIGHT(FP4,2) -> 2Q03 | FN4: =LEFT(FG4,2)&RIGHT(FP4,2) -> 3Q03 | FO4: =LEFT(FH4,2)&RIGHT(FP4,2) -> 4Q03 | FP4: =FI4+1 -> 2003 | FR4: CSX - Summary | FS4: =LEFT(FL4,2)&RIGHT(FW4,2) -> 1Q04 | FT4: =LEFT(FM4,2)&RIGHT(FW4,2) -> 2Q04 | FU4: =LEFT(FN4,2)&RIGHT(FW4,2) -> 3Q04 | FV4: =LEFT(FO4,2)&RIGHT(FW4,2) -> 4Q04 | FW4: =FP4+1 -> 2004 | FY4: CSX - Summary | FZ4: =LEFT(FS4,2)&RIGHT(GD4,2) -> 1Q05 | GA4: =LEFT(FT4,2)&RIGHT(GD4,2) -> 2Q05 | GB4: =LEFT(FU4,2)&RIGHT(GD4,2) -> 3Q05 | GC4: =LEFT(FV4,2)&RIGHT(GD4,2) -> 4Q05 | GD4: =FW4+1 -> 2005 | GF4: CSX - Summary | GG4: =LEFT(FZ4,2)&RIGHT(GK4,2) -> 1Q06 | GH4: =LEFT(GA4,2)&RIGHT(GK4,2) -> 2Q06 | GI4: =LEFT(GB4,2)&RIGHT(GK4,2) -> 3Q06 | GJ4: =LEFT(GC4,2)&RIGHT(GK4,2) -> 4Q06 | GK4: =GD4+1 -> 2006 | GM4: CSX - Summary | GN4: =LEFT(GG4,2)&RIGHT(GR4,2) -> 1Q07 | GO4: =LEFT(GH4,2)&RIGHT(GR4,2) -> 2Q07 | GP4: =LEFT(GI4,2)&RIGHT(GR4,2) -> 3Q07 | GQ4: =LEFT(GJ4,2)&RIGHT(GR4,2) -> 4Q07 | GR4: =GK4+1 -> 2007 | GT4: CSX - Summary | GU4: =LEFT(GN4,2)&RIGHT(GY4,2) -> 1Q08 | GV4: =LEFT(GO4,2)&RIGHT(GY4,2) -> 2Q08 | GW4: =LEFT(GP4,2)&RIGHT(GY4,2) -> 3Q08 | GX4: =LEFT(GQ4,2)&RIGHT(GY4,2) -> 4Q08 | GY4: =GR4+1 -> 2008 | HA4: CSX - Summary | HB4: =LEFT(GU4,2)&RIGHT(HF4,2) -> 1Q09 | HC4: =LEFT(GV4,2)&RIGHT(HF4,2) -> 2Q09 | HD4: =LEFT(GW4,2)&RIGHT(HF4,2) -> 3Q09 | HE4: =LEFT(GX4,2)&RIGHT(HF4,2) -> 4Q09 | HF4: =GY4+1 -> 2009 | HH4: CSX - Summary | HI4: =LEFT(HB4,2)&RIGHT(HM4,2) -> 1Q10 | HJ4: =LEFT(HC4,2)&RIGHT(HM4,2) -> 2Q10 | HK4: =LEFT(HD4,2)&RIGHT(HM4,2) -> 3Q10 | HL4: =LEFT(HE4,2)&RIGHT(HM4,2) -> 4Q10 | HM4: =HF4+1 -> 2010 | HO4: CSX - Summary | HP4: =LEFT(HI4,2)&RIGHT(HT4,2) -> 1Q11 | HQ4: =LEFT(HJ4,2)&RIGHT(HT4,2) -> 2Q11 | HR4: =LEFT(HK4,2)&RIGHT(HT4,2) -> 3Q11 | HS4: =LEFT(HL4,2)&RIGHT(HT4,2) -> 4Q11 | HT4: =HM4+1 -> 2011 | HV4: CSX - Summary | HW4: =LEFT(HP4,2)&RIGHT(IA4,2) -> 1Q12 | HX4: =LEFT(HQ4,2)&RIGHT(IA4,2) -> 2Q12 | HY4: =LEFT(HR4,2)&RIGHT(IA4,2) -> 3Q12 | HZ4: =LEFT(HS4,2)&RIGHT(IA4,2) -> 4Q12 | IA4: =HT4+1 -> 2012 | IC4: CSX - Summary | ID4: =LEFT(HW4,2)&RIGHT(IH4,2) -> 1Q13 | IE4: =LEFT(HX4,2)&RIGHT(IH4,2) -> 2Q13 | IF4: =LEFT(HY4,2)&RIGHT(IH4,2) -> 3Q13 | IG4: =LEFT(HZ4,2)&RIGHT(IH4,2) -> 4Q13 | IH4: =IA4+1 -> 2013 | IJ4: CSX - Summary | IK4: =LEFT(ID4,2)&RIGHT(IO4,2) -> 1Q14 | IL4: =LEFT(IE4,2)&RIGHT(IO4,2) -> 2Q14 | IM4: =LEFT(IF4,2)&RIGHT(IO4,2) -> 3Q14 | IN4: =LEFT(IG4,2)&RIGHT(IO4,2) -> 4Q14 | IO4: =IH4+1 -> 2014 | IQ4: CSX - Summary | IR4: =LEFT(IK4,2)&RIGHT(IV4,2) -> 1Q15 | IS4: =LEFT(IL4,2)&RIGHT(IV4,2) -> 2Q15 | IT4: =LEFT(IM4,2)&RIGHT(IV4,2) -> 3Q15 | IU4: =LEFT(IN4,2)&RIGHT(IV4,2) -> 4Q15 | IV4: =IO4+1 -> 2015 | IX4: CSX - Summary | IY4: =LEFT(IR4,2)&RIGHT(JC4,2) -> 1Q16 | IZ4: =LEFT(IS4,2)&RIGHT(JC4,2) -> 2Q16 | JA4: =LEFT(IT4,2)&RIGHT(JC4,2) -> 3Q16 | JB4: =LEFT(IU4,2)&RIGHT(JC4,2) -> 4Q16 | JC4: =IV4+1 -> 2016 | JE4: CSX - Summary | JF4: =LEFT(IY4,2)&RIGHT(JJ4,2) -> 1Q17 | JG4: =LEFT(IZ4,2)&RIGHT(JJ4,2) -> 2Q17 | JH4: =LEFT(JA4,2)&RIGHT(JJ4,2) -> 3Q17 | JI4: =LEFT(JB4,2)&RIGHT(JJ4,2) -> 4Q17 | JJ4: =JC4+1 -> 2017 | JL4: CSX - Summary | JM4: =LEFT(JF4,2)&RIGHT(JQ4,2) -> 1Q18 | JN4: =LEFT(JG4,2)&RIGHT(JQ4,2) -> 2Q18 | JO4: =LEFT(JH4,2)&RIGHT(JQ4,2) -> 3Q18 | JP4: =LEFT(JI4,2)&RIGHT(JQ4,2) -> 4Q18 | JQ4: =JJ4+1 -> 2018 | JS4: CSX - Summary | JT4: =LEFT(JM4,2)&RIGHT(JX4,2) -> 1Q19 | JU4: =LEFT(JN4,2)&RIGHT(JX4,2) -> 2Q19 | JV4: =LEFT(JO4,2)&RIGHT(JX4,2) -> 3Q19 | JW4: =LEFT(JP4,2)&RIGHT(JX4,2) -> 4Q19 | JX4: =JQ4+1 -> 2019 | JZ4: CSX - Summary | KA4: =LEFT(JT4,2)&RIGHT(KE4,2) -> 1Q20 | KB4: =LEFT(JU4,2)&RIGHT(KE4,2) -> 2Q20 | KC4: =LEFT(JV4,2)&RIGHT(KE4,2) -> 3Q20 | KD4: =LEFT(JW4,2)&RIGHT(KE4,2) -> 4Q20 | KE4: =JX4+1 -> 2020 | KG4: CSX - Summary | KH4: =LEFT(KA4,2)&RIGHT(KL4,2) -> 1Q21 | KI4: =LEFT(KB4,2)&RIGHT(KL4,2) -> 2Q21 | KJ4: =LEFT(KC4,2)&RIGHT(KL4,2) -> 3Q21 | KK4: =LEFT(KD4,2)&RIGHT(KL4,2) -> 4Q21 | KL4: =KE4+1 -> 2021 | KN4: CSX - Summary | KO4: =LEFT(KH4,2)&RIGHT(KS4,2) -> 1Q22 | KP4: =LEFT(KI4,2)&RIGHT(KS4,2) -> 2Q22 | KQ4: =LEFT(KJ4,2)&RIGHT(KS4,2) -> 3Q22 | KR4: =LEFT(KK4,2)&RIGHT(KS4,2) -> 4Q22 | KS4: =KL4+1 -> 2022 | KU4: CSX - Summary | KV4: =LEFT(KO4,2)&RIGHT(KZ4,2) -> 1Q23 | KW4: =LEFT(KP4,2)&RIGHT(KZ4,2) -> 2Q23 | KX4: =LEFT(KQ4,2)&RIGHT(KZ4,2) -> 3Q23 | KY4: =LEFT(KR4,2)&RIGHT(KZ4,2) -> 4Q23 | KZ4: =KS4+1 -> 2023 | LB4: CSX - Summary | LC4: =LEFT(KV4,2)&RIGHT($LG$3,2) -> 1Q24 | LD4: =LEFT(KW4,2)&RIGHT($LG$3,2) -> 2Q24 | LE4: =LEFT(KX4,2)&RIGHT($LG$3,2) -> 3Q24 | LF4: =LEFT(KY4,2)&RIGHT($LG$3,2) -> 4Q24 | LG4: =KZ4+1 -> 2024 | LI4: CSX - Summary | LJ4: 1Q25 | LK4: 2Q25 | LL4: 3Q25 | LM4: 4Q25 | LN4: =LG4+1 -> 2025 | LP4: CSX - Summary | LQ4: 1Q26E | LR4: 2Q26E | LS4: 3Q26E | LT4: 4Q26E | LU4: =CONCATENATE(TEXT(LT5,"YYYY"),"E") -> 2026E | LW4: CSX - Summary | LX4: =LEFT(LQ4,2)&RIGHT(MB4,3) -> 1Q27E | LY4: =LEFT(LR4,2)&RIGHT(MB4,3) -> 2Q27E | LZ4: =LEFT(LS4,2)&RIGHT(MB4,3) -> 3Q27E | MA4: =LEFT(LT4,2)&RIGHT(MB4,3) -> 4Q27E | MB4: =CONCATENATE(TEXT(MA5,"YYYY"),"E") -> 2027E | MD4: CSX - Summary | ME4: =LEFT(LX4,2)&RIGHT(MI4,3) -> 1Q28E | MF4: =LEFT(LY4,2)&RIGHT(MI4,3) -> 2Q28E | MG4: =LEFT(LZ4,2)&RIGHT(MI4,3) -> 3Q28E | MH4: =LEFT(MA4,2)&RIGHT(MI4,3) -> 4Q28E | MI4: =CONCATENATE(TEXT(MH5,"YYYY"),"E") -> 2028E
B5: ($ in millions except per share amounts) | C5: FY | D5: FY | E5: FY | F5: FY | G5: FY | H5: FY | I5: FY | J5: FY | K5: FY | L5: FY | M5: FY | N5: =BV5 -> FY | O5: =CC5 -> FY | P5: =CJ5 -> FY | Q5: =CQ5 -> FY | R5: =CX5 -> FY | S5: =DE5 -> FY | T5: =DL5 -> FY | U5: =DS5 -> FY | V5: =DZ5 -> FY | W5: =EG5 -> FY | X5: =EN5 -> FY | Y5: =EU5 -> FY | Z5: =FB5 -> FY | AA5: =FI5 -> FY | AB5: =FP5 -> FY | AC5: =FW5 -> FY | AD5: =GD5 -> FY | AE5: =GK5 -> FY | AF5: =GR5 -> FY | AG5: =GY5 -> FY | AH5: =HF5 -> FY | AI5: =HM5 -> FY | AJ5: =HT5 -> FY | AK5: =IA5 -> FY | AL5: =IH5 -> FY | AM5: =IO5 -> FY | AN5: =IV5 -> FY | AO5: =JC5 -> FY | AP5: =JJ5 -> FY | AQ5: =JQ5 -> FY | AR5: =JX5 -> FY | AS5: =KE5 -> FY | AT5: =KL5 -> FY | AU5: =KS5 -> FY | AV5: =KZ5 -> FY | AW5: =LG5 -> FY | AX5: =LN5 -> FY | AY5: =LU5 -> FY | AZ5: =MB5 -> FY | BA5: =MI5 -> FY | BQ5: ($ in millions except per share amounts) | BR5: 32598 | BS5: =EOMONTH(BR5,3) -> 32689 | BT5: =EOMONTH(BS5,3) -> 32781 | BU5: =EOMONTH(BT5,3) -> 32873 | BV5: FY | BX5: ($ in millions except per share amounts) | BY5: =EOMONTH(BR5,12) -> 32963 | BZ5: =EOMONTH(BY5,3) -> 33054 | CA5: =EOMONTH(BZ5,3) -> 33146 | CB5: =EOMONTH(CA5,3) -> 33238 | CC5: FY | CE5: ($ in millions except per share amounts) | CF5: =EOMONTH(BY5,12) -> 33328 | CG5: =EOMONTH(CF5,3) -> 33419 | CH5: =EOMONTH(CG5,3) -> 33511 | CI5: =EOMONTH(CH5,3) -> 33603 | CJ5: FY | CL5: ($ in millions except per share amounts) | CM5: =EOMONTH(CF5,12) -> 33694 | CN5: =EOMONTH(CM5,3) -> 33785 | CO5: =EOMONTH(CN5,3) -> 33877 | CP5: =EOMONTH(CO5,3) -> 33969 | CQ5: FY | CS5: ($ in millions except per share amounts) | CT5: =EOMONTH(CM5,12) -> 34059 | CU5: =EOMONTH(CT5,3) -> 34150 | CV5: =EOMONTH(CU5,3) -> 34242 | CW5: =EOMONTH(CV5,3) -> 34334 | CX5: FY | CZ5: ($ in millions except per share amounts) | DA5: =EOMONTH(CT5,12) -> 34424 | DB5: =EOMONTH(DA5,3) -> 34515 | DC5: =EOMONTH(DB5,3) -> 34607 | DD5: =EOMONTH(DC5,3) -> 34699 | DE5: FY | DG5: ($ in millions except per share amounts) | DH5: =EOMONTH(DA5,12) -> 34789 | DI5: =EOMONTH(DH5,3) -> 34880 | DJ5: =EOMONTH(DI5,3) -> 34972 | DK5: =EOMONTH(DJ5,3) -> 35064 | DL5: FY | DN5: ($ in millions except per share amounts) | DO5: =EOMONTH(DH5,12) -> 35155 | DP5: =EOMONTH(DO5,3) -> 35246 | DQ5: =EOMONTH(DP5,3) -> 35338 | DR5: =EOMONTH(DQ5,3) -> 35430 | DS5: FY | DU5: ($ in millions except per share amounts) | DV5: =EOMONTH(DO5,12) -> 35520 | DW5: =EOMONTH(DV5,3) -> 35611 | DX5: =EOMONTH(DW5,3) -> 35703 | DY5: =EOMONTH(DX5,3) -> 35795 | DZ5: FY | EB5: ($ in millions except per share amounts) | EC5: =EOMONTH(DV5,12) -> 35885 | ED5: =EOMONTH(EC5,3) -> 35976 | EE5: =EOMONTH(ED5,3) -> 36068 | EF5: =EOMONTH(EE5,3) -> 36160 | EG5: FY | EI5: ($ in millions except per share amounts) | EJ5: =EOMONTH(EC5,12) -> 36250 | EK5: =EOMONTH(EJ5,3) -> 36341 | EL5: =EOMONTH(EK5,3) -> 36433 | EM5: =EOMONTH(EL5,3) -> 36525 | EN5: FY | EP5: ($ in millions except per share amounts) | EQ5: =EOMONTH(EJ5,12) -> 36616 | ER5: =EOMONTH(EQ5,3) -> 36707 | ES5: =EOMONTH(ER5,3) -> 36799 | ET5: =EOMONTH(ES5,3) -> 36891 | EU5: FY | EW5: ($ in millions except per share amounts) | EX5: =EOMONTH(EQ5,12) -> 36981 | EY5: =EOMONTH(EX5,3) -> 37072 | EZ5: =EOMONTH(EY5,3) -> 37164 | FA5: =EOMONTH(EZ5,3) -> 37256 | FB5: FY | FD5: ($ in millions except per share amounts) | FE5: =EOMONTH(EX5,12) -> 37346 | FF5: =EOMONTH(FE5,3) -> 37437 | FG5: =EOMONTH(FF5,3) -> 37529 | FH5: =EOMONTH(FG5,3) -> 37621 | FI5: FY | FK5: ($ in millions except per share amounts) | FL5: =EOMONTH(FE5,12) -> 37711 | FM5: =EOMONTH(FL5,3) -> 37802 | FN5: =EOMONTH(FM5,3) -> 37894 | FO5: =EOMONTH(FN5,3) -> 37986 | FP5: FY | FR5: ($ in millions except per share amounts) | FS5: =EOMONTH(FL5,12) -> 38077 | FT5: =EOMONTH(FS5,3) -> 38168 | FU5: =EOMONTH(FT5,3) -> 38260 | FV5: =EOMONTH(FU5,3) -> 38352 | FW5: FY | FY5: ($ in millions except per share amounts) | FZ5: =EOMONTH(FS5,12) -> 38442 | GA5: =EOMONTH(FZ5,3) -> 38533 | GB5: =EOMONTH(GA5,3) -> 38625 | GC5: =EOMONTH(GB5,3) -> 38717 | GD5: FY | GF5: ($ in millions except per share amounts) | GG5: =EOMONTH(FZ5,12) -> 38807 | GH5: =EOMONTH(GG5,3) -> 38898 | GI5: =EOMONTH(GH5,3) -> 38990 | GJ5: =EOMONTH(GI5,3) -> 39082 | GK5: FY | GM5: ($ in millions except per share amounts) | GN5: =EOMONTH(GG5,12) -> 39172 | GO5: =EOMONTH(GN5,3) -> 39263 | GP5: =EOMONTH(GO5,3) -> 39355 | GQ5: =EOMONTH(GP5,3) -> 39447 | GR5: FY | GT5: ($ in millions except per share amounts) | GU5: =EOMONTH(GN5,12) -> 39538 | GV5: =EOMONTH(GU5,3) -> 39629 | GW5: =EOMONTH(GV5,3) -> 39721 | GX5: =EOMONTH(GW5,3) -> 39813 | GY5: FY | HA5: ($ in millions except per share amounts) | HB5: =EOMONTH(GU5,12) -> 39903 | HC5: =EOMONTH(HB5,3) -> 39994 | HD5: =EOMONTH(HC5,3) -> 40086 | HE5: =EOMONTH(HD5,3) -> 40178 | HF5: FY | HH5: ($ in millions except per share amounts) | HI5: =EOMONTH(HB5,12) -> 40268 | HJ5: =EOMONTH(HI5,3) -> 40359 | HK5: =EOMONTH(HJ5,3) -> 40451 | HL5: =EOMONTH(HK5,3) -> 40543 | HM5: FY | HO5: ($ in millions except per share amounts) | HP5: =EOMONTH(HI5,12) -> 40633 | HQ5: =EOMONTH(HP5,3) -> 40724 | HR5: =EOMONTH(HQ5,3) -> 40816 | HS5: =EOMONTH(HR5,3) -> 40908 | HT5: FY | HV5: ($ in millions except per share amounts) | HW5: =EOMONTH(HP5,12) -> 40999 | HX5: =EOMONTH(HW5,3) -> 41090 | HY5: =EOMONTH(HX5,3) -> 41182 | HZ5: =EOMONTH(HY5,3) -> 41274 | IA5: FY | IC5: ($ in millions except per share amounts) | ID5: =EOMONTH(HW5,12) -> 41364 | IE5: =EOMONTH(ID5,3) -> 41455 | IF5: =EOMONTH(IE5,3) -> 41547 | IG5: =EOMONTH(IF5,3) -> 41639 | IH5: FY | IJ5: ($ in millions except per share amounts) | IK5: =EOMONTH(ID5,12) -> 41729 | IL5: =EOMONTH(IK5,3) -> 41820 | IM5: =EOMONTH(IL5,3) -> 41912 | IN5: =EOMONTH(IM5,3) -> 42004 | IO5: FY | IQ5: ($ in millions except per share amounts) | IR5: =EOMONTH(IK5,12) -> 42094 | IS5: =EOMONTH(IR5,3) -> 42185 | IT5: =EOMONTH(IS5,3) -> 42277 | IU5: =EOMONTH(IT5,3) -> 42369 | IV5: FY | IX5: ($ in millions except per share amounts) | IY5: =EOMONTH(IR5,12) -> 42460 | IZ5: =EOMONTH(IY5,3) -> 42551 | JA5: =EOMONTH(IZ5,3) -> 42643 | JB5: =EOMONTH(JA5,3) -> 42735 | JC5: FY | JE5: ($ in millions except per share amounts) | JF5: =EOMONTH(IY5,12) -> 42825 | JG5: =EOMONTH(JF5,3) -> 42916 | JH5: =EOMONTH(JG5,3) -> 43008 | JI5: =EOMONTH(JH5,3) -> 43100 | JJ5: FY | JL5: ($ in millions except per share amounts) | JM5: =EOMONTH(JF5,12) -> 43190 | JN5: =EOMONTH(JM5,3) -> 43281 | JO5: =EOMONTH(JN5,3) -> 43373 | JP5: =EOMONTH(JO5,3) -> 43465 | JQ5: FY | JS5: ($ in millions except per share amounts) | JT5: =EOMONTH(JM5,12) -> 43555 | JU5: =EOMONTH(JT5,3) -> 43646 | JV5: =EOMONTH(JU5,3) -> 43738 | JW5: =EOMONTH(JV5,3) -> 43830 | JX5: FY | JZ5: ($ in millions except per share amounts) | KA5: =EOMONTH(JT5,12) -> 43921 | KB5: =EOMONTH(KA5,3) -> 44012 | KC5: =EOMONTH(KB5,3) -> 44104 | KD5: =EOMONTH(KC5,3) -> 44196 | KE5: FY | KG5: ($ in millions except per share amounts) | KH5: =EOMONTH(KA5,12) -> 44286 | KI5: =EOMONTH(KH5,3) -> 44377 | KJ5: =EOMONTH(KI5,3) -> 44469 | KK5: =EOMONTH(KJ5,3) -> 44561 | KL5: FY | KN5: ($ in millions except per share amounts) | KO5: =EOMONTH(KH5,12) -> 44651 | KP5: =EOMONTH(KO5,3) -> 44742 | KQ5: =EOMONTH(KP5,3) -> 44834 | KR5: =EOMONTH(KQ5,3) -> 44926 | KS5: FY | KU5: ($ in millions except per share amounts) | KV5: =EOMONTH(KO5,12) -> 45016 | KW5: =EOMONTH(KV5,3) -> 45107 | KX5: =EOMONTH(KW5,3) -> 45199 | KY5: =EOMONTH(KX5,3) -> 45291 | KZ5: FY | LB5: ($ in millions except per share amounts) | LC5: =EOMONTH(KV5,12) -> 45382 | LD5: =EOMONTH(LC5,3) -> 45473 | LE5: =EOMONTH(LD5,3) -> 45565 | LF5: =EOMONTH(LE5,3) -> 45657 | LG5: FY | LI5: ($ in millions except per share amounts) | LJ5: =EOMONTH(LC5,12) -> 45747 | LK5: =EOMONTH(LJ5,3) -> 45838 | LL5: =EOMONTH(LK5,3) -> 45930 | LM5: =EOMONTH(LL5,3) -> 46022 | LN5: FY | LP5: ($ in millions except per share amounts) | LQ5: =EOMONTH(LJ5,12) -> 46112 | LR5: =EOMONTH(LQ5,3) -> 46203 | LS5: =EOMONTH(LR5,3) -> 46295 | LT5: =EOMONTH(LS5,3) -> 46387 | LU5: FY | LW5: ($ in millions except per share amounts) | LX5: =EOMONTH(LQ5,12) -> 46477 | LY5: =EOMONTH(LX5,3) -> 46568 | LZ5: =EOMONTH(LY5,3) -> 46660 | MA5: =EOMONTH(LZ5,3) -> 46752 | MB5: FY | MD5: ($ in millions except per share amounts) | ME5: =EOMONTH(LX5,12) -> 46843 | MF5: =EOMONTH(ME5,3) -> 46934 | MG5: =EOMONTH(MF5,3) -> 47026 | MH5: =EOMONTH(MG5,3) -> 47118 | MI5: FY
B7: Revenue | C7: =+C20 -> 3623.525 | D7: =+D20 -> 4219.9 | E7: =+E20 -> 4723.4 | F7: =+F20 -> 5345.2 | G7: =+G20 -> 4855 | H7: =+H20 -> 4902 | I7: =+I20 -> 5597 | J7: =+J20 -> 5361 | ... M7: =+M20 -> 7592 | N7: =BV7 -> 7745 | O7: =CC7 -> 8205.317 | P7: =CJ7 -> 8636.3 | Q7: =CQ7 -> 8734.1 | R7: =CX7 -> 8940.5 | S7: =DE7 -> 9608 | T7: =DL7 -> 10304 | U7: =DS7 -> 10536 | V7: =DZ7 -> 10963 | W7: =EG7 -> 9861 | X7: =EN7 -> 10811 | Y7: =EU7 -> 8435 | Z7: =FB7 -> 8110 | AA7: =FI7 -> 8152 | AB7: =FP7 -> 7567 | AC7: =FW7 -> 8025 | AD7: =GD7 -> 8601 | AE7: =GK7 -> 9566 | AF7: =GR7 -> 10030 | AG7: =GY7 -> 11255 | AH7: =HF7 -> 9041 | AI7: =HM7 -> 10636 | AJ7: =HT7 -> 11743 | AK7: =IA7 -> 11756 | AL7: =IH7 -> 12058 | AM7: =IO7 -> 12669 | AN7: =IV7 -> 11811 | AO7: =JC7 -> 11069 | AP7: =JJ7 -> 11408 | AQ7: =JQ7 -> 12250 | AR7: =JX7 -> 11937 | AS7: =KE7 -> 10583 | AT7: =KL7 -> 12522 | AU7: =KS7 -> 14853 | AV7: =KZ7 -> 14657 | AW7: =LG7 -> 14540 | AX7: =LN7 -> 14092 | AY7: =LU7 -> 14494.795 | AZ7: =MB7 -> 15180.906 | BA7: =MI7 -> 15848.637 | BQ7: Revenue | BR7: =+BR20 -> 1843.8 | BS7: =+BS20 -> 1974 | BT7: =+BT20 -> 1892.9 | BU7: =+BU20 -> 2034.3 | BV7: =+BV20 -> 7745 | BX7: Revenue | BY7: =+BY20 -> 1907.7 | BZ7: =+BZ20 -> 2046.9 | CA7: =+CA20 -> 2063 | CB7: =+CB20 -> 2187.717 | CC7: =+CC20 -> 8205.317 | CE7: Revenue | CF7: =+CF20 -> 2030.3 | CG7: =+CG20 -> 2125 | CH7: =+CH20 -> 2204.9 | CI7: =+CI20 -> 2276.1 | CJ7: =+CJ20 -> 8636.3 | CL7: Revenue | CM7: =+CM20 -> 2086.4 | CN7: =+CN20 -> 2188.2 | CO7: =+CO20 -> 2214.3 | CP7: =+CP20 -> 2245.2 | CQ7: =+CQ20 -> 8734.1 | CS7: Revenue | CT7: =+CT20 -> 2123.3 | CU7: =+CU20 -> 2263.5 | CV7: =+CV20 -> 2238.7 | CW7: =+CW20 -> 2315 | CX7: =+CX20 -> 8940.5 | CZ7: Revenue | DA7: =+DA20 -> 2227 | DB7: =+DB20 -> 2371 | DC7: =+DC20 -> 2470 | DD7: =+DD20 -> 2540 | DE7: =+DE20 -> 9608 | DG7: Revenue | DH7: =+DH20 -> 2444 | DI7: =+DI20 -> 2549 | DJ7: =+DJ20 -> 2601 | DK7: =+DK20 -> 2710 | DL7: =+DL20 -> 10304 | DN7: Revenue | DO7: =+DO20 -> 2514 | DP7: =+DP20 -> 2672 | DQ7: =+DQ20 -> 2647 | DR7: =+DR20 -> 2703 | DS7: =+DS20 -> 10536 | DU7: Revenue | DV7: =+DV20 -> 2567 | DW7: =+DW20 -> 2678 | DX7: =+DX20 -> 2815 | DY7: =+DY20 -> 2903 | DZ7: =+DZ20 -> 10963 | EB7: Revenue | EC7: =+EC20 -> 2442 | ED7: =+ED20 -> 2490 | EE7: =+EE20 -> 2429 | EF7: =+EF20 -> 2500 | EG7: =+EG20 -> 9861 | EI7: Revenue | EJ7: =+EJ20 -> 2541 | EK7: =+EK20 -> 2616 | EL7: =+EL20 -> 2906 | EM7: =+EM20 -> 2748 | EN7: =+EN20 -> 10811 | EP7: Revenue | EQ7: =+EQ20 -> 2147 | ER7: =+ER20 -> 2202 | ES7: =+ES20 -> 2039 | ET7: =+ET20 -> 2047 | EU7: =+EU20 -> 8435 | EW7: Revenue | EX7: =+EX20 -> 2025 | EY7: =+EY20 -> 2057 | EZ7: =+EZ20 -> 2019 | FA7: =+FA20 -> 2009 | FB7: =+FB20 -> 8110 | FD7: Revenue | FE7: =+FE20 -> 1964 | FF7: =+FF20 -> 2073 | FG7: =+FG20 -> 2055 | FH7: =+FH20 -> 2060 | FI7: =+FI20 -> 8152 | FK7: Revenue | FL7: =+FL20 -> 1960 | FM7: =+FM20 -> 1888 | FN7: =+FN20 -> 1823 | FO7: =+FO20 -> 1896 | FP7: =+FP20 -> 7567 | FR7: Revenue | FS7: =+FS20 -> 1920 | FT7: =+FT20 -> 1995 | FU7: =+FU20 -> 1938 | FV7: =+FV20 -> 2172 | FW7: =+FW20 -> 8025 | FY7: Revenue | FZ7: =+FZ20 -> 2108 | GA7: =+GA20 -> 2149 | GB7: =+GB20 -> 2125 | GC7: =+GC20 -> 2219 | GD7: =+GD20 -> 8601 | GF7: Revenue | GG7: =+GG20 -> 2331 | GH7: =+GH20 -> 2421 | GI7: =+GI20 -> 2418 | GJ7: =+GJ20 -> 2396 | GK7: =+GK20 -> 9566 | GM7: Revenue | GN7: =+GN20 -> 2422 | GO7: =+GO20 -> 2530 | GP7: =+GP20 -> 2501 | GQ7: =+GQ20 -> 2577 | GR7: =+GR20 -> 10030 | GT7: Revenue | GU7: =+GU20 -> 2713 | GV7: =+GV20 -> 2907 | GW7: =+GW20 -> 2961 | GX7: =+GX20 -> 2674 | GY7: =+GY20 -> 11255 | HA7: Revenue | HB7: =+HB20 -> 2247 | HC7: =+HC20 -> 2185 | HD7: =+HD20 -> 2289 | HE7: =+HE20 -> 2320 | HF7: =+HF20 -> 9041 | HH7: Revenue | HI7: =+HI20 -> 2491 | HJ7: =+HJ20 -> 2663 | HK7: =+HK20 -> 2666 | HL7: =+HL20 -> 2816 | HM7: =+HM20 -> 10636 | HO7: Revenue | HP7: =+HP20 -> 2810 | HQ7: =+HQ20 -> 3019 | HR7: =+HR20 -> 2963 | HS7: =+HS20 -> 2951 | HT7: =+HT20 -> 11743 | HV7: Revenue | HW7: =+HW20 -> 2966 | HX7: =+HX20 -> 3012 | HY7: =+HY20 -> 2894 | HZ7: =+HZ20 -> 2884 | IA7: =+IA20 -> 11756 | IC7: Revenue | ID7: =+ID20 -> 2958 | IE7: =+IE20 -> 3069 | IF7: =+IF20 -> 2999 | IG7: =+IG20 -> 3032 | IH7: =+IH20 -> 12058 | IJ7: Revenue | IK7: =+IK20 -> 3012 | IL7: =+IL20 -> 3244 | IM7: =+IM20 -> 3221 | IN7: =+IN20 -> 3192 | IO7: =+IO20 -> 12669 | IQ7: Revenue | IR7: =+IR20 -> 3027 | IS7: =+IS20 -> 3064 | IT7: =+IT20 -> 2939 | IU7: =+IU20 -> 2781 | IV7: =+IV20 -> 11811 | IX7: Revenue | IY7: =+IY20 -> 2618 | IZ7: =+IZ20 -> 2704 | JA7: =+JA20 -> 2710 | JB7: =+JB20 -> 3037 | JC7: =+JC20 -> 11069 | JE7: Revenue | JF7: =+JF20 -> 2869 | JG7: =+JG20 -> 2933 | JH7: =+JH20 -> 2743 | JI7: =+JI20 -> 2863 | JJ7: =+JJ20 -> 11408 | JL7: Revenue | JM7: =+JM20 -> 2876 | JN7: =+JN20 -> 3102 | JO7: =+JO20 -> 3129 | JP7: =+JP20 -> 3143 | JQ7: =+JQ20 -> 12250 | JS7: Revenue | JT7: =+JT20 -> 3013 | JU7: =+JU20 -> 3061 | JV7: =+JV20 -> 2978 | JW7: =+JW20 -> 2885 | JX7: =+JX20 -> 11937 | JZ7: Revenue | KA7: =+KA20 -> 2855 | KB7: =+KB20 -> 2255 | KC7: =+KC20 -> 2648 | KD7: =+KD20 -> 2825 | KE7: =+KE20 -> 10583 | KG7: Revenue | KH7: =+KH20 -> 2813 | KI7: =+KI20 -> 2990 | KJ7: =+KJ20 -> 3292 | KK7: =+KK20 -> 3427 | KL7: =+KL20 -> 12522 | KN7: Revenue | KO7: =+KO20 -> 3413 | KP7: =+KP20 -> 3815 | KQ7: =+KQ20 -> 3895 | KR7: =+KR20 -> 3730 | KS7: =+KS20 -> 14853 | KU7: Revenue | KV7: =+KV20 -> 3706 | KW7: =+KW20 -> 3699 | KX7: =+KX20 -> 3572 | KY7: =+KY20 -> 3680 | KZ7: =+KZ20 -> 14657 | LB7: Revenue | LC7: =+LC20 -> 3681 | LD7: =+LD20 -> 3701 | LE7: =+LE20 -> 3619 | LF7: =+LF20 -> 3539 | LG7: =+LG20 -> 14540 | LI7: Revenue | LJ7: =+LJ20 -> 3423 | LK7: =+LK20 -> 3574 | LL7: =+LL20 -> 3587 | LM7: =+LM20 -> 3508 | LN7: =+LN20 -> 14092 | LP7: Revenue | LQ7: =+LQ20 -> 3460.8174 | LR7: =+LR20 -> 3635.8899 | LS7: =+LS20 -> 3703.9341 | LT7: =+LT20 -> 3694.1538 | LU7: =+LU20 -> 14494.795 | LW7: Revenue | LX7: =+LX20 -> 3628.2348 | LY7: =+LY20 -> 3808.953 | LZ7: =+LZ20 -> 3876.0114 | MA7: =+MA20 -> 3867.7067 | MB7: =+MB20 -> 15180.906 | MD7: Revenue | ME7: =+ME20 -> 3790.9745 | MF7: =+MF20 -> 3977.245 | MG7: =+MG20 -> 4046.1072 | MH7: =+MH20 -> 4034.3107 | MI7: =+MI20 -> 15848.637
B8: Yr/ Yr % | D8: =+D7/C7-1 -> 0.16458421 | E8: =+E7/D7-1 -> 0.11931562 | F8: =+F7/E7-1 -> 0.13164246 | G8: =+G7/F7-1 -> -0.091708449 | H8: =+H7/G7-1 -> 0.0096807415 | I8: =+I7/H7-1 -> 0.14177887 | J8: =+J7/I7-1 -> -0.042165446 | K8: =+K7/J7-1 -> 0.12367096 | ... M8: =+M7/L7-1 -> 0.092374101 | N8: =BV8 -> #DIV/0! | O8: =CC8 -> 0.059434087 | P8: =CJ8 -> 0.052524845 | Q8: =CQ8 -> 0.011324294 | R8: =CX8 -> 0.023631513 | S8: =DE8 -> 0.074660254 | T8: =DL8 -> 0.072439634 | U8: =DS8 -> 0.022515528 | V8: =DZ8 -> 0.040527715 | W8: =EG8 -> -0.10051993 | X8: =EN8 -> 0.096339114 | Y8: =EU8 -> -0.21977615 | Z8: =FB8 -> -0.038529935 | AA8: =FI8 -> 0.0051787916 | AB8: =FP8 -> -0.071761531 | AC8: =FW8 -> 0.060525968 | AD8: =GD8 -> 0.071775701 | AE8: =GK8 -> 0.11219626 | AF8: =GR8 -> 0.048505122 | AG8: =GY8 -> 0.1221336 | AH8: =HF8 -> -0.19671257 | AI8: =HM8 -> 0.17641854 | AJ8: =HT8 -> 0.10408048 | AK8: =IA8 -> 0.0011070425 | AL8: =IH8 -> 0.02568901 | AM8: =IO8 -> 0.050671753 | AN8: =IV8 -> -0.067724367 | AO8: =JC8 -> -0.062822792 | AP8: =JJ8 -> 0.030626073 | AQ8: =JQ8 -> 0.073807854 | AR8: =JX8 -> -0.02555102 | AS8: =KE8 -> -0.11342883 | AT8: =KL8 -> 0.18321837 | AU8: =KS8 -> 0.18615237 | AV8: =KZ8 -> -0.013195987 | AW8: =LG8 -> -0.0079825339 | AX8: =LN8 -> -0.030811554 | AY8: =LU8 -> 0.028583258 | AZ8: =MB8 -> 0.047334962 | BA8: =MI8 -> 0.043984959 | BQ8: Yr/ Yr % | BR8: =+BR7/AV7-1 -> -0.87420345 | BS8: =+BS7/AW7-1 -> -0.86423659 | BT8: =+BT7/AX7-1 -> -0.86567556 | BU8: =+BU7/AY7-1 -> -0.85965307 | BV8: =+BV7/BP7-1 -> #DIV/0! | BX8: Yr/ Yr % | BY8: =+BY7/BR7-1 -> 0.034656687 | BZ8: =+BZ7/BS7-1 -> 0.036930091 | CA8: =+CA7/BT7-1 -> 0.089862116 | CB8: =+CB7/BU7-1 -> 0.075415131 | CC8: =+CC7/BV7-1 -> 0.059434087 | CE8: Yr/ Yr % | CF8: =+CF7/BY7-1 -> 0.06426587 | CG8: =+CG7/BZ7-1 -> 0.038155259 | CH8: =+CH7/CA7-1 -> 0.068783325 | CI8: =+CI7/CB7-1 -> 0.040399649 | CJ8: =+CJ7/CC7-1 -> 0.052524845 | CL8: Yr/ Yr % | CM8: =+CM7/CF7-1 -> 0.027631385 | CN8: =+CN7/CG7-1 -> 0.029741176 | CO8: =+CO7/CH7-1 -> 0.0042632319 | CP8: =+CP7/CI7-1 -> -0.013575853 | CQ8: =+CQ7/CJ7-1 -> 0.011324294 | CS8: Yr/ Yr % | CT8: =+CT7/CM7-1 -> 0.017685966 | CU8: =+CU7/CN7-1 -> 0.034411845 | CV8: =+CV7/CO7-1 -> 0.011019284 | CW8: =+CW7/CP7-1 -> 0.031088544 | CX8: =+CX7/CQ7-1 -> 0.023631513 | CZ8: Yr/ Yr % | DA8: =+DA7/CT7-1 -> 0.048839071 | DB8: =+DB7/CU7-1 -> 0.047492821 | DC8: =+DC7/CV7-1 -> 0.10331889 | DD8: =+DD7/CW7-1 -> 0.097192225 | DE8: =+DE7/CX7-1 -> 0.074660254 | DG8: Yr/ Yr % | DH8: =+DH7/DA7-1 -> 0.097440503 | DI8: =+DI7/DB7-1 -> 0.075073809 | DJ8: =+DJ7/DC7-1 -> 0.053036437 | DK8: =+DK7/DD7-1 -> 0.066929134 | DL8: =+DL7/DE7-1 -> 0.072439634 | DN8: Yr/ Yr % | DO8: =+DO7/DH7-1 -> 0.028641571 | DP8: =+DP7/DI7-1 -> 0.048254217 | DQ8: =+DQ7/DJ7-1 -> 0.017685506 | DR8: =+DR7/DK7-1 -> -0.0025830258 | DS8: =+DS7/DL7-1 -> 0.022515528 | DU8: Yr/ Yr % | DV8: =+DV7/DO7-1 -> 0.021081941 | DW8: =+DW7/DP7-1 -> 0.002245509 | DX8: =+DX7/DQ7-1 -> 0.063468077 | DY8: =+DY7/DR7-1 -> 0.073991861 | DZ8: =+DZ7/DS7-1 -> 0.040527715 | EB8: Yr/ Yr % | EC8: =+EC7/DV7-1 -> -0.048694975 | ED8: =+ED7/DW7-1 -> -0.070201643 | EE8: =+EE7/DX7-1 -> -0.13712256 | EF8: =+EF7/DY7-1 -> -0.13882191 | EG8: =+EG7/DZ7-1 -> -0.10051993 | EI8: Yr/ Yr % | EJ8: =+EJ7/EC7-1 -> 0.040540541 | EK8: =+EK7/ED7-1 -> 0.05060241 | EL8: =+EL7/EE7-1 -> 0.19637711 | EM8: =+EM7/EF7-1 -> 0.0992 | EN8: =+EN7/EG7-1 -> 0.096339114 | EP8: Yr/ Yr % | EQ8: =+EQ7/EJ7-1 -> -0.15505706 | ER8: =+ER7/EK7-1 -> -0.15825688 | ES8: =+ES7/EL7-1 -> -0.29834825 | ET8: =+ET7/EM7-1 -> -0.25509461 | EU8: =+EU7/EN7-1 -> -0.21977615 | EW8: Yr/ Yr % | EX8: =+EX7/EQ7-1 -> -0.056823475 | EY8: =+EY7/ER7-1 -> -0.065849228 | EZ8: =+EZ7/ES7-1 -> -0.0098087298 | FA8: =+FA7/ET7-1 -> -0.018563752 | FB8: =+FB7/EU7-1 -> -0.038529935 | FD8: Yr/ Yr % | FE8: =+FE7/EX7-1 -> -0.030123457 | FF8: =+FF7/EY7-1 -> 0.0077783179 | FG8: =+FG7/EZ7-1 -> 0.017830609 | FH8: =+FH7/FA7-1 -> 0.025385764 | FI8: =+FI7/FB7-1 -> 0.0051787916 | FK8: Yr/ Yr % | FL8: =+FL7/FE7-1 -> -0.0020366599 | FM8: =+FM7/FF7-1 -> -0.089242644 | FN8: =+FN7/FG7-1 -> -0.11289538 | FO8: =+FO7/FH7-1 -> -0.07961165 | FP8: =+FP7/FI7-1 -> -0.071761531 | FR8: Yr/ Yr % | FS8: =+FS7/FL7-1 -> -0.020408163 | FT8: =+FT7/FM7-1 -> 0.056673729 | FU8: =+FU7/FN7-1 -> 0.06308283 | FV8: =+FV7/FO7-1 -> 0.14556962 | FW8: =+FW7/FP7-1 -> 0.060525968 | FY8: Yr/ Yr % | FZ8: =+FZ7/FS7-1 -> 0.097916667 | GA8: =+GA7/FT7-1 -> 0.077192982 | GB8: =+GB7/FU7-1 -> 0.096491228 | GC8: =+GC7/FV7-1 -> 0.021639042 | GD8: =+GD7/FW7-1 -> 0.071775701 | GF8: Yr/ Yr % | GG8: =+GG7/FZ7-1 -> 0.10578748 | GH8: =+GH7/GA7-1 -> 0.1265705 | GI8: =+GI7/GB7-1 -> 0.13788235 | GJ8: =+GJ7/GC7-1 -> 0.07976566 | GK8: =+GK7/GD7-1 -> 0.11219626 | GM8: Yr/ Yr % | GN8: =+GN7/GG7-1 -> 0.039039039 | GO8: =+GO7/GH7-1 -> 0.045022718 | GP8: =+GP7/GI7-1 -> 0.034325889 | GQ8: =+GQ7/GJ7-1 -> 0.075542571 | GR8: =+GR7/GK7-1 -> 0.048505122 | GT8: Yr/ Yr % | GU8: =+GU7/GN7-1 -> 0.12014864 | GV8: =+GV7/GO7-1 -> 0.14901186 | GW8: =+GW7/GP7-1 -> 0.18392643 | GX8: =+GX7/GQ7-1 -> 0.037640667 | GY8: =+GY7/GR7-1 -> 0.1221336 | HA8: Yr/ Yr % | HB8: =+HB7/GU7-1 -> -0.17176557 | HC8: =+HC7/GV7-1 -> -0.24836601 | HD8: =+HD7/GW7-1 -> -0.22695035 | HE8: =+HE7/GX7-1 -> -0.13238594 | HF8: =+HF7/GY7-1 -> -0.19671257 | HH8: Yr/ Yr % | HI8: =+HI7/HB7-1 -> 0.10858923 | HJ8: =+HJ7/HC7-1 -> 0.2187643 | HK8: =+HK7/HD7-1 -> 0.16470074 | HL8: =+HL7/HE7-1 -> 0.2137931 | HM8: =+HM7/HF7-1 -> 0.17641854 | HO8: Yr/ Yr % | HP8: =+HP7/HI7-1 -> 0.12806102 | HQ8: =+HQ7/HJ7-1 -> 0.13368382 | HR8: =+HR7/HK7-1 -> 0.11140285 | HS8: =+HS7/HL7-1 -> 0.047940341 | HT8: =+HT7/HM7-1 -> 0.10408048 | HV8: Yr/ Yr % | HW8: =+HW7/HP7-1 -> 0.055516014 | HX8: =+HX7/HQ7-1 -> -0.0023186486 | HY8: =+HY7/HR7-1 -> -0.023287209 | HZ8: =+HZ7/HS7-1 -> -0.022704168 | IA8: =+IA7/HT7-1 -> 0.0011070425 | IC8: Yr/ Yr % | ID8: =+ID7/HW7-1 -> -0.0026972353 | IE8: =+IE7/HX7-1 -> 0.018924303 | IF8: =+IF7/HY7-1 -> 0.036281963 | IG8: =+IG7/HZ7-1 -> 0.051317614 | IH8: =+IH7/IA7-1 -> 0.02568901 | IJ8: Yr/ Yr % | IK8: =+IK7/ID7-1 -> 0.018255578 | IL8: =+IL7/IE7-1 -> 0.057021831 | IM8: =+IM7/IF7-1 -> 0.074024675 | IN8: =+IN7/IG7-1 -> 0.052770449 | IO8: =+IO7/IH7-1 -> 0.050671753 | IQ8: Yr/ Yr % | IR8: =+IR7/IK7-1 -> 0.0049800797 | IS8: =+IS7/IL7-1 -> -0.055487053 | IT8: =+IT7/IM7-1 -> -0.08755045 | IU8: =+IU7/IN7-1 -> -0.1287594 | IV8: =+IV7/IO7-1 -> -0.067724367 | IX8: Yr/ Yr % | IY8: =+IY7/IR7-1 -> -0.13511728 | IZ8: =+IZ7/IS7-1 -> -0.11749347 | JA8: =+JA7/IT7-1 -> -0.077917659 | JB8: =+JB7/IU7-1 -> 0.092053218 | JC8: =+JC7/IV7-1 -> -0.062822792 | JE8: Yr/ Yr % | JF8: =+JF7/IY7-1 -> 0.095874714 | JG8: =+JG7/IZ7-1 -> 0.084689349 | JH8: =+JH7/JA7-1 -> 0.012177122 | JI8: =+JI7/JB7-1 -> -0.057293382 | JJ8: =+JJ7/JC7-1 -> 0.030626073 | JL8: Yr/ Yr % | JM8: =+JM7/JF7-1 -> 0.0024398745 | JN8: =+JN7/JG7-1 -> 0.057620184 | JO8: =+JO7/JH7-1 -> 0.14072184 | JP8: =+JP7/JI7-1 -> 0.097799511 | JQ8: =+JQ7/JJ7-1 -> 0.073807854 | JS8: Yr/ Yr % | JT8: =+JT7/JM7-1 -> 0.047635605 | JU8: =+JU7/JN7-1 -> -0.013217279 | JV8: =+JV7/JO7-1 -> -0.048258229 | JW8: =+JW7/JP7-1 -> -0.082087178 | JX8: =+JX7/JQ7-1 -> -0.02555102 | JZ8: Yr/ Yr % | KA8: =+KA7/JT7-1 -> -0.052439429 | KB8: =+KB7/JU7-1 -> -0.26331264 | KC8: =+KC7/JV7-1 -> -0.11081263 | KD8: =+KD7/JW7-1 -> -0.020797227 | KE8: =+KE7/JX7-1 -> -0.11342883 | KG8: Yr/ Yr % | KH8: =+KH7/KA7-1 -> -0.014711033 | KI8: =+KI7/KB7-1 -> 0.32594235 | KJ8: =+KJ7/KC7-1 -> 0.24320242 | KK8: =+KK7/KD7-1 -> 0.21309735 | KL8: =+KL7/KE7-1 -> 0.18321837 | KN8: Yr/ Yr % | KO8: =+KO7/KH7-1 -> 0.21329541 | KP8: =+KP7/KI7-1 -> 0.27591973 | KQ8: =+KQ7/KJ7-1 -> 0.18317132 | KR8: =+KR7/KK7-1 -> 0.088415524 | KS8: =+KS7/KL7-1 -> 0.18615237 | KU8: Yr/ Yr % | KV8: =+KV7/KO7-1 -> 0.085848227 | KW8: =+KW7/KP7-1 -> -0.030406291 | KX8: =+KX7/KQ7-1 -> -0.082926829 | KY8: =+KY7/KR7-1 -> -0.013404826 | KZ8: =+KZ7/KS7-1 -> -0.013195987 | LB8: Yr/ Yr % | LC8: =+LC7/KV7-1 -> -0.0067458176 | LD8: =+LD7/KW7-1 -> 0.00054068667 | LE8: =+LE7/KX7-1 -> 0.013157895 | LF8: =+LF7/KY7-1 -> -0.038315217 | LG8: =+LG7/KZ7-1 -> -0.0079825339 | LI8: Yr/ Yr % | LJ8: =+LJ7/LC7-1 -> -0.07008965 | LK8: =+LK7/LD7-1 -> -0.03431505 | LL8: =+LL7/LE7-1 -> -0.0088422216 | LM8: =+LM7/LF7-1 -> -0.0087595366 | LN8: =+LN7/LG7-1 -> -0.030811554 | LP8: Yr/ Yr % | LQ8: =+LQ7/LJ7-1 -> 0.011048035 | LR8: =+LR7/LK7-1 -> 0.017316711 | LS8: =+LS7/LL7-1 -> 0.032599428 | LT8: =+LT7/LM7-1 -> 0.0530655 | LU8: =+LU7/LN7-1 -> 0.028583258 | LW8: Yr/ Yr % | LX8: =+LX7/LQ7-1 -> 0.048375105 | LY8: =+LY7/LR7-1 -> 0.047598534 | LZ8: =+LZ7/LS7-1 -> 0.046457965 | MA8: =+MA7/LT7-1 -> 0.046980423 | MB8: =+MB7/LU7-1 -> 0.047334962 | MD8: Yr/ Yr % | ME8: =+ME7/LX7-1 -> 0.044853677 | MF8: =+MF7/LY7-1 -> 0.044183271 | MG8: =+MG7/LZ7-1 -> 0.04388424 | MH8: =+MH7/MA7-1 -> 0.043075665 | MI8: =+MI7/MB7-1 -> 0.043984959
B10: EPS (Recurring) | C10: =+C62 -> 0.041307607 | D10: =+D62 -> 0.076148068 | E10: =+E62 -> 0.078254736 | F10: =+F62 -> 0.10113868 | G10: =+G62 -> 0.060979194 | H10: =+H62 -> 0.047014456 | I10: =+I62 -> 0.066982961 | J10: =+J62 -> 0.067477122 | ... M10: =+M62 -> 0.085371526 | N10: =BV10 -> 0.11623156 | O10: =CC10 -> 0.11117791 | P10: =CJ10 -> 0.11310847 | Q10: =CQ10 -> 0.12535025 | R10: =CX10 -> 0.12431525 | S10: =DE10 -> 0.1612841 | T10: =DL10 -> 0.19242969 | U10: =DS10 -> 0.21644196 | V10: =DZ10 -> 0.22457436 | W10: =EG10 -> 0.13641276 | X10: =EN10 -> 0.085698428 | Y10: =EU10 -> 0.050115849 | Z10: =FB10 -> 0.088061976 | AA10: =FI10 -> 0.11971524 | AB10: =FP10 -> 0.097850741 | AC10: =FW10 -> 0.11144133 | AD10: =GD10 -> 0.18553469 | AE10: =GK10 -> 0.28476892 | AF10: =GR10 -> 0.30678563 | AG10: =GY10 -> 0.39013514 | AH10: =HF10 -> 0.31030609 | AI10: =HM10 -> 0.4586944 | AJ10: =HT10 -> 0.54882155 | AK10: =IA10 -> 0.58162179 | AL10: =IH10 -> 0.60680406 | AM10: =IO10 -> 0.64105123 | AN10: =IV10 -> 0.66666667 | AO10: =JC10 -> 0.62733826 | AP10: =JJ10 -> 0.76477024 | AQ10: =JQ10 -> 1.2810685 | AR10: =JX10 -> 1.3913952 | AS10: =KE10 -> 1.2000868 | AT10: =KL10 -> 1.558063 | AU10: =KS10 -> 1.9027352 | AV10: =KZ10 -> 1.822156 | AW10: =LG10 -> 1.8283361 | AX10: =LN10 -> 1.6447654 | AY10: =LU10 -> 1.8953327 | AZ10: =MB10 -> 2.2046884 | BA10: =MI10 -> 2.4592512 | BQ10: EPS (Recurring) | BR10: =+BR62 -> 0.019976487 | BS10: =+BS62 -> 0.035563823 | BT10: =+BT62 -> 0.025838288 | BU10: =+BU62 -> 0.035345139 | BV10: =+BV62 -> 0.11623156 | BX10: EPS (Recurring) | BY10: =+BY62 -> 0.016441639 | BZ10: =+BZ62 -> 0.030402705 | CA10: =+CA62 -> 0.028153938 | CB10: =+CB62 -> 0.036120252 | CC10: =+CC62 -> 0.11117791 | CE10: EPS (Recurring) | CF10: =+CF62 -> 0.015905935 | CG10: =+CG62 -> 0.031676201 | CH10: =+CH62 -> 0.029237171 | CI10: =+CI62 -> 0.035971022 | CJ10: =+CJ62 -> 0.11310847 | CL10: EPS (Recurring) | CM10: =+CM62 -> 0.01668723 | CN10: =+CN62 -> 0.03392481 | CO10: =+CO62 -> 0.034182598 | CP10: =+CP62 -> 0.040490138 | CQ10: =+CQ62 -> 0.12535025 | CS10: EPS (Recurring) | CT10: =+CT62 -> 0.013844813 | CU10: =+CU62 -> 0.040601765 | CV10: =+CV62 -> 0.030003775 | CW10: =+CW62 -> 0.039810974 | CX10: =+CX62 -> 0.12431525 | CZ10: EPS (Recurring) | DA10: =+DA62 -> 0.01944321 | DB10: =+DB62 -> 0.042463646 | DC10: =+DC62 -> 0.046383648 | DD10: =+DD62 -> 0.052940504 | DE10: =+DE62 -> 0.1612841 | DG10: EPS (Recurring) | DH10: =+DH62 -> 0.031645305 | DI10: =+DI62 -> 0.048021865 | DJ10: =+DJ62 -> 0.053831268 | DK10: =+DK62 -> 0.058857523 | DL10: =+DL62 -> 0.19242969 | DN10: EPS (Recurring) | DO10: =+DO62 -> 0.037990797 | DP10: =+DP62 -> 0.057399229 | DQ10: =+DQ62 -> 0.056731847 | DR10: =+DR62 -> 0.064073245 | DS10: =+DS62 -> 0.21644196 | DU10: EPS (Recurring) | DV10: =+DV62 -> 0.039463567 | DW10: =+DW62 -> 0.059108403 | DX10: =+DX62 -> 0.060608557 | DY10: =+DY62 -> 0.072172427 | DZ10: =+DZ62 -> 0.22457436 | EB10: EPS (Recurring) | EC10: =+EC62 -> 0.026448158 | ED10: =+ED62 -> 0.044268314 | EE10: =+EE62 -> 0.03273974 | EF10: =+EF62 -> 0.032931683 | EG10: =+EG62 -> 0.13641276 | EI10: EPS (Recurring) | EJ10: =+EJ62 -> 0.017451633 | EK10: =+EK62 -> 0.025020681 | EL10: =+EL62 -> 0.03241773 | EM10: =+EM62 -> 0.010795053 | EN10: =+EN62 -> 0.085698428 | EP10: EPS (Recurring) | EQ10: =+EQ62 -> 0.0059310007 | ER10: =+ER62 -> 0.014466839 | ES10: =+ES62 -> 0.015515814 | ET10: =+ET62 -> 0.014229811 | EU10: =+EU62 -> 0.050115849 | EW10: EPS (Recurring) | EX10: =+EX62 -> 0.0069986833 | EY10: =+EY62 -> 0.028240078 | EZ10: =+EZ62 -> 0.025611394 | FA10: =+FA62 -> 0.027164104 | FB10: =+FB62 -> 0.088061976 | FD10: EPS (Recurring) | FE10: =+FE62 -> 0.017720239 | FF10: =+FF62 -> 0.03327354 | FG10: =+FG62 -> 0.033078535 | FH10: =+FH62 -> 0.035617535 | FI10: =+FI62 -> 0.11971524 | FK10: EPS (Recurring) | FL10: =+FL62 -> 0.0095980443 | FM10: =+FM62 -> 0.030574198 | FN10: =+FN62 -> 0.027718208 | FO10: =+FO62 -> 0.029448156 | FP10: =+FP62 -> 0.097850741 | FR10: EPS (Recurring) | FS10: =+FS62 -> 0.01482272 | FT10: =+FT62 -> 0.032536429 | FU10: =+FU62 -> 0.024845955 | FV10: =+FV62 -> 0.039194284 | FW10: =+FW62 -> 0.11144133 | FY10: EPS (Recurring) | FZ10: =+FZ62 -> 0.037815279 | GA10: =+GA62 -> 0.050435333 | GB10: =+GB62 -> 0.039887013 | GC10: =+GC62 -> 0.057253471 | GD10: =+GD62 -> 0.18553469 | GF10: EPS (Recurring) | GG10: =+GG62 -> 0.058622594 | GH10: =+GH62 -> 0.09381231 | GI10: =+GI62 -> 0.073162632 | GJ10: =+GJ62 -> 0.068904499 | GK10: =+GK62 -> 0.28476892 | GM10: EPS (Recurring) | GN10: =+GN62 -> 0.059732513 | GO10: =+GO62 -> 0.078444532 | GP10: =+GP62 -> 0.074066094 | GQ10: =+GQ62 -> 0.096070405 | GR10: =+GR62 -> 0.30678563 | GT10: EPS (Recurring) | GU10: =+GU62 -> 0.088576242 | GV10: =+GV62 -> 0.098340159 | GW10: =+GW62 -> 0.10390663 | GX10: =+GX62 -> 0.099520406 | GY10: =+GY62 -> 0.39013514 | HA10: EPS (Recurring) | HB10: =+HB62 -> 0.069356086 | HC10: =+HC62 -> 0.078688518 | HD10: =+HD62 -> 0.081020449 | HE10: =+HE62 -> 0.081176676 | HF10: =+HF62 -> 0.31030609 | HH10: EPS (Recurring) | HI10: =+HI62 -> 0.085660089 | HJ10: =+HJ62 -> 0.12021858 | HK10: =+HK62 -> 0.12692868 | HL10: =+HL62 -> 0.12706856 | HM10: =+HM62 -> 0.4586944 | HO10: EPS (Recurring) | HP10: =+HP62 -> 0.1180867 | HQ10: =+HQ62 -> 0.14788097 | HR10: =+HR62 -> 0.14360879 | HS10: =+HS62 -> 0.1395202 | HT10: =+HT62 -> 0.54882155 | HV10: EPS (Recurring) | HW10: =+HW62 -> 0.14267556 | HX10: =+HX62 -> 0.16075423 | HY10: =+HY62 -> 0.14583333 | HZ10: =+HZ62 -> 0.13218547 | IA10: =+IA62 -> 0.58162179 | IC10: EPS (Recurring) | ID10: =+ID62 -> 0.14956012 | IE10: =+IE62 -> 0.16878462 | IF10: =+IF62 -> 0.14800262 | IG10: =+IG62 -> 0.14017769 | IH10: =+IH62 -> 0.60680406 | IJ10: EPS (Recurring) | IK10: =+IK62 -> 0.13161376 | IL10: =+IL62 -> 0.17580592 | IM10: =+IM62 -> 0.1698365 | IN10: =+IN62 -> 0.16448911 | IO10: =+IO62 -> 0.64105123 | IQ10: EPS (Recurring) | IR10: =+IR62 -> 0.14852151 | IS10: =+IS62 -> 0.18638355 | IT10: =+IT62 -> 0.17209776 | IU10: =+IU62 -> 0.15964371 | IV10: =+IV62 -> 0.66666667 | IX10: EPS (Recurring) | IY10: =+IY62 -> 0.12322603 | IZ10: =+IZ62 -> 0.15581232 | JA10: =+JA62 -> 0.16083422 | JB10: =+JB62 -> 0.18828877 | JC10: =+JC62 -> 0.62733826 | JE10: EPS (Recurring) | JF10: =+JF62 -> 0.16864011 | JG10: =+JG62 -> 0.21320346 | JH10: =+JH62 -> 0.17034584 | JI10: =+JI62 -> 0.21316964 | JJ10: =+JJ62 -> 0.76477024 | JL10: EPS (Recurring) | JM10: =+JM62 -> 0.26088589 | JN10: =+JN62 -> 0.33678955 | JO10: =+JO62 -> 0.34894614 | JP10: =+JP62 -> 0.33733493 | JQ10: =+JQ62 -> 1.2810685 | JS10: EPS (Recurring) | JT10: =+JT62 -> 0.34026928 | JU10: =+JU62 -> 0.35935564 | JV10: =+JV62 -> 0.36026936 | JW10: =+JW62 -> 0.33033419 | JX10: =+JX62 -> 1.3913952 | JZ10: EPS (Recurring) | KA10: =+KA62 -> 0.33203967 | KB10: =+KB62 -> 0.21686223 | KC10: =+KC62 -> 0.31986093 | KD10: =+KD62 -> 0.33072237 | KE10: =+KE62 -> 1.2000868 | KG10: EPS (Recurring) | KH10: =+KH62 -> 0.3088364 | KI10: =+KI62 -> 0.39799216 | KJ10: =+KJ62 -> 0.43175736 | KK10: =+KK62 -> 0.42129003 | KL10: =+KL62 -> 1.558063 | KN10: EPS (Recurring) | KO10: =+KO62 -> 0.39170087 | KP10: =+KP62 -> 0.50196768 | KQ10: =+KQ62 -> 0.52257761 | KR10: =+KR62 -> 0.4882494 | KS10: =+KS62 -> 1.9027352 | KU10: EPS (Recurring) | KV10: =+KV62 -> 0.47327502 | KW10: =+KW62 -> 0.48592593 | KX10: =+KX62 -> 0.4142071 | KY10: =+KY62 -> 0.44794312 | KZ10: =+KZ62 -> 1.822156 | LB10: EPS (Recurring) | LC10: =+LC62 -> 0.44852192 | LD10: =+LD62 -> 0.49435318 | LE10: =+LE62 -> 0.46082474 | LF10: =+LF62 -> 0.4242582 | LG10: =+LG62 -> 1.8283361 | LI10: EPS (Recurring) | LJ10: =+LJ62 -> 0.34143763 | LK10: =+LK62 -> 0.4435527 | LL10: =+LL62 -> 0.45257097 | LM10: =+LM62 -> 0.40809853 | LN10: =+LN62 -> 1.6447654 | LP10: EPS (Recurring) | LQ10: =+LQ62 -> 0.4027231 | LR10: =+LR62 -> 0.48784498 | LS10: =+LS62 -> 0.50931281 | LT10: =+LT62 -> 0.49684328 | LU10: =+LU62 -> 1.8953327 | LW10: EPS (Recurring) | LX10: =+LX62 -> 0.47512354 | LY10: =+LY62 -> 0.56740712 | LZ10: =+LZ62 -> 0.59371422 | MA10: =+MA62 -> 0.56994235 | MB10: =+MB62 -> 2.2046884 | MD10: EPS (Recurring) | ME10: =+ME62 -> 0.53775277 | MF10: =+MF62 -> 0.63197805 | MG10: =+MG62 -> 0.65647148 | MH10: =+MH62 -> 0.63467794 | MI10: =+MI62 -> 2.4592512
B11: Yr/ Yr % | D11: =+D10/C10-1 -> 0.84343935 | E11: =+E10/D10-1 -> 0.027665412 | F11: =+F10/E10-1 -> 0.29242883 | G11: =+G10/F10-1 -> -0.39707345 | H11: =+H10/G10-1 -> -0.22900824 | I11: =+I10/H10-1 -> 0.42473116 | J11: =+J10/I10-1 -> 0.007377414 | K11: =+K10/J10-1 -> -0.16388363 | ... M11: =+M10/L10-1 -> 0.28303104 | N11: =BV11 -> #DIV/0! | O11: =CC11 -> -0.043479077 | P11: =CJ11 -> 0.017364515 | Q11: =CQ11 -> 0.10823051 | R11: =CX11 -> -0.0082568601 | S11: =DE11 -> 0.29737986 | T11: =DL11 -> 0.19311008 | U11: =DS11 -> 0.12478462 | V11: =DZ11 -> 0.037573138 | W11: =EG11 -> -0.392572 | X11: =EN11 -> -0.37177116 | Y11: =EU11 -> -0.4152069 | Z11: =FB11 -> 0.75716819 | AA11: =FI11 -> 0.35944308 | AB11: =FP11 -> -0.18263758 | AC11: =FW11 -> 0.13889102 | AD11: =GD11 -> 0.66486427 | AE11: =GK11 -> 0.53485542 | AF11: =GR11 -> 0.077314276 | AG11: =GY11 -> 0.2716865 | AH11: =HF11 -> -0.20461896 | AI11: =HM11 -> 0.47819977 | AJ11: =HT11 -> 0.19648627 | AK11: =IA11 -> 0.059764866 | AL11: =IH11 -> 0.043296626 | AM11: =IO11 -> 0.056438605 | AN11: =IV11 -> 0.039958485 | AO11: =JC11 -> -0.058992616 | AP11: =JJ11 -> 0.21907158 | AQ11: =JQ11 -> 0.67510248 | AR11: =JX11 -> 0.086120787 | AS11: =KE11 -> -0.1374939 | AT11: =KL11 -> 0.29829196 | AU11: =KS11 -> 0.22121837 | AV11: =KZ11 -> -0.042349156 | AW11: =LG11 -> 0.003391661 | AX11: =LN11 -> -0.10040314 | AY11: =LU11 -> 0.15234224 | AZ11: =MB11 -> 0.16321975 | BA11: =MI11 -> 0.11546429 | BQ11: Yr/ Yr % | BR11: =+BR10/AV10-1 -> -0.9890369 | BS11: =+BS10/AW10-1 -> -0.98054853 | BT11: =+BT10/AX10-1 -> -0.98429059 | BU11: =+BU10/AY10-1 -> -0.98135149 | BV11: =+BV10/BP10-1 -> #DIV/0! | BX11: Yr/ Yr % | BY11: =+BY10/BR10-1 -> -0.17695044 | BZ11: =+BZ10/BS10-1 -> -0.1451227 | CA11: =+CA10/BT10-1 -> 0.089620861 | CB11: =+CB10/BU10-1 -> 0.021929822 | CC11: =+CC10/BV10-1 -> -0.043479077 | CE11: Yr/ Yr % | CF11: =+CF10/BY10-1 -> -0.03258217 | CG11: =+CG10/BZ10-1 -> 0.041887578 | CH11: =+CH10/CA10-1 -> 0.038475364 | CI11: =+CI10/CB10-1 -> -0.00413147 | CJ11: =+CJ10/CC10-1 -> 0.017364515 | CL11: Yr/ Yr % | CM11: =+CM10/CF10-1 -> 0.04911974 | CN11: =+CN10/CG10-1 -> 0.070987321 | CO11: =+CO10/CH10-1 -> 0.16914864 | CP11: =+CP10/CI10-1 -> 0.12563212 | CQ11: =+CQ10/CJ10-1 -> 0.10823051 | CS11: Yr/ Yr % | CT11: =+CT10/CM10-1 -> -0.17033486 | CU11: =+CU10/CN10-1 -> 0.19681629 | CV11: =+CV10/CO10-1 -> -0.12225001 | CW11: =+CW10/CP10-1 -> -0.016773562 | CX11: =+CX10/CQ10-1 -> -0.0082568601 | CZ11: Yr/ Yr % | DA11: =+DA10/CT10-1 -> 0.40436778 | DB11: =+DB10/CU10-1 -> 0.045857162 | DC11: =+DC10/CV10-1 -> 0.54592705 | DD11: =+DD10/CW10-1 -> 0.32979675 | DE11: =+DE10/CX10-1 -> 0.29737986 | DG11: Yr/ Yr % | DH11: =+DH10/DA10-1 -> 0.62757618 | DI11: =+DI10/DB10-1 -> 0.13089357 | DJ11: =+DJ10/DC10-1 -> 0.16056565 | DK11: =+DK10/DD10-1 -> 0.11176732 | DL11: =+DL10/DE10-1 -> 0.19311008 | DN11: Yr/ Yr % | DO11: =+DO10/DH10-1 -> 0.20051923 | DP11: =+DP10/DI10-1 -> 0.19527282 | DQ11: =+DQ10/DJ10-1 -> 0.053882784 | DR11: =+DR10/DK10-1 -> 0.088616073 | DS11: =+DS10/DL10-1 -> 0.12478462 | DU11: Yr/ Yr % | DV11: =+DV10/DO10-1 -> 0.038766505 | DW11: =+DW10/DP10-1 -> 0.029776946 | DX11: =+DX10/DQ10-1 -> 0.068333923 | DY11: =+DY10/DR10-1 -> 0.12640505 | DZ11: =+DZ10/DS10-1 -> 0.037573138 | EB11: Yr/ Yr % | EC11: =+EC10/DV10-1 -> -0.32980824 | ED11: =+ED10/DW10-1 -> -0.25106563 | EE11: =+EE10/DX10-1 -> -0.45981654 | EF11: =+EF10/DY10-1 -> -0.54370825 | EG11: =+EG10/DZ10-1 -> -0.392572 | EI11: Yr/ Yr % | EJ11: =+EJ10/EC10-1 -> -0.34015694 | EK11: =+EK10/ED10-1 -> -0.43479481 | EL11: =+EL10/EE10-1 -> -0.0098354341 | EM11: =+EM10/EF10-1 -> -0.67219856 | EN11: =+EN10/EG10-1 -> -0.37177116 | EP11: Yr/ Yr % | EQ11: =+EQ10/EJ10-1 -> -0.66014638 | ER11: =+ER10/EK10-1 -> -0.42180475 | ES11: =+ES10/EL10-1 -> -0.52137876 | ET11: =+ET10/EM10-1 -> 0.31817893 | EU11: =+EU10/EN10-1 -> -0.4152069 | EW11: Yr/ Yr % | EX11: =+EX10/EQ10-1 -> 0.18001728 | EY11: =+EY10/ER10-1 -> 0.95205588 | EZ11: =+EZ10/ES10-1 -> 0.65066387 | FA11: =+FA10/ET10-1 -> 0.90895742 | FB11: =+FB10/EU10-1 -> 0.75716819 | FD11: Yr/ Yr % | FE11: =+FE10/EX10-1 -> 1.531939 | FF11: =+FF10/EY10-1 -> 0.17823823 | FG11: =+FG10/EZ10-1 -> 0.29155545 | FH11: =+FH10/FA10-1 -> 0.3111986 | FI11: =+FI10/FB10-1 -> 0.35944308 | FK11: Yr/ Yr % | FL11: =+FL10/FE10-1 -> -0.45835695 | FM11: =+FM10/FF10-1 -> -0.081125772 | FN11: =+FN10/FG10-1 -> -0.16204851 | FO11: =+FO10/FH10-1 -> -0.17321184 | FP11: =+FP10/FI10-1 -> -0.18263758 | FR11: Yr/ Yr % | FS11: =+FS10/FL10-1 -> 0.54434798 | FT11: =+FT10/FM10-1 -> 0.064179285 | FU11: =+FU10/FN10-1 -> -0.10362332 | FV11: =+FV10/FO10-1 -> 0.33095883 | FW11: =+FW10/FP10-1 -> 0.13889102 | FY11: Yr/ Yr % | FZ11: =+FZ10/FS10-1 -> 1.55117 | GA11: =+GA10/FT10-1 -> 0.55011892 | GB11: =+GB10/FU10-1 -> 0.60537249 | GC11: =+GC10/FV10-1 -> 0.46076074 | GD11: =+GD10/FW10-1 -> 0.66486427 | GF11: Yr/ Yr % | GG11: =+GG10/FZ10-1 -> 0.55023567 | GH11: =+GH10/GA10-1 -> 0.86005135 | GI11: =+GI10/GB10-1 -> 0.83424696 | GJ11: =+GJ10/GC10-1 -> 0.20349906 | GK11: =+GK10/GD10-1 -> 0.53485542 | GM11: Yr/ Yr % | GN11: =+GN10/GG10-1 -> 0.018933306 | GO11: =+GO10/GH10-1 -> -0.16381409 | GP11: =+GP10/GI10-1 -> 0.01234868 | GQ11: =+GQ10/GJ10-1 -> 0.39425446 | GR11: =+GR10/GK10-1 -> 0.077314276 | GT11: Yr/ Yr % | GU11: =+GU10/GN10-1 -> 0.48288155 | GV11: =+GV10/GO10-1 -> 0.25362669 | GW11: =+GW10/GP10-1 -> 0.40289058 | GX11: =+GX10/GQ10-1 -> 0.03591117 | GY11: =+GY10/GR10-1 -> 0.2716865 | HA11: Yr/ Yr % | HB11: =+HB10/GU10-1 -> -0.21698997 | HC11: =+HC10/GV10-1 -> -0.19983333 | HD11: =+HD10/GW10-1 -> -0.22025715 | HE11: =+HE10/GX10-1 -> -0.18432129 | HF11: =+HF10/GY10-1 -> -0.20461896 | HH11: Yr/ Yr % | HI11: =+HI10/HB10-1 -> 0.23507674 | HJ11: =+HJ10/HC10-1 -> 0.5277779 | HK11: =+HK10/HD10-1 -> 0.56662518 | HL11: =+HL10/HE10-1 -> 0.56533334 | HM11: =+HM10/HF10-1 -> 0.47819977 | HO11: Yr/ Yr % | HP11: =+HP10/HI10-1 -> 0.37854978 | HQ11: =+HQ10/HJ10-1 -> 0.23010083 | HR11: =+HR10/HK10-1 -> 0.13141329 | HS11: =+HS10/HL10-1 -> 0.097991543 | HT11: =+HT10/HM10-1 -> 0.19648627 | HV11: Yr/ Yr % | HW11: =+HW10/HP10-1 -> 0.20822724 | HX11: =+HX10/HQ10-1 -> 0.087051501 | HY11: =+HY10/HR10-1 -> 0.015490302 | HZ11: =+HZ10/HS10-1 -> -0.052571087 | IA11: =+IA10/HT10-1 -> 0.059764866 | IC11: Yr/ Yr % | ID11: =+ID10/HW10-1 -> 0.048253205 | IE11: =+IE10/HX10-1 -> 0.049954428 | IF11: =+IF10/HY10-1 -> 0.014875105 | IG11: =+IG10/HZ10-1 -> 0.06046214 | IH11: =+IH10/IA10-1 -> 0.043296626 | IJ11: Yr/ Yr % | IK11: =+IK10/ID10-1 -> -0.11999429 | IL11: =+IL10/IE10-1 -> 0.041599141 | IM11: =+IM10/IF10-1 -> 0.14752363 | IN11: =+IN10/IG10-1 -> 0.17343289 | IO11: =+IO10/IH10-1 -> 0.056438605 | IQ11: Yr/ Yr % | IR11: =+IR10/IK10-1 -> 0.12846491 | IS11: =+IS10/IL10-1 -> 0.060166558 | IT11: =+IT10/IM10-1 -> 0.013314314 | IU11: =+IU10/IN10-1 -> -0.02945726 | IV11: =+IV10/IO10-1 -> 0.039958485 | IX11: Yr/ Yr % | IY11: =+IY10/IR10-1 -> -0.17031524 | IZ11: =+IZ10/IS10-1 -> -0.1640232 | JA11: =+JA10/IT10-1 -> -0.065448514 | JB11: =+JB10/IU10-1 -> 0.17943116 | JC11: =+JC10/IV10-1 -> -0.058992616 | JE11: Yr/ Yr % | JF11: =+JF10/IY10-1 -> 0.36854295 | JG11: =+JG10/IZ10-1 -> 0.36833504 | JH11: =+JH10/JA10-1 -> 0.059139315 | JI11: =+JI10/JB10-1 -> 0.1321421 | JJ11: =+JJ10/JC10-1 -> 0.21907158 | JL11: Yr/ Yr % | JM11: =+JM10/JF10-1 -> 0.5469978 | JN11: =+JN10/JG10-1 -> 0.57966268 | JO11: =+JO10/JH10-1 -> 1.048457 | JP11: =+JP10/JI10-1 -> 0.58247173 | JQ11: =+JQ10/JJ10-1 -> 0.67510248 | JS11: Yr/ Yr % | JT11: =+JT10/JM10-1 -> 0.30428397 | JU11: =+JU10/JN10-1 -> 0.067003514 | JV11: =+JV10/JO10-1 -> 0.032449777 | JW11: =+JW10/JP10-1 -> -0.020753094 | JX11: =+JX10/JQ10-1 -> 0.086120787 | JZ11: Yr/ Yr % | KA11: =+KA10/JT10-1 -> -0.024185567 | KB11: =+KB10/JU10-1 -> -0.39652475 | KC11: =+KC10/JV10-1 -> -0.11216172 | KD11: =+KD10/JW10-1 -> 0.001175104 | KE11: =+KE10/JX10-1 -> -0.1374939 | KG11: Yr/ Yr % | KH11: =+KH10/KA10-1 -> -0.069881038 | KI11: =+KI10/KB10-1 -> 0.83523039 | KJ11: =+KJ10/KC10-1 -> 0.34982838 | KK11: =+KK10/KD10-1 -> 0.27384802 | KL11: =+KL10/KE10-1 -> 0.29829196 | KN11: Yr/ Yr % | KO11: =+KO10/KH10-1 -> 0.26831187 | KP11: =+KP10/KI10-1 -> 0.26125017 | KQ11: =+KQ10/KJ10-1 -> 0.21035021 | KR11: =+KR10/KK10-1 -> 0.15893889 | KS11: =+KS10/KL10-1 -> 0.22121837 | KU11: Yr/ Yr % | KV11: =+KV10/KO10-1 -> 0.20825626 | KW11: =+KW10/KP10-1 -> -0.031957748 | KX11: =+KX10/KQ10-1 -> -0.20737687 | KY11: =+KY10/KR10-1 -> -0.082552651 | KZ11: =+KZ10/KS10-1 -> -0.042349156 | LB11: Yr/ Yr % | LC11: =+LC10/KV10-1 -> -0.052301741 | LD11: =+LD10/KW10-1 -> 0.017342678 | LE11: =+LE10/KX10-1 -> 0.11254669 | LF11: =+LF10/KY10-1 -> -0.052874837 | LG11: =+LG10/KZ10-1 -> 0.003391661 | LI11: Yr/ Yr % | LJ11: =+LJ10/LC10-1 -> -0.23874928 | LK11: =+LK10/LD10-1 -> -0.10276151 | LL11: =+LL10/LE10-1 -> -0.017910872 | LM11: =+LM10/LF10-1 -> -0.038089242 | LN11: =+LN10/LG10-1 -> -0.10040314 | LP11: Yr/ Yr % | LQ11: =+LQ10/LJ10-1 -> 0.17949243 | LR11: =+LR10/LK10-1 -> 0.099857994 | LS11: =+LS10/LL10-1 -> 0.12537668 | LT11: =+LT10/LM10-1 -> 0.21745914 | LU11: =+LU10/LN10-1 -> 0.15234224 | LW11: Yr/ Yr % | LX11: =+LX10/LQ10-1 -> 0.17977722 | LY11: =+LY10/LR10-1 -> 0.16308896 | LZ11: =+LZ10/LS10-1 -> 0.16571623 | MA11: =+MA10/LT10-1 -> 0.14712702 | MB11: =+MB10/LU10-1 -> 0.16321975 | MD11: Yr/ Yr % | ME11: =+ME10/LX10-1 -> 0.13181672 | MF11: =+MF10/LY10-1 -> 0.1138 | MG11: =+MG10/LZ10-1 -> 0.10570282 | MH11: =+MH10/MA10-1 -> 0.1135827 | MI11: =+MI10/MB10-1 -> 0.11546429
