Workbook
Name \0: #REF!
Name \1: #N/A
Name \2: #N/A
Name \3: #N/A
Name \4: #N/A
Name \5: #N/A
Name \6: #N/A
Name \a: #N/A
Name \b: #REF!
Name \c: #REF!
Name \d: #REF!
Name \e: #REF!
Name \f: #REF!
Name \g: #REF!
Name \h: #REF!
Name \i: #REF!
Name \j: #REF!
Name \k: #N/A
Name \l: #REF!
Name \m: #REF!
Name \n: #REF!
Name \o: #REF!
Name \p: #REF!
Name \PRINJV: #REF!
Name \q: #REF!
Name \r: #REF!
Name \s: #REF!
Name \t: #REF!
Name \u: #REF!
Name \v: #N/A
Name \w: #REF!
Name \x: #REF!
Name \y: #REF!
Name \z: #REF!
Name _: #REF!
Name _.4: #REF!
Name _????_3: #REF!
Name _????1_3: #REF!
Name _????8_3: #REF!
Name _??_3: #REF!
Name _??1???_3: #REF!
Name __: #REF!
Name ___: #REF!
Name ____: #REF!
Name _____: #REF!
Name ______: #REF!
Name ________: #REF!
Name __________: #REF!
Name ____________: #REF!
Name _____________: #REF!
Name ______________: #REF!
Name _______________________________________________tax2: #REF!
Name ______________________________________________tax2: #REF!
Name _____________________________________________tax2: #REF!
Name ____________________________________________tax2: #REF!
Name ___________________________________________tax2: #REF!
Name __________________________________________tax2: #REF!
Name _________________________________________tax2: #REF!
Name ________________________________________tax2: #REF!
Name _______________________________________tax2: #REF!

Sheet Disclaimer
C5: Equity Research
C7: Financial Model
C8: Software
C9: 46083
C12: =+'Income Statement'!A1 -> Tenable Holdings, Inc. (TENB)
C17: Wells Fargo Software Team
C19: Richard Poland | E19: David Unger
C20: Analyst | E20: Associate Analyst
C21: (212) 214-5333 | E21: (212) 214-5317
C22: richard.d.poland@wellsfargo.com | E22: David.Unger@wellsfargo.com
C24: Important Disclaimers:

Sheet Income Statement
A1: Tenable Holdings, Inc. (TENB)
A2: Income Statement | B2: 2017/1F | C2: 2017/2F | D2: 2017/3F | E2: 2017/4F | F2: 2018/1F | G2: 2018/2F | H2: 2018/3F | I2: 2018/4F | J2: 2019/1F | K2: 2019/2F | L2: 2019/3F | M2: 2019/4F | N2: 2020/1F | O2: 2020/2F | P2: 2020/3F | Q2: 2020/4F | R2: 2021/1F | S2: 2021/2F | T2: 2021/3F | U2: 2021/4F | V2: 2022/1F | W2: 2022/2F | X2: 2022/3F | Y2: 2022/4F | Z2: 2023/1F | AA2: 2023/2F | AB2: 2023/3F | AC2: 2023/4F | AD2: 2024/1F | AE2: 2024/2F | AF2: 2024/3F | AG2: 2024/4F | AH2: 2025/1F | AI2: 2025/2F | AJ2: 2025/3F | AK2: 2025/4F | AL2: 2026/1F | AM2: 2026/2F | AN2: 2026/3F | AO2: 2026/4F | AP2: 2027/1F | AQ2: 2027/2F | AR2: 2027/3F | AS2: 2027/4F | AU2: 2017 | AV2: 2018 | AW2: 2019 | AX2: 2020 | AY2: 2021 | AZ2: 2022 | BA2: 2023 | BB2: 2024 | BC2: =BB2+1 -> 2025 | BD2: =BC2+1 -> 2026 | BE2: =BD2+1 -> 2027
B3: 2017 | F3: 2018 | J3: 2019 | N3: 2020 | R3: 2021 | V3: 2022 | Z3: 2023 | AD3: 2024 | AH3: =AD3+1 -> 2025 | AL3: =AH3+1 -> 2026 | AP3: =AL3+1 -> 2027
A4: ($ in millions, unless otherwise stated) | B4: 42825 | C4: 42916 | D4: 43008 | E4: 43100 | F4: 43190 | G4: 43281 | H4: 43373 | I4: 43465 | J4: 43555 | K4: 43646 | L4: 43738 | M4: 43830 | N4: 43921 | O4: 44012 | P4: 44104 | Q4: 44196 | R4: 44286 | S4: 44377 | T4: 44469 | U4: 44561 | V4: 44651 | W4: 44742 | X4: 44834 | Y4: 44926 | Z4: 45016 | AA4: 45107 | AB4: 45199 | AC4: 45291 | AD4: 45382 | AE4: 45473 | AF4: Sep-24 | AG4: Dec-24 | AH4: Mar-25 | AI4: Jun-25 | AJ4: Sep-25 | AK4: Dec-25 | AL4: Mar-26E | AM4: Jun-26E | AN4: Sep-26E | AO4: Dec-26E | AP4: Mar-27E | AQ4: Jun-27E | AR4: Sep-27E | AS4: Dec-27E | AU4: 2017 | AV4: 2018 | AW4: 2019 | AX4: 2020 | AY4: CY21 | AZ4: CY22 | BA4: CY23 | BB4: CY24 | BC4: CY25 | BD4: CY26E | BE4: CY27E
A5: Revenue
A6: Subscription | B6: ='Revenue Build'!B13 -> 27.702 | C6: ='Revenue Build'!C13 -> 30.844 | D6: ='Revenue Build'!D13 -> 34.932 | E6: ='Revenue Build'!E13 -> 39.395 | F6: ='Revenue Build'!F13 -> 44.332 | G6: ='Revenue Build'!G13 -> 48.725 | H6: ='Revenue Build'!H13 -> 53.511 | I6: ='Revenue Build'!I13 -> 59.259 | ... AS6: ='Revenue Build'!AS13 -> 275.96222 | AU6: =SUM(B6:E6) -> 132.873 | AV6: =SUM(F6:I6) -> 205.827 | AW6: =SUM(J6:M6) -> 290.549 | AX6: =SUM(N6:Q6) -> 377.354 | AY6: =SUM(R6:U6) -> 476.023 | AZ6: =SUM(V6:Y6) -> 612.51 | BA6: =SUM(Z6:AC6) -> 725.013 | BB6: =SUM(AD6:AG6) -> 824.659 | BC6: =SUM(AH6:AK6) -> 919.573 | BD6: =SUM(AL6:AO6) -> 995.23014 | BE6: =SUM(AP6:AS6) -> 1069.6212
A7: Perpetual Licnese and Maintenance | B7: ='Revenue Build'!B18 -> 11.989 | C7: ='Revenue Build'!C18 -> 12.283 | D7: ='Revenue Build'!D18 -> 12.857 | E7: ='Revenue Build'!E18 -> 13.208 | F7: ='Revenue Build'!F18 -> 13.477 | G7: ='Revenue Build'!G18 -> 13.412 | H7: ='Revenue Build'!H18 -> 13.864 | I7: ='Revenue Build'!I18 -> 13.869 | ... AS7: ='Revenue Build'!AS18 -> 8.5941 | AU7: =SUM(B7:E7) -> 50.337 | AV7: =SUM(F7:I7) -> 54.622 | AW7: =SUM(J7:M7) -> 54.173 | AX7: =SUM(N7:Q7) -> 50.594 | AY7: =SUM(R7:U7) -> 50.333 | AZ7: =SUM(V7:Y7) -> 50.699 | BA7: =SUM(Z7:AC7) -> 48.729 | BB7: =SUM(AD7:AG7) -> 47.774 | BC7: =SUM(AH7:AK7) -> 44.661 | BD7: =SUM(AL7:AO7) -> 40.1949 | BE7: =SUM(AP7:AS7) -> 36.17541
A8: Professional Services and Other | B8: ='Revenue Build'!B23 -> 0.79 | C8: ='Revenue Build'!C23 -> 1.022 | D8: ='Revenue Build'!D23 -> 1.191 | E8: ='Revenue Build'!E23 -> 1.514 | F8: ='Revenue Build'!F23 -> 1.298 | G8: ='Revenue Build'!G23 -> 1.455 | H8: ='Revenue Build'!H23 -> 2.065 | I8: ='Revenue Build'!I23 -> 2.093 | ... AS8: ='Revenue Build'!AS23 -> 11.035 | AU8: =SUM(B8:E8) -> 4.517 | AV8: =SUM(F8:I8) -> 6.911 | AW8: =SUM(J8:M8) -> 9.864 | AX8: =SUM(N8:Q8) -> 12.273 | AY8: =SUM(R8:U8) -> 14.774 | AZ8: =SUM(V8:Y8) -> 19.982 | BA8: =SUM(Z8:AC8) -> 24.968 | BB8: =SUM(AD8:AG8) -> 27.588 | BC8: =SUM(AH8:AK8) -> 35.171 | BD8: =SUM(AL8:AO8) -> 34.8139 | BE8: =SUM(AP8:AS8) -> 34.8139
A9: Total revenue | B9: =+'Revenue Build'!B5 -> 40.481 | C9: =+'Revenue Build'!C5 -> 44.149 | D9: =+'Revenue Build'!D5 -> 48.98 | E9: =+'Revenue Build'!E5 -> 54.117 | F9: =+'Revenue Build'!F5 -> 59.107 | G9: =+'Revenue Build'!G5 -> 63.592 | H9: =+'Revenue Build'!H5 -> 69.44 | I9: =+'Revenue Build'!I5 -> 75.221 | ... AS9: =+'Revenue Build'!AS5 -> 295.59132 | AU9: =SUM(B9:E9) -> 187.727 | AV9: =SUM(F9:I9) -> 267.36 | AW9: =SUM(J9:M9) -> 354.586 | AX9: =SUM(N9:Q9) -> 440.221 | AY9: =SUM(R9:U9) -> 541.13 | AZ9: =SUM(V9:Y9) -> 683.191 | BA9: =SUM(Z9:AC9) -> 798.71 | BB9: =SUM(AD9:AG9) -> 900.021 | BC9: =SUM(AH9:AK9) -> 999.405 | BD9: =SUM(AL9:AO9) -> 1070.2389 | BE9: =SUM(AP9:AS9) -> 1140.6105
A10: Consensus revenue | B10: ='[2]VA Consensus'!C16 -> - | C10: ='[2]VA Consensus'!D16 -> - | D10: ='[2]VA Consensus'!E16 -> - | E10: ='[2]VA Consensus'!F16 -> - | F10: ='[2]VA Consensus'!G16 -> - | G10: ='[2]VA Consensus'!H16 -> - | H10: ='[2]VA Consensus'!I16 -> 66.295101 | I10: ='[2]VA Consensus'!J16 -> 72.829307 | ... AS10: ='[2]VA Consensus'!AT16 -> 296.33303 | AU10: ='[2]VA Consensus'!AV16 -> - | AV10: ='[2]VA Consensus'!AW16 -> 264.96833 | AW10: ='[2]VA Consensus'!AX16 -> 351.79152 | AX10: ='[2]VA Consensus'!AY16 -> 437.03012 | AY10: ='[2]VA Consensus'!AZ16 -> 536.56619 | AZ10: ='[2]VA Consensus'!BA16 -> 680.03864 | BA10: ='[2]VA Consensus'!BB16 -> 791.94039 | BB10: ='[2]VA Consensus'!BC16 -> 895.84654 | ... BE10: ='[2]VA Consensus'!BF16 -> 1145.8385
A11: Management Guidance - Revenue
A12: Low | N12: ='Revenue Build'!N9 -> 100 | O12: ='Revenue Build'!O9 -> 101 | P12: ='Revenue Build'!P9 -> 108 | Q12: ='Revenue Build'!Q9 -> 113 | R12: ='Revenue Build'!R9 -> 118 | S12: ='Revenue Build'!S9 -> 124 | T12: ='Revenue Build'!T9 -> 133 | U12: ='Revenue Build'!U9 -> 143 | ... AB12: ='Revenue Build'!AB9 -> 197 | AC12: 204 | AD12: ='Revenue Build'!AD9 -> 212 | AE12: ='Revenue Build'!AE9 -> 217 | AF12: ='Revenue Build'!AF9 -> 222 | AG12: 229 | AH12: 233 | AI12: ='Revenue Build'!AI9 -> 241 | AJ12: ='Revenue Build'!AJ9 -> 246 | AK12: ='Revenue Build'!AK9 -> 249.1 | AL12: ='Revenue Build'!AL9 -> 257 | AM12: ='Revenue Build'!AM9 | AN12: ='Revenue Build'!AN9 | AO12: ='Revenue Build'!AO9 | AP12: ='Revenue Build'!AP9 | ... AS12: ='Revenue Build'!AS9 | AY12: ='Revenue Build'!AY9 -> 535.1 | AZ12: ='Revenue Build'!AZ9 -> 678.6 | BA12: ='Revenue Build'!BA9 -> 789.4 | BB12: ='Revenue Build'!BB9 -> 893.3 | BC12: ='Revenue Build'!BC9 -> 988 | BD12: ='Revenue Build'!BD9 -> 1065
A13: Mid | N13: ='Revenue Build'!N10 -> 100.5 | O13: ='Revenue Build'!O10 -> 102 | P13: ='Revenue Build'!P10 -> 109 | Q13: ='Revenue Build'!Q10 -> 114 | R13: ='Revenue Build'!R10 -> 119 | S13: ='Revenue Build'!S10 -> 125 | T13: ='Revenue Build'!T10 -> 134 | U13: ='Revenue Build'!U10 -> 144 | ... AS13: ='Revenue Build'!AS10 | AY13: ='Revenue Build'!AY10 -> 536.1 | AZ13: ='Revenue Build'!AZ10 -> 679.6 | BA13: ='Revenue Build'!BA10 -> 791.4 | BB13: ='Revenue Build'!BB10 -> 895.3 | BC13: ='Revenue Build'!BC10 -> 990 | BD13: ='Revenue Build'!BD10 -> 1070
A14: High | N14: ='Revenue Build'!N11 -> 101 | O14: ='Revenue Build'!O11 -> 103 | P14: ='Revenue Build'!P11 -> 110 | Q14: ='Revenue Build'!Q11 -> 115 | R14: ='Revenue Build'!R11 -> 120 | S14: ='Revenue Build'!S11 -> 126 | T14: ='Revenue Build'!T11 -> 135 | U14: ='Revenue Build'!U11 -> 145 | ... AB14: ='Revenue Build'!AB11 -> 199 | AC14: 208 | AD14: ='Revenue Build'!AD11 -> 214 | AE14: ='Revenue Build'!AE11 -> 219 | AF14: ='Revenue Build'!AF11 -> 224 | AG14: 233 | AH14: 235 | AI14: ='Revenue Build'!AI11 -> 243 | AJ14: ='Revenue Build'!AJ11 -> 248 | AK14: ='Revenue Build'!AK11 -> 253.1 | AL14: ='Revenue Build'!AL11 -> 260 | AM14: ='Revenue Build'!AM11 | AN14: ='Revenue Build'!AN11 | AO14: ='Revenue Build'!AO11 | AP14: ='Revenue Build'!AP11 | ... AS14: ='Revenue Build'!AS11 | AY14: ='Revenue Build'!AY11 -> 537.1 | AZ14: ='Revenue Build'!AZ11 -> 680.6 | BA14: ='Revenue Build'!BA11 -> 793.4 | BB14: ='Revenue Build'!BB11 -> 897.3 | BC14: ='Revenue Build'!BC11 -> 992 | BD14: ='Revenue Build'!BD11 -> 1075
A16: Cost of Revenue | B16: =B112-B83-B86 -> 4.233 | C16: =C112-C83-C86 -> 5.147 | D16: =D112-D83-D86 -> 7.21 | E16: =E112-E83-E86 -> 8.114 | F16: =F112-F83-F86 -> 8.5 | G16: =G112-G83-G86 -> 9.614 | H16: =H112-H83-H86 -> 11.318 | I16: =I112-I83-I86 -> 11.425 | ... AK16: =AK112-AK83-AK86 -> 45.064 | AL16: =(1-AL69)*AL9 -> 47.056131 | AM16: =(1-AM69)*AM9 -> 47.980399 | AN16: =(1-AN69)*AN9 -> 47.83697 | AO16: =(1-AO69)*AO9 -> 47.988228 | AP16: =(1-AP69)*AP9 -> 50.43283 | AQ16: =(1-AQ69)*AQ9 -> 51.421835 | AR16: =(1-AR69)*AR9 -> 51.264925 | AS16: =(1-AS69)*AS9 -> 51.43289 | AU16: =SUM(B16:E16) -> 24.704 | AV16: =SUM(F16:I16) -> 40.857 | AW16: =SUM(J16:M16) -> 57.381 | AX16: =SUM(N16:Q16) -> 72.082 | AY16: =SUM(R16:U16) -> 95.503 | AZ16: =SUM(V16:Y16) -> 135.048 | BA16: =SUM(Z16:AC16) -> 158.471 | BB16: =SUM(AD16:AG16) -> 167.534 | BC16: =SUM(AH16:AK16) -> 179.258 | BD16: =SUM(AL16:AO16) -> 190.86173 | BE16: =SUM(AP16:AS16) -> 204.55248
A17: Gross profit | B17: =B9-B16 -> 36.248 | C17: =C9-C16 -> 39.002 | D17: =D9-D16 -> 41.77 | E17: =E9-E16 -> 46.003 | F17: =F9-F16 -> 50.607 | G17: =G9-G16 -> 53.978 | H17: =H9-H16 -> 58.122 | I17: =I9-I16 -> 63.796 | ... AS17: =AS9-AS16 -> 244.15843 | AU17: =SUM(B17:E17) -> 163.023 | AV17: =SUM(F17:I17) -> 226.503 | AW17: =SUM(J17:M17) -> 297.205 | AX17: =SUM(N17:Q17) -> 368.139 | AY17: =SUM(R17:U17) -> 445.627 | AZ17: =SUM(V17:Y17) -> 548.143 | BA17: =SUM(Z17:AC17) -> 640.239 | BB17: =SUM(AD17:AG17) -> 732.487 | BC17: =SUM(AH17:AK17) -> 820.147 | BD17: =SUM(AL17:AO17) -> 879.37722 | BE17: =SUM(AP17:AS17) -> 936.058
A18: Consensus gross profit | B18: ='[2]VA Consensus'!C23 -> - | C18: ='[2]VA Consensus'!D23 -> - | D18: ='[2]VA Consensus'!E23 -> - | E18: ='[2]VA Consensus'!F23 -> - | F18: ='[2]VA Consensus'!G23 -> - | G18: ='[2]VA Consensus'!H23 -> - | H18: ='[2]VA Consensus'!I23 -> 54.516385 | I18: ='[2]VA Consensus'!J23 -> 59.879956 | ... AS18: ='[2]VA Consensus'!AT23 -> 244.19627 | AU18: ='[2]VA Consensus'!AV23 -> - | AV18: ='[2]VA Consensus'!AW23 -> 222.53371 | AW18: ='[2]VA Consensus'!AX23 -> 296.58138 | AX18: ='[2]VA Consensus'!AY23 -> 364.88916 | AY18: ='[2]VA Consensus'!AZ23 -> 442.34027 | AZ18: ='[2]VA Consensus'!BA23 -> 550.00836 | BA18: ='[2]VA Consensus'!BB23 -> 632.37188 | BB18: ='[2]VA Consensus'!BC23 -> 727.79762 | ... BE18: ='[2]VA Consensus'!BF23 -> 941.23666
A20: Operating expenses
A21: Sales and marketing | B21: =B116-B143-B152-B161 -> 25.898 | C21: =C116-C143-C152-C161 -> 27.415 | D21: =D116-D143-D152-D161 -> 29.165 | E21: =E116-E143-E152-E161 -> 32.242 | F21: =F116-F143-F152-F161 -> 38.986 | G21: =G116-G143-G152-G161 -> 41.151 | H21: =H116-H143-H152-H161 -> 41.843 | I21: =I116-I143-I152-I161 -> 44.453 | ... AK21: =AK116-AK143-AK152-AK161 -> 89.425 | AL21: =AL$9*AL71 -> 91.151844 | AM21: =AM$9*AM71 -> 91.598078 | AN21: =AN$9*AN71 -> 84.221809 | AO21: =AO$9*AO71 -> 91.049665 | AP21: =AP$9*AP71 -> 95.780897 | AQ21: =AQ$9*AQ71 -> 96.212651 | AR21: =AR$9*AR71 -> 88.320858 | AS21: =AS$9*AS71 -> 95.546546 | AU21: =SUM(B21:E21) -> 114.72 | AV21: =SUM(F21:I21) -> 166.433 | AW21: =SUM(J21:M21) -> 212.003 | AX21: =SUM(N21:Q21) -> 204.435 | AY21: =SUM(R21:U21) -> 240.629 | AZ21: =SUM(V21:Y21) -> 300.047 | BA21: =SUM(Z21:AC21) -> 332.128 | BB21: =SUM(AD21:AG21) -> 332.658 | BC21: =SUM(AH21:AK21) -> 346.836 | BD21: =SUM(AL21:AO21) -> 358.0214 | BE21: =SUM(AP21:AS21) -> 375.86095
A22: Research and development | B22: =B117-B144-B153-B162 -> 12.064 | C22: =C117-C144-C153-C162 -> 13.261 | D22: =D117-D144-D153-D162 -> 15.359 | E22: =E117-E144-E153-E162 -> 15.207 | F22: =F117-F144-F153-F162 -> 16.658 | G22: =G117-G144-G153-G162 -> 17.151 | H22: =H117-H144-H153-H162 -> 18.126 | I22: =I117-I144-I153-I162 -> 18.959 | ... AK22: =AK117-AK144-AK153-AK162 -> 40.84 | AL22: =AL$9*AL72 -> 42.187116 | AM22: =AM$9*AM72 -> 46.605664 | AN22: =AN$9*AN72 -> 44.809979 | AO22: =AO$9*AO72 -> 43.482209 | AP22: =AP$9*AP72 -> 44.96733 | AQ22: =AQ$9*AQ72 -> 49.673589 | AR22: =AR$9*AR72 -> 47.752748 | AS22: =AS$9*AS72 -> 46.335588 | AU22: =SUM(B22:E22) -> 55.891 | AV22: =SUM(F22:I22) -> 70.894 | AW22: =SUM(J22:M22) -> 78.153 | AX22: =SUM(N22:Q22) -> 86.893 | AY22: =SUM(R22:U22) -> 95.7 | AZ22: =SUM(V22:Y22) -> 112.061 | BA22: =SUM(Z22:AC22) -> 115.938 | BB22: =SUM(AD22:AG22) -> 133.968 | BC22: =SUM(AH22:AK22) -> 165.352 | BD22: =SUM(AL22:AO22) -> 177.08497 | BE22: =SUM(AP22:AS22) -> 188.72925
A23: General and administrative | B23: =B118-B145-B154-B163 -> 5.255 | C23: =C118-C145-C154-C163 -> 5.555 | D23: =D118-D145-D154-D163 -> 6.229 | E23: =E118-E145-E154-E163 -> 7.77 | F23: =F118-F145-F154-F163 -> 7.862 | G23: =G118-G145-G154-G163 -> 8.946 | H23: =H118-H145-H154-H163 -> 10.315 | I23: =I118-I145-I154-I163 -> 11.156 | ... AK23: =AK118-AK145-AK154-AK163 -> 21.511 | AL23: =AL$9*AL73 -> 24.046711 | AM23: =AM$9*AM73 -> 23.632752 | AN23: =AN$9*AN73 -> 23.918485 | AO23: =AO$9*AO73 -> 22.191088 | AP23: =AP$9*AP73 -> 25.080223 | AQ23: =AQ$9*AQ73 -> 24.622399 | AR23: =AR$9*AR73 -> 24.916472 | AS23: =AS$9*AS73 -> 23.056123 | AU23: =SUM(B23:E23) -> 24.809 | AV23: =SUM(F23:I23) -> 38.279 | AW23: =SUM(J23:M23) -> 49.815 | AX23: =SUM(N23:Q23) -> 51.018 | AY23: =SUM(R23:U23) -> 58.313 | AZ23: =SUM(V23:Y23) -> 68.365 | BA23: =SUM(Z23:AC23) -> 71.176 | BB23: =SUM(AD23:AG23) -> 81.743 | BC23: =SUM(AH23:AK23) -> 88.98 | BD23: =SUM(AL23:AO23) -> 93.789036 | BE23: =SUM(AP23:AS23) -> 97.675218
A24: Total operating expenses | B24: =B21+B22+B23 -> 43.217 | C24: =C21+C22+C23 -> 46.231 | D24: =D21+D22+D23 -> 50.753 | E24: =E21+E22+E23 -> 55.219 | F24: =F21+F22+F23 -> 63.506 | G24: =G21+G22+G23 -> 67.248 | H24: =H21+H22+H23 -> 70.284 | I24: =I21+I22+I23 -> 74.568 | ... AS24: =AS21+AS22+AS23 -> 164.93826 | AU24: =SUM(B24:E24) -> 195.42 | AV24: =SUM(F24:I24) -> 275.606 | AW24: =SUM(J24:M24) -> 339.971 | AX24: =SUM(N24:Q24) -> 342.346 | AY24: =SUM(R24:U24) -> 394.642 | AZ24: =SUM(V24:Y24) -> 480.473 | BA24: =SUM(Z24:AC24) -> 519.242 | BB24: =SUM(AD24:AG24) -> 548.369 | BC24: =SUM(AH24:AK24) -> 601.168 | BD24: =SUM(AL24:AO24) -> 628.8954 | BE24: =SUM(AP24:AS24) -> 662.26542
A25: Operating Income | B25: =B17-B24 -> -6.969 | C25: =C17-C24 -> -7.229 | D25: =D17-D24 -> -8.983 | E25: =E17-E24 -> -9.216 | F25: =F17-F24 -> -12.899 | G25: =G17-G24 -> -13.27 | H25: =H17-H24 -> -12.162 | I25: =I17-I24 -> -10.772 | ... AS25: =AS17-AS24 -> 79.220176 | AU25: =SUM(B25:E25) -> -32.397 | AV25: =SUM(F25:I25) -> -49.103 | AW25: =SUM(J25:M25) -> -42.766 | AX25: =SUM(N25:Q25) -> 25.793 | AY25: =SUM(R25:U25) -> 50.985 | AZ25: =SUM(V25:Y25) -> 67.67 | BA25: =SUM(Z25:AC25) -> 120.997 | BB25: =SUM(AD25:AG25) -> 184.118 | BC25: =SUM(AH25:AK25) -> 218.979 | BD25: =SUM(AL25:AO25) -> 250.48182 | BE25: =SUM(AP25:AS25) -> 273.79258
A26: Consensus operating income | B26: ='[2]VA Consensus'!C29 -> - | C26: ='[2]VA Consensus'!D29 -> - | D26: ='[2]VA Consensus'!E29 -> - | E26: ='[2]VA Consensus'!F29 -> - | F26: ='[2]VA Consensus'!G29 -> - | G26: ='[2]VA Consensus'!H29 -> - | H26: ='[2]VA Consensus'!I29 -> -16.934376 | I26: ='[2]VA Consensus'!J29 -> -13.435126 | ... AS26: ='[2]VA Consensus'!AT29 -> 77.324023 | AU26: ='[2]VA Consensus'!AV29 -> - | AV26: ='[2]VA Consensus'!AW29 -> -51.76636 | AW26: ='[2]VA Consensus'!AX29 -> -44.405321 | AX26: ='[2]VA Consensus'!AY29 -> 19.247211 | AY26: ='[2]VA Consensus'!AZ29 -> 46.924672 | AZ26: ='[2]VA Consensus'!BA29 -> 63.35298 | BA26: ='[2]VA Consensus'!BB29 -> 108.76154 | BB26: ='[2]VA Consensus'!BC29 -> 172.68222 | ... BE26: ='[2]VA Consensus'!BF29 -> 280.1123
A27: Management Guidance - Operating Income
A28: Low | N28: -18 | O28: -5.5 | P28: 3 | Q28: 8 | R28: 7 | S28: 7 | T28: 7 | U28: 7 | V28: 10 | W28: 6 | X28: 9 | Y28: 15 | Z28: 9 | AA28: 20 | AB28: 26 | AC28: 23 | AD28: 27 | AE28: 34 | AF28: 42 | AG28: 47 | AH28: 40 | AI28: 43 | AJ28: 52 | AK28: 55.7 | AL28: 53 | AY28: 46.1 | AZ28: 62.7 | BA28: 107.9 | BB28: 171.8 | BC28: 205 | BD28: 245
A29: Mid | N29: =AVERAGE(N28,N30) -> -17.5 | O29: =AVERAGE(O28,O30) -> -4.5 | P29: =AVERAGE(P28,P30) -> 3.5 | Q29: =AVERAGE(Q28,Q30) -> 8.5 | R29: =AVERAGE(R28,R30) -> 8 | S29: =AVERAGE(S28,S30) -> 7.5 | T29: =AVERAGE(T28,T30) -> 7.5 | U29: =AVERAGE(U28,U30) -> 7.5 | ... AC29: =AVERAGE(AC28,AC30) -> 23.5 | AD29: =IFERROR(AVERAGE(AD28,AD30),"") -> 28 | AE29: =IFERROR(AVERAGE(AE28,AE30),"") -> 35 | AF29: =IFERROR(AVERAGE(AF28,AF30),"") -> 43 | AG29: =IFERROR(AVERAGE(AG28,AG30),"") -> 48 | AH29: =IFERROR(AVERAGE(AH28,AH30),"") -> 41 | AI29: =IFERROR(AVERAGE(AI28,AI30),"") -> 44 | AJ29: =IFERROR(AVERAGE(AJ28,AJ30),"") -> 53 | AK29: =IFERROR(AVERAGE(AK28,AK30),"") -> 57.7 | ... AS29: =IFERROR(AVERAGE(AS28,AS30),"") | AY29: =AVERAGE(AY28,AY30) -> 46.6 | AZ29: =AVERAGE(AZ28,AZ30) -> 63.2 | BA29: =AVERAGE(BA28,BA30) -> 108.4 | BB29: =IFERROR(AVERAGE(BB28,BB30),"") -> 172.8 | BC29: =IFERROR(AVERAGE(BC28,BC30),"") -> 210 | BD29: =IFERROR(AVERAGE(BD28,BD30),"") -> 250 | BE29: =IFERROR(AVERAGE(BE28,BE30),"")
A30: High | N30: -17 | O30: -3.5 | P30: 4 | Q30: 9 | R30: 9 | S30: 8 | T30: 8 | U30: 8 | V30: 11 | W30: 7 | X30: 10 | Y30: 16 | Z30: 10 | AA30: 21 | AB30: 27 | AC30: 24 | AD30: 29 | AE30: 36 | AF30: 44 | AG30: 49 | AH30: 42 | AI30: 45 | AJ30: 54 | AK30: 59.7 | AL30: 56 | AY30: 47.1 | AZ30: 63.7 | BA30: 108.9 | BB30: 173.8 | BC30: 215 | BD30: 255
A31: EBITDA | B31: =B25+'Cash Flow'!B8-'Income Statement'!B85 -> -6.084 | C31: =C25+'Cash Flow'!C8-'Income Statement'!C85 -> -6.295 | D31: =D25+'Cash Flow'!D8-'Income Statement'!D85 -> -7.939 | E31: =E25+'Cash Flow'!E8-'Income Statement'!E85 -> -7.99 | F31: =F25+'Cash Flow'!F8-'Income Statement'!F85 -> -11.596 | G31: =G25+'Cash Flow'!G8-'Income Statement'!G85 -> -11.881 | H31: =H25+'Cash Flow'!H8-'Income Statement'!H85 -> -10.727 | I31: =I25+'Cash Flow'!I8-'Income Statement'!I85 -> -9.31 | ... AC31: =AC25+'Cash Flow'!AC8-'Income Statement'!AC85 -> 39.62 | AD31: =AD25+'Cash Flow'!AT8-'Income Statement'!AD85 -> 32.339 | AE31: =AE25+'Cash Flow'!AU8-'Income Statement'!AE85 -> 42.716 | AF31: =AF25+'Cash Flow'!AV8-'Income Statement'!AF85 -> 46.153 | AG31: =AG25+'Cash Flow'!AW8-'Income Statement'!AG85 -> 61.217 | AH31: =AH25+'Cash Flow'!AX8-'Income Statement'!AH85 -> 53.446 | AI31: =AI25+'Cash Flow'!AY8-'Income Statement'!AI85 -> 57.329 | AJ31: =AJ25+'Cash Flow'!AZ8-'Income Statement'!AJ85 -> 74.325 | AK31: =AK25+'Cash Flow'!BA8-'Income Statement'!AK85 -> 84.019 | ... AN31: =AN25+'Cash Flow'!BD8-'Income Statement'!AN85 -> 106.76914 | AO31: =AO25+'Cash Flow'!BF8-'Income Statement'!AO85 -> 65.89541 | AP31: =AP25+'Cash Flow'!BF8-'Income Statement'!AP85 -> 52.563568 | AQ31: =AQ25+'Cash Flow'!BG8-'Income Statement'!AQ85 -> 57.119611 | AR31: =AR25+'Cash Flow'!BH8-'Income Statement'!AR85 -> 74.166226 | AS31: =AS25+'Cash Flow'!BJ8-'Income Statement'!AS85 -> 88.608176 | AU31: =SUM(B31:E31) -> -28.308 | AV31: =SUM(F31:I31) -> -43.514 | AW31: =SUM(J31:M31) -> -36.506 | AX31: =SUM(N31:Q31) -> 34.112 | AY31: =SUM(R31:U31) -> 60.708 | AZ31: =SUM(V31:Y31) -> 78.492 | BA31: =SUM(Z31:AC31) -> 134.246 | BB31: =SUM(AD31:AG31) -> 182.425 | BC31: =SUM(AH31:AK31) -> 269.119 | BD31: =SUM(AL31:AO31) -> 344.10918 | BE31: =SUM(AP31:AS31) -> 272.45758
A33: Interest income | B33: =B123 -> 0 | C33: =C123 -> 0 | D33: =D123 -> 0 | E33: =E123 -> 0 | F33: =F123 -> -0.026 | G33: =G123 -> -0.023 | H33: =H123 -> 0.894 | I33: =I123 -> 1.509 | ... AK33: =AK123 -> 3.395 | AL33: =AK33-0.5 -> 2.895 | AM33: =AL33-0.7 -> 2.195 | AN33: =AM33+0.3 -> 2.495 | AO33: =AN33+0.3 -> 2.795 | AP33: =AO33+0.3 -> 3.095 | AQ33: =AP33+0.3 -> 3.395 | AR33: =AQ33+0.3 -> 3.695 | AS33: =AR33+0.3 -> 3.995 | AU33: =SUM(B33:E33) -> 0 | AV33: =SUM(F33:I33) -> 2.354 | AW33: =SUM(J33:M33) -> 5.83 | AX33: =SUM(N33:Q33) -> 1.74 | AY33: =SUM(R33:U33) -> 0.606 | AZ33: =SUM(V33:Y33) -> 6.284 | BA33: =SUM(Z33:AC33) -> 24.7 | BB33: =SUM(AD33:AG33) -> 23.325 | BC33: =SUM(AH33:AK33) -> 15.992 | BD33: =SUM(AL33:AO33) -> 10.38 | BE33: =SUM(AP33:AS33) -> 14.18
A34: Interest expense | B34: =B124 -> 0 | C34: =C124 -> 0 | D34: =D124 -> 0 | E34: =E124 -> 0 | F34: =F124 -> 0 | G34: =G124 -> 0 | H34: =H124 -> 0 | I34: =I124 -> 0 | ... AK34: =AK124 -> -7.056 | AL34: =AK34+0.7 -> -6.356 | AM34: =AL34-0.025 -> -6.381 | AN34: =AM34-0.025 -> -6.406 | AO34: =AN34-0.025 -> -6.431 | AP34: =AO34-0.025 -> -6.456 | AQ34: =AP34-0.025 -> -6.481 | AR34: =AQ34-0.025 -> -6.506 | AS34: =AR34-0.025 -> -6.531 | AY34: =SUM(R34:U34) -> -7.502 | AZ34: =SUM(V34:Y34) -> -19.001 | BA34: =SUM(Z34:AC34) -> -31.339 | BB34: =SUM(AD34:AG34) -> -31.92 | BC34: =SUM(AH34:AK34) -> -28.419 | BD34: =SUM(AL34:AO34) -> -25.574 | BE34: =SUM(AP34:AS34) -> -25.974
A35: Other income (expense), net | B35: =B125 -> -0.029 | C35: =C125 -> 0.056 | D35: =D125 -> -0.092 | E35: =E125 -> -0.026 | F35: =F125 -> 0.018 | G35: =G125 -> -0.438 | H35: =H125 -> -0.185 | I35: =I125 -> -0.325 | ... AK35: =AK125 -> -1.134 | AL35: =AK35 -> -1.134 | AM35: =AL35 -> -1.134 | AN35: =AM35 -> -1.134 | AO35: =AN35 -> -1.134 | AP35: =AO35 -> -1.134 | AQ35: =AP35 -> -1.134 | AR35: =AQ35 -> -1.134 | AS35: =AR35 -> -1.134 | AU35: =SUM(B35:E35) -> -0.091 | AV35: =SUM(F35:I35) -> -0.93 | AW35: =SUM(J35:M35) -> -0.68 | AX35: =SUM(N35:Q35) -> -1.885 | AY35: =SUM(R35:U35) -> -1.965 | AZ35: =SUM(V35:Y35) -> -4.757 | BA35: =SUM(Z35:AC35) -> -8.602 | BB35: =SUM(AD35:AG35) -> -3.435 | BC35: =SUM(AH35:AK35) -> -1.338 | BD35: =SUM(AL35:AO35) -> -4.536 | BE35: =SUM(AP35:AS35) -> -4.536
A36: Pre-tax income | B36: =B25+SUM(B33:B35) -> -6.998 | C36: =C25+SUM(C33:C35) -> -7.173 | D36: =D25+SUM(D33:D35) -> -9.075 | E36: =E25+SUM(E33:E35) -> -9.242 | F36: =F25+SUM(F33:F35) -> -12.907 | G36: =G25+SUM(G33:G35) -> -13.731 | H36: =H25+SUM(H33:H35) -> -11.453 | I36: =I25+SUM(I33:I35) -> -9.588 | ... AS36: =AS25+SUM(AS33:AS35) -> 75.550176 | AU36: =SUM(B36:E36) -> -32.488 | AV36: =SUM(F36:I36) -> -47.679 | AW36: =SUM(J36:M36) -> -37.616 | AX36: =SUM(N36:Q36) -> 25.152 | AY36: =SUM(R36:U36) -> 42.124 | AZ36: =SUM(V36:Y36) -> 50.196 | BA36: =SUM(Z36:AC36) -> 105.756 | BB36: =SUM(AD36:AG36) -> 172.088 | BC36: =SUM(AH36:AK36) -> 205.214 | BD36: =SUM(AL36:AO36) -> 230.75182 | BE36: =SUM(AP36:AS36) -> 257.46258
A37: Provision for (benefit from) income taxes | B37: =B128-B169-B170-B171 -> 0.061 | C37: =C128-C169-C170-C171 -> 0.053 | D37: =D128-D169-D170-D171 -> 0.072 | E37: =E128-E169-E170-E171 -> 0.039 | F37: =F128-F169-F170-F171 -> 0.454 | G37: =G128-G169-G170-G171 -> 0.269 | H37: =H128-H169-H170-H171 -> 0.572 | I37: =I128-I169-I170-I171 -> 1.287 | ... AK37: =AK128-AK169-AK170-AK171 -> 1.593 | AL37: =AK37+0.075 -> 1.668 | AM37: =AL37+2 -> 3.668 | AN37: =AM37+0.075 -> 3.743 | AO37: =AN37+0.075 -> 3.818 | AP37: =AO37+0.075 -> 3.893 | AQ37: =AP37+0.075 -> 3.968 | AR37: =AQ37+0.075 -> 4.043 | AS37: =AR37+0.075 -> 4.118 | AU37: =SUM(B37:E37) -> 0.225 | AV37: =SUM(F37:I37) -> 2.582 | AW37: =SUM(J37:M37) -> 2.877 | AX37: =SUM(N37:Q37) -> 4.358 | AY37: =SUM(R37:U37) -> 3.183 | AZ37: =SUM(V37:Y37) -> 5.881 | BA37: =SUM(Z37:AC37) -> 8.601 | BB37: =SUM(AD37:AG37) -> 13.499 | BC37: =SUM(AH37:AK37) -> 10.784 | BD37: =SUM(AL37:AO37) -> 12.897 | BE37: =SUM(AP37:AS37) -> 16.022
A38: Adjusted tax rate (non-GAAP) | B38: =+B37/B36 -> -0.0087167762 | C38: =+C37/C36 -> -0.0073888192 | D38: =+D37/D36 -> -0.0079338843 | E38: =+E37/E36 -> -0.0042198658 | F38: =+F37/F36 -> -0.035174711 | G38: =+G37/G36 -> -0.019590707 | H38: =+H37/H36 -> -0.049943246 | I38: =+I37/I36 -> -0.13423029 | ... AS38: =+AS37/AS36 -> 0.054506822 | AU38: =AU37/AU36 -> -0.0069256341 | AV38: =AV37/AV36 -> -0.05415382 | AW38: =AW37/AW36 -> -0.076483411 | AX38: =AX37/AX36 -> 0.17326654 | AY38: =AY37/AY36 -> 0.075562625 | AZ38: =AZ37/AZ36 -> 0.11716073 | BA38: =BA37/BA36 -> 0.081328719 | BB38: =BB37/BB36 -> 0.078442425 | ... BE38: =BE37/BE36 -> 0.062230402
A39: Non-GAAP Net income | B39: =B36-B37 -> -7.059 | C39: =C36-C37 -> -7.226 | D39: =D36-D37 -> -9.147 | E39: =E36-E37 -> -9.281 | F39: =F36-F37 -> -13.361 | G39: =G36-G37 -> -14 | H39: =H36-H37 -> -12.025 | I39: =I36-I37 -> -10.875 | ... AS39: =AS36-AS37 -> 71.432176 | AU39: =SUM(B39:E39) -> -32.713 | AV39: =SUM(F39:I39) -> -50.261 | AW39: =SUM(J39:M39) -> -40.493 | AX39: =SUM(N39:Q39) -> 20.794 | AY39: =SUM(R39:U39) -> 38.941 | AZ39: =SUM(V39:Y39) -> 44.315 | BA39: =SUM(Z39:AC39) -> 97.155 | BB39: =SUM(AD39:AG39) -> 158.589 | BC39: =SUM(AH39:AK39) -> 194.43 | BD39: =SUM(AL39:AO39) -> 217.85482 | BE39: =SUM(AP39:AS39) -> 241.44058
A40: Consensus net income | B40: ='[2]VA Consensus'!C31 -> - | C40: ='[2]VA Consensus'!D31 -> - | D40: ='[2]VA Consensus'!E31 -> - | E40: ='[2]VA Consensus'!F31 -> - | F40: ='[2]VA Consensus'!G31 -> - | G40: ='[2]VA Consensus'!H31 -> - | H40: ='[2]VA Consensus'!I31 -> -16.619108 | I40: ='[2]VA Consensus'!J31 -> -13.023466 | ... AS40: ='[2]VA Consensus'!AT31 -> 68.638046 | AU40: ='[2]VA Consensus'!AV31 -> - | AV40: ='[2]VA Consensus'!AW31 -> -52.415811 | AW40: ='[2]VA Consensus'!AX31 -> -41.748534 | AX40: ='[2]VA Consensus'!AY31 -> 13.487622 | AY40: ='[2]VA Consensus'!AZ31 -> 35.695242 | AZ40: ='[2]VA Consensus'!BA31 -> 38.339587 | BA40: ='[2]VA Consensus'!BB31 -> 83.813788 | BB40: ='[2]VA Consensus'!BC31 -> 151.10782 | ... BE40: ='[2]VA Consensus'!BF31 -> 248.16594
A41: Management Guidance - Non-GAAP Net Income
A42: Low | N42: -19 | O42: -6 | P42: 2 | Q42: 6 | R42: 5 | S42: 5 | T42: 1 | U42: 2 | V42: 5.2 | W42: 1 | X42: 3.2 | Y42: 7.5 | Z42: 3 | AA42: 15 | AB42: 22 | AC42: 16 | AD42: 20 | AE42: 28 | AF42: 35 | AG42: 42 | AH42: 32 | AI42: 36 | AJ42: 44 | AK42: 47.9 | AL42: 46 | AY42: 35 | AZ42: 37.6 | BA42: 83 | BB42: 149.9 | BC42: 185 | BD42: 214
A43: Mid | N43: =AVERAGE(N42,N44) -> -18.5 | O43: =AVERAGE(O42,O44) -> -5 | P43: =AVERAGE(P42,P44) -> 2.5 | Q43: =AVERAGE(Q42,Q44) -> 6.5 | R43: =AVERAGE(R42,R44) -> 6 | S43: =AVERAGE(S42,S44) -> 5.5 | T43: =AVERAGE(T42,T44) -> 2 | U43: =AVERAGE(U42,U44) -> 2.5 | ... AC43: =AVERAGE(AC42,AC44) -> 16.5 | AD43: =IFERROR(AVERAGE(AD42,AD44),"") -> 21 | AE43: =IFERROR(AVERAGE(AE42,AE44),"") -> 29 | AF43: =IFERROR(AVERAGE(AF42,AF44),"") -> 36 | AG43: =IFERROR(AVERAGE(AG42,AG44),"") -> 43 | AH43: =IFERROR(AVERAGE(AH42,AH44),"") -> 33 | AI43: =IFERROR(AVERAGE(AI42,AI44),"") -> 37 | AJ43: =IFERROR(AVERAGE(AJ42,AJ44),"") -> 45 | AK43: =IFERROR(AVERAGE(AK42,AK44),"") -> 49.9 | ... AS43: =IFERROR(AVERAGE(AS42,AS44),"") | AY43: =AVERAGE(AY42,AY44) -> 35.5 | AZ43: =AVERAGE(AZ42,AZ44) -> 38.1 | BA43: =AVERAGE(BA42,BA44) -> 83.5 | BB43: =IFERROR(AVERAGE(BB42,BB44),"") -> 150.9 | BC43: =IFERROR(AVERAGE(BC42,BC44),"") -> 187 | BD43: =IFERROR(AVERAGE(BD42,BD44),"") -> 219 | BE43: =IFERROR(AVERAGE(BE42,BE44),"") | BF43: =IFERROR(AVERAGE(BF42,BF44),"")
...

Sheet Revenue Build
A1: =+'Income Statement'!A1 -> Tenable Holdings, Inc. (TENB)
A2: Revenue Build | R2: ='Income Statement'!R2 -> 2021/1F | S2: ='Income Statement'!S2 -> 2021/2F | T2: ='Income Statement'!T2 -> 2021/3F | U2: ='Income Statement'!U2 -> 2021/4F | V2: ='Income Statement'!V2 -> 2022/1F | W2: ='Income Statement'!W2 -> 2022/2F | X2: ='Income Statement'!X2 -> 2022/3F | Y2: ='Income Statement'!Y2 -> 2022/4F | ... AS2: ='Income Statement'!AS2 -> 2027/4F | AX2: ='Income Statement'!AX2 -> 2020 | AY2: ='Income Statement'!AY2 -> 2021 | AZ2: ='Income Statement'!AZ2 -> 2022 | BA2: ='Income Statement'!BA2 -> 2023 | BB2: ='Income Statement'!BB2 -> 2024 | BC2: ='Income Statement'!BC2 -> 2025 | BD2: ='Income Statement'!BD2 -> 2026 | BE2: ='Income Statement'!BE2 -> 2027
B3: ='Income Statement'!B$3 -> 2017 | F3: ='Income Statement'!F$3 -> 2018 | J3: ='Income Statement'!J$3 -> 2019 | N3: ='Income Statement'!N$3 -> 2020 | R3: ='Income Statement'!R$3 -> 2021 | V3: ='Income Statement'!V$3 -> 2022 | Z3: ='Income Statement'!Z$3 -> 2023 | AD3: ='Income Statement'!AD$3 -> 2024 | AH3: ='Income Statement'!AH$3 -> 2025 | AL3: ='Income Statement'!AL$3 -> 2026 | AP3: ='Income Statement'!AP$3 -> 2027
A4: ='Income Statement'!A4 -> ($ in millions, unless otherwise stated) | B4: ='Income Statement'!B$4 -> 42825 | C4: ='Income Statement'!C$4 -> 42916 | D4: ='Income Statement'!D$4 -> 43008 | E4: ='Income Statement'!E$4 -> 43100 | F4: ='Income Statement'!F$4 -> 43190 | G4: ='Income Statement'!G$4 -> 43281 | H4: ='Income Statement'!H$4 -> 43373 | I4: ='Income Statement'!I$4 -> 43465 | ... AS4: ='Income Statement'!AS$4 -> Dec-27E | AU4: ='Income Statement'!AU$4 -> 2017 | AV4: ='Income Statement'!AV$4 -> 2018 | AW4: ='Income Statement'!AW$4 -> 2019 | AX4: ='Income Statement'!AX$4 -> 2020 | AY4: ='Income Statement'!AY$4 -> CY21 | AZ4: ='Income Statement'!AZ$4 -> CY22 | BA4: ='Income Statement'!BA$4 -> CY23 | BB4: ='Income Statement'!BB$4 -> CY24 | ... BE4: ='Income Statement'!BE$4 -> CY27E
A5: Total Revenue | B5: =B13+B18+B23 -> 40.481 | C5: 44.149 | D5: =D13+D18+D23 -> 48.98 | E5: =E13+E18+E23 -> 54.117 | F5: =F13+F18+F23 -> 59.107 | G5: =G13+G18+G23 -> 63.592 | H5: =H13+H18+H23 -> 69.44 | I5: =I13+I18+I23 -> 75.221 | J5: =J13+J18+J23 -> 80.301 | K5: =K13+K18+K23 -> 85.384 | ... AS5: =AS13+AS18+AS23 -> 295.59132 | AU5: =SUM(B5:E5) -> 187.727 | AV5: =SUM(F5:I5) -> 267.36 | AW5: =SUM(J5:M5) -> 354.586 | AX5: =SUM(N5:Q5) -> 440.221 | AY5: =SUM(R5:U5) -> 541.13 | AZ5: =SUM(V5:Y5) -> 683.191 | BA5: =SUM(Z5:AC5) -> 798.71 | BB5: =SUM(AD5:AG5) -> 900.021 | BC5: =SUM(AH5:AK5) -> 999.405 | BD5: =SUM(AL5:AO5) -> 1070.2389 | BE5: =SUM(AP5:AS5) -> 1140.6105
A6: Consensus revenue | B6: ='Income Statement'!B10 -> - | C6: ='Income Statement'!C10 -> - | D6: ='Income Statement'!D10 -> - | E6: ='Income Statement'!E10 -> - | F6: ='Income Statement'!F10 -> - | G6: ='Income Statement'!G10 -> - | H6: ='Income Statement'!H10 -> 66.295101 | I6: ='Income Statement'!I10 -> 72.829307 | ... AD6: ='Income Statement'!AD10 -> 213.54153 | AE6: 218.54245 | AF6: 223.26996 | AG6: ='Income Statement'!AG10 -> 231.55654 | AH6: ='Income Statement'!AH10 -> 233.57912 | AI6: ='Income Statement'!AI10 -> 242.07841 | AJ6: ='Income Statement'!AJ10 -> 247.33865 | AK6: ='Income Statement'!AK10 -> 251.72895 | AL6: ='Income Statement'!AL10 -> 258.87608 | AM6: ='Income Statement'!AM10 -> 264.67593 | AN6: ='Income Statement'!AN10 -> 269.71728 | ... AS6: ='Income Statement'!AS10 -> 296.33303 | AX6: ='Income Statement'!AX10 -> 437.03012 | AY6: ='Income Statement'!AY10 -> 536.56619 | AZ6: ='Income Statement'!AZ10 -> 680.03864 | BA6: ='Income Statement'!BA10 -> 791.94039 | BB6: ='Income Statement'!BB10 -> 895.84654 | BC6: ='Income Statement'!BC10 -> 990.66282 | BD6: ='Income Statement'!BD10 -> 1070.3484 | BE6: ='Income Statement'!BE10 -> 1145.8385
A7: Y/Y Growth | B7: =IF(ISERROR(B5/#REF!-1),"NA",B5/#REF!-1) -> NA | C7: =IF(ISERROR(C5/#REF!-1),"NA",C5/#REF!-1) -> NA | D7: =IF(ISERROR(D5/#REF!-1),"NA",D5/#REF!-1) -> NA | E7: =IF(ISERROR(E5/#REF!-1),"NA",E5/#REF!-1) -> NA | F7: =IF(ISERROR(F5/B5-1),"NA",F5/B5-1) -> 0.46011709 | G7: =IF(ISERROR(G5/C5-1),"NA",G5/C5-1) -> 0.44039503 | H7: =IF(ISERROR(H5/D5-1),"NA",H5/D5-1) -> 0.41772152 | I7: =IF(ISERROR(I5/E5-1),"NA",I5/E5-1) -> 0.38996988 | J7: =IF(ISERROR(J5/F5-1),"NA",J5/F5-1) -> 0.35857005 | K7: =IF(ISERROR(K5/G5-1),"NA",K5/G5-1) -> 0.34268461 | L7: =IF(ISERROR(L5/H5-1),"NA",L5/H5-1) -> 0.32275346 | M7: =IF(ISERROR(M5/I5-1),"NA",M5/I5-1) -> 0.29018492 | ... AS7: =IF(ISERROR(AS5/AO5-1),"NA",AS5/AO5-1) -> 0.065621742 | AU7: =IF(ISERROR(AU5/#REF!-1),"NA",AU5/#REF!-1) -> NA | AV7: =IF(ISERROR(AV5/AU5-1),"NA",AV5/AU5-1) -> 0.42419577 | AW7: =IF(ISERROR(AW5/AV5-1),"NA",AW5/AV5-1) -> 0.32624925 | AX7: =IF(ISERROR(AX5/AW5-1),"NA",AX5/AW5-1) -> 0.241507 | AY7: =IF(ISERROR(AY5/AX5-1),"NA",AY5/AX5-1) -> 0.2292235 | AZ7: =IF(ISERROR(AZ5/AY5-1),"NA",AZ5/AY5-1) -> 0.26252656 | BA7: =IF(ISERROR(BA5/AZ5-1),"NA",BA5/AZ5-1) -> 0.16908741 | BB7: =IF(ISERROR(BB5/BA5-1),"NA",BB5/BA5-1) -> 0.12684328 | BC7: =IF(ISERROR(BC5/BB5-1),"NA",BC5/BB5-1) -> 0.11042409 | ... BE7: =IF(ISERROR(BE5/BD5-1),"NA",BE5/BD5-1) -> 0.065753111
A8: Management Guidance - Revenue
A9: Low | N9: 100 | O9: 101 | P9: 108 | Q9: 113 | R9: 118 | S9: 124 | T9: 133 | U9: 143 | V9: 152 | W9: 162 | X9: 169 | Y9: 180 | Z9: 186 | AA9: 189 | AB9: 197 | AC9: 204 | AD9: 212 | AE9: 217 | AF9: 222 | AG9: 229 | AH9: 233 | AI9: 241 | AJ9: 246 | AK9: 249.1 | AL9: 257 | AY9: 535.1 | AZ9: 678.6 | BA9: 789.4 | BB9: 893.3 | BC9: 988 | BD9: 1065
A10: Mid | N10: =AVERAGE(N9,N11) -> 100.5 | O10: =AVERAGE(O9,O11) -> 102 | P10: =AVERAGE(P9,P11) -> 109 | Q10: =AVERAGE(Q9,Q11) -> 114 | R10: =AVERAGE(R9,R11) -> 119 | S10: =AVERAGE(S9,S11) -> 125 | T10: =AVERAGE(T9,T11) -> 134 | U10: =AVERAGE(U9,U11) -> 144 | ... AB10: =AVERAGE(AB9,AB11) -> 198 | AC10: =IFERROR(AVERAGE(AC9,AC11),"") -> 206 | AD10: =IFERROR(AVERAGE(AD9,AD11),"") -> 213 | AE10: =IFERROR(AVERAGE(AE9,AE11),"") -> 218 | AF10: =IFERROR(AVERAGE(AF9,AF11),"") -> 223 | AG10: =IFERROR(AVERAGE(AG9,AG11),"") -> 231 | AH10: =IFERROR(AVERAGE(AH9,AH11),"") -> 234 | AI10: =IFERROR(AVERAGE(AI9,AI11),"") -> 242 | AJ10: =IFERROR(AVERAGE(AJ9,AJ11),"") -> 247 | ... AS10: =IFERROR(AVERAGE(AS9,AS11),"") | AY10: =AVERAGE(AY9,AY11) -> 536.1 | AZ10: =AVERAGE(AZ9,AZ11) -> 679.6 | BA10: =AVERAGE(BA9,BA11) -> 791.4 | BB10: =IFERROR(AVERAGE(BB9,BB11),"") -> 895.3 | BC10: =IFERROR(AVERAGE(BC9,BC11),"") -> 990 | BD10: =IFERROR(AVERAGE(BD9,BD11),"") -> 1070 | BE10: =IFERROR(AVERAGE(BE9,BE11),"")
A11: High | N11: 101 | O11: 103 | P11: 110 | Q11: 115 | R11: 120 | S11: 126 | T11: 135 | U11: 145 | V11: 154 | W11: 164 | X11: 171 | Y11: 182 | Z11: 188 | AA11: 191 | AB11: 199 | AC11: 208 | AD11: 214 | AE11: 219 | AF11: 224 | AG11: 233 | AH11: 235 | AI11: 243 | AJ11: 248 | AK11: 253.1 | AL11: 260 | AY11: 537.1 | AZ11: 680.6 | BA11: 793.4 | BB11: 897.3 | BC11: 992 | BD11: 1075
A12: Revenue by Type
A13: Subscription | B13: 27.702 | C13: =132.873-B13-D13-E13 -> 30.844 | D13: 34.932 | E13: 39.395 | F13: 44.332 | G13: 48.725 | H13: 53.511 | I13: 59.259 | J13: 64.737 | K13: 69.37 | L13: 75.503 | M13: 80.939 | N13: 86.39 | O13: 92.01 | P13: 96.792 | Q13: 102.162 | R13: 107.402 | S13: 114.167 | T13: 122.156 | U13: 132.298 | V13: 142.687 | W13: 146.806 | X13: 156.764 | Y13: 166.253 | Z13: 171.098 | AA13: 176.767 | AB13: 183.268 | AC13: 193.88 | AD13: 197.635 | AE13: 202.538 | AF13: 208.554 | AG13: 215.932 | AH13: 220.443 | AI13: 228.031 | AJ13: 232.211 | AK13: 238.888 | AL13: =AH13*(1+AL15) -> 241.38509 | AM13: =AI13*(1+AM15) -> 247.41363 | AN13: =AJ13*(1+AN15) -> 249.62682 | AO13: =AK13*(1+AO15) -> 256.8046 | AP13: =AL13*(1+AP15) -> 259.46483 | AQ13: =AM13*(1+AQ15) -> 265.92017 | AR13: =AN13*(1+AR15) -> 268.27395 | AS13: =AO13*(1+AS15) -> 275.96222 | AU13: =SUM(B13:E13) -> 132.873 | AV13: =SUM(F13:I13) -> 205.827 | AW13: =SUM(J13:M13) -> 290.549 | AX13: =SUM(N13:Q13) -> 377.354 | AY13: =SUM(R13:U13) -> 476.023 | AZ13: =SUM(V13:Y13) -> 612.51 | BA13: =SUM(Z13:AC13) -> 725.013 | BB13: =SUM(AD13:AG13) -> 824.659 | BC13: =SUM(AH13:AK13) -> 919.573 | BD13: =SUM(AL13:AO13) -> 995.23014 | BE13: =SUM(AP13:AS13) -> 1069.6212
A14: Consensus subscription revenue | B14: ='[2]VA Consensus'!C18 -> - | C14: ='[2]VA Consensus'!D18 -> - | D14: ='[2]VA Consensus'!E18 -> - | E14: ='[2]VA Consensus'!F18 -> - | F14: ='[2]VA Consensus'!G18 -> - | G14: ='[2]VA Consensus'!H18 -> - | H14: ='[2]VA Consensus'!I18 -> 55.628656 | I14: ='[2]VA Consensus'!J18 -> 61.298786 | ... AS14: ='[2]VA Consensus'!AT18 -> 275.49041 | AU14: ='[2]VA Consensus'!AV18 -> - | AV14: ='[2]VA Consensus'!AW18 -> 219.33527 | AW14: ='[2]VA Consensus'!AX18 -> 290.64225 | AX14: ='[2]VA Consensus'!AY18 -> 374.87473 | AY14: ='[2]VA Consensus'!AZ18 -> 471.94538 | AZ14: ='[2]VA Consensus'!BA18 -> 610.65686 | BA14: ='[2]VA Consensus'!BB18 -> 719.17729 | BB14: ='[2]VA Consensus'!BC18 -> 821.32236 | ... BE14: ='[2]VA Consensus'!BF18 -> 1067.1284
A15: Y/Y Growth | F15: =F13/B13-1 -> 0.60031767 | G15: =G13/C13-1 -> 0.57972377 | H15: =H13/D13-1 -> 0.5318619 | I15: =I13/E13-1 -> 0.50422642 | J15: =J13/F13-1 -> 0.460277 | K15: =K13/G13-1 -> 0.42370446 | L15: =L13/H13-1 -> 0.41098092 | M15: =M13/I13-1 -> 0.3658516 | ... AK15: =AK13/AG13-1 -> 0.10631125 | AL15: 0.095 | AM15: 0.085 | AN15: 0.075 | AO15: 0.075 | AP15: =+AO15-0.0001 -> 0.0749 | AQ15: =+AP15-0.0001 -> 0.0748 | AR15: =+AQ15-0.0001 -> 0.0747 | AS15: =+AR15-0.0001 -> 0.0746 | AU15: =IF(ISERROR(AU13/#REF!-1),"NA",AU13/#REF!-1) -> NA | AV15: =IF(ISERROR(AV13/AU13-1),"NA",AV13/AU13-1) -> 0.5490506 | AW15: =IF(ISERROR(AW13/AV13-1),"NA",AW13/AV13-1) -> 0.41161752 | AX15: =IF(ISERROR(AX13/AW13-1),"NA",AX13/AW13-1) -> 0.298762 | AY15: =IF(ISERROR(AY13/AX13-1),"NA",AY13/AX13-1) -> 0.26147596 | AZ15: =IF(ISERROR(AZ13/AY13-1),"NA",AZ13/AY13-1) -> 0.28672354 | BA15: =IF(ISERROR(BA13/AZ13-1),"NA",BA13/AZ13-1) -> 0.18367537 | BB15: =IF(ISERROR(BB13/BA13-1),"NA",BB13/BA13-1) -> 0.13744029 | BC15: =IF(ISERROR(BC13/BB13-1),"NA",BC13/BB13-1) -> 0.11509485 | ... BE15: =IF(ISERROR(BE13/BD13-1),"NA",BE13/BD13-1) -> 0.074747565
A16: % of total revenue | B16: =B13/B$5 -> 0.68432104 | C16: =C13/C$5 -> 0.69863417 | D16: =D13/D$5 -> 0.71318906 | E16: =E13/E$5 -> 0.72795979 | F16: =F13/F$5 -> 0.75002961 | G16: =G13/G$5 -> 0.76621273 | H16: =H13/H$5 -> 0.77060772 | I16: =I13/I$5 -> 0.78779862 | ... AS16: =AS13/AS$5 -> 0.93359379 | AU16: =AU13/AU$5 -> 0.70779909 | AV16: =AV13/AV$5 -> 0.76984964 | AW16: =AW13/AW$5 -> 0.81940347 | AX16: =AX13/AX$5 -> 0.85719218 | AY16: =AY13/AY$5 -> 0.87968326 | AZ16: =AZ13/AZ$5 -> 0.89654284 | BA16: =BA13/BA$5 -> 0.90772996 | BB16: =BB13/BB$5 -> 0.9162664 | ... BE16: =BE13/BE$5 -> 0.937762
A18: Perpetual License and Maintenance | B18: 11.989 | C18: =50.337-B18-D18-E18 -> 12.283 | D18: 12.857 | E18: 13.208 | F18: 13.477 | G18: 13.412 | H18: 13.864 | I18: 13.869 | J18: 13.527 | K18: 13.553 | L18: 13.797 | M18: 13.296 | N18: 13.419 | O18: 12.179 | P18: 12.448 | Q18: 12.548 | R18: 12.405 | S18: 12.567 | T18: 12.749 | U18: 12.612 | V18: 12.873 | W18: 12.683 | X18: 12.658 | Y18: 12.485 | Z18: 12.181 | AA18: 12.154 | AB18: 12.2 | AC18: 12.194 | AD18: 12.156 | AE18: 12.016 | AF18: 11.769 | AG18: 11.833 | AH18: 11.552 | AI18: 11.411 | AJ18: 11.088 | AK18: 10.61 | AL18: =AH18*(1+AL20) -> 10.3968 | AM18: =AI18*(1+AM20) -> 10.2699 | AN18: =AJ18*(1+AN20) -> 9.9792 | AO18: =AK18*(1+AO20) -> 9.549 | AP18: =AL18*(1+AP20) -> 9.35712 | AQ18: =AM18*(1+AQ20) -> 9.24291 | AR18: =AN18*(1+AR20) -> 8.98128 | AS18: =AO18*(1+AS20) -> 8.5941 | AU18: =SUM(B18:E18) -> 50.337 | AV18: =SUM(F18:I18) -> 54.622 | AW18: =SUM(J18:M18) -> 54.173 | AX18: =SUM(N18:Q18) -> 50.594 | AY18: =SUM(R18:U18) -> 50.333 | AZ18: =SUM(V18:Y18) -> 50.699 | BA18: =SUM(Z18:AC18) -> 48.729 | BB18: =SUM(AD18:AG18) -> 47.774 | BC18: =SUM(AH18:AK18) -> 44.661 | BD18: =SUM(AL18:AO18) -> 40.1949 | BE18: =SUM(AP18:AS18) -> 36.17541
A19: Consensus perpetual license and maintenance revenue | B19: ='[2]VA Consensus'!C19 -> - | C19: ='[2]VA Consensus'!D19 -> - | D19: ='[2]VA Consensus'!E19 -> - | E19: ='[2]VA Consensus'!F19 -> - | F19: ='[2]VA Consensus'!G19 -> - | G19: ='[2]VA Consensus'!H19 -> - | H19: ='[2]VA Consensus'!I19 -> 9.0917194 | I19: ='[2]VA Consensus'!J19 -> 9.7982908 | ... AS19: ='[2]VA Consensus'!AT19 -> 9.5120752 | AU19: ='[2]VA Consensus'!AV19 -> - | AV19: ='[2]VA Consensus'!AW19 -> 37.803338 | AW19: ='[2]VA Consensus'!AX19 -> 51.993046 | AX19: ='[2]VA Consensus'!AY19 -> 50.344036 | AY19: ='[2]VA Consensus'!AZ19 -> 50.28586 | AZ19: ='[2]VA Consensus'!BA19 -> 50.228755 | BA19: ='[2]VA Consensus'!BB19 -> 48.736255 | BB19: ='[2]VA Consensus'!BC19 -> 47.807977 | ... BE19: ='[2]VA Consensus'!BF19 -> 39.682475
A20: Y/Y Growth | F20: =F18/B18-1 -> 0.12411377 | G20: =G18/C18-1 -> 0.091915656 | H20: =H18/D18-1 -> 0.078323092 | I20: =I18/E18-1 -> 0.050045427 | J20: =J18/F18-1 -> 0.0037100245 | K20: =K18/G18-1 -> 0.010512973 | L20: =L18/H18-1 -> -0.0048326601 | M20: =M18/I18-1 -> -0.041315163 | ... AK20: =AK18/AG18-1 -> -0.10335502 | AL20: -0.1 | AM20: =AL20 -> -0.1 | AN20: =AM20 -> -0.1 | AO20: =AN20 -> -0.1 | AP20: =AO20 -> -0.1 | AQ20: =AP20 -> -0.1 | AR20: =AQ20 -> -0.1 | AS20: =AR20 -> -0.1 | AU20: =IF(ISERROR(AU18/#REF!-1),"NA",AU18/#REF!-1) -> NA | AV20: =IF(ISERROR(AV18/AU18-1),"NA",AV18/AU18-1) -> 0.085126249 | AW20: =IF(ISERROR(AW18/AV18-1),"NA",AW18/AV18-1) -> -0.0082201311 | AX20: =IF(ISERROR(AX18/AW18-1),"NA",AX18/AW18-1) -> -0.066066121 | AY20: =IF(ISERROR(AY18/AX18-1),"NA",AY18/AX18-1) -> -0.0051587145 | AZ20: =IF(ISERROR(AZ18/AY18-1),"NA",AZ18/AY18-1) -> 0.0072715713 | BA20: =IF(ISERROR(BA18/AZ18-1),"NA",BA18/AZ18-1) -> -0.038856782 | BB20: =IF(ISERROR(BB18/BA18-1),"NA",BB18/BA18-1) -> -0.019598186 | BC20: =IF(ISERROR(BC18/BB18-1),"NA",BC18/BB18-1) -> -0.065160966 | ... BE20: =IF(ISERROR(BE18/BD18-1),"NA",BE18/BD18-1) -> -0.1
A21: % of total revenue | B21: =B18/B$5 -> 0.29616363 | C21: =C18/C$5 -> 0.27821695 | D21: =D18/D$5 -> 0.2624949 | E21: =E18/E$5 -> 0.24406379 | F21: =F18/F$5 -> 0.22801022 | G21: =G18/G$5 -> 0.21090703 | H21: =H18/H$5 -> 0.19965438 | I21: =I18/I$5 -> 0.1843767 | ... AS21: =AS18/AS$5 -> 0.029074263 | AU21: =AU18/AU$5 -> 0.26813937 | AV21: =AV18/AV$5 -> 0.20430132 | AW21: =AW18/AW$5 -> 0.15277817 | AX21: =AX18/AX$5 -> 0.11492864 | AY21: =AY18/AY$5 -> 0.093014618 | AZ21: =AZ18/AZ$5 -> 0.074209116 | BA21: =BA18/BA$5 -> 0.061009628 | BB21: =BB18/BB$5 -> 0.053080984 | ... BE21: =BE18/BE$5 -> 0.031715832
A23: Professional Services and Other Revenue | B23: 0.79 | C23: =4.517-B23-D23-E23 -> 1.022 | D23: 1.191 | E23: 1.514 | F23: 1.298 | G23: 1.455 | H23: 2.065 | I23: 2.093 | J23: 2.037 | K23: 2.461 | L23: 2.552 | M23: 2.814 | N23: 2.839 | O23: 3.02 | P23: 3.042 | Q23: 3.372 | R23: 3.382 | S23: 3.525 | T23: 3.759 | U23: 4.108 | V23: 3.808 | W23: 4.852 | X23: 5.429 | Y23: 5.893 | Z23: 5.56 | AA23: 6.115 | AB23: 6.061 | AC23: 7.232 | AD23: 6.17 | AE23: 6.687 | AF23: 6.765 | AG23: 7.966 | AH23: 7.142 | AI23: 7.853 | AJ23: 9.141 | AK23: 11.035 | AL23: =AH23*(1+AL25) -> 6.7849 | AM23: =AI23*(1+AM25) -> 7.853 | AN23: =AJ23*(1+AN25) -> 9.141 | AO23: =AK23*(1+AO25) -> 11.035 | AP23: =AL23*(1+AP25) -> 6.7849 | AQ23: =AM23*(1+AQ25) -> 7.853 | AR23: =AN23*(1+AR25) -> 9.141 | AS23: =AO23*(1+AS25) -> 11.035 | AU23: =SUM(B23:E23) -> 4.517 | AV23: =SUM(F23:I23) -> 6.911 | AW23: =SUM(J23:M23) -> 9.864 | AX23: =SUM(N23:Q23) -> 12.273 | AY23: =SUM(R23:U23) -> 14.774 | AZ23: =SUM(V23:Y23) -> 19.982 | BA23: =SUM(Z23:AC23) -> 24.968 | BB23: =SUM(AD23:AG23) -> 27.588 | BC23: =SUM(AH23:AK23) -> 35.171 | BD23: =SUM(AL23:AO23) -> 34.8139 | BE23: =SUM(AP23:AS23) -> 34.8139
A24: Consensus professional services & other revenue | B24: ='[2]VA Consensus'!C20 -> - | C24: ='[2]VA Consensus'!D20 -> - | D24: ='[2]VA Consensus'!E20 -> - | E24: ='[2]VA Consensus'!F20 -> - | F24: ='[2]VA Consensus'!G20 -> - | G24: ='[2]VA Consensus'!H20 -> - | H24: ='[2]VA Consensus'!I20 -> 1.5606257 | I24: ='[2]VA Consensus'!J20 -> 1.8357154 | ... AS24: ='[2]VA Consensus'!AT20 -> 11.236806 | AU24: ='[2]VA Consensus'!AV20 -> - | AV24: ='[2]VA Consensus'!AW20 -> 6.6590402 | AW24: ='[2]VA Consensus'!AX20 -> 9.4087585 | AX24: ='[2]VA Consensus'!AY20 -> 11.959601 | AY24: ='[2]VA Consensus'!AZ20 -> 14.426971 | AZ24: ='[2]VA Consensus'!BA20 -> 19.264648 | BA24: ='[2]VA Consensus'!BB20 -> 24.049979 | BB24: ='[2]VA Consensus'!BC20 -> 26.584014 | ... BE24: ='[2]VA Consensus'!BF20 -> 38.210345
A25: Y/Y Growth | F25: =F23/B23-1 -> 0.64303797 | G25: =G23/C23-1 -> 0.42367906 | H25: =H23/D23-1 -> 0.73383711 | I25: =I23/E23-1 -> 0.38243065 | J25: =J23/F23-1 -> 0.56933744 | K25: =K23/G23-1 -> 0.69140893 | L25: =L23/H23-1 -> 0.23583535 | M25: =M23/I23-1 -> 0.34448161 | ... AK25: =AK23/AG23-1 -> 0.38526237 | AL25: -0.05 | AM25: 0 | AN25: 0 | AO25: 0 | AP25: 0 | AQ25: 0 | AR25: 0 | AS25: 0 | AU25: =IF(ISERROR(AU23/#REF!-1),"NA",AU23/#REF!-1) -> NA | AV25: =IF(ISERROR(AV23/AU23-1),"NA",AV23/AU23-1) -> 0.52999779 | AW25: =IF(ISERROR(AW23/AV23-1),"NA",AW23/AV23-1) -> 0.42728983 | AX25: =IF(ISERROR(AX23/AW23-1),"NA",AX23/AW23-1) -> 0.24422141 | AY25: =IF(ISERROR(AY23/AX23-1),"NA",AY23/AX23-1) -> 0.20378066 | AZ25: =IF(ISERROR(AZ23/AY23-1),"NA",AZ23/AY23-1) -> 0.35251117 | BA25: =IF(ISERROR(BA23/AZ23-1),"NA",BA23/AZ23-1) -> 0.24952457 | BB25: =IF(ISERROR(BB23/BA23-1),"NA",BB23/BA23-1) -> 0.10493432 | BC25: =IF(ISERROR(BC23/BB23-1),"NA",BC23/BB23-1) -> 0.27486588 | ... BE25: =IF(ISERROR(BE23/BD23-1),"NA",BE23/BD23-1) -> 0
A26: % of total revenue | B26: =B23/B$5 -> 0.019515328 | C26: =C23/C$5 -> 0.023148882 | D26: =D23/D$5 -> 0.024316047 | E26: =E23/E$5 -> 0.027976421 | F26: =F23/F$5 -> 0.021960174 | G26: =G23/G$5 -> 0.022880237 | H26: =H23/H$5 -> 0.029737903 | I26: =I23/I$5 -> 0.027824677 | ... AS26: =AS23/AS$5 -> 0.037331948 | AU26: =AU23/AU$5 -> 0.024061536 | AV26: =AV23/AV$5 -> 0.025849042 | AW26: =AW23/AW$5 -> 0.027818357 | AX26: =AX23/AX$5 -> 0.027879179 | AY26: =AY23/AY$5 -> 0.027302127 | AZ26: =AZ23/AZ$5 -> 0.029248043 | BA26: =BA23/BA$5 -> 0.031260407 | BB26: =BB23/BB$5 -> 0.030652618 | ... BE26: =BE23/BE$5 -> 0.030522164
B28: ='Income Statement'!B$3 -> 2017 | F28: ='Income Statement'!F$3 -> 2018 | J28: ='Income Statement'!J$3 -> 2019 | N28: ='Income Statement'!N$3 -> 2020 | R28: ='Income Statement'!R$3 -> 2021 | V28: ='Income Statement'!V$3 -> 2022 | Z28: ='Income Statement'!Z$3 -> 2023 | AD28: ='Income Statement'!AD$3 -> 2024 | AH28: ='Income Statement'!AH$3 -> 2025 | AL28: ='Income Statement'!AL$3 -> 2026 | AP28: ='Income Statement'!AP$3 -> 2027
A29: Billings & Bookings | B29: ='Income Statement'!B$4 -> 42825 | C29: ='Income Statement'!C$4 -> 42916 | D29: ='Income Statement'!D$4 -> 43008 | E29: ='Income Statement'!E$4 -> 43100 | F29: ='Income Statement'!F$4 -> 43190 | G29: ='Income Statement'!G$4 -> 43281 | H29: ='Income Statement'!H$4 -> 43373 | I29: ='Income Statement'!I$4 -> 43465 | ... AS29: ='Income Statement'!AS$4 -> Dec-27E | AU29: ='Income Statement'!AU$4 -> 2017 | AV29: ='Income Statement'!AV$4 -> 2018 | AW29: ='Income Statement'!AW$4 -> 2019 | AX29: ='Income Statement'!AX$4 -> 2020 | AY29: ='Income Statement'!AY$4 -> CY21 | AZ29: ='Income Statement'!AZ$4 -> CY22 | BA29: ='Income Statement'!BA$4 -> CY23 | BB29: ='Income Statement'!BB$4 -> CY24 | ... BE29: ='Income Statement'!BE$4 -> CY27E
A30: Revenue | B30: =B5 -> 40.481 | C30: =C5 -> 44.149 | D30: =D5 -> 48.98 | E30: =E5 -> 54.117 | F30: =F5 -> 59.107 | G30: =G5 -> 63.592 | H30: =H5 -> 69.44 | I30: =I5 -> 75.221 | ... AS30: =AS5 -> 295.59132 | AU30: =SUM(B30:E30) -> 187.727 | AV30: =SUM(F30:I30) -> 267.36 | AW30: =SUM(J30:M30) -> 354.586 | AX30: =SUM(N30:Q30) -> 440.221 | AY30: =SUM(R30:U30) -> 541.13 | AZ30: =SUM(V30:Y30) -> 683.191 | BA30: =SUM(Z30:AC30) -> 798.71 | BB30: =SUM(AD30:AG30) -> 900.021 | BC30: =SUM(AH30:AK30) -> 999.405 | BD30: =SUM(AL30:AO30) -> 1070.2389 | BE30: =SUM(AP30:AS30) -> 1140.6105
A31: Beginning deferred revenue balance | E31: 107.447 | F31: =E32 -> 225.818 | G31: =F32 -> 230.614 | H31: =G32 -> 247.137 | I31: =H32 -> 265.698 | J31: =I32 -> 289.903 | K31: =J32 -> 291.905 | L31: =K32 -> 307.333 | M31: =L32 -> 329.375 | ... AS31: =AR32 -> 942.84624 | AU31: =SUM(B31:E31) -> 107.447 | AV31: =SUM(F31:I31) -> 969.267 | AW31: =SUM(J31:M31) -> 1218.516 | AX31: =SUM(N31:Q31) -> 1476.729 | AY31: =SUM(R31:U31) -> 1785.203 | AZ31: =SUM(V31:Y31) -> 2200.16 | BA31: =SUM(Z31:AC31) -> 2638.322 | BB31: =SUM(AD31:AG31) -> 2946.455 | BC31: =SUM(AH31:AK31) -> 3249.874 | BD31: =SUM(AL31:AO31) -> 3507.4433 | BE31: =SUM(AP31:AS31) -> 3780.9609
A32: Ending deferred revenue balance | E32: ='Balance Sheet'!E25+'Balance Sheet'!E32 -> 225.818 | F32: ='Balance Sheet'!F25+'Balance Sheet'!F32 -> 230.614 | G32: ='Balance Sheet'!G25+'Balance Sheet'!G32 -> 247.137 | H32: ='Balance Sheet'!H25+'Balance Sheet'!H32 -> 265.698 | I32: ='Balance Sheet'!I25+'Balance Sheet'!I32 -> 289.903 | J32: ='Balance Sheet'!J25+'Balance Sheet'!J32 -> 291.905 | K32: ='Balance Sheet'!K25+'Balance Sheet'!K32 -> 307.333 | L32: ='Balance Sheet'!L25+'Balance Sheet'!L32 -> 329.375 | ... AK32: ='Balance Sheet'!AK25+'Balance Sheet'!AK32 -> 899.276 | AL32: =AL31+AL33 -> 872.44803 | AM32: =AM31+AM33 -> 861.10264 | AN32: =AN31+AN33 -> 874.61664 | AO32: =AO31+AO33 -> 969.13296 | AP32: =AP31+AP33 -> 940.53697 | AQ32: =AQ31+AQ33 -> 928.44474 | AR32: =AR31+AR33 -> 942.84624 | AS32: =AS31+AS33 -> 1043.5649 | AU32: =SUM(B32:E32) -> 225.818 | AV32: =SUM(F32:I32) -> 1033.352 | AW32: =SUM(J32:M32) -> 1291.74 | AX32: =SUM(N32:Q32) -> 1548.112 | AY32: =SUM(R32:U32) -> 1881.578 | AZ32: =SUM(V32:Y32) -> 2333.877 | BA32: =SUM(Z32:AC32) -> 2724.217 | BB32: =SUM(AD32:AG32) -> 3029.145 | BC32: =SUM(AH32:AK32) -> 3315.963 | BD32: =SUM(AL32:AO32) -> 3577.3003 | BE32: =SUM(AP32:AS32) -> 3855.3928
A33: Change in deferred revenue | E33: =E32-E31 -> 118.371 | F33: =F32-F31 -> 4.796 | G33: =G32-G31 -> 16.523 | H33: =H32-H31 -> 18.561 | I33: =I32-I31 -> 24.205 | J33: =J32-J31 -> 2.002 | K33: =K32-K31 -> 15.428 | L33: =L32-L31 -> 22.042 | ... AK33: =AK32-AK31 -> 88.773 | AL33: =AL34-AL30 -> -26.827965 | AM33: =AM34-AM30 -> -11.345393 | AN33: =AN34-AN30 -> 13.514002 | AO33: =AO34-AO30 -> 94.516312 | AP33: =AP34-AP30 -> -28.595981 | AQ33: =AQ34-AQ30 -> -12.09223 | AR33: =AR34-AR30 -> 14.401496 | AS33: =AS34-AS30 -> 100.71864 | AU33: =SUM(B33:E33) -> 118.371 | AV33: =SUM(F33:I33) -> 64.085 | AW33: =SUM(J33:M33) -> 73.224 | AX33: =SUM(N33:Q33) -> 71.383 | AY33: =SUM(R33:U33) -> 96.375 | AZ33: =SUM(V33:Y33) -> 133.717 | BA33: =SUM(Z33:AC33) -> 85.895 | BB33: =SUM(AD33:AG33) -> 82.69 | BC33: =SUM(AH33:AK33) -> 66.089 | BD33: =SUM(AL33:AO33) -> 69.856956 | BE33: =SUM(AP33:AS33) -> 74.431922
A34: Total Billings | F34: =F30+F33 -> 63.903 | G34: =G30+G33 -> 80.115 | H34: =H30+H33 -> 88.001 | I34: =I30+I33 -> 99.426 | J34: =J30+J33 -> 82.303 | K34: =K30+K33 -> 100.812 | L34: =L30+L33 -> 113.894 | M34: =M30+M33 -> 130.801 | ... AK34: =AK30+AK33 -> 349.306 | AL34: =AH34*(1+AL35) -> 231.73882 | AM34: =AI34*(1+AM35) -> 254.19114 | AN34: =AJ34*(1+AN35) -> 282.26103 | AO34: =AK34*(1+AO35) -> 371.90491 | AP34: =AL34*(1+AP35) -> 247.01087 | AQ34: =AM34*(1+AQ35) -> 270.92386 | AR34: =AN34*(1+AR35) -> 300.79773 | AS34: =AO34*(1+AS35) -> 396.30996 | AU34: =SUM(B34:E34) -> 0 | AV34: =SUM(F34:I34) -> 331.445 | AW34: =SUM(J34:M34) -> 427.81 | AX34: =SUM(N34:Q34) -> 511.604 | AY34: =SUM(R34:U34) -> 637.505 | AZ34: =SUM(V34:Y34) -> 816.908 | BA34: =SUM(Z34:AC34) -> 884.605 | BB34: =SUM(AD34:AG34) -> 982.711 | BC34: =SUM(AH34:AK34) -> 1065.494 | BD34: =SUM(AL34:AO34) -> 1140.0959 | BE34: =SUM(AP34:AS34) -> 1215.0424
A35: Y/Y Growth | J35: =J34/F34-1 -> 0.2879364 | K35: =K34/G34-1 -> 0.25834113 | L35: =L34/H34-1 -> 0.29423529 | M35: =M34/I34-1 -> 0.31556132 | N35: =N34/J34-1 -> 0.1860078 | O35: =O34/K34-1 -> 0.13505337 | P35: =P34/L34-1 -> 0.20440936 | Q35: =Q34/M34-1 -> 0.24150427 | ... AK35: =AK34/AG34-1 -> 0.086603249 | AL35: =+AL7 -> 0.081249598 | AM35: =+AM7 -> 0.073764269 | AN35: =+AN7 -> 0.064597627 | AO35: =+AO7 -> 0.064696603 | AP35: =+AP7 -> 0.065901979 | AQ35: =+AQ7 -> 0.065827288 | AR35: =+AR7 -> 0.065672183 | AS35: =+AS7 -> 0.065621742 | AV35: =IF(ISERROR(AV34/AU34-1),"NA",AV34/AU34-1) -> NA | AW35: =IF(ISERROR(AW34/AV34-1),"NA",AW34/AV34-1) -> 0.29074205 | AX35: =IF(ISERROR(AX34/AW34-1),"NA",AX34/AW34-1) -> 0.19586732 | AY35: =IF(ISERROR(AY34/AX34-1),"NA",AY34/AX34-1) -> 0.24609073 | AZ35: =IF(ISERROR(AZ34/AY34-1),"NA",AZ34/AY34-1) -> 0.28141426 | BA35: =IF(ISERROR(BA34/AZ34-1),"NA",BA34/AZ34-1) -> 0.082869797 | BB35: =IF(ISERROR(BB34/BA34-1),"NA",BB34/BA34-1) -> 0.11090374 | BC35: =IF(ISERROR(BC34/BB34-1),"NA",BC34/BB34-1) -> 0.084239415 | ... BE35: =IF(ISERROR(BE34/BD34-1),"NA",BE34/BD34-1) -> 0.065737019
A37: Revenue | B37: =B30 -> 40.481 | C37: =C30 -> 44.149 | D37: =D30 -> 48.98 | E37: =E30 -> 54.117 | F37: =F30 -> 59.107 | G37: =G30 -> 63.592 | H37: =H30 -> 69.44 | I37: =I30 -> 75.221 | ... AS37: =AS30 -> 295.59132 | AV37: =SUM(F37:I37) -> 267.36 | AW37: =SUM(J37:M37) -> 354.586 | AX37: =SUM(N37:Q37) -> 440.221 | AY37: =SUM(R37:U37) -> 541.13 | AZ37: =SUM(V37:Y37) -> 683.191 | BA37: =SUM(Z37:AC37) -> 798.71 | BB37: =SUM(AD37:AG37) -> 900.021 | BC37: =SUM(AH37:AK37) -> 999.405 | BD37: =SUM(AL37:AO37) -> 1070.2389 | BE37: =SUM(AP37:AS37) -> 1140.6105
A38: Beginning deferred revenue (current) balance | F38: =E39 -> 154.898 | G38: =F39 -> 160.503 | H38: =G39 -> 174.277 | I38: =H39 -> 191.578 | J38: =I39 -> 213.644 | K38: =J39 -> 214.508 | L38: =K39 -> 227.227 | M38: =L39 -> 245.985 | ... U38: =T39 -> 362.308 | V38: =U39+0.137 -> 407.635 | W38: =V39+0.808 -> 405.594 | X38: =W39 -> 415.378 | Y38: =X39 -> 447.863 | Z38: =Y39 -> 502.115 | AA38: =Z39 -> 490.076 | AB38: =AA39 -> 495.199 | AC38: =AB39+4.1 -> 522.472 | AD38: =AC39 -> 580.779 | AE38: =AD39 -> 562.575 | AF38: =AE39 -> 562.587 | AG38: =AF39 -> 583.94 | AH38: =AG39+6.629 -> 657.001 | AI38: =AH39 -> 633.224 | AJ38: =AI39 -> 624.548 | AK38: =AJ39 -> 639.614 | AL38: =AK39 -> 706.866 | AM38: =AL39 -> 685.77817 | AN38: =AM39 -> 676.86025 | AO38: =AN39 -> 687.48278 | AP38: =AO39 -> 761.77629 | ... AS38: =AR39 -> 741.11391 | AV38: =SUM(F38:I38) -> 681.256 | AW38: =SUM(J38:M38) -> 901.364 | AX38: =SUM(N38:Q38) -> 1116.577 | AY38: =SUM(R38:U38) -> 1350.346 | AZ38: =SUM(V38:Y38) -> 1676.47 | BA38: =SUM(Z38:AC38) -> 2009.862 | BB38: =SUM(AD38:AG38) -> 2289.881 | BC38: =SUM(AH38:AK38) -> 2554.387 | BD38: =SUM(AL38:AO38) -> 2756.9872 | BE38: =SUM(AP38:AS38) -> 2971.9827
A39: Ending deferred revenue (current) balance | E39: ='Balance Sheet'!E25 -> 154.898 | F39: ='Balance Sheet'!F25 -> 160.503 | G39: ='Balance Sheet'!G25 -> 174.277 | H39: ='Balance Sheet'!H25 -> 191.578 | I39: ='Balance Sheet'!I25 -> 213.644 | J39: ='Balance Sheet'!J25 -> 214.508 | K39: ='Balance Sheet'!K25 -> 227.227 | L39: ='Balance Sheet'!L25 -> 245.985 | ... AS39: ='Balance Sheet'!AS25 -> 820.28268 | AV39: =SUM(F39:I39) -> 740.002 | AW39: =SUM(J39:M39) -> 962.068 | AX39: =SUM(N39:Q39) -> 1171.048 | AY39: =SUM(R39:U39) -> 1429.025 | AZ39: =SUM(V39:Y39) -> 1770.142 | BA39: =SUM(Z39:AC39) -> 2084.426 | BB39: =SUM(AD39:AG39) -> 2359.474 | BC39: =SUM(AH39:AK39) -> 2604.252 | BD39: =SUM(AL39:AO39) -> 2811.8975 | BE39: =SUM(AP39:AS39) -> 3030.4891
A40: Change in deferred revenue (current) | F40: =F39-F38 -> 5.605 | G40: =G39-G38 -> 13.774 | H40: =H39-H38 -> 17.301 | I40: =I39-I38 -> 22.066 | J40: =J39-J38 -> 0.864 | K40: =K39-K38 -> 12.719 | L40: =L39-L38 -> 18.758 | M40: =M39-M38 -> 28.363 | ... AS40: =AS39-AS38 -> 79.168775 | AV40: =SUM(F40:I40) -> 58.746 | AW40: =SUM(J40:M40) -> 60.704 | AX40: =SUM(N40:Q40) -> 54.471 | AY40: =SUM(R40:U40) -> 78.679 | AZ40: =SUM(V40:Y40) -> 93.672 | BA40: =SUM(Z40:AC40) -> 74.564 | BB40: =SUM(AD40:AG40) -> 69.593 | BC40: =SUM(AH40:AK40) -> 49.865 | BD40: =SUM(AL40:AO40) -> 54.910291 | BE40: =SUM(AP40:AS40) -> 58.506393
A41: Current Billings | F41: =F37+F40 -> 64.712 | G41: =G37+G40 -> 77.366 | H41: =H37+H40 -> 86.741 | I41: =I37+I40 -> 97.287 | J41: =J37+J40 -> 81.165 | K41: =K37+K40 -> 98.103 | L41: =L37+L40 -> 110.61 | M41: =M37+M40 -> 125.412 | ... AS41: =AS37+AS40 -> 374.7601 | AV41: =SUM(F41:I41) -> 326.106 | AW41: =SUM(J41:M41) -> 415.29 | AX41: =SUM(N41:Q41) -> 494.692 | AY41: =SUM(R41:U41) -> 619.809 | AZ41: =SUM(V41:Y41) -> 776.863 | BA41: =SUM(Z41:AC41) -> 873.274 | BB41: =SUM(AD41:AG41) -> 969.614 | BC41: =SUM(AH41:AK41) -> 1049.27 | BD41: =SUM(AL41:AO41) -> 1125.1492 | BE41: =SUM(AP41:AS41) -> 1199.1169
A42: Consensus Current Billings | B42: ='[2]VA Consensus'!C13 -> - | C42: ='[2]VA Consensus'!D13 -> - | D42: ='[2]VA Consensus'!E13 -> - | E42: ='[2]VA Consensus'!F13 -> - | F42: ='[2]VA Consensus'!G13 -> - | G42: ='[2]VA Consensus'!H13 -> - | H42: ='[2]VA Consensus'!I13 -> 80.923611 | I42: ='[2]VA Consensus'!J13 -> 93.35714 | ... AS42: ='[2]VA Consensus'!AT13 -> 370.09809 | AU42: ='[2]VA Consensus'!AV13 -> - | AV42: ='[2]VA Consensus'!AW13 -> 322.17613 | AW42: ='[2]VA Consensus'!AX13 -> 412.84391 | AX42: ='[2]VA Consensus'!AY13 -> 487.68591 | AY42: ='[2]VA Consensus'!AZ13 -> 604.67528 | AZ42: ='[2]VA Consensus'!BA13 -> 773.56192 | BA42: ='[2]VA Consensus'!BB13 -> 865.96706 | BB42: ='[2]VA Consensus'!BC13 -> 962.40681 | ... BE42: ='[2]VA Consensus'!BF13 -> 1209.507
A43: Y/Y Growth | J43: =J41/F41-1 -> 0.2542496 | K43: =K41/G41-1 -> 0.26803764 | L43: =L41/H41-1 -> 0.27517552 | M43: =M41/I41-1 -> 0.2890931 | N43: =N41/J41-1 -> 0.22239882 | O43: =O41/K41-1 -> 0.13397144 | P43: =P41/L41-1 -> 0.20865202 | Q43: =Q41/M41-1 -> 0.20037158 | ... AS43: =AS41/AO41-1 -> 0.065621742 | AW43: =AW41/AV41-1 -> 0.27348163 | AX43: =AX41/AW41-1 -> 0.19119651 | AY43: =AY41/AX41-1 -> 0.25291899 | AZ43: =AZ41/AY41-1 -> 0.25339096 | BA43: =BA41/AZ41-1 -> 0.12410296 | BB43: =BB41/BA41-1 -> 0.11032047 | BC43: =BC41/BB41-1 -> 0.082152279 | BD43: =BD41/BC41-1 -> 0.072316216 | BE43: =BE41/BD41-1 -> 0.065740294
A44: Management Guidance - Current Billings
...

Sheet Balance Sheet
A1: =+'Income Statement'!A1 -> Tenable Holdings, Inc. (TENB)
A2: Balance Sheet | AU2: =+'Income Statement'!AU2 -> 2017 | AV2: =+'Income Statement'!AV2 -> 2018 | AW2: =+'Income Statement'!AW2 -> 2019 | AX2: =+'Income Statement'!AX2 -> 2020 | AY2: =+'Income Statement'!AY2 -> 2021 | AZ2: =+'Income Statement'!AZ2 -> 2022 | BA2: =+'Income Statement'!BA2 -> 2023 | BB2: =+'Income Statement'!BB2 -> 2024 | ... BE2: =+'Income Statement'!BE2 -> 2027
B3: ='Income Statement'!B$3 -> 2017 | F3: ='Income Statement'!F$3 -> 2018 | J3: ='Income Statement'!J$3 -> 2019 | N3: ='Income Statement'!N$3 -> 2020 | R3: ='Income Statement'!R$3 -> 2021 | V3: ='Income Statement'!V$3 -> 2022 | Z3: ='Income Statement'!Z$3 -> 2023 | AD3: ='Income Statement'!AD$3 -> 2024 | AH3: ='Income Statement'!AH$3 -> 2025 | AL3: ='Income Statement'!AL$3 -> 2026 | AP3: ='Income Statement'!AP$3 -> 2027
A4: ='Income Statement'!A4 -> ($ in millions, unless otherwise stated) | B4: ='Income Statement'!B$4 -> 42825 | C4: ='Income Statement'!C$4 -> 42916 | D4: ='Income Statement'!D$4 -> 43008 | E4: ='Income Statement'!E$4 -> 43100 | F4: ='Income Statement'!F$4 -> 43190 | G4: ='Income Statement'!G$4 -> 43281 | H4: ='Income Statement'!H$4 -> 43373 | I4: ='Income Statement'!I$4 -> 43465 | ... AS4: ='Income Statement'!AS$4 -> Dec-27E | AU4: ='Income Statement'!AU$4 -> 2017 | AV4: ='Income Statement'!AV$4 -> 2018 | AW4: ='Income Statement'!AW$4 -> 2019 | AX4: ='Income Statement'!AX$4 -> 2020 | AY4: ='Income Statement'!AY$4 -> CY21 | AZ4: ='Income Statement'!AZ$4 -> CY22 | BA4: ='Income Statement'!BA$4 -> CY23 | BB4: ='Income Statement'!BB$4 -> CY24 | ... BE4: ='Income Statement'!BE$4 -> CY27E
A5: Current assets
