Workbook
Name ___eps95: #REF!
Name ___eps95: #REF!
Name ___eps95: #REF!
Name ___eps95: #REF!
Name ___eps95: #REF!
Name ___eps95: #REF!
Name ___eps95: #REF!
Name ___eps96: #REF!
Name ___eps96: #REF!
Name ___eps96: #REF!
Name ___eps96: #REF!
Name ___eps96: #REF!
Name ___eps96: #REF!
Name ___eps96: #REF!
Name ___eps97: #REF!
Name ___eps97: #REF!
Name ___eps97: #REF!
Name ___eps97: #REF!
Name ___eps97: #REF!
Name ___eps97: #REF!
Name ___eps97: #REF!
Name ___eps98: #REF!
Name ___eps98: #REF!
Name ___eps98: #REF!
Name ___eps98: #REF!
Name ___fcc97: #REF!
Name ___fcc97: #REF!
Name ___fcc97: #REF!
Name ___fcc97: #REF!
Name ___grm98: #REF!
Name ___grm98: #REF!
Name ___grm98: #REF!
Name ___grm98: #REF!
Name ___grm99: #REF!
Name ___grm99: #REF!
Name ___grm99: #REF!
Name ___grm99: #REF!
Name ___net96: #REF!
Name ___net96: #REF!
Name ___net96: #REF!
Name ___net96: #REF!
Name ___net97: #REF!
Name ___net97: #REF!
Name ___net97: #REF!
Name ___net97: #REF!
Name ___net98: #REF!
Name ___net98: #REF!
Name ___net98: #REF!
Name ___net98: #REF!
Name ___net99: #REF!
Name ___net99: #REF!
Name ___net99: #REF!
Name ___net99: #REF!
Name ___opm98: #REF!
Name ___opm98: #REF!
Name ___opm98: #REF!
Name ___opm98: #REF!
Name ___opm99: #REF!
Name ___opm99: #REF!
Name ___opm99: #REF!

Sheet __FDSCACHE__
B1: This sheet contains FactSet XML data for use with this workbook's =FDS codes. Modifying the worksheet's contents may damage the workbook's =FDS functionality.

Sheet BM Upload
A1: ALL FISCAL DATA MUST BE ENTERED IN MILLION (INCLUDING NUMBER OF SHARE) | CD1: NULL:FISCAL
A2: ALL PER SHARE DATA MUST BE IN UNIT | CD2: ADJUSTED:FISCAL
A3: DATA MUST BE ENTERED IN THE CURRENCY OF THE COMPANY | CD3: BASIC:FISCAL
A4: Click here to find a list of BlueMatrix Client Codes | CD4: DILUTED:FISCAL
CB5: Strong Buy | CD5: GAAP:FISCAL
CB6: Buy | CD6: INDICATED:FISCAL
CB7: Hold | CD7: MANAGED:FISCAL
CB8: Under Perform | CD8: NON-GAAP:FISCAL
A9: Company name | C9: Qualys | CB9: Rating Suspended | CD9: OPERATING:FISCAL
A10: Rating | B10: RATING | C10: Hold | D10: =_xll.BLUEMATRIX2("/servlet/excelData",C10, $C$14,$B10) -> #NAME? | CB10: Restricted | CD10: PRIMARY:FISCAL
A11: Currency | C11: USD | CB11: Under Review | CD11: PROFORMA:FISCAL
CB12: Sell | CD12: RESTATED:FISCAL
A13: 12-Month Price Target | B13: TARGET_PRICE | C13: NA | D13: =_xll.BLUEMATRIX2("/servlet/excelData",C13, $C$14,$B13) -> #NAME? | CD13: REVENUE:FISCAL
A14: Ticker | C14: QLYS | AB14: E | CB14: A | CC14: E | CD14: NULL:CALENDAR
CB15: E | CC15: A | CD15: ADJUSTED:CALENDAR
D16: =$B$17-3 -> 2013 | E16: =$B$17-3 -> 2013 | F16: =$B$17-3 -> 2013 | G16: =$B$17-3 -> 2013 | H16: =$B$17-3 -> 2013 | I16: =$B$17-2 -> 2014 | J16: =$B$17-2 -> 2014 | K16: =$B$17-2 -> 2014 | L16: =$B$17-2 -> 2014 | M16: =$B$17-2 -> 2014 | N16: =$B$17-1 -> 2015 | O16: =$B$17-1 -> 2015 | P16: =$B$17-1 -> 2015 | Q16: =$B$17-1 -> 2015 | R16: =$B$17-1 -> 2015 | S16: =$B$17-0 -> 2016 | T16: =$B$17-0 -> 2016 | U16: =$B$17-0 -> 2016 | V16: =$B$17-0 -> 2016 | W16: =$B$17-0 -> 2016 | X16: =$B$17+1 -> 2017 | Y16: =$B$17+1 -> 2017 | Z16: =$B$17+1 -> 2017 | AA16: =$B$17+1 -> 2017 | AB16: =$B$17+1 -> 2017 | AC16: =$B$17+2 -> 2018 | AD16: =$B$17+2 -> 2018 | AE16: =$B$17+2 -> 2018 | AF16: =$B$17+2 -> 2018 | AG16: =$B$17+2 -> 2018 | AH16: =$B$17+3 -> 2019 | AI16: =$B$17+3 -> 2019 | AJ16: =$B$17+3 -> 2019 | AK16: =$B$17+3 -> 2019 | AL16: =$B$17+3 -> 2019 | AM16: =$B$17+4 -> 2020 | AN16: =$B$17+4 -> 2020 | AO16: =$B$17+4 -> 2020 | AP16: =$B$17+4 -> 2020 | AQ16: =$B$17+4 -> 2020 | AR16: =$B$17+5 -> 2021 | AS16: =$B$17+5 -> 2021 | AT16: =$B$17+5 -> 2021 | AU16: =$B$17+5 -> 2021 | AV16: =$B$17+5 -> 2021 | AW16: =$B$17+6 -> 2022 | AX16: =$B$17+6 -> 2022 | AY16: =$B$17+6 -> 2022 | AZ16: =$B$17+6 -> 2022 | BA16: =$B$17+6 -> 2022 | BB16: =$B$17+7 -> 2023 | BC16: =$B$17+7 -> 2023 | BD16: =$B$17+7 -> 2023 | BE16: =$B$17+7 -> 2023 | BF16: =$B$17+7 -> 2023 | BG16: 2024 | BH16: 2024 | BI16: 2024 | BJ16: 2024 | BK16: 2024 | BL16: =BG16+1 -> 2025 | BM16: =BH16+1 -> 2025 | BN16: =BI16+1 -> 2025 | BO16: =BJ16+1 -> 2025 | BP16: =BK16+1 -> 2025 | BQ16: =BL16+1 -> 2026 | BR16: =BM16+1 -> 2026 | BS16: =BN16+1 -> 2026 | ... BZ16: =BU16+1 -> 2027
A17: Current Year (Matching What Selected From Drop-down Bars - ie. Fiscal or Calendar) | B17: 2016 | D17: A | E17: A | F17: A | G17: A | H17: A | I17: A | J17: A | K17: A | L17: A | M17: A | N17: A | O17: A | P17: A | Q17: A | R17: A | S17: A | T17: A | U17: A | V17: A | W17: A | X17: A | Y17: A | Z17: A | AA17: A | AB17: A | AC17: A | AD17: A | AE17: A | AF17: A | AG17: A | AH17: A | AI17: A | AJ17: A | AK17: A | AL17: =+AK17 -> A | AM17: A | AN17: A | AO17: A | AP17: A | AQ17: =+AP17 -> A | AR17: A | AS17: A | AT17: A | AU17: A | AV17: =+AU17 -> A | AW17: A | AX17: A | AY17: A | AZ17: A | BA17: =+AZ17 -> A | BB17: A | BC17: A | BD17: A | BE17: A | BF17: =+BE17 -> A | BG17: =+BF17 -> A | BH17: A | BI17: A | BJ17: A | BK17: =+BJ17 -> A | BL17: A | BM17: A | BN17: A | BO17: A | BP17: =+BO17 -> A | BQ17: E | BR17: E | BS17: E | BT17: E | BU17: =+BT17 -> E | BV17: E | BW17: E | BX17: E | BY17: E | BZ17: =+BY17 -> E
A18: Current Base Quarter (NOT one just reported - One After That) | B18: Q2 | D18: =D16&D19 -> 2013Q1 | E18: =E16&E19 -> 2013Q2 | F18: =F16&F19 -> 2013Q3 | G18: =G16&G19 -> 2013Q4 | H18: =H16 -> 2013 | I18: =I16&I19&I17 -> 2014Q1A | J18: =J16&J19&J17 -> 2014Q2A | K18: =K16&K19&K17 -> 2014Q3A | L18: =L16&L19&L17 -> 2014Q4A | M18: =M16&M17 -> 2014A | N18: =N16&N19&N17 -> 2015Q1A | O18: =O16&O19&O17 -> 2015Q2A | P18: =P16&P19&P17 -> 2015Q3A | Q18: =Q16&Q19&Q17 -> 2015Q4A | R18: =R16&R17 -> 2015A | S18: =S16&S19&S17 -> 2016Q1A | T18: =T16&T19&T17 -> 2016Q2A | U18: =U16&U19&U17 -> 2016Q3A | V18: =V16&V19&V17 -> 2016Q4A | W18: =W16&W17 -> 2016A | X18: =X16&X19&X17 -> 2017Q1A | Y18: =Y16&Y19&Y17 -> 2017Q2A | Z18: =Z16&Z19&Z17 -> 2017Q3A | AA18: =AA16&AA19&AA17 -> 2017Q4A | AB18: =AB16&AB17 -> 2017A | AC18: =AC16&AC19&AC17 -> 2018Q1A | AD18: =AD16&AD19&AD17 -> 2018Q2A | AE18: =AE16&AE19&AE17 -> 2018Q3A | AF18: =AF16&AF19&AF17 -> 2018Q4A | AG18: =AG16&AG17 -> 2018A | AH18: =AH16&AH19&AH17 -> 2019Q1A | AI18: =AI16&AI19&AI17 -> 2019Q2A | AJ18: =AJ16&AJ19&AJ17 -> 2019Q3A | AK18: =AK16&AK19&AK17 -> 2019Q4A | AL18: =AL16&AL17 -> 2019A | AM18: =AM16&AM19&AM17 -> 2020Q1A | AN18: =AN16&AN19&AN17 -> 2020Q2A | AO18: =AO16&AO19&AO17 -> 2020Q3A | AP18: =AP16&AP19&AP17 -> 2020Q4A | AQ18: =AQ16&AQ17 -> 2020A | AR18: =AR16&AR19&AR17 -> 2021Q1A | AS18: =AS16&AS19&AS17 -> 2021Q2A | AT18: =AT16&AT19&AT17 -> 2021Q3A | AU18: =AU16&AU19&AU17 -> 2021Q4A | AV18: =AV16&AV17 -> 2021A | AW18: =AW16&AW19&AW17 -> 2022Q1A | AX18: =AX16&AX19&AX17 -> 2022Q2A | AY18: =AY16&AY19&AY17 -> 2022Q3A | AZ18: =AZ16&AZ19&AZ17 -> 2022Q4A | BA18: =BA16&BA17 -> 2022A | BB18: =BB16&BB19&BB17 -> 2023Q1A | BC18: =BC16&BC19&BC17 -> 2023Q2A | BD18: =BD16&BD19&BD17 -> 2023Q3A | BE18: =BE16&BE19&BE17 -> 2023Q4A | BF18: =BF16&BF17 -> 2023A | BG18: =BG16&BG19&BG17 -> 2024Q1A | BH18: =BH16&BH19&BH17 -> 2024Q2A | BI18: =BI16&BI19&BI17 -> 2024Q3A | BJ18: =BJ16&BJ19&BJ17 -> 2024Q4A | BK18: =BK16&BK17 -> 2024A | BL18: =BL16&BL19&BL17 -> 2025Q1A | BM18: =BM16&BM19&BM17 -> 2025Q2A | BN18: =BN16&BN19&BN17 -> 2025Q3A | BO18: =BO16&BO19&BO17 -> 2025Q4A | BP18: =BP16&BP17 -> 2025A | BQ18: =BQ16&BQ19&BQ17 -> 2026Q1E | BR18: =BR16&BR19&BR17 -> 2026Q2E | BS18: =BS16&BS19&BS17 -> 2026Q3E | BT18: =BT16&BT19&BT17 -> 2026Q4E | BU18: =BU16&BU17 -> 2026E | BV18: =BV16&BV19&BV17 -> 2027Q1E | BW18: =BW16&BW19&BW17 -> 2027Q2E | BX18: =BX16&BX19&BX17 -> 2027Q3E | BY18: =BY16&BY19&BY17 -> 2027Q4E | BZ18: =BZ16&BZ17 -> 2027E
D19: Q1 | E19: Q2 | F19: Q3 | G19: Q4 | H19: AN | I19: Q1 | J19: Q2 | K19: Q3 | L19: Q4 | M19: AN | N19: Q1 | O19: Q2 | P19: Q3 | Q19: Q4 | R19: AN | S19: Q1 | T19: Q2 | U19: Q3 | V19: Q4 | W19: AN | X19: Q1 | Y19: Q2 | Z19: Q3 | AA19: Q4 | AB19: AN | AC19: Q1 | AD19: Q2 | AE19: Q3 | AF19: Q4 | AG19: AN | AH19: Q1 | AI19: Q2 | AJ19: Q3 | AK19: Q4 | AL19: AN | AM19: Q1 | AN19: Q2 | AO19: Q3 | AP19: Q4 | AQ19: AN | AR19: Q1 | AS19: Q2 | AT19: Q3 | AU19: Q4 | AV19: AN | AW19: Q1 | AX19: Q2 | AY19: Q3 | AZ19: Q4 | BA19: AN | BB19: Q1 | BC19: Q2 | BD19: Q3 | BE19: Q4 | BF19: AN | BG19: Q1 | BH19: Q2 | BI19: Q3 | BJ19: Q4 | BK19: AN | BL19: Q1 | BM19: Q2 | BN19: Q3 | BO19: Q4 | BP19: AN | BQ19: Q1 | BR19: Q2 | BS19: Q3 | BT19: Q4 | BU19: AN | BV19: Q1 | BW19: Q2 | BX19: Q3 | BY19: Q4 | BZ19: AN
A20: BlueMatrix Time Series Grids | D20: =($B$45&"/"&31&"/"&(D16+$D$45)) -> 3/31/2013 | E20: =$B$46&"/"&31&"/"&(E16+$D$46) -> 6/31/2013 | F20: =$B$47&"/"&31&"/"&(F16+$D$47) -> 9/31/2013 | G20: =$B$48&"/"&31&"/"&(G16+$D$48) -> 12/31/2013 | H20: =G20 -> 12/31/2013 | I20: =($B$45&"/"&31&"/"&(I16+$D$45)) -> 3/31/2014 | J20: =$B$46&"/"&31&"/"&(J16+$D$46) -> 6/31/2014 | K20: =$B$47&"/"&31&"/"&(K16+$D$47) -> 9/31/2014 | L20: =$B$48&"/"&31&"/"&(L16+$D$48) -> 12/31/2014 | M20: =L20 -> 12/31/2014 | N20: =($B$45&"/"&31&"/"&(N16+$D$45)) -> 3/31/2015 | O20: =$B$46&"/"&31&"/"&(O16+$D$46) -> 6/31/2015 | P20: =$B$47&"/"&31&"/"&(P16+$D$47) -> 9/31/2015 | Q20: =$B$48&"/"&31&"/"&(Q16+$D$48) -> 12/31/2015 | R20: =Q20 -> 12/31/2015 | S20: =($B$45&"/"&31&"/"&(S16+$D$45)) -> 3/31/2016 | T20: =$B$46&"/"&31&"/"&(T16+$D$46) -> 6/31/2016 | U20: =$B$47&"/"&31&"/"&(U16+$D$47) -> 9/31/2016 | V20: =$B$48&"/"&31&"/"&(V16+$D$48) -> 12/31/2016 | W20: =V20 -> 12/31/2016 | X20: =($B$45&"/"&31&"/"&(X16+$D$45)) -> 3/31/2017 | Y20: =$B$46&"/"&31&"/"&(Y16+$D$46) -> 6/31/2017 | Z20: =$B$47&"/"&31&"/"&(Z16+$D$47) -> 9/31/2017 | AA20: =$B$48&"/"&31&"/"&(AA16+$D$48) -> 12/31/2017 | AB20: =AA20 -> 12/31/2017 | AC20: =($B$45&"/"&31&"/"&(AC16+$D$45)) -> 3/31/2018 | AD20: =$B$46&"/"&31&"/"&(AD16+$D$46) -> 6/31/2018 | AE20: =$B$47&"/"&31&"/"&(AE16+$D$47) -> 9/31/2018 | AF20: =$B$48&"/"&31&"/"&(AF16+$D$48) -> 12/31/2018 | AG20: =AF20 -> 12/31/2018 | AH20: =($B$45&"/"&31&"/"&(AH16+$D$45)) -> 3/31/2019 | AI20: =$B$46&"/"&31&"/"&(AI16+$D$46) -> 6/31/2019 | AJ20: =$B$47&"/"&31&"/"&(AJ16+$D$47) -> 9/31/2019 | AK20: =$B$48&"/"&31&"/"&(AK16+$D$48) -> 12/31/2019 | AL20: =AK20 -> 12/31/2019 | AM20: =($B$45&"/"&31&"/"&(AM16+$D$45)) -> 3/31/2020 | AN20: =$B$46&"/"&31&"/"&(AN16+$D$46) -> 6/31/2020 | AO20: =$B$47&"/"&31&"/"&(AO16+$D$47) -> 9/31/2020 | AP20: =$B$48&"/"&31&"/"&(AP16+$D$48) -> 12/31/2020 | AQ20: =AP20 -> 12/31/2020 | AR20: =($B$45&"/"&31&"/"&(AR16+$D$45)) -> 3/31/2021 | AS20: =$B$46&"/"&31&"/"&(AS16+$D$46) -> 6/31/2021 | AT20: =$B$47&"/"&31&"/"&(AT16+$D$47) -> 9/31/2021 | AU20: =$B$48&"/"&31&"/"&(AU16+$D$48) -> 12/31/2021 | AV20: =AU20 -> 12/31/2021 | AW20: =($B$45&"/"&31&"/"&(AW16+$D$45)) -> 3/31/2022 | AX20: =$B$46&"/"&31&"/"&(AX16+$D$46) -> 6/31/2022 | AY20: =$B$47&"/"&31&"/"&(AY16+$D$47) -> 9/31/2022 | AZ20: =$B$48&"/"&31&"/"&(AZ16+$D$48) -> 12/31/2022 | BA20: =AZ20 -> 12/31/2022 | BB20: =($B$45&"/"&31&"/"&(BB16+$D$45)) -> 3/31/2023 | BC20: =$B$46&"/"&31&"/"&(BC16+$D$46) -> 6/31/2023 | BD20: =$B$47&"/"&31&"/"&(BD16+$D$47) -> 9/31/2023 | BE20: =$B$48&"/"&31&"/"&(BE16+$D$48) -> 12/31/2023 | BF20: =BE20 -> 12/31/2023 | BG20: =($B$45&"/"&31&"/"&(BG16+$D$45)) -> 3/31/2024 | BH20: =$B$46&"/"&31&"/"&(BH16+$D$46) -> 6/31/2024 | BI20: =$B$47&"/"&31&"/"&(BI16+$D$47) -> 9/31/2024 | BJ20: =$B$48&"/"&31&"/"&(BJ16+$D$48) -> 12/31/2024 | BK20: =BJ20 -> 12/31/2024 | BL20: =($B$45&"/"&31&"/"&(BL16+$D$45)) -> 3/31/2025 | BM20: =$B$46&"/"&31&"/"&(BM16+$D$46) -> 6/31/2025 | BN20: =$B$47&"/"&31&"/"&(BN16+$D$47) -> 9/31/2025 | BO20: =$B$48&"/"&31&"/"&(BO16+$D$48) -> 12/31/2025 | BP20: =BO20 -> 12/31/2025 | BQ20: =($B$45&"/"&31&"/"&(BQ16+$D$45)) -> 3/31/2026 | BR20: =$B$46&"/"&31&"/"&(BR16+$D$46) -> 6/31/2026 | BS20: =$B$47&"/"&31&"/"&(BS16+$D$47) -> 9/31/2026 | BT20: =$B$48&"/"&31&"/"&(BT16+$D$48) -> 12/31/2026 | BU20: =BT20 -> 12/31/2026 | BV20: =($B$45&"/"&31&"/"&(BV16+$D$45)) -> 3/31/2027 | BW20: =$B$46&"/"&31&"/"&(BW16+$D$46) -> 6/31/2027 | BX20: =$B$47&"/"&31&"/"&(BX16+$D$47) -> 9/31/2027 | BY20: =$B$48&"/"&31&"/"&(BY16+$D$48) -> 12/31/2027 | BZ20: =BY20 -> 12/31/2027
A21: Revenue ($M) | B21: REVENUE | D21: =+IS!I9/1000 -> 24.883 | E21: =+IS!J9/1000 -> 26.291 | F21: =+IS!K9/1000 -> 27.749 | G21: =+IS!L9/1000 -> 29.039 | H21: =+IS!M9/1000 -> 107.962 | I21: =+IS!N9/1000 -> 30.356 | J21: =+IS!O9/1000 -> 32.302 | K21: =+IS!P9/1000 -> 34.348 | ... BZ21: =+IS!CE9/1000 -> 769.34508
B22: NON-GAAP:CALENDAR | D22: =_xll.BLUEMATRIX2("/servlet/excelData",D21, $C$14,$B21&":"&D$16&D$17&":"&D$19&":"&$B22) -> #NAME? | E22: =_xll.BLUEMATRIX2("/servlet/excelData",E21, $C$14,$B21&":"&E$16&E$17&":"&E$19&":"&$B22) -> #NAME? | F22: =_xll.BLUEMATRIX2("/servlet/excelData",F21, $C$14,$B21&":"&F$16&F$17&":"&F$19&":"&$B22) -> #NAME? | G22: =_xll.BLUEMATRIX2("/servlet/excelData",G21, $C$14,$B21&":"&G$16&G$17&":"&G$19&":"&$B22) -> #NAME? | H22: =_xll.BLUEMATRIX2("/servlet/excelData",H21, $C$14,$B21&":"&H$16&H$17&":"&H$19&":"&$B22) -> #NAME? | I22: =_xll.BLUEMATRIX2("/servlet/excelData",I21, $C$14,$B21&":"&I$16&I$17&":"&I$19&":"&$B22) -> #NAME? | J22: =_xll.BLUEMATRIX2("/servlet/excelData",J21, $C$14,$B21&":"&J$16&J$17&":"&J$19&":"&$B22) -> #NAME? | K22: =_xll.BLUEMATRIX2("/servlet/excelData",K21, $C$14,$B21&":"&K$16&K$17&":"&K$19&":"&$B22) -> #NAME? | ... BZ22: =_xll.BLUEMATRIX2("/servlet/excelData",BZ21, $C$14,$B21&":"&BZ$16&BZ$17&":"&BZ$19&":"&$B22) -> #NAME?
A23: EPS | B23: EPS | D23: =IS!I59 -> 0.0097969816 | E23: =IS!J59 -> 0.059644562 | F23: =IS!K59 -> 0.080834276 | G23: =IS!L59 -> 0.047521675 | H23: =IS!M59 -> 0.19855885 | I23: =IS!N59 -> 0.045466803 | J23: =IS!O59 -> 0.11362958 | K23: =IS!P59 -> 0.15377562 | ... BZ23: =IS!CE59 -> 8.0972876
B24: NON-GAAP:CALENDAR | D24: =_xll.BLUEMATRIX2("/servlet/excelData",D23, $C$14,$B23&":"&D$16&D$17&":"&D$19&":"&$B24) -> #NAME? | E24: =_xll.BLUEMATRIX2("/servlet/excelData",E23, $C$14,$B23&":"&E$16&E$17&":"&E$19&":"&$B24) -> #NAME? | F24: =_xll.BLUEMATRIX2("/servlet/excelData",F23, $C$14,$B23&":"&F$16&F$17&":"&F$19&":"&$B24) -> #NAME? | G24: =_xll.BLUEMATRIX2("/servlet/excelData",G23, $C$14,$B23&":"&G$16&G$17&":"&G$19&":"&$B24) -> #NAME? | H24: =_xll.BLUEMATRIX2("/servlet/excelData",H23, $C$14,$B23&":"&H$16&H$17&":"&H$19&":"&$B24) -> #NAME? | I24: =_xll.BLUEMATRIX2("/servlet/excelData",I23, $C$14,$B23&":"&I$16&I$17&":"&I$19&":"&$B24) -> #NAME? | J24: =_xll.BLUEMATRIX2("/servlet/excelData",J23, $C$14,$B23&":"&J$16&J$17&":"&J$19&":"&$B24) -> #NAME? | K24: =_xll.BLUEMATRIX2("/servlet/excelData",K23, $C$14,$B23&":"&K$16&K$17&":"&K$19&":"&$B24) -> #NAME? | ... BZ24: =_xll.BLUEMATRIX2("/servlet/excelData",BZ23, $C$14,$B23&":"&BZ$16&BZ$17&":"&BZ$19&":"&$B24) -> #NAME?
A25: FCF | B25: FCF | BI25: RESTATED:CALENDAR
D26: =_xll.BLUEMATRIX2("/servlet/excelData",D25, $C$14,$B25&":"&D$16&D$17&":"&D$19&":"&$B26) -> #NAME? | E26: =_xll.BLUEMATRIX2("/servlet/excelData",E25, $C$14,$B25&":"&E$16&E$17&":"&E$19&":"&$B26) -> #NAME? | F26: =_xll.BLUEMATRIX2("/servlet/excelData",F25, $C$14,$B25&":"&F$16&F$17&":"&F$19&":"&$B26) -> #NAME? | G26: =_xll.BLUEMATRIX2("/servlet/excelData",G25, $C$14,$B25&":"&G$16&G$17&":"&G$19&":"&$B26) -> #NAME? | H26: =_xll.BLUEMATRIX2("/servlet/excelData",H25, $C$14,$B25&":"&H$16&H$17&":"&H$19&":"&$B26) -> #NAME? | I26: =_xll.BLUEMATRIX2("/servlet/excelData",I25, $C$14,$B25&":"&I$16&I$17&":"&I$19&":"&$B26) -> #NAME? | J26: =_xll.BLUEMATRIX2("/servlet/excelData",J25, $C$14,$B25&":"&J$16&J$17&":"&J$19&":"&$B26) -> #NAME? | K26: =_xll.BLUEMATRIX2("/servlet/excelData",K25, $C$14,$B25&":"&K$16&K$17&":"&K$19&":"&$B26) -> #NAME? | ... W26: =_xll.BLUEMATRIX2("/servlet/excelData",W25, $C$14,$B25&":"&W$16&W$17&":"&W$19&":"&$B26) -> #NAME? | BI26: REVENUE:CALENDAR
A27: FFO | B27: FFO
D28: =_xll.BLUEMATRIX2("/servlet/excelData",D27, $C$14,$B27&":"&D$16&D$17&":"&D$19&":"&$B28) -> #NAME? | E28: =_xll.BLUEMATRIX2("/servlet/excelData",E27, $C$14,$B27&":"&E$16&E$17&":"&E$19&":"&$B28) -> #NAME? | F28: =_xll.BLUEMATRIX2("/servlet/excelData",F27, $C$14,$B27&":"&F$16&F$17&":"&F$19&":"&$B28) -> #NAME? | G28: =_xll.BLUEMATRIX2("/servlet/excelData",G27, $C$14,$B27&":"&G$16&G$17&":"&G$19&":"&$B28) -> #NAME? | H28: =_xll.BLUEMATRIX2("/servlet/excelData",H27, $C$14,$B27&":"&H$16&H$17&":"&H$19&":"&$B28) -> #NAME? | I28: =_xll.BLUEMATRIX2("/servlet/excelData",I27, $C$14,$B27&":"&I$16&I$17&":"&I$19&":"&$B28) -> #NAME? | J28: =_xll.BLUEMATRIX2("/servlet/excelData",J27, $C$14,$B27&":"&J$16&J$17&":"&J$19&":"&$B28) -> #NAME? | K28: =_xll.BLUEMATRIX2("/servlet/excelData",K27, $C$14,$B27&":"&K$16&K$17&":"&K$19&":"&$B28) -> #NAME? | ... W28: =_xll.BLUEMATRIX2("/servlet/excelData",W27, $C$14,$B27&":"&W$16&W$17&":"&W$19&":"&$B28) -> #NAME?
A29: Net Cash/Debt ($M) | B29: NET_CASH_DEBT
D30: =_xll.BLUEMATRIX2("/servlet/excelData",D29, $C$14,$B29&":"&D$16&D$17&":"&D$19&":"&$B30) -> #NAME? | E30: =_xll.BLUEMATRIX2("/servlet/excelData",E29, $C$14,$B29&":"&E$16&E$17&":"&E$19&":"&$B30) -> #NAME? | F30: =_xll.BLUEMATRIX2("/servlet/excelData",F29, $C$14,$B29&":"&F$16&F$17&":"&F$19&":"&$B30) -> #NAME? | G30: =_xll.BLUEMATRIX2("/servlet/excelData",G29, $C$14,$B29&":"&G$16&G$17&":"&G$19&":"&$B30) -> #NAME? | H30: =_xll.BLUEMATRIX2("/servlet/excelData",H29, $C$14,$B29&":"&H$16&H$17&":"&H$19&":"&$B30) -> #NAME? | I30: =_xll.BLUEMATRIX2("/servlet/excelData",I29, $C$14,$B29&":"&I$16&I$17&":"&I$19&":"&$B30) -> #NAME? | J30: =_xll.BLUEMATRIX2("/servlet/excelData",J29, $C$14,$B29&":"&J$16&J$17&":"&J$19&":"&$B30) -> #NAME? | K30: =_xll.BLUEMATRIX2("/servlet/excelData",K29, $C$14,$B29&":"&K$16&K$17&":"&K$19&":"&$B30) -> #NAME? | ... W30: =_xll.BLUEMATRIX2("/servlet/excelData",W29, $C$14,$B29&":"&W$16&W$17&":"&W$19&":"&$B30) -> #NAME?
A31: Operating Margin | B31: OP_MARGIN
D32: =_xll.BLUEMATRIX2("/servlet/excelData",D31, $C$14,$B31&":"&D$16&D$17&":"&D$19&":"&$B32) -> #NAME? | E32: =_xll.BLUEMATRIX2("/servlet/excelData",E31, $C$14,$B31&":"&E$16&E$17&":"&E$19&":"&$B32) -> #NAME? | F32: =_xll.BLUEMATRIX2("/servlet/excelData",F31, $C$14,$B31&":"&F$16&F$17&":"&F$19&":"&$B32) -> #NAME? | G32: =_xll.BLUEMATRIX2("/servlet/excelData",G31, $C$14,$B31&":"&G$16&G$17&":"&G$19&":"&$B32) -> #NAME? | H32: =_xll.BLUEMATRIX2("/servlet/excelData",H31, $C$14,$B31&":"&H$16&H$17&":"&H$19&":"&$B32) -> #NAME? | I32: =_xll.BLUEMATRIX2("/servlet/excelData",I31, $C$14,$B31&":"&I$16&I$17&":"&I$19&":"&$B32) -> #NAME? | J32: =_xll.BLUEMATRIX2("/servlet/excelData",J31, $C$14,$B31&":"&J$16&J$17&":"&J$19&":"&$B32) -> #NAME? | K32: =_xll.BLUEMATRIX2("/servlet/excelData",K31, $C$14,$B31&":"&K$16&K$17&":"&K$19&":"&$B32) -> #NAME? | ... W32: =_xll.BLUEMATRIX2("/servlet/excelData",W31, $C$14,$B31&":"&W$16&W$17&":"&W$19&":"&$B32) -> #NAME?
A33: Revenue ($M) | B33: REVENUE
D34: =_xll.BLUEMATRIX2("/servlet/excelData",D33, $C$14,$B33&":"&D$16&D$17&":"&D$19&":"&$B34) -> #NAME? | E34: =_xll.BLUEMATRIX2("/servlet/excelData",E33, $C$14,$B33&":"&E$16&E$17&":"&E$19&":"&$B34) -> #NAME? | F34: =_xll.BLUEMATRIX2("/servlet/excelData",F33, $C$14,$B33&":"&F$16&F$17&":"&F$19&":"&$B34) -> #NAME? | G34: =_xll.BLUEMATRIX2("/servlet/excelData",G33, $C$14,$B33&":"&G$16&G$17&":"&G$19&":"&$B34) -> #NAME? | H34: =_xll.BLUEMATRIX2("/servlet/excelData",H33, $C$14,$B33&":"&H$16&H$17&":"&H$19&":"&$B34) -> #NAME? | I34: =_xll.BLUEMATRIX2("/servlet/excelData",I33, $C$14,$B33&":"&I$16&I$17&":"&I$19&":"&$B34) -> #NAME? | J34: =_xll.BLUEMATRIX2("/servlet/excelData",J33, $C$14,$B33&":"&J$16&J$17&":"&J$19&":"&$B34) -> #NAME? | K34: =_xll.BLUEMATRIX2("/servlet/excelData",K33, $C$14,$B33&":"&K$16&K$17&":"&K$19&":"&$B34) -> #NAME? | ... W34: =_xll.BLUEMATRIX2("/servlet/excelData",W33, $C$14,$B33&":"&W$16&W$17&":"&W$19&":"&$B34) -> #NAME?
A35: ROIC | B35: ROIC
D36: =_xll.BLUEMATRIX2("/servlet/excelData",D35, $C$14,$B35&":"&D$16&D$17&":"&D$19&":"&$B36) -> #NAME? | E36: =_xll.BLUEMATRIX2("/servlet/excelData",E35, $C$14,$B35&":"&E$16&E$17&":"&E$19&":"&$B36) -> #NAME? | F36: =_xll.BLUEMATRIX2("/servlet/excelData",F35, $C$14,$B35&":"&F$16&F$17&":"&F$19&":"&$B36) -> #NAME? | G36: =_xll.BLUEMATRIX2("/servlet/excelData",G35, $C$14,$B35&":"&G$16&G$17&":"&G$19&":"&$B36) -> #NAME? | H36: =_xll.BLUEMATRIX2("/servlet/excelData",H35, $C$14,$B35&":"&H$16&H$17&":"&H$19&":"&$B36) -> #NAME? | I36: =_xll.BLUEMATRIX2("/servlet/excelData",I35, $C$14,$B35&":"&I$16&I$17&":"&I$19&":"&$B36) -> #NAME? | J36: =_xll.BLUEMATRIX2("/servlet/excelData",J35, $C$14,$B35&":"&J$16&J$17&":"&J$19&":"&$B36) -> #NAME? | K36: =_xll.BLUEMATRIX2("/servlet/excelData",K35, $C$14,$B35&":"&K$16&K$17&":"&K$19&":"&$B36) -> #NAME? | ... W36: =_xll.BLUEMATRIX2("/servlet/excelData",W35, $C$14,$B35&":"&W$16&W$17&":"&W$19&":"&$B36) -> #NAME?
D44: Calendar Year = Fiscal Year (If yes =0, if less= -1, if more = 1)
A45: Fiscal 1Q Ending Month Number | B45: 3 | D45: 0
A46: Fiscal 2Q Ending Month Number | B46: 6 | D46: 0
A47: Fiscal 3Q Ending Month Number | B47: 9 | D47: 0
...

Sheet Variance
B3: Qualys, Inc. Quarterly Variance Analysis
B4: (Thousands Of Dollars, Except Per-Share Data) | T4: Guidance
D5: Actual | E5: Actual | F5: NH-Ests. | G5: Actual | I5: Variance | L5: Yr-Yr | O5: Q-Q | T5: Quarter | U5: Low Band | V5: High Band | W5: Midpoint
D6: =IS!BO6 -> 4Q-Dec 24A | E6: 3Q-Sep 25A | F6: 4Q-Dec 25E | G6: =IS!BT6 -> 4Q-Dec 25A | I6: % | J6: Absolute | L6: % | M6: Absolute | O6: % | P6: Absolute | T6: Revs | U6: 154500 | V6: 157500 | W6: =AVERAGE(V6,U6) -> 156000
T7: EPS | U7: 5.81 | V7: 5.91 | W7: =AVERAGE(V7,U7) -> 5.86
B8: Calculated Current Billings | D8: =+IS!BO7 -> 192827 | E8: 186387 | F8: 205709.83 | G8: =+IS!BT7 -> 204933 | I8: =+G8/F8-1 -> -0.0037763533 | J8: =+G8-F8 -> -776.833 | L8: =+G8/D8-1 -> 0.062781664 | M8: =+G8-D8 -> 12106 | O8: =+G8/E8-1 -> 0.099502648 | P8: =+G8-E8 -> 18546
B10: Revenues | D10: =+IS!BO9 -> 159191 | E10: 169882 | F10: 173040.62 | G10: =+IS!BT9 -> 175282 | I10: =+G10/F10-1 -> 0.01295293 | J10: =+G10-F10 -> 2241.383 | L10: =+G10/D10-1 -> 0.10107983 | M10: =+G10-D10 -> 16091 | O10: =+G10/E10-1 -> 0.03178677 | P10: =+G10-E10 -> 5400 | T10: New Year | U10: Low Band | V10: High Band | W10: Midpoint | X10: $∆ | Y10: %∆
B11: Street Estimate | C11: Guide: $172.0-$174.0M | F11: 173160 | I11: =+G10/F11-1 -> 0.012254562 | J11: =+G10-F11 -> 2122 | T11: Revs | W11: =+AVERAGE(U11:V11) -> #DIV/0! | X11: =+W11-W18 -> #DIV/0! | Y11: =+W11/W18-1 -> #DIV/0!
B12: Cost of Goods Sold (Non GAAP) | D12: =+IS!BO14 -> 26236 | E12: 24987 | F12: 26821.296 | G12: =+IS!BT14 -> 26241 | I12: =+G12/F12-1 -> -0.02163563 | J12: =+G12-F12 -> -580.29564 | L12: =+G12/D12-1 -> 0.00019057783 | M12: =+G12-D12 -> 5 | O12: =+G12/E12-1 -> 0.050186097 | P12: =+G12-E12 -> 1254 | T12: EPS | W12: =+AVERAGE(U12:V12) -> #DIV/0! | X12: =+W12-W19 -> #DIV/0! | Y12: =+W12/W19-1 -> #DIV/0!
D13: ______ | E13: ______ | F13: ______ | G13: ______ | I13: ______ | J13: ______ | L13: ______ | M13: ______ | O13: ______ | P13: ______
B14: Gross Profit | D14: =+D10-D12 -> 132955 | E14: 144895 | F14: 146219.32 | G14: =+G10-G12 -> 149041 | I14: =+G14/F14-1 -> 0.019297577 | J14: =+G14-F14 -> 2821.6786 | L14: =+G14/D14-1 -> 0.1209883 | M14: =+G14-D14 -> 16086 | O14: =+G14/E14-1 -> 0.028613824 | P14: =+G14-E14 -> 4146
B15: Gross Margin | D15: =+D14/D10 -> 0.83519169 | E15: 0.85291555 | F15: 0.845 | G15: =+G14/G10 -> 0.85029267 | I15: =+G15/F15-1 -> 0.0062635163 | J15: =+(G15-F15)*10000 -> 52.926712 | K15: BPs | L15: =+G15/D15-1 -> 0.018080859 | M15: =+(G15-D15)*10000 -> 151.00983 | N15: BPs | O15: =+G15/E15-1 -> -0.0030751953 | P15: =+(G15-E15)*10000 -> -26.228819 | Q15: BPs
B17: Operating Expenses | T17: Old Year | U17: Low Band | V17: High Band | W17: Midpoint
B18: Research and Development | D18: =+IS!BO21 -> 23025 | E18: 23720 | F18: 23245.6 | G18: =+IS!BT21 -> 24167 | I18: =+G18/F18-1 -> 0.039637609 | J18: =+G18-F18 -> 921.4 | L18: =+G18/D18-1 -> 0.049598263 | M18: =+G18-D18 -> 1142 | O18: =+G18/E18-1 -> 0.018844857 | P18: =+G18-E18 -> 447 | T18: Revs
B19: % of Revenue | D19: =+D18/D10 -> 0.14463757 | E19: 0.13962633 | F19: 0.13433609 | G19: =+G18/G10 -> 0.13787497 | J19: =+(G19-F19)*10000 -> 35.388766 | K19: BPs | M19: =+(G19-D19)*10000 -> -67.626065 | N19: BPs | P19: =+(G19-E19)*10000 -> -17.513617 | Q19: BPs | T19: EPS
B20: Sales and Marketing | D20: =+IS!BO26 -> 30393 | E20: 31790 | F20: 32425.8 | G20: =+IS!BT26 -> 35721 | I20: =+G20/F20-1 -> 0.10162278 | J20: =+G20-F20 -> 3295.2 | L20: =+G20/D20-1 -> 0.17530352 | M20: =+G20-D20 -> 5328 | O20: =+G20/E20-1 -> 0.12365524 | P20: =+G20-E20 -> 3931
B21: % of Revenue | D21: =+D20/D10 -> 0.1909216 | E21: 0.18712989 | F21: 0.18738837 | G21: =+G20/G10 -> 0.2037916 | J21: =+(G21-F21)*10000 -> 164.0323 | K21: BPs | M21: =+(G21-D21)*10000 -> 128.70007 | N21: BPs | P21: =+(G21-E21)*10000 -> 166.61714 | Q21: BPs
B22: General and Administrative | D22: =+IS!BO31 -> 8806 | E22: 9344 | F22: 9157.12 | G22: =+IS!BT31 -> 9026 | I22: =+G22/F22-1 -> -0.014318912 | J22: =+G22-F22 -> -131.12 | L22: =+G22/D22-1 -> 0.024982966 | M22: =+G22-D22 -> 220 | O22: =+G22/E22-1 -> -0.034032534 | P22: =+G22-E22 -> -318
B23: % of Revenue | D23: =+D22/D10 -> 0.055317198 | E23: 0.055002884 | F23: 0.052918905 | G23: =+G22/G10 -> 0.051494164 | J23: =+(G23-F23)*10000 -> -14.247415 | K23: BPs | M23: =+(G23-D23)*10000 -> -38.230339 | N23: BPs | P23: =+(G23-E23)*10000 -> -35.087207 | Q23: BPs
D24: ______ | E24: ______ | F24: ______ | G24: ______ | I24: ______ | J24: ______ | L24: ______ | M24: ______ | O24: ______ | P24: ______
B25: Total Operating Expenses | D25: =D18+D22+D20 -> 62224 | E25: 64854 | F25: 64828.52 | G25: =G18+G22+G20 -> 68914 | I25: =+G25/F25-1 -> 0.063019794 | J25: =+G25-F25 -> 4085.48 | L25: =+G25/D25-1 -> 0.10751479 | M25: =+G25-D25 -> 6690 | O25: =+G25/E25-1 -> 0.062602153 | P25: =+G25-E25 -> 4060
B26: % of Revenue | D26: =D25/D$10 -> 0.39087637 | E26: 0.3817591 | F26: 0.37464337 | G26: =G25/G$10 -> 0.39316074 | J26: =+(G26-F26)*10000 -> 185.17365 | K26: BPs | M26: =+(G26-D26)*10000 -> 22.843666 | N26: BPs | P26: =+(G26-E26)*10000 -> 114.01632 | Q26: BPs
D27: ______ | E27: ______ | F27: ______ | G27: ______ | I27: ______ | J27: ______ | L27: ______ | M27: ______ | O27: ______ | P27: ______
B28: Operating Income | D28: =D14-D25 -> 70731 | E28: 80041 | F28: 81390.801 | G28: =G14-G25 -> 80127 | I28: =+G28/F28-1 -> -0.01552757 | J28: =+G28-F28 -> -1263.8014 | L28: =+G28/D28-1 -> 0.13284133 | M28: =+G28-D28 -> 9396 | O28: =+G28/E28-1 -> 0.0010744493 | P28: =+G28-E28 -> 86
B29: Operating Margin | D29: =D28/D$10 -> 0.44431532 | E29: 0.47115645 | F29: 0.47035663 | G29: =G28/G$10 -> 0.45713194 | I29: =+G29/F29-1 -> -0.028116311 | J29: =+(G29-F29)*10000 -> -132.24693 | K29: BPs | L29: =+G29/D29-1 -> 0.028845768 | M29: =+(G29-D29)*10000 -> 128.16617 | N29: BPs | O29: =+G29/E29-1 -> -0.029766151 | P29: =+(G29-E29)*10000 -> -140.24514 | Q29: BPs
B32: Interest expense | D32: =+IS!BO45 -> 0 | E32: 0 | F32: 0 | G32: =+IS!BT45 -> 0
B33: Interest income | D33: =+IS!BO46 -> 6194 | E33: 6264 | F33: 500 | G33: =+IS!BT46 -> 6345 | I33: =+G33/F33-1 -> 11.69 | J33: =+G33-F33 -> 5845 | L33: =+G33/D33-1 -> 0.024378431 | M33: =+G33-D33 -> 151 | O33: =+G33/E33-1 -> 0.012931034 | P33: =+G33-E33 -> 81
B34: Other expense, net | D34: =+IS!BO47 -> -1777 | E34: -937 | F34: 0 | G34: =+IS!BT47 -> -754 | I34: NA | J34: =+G34-F34 -> -754 | L34: =+G34/D34-1 -> -0.57568936 | M34: =+G34-D34 -> 1023 | O34: =+G34/E34-1 -> -0.19530416 | P34: =+G34-E34 -> 183
B35: Interest and Other Income, net | D35: =SUM(IS!BO45:BO47) -> 4417 | E35: 5327 | F35: 500 | G35: =SUM(IS!BT45:BT47) -> 5591 | I35: =+G35/F35-1 -> 10.182 | J35: =+G35-F35 -> 5091 | L35: =+G35/D35-1 -> 0.26579126 | M35: =+G35-D35 -> 1174 | O35: =+G35/E35-1 -> 0.049558851 | P35: =+G35-E35 -> 264
D36: ______ | E36: ______ | F36: ______ | G36: ______ | I36: ______ | J36: ______ | L36: ______ | M36: ______ | O36: ______ | P36: ______
B37: Pretax Income | D37: =+D34+D28+D33+D32 -> 75148 | E37: 85368 | F37: 81890.801 | G37: =+G34+G28+G33+G32 -> 85718 | I37: =+G37/F37-1 -> 0.046735391 | J37: =+G37-F37 -> 3827.1986 | L37: =+G37/D37-1 -> 0.14065577 | M37: =+G37-D37 -> 10570 | O37: =+G37/E37-1 -> 0.0040998969 | P37: =+G37-E37 -> 350
B38: Pretax Margin | D38: =+D37/D10 -> 0.47206186 | E38: 0.50251351 | F38: 0.47324612 | G38: =+G37/G10 -> 0.48902911 | I38: =+G38/F38-1 -> 0.033350475 | J38: =+(G38-F38)*10000 -> 157.82983 | K38: BPs | L38: =+G38/D38-1 -> 0.035942841 | M38: =+(G38-D38)*10000 -> 169.67245 | N38: BPs | O38: =+G38/E38-1 -> -0.026833909 | P38: =+(G38-E38)*10000 -> -134.84402 | Q38: BPs
B41: Income Tax Expense (Income) | D41: =+IS!BO53 -> 15781 | E41: 17927 | F41: 17197.068 | G41: =+IS!BT53 -> 18003 | I41: =+G41/F41-1 -> 0.046864483 | J41: =+G41-F41 -> 805.93171 | L41: =+G41/D41-1 -> 0.14080223 | M41: =+G41-D41 -> 2222 | O41: =+G41/E41-1 -> 0.0042394154 | P41: =+G41-E41 -> 76
B42: Tax Rate | D42: =+D41/D37 -> 0.20999894 | E42: 0.20999672 | F42: 0.21 | G42: =+G41/G37 -> 0.2100259 | I42: =+G42/F42-1 -> 0.00012332799 | J42: =+(G42-F42)*10000 -> 0.25898878 | K42: BPs | L42: =+G42/D42-1 -> 0.000128398 | M42: =+(G42-D42)*10000 -> 0.26963444 | N42: BPs | O42: =+G42/E42-1 -> 0.00013894881 | P42: =+(G42-E42)*10000 -> 0.29178795 | Q42: BPs
D43: ______ | E43: ______ | F43: ______ | G43: ______ | I43: ______ | J43: ______ | L43: ______ | M43: ______ | O43: ______ | P43: ______
B44: NG-Net Income | D44: =+D37-D41 -> 59367 | E44: 67441 | F44: 64693.733 | G44: =+G37-G41 -> 67715 | I44: =+G44/F44-1 -> 0.046701076 | J44: =+J37-J41 -> 3021.2669 | L44: =+G44/D44-1 -> 0.14061684 | M44: =+G44-D44 -> 8348 | O44: =+G44/E44-1 -> 0.0040628105 | P44: =+G44-E44 -> 274
B47: NG--Earnings Per Share | D47: =+IS!BO59 -> 1.6045135 | E47: 1.8582371 | F47: 1.7960103 | G47: =+IS!BT59 -> 1.8736857 | I47: =+G47/F47-1 -> 0.04324883 | J47: =+G47-F47 -> 0.077675345 | L47: =+G47/D47-1 -> 0.16775936 | M47: =+G47-D47 -> 0.26917215 | O47: =+G47/E47-1 -> 0.0083135468 | P47: =+G47-E47 -> 0.015448541
B48: Street Estimate | C48: Guide: $1.73-$1.80 | F48: 1.78 | I48: =+G47/F48-1 -> 0.052632397 | J48: =+G47-F48 -> 0.093685667
B50: Shares Outstanding | D50: =+IS!BK62 -> 37575 | E50: 37136 | F50: 37136 | G50: =+IS!BN62 -> 37136 | I50: =+G50/F50-1 -> 0 | J50: =+G50-F50 -> 0 | L50: =+G50/D50-1 -> -0.0116833 | M50: =+G50-D50 -> -439 | O50: =+G50/E50-1 -> 0 | P50: =+G50-E50 -> 0
B52: Source: Qualys, Inc. Financial Statements, FactSet Estimates

Sheet BS
B3: Qualys, Inc.—Balance Sheet
B4: (Thousands Of Dollars, Except Per-Share Data) | D4: March | E4: June | F4: Sept | G4: Dec | H4: Dec | I4: March | J4: June | K4: Sept | L4: Dec | M4: Dec | N4: March | O4: June | P4: Sept | Q4: Dec | R4: Dec | S4: March | T4: June | U4: Sept | V4: Dec | W4: Dec | X4: March | Y4: June | Z4: Sept | AA4: Dec | AB4: Dec | AC4: March | AD4: June | AE4: Sept | AF4: Dec | AG4: Dec | AH4: March | AI4: June | AJ4: Sept | AK4: Dec | AL4: Dec | AM4: March | AN4: June | AO4: Sept | AP4: Dec | AQ4: Dec | AR4: March | AS4: June | AT4: Sept | AU4: Dec | AV4: Dec | AW4: March | AX4: June | AY4: Sept | AZ4: Dec | BA4: Dec | BB4: March | BC4: June | BD4: Sept | BE4: Dec | BF4: Dec | BG4: March | BH4: June | BI4: Sept | BJ4: Dec | BK4: Dec | BL4: March | BM4: June | BN4: Sept | BO4: Dec | BP4: Dec | BQ4: March | BR4: June | BS4: Sept | BT4: Dec | BU4: Dec | BV4: March | BW4: June | BX4: Sept | BY4: Dec | BZ4: Dec | CA4: March | CB4: June | CC4: Sept | CD4: Dec | CE4: Dec
D5: 2012A | E5: 2012A | F5: 2012A | G5: 2012A | H5: 2012A | I5: 2013A | J5: 2013A | K5: 2013A | L5: 2013A | M5: 2013A | N5: 2014A | O5: 2014A | P5: 2014A | Q5: 2014A | R5: 2014A | S5: 2015A | T5: 2015A | U5: 2015A | V5: 2015A | W5: 2015A | X5: 2016A | Y5: 2016A | Z5: 2016A | AA5: 2016A | AB5: 2016A | AC5: 2017A | AD5: 2017A | AE5: 2017A | AF5: 2017A | AG5: 2017A | AH5: 2018A | AI5: 2018A | AJ5: 2018A | AK5: 2018A | AL5: 2018A | AM5: 2019A | AN5: 2019A | AO5: 2019A | AP5: 2019A | AQ5: =+AP5 -> 2019A | AR5: 2020A | AS5: 2020A | AT5: 2020A | AU5: 2020A | AV5: =+AU5 -> 2020A | AW5: 2021A | AX5: 2021A | AY5: 2021A | AZ5: 2021A | BA5: =+AZ5 -> 2021A | BB5: 2022A | BC5: 2022A | BD5: 2022A | BE5: 2022A | BF5: =+BE5 -> 2022A | BG5: 2023A | BH5: 2023A | BI5: 2023A | BJ5: 2023A | BK5: =+BJ5 -> 2023A | BL5: 2024A | BM5: 2024A | BN5: 2024A | BO5: 2024A | BP5: =+BO5 -> 2024A | BQ5: 2025A | BR5: 2025A | BS5: 2025A | BT5: 2025A | BU5: =+BT5 -> 2025A | BV5: 2026E | BW5: 2026E | BX5: 2026E | BY5: 2026E | BZ5: =+BY5 -> 2026E | CA5: 2027E | CB5: 2027E | CC5: 2027E | CD5: 2027E | CE5: =+CD5 -> 2027E
B6: Current Assets
B7: Cash and Cash Equivalents | G7: 34885 | H7: =+G7 -> 34885 | L7: 42369 | M7: =+L7 -> 42369 | N7: 48296 | O7: 41672 | P7: 88285 | Q7: 76504 | R7: =+Q7 -> 76504 | S7: 78018 | T7: 84058 | U7: 94763 | V7: 91698 | W7: =+V7 -> 91698 | X7: 112471 | Y7: 118194 | Z7: 98299 | AA7: 86737 | AB7: =+AA7 -> 86737 | AC7: 109651 | AD7: 130572 | AE7: 90517 | AF7: 86591 | AG7: =+AF7 -> 86591 | AH7: 93174 | AI7: 86779 | AJ7: 97964 | AK7: 41026 | AL7: =+AK7 -> 41026 | AM7: 93127 | AN7: 91381 | AO7: 75615 | AP7: =87559 -> 87559 | AQ7: =+AP7 -> 87559 | AR7: 147565 | AS7: 113909 | AT7: =93027 -> 93027 | AU7: =74132 -> 74132 | AV7: =AU7 -> 74132 | AW7: =108753 -> 108753 | AX7: =97278 -> 97278 | AY7: =145740 -> 145740 | AZ7: =137328 -> 137328 | BA7: =+AZ7 -> 137328 | BB7: =166287 -> 166287 | BC7: =120965 -> 120965 | BD7: =193902 -> 193902 | BE7: =173719 -> 173719 | BF7: =+BE7 -> 173719 | BG7: =193854 -> 193854 | BH7: =186145 -> 186145 | BI7: =208724 -> 208724 | BJ7: =203665 -> 203665 | BK7: =+BJ7 -> 203665 | BL7: =273783 -> 273783 | BM7: =281205 -> 281205 | BN7: =235430 -> 235430 | BO7: =232182 -> 232182 | BP7: =+BO7 -> 232182 | BQ7: =290671 -> 290671 | BR7: =193983 -> 193983 | BS7: =225253 -> 225253 | BT7: =250258 -> 250258 | BU7: =+BT7 -> 250258 | BV7: =+CF!BV61 -> 359729.96 | BW7: =+CF!BW61 -> 400997.09 | BX7: =+CF!BX61 -> 487609.74 | BY7: =+CF!BY61 -> 549144.83 | BZ7: =+BY7 -> 549144.83 | CA7: =+CF!CA61 -> 666827.82 | CB7: =+CF!CB61 -> 699696.94 | CC7: =+CF!CC61 -> 807758.35 | CD7: =+CF!CD61 -> 874317.89 | CE7: =+CD7 -> 874317.89
B8: Short-Term Investments | G8: 83547 | H8: =+G8 -> 83547 | L8: 54827 | M8: =+L8 -> 54827 | N8: 57312 | O8: 67673 | P8: 25133 | Q8: 50714 | R8: =+Q8 -> 50714 | S8: 64932 | T8: 74052 | U8: 79382 | V8: 87268 | W8: =+V8 -> 87268 | X8: 93238 | Y8: 96186 | Z8: 111678 | AA8: 157119 | AB8: =+AA8 -> 157119 | AC8: 135128 | AD8: 148290 | AE8: 212210 | AF8: 201823 | AG8: =+AF8 -> 201823 | AH8: 235353 | AI8: 235740 | AJ8: 228542 | AK8: 248140 | AL8: =+AK8 -> 248140 | AM8: 205009 | AN8: 207626 | AO8: 222421 | AP8: =211331 -> 211331 | AQ8: =+AP8 -> 211331 | AR8: 184387 | AS8: 233922 | AT8: =225734 -> 225734 | AU8: =281892 -> 281892 | AV8: =AU8 -> 281892 | AW8: =247982 -> 247982 | AX8: =262941 -> 262941 | AY8: =199947 -> 199947 | AZ8: =267960 -> 267960 | BA8: =+AZ8 -> 267960 | BB8: =290851 -> 290851 | BC8: =298124 -> 298124 | BD8: =191378 -> 191378 | BE8: =147608 -> 147608 | BF8: =+BE8 -> 147608 | BG8: =139925 -> 139925 | BH8: =163107 -> 163107 | BI8: =218690 -> 218690 | BJ8: =221893 -> 221893 | BK8: =+BJ8 -> 221893 | BL8: =179887 -> 179887 | BM8: =112004 -> 112004 | BN8: =150913 -> 150913 | BO8: =149241 -> 149241 | BP8: =+BO8 -> 149241 | BQ8: =150206 -> 150206 | BR8: =176048 -> 176048 | BS8: =193321 -> 193321 | BT8: =195681 -> 195681 | BU8: =+BT8 -> 195681 | BV8: =+BT8 -> 195681 | BW8: =+BV8 -> 195681 | BX8: =+BW8 -> 195681 | BY8: =+BX8 -> 195681 | BZ8: =+BY8 -> 195681 | CA8: =+BY8 -> 195681 | CB8: =+CA8 -> 195681 | CC8: =+CB8 -> 195681 | CD8: =+CC8 -> 195681 | CE8: =+CD8 -> 195681
B9: Accounts Receivable, net | G9: 24545 | H9: =+G9 -> 24545 | L9: 28581 | M9: =+L9 -> 28581 | N9: 21887 | O9: 28062 | P9: 30278 | Q9: 32993 | R9: =+Q9 -> 32993 | S9: 38732 | T9: 34552 | U9: 37876 | V9: 42325 | W9: =+V9 -> 42325 | X9: 42414 | Y9: 40387 | Z9: 41910 | AA9: 47024 | AB9: =+AA9 -> 47024 | AC9: 41639 | AD9: 46359 | AE9: 46354 | AF9: 64412 | AG9: =+AF9 -> 64412 | AH9: 49874 | AI9: 52535 | AJ9: 58612 | AK9: 75825 | AL9: =+AK9 -> 75825 | AM9: 67863 | AN9: 63184 | AO9: 61314 | AP9: =78034 -> 78034 | AQ9: =+AP9 -> 78034 | AR9: 72696 | AS9: 75938 | AT9: =64291 -> 64291 | AU9: =100179 -> 100179 | AV9: =AU9 -> 100179 | AW9: =85222 -> 85222 | AX9: =86044 -> 86044 | AY9: =84267 -> 84267 | AZ9: =108998 -> 108998 | BA9: =+AZ9 -> 108998 | BB9: =89294 -> 89294 | BC9: =97692 -> 97692 | BD9: =98717 -> 98717 | BE9: =121795 -> 121795 | BF9: =+BE9 -> 121795 | BG9: =101786 -> 101786 | BH9: =124912 -> 124912 | BI9: =103428 -> 103428 | BJ9: =146226 -> 146226 | BK9: =+BJ9 -> 146226 | BL9: =115629 -> 115629 | BM9: =109584 -> 109584 | BN9: =114967 -> 114967 | BO9: =164551 -> 164551 | BP9: =+BO9 -> 164551 | BQ9: =121563 -> 121563 | BR9: =128675 -> 128675 | BS9: =128418 -> 128418 | BT9: =170991 -> 170991 | BU9: =+BT9 -> 170991 | BV9: =+BV58*BV74/90 -> 131081.65 | BW9: =+BW58*BW74/90 -> 141749.57 | BX9: =+BX58*BX74/90 -> 131894.5 | BY9: =+BY58*BY74/90 -> 191719.56 | BZ9: =+BY9 -> 191719.56 | CA9: =+CA58*CA74/90 -> 143650.06 | CB9: =+CB58*CB74/90 -> 149565.48 | CC9: =+CC58*CC74/90 -> 141959.06 | CD9: =+CD58*CD74/90 -> 198804.84 | CE9: =+CD9 -> 198804.84
B10: Prepaid Expenses & Other Current Assets | G10: 4377 | H10: =+G10 -> 4377 | L10: 4679 | M10: =+L10 -> 4679 | N10: 4389 | O10: 5502 | P10: 5901 | Q10: 6528 | R10: =+Q10 -> 6528 | S10: 14167 | T10: 12851 | U10: 13300 | V10: 7945 | W10: =+V10 -> 7945 | X10: 7448 | Y10: 7635 | Z10: 9072 | AA10: 9808 | AB10: =+AA10 -> 9808 | AC10: 9043 | AD10: 19055 | AE10: 18299 | AF10: 16524 | AG10: =+AF10 -> 16524 | AH10: 15488 | AI10: 15815 | AJ10: 16623 | AK10: 13974 | AL10: =+AK10 -> 13974 | AM10: 16539 | AN10: 19395 | AO10: 20459 | AP10: =18692 -> 18692 | AQ10: =+AP10 -> 18692 | AR10: 20490 | AS10: 24338 | AT10: =22480 -> 22480 | AU10: =19142 -> 19142 | AV10: =AU10 -> 19142 | AW10: =22099 -> 22099 | AX10: =21979 -> 21979 | AY10: =22899 -> 22899 | AZ10: =32112 -> 32112 | BA10: =+AZ10 -> 32112 | BB10: =26752 -> 26752 | BC10: =34959 -> 34959 | BD10: =38736 -> 38736 | BE10: =30216 -> 30216 | BF10: =+BE10 -> 30216 | BG10: =29183 -> 29183 | BH10: 34017 | BI10: =29836 -> 29836 | BJ10: =26714 -> 26714 | BK10: =+BJ10 -> 26714 | BL10: =36112 -> 36112 | BM10: =31266 -> 31266 | BN10: =35307 -> 35307 | BO10: =39717 -> 39717 | BP10: =+BO10 -> 39717 | BQ10: =39506 -> 39506 | BR10: =44266 -> 44266 | BS10: =49720 -> 49720 | BT10: =40686 -> 40686 | BU10: =+BT10 -> 40686 | BV10: =+(BV59+BV60)*BV78 -> 39379.063 | BW10: =+(BW59+BW60)*BW78 -> 41192.585 | BX10: =+(BX59+BX60)*BX78 -> 53083.714 | BY10: =+(BY59+BY60)*BY78 -> 38888.569 | BZ10: =+BY10 -> 38888.569 | CA10: =+(CA59+CA60)*CA78 -> 38069.306 | CB10: =+(CB59+CB60)*CB78 -> 43709.559 | CC10: =+(CC59+CC60)*CC78 -> 43967.653 | CD10: =+(CD59+CD60)*CD78 -> 43267.735 | CE10: =+CD10 -> 43267.735
D11: ______ | E11: ______ | F11: ______ | G11: ______ | H11: ______ | I11: ______ | J11: ______ | K11: ______ | L11: ______ | M11: ______ | N11: ______ | O11: ______ | P11: ______ | Q11: ______ | R11: ______ | S11: ______ | T11: ______ | U11: ______ | V11: ______ | W11: ______ | X11: ______ | Y11: ______ | Z11: ______ | AA11: ______ | AB11: ______ | AC11: ______ | AD11: ______ | AE11: ______ | AF11: ______ | AG11: ______ | AH11: ______ | AI11: ______ | AJ11: ______ | AK11: ______ | AL11: ______ | AM11: ______ | AN11: ______ | AO11: ______ | AP11: ______ | AQ11: ______ | AR11: ______ | AS11: ______ | AT11: ______ | AU11: ______ | AV11: ______ | AW11: ______ | AX11: ______ | AY11: ______ | AZ11: ______ | BA11: ______ | BB11: ______ | BC11: ______ | BD11: ______ | BE11: ______ | BF11: ______ | BG11: ______ | BH11: ______ | BI11: ______ | BJ11: ______ | BK11: ______ | BL11: ______ | BM11: ______ | BN11: ______ | BO11: ______ | BP11: ______ | BQ11: ______ | BR11: ______ | BS11: ______ | BT11: ______ | BU11: ______ | BV11: ______ | BW11: ______ | BX11: ______ | BY11: ______ | BZ11: ______ | CA11: ______ | CB11: ______ | CC11: ______ | CD11: ______ | CE11: ______
B12: Total Current Assets | D12: =SUM(D7:D10) -> 0 | E12: =SUM(E7:E10) -> 0 | F12: =SUM(F7:F10) -> 0 | G12: =SUM(G7:G10) -> 147354 | H12: =SUM(H7:H10) -> 147354 | I12: =SUM(I7:I10) -> 0 | J12: =SUM(J7:J10) -> 0 | K12: =SUM(K7:K10) -> 0 | ... CE12: =SUM(CE7:CE10) -> 1312071.5
B14: Long-Term Investments | G14: 0 | H14: =+G14 -> 0 | L14: 35608 | M14: =+L14 -> 35608 | N14: 39387 | O14: 34415 | P14: 37896 | Q14: 39448 | R14: =+Q14 -> 39448 | S14: 30891 | T14: 29031 | U14: 25732 | V14: 43277 | W14: =+V14 -> 43277 | X14: 34614 | Y14: 46534 | Z14: 64930 | AA14: 45725 | AB14: =+AA14 -> 45725 | AC14: 63684 | AD14: 45003 | AE14: 40358 | AF14: 67224 | AG14: =+AF14 -> 67224 | AH14: 65363 | AI14: =64215+2500 -> 66715 | AJ14: =64103+2500 -> 66603 | AK14: =76710+2500 -> 79210 | AL14: =+AK14 -> 79210 | AM14: 96322 | AN14: 111521 | AO14: 100951 | AP14: =119508 -> 119508 | AQ14: =+AP14 -> 119508 | AR14: 102777 | AS14: 97483 | AT14: =133260 -> 133260 | AU14: =98458 -> 98458 | AV14: =AU14 -> 98458 | AW14: =101474 -> 101474 | AX14: =110890 -> 110890 | AY14: =136124 -> 136124 | AZ14: =111198 -> 111198 | BA14: =+AZ14 -> 111198 | BB14: =82360 -> 82360 | BC14: =80122 -> 80122 | BD14: =70997 -> 70997 | BE14: =59206 -> 59206 | BF14: =+BE14 -> 59206 | BG14: =44587 -> 44587 | BH14: =38838 -> 38838 | BI14: =33648 -> 33648 | BJ14: =56644 -> 56644 | BK14: =+BJ14 -> 56644 | BL14: =89693 -> 89693 | BM14: =162058 -> 162058 | BN14: =186680 -> 186680 | BO14: =193887 -> 193887 | BP14: =+BO14 -> 193887 | BQ14: =198990 -> 198990 | BR14: =251179 -> 251179 | BS14: =244984 -> 244984 | BT14: =250868 -> 250868 | BU14: =+BT14 -> 250868 | BV14: =+BT14 -> 250868 | BW14: =+BV14 -> 250868 | BX14: =+BW14 -> 250868 | BY14: =+BX14 -> 250868 | BZ14: =+BY14 -> 250868 | CA14: =+BY14 -> 250868 | CB14: =+CA14 -> 250868 | CC14: =+CB14 -> 250868 | CD14: =+CC14 -> 250868 | CE14: =+CD14 -> 250868
B15: Property, Plant, And Equipment, net | G15: 18148 | H15: =+G15 -> 18148 | L15: 23075 | M15: =+L15 -> 23075 | N15: 24169 | O15: 24012 | P15: 24776 | Q15: 26618 | R15: =+Q15 -> 26618 | S15: 28279 | T15: 29238 | U15: 29965 | V15: 31329 | W15: =+V15 -> 31329 | X15: 31786 | Y15: 40025 | Z15: 40670 | AA15: 39401 | AB15: =+AA15 -> 39401 | AC15: 40823 | AD15: 42768 | AE15: 51281 | AF15: 58557 | AG15: =+AF15 -> 58557 | AH15: 60696 | AI15: 64973 | AJ15: 64503 | AK15: 61442 | AL15: =+AK15 -> 61442 | AM15: 60486 | AN15: 59359 | AO15: 58705 | AP15: =60579 -> 60579 | AQ15: =+AP15 -> 60579 | AR15: 61665 | AS15: 63098 | AT15: =67574 -> 67574 | AU15: =64850 -> 64850 | AV15: =AU15 -> 64850 | AW15: =64143 -> 64143 | AX15: =65959 -> 65959 | AY15: =63257 -> 63257 | AZ15: =61854 -> 61854 | BA15: =+AZ15 -> 61854 | BB15: =63377 -> 63377 | BC15: =57830 -> 57830 | BD15: =53935 -> 53935 | BE15: =47428 -> 47428 | BF15: =+BE15 -> 47428 | BG15: =45161 -> 45161 | BH15: =40350 -> 40350 | BI15: =36160 -> 36160 | BJ15: =32599 -> 32599 | BK15: =+BJ15 -> 32599 | BL15: =30191 -> 30191 | BM15: =27758 -> 27758 | BN15: =27343 -> 27343 | BO15: =30349 -> 30349 | BP15: =+BO15 -> 30349 | BQ15: =28250 -> 28250 | BR15: =26162 -> 26162 | BS15: =24792 -> 24792 | BT15: =23166 -> 23166 | BU15: =+BT15 -> 23166 | BV15: =+BV90 -> 21599.495 | BW15: =+BW90 -> 21017.375 | BX15: =+BX90 -> 21654.985 | BY15: =+BY90 -> 22302.762 | BZ15: =+BY15 -> 22302.762 | CA15: =+CA90 -> 20831.044 | CB15: =+CB90 -> 19602.288 | CC15: =+CC90 -> 19185.819 | CD15: =+CD90 -> 18871.569 | CE15: =+CD15 -> 18871.569
B16: Operating Lease ROU Asset | AM16: =29604 -> 29604 | AN16: 28101 | AO16: 27043 | AP16: =40551 -> 40551 | AQ16: =+AP16 -> 40551 | AR16: 38760 | AS16: 42930 | AT16: =47985 -> 47985 | AU16: =44838 -> 44838 | AV16: =AU16 -> 44838 | AW16: =42113 -> 42113 | AX16: =40403 -> 40403 | AY16: =37795 -> 37795 | AZ16: =37016 -> 37016 | BA16: =+AZ16 -> 37016 | BB16: =34569 -> 34569 | BC16: =33451 -> 33451 | BD16: =31454 -> 31454 | BE16: =33752 -> 33752 | BF16: =+BE16 -> 33752 | BG16: =30737 -> 30737 | BH16: =27992 -> 27992 | BI16: =25211 -> 25211 | BJ16: =22391 -> 22391 | BK16: =+BJ16 -> 22391 | BL16: =31371 -> 31371 | BM16: =44100 -> 44100 | BN16: =41294 -> 41294 | BO16: =40968 -> 40968 | BP16: =+BO16 -> 40968 | BQ16: =41329 -> 41329 | BR16: =48678 -> 48678 | BS16: =47959 -> 47959 | BT16: =46001 -> 46001 | BU16: =+BT16 -> 46001 | BV16: =+BU16-1500 -> 44501 | BW16: =+BV16-1500 -> 43001 | BX16: =+BW16-1500 -> 41501 | BY16: =+BX16-1500 -> 40001 | BZ16: =+BY16 -> 40001 | CA16: =+BZ16-1500 -> 38501 | CB16: =+CA16-1500 -> 37001 | CC16: =+CB16-1500 -> 35501 | CD16: =+CC16-1500 -> 34001 | CE16: =+CD16 -> 34001
B17: Deferred Tax Assets, net | G17: 0 | H17: =+G17 -> 0 | L17: 72 | M17: =+L17 -> 72 | N17: 0 | O17: 0 | P17: 0 | Q17: 22639 | R17: =+Q17 -> 22639 | S17: 14415 | T17: 14035 | U17: 13180 | V17: 16079 | W17: =+V17 -> 16079 | X17: 17165 | Y17: 16123 | Z17: 15141 | AA17: 16590 | AB17: =+AA17 -> 16590 | AC17: 37279 | AD17: 35622 | AE17: 32359 | AF17: 25066 | AG17: =+AF17 -> 25066 | AH17: 24085 | AI17: 23570 | AJ17: 28248 | AK17: 26387 | AL17: =+AK17 -> 26387 | AM17: 24653 | AN17: 22976 | AO17: 18302 | AP17: =18830 -> 18830 | AQ17: =+AP17 -> 18830 | AR17: 16930 | AS17: 16971 | AT17: =13581 -> 13581 | AU17: =15811 -> 15811 | AV17: =AU17 -> 15811 | AW17: =20786 -> 20786 | AX17: =16469 -> 16469 | AY17: =31367 -> 31367 | AZ17: =25087 -> 25087 | BA17: =+AZ17 -> 25087 | BB17: =29986 -> 29986 | BC17: =35426 -> 35426 | BD17: =39802 -> 39802 | BE17: =45412 -> 45412 | BF17: =+BE17 -> 45412 | BG17: =49865 -> 49865 | BH17: =54891 -> 54891 | BI17: =57171 -> 57171 | BJ17: =62761 -> 62761 | BK17: =+BJ17 -> 62761 | BL17: =66565 -> 66565 | BM17: =70433 -> 70433 | BN17: =77730 -> 77730 | BO17: =81307 -> 81307 | BP17: =+BO17 -> 81307 | BQ17: =86059 -> 86059 | BR17: =91551 -> 91551 | BS17: =76258 -> 76258 | BT17: =74518 -> 74518 | BU17: =+BT17 -> 74518 | BV17: =+BT17 -> 74518 | BW17: =+BV17 -> 74518 | BX17: =+BW17 -> 74518 | BY17: =+BX17 -> 74518 | BZ17: =+BY17 -> 74518 | CA17: =+BY17 -> 74518 | CB17: =+CA17 -> 74518 | CC17: =+CB17 -> 74518 | CD17: =+CC17 -> 74518 | CE17: =+CD17 -> 74518
B18: Intangible Assets, net | G18: 2811 | H18: =+G18 -> 2811 | L18: 2394 | M18: =+L18 -> 2394 | N18: 2296 | O18: 2198 | P18: 2099 | Q18: 2001 | R18: =+Q18 -> 2001 | S18: 1903 | T18: 1805 | U18: 1708 | V18: 1360 | W18: =+V18 -> 1360 | X18: 1267 | Y18: 1174 | Z18: 1080 | AA18: 987 | AB18: =+AA18 -> 987 | AC18: 894 | AD18: 801 | AE18: 5801 | AF18: 12401 | AG18: =+AF18 -> 12401 | AH18: 11769 | AI18: 14605 | AJ18: 13741 | AK18: 21976 | AL18: =+AK18 -> 21976 | AM18: 21356 | AN18: 19836 | AO18: 18316 | AP18: =16795 -> 16795 | AQ18: =+AP18 -> 16795 | AR18: 15275 | AS18: 13755 | AT18: =13651 -> 13651 | AU18: =12006 -> 12006 | AV18: =AU18 -> 12006 | AW18: =10361 -> 10361 | AX18: =8715 -> 8715 | AY18: =8250 -> 8250 | AZ18: =6545 -> 6545 | BA18: =+AZ18 -> 6545 | BB18: =4839 -> 4839 | BC18: =3365 -> 3365 | BD18: =2019 -> 2019 | BE18: =12801 -> 12801 | BF18: =+BE18 -> 12801 | BG18: =12030 -> 12030 | BH18: =11258 -> 11258 | BI18: =10486 -> 10486 | BJ18: =9715 -> 9715 | BK18: =+BJ18 -> 9715 | BL18: =8943 -> 8943 | BM18: =8172 -> 8172 | BN18: =7451 -> 7451 | BO18: =6812 -> 6812 | BP18: =+BO18 -> 6812 | BQ18: =6172 -> 6172 | BR18: =5533 -> 5533 | BS18: =4894 -> 4894 | BT18: =4255 -> 4255 | BU18: =+BT18 -> 4255 | BV18: =+BV100 -> 3616.75 | BW18: =+BW100 -> 3074.2375 | BX18: =+BX100 -> 2613.1019 | BY18: =+BY100 -> 2221.1366 | BZ18: =+BY18 -> 2221.1366 | CA18: =+CA100 -> 1776.9093 | CB18: =+CB100 -> 1421.5274 | CC18: =+CC100 -> 1137.2219 | CD18: =+CD100 -> 909.77755 | CE18: =+CD18 -> 909.77755
B19: Goodwill | G19: 317 | H19: =+G19 -> 317 | L19: 317 | M19: =+L19 -> 317 | N19: 317 | O19: 317 | P19: 317 | Q19: 317 | R19: =+Q19 -> 317 | S19: 317 | T19: 317 | U19: 317 | V19: 317 | W19: =+V19 -> 317 | X19: 317 | Y19: 317 | Z19: 317 | AA19: 317 | AB19: =+AA19 -> 317 | AC19: 317 | AD19: 317 | AE19: 900 | AF19: 1549 | AG19: =+AF19 -> 1549 | AH19: 1549 | AI19: 1849 | AJ19: 1849 | AK19: 7225 | AL19: =+AK19 -> 7225 | AM19: 7325 | AN19: 7325 | AO19: 7447 | AP19: =7447 -> 7447 | AQ19: =+AP19 -> 7447 | AR19: 7447 | AS19: 7447 | AT19: =7447 -> 7447 | AU19: =7447 -> 7447 | AV19: =AU19 -> 7447 | AW19: =7447 -> 7447 | AX19: =7447 -> 7447 | AY19: =7447 -> 7447 | AZ19: =7447 -> 7447 | BA19: =+AZ19 -> 7447 | BB19: =7447 -> 7447 | BC19: =7447 -> 7447 | BD19: =7447 -> 7447 | BE19: =7447 -> 7447 | BF19: =+BE19 -> 7447 | BG19: =7447 -> 7447 | BH19: =7447 -> 7447 | BI19: =7447 -> 7447 | BJ19: =7447 -> 7447 | BK19: =+BJ19 -> 7447 | BL19: =7447 -> 7447 | BM19: =7447 -> 7447 | BN19: =7447 -> 7447 | BO19: =7447 -> 7447 | BP19: =+BO19 -> 7447 | BQ19: =7447 -> 7447 | BR19: =7447 -> 7447 | BS19: =7447 -> 7447 | BT19: =7447 -> 7447 | BU19: =+BT19 -> 7447 | BV19: =+BT19 -> 7447 | BW19: =+BV19 -> 7447 | BX19: =+BW19 -> 7447 | BY19: =+BX19 -> 7447 | BZ19: =+BY19 -> 7447 | CA19: =+BY19 -> 7447 | CB19: =+CA19 -> 7447 | CC19: =+CB19 -> 7447 | CD19: =+CC19 -> 7447 | CE19: =+CD19 -> 7447
B20: Restricted Cash | G20: 114 | H20: =+G20 -> 114 | L20: 0 | M20: =+L20 -> 0 | N20: 0 | O20: 0 | P20: 0 | Q20: 0 | R20: =+Q20 -> 0 | S20: 0 | T20: 0 | U20: 0 | V20: 0 | W20: =+V20 -> 0 | X20: 0 | Y20: 0 | Z20: 0 | AA20: 1200 | AB20: =+AA20 -> 1200 | AC20: 1200 | AD20: 1200 | AE20: 1200 | AF20: 1200 | AG20: =+AF20 -> 1200 | AH20: 1200 | AI20: 1200 | AJ20: 1200 | AK20: 1200 | AL20: =+AK20 -> 1200 | AM20: 1200 | AN20: 1200 | AO20: 1200 | AP20: =1200 -> 1200 | AQ20: =+AP20 -> 1200 | AR20: 1200 | AS20: 1200 | AT20: =1200 -> 1200 | AU20: =1200 -> 1200 | AV20: =AU20 -> 1200 | AW20: =1200 -> 1200 | AX20: =1200 -> 1200 | AY20: =1200 -> 1200 | AZ20: =1200 -> 1200 | BA20: =+AZ20 -> 1200 | BB20: =1200 -> 1200 | BC20: =1200 -> 1200 | BD20: =1200 -> 1200 | BE20: =2700 -> 2700 | BF20: =+BE20 -> 2700 | BG20: =2700 -> 2700 | BH20: =2700 -> 2700 | BI20: =1200+1500 -> 2700 | BJ20: =1200+1500 -> 2700 | BK20: =+BJ20 -> 2700 | BL20: =1200 -> 1200 | BM20: =1200 -> 1200 | BN20: =1200 -> 1200 | BO20: =1200 -> 1200 | BP20: =+BO20 -> 1200 | BQ20: =1200 -> 1200 | BR20: =1200 -> 1200 | BS20: =1200 -> 1200 | BT20: =1200 -> 1200 | BU20: =+BT20 -> 1200 | BV20: =+BT20 -> 1200 | BW20: =+BV20 -> 1200 | BX20: =+BW20 -> 1200 | BY20: =+BX20 -> 1200 | BZ20: =+BY20 -> 1200 | CA20: =+BY20 -> 1200 | CB20: =+CA20 -> 1200 | CC20: =+CB20 -> 1200 | CD20: =+CC20 -> 1200 | CE20: =+CD20 -> 1200
B21: Other Noncurrent Assets | G21: 1574 | H21: =+G21 -> 1574 | L21: 681 | M21: =+L21 -> 681 | N21: 784 | O21: 721 | P21: 726 | Q21: 2262 | R21: =+Q21 -> 2262 | S21: 2254 | T21: 2106 | U21: 2065 | V21: 1916 | W21: =+V21 -> 1916 | X21: 1942 | Y21: 2276 | Z21: 1939 | AA21: 2096 | AB21: =+AA21 -> 2096 | AC21: 1863 | AD21: 1959 | AE21: 2048 | AF21: 2178 | AG21: =+AF21 -> 2178 | AH21: 7061 | AI21: 7134 | AJ21: 8115 | AK21: 9275 | AL21: =+AK21 -> 9275 | AM21: =2500+10158 -> 12658 | AN21: =13708 -> 13708 | AO21: 14151 | AP21: =15082 -> 15082 | AQ21: =+AP21 -> 15082 | AR21: 15300 | AS21: 16024 | AT21: =16854 -> 16854 | AU21: =16864 -> 16864 | AV21: =AU21 -> 16864 | AW21: =18362 -> 18362 | AX21: =17980 -> 17980 | AY21: =17887 -> 17887 | AZ21: =17814 -> 17814 | BA21: =+AZ21 -> 17814 | BB21: =17588 -> 17588 | BC21: =18430 -> 18430 | BD21: =18044 -> 18044 | BE21: =18857 -> 18857 | BF21: =+BE21 -> 18857 | BG21: =18478 -> 18478 | BH21: =17927 -> 17927 | BI21: =18360 -> 18360 | BJ21: =19863 -> 19863 | BK21: =+BJ21 -> 19863 | BL21: =20961 -> 20961 | BM21: =21373 -> 21373 | BN21: =22561 -> 22561 | BO21: =25876 -> 25876 | BP21: =+BO21 -> 25876 | BQ21: =25078 -> 25078 | BR21: =24783 -> 24783 | BS21: =27743 -> 27743 | BT21: =30010 -> 30010 | BU21: =+BT21 -> 30010 | BV21: =+BT21 -> 30010 | BW21: =+BV21 -> 30010 | BX21: =+BW21 -> 30010 | BY21: =+BX21 -> 30010 | BZ21: =+BY21 -> 30010 | CA21: =+BY21 -> 30010 | CB21: =+CA21 -> 30010 | CC21: =+CB21 -> 30010 | CD21: =+CC21 -> 30010 | CE21: =+CD21 -> 30010
D22: ______ | E22: ______ | F22: ______ | G22: ______ | H22: ______ | I22: ______ | J22: ______ | K22: ______ | L22: ______ | M22: ______ | N22: ______ | O22: ______ | P22: ______ | Q22: ______ | R22: ______ | S22: ______ | T22: ______ | U22: ______ | V22: ______ | W22: ______ | X22: ______ | Y22: ______ | Z22: ______ | AA22: ______ | AB22: ______ | AC22: ______ | AD22: ______ | AE22: ______ | AF22: ______ | AG22: ______ | AH22: ______ | AI22: ______ | AJ22: ______ | AK22: ______ | AL22: ______ | AM22: ______ | AN22: ______ | AO22: ______ | AP22: ______ | AQ22: ______ | AR22: ______ | AS22: ______ | AT22: ______ | AU22: ______ | AV22: ______ | AW22: ______ | AX22: ______ | AY22: ______ | AZ22: ______ | BA22: ______ | BB22: ______ | BC22: ______ | BD22: ______ | BE22: ______ | BF22: ______ | BG22: ______ | BH22: ______ | BI22: ______ | BJ22: ______ | BK22: ______ | BL22: ______ | BM22: ______ | BN22: ______ | BO22: ______ | BP22: ______ | BQ22: ______ | BR22: ______ | BS22: ______ | BT22: ______ | BU22: ______ | BV22: ______ | BW22: ______ | BX22: ______ | BY22: ______ | BZ22: ______ | CA22: ______ | CB22: ______ | CC22: ______ | CD22: ______ | CE22: ______
B23: Total Assets | D23: =SUM(D14:D21)+D12 -> 0 | E23: =SUM(E14:E21)+E12 -> 0 | F23: =SUM(F14:F21)+F12 -> 0 | G23: =SUM(G14:G21)+G12 -> 170318 | H23: =SUM(H14:H21)+H12 -> 170318 | I23: =SUM(I14:I21)+I12 -> 0 | J23: =SUM(J14:J21)+J12 -> 0 | K23: =SUM(K14:K21)+K12 -> 0 | ... CE23: =SUM(CE14:CE21)+CE12 -> 1729896.8
B25: Liabilities and Stock Holders' Equity
B26: Current Liabilities
B27: Accounts Payable | G27: 2031 | H27: =+G27 -> 2031 | L27: 1930 | M27: =+L27 -> 1930 | N27: 2018 | O27: 1735 | P27: 1898 | Q27: 5661 | R27: =+Q27 -> 5661 | S27: 2052 | T27: 1042 | U27: 2055 | V27: 2368 | W27: =+V27 -> 2368 | X27: 4393 | Y27: 5853 | Z27: 1491 | AA27: 2051 | AB27: =+AA27 -> 2051 | AC27: 4338 | AD27: 1924 | AE27: 1398 | AF27: 1144 | AG27: =+AF27 -> 1144 | AH27: 1310 | AI27: 1024 | AJ27: 4723 | AK27: 5588 | AL27: =+AK27 -> 5588 | AM27: 566 | AN27: 963 | AO27: 909 | AP27: =848 -> 848 | AQ27: =+AP27 -> 848 | AR27: 653 | AS27: 1395 | AT27: =2223 -> 2223 | AU27: =731 -> 731 | AV27: =AU27 -> 731 | AW27: =1164 -> 1164 | AX27: =1597 -> 1597 | AY27: =1099 -> 1099 | AZ27: =1296 -> 1296 | BA27: =+AZ27 -> 1296 | BB27: =2477 -> 2477 | BC27: =2132 -> 2132 | BD27: =1308 -> 1308 | BE27: =2808 -> 2808 | BF27: =+BE27 -> 2808 | BG27: =1740 -> 1740 | BH27: =2160 -> 2160 | BI27: =1165 -> 1165 | BJ27: =988 -> 988 | BK27: =+BJ27 -> 988 | BL27: =645 -> 645 | BM27: =1277 -> 1277 | BN27: =1422 -> 1422 | BO27: =1270 -> 1270 | BP27: =+BO27 -> 1270 | BQ27: =1292 -> 1292 | BR27: =1977 -> 1977 | BS27: =1823 -> 1823 | BT27: =1202 -> 1202 | BU27: =+BT27 -> 1202 | BV27: =+BV59*BV108/90 -> 1542.137 | BW27: =+BW59*BW108/90 -> 1889.9942 | BX27: =+BX59*BX108/90 -> 1911.4556 | BY27: =+BY59*BY108/90 -> 1938.0346 | BZ27: =+BY27 -> 1938.0346 | CA27: =+CA59*CA108/90 -> 1644.6891 | CB27: =+CB59*CB108/90 -> 1971.7365 | CC27: =+CC59*CC108/90 -> 2000.3322 | CD27: =+CD59*CD108/90 -> 1988.0484 | CE27: =+CD27 -> 1988.0484
B28: Accrued Liabilities | G28: 7803 | H28: =+G28 -> 7803 | L28: 9037 | M28: =+L28 -> 9037 | N28: 8444 | O28: 8389 | P28: 9101 | Q28: 10353 | R28: =+Q28 -> 10353 | S28: 10547 | T28: 10598 | U28: 11358 | V28: 11786 | W28: =+V28 -> 11786 | X28: 11513 | Y28: 16851 | Z28: 16324 | AA28: 13317 | AB28: =+AA28 -> 13317 | AC28: 13338 | AD28: 13836 | AE28: 14679 | AF28: 21444 | AG28: =+AF28 -> 21444 | AH28: 22181 | AI28: 27454 | AJ28: 23208 | AK28: 25130 | AL28: =+AK28 -> 25130 | AM28: 32017 | AN28: 24315 | AO28: 25595 | AP28: =22784 -> 22784 | AQ28: =+AP28 -> 22784 | AR28: 23753 | AS28: 24810 | AT28: =24772 -> 24772 | AU28: =29833 -> 29833 | AV28: =AU28 -> 29833 | AW28: =27836 -> 27836 | AX28: =30685 -> 30685 | AY28: =33878 -> 33878 | AZ28: =32504 -> 32504 | BA28: =+AZ28 -> 32504 | BB28: =37083 -> 37083 | BC28: =37987 -> 37987 | BD28: =42816 -> 42816 | BE28: =42592 -> 42592 | BF28: =+BE28 -> 42592 | BG28: =41777 -> 41777 | BH28: =52637 -> 52637 | BI28: =49838 -> 49838 | BJ28: =43096 -> 43096 | BK28: =+BJ28 -> 43096 | BL28: =48246 -> 48246 | BM28: =36095 -> 36095 | BN28: =39960 -> 39960 | BO28: =45942 -> 45942 | BP28: =+BO28 -> 45942 | BQ28: =52921 -> 52921 | BR28: =52768 -> 52768 | BS28: =51136 -> 51136 | BT28: =57694 -> 57694 | BU28: =+BT28 -> 57694 | BV28: =+(BV59+BV60)*BV112 -> 59068.594 | BW28: =+(BW59+BW60)*BW112 -> 56639.805 | BX28: =+(BX59+BX60)*BX112 -> 58392.086 | BY28: =+(BY59+BY60)*BY112 -> 66666.118 | BZ28: =+BY28 -> 66666.118 | CA28: =+(CA59+CA60)*CA112 -> 70700.14 | CB28: =+(CB59+CB60)*CB112 -> 54636.948 | CC28: =+(CC59+CC60)*CC112 -> 60455.522 | CD28: =+(CD59+CD60)*CD112 -> 72112.892 | CE28: =+CD28 -> 72112.892
B29: Deferred Revenues, Current | G29: 56497 | H29: =+G29 -> 56497 | L29: 67505 | M29: =+L29 -> 67505 | N29: 71410 | O29: 71853 | P29: 74337 | Q29: 81147 | R29: =+Q29 -> 81147 | S29: 87929 | T29: 87411 | U29: 91939 | V29: 98025 | W29: =+V29 -> 98025 | X29: 101557 | Y29: 103753 | Z29: 109026 | AA29: 114964 | AB29: =+AA29 -> 114964 | AC29: 120044 | AD29: 124738 | AE29: 132167 | AF29: 143186 | AG29: =+AF29 -> 143186 | AH29: 147656 | AI29: 151419 | AJ29: 155115 | AK29: 164624 | AL29: =+AK29 -> 164624 | AM29: 174452 | AN29: 176609 | AO29: 180304 | AP29: =192172 -> 192172 | AQ29: =+AP29 -> 192172 | AR29: 201861 | AS29: 199732 | AT29: =200283 -> 200283 | AU29: =213494 -> 213494 | AV29: =AU29 -> 213494 | AW29: =218898 -> 218898 | AX29: =228180 -> 228180 | AY29: =237539 -> 237539 | AZ29: =257872 -> 257872 | BA29: =+AZ29 -> 257872 | BB29: =266934 -> 266934 | BC29: =275725 -> 275725 | BD29: =278947 -> 278947 | BE29: =293728 -> 293728 | BF29: =+BE29 -> 293728 | BG29: =296516 -> 296516 | BH29: =302446 -> 302446 | BI29: =307179 -> 307179 | BJ29: =333267 -> 333267 | BK29: =+BJ29 -> 333267 | BL29: =332128 -> 332128 | BM29: =324334 -> 324334 | BN29: =337821 -> 337821 | BO29: =371457 -> 371457 | BP29: =+BO29 -> 371457 | BQ29: =366824 -> 366824 | BR29: =354971 -> 354971 | BS29: =371476 -> 371476 | BT29: =401127 -> 401127 | BU29: =+BT29 -> 401127 | BV29: =+BQ29*(1+BV118) -> 396169.92 | BW29: =+BR29*(1+BW118) -> 383368.68 | BX29: =+BS29*(1+BX118) -> 401194.08 | BY29: =+BT29*(1+BY118) -> 431211.52 | BZ29: =+BY29 -> 431211.52 | CA29: =+BV29*(1+CA118) -> 423901.81 | CB29: =+BW29*(1+CB118) -> 410204.49 | CC29: =+BX29*(1+CC118) -> 429277.67 | CD29: =+BY29*(1+CD118) -> 461396.33 | CE29: =+CD29 -> 461396.33
B30: Operating Lease Liabiliy, Current | G30: 1183 | H30: =+G30 -> 1183 | L30: 805 | M30: =+L30 -> 805 | N30: 538 | O30: 270 | P30: 0 | Q30: 0 | R30: =+Q30 -> 0 | S30: 0 | T30: 0 | U30: 0 | V30: 0 | W30: =+V30 -> 0 | X30: 0 | Y30: 0 | Z30: 0 | AA30: 0 | AB30: =+AA30 -> 0 | AC30: 0 | AD30: 0 | AE30: =+AD30 -> 0 | AF30: =+AE30 -> 0 | AG30: =+AF30 -> 0 | AH30: 0 | AI30: 0 | AJ30: 0 | AK30: 1565 | AL30: =+AK30 -> 1565 | AM30: 1153 | AN30: 6826 | AO30: 6937 | AP30: =7663 -> 7663 | AQ30: =+AP30 -> 7663 | AR30: 7968 | AS30: 9161 | AT30: =11777 -> 11777 | AU30: =11672 -> 11672 | AV30: =AU30 -> 11672 | AW30: =11846 -> 11846 | AX30: =12246 -> 12246 | AY30: =12176 -> 12176 | AZ30: =12608 -> 12608 | BA30: =+AZ30 -> 12608 | BB30: =12044 -> 12044 | BC30: =11545 -> 11545 | BD30: =10959 -> 10959 | BE30: =13060 -> 13060 | BF30: =+BE30 -> 13060 | BG30: =12925 -> 12925 | BH30: =11877 -> 11877 | BI30: =12309 -> 12309 | BJ30: =11857 -> 11857 | BK30: =+BJ30 -> 11857 | BL30: =10046 -> 10046 | BM30: =10123 -> 10123 | BN30: =9333 -> 9333 | BO30: =9721 -> 9721 | BP30: =+BO30 -> 9721 | BQ30: =10991 -> 10991 | BR30: =7099 -> 7099 | BS30: =7345 -> 7345 | BT30: =7315 -> 7315 | BU30: =+BT30 -> 7315 | BV30: =+BT30 -> 7315 | BW30: =+BV30 -> 7315 | BX30: =+BW30 -> 7315 | BY30: =+BX30 -> 7315 | BZ30: =+BY30 -> 7315 | CA30: =+BY30 -> 7315 | CB30: =+CA30 -> 7315 | CC30: =+CB30 -> 7315 | CD30: =+CC30 -> 7315 | CE30: =+CD30 -> 7315
